I0409 14:48:35.494131       1 serving.go:386] Generated self-signed cert in-memory
W0409 14:48:35.494984       1 client_config.go:667] Neither --kubeconfig nor --master was specified.  Using the inClusterConfig.  This might not work.
I0409 14:48:35.902714       1 server.go:166] "Starting Kubernetes Scheduler" version="v0.0.0-master+$Format:%H$"
I0409 14:48:35.902739       1 server.go:168] "Golang settings" GOGC="" GOMAXPROCS="" GOTRACEBACK=""
I0409 14:48:35.907349       1 requestheader_controller.go:180] Starting RequestHeaderAuthRequestController
I0409 14:48:35.907432       1 configmap_cafile_content.go:205] "Starting controller" name="client-ca::kube-system::extension-apiserver-authentication::client-ca-file"
I0409 14:48:35.907446       1 shared_informer.go:313] Waiting for caches to sync for RequestHeaderAuthRequestController
I0409 14:48:35.907459       1 configmap_cafile_content.go:205] "Starting controller" name="client-ca::kube-system::extension-apiserver-authentication::requestheader-client-ca-file"
I0409 14:48:35.907446       1 shared_informer.go:313] Waiting for caches to sync for client-ca::kube-system::extension-apiserver-authentication::client-ca-file
I0409 14:48:35.907478       1 shared_informer.go:313] Waiting for caches to sync for client-ca::kube-system::extension-apiserver-authentication::requestheader-client-ca-file
I0409 14:48:35.907642       1 secure_serving.go:213] Serving securely on [::]:10259
I0409 14:48:35.907719       1 tlsconfig.go:243] "Starting DynamicServingCertificateController"
I0409 14:48:35.912518       1 scheduler.go:205] [OnAddPod] Pod added: kube-system/coredns-668d6bf9bc-6lnzs, Annotations: map[]
I0409 14:48:35.912622       1 scheduler.go:205] [OnAddPod] Pod added: kube-system/custom-scheduler-8dcdbb8b5-7bscj, Annotations: map[]
I0409 14:48:35.912690       1 scheduler.go:205] [OnAddPod] Pod added: kube-system/etcd-minikube, Annotations: map[kubeadm.kubernetes.io/etcd.advertise-client-urls:https://192.168.49.2:2379 kubernetes.io/config.hash:2b4b75c2a289008e0b381891e9683040 kubernetes.io/config.mirror:2b4b75c2a289008e0b381891e9683040 kubernetes.io/config.seen:2025-03-28T11:15:45.895682961Z kubernetes.io/config.source:file]
I0409 14:48:35.912834       1 scheduler.go:205] [OnAddPod] Pod added: kube-system/kube-apiserver-minikube, Annotations: map[kubeadm.kubernetes.io/kube-apiserver.advertise-address.endpoint:192.168.49.2:8443 kubernetes.io/config.hash:d72d0a4cf4be077c9919d46b7358a5e8 kubernetes.io/config.mirror:d72d0a4cf4be077c9919d46b7358a5e8 kubernetes.io/config.seen:2025-03-28T11:15:45.895684581Z kubernetes.io/config.source:file]
I0409 14:48:35.912950       1 scheduler.go:205] [OnAddPod] Pod added: kube-system/kube-controller-manager-minikube, Annotations: map[kubernetes.io/config.hash:843c74f7b3bc7d7040a05c31708a6a30 kubernetes.io/config.mirror:843c74f7b3bc7d7040a05c31708a6a30 kubernetes.io/config.seen:2025-03-28T11:15:41.285226822Z kubernetes.io/config.source:file]
I0409 14:48:35.913026       1 scheduler.go:205] [OnAddPod] Pod added: kube-system/kube-proxy-6mvvt, Annotations: map[]
I0409 14:48:35.913287       1 scheduler.go:205] [OnAddPod] Pod added: kube-system/kube-scheduler-minikube, Annotations: map[kubernetes.io/config.hash:d14ce008bee3a1f3bd7cf547688f9dfe kubernetes.io/config.mirror:d14ce008bee3a1f3bd7cf547688f9dfe kubernetes.io/config.seen:2025-03-28T11:15:45.895678961Z kubernetes.io/config.source:file]
I0409 14:48:35.913330       1 scheduler.go:205] [OnAddPod] Pod added: kube-system/kwok-controller-5cc659f5cc-dlncs, Annotations: map[]
I0409 14:48:35.913792       1 scheduler.go:205] [OnAddPod] Pod added: kube-system/storage-provisioner, Annotations: map[kubectl.kubernetes.io/last-applied-configuration:{"apiVersion":"v1","kind":"Pod","metadata":{"annotations":{},"labels":{"addonmanager.kubernetes.io/mode":"Reconcile","integration-test":"storage-provisioner"},"name":"storage-provisioner","namespace":"kube-system"},"spec":{"containers":[{"command":["/storage-provisioner"],"image":"gcr.io/k8s-minikube/storage-provisioner:v5","imagePullPolicy":"IfNotPresent","name":"storage-provisioner","volumeMounts":[{"mountPath":"/tmp","name":"tmp"}]}],"hostNetwork":true,"serviceAccountName":"storage-provisioner","volumes":[{"hostPath":{"path":"/tmp","type":"Directory"},"name":"tmp"}]}}
]
I0409 14:48:36.007631       1 shared_informer.go:320] Caches are synced for client-ca::kube-system::extension-apiserver-authentication::client-ca-file
I0409 14:48:36.007689       1 shared_informer.go:320] Caches are synced for RequestHeaderAuthRequestController
I0409 14:48:36.007715       1 shared_informer.go:320] Caches are synced for client-ca::kube-system::extension-apiserver-authentication::requestheader-client-ca-file
I0409 14:48:36.007778       1 leaderelection.go:257] attempting to acquire leader lease kube-system/kube-scheduler...
I0409 14:48:36.016023       1 leaderelection.go:271] successfully acquired lease kube-system/kube-scheduler
I0409 14:49:09.153158       1 scheduler.go:205] [OnAddPod] Pod added: kube-system/kube-proxy-v9z29, Annotations: map[]
I0409 14:49:09.366722       1 default_preemption.go:51] [PreEnqueue] PreEnqueue called for pod: gold-class-deploy-1-78bb76545-pwz55
I0409 14:49:09.366750       1 default_preemption.go:52] [PreEnqueue] SchedulerName for pod gold-class-deploy-1-78bb76545-pwz55: custom-scheduler
E0409 14:49:09.366763       1 types.go:135] Controller gold-class-deploy-1-78bb76545-pwz55_default associated with , which is no valid QoS measure approach.
I0409 14:49:09.366745       1 scheduler.go:205] [OnAddPod] Pod added: default/gold-class-deploy-1-78bb76545-pwz55, Annotations: map[acceptablePreemptionOverhead:0.05 controller:gold-controller-1 kwok.x-k8s.io/usage-cpu:1m kwok.x-k8s.io/usage-memory:1Mi qosMeasuring:average slo:1]
E0409 14:49:09.366771       1 types.go:564] Pod gold-class-deploy-1-78bb76545-pwz55_default with no valid QoS measure approach associated with.
I0409 14:49:09.369202       1 scheduler.go:164] [PreBind] Validating pod gold-class-deploy-1-78bb76545-pwz55 before binding to node kwok-node-1
I0409 14:49:09.376656       1 scheduler.go:255] [OnUpdatePod] Updating 'LastStatus' of pod default/gold-class-deploy-1-78bb76545-pwz55 in metrics
I0409 14:49:09.376695       1 scheduler.go:172] [PostBind] Called for pod gold-class-deploy-1-78bb76545-pwz55
I0409 14:49:09.376706       1 scheduler.go:190] [PostBind] Pod gold-class-deploy-1-78bb76545-pwz55 - Binding start: 2025-04-09 14:49:09.369220225 +0000 UTC m=+34.056590653, Binding end: 2025-04-09 14:49:09.376703515 +0000 UTC m=+34.064073953
I0409 14:49:09.376722       1 scheduler.go:197] [PostBind] Metrics updated for pod gold-class-deploy-1-78bb76545-pwz55
I0409 14:49:09.384785       1 scheduler.go:255] [OnUpdatePod] Updating 'LastStatus' of pod default/gold-class-deploy-1-78bb76545-pwz55 in metrics
I0409 14:49:09.456568       1 default_preemption.go:51] [PreEnqueue] PreEnqueue called for pod: gold-class-deploy-2-58ff5bfb68-446gs
I0409 14:49:09.456647       1 default_preemption.go:52] [PreEnqueue] SchedulerName for pod gold-class-deploy-2-58ff5bfb68-446gs: custom-scheduler
E0409 14:49:09.456662       1 types.go:135] Controller gold-class-deploy-2-58ff5bfb68-446gs_default associated with , which is no valid QoS measure approach.
E0409 14:49:09.456680       1 types.go:564] Pod gold-class-deploy-2-58ff5bfb68-446gs_default with no valid QoS measure approach associated with.
I0409 14:49:09.456581       1 scheduler.go:205] [OnAddPod] Pod added: default/gold-class-deploy-2-58ff5bfb68-446gs, Annotations: map[acceptablePreemptionOverhead:0.05 controller:gold-controller-2 kwok.x-k8s.io/usage-cpu:1m kwok.x-k8s.io/usage-memory:1Mi qosMeasuring:average slo:1]
I0409 14:49:09.458837       1 scheduler.go:164] [PreBind] Validating pod gold-class-deploy-2-58ff5bfb68-446gs before binding to node kwok-node-1
I0409 14:49:09.466017       1 scheduler.go:172] [PostBind] Called for pod gold-class-deploy-2-58ff5bfb68-446gs
I0409 14:49:09.466047       1 scheduler.go:190] [PostBind] Pod gold-class-deploy-2-58ff5bfb68-446gs - Binding start: 2025-04-09 14:49:09.458855831 +0000 UTC m=+34.146226269, Binding end: 2025-04-09 14:49:09.466043354 +0000 UTC m=+34.153413802
I0409 14:49:09.466054       1 scheduler.go:255] [OnUpdatePod] Updating 'LastStatus' of pod default/gold-class-deploy-2-58ff5bfb68-446gs in metrics
I0409 14:49:09.466114       1 scheduler.go:197] [PostBind] Metrics updated for pod gold-class-deploy-2-58ff5bfb68-446gs
I0409 14:49:09.473303       1 scheduler.go:255] [OnUpdatePod] Updating 'LastStatus' of pod default/gold-class-deploy-2-58ff5bfb68-446gs in metrics
I0409 14:49:09.548610       1 default_preemption.go:51] [PreEnqueue] PreEnqueue called for pod: bronze-class-deploy-3-775f4fbdd9-d77dm
I0409 14:49:09.548635       1 default_preemption.go:52] [PreEnqueue] SchedulerName for pod bronze-class-deploy-3-775f4fbdd9-d77dm: custom-scheduler
E0409 14:49:09.548646       1 types.go:135] Controller bronze-class-deploy-3-775f4fbdd9-d77dm_default associated with , which is no valid QoS measure approach.
E0409 14:49:09.548652       1 types.go:564] Pod bronze-class-deploy-3-775f4fbdd9-d77dm_default with no valid QoS measure approach associated with.
I0409 14:49:09.548662       1 scheduler.go:205] [OnAddPod] Pod added: default/bronze-class-deploy-3-775f4fbdd9-d77dm, Annotations: map[acceptablePreemptionOverhead:0.05 controller:bronze-controller-3 kwok.x-k8s.io/usage-cpu:1m kwok.x-k8s.io/usage-memory:1Mi qosMeasuring:average slo:0.5]
I0409 14:49:09.550759       1 scheduler.go:164] [PreBind] Validating pod bronze-class-deploy-3-775f4fbdd9-d77dm before binding to node kwok-node-1
I0409 14:49:09.557352       1 scheduler.go:172] [PostBind] Called for pod bronze-class-deploy-3-775f4fbdd9-d77dm
I0409 14:49:09.557415       1 scheduler.go:190] [PostBind] Pod bronze-class-deploy-3-775f4fbdd9-d77dm - Binding start: 2025-04-09 14:49:09.550778393 +0000 UTC m=+34.238148831, Binding end: 2025-04-09 14:49:09.557411573 +0000 UTC m=+34.244782001
I0409 14:49:09.557435       1 scheduler.go:197] [PostBind] Metrics updated for pod bronze-class-deploy-3-775f4fbdd9-d77dm
I0409 14:49:09.557480       1 scheduler.go:255] [OnUpdatePod] Updating 'LastStatus' of pod default/bronze-class-deploy-3-775f4fbdd9-d77dm in metrics
I0409 14:49:09.565044       1 scheduler.go:255] [OnUpdatePod] Updating 'LastStatus' of pod default/bronze-class-deploy-3-775f4fbdd9-d77dm in metrics
I0409 14:49:09.639179       1 default_preemption.go:51] [PreEnqueue] PreEnqueue called for pod: gold-class-deploy-4-b6866bf4b-5dnw5
I0409 14:49:09.639204       1 default_preemption.go:52] [PreEnqueue] SchedulerName for pod gold-class-deploy-4-b6866bf4b-5dnw5: custom-scheduler
E0409 14:49:09.639217       1 types.go:135] Controller gold-class-deploy-4-b6866bf4b-5dnw5_default associated with , which is no valid QoS measure approach.
E0409 14:49:09.639222       1 types.go:564] Pod gold-class-deploy-4-b6866bf4b-5dnw5_default with no valid QoS measure approach associated with.
I0409 14:49:09.639215       1 scheduler.go:205] [OnAddPod] Pod added: default/gold-class-deploy-4-b6866bf4b-5dnw5, Annotations: map[acceptablePreemptionOverhead:0.05 controller:gold-controller-4 kwok.x-k8s.io/usage-cpu:1m kwok.x-k8s.io/usage-memory:1Mi qosMeasuring:average slo:1]
I0409 14:49:09.642426       1 scheduler.go:164] [PreBind] Validating pod gold-class-deploy-4-b6866bf4b-5dnw5 before binding to node kwok-node-1
I0409 14:49:09.648253       1 scheduler.go:172] [PostBind] Called for pod gold-class-deploy-4-b6866bf4b-5dnw5
I0409 14:49:09.648284       1 scheduler.go:255] [OnUpdatePod] Updating 'LastStatus' of pod default/gold-class-deploy-4-b6866bf4b-5dnw5 in metrics
I0409 14:49:09.648284       1 scheduler.go:190] [PostBind] Pod gold-class-deploy-4-b6866bf4b-5dnw5 - Binding start: 2025-04-09 14:49:09.642451019 +0000 UTC m=+34.329821447, Binding end: 2025-04-09 14:49:09.648281213 +0000 UTC m=+34.335651651
I0409 14:49:09.648301       1 scheduler.go:197] [PostBind] Metrics updated for pod gold-class-deploy-4-b6866bf4b-5dnw5
I0409 14:49:09.657315       1 scheduler.go:255] [OnUpdatePod] Updating 'LastStatus' of pod default/gold-class-deploy-4-b6866bf4b-5dnw5 in metrics
I0409 14:49:09.729992       1 default_preemption.go:51] [PreEnqueue] PreEnqueue called for pod: gold-class-deploy-5-c4557676f-pdmbf
I0409 14:49:09.730019       1 default_preemption.go:52] [PreEnqueue] SchedulerName for pod gold-class-deploy-5-c4557676f-pdmbf: custom-scheduler
E0409 14:49:09.730031       1 types.go:135] Controller gold-class-deploy-5-c4557676f-pdmbf_default associated with , which is no valid QoS measure approach.
E0409 14:49:09.730037       1 types.go:564] Pod gold-class-deploy-5-c4557676f-pdmbf_default with no valid QoS measure approach associated with.
I0409 14:49:09.730038       1 scheduler.go:205] [OnAddPod] Pod added: default/gold-class-deploy-5-c4557676f-pdmbf, Annotations: map[acceptablePreemptionOverhead:0.05 controller:gold-controller-5 kwok.x-k8s.io/usage-cpu:1m kwok.x-k8s.io/usage-memory:1Mi qosMeasuring:average slo:1]
I0409 14:49:09.732171       1 scheduler.go:164] [PreBind] Validating pod gold-class-deploy-5-c4557676f-pdmbf before binding to node kwok-node-1
I0409 14:49:09.738349       1 scheduler.go:255] [OnUpdatePod] Updating 'LastStatus' of pod default/gold-class-deploy-5-c4557676f-pdmbf in metrics
I0409 14:49:09.738433       1 scheduler.go:172] [PostBind] Called for pod gold-class-deploy-5-c4557676f-pdmbf
I0409 14:49:09.738447       1 scheduler.go:190] [PostBind] Pod gold-class-deploy-5-c4557676f-pdmbf - Binding start: 2025-04-09 14:49:09.732193212 +0000 UTC m=+34.419563650, Binding end: 2025-04-09 14:49:09.73844343 +0000 UTC m=+34.425813868
I0409 14:49:09.738463       1 scheduler.go:197] [PostBind] Metrics updated for pod gold-class-deploy-5-c4557676f-pdmbf
I0409 14:49:09.747493       1 scheduler.go:255] [OnUpdatePod] Updating 'LastStatus' of pod default/gold-class-deploy-5-c4557676f-pdmbf in metrics
I0409 14:49:09.821342       1 default_preemption.go:51] [PreEnqueue] PreEnqueue called for pod: gold-class-deploy-6-6df4d4d67b-bf8cr
I0409 14:49:09.821401       1 default_preemption.go:52] [PreEnqueue] SchedulerName for pod gold-class-deploy-6-6df4d4d67b-bf8cr: custom-scheduler
E0409 14:49:09.821413       1 types.go:135] Controller gold-class-deploy-6-6df4d4d67b-bf8cr_default associated with , which is no valid QoS measure approach.
E0409 14:49:09.821420       1 types.go:564] Pod gold-class-deploy-6-6df4d4d67b-bf8cr_default with no valid QoS measure approach associated with.
I0409 14:49:09.821349       1 scheduler.go:205] [OnAddPod] Pod added: default/gold-class-deploy-6-6df4d4d67b-bf8cr, Annotations: map[acceptablePreemptionOverhead:0.05 controller:gold-controller-6 kwok.x-k8s.io/usage-cpu:1m kwok.x-k8s.io/usage-memory:1Mi qosMeasuring:average slo:1]
I0409 14:49:09.827471       1 scheduler.go:164] [PreBind] Validating pod gold-class-deploy-6-6df4d4d67b-bf8cr before binding to node kwok-node-1
I0409 14:49:09.832937       1 scheduler.go:172] [PostBind] Called for pod gold-class-deploy-6-6df4d4d67b-bf8cr
I0409 14:49:09.832955       1 scheduler.go:190] [PostBind] Pod gold-class-deploy-6-6df4d4d67b-bf8cr - Binding start: 2025-04-09 14:49:09.827499413 +0000 UTC m=+34.514869851, Binding end: 2025-04-09 14:49:09.832952544 +0000 UTC m=+34.520322982
I0409 14:49:09.832974       1 scheduler.go:197] [PostBind] Metrics updated for pod gold-class-deploy-6-6df4d4d67b-bf8cr
I0409 14:49:09.832995       1 scheduler.go:255] [OnUpdatePod] Updating 'LastStatus' of pod default/gold-class-deploy-6-6df4d4d67b-bf8cr in metrics
I0409 14:49:09.840550       1 scheduler.go:255] [OnUpdatePod] Updating 'LastStatus' of pod default/gold-class-deploy-6-6df4d4d67b-bf8cr in metrics
I0409 14:49:09.963721       1 default_preemption.go:51] [PreEnqueue] PreEnqueue called for pod: silver-class-deploy-7-ff55f69ff-hwmfr
I0409 14:49:09.963769       1 default_preemption.go:52] [PreEnqueue] SchedulerName for pod silver-class-deploy-7-ff55f69ff-hwmfr: custom-scheduler
E0409 14:49:09.963781       1 types.go:135] Controller silver-class-deploy-7-ff55f69ff-hwmfr_default associated with , which is no valid QoS measure approach.
E0409 14:49:09.963787       1 types.go:564] Pod silver-class-deploy-7-ff55f69ff-hwmfr_default with no valid QoS measure approach associated with.
I0409 14:49:09.963721       1 scheduler.go:205] [OnAddPod] Pod added: default/silver-class-deploy-7-ff55f69ff-hwmfr, Annotations: map[acceptablePreemptionOverhead:0.05 controller:silver-controller-7 kwok.x-k8s.io/usage-cpu:1m kwok.x-k8s.io/usage-memory:1Mi qosMeasuring:average slo:0.9]
I0409 14:49:09.965771       1 scheduler.go:164] [PreBind] Validating pod silver-class-deploy-7-ff55f69ff-hwmfr before binding to node kwok-node-1
I0409 14:49:09.972785       1 scheduler.go:255] [OnUpdatePod] Updating 'LastStatus' of pod default/silver-class-deploy-7-ff55f69ff-hwmfr in metrics
I0409 14:49:09.972872       1 scheduler.go:172] [PostBind] Called for pod silver-class-deploy-7-ff55f69ff-hwmfr
I0409 14:49:09.972893       1 scheduler.go:190] [PostBind] Pod silver-class-deploy-7-ff55f69ff-hwmfr - Binding start: 2025-04-09 14:49:09.965789894 +0000 UTC m=+34.653160322, Binding end: 2025-04-09 14:49:09.972889732 +0000 UTC m=+34.660260160
I0409 14:49:09.972907       1 scheduler.go:197] [PostBind] Metrics updated for pod silver-class-deploy-7-ff55f69ff-hwmfr
I0409 14:49:09.981390       1 scheduler.go:255] [OnUpdatePod] Updating 'LastStatus' of pod default/silver-class-deploy-7-ff55f69ff-hwmfr in metrics
I0409 14:49:10.113262       1 default_preemption.go:51] [PreEnqueue] PreEnqueue called for pod: bronze-class-deploy-8-6fff566748-k8mmd
I0409 14:49:10.113285       1 default_preemption.go:52] [PreEnqueue] SchedulerName for pod bronze-class-deploy-8-6fff566748-k8mmd: custom-scheduler
E0409 14:49:10.113297       1 types.go:135] Controller bronze-class-deploy-8-6fff566748-k8mmd_default associated with , which is no valid QoS measure approach.
E0409 14:49:10.113304       1 types.go:564] Pod bronze-class-deploy-8-6fff566748-k8mmd_default with no valid QoS measure approach associated with.
I0409 14:49:10.113309       1 scheduler.go:205] [OnAddPod] Pod added: default/bronze-class-deploy-8-6fff566748-k8mmd, Annotations: map[acceptablePreemptionOverhead:0.05 controller:bronze-controller-8 kwok.x-k8s.io/usage-cpu:1m kwok.x-k8s.io/usage-memory:1Mi qosMeasuring:average slo:0.5]
I0409 14:49:10.115635       1 scheduler.go:164] [PreBind] Validating pod bronze-class-deploy-8-6fff566748-k8mmd before binding to node kwok-node-1
I0409 14:49:10.121750       1 scheduler.go:255] [OnUpdatePod] Updating 'LastStatus' of pod default/bronze-class-deploy-8-6fff566748-k8mmd in metrics
I0409 14:49:10.121803       1 scheduler.go:172] [PostBind] Called for pod bronze-class-deploy-8-6fff566748-k8mmd
I0409 14:49:10.121822       1 scheduler.go:190] [PostBind] Pod bronze-class-deploy-8-6fff566748-k8mmd - Binding start: 2025-04-09 14:49:10.115651146 +0000 UTC m=+34.803021574, Binding end: 2025-04-09 14:49:10.121819229 +0000 UTC m=+34.809189667
I0409 14:49:10.121845       1 scheduler.go:197] [PostBind] Metrics updated for pod bronze-class-deploy-8-6fff566748-k8mmd
I0409 14:49:10.131594       1 scheduler.go:255] [OnUpdatePod] Updating 'LastStatus' of pod default/bronze-class-deploy-8-6fff566748-k8mmd in metrics
I0409 14:49:10.214396       1 default_preemption.go:51] [PreEnqueue] PreEnqueue called for pod: gold-class-deploy-9-868dfbd94f-6hvv5
I0409 14:49:10.214423       1 default_preemption.go:52] [PreEnqueue] SchedulerName for pod gold-class-deploy-9-868dfbd94f-6hvv5: custom-scheduler
I0409 14:49:10.214412       1 scheduler.go:205] [OnAddPod] Pod added: default/gold-class-deploy-9-868dfbd94f-6hvv5, Annotations: map[acceptablePreemptionOverhead:0.05 controller:gold-controller-9 kwok.x-k8s.io/usage-cpu:1m kwok.x-k8s.io/usage-memory:1Mi qosMeasuring:average slo:1]
E0409 14:49:10.214436       1 types.go:135] Controller gold-class-deploy-9-868dfbd94f-6hvv5_default associated with , which is no valid QoS measure approach.
E0409 14:49:10.214443       1 types.go:564] Pod gold-class-deploy-9-868dfbd94f-6hvv5_default with no valid QoS measure approach associated with.
I0409 14:49:10.216779       1 scheduler.go:164] [PreBind] Validating pod gold-class-deploy-9-868dfbd94f-6hvv5 before binding to node kwok-node-1
I0409 14:49:10.224777       1 scheduler.go:172] [PostBind] Called for pod gold-class-deploy-9-868dfbd94f-6hvv5
I0409 14:49:10.224795       1 scheduler.go:190] [PostBind] Pod gold-class-deploy-9-868dfbd94f-6hvv5 - Binding start: 2025-04-09 14:49:10.21679658 +0000 UTC m=+34.904167018, Binding end: 2025-04-09 14:49:10.224792231 +0000 UTC m=+34.912162659
I0409 14:49:10.224826       1 scheduler.go:197] [PostBind] Metrics updated for pod gold-class-deploy-9-868dfbd94f-6hvv5
I0409 14:49:10.224960       1 scheduler.go:255] [OnUpdatePod] Updating 'LastStatus' of pod default/gold-class-deploy-9-868dfbd94f-6hvv5 in metrics
I0409 14:49:10.233042       1 scheduler.go:255] [OnUpdatePod] Updating 'LastStatus' of pod default/gold-class-deploy-9-868dfbd94f-6hvv5 in metrics
I0409 14:49:10.464114       1 default_preemption.go:51] [PreEnqueue] PreEnqueue called for pod: silver-class-deploy-10-6866d9b887-l2866
I0409 14:49:10.464142       1 default_preemption.go:52] [PreEnqueue] SchedulerName for pod silver-class-deploy-10-6866d9b887-l2866: custom-scheduler
E0409 14:49:10.464157       1 types.go:135] Controller silver-class-deploy-10-6866d9b887-l2866_default associated with , which is no valid QoS measure approach.
E0409 14:49:10.464164       1 types.go:564] Pod silver-class-deploy-10-6866d9b887-l2866_default with no valid QoS measure approach associated with.
I0409 14:49:10.464187       1 scheduler.go:205] [OnAddPod] Pod added: default/silver-class-deploy-10-6866d9b887-l2866, Annotations: map[acceptablePreemptionOverhead:0.05 controller:silver-controller-10 kwok.x-k8s.io/usage-cpu:1m kwok.x-k8s.io/usage-memory:1Mi qosMeasuring:average slo:0.9]
I0409 14:49:10.466191       1 scheduler.go:164] [PreBind] Validating pod silver-class-deploy-10-6866d9b887-l2866 before binding to node kwok-node-1
I0409 14:49:10.469304       1 scheduler.go:172] [PostBind] Called for pod silver-class-deploy-10-6866d9b887-l2866
I0409 14:49:10.469334       1 scheduler.go:190] [PostBind] Pod silver-class-deploy-10-6866d9b887-l2866 - Binding start: 2025-04-09 14:49:10.466206753 +0000 UTC m=+35.153577191, Binding end: 2025-04-09 14:49:10.469331347 +0000 UTC m=+35.156701775
I0409 14:49:10.469351       1 scheduler.go:197] [PostBind] Metrics updated for pod silver-class-deploy-10-6866d9b887-l2866
I0409 14:49:10.469460       1 scheduler.go:255] [OnUpdatePod] Updating 'LastStatus' of pod default/silver-class-deploy-10-6866d9b887-l2866 in metrics
I0409 14:49:10.475490       1 scheduler.go:255] [OnUpdatePod] Updating 'LastStatus' of pod default/silver-class-deploy-10-6866d9b887-l2866 in metrics
I0409 14:49:10.612576       1 default_preemption.go:51] [PreEnqueue] PreEnqueue called for pod: bronze-class-deploy-11-559c656b44-cgqs5
I0409 14:49:10.612598       1 default_preemption.go:52] [PreEnqueue] SchedulerName for pod bronze-class-deploy-11-559c656b44-cgqs5: custom-scheduler
E0409 14:49:10.612609       1 types.go:135] Controller bronze-class-deploy-11-559c656b44-cgqs5_default associated with , which is no valid QoS measure approach.
E0409 14:49:10.612616       1 types.go:564] Pod bronze-class-deploy-11-559c656b44-cgqs5_default with no valid QoS measure approach associated with.
I0409 14:49:10.612629       1 scheduler.go:205] [OnAddPod] Pod added: default/bronze-class-deploy-11-559c656b44-cgqs5, Annotations: map[acceptablePreemptionOverhead:0.05 controller:bronze-controller-11 kwok.x-k8s.io/usage-cpu:1m kwok.x-k8s.io/usage-memory:1Mi qosMeasuring:average slo:0.5]
I0409 14:49:10.614509       1 scheduler.go:164] [PreBind] Validating pod bronze-class-deploy-11-559c656b44-cgqs5 before binding to node kwok-node-1
I0409 14:49:10.619684       1 scheduler.go:172] [PostBind] Called for pod bronze-class-deploy-11-559c656b44-cgqs5
I0409 14:49:10.619711       1 scheduler.go:190] [PostBind] Pod bronze-class-deploy-11-559c656b44-cgqs5 - Binding start: 2025-04-09 14:49:10.614522894 +0000 UTC m=+35.301893322, Binding end: 2025-04-09 14:49:10.619707769 +0000 UTC m=+35.307078207
I0409 14:49:10.619730       1 scheduler.go:197] [PostBind] Metrics updated for pod bronze-class-deploy-11-559c656b44-cgqs5
I0409 14:49:10.619791       1 scheduler.go:255] [OnUpdatePod] Updating 'LastStatus' of pod default/bronze-class-deploy-11-559c656b44-cgqs5 in metrics
I0409 14:49:10.627908       1 scheduler.go:255] [OnUpdatePod] Updating 'LastStatus' of pod default/bronze-class-deploy-11-559c656b44-cgqs5 in metrics
I0409 14:49:10.811915       1 default_preemption.go:51] [PreEnqueue] PreEnqueue called for pod: gold-class-deploy-12-598494bf8f-jqzbs
I0409 14:49:10.811937       1 default_preemption.go:52] [PreEnqueue] SchedulerName for pod gold-class-deploy-12-598494bf8f-jqzbs: custom-scheduler
E0409 14:49:10.811948       1 types.go:135] Controller gold-class-deploy-12-598494bf8f-jqzbs_default associated with , which is no valid QoS measure approach.
E0409 14:49:10.811955       1 types.go:564] Pod gold-class-deploy-12-598494bf8f-jqzbs_default with no valid QoS measure approach associated with.
I0409 14:49:10.811954       1 scheduler.go:205] [OnAddPod] Pod added: default/gold-class-deploy-12-598494bf8f-jqzbs, Annotations: map[acceptablePreemptionOverhead:0.05 controller:gold-controller-12 kwok.x-k8s.io/usage-cpu:1m kwok.x-k8s.io/usage-memory:1Mi qosMeasuring:average slo:1]
I0409 14:49:10.813876       1 scheduler.go:164] [PreBind] Validating pod gold-class-deploy-12-598494bf8f-jqzbs before binding to node kwok-node-1
I0409 14:49:10.819610       1 scheduler.go:172] [PostBind] Called for pod gold-class-deploy-12-598494bf8f-jqzbs
I0409 14:49:10.819652       1 scheduler.go:190] [PostBind] Pod gold-class-deploy-12-598494bf8f-jqzbs - Binding start: 2025-04-09 14:49:10.81389274 +0000 UTC m=+35.501263178, Binding end: 2025-04-09 14:49:10.819647469 +0000 UTC m=+35.507017907
I0409 14:49:10.819681       1 scheduler.go:197] [PostBind] Metrics updated for pod gold-class-deploy-12-598494bf8f-jqzbs
I0409 14:49:10.820064       1 scheduler.go:255] [OnUpdatePod] Updating 'LastStatus' of pod default/gold-class-deploy-12-598494bf8f-jqzbs in metrics
I0409 14:49:10.827179       1 scheduler.go:255] [OnUpdatePod] Updating 'LastStatus' of pod default/gold-class-deploy-12-598494bf8f-jqzbs in metrics
I0409 14:49:11.011319       1 scheduler.go:205] [OnAddPod] Pod added: default/gold-class-deploy-13-5f585cb744-n2l5p, Annotations: map[acceptablePreemptionOverhead:0.05 controller:gold-controller-13 kwok.x-k8s.io/usage-cpu:1m kwok.x-k8s.io/usage-memory:1Mi qosMeasuring:average slo:1]
I0409 14:49:11.011393       1 default_preemption.go:51] [PreEnqueue] PreEnqueue called for pod: gold-class-deploy-13-5f585cb744-n2l5p
I0409 14:49:11.011405       1 default_preemption.go:52] [PreEnqueue] SchedulerName for pod gold-class-deploy-13-5f585cb744-n2l5p: custom-scheduler
E0409 14:49:11.011415       1 types.go:135] Controller gold-class-deploy-13-5f585cb744-n2l5p_default associated with , which is no valid QoS measure approach.
E0409 14:49:11.011421       1 types.go:564] Pod gold-class-deploy-13-5f585cb744-n2l5p_default with no valid QoS measure approach associated with.
I0409 14:49:11.013554       1 scheduler.go:164] [PreBind] Validating pod gold-class-deploy-13-5f585cb744-n2l5p before binding to node kwok-node-1
I0409 14:49:11.018865       1 scheduler.go:172] [PostBind] Called for pod gold-class-deploy-13-5f585cb744-n2l5p
I0409 14:49:11.018893       1 scheduler.go:190] [PostBind] Pod gold-class-deploy-13-5f585cb744-n2l5p - Binding start: 2025-04-09 14:49:11.013578486 +0000 UTC m=+35.700948914, Binding end: 2025-04-09 14:49:11.018889518 +0000 UTC m=+35.706259956
I0409 14:49:11.018913       1 scheduler.go:197] [PostBind] Metrics updated for pod gold-class-deploy-13-5f585cb744-n2l5p
I0409 14:49:11.018959       1 scheduler.go:255] [OnUpdatePod] Updating 'LastStatus' of pod default/gold-class-deploy-13-5f585cb744-n2l5p in metrics
I0409 14:49:11.026748       1 scheduler.go:255] [OnUpdatePod] Updating 'LastStatus' of pod default/gold-class-deploy-13-5f585cb744-n2l5p in metrics
I0409 14:49:11.215513       1 default_preemption.go:51] [PreEnqueue] PreEnqueue called for pod: silver-class-deploy-14-79f95c48b7-jh9nd
I0409 14:49:11.215540       1 default_preemption.go:52] [PreEnqueue] SchedulerName for pod silver-class-deploy-14-79f95c48b7-jh9nd: custom-scheduler
I0409 14:49:11.215522       1 scheduler.go:205] [OnAddPod] Pod added: default/silver-class-deploy-14-79f95c48b7-jh9nd, Annotations: map[acceptablePreemptionOverhead:0.05 controller:silver-controller-14 kwok.x-k8s.io/usage-cpu:1m kwok.x-k8s.io/usage-memory:1Mi qosMeasuring:average slo:0.9]
E0409 14:49:11.215552       1 types.go:135] Controller silver-class-deploy-14-79f95c48b7-jh9nd_default associated with , which is no valid QoS measure approach.
E0409 14:49:11.215558       1 types.go:564] Pod silver-class-deploy-14-79f95c48b7-jh9nd_default with no valid QoS measure approach associated with.
I0409 14:49:11.217581       1 scheduler.go:164] [PreBind] Validating pod silver-class-deploy-14-79f95c48b7-jh9nd before binding to node kwok-node-1
I0409 14:49:11.220623       1 scheduler.go:172] [PostBind] Called for pod silver-class-deploy-14-79f95c48b7-jh9nd
I0409 14:49:11.220651       1 scheduler.go:190] [PostBind] Pod silver-class-deploy-14-79f95c48b7-jh9nd - Binding start: 2025-04-09 14:49:11.217600956 +0000 UTC m=+35.904971394, Binding end: 2025-04-09 14:49:11.220647395 +0000 UTC m=+35.908017833
I0409 14:49:11.220672       1 scheduler.go:197] [PostBind] Metrics updated for pod silver-class-deploy-14-79f95c48b7-jh9nd
I0409 14:49:11.220723       1 scheduler.go:255] [OnUpdatePod] Updating 'LastStatus' of pod default/silver-class-deploy-14-79f95c48b7-jh9nd in metrics
I0409 14:49:11.228913       1 scheduler.go:255] [OnUpdatePod] Updating 'LastStatus' of pod default/silver-class-deploy-14-79f95c48b7-jh9nd in metrics
I0409 14:49:11.463459       1 default_preemption.go:51] [PreEnqueue] PreEnqueue called for pod: silver-class-deploy-15-cb96c7dc4-9m85g
I0409 14:49:11.463481       1 default_preemption.go:52] [PreEnqueue] SchedulerName for pod silver-class-deploy-15-cb96c7dc4-9m85g: custom-scheduler
I0409 14:49:11.463471       1 scheduler.go:205] [OnAddPod] Pod added: default/silver-class-deploy-15-cb96c7dc4-9m85g, Annotations: map[acceptablePreemptionOverhead:0.05 controller:silver-controller-15 kwok.x-k8s.io/usage-cpu:1m kwok.x-k8s.io/usage-memory:1Mi qosMeasuring:average slo:0.9]
E0409 14:49:11.463493       1 types.go:135] Controller silver-class-deploy-15-cb96c7dc4-9m85g_default associated with , which is no valid QoS measure approach.
E0409 14:49:11.463500       1 types.go:564] Pod silver-class-deploy-15-cb96c7dc4-9m85g_default with no valid QoS measure approach associated with.
I0409 14:49:11.465283       1 scheduler.go:164] [PreBind] Validating pod silver-class-deploy-15-cb96c7dc4-9m85g before binding to node kwok-node-1
I0409 14:49:11.470205       1 scheduler.go:172] [PostBind] Called for pod silver-class-deploy-15-cb96c7dc4-9m85g
I0409 14:49:11.470228       1 scheduler.go:190] [PostBind] Pod silver-class-deploy-15-cb96c7dc4-9m85g - Binding start: 2025-04-09 14:49:11.465296628 +0000 UTC m=+36.152667066, Binding end: 2025-04-09 14:49:11.470224508 +0000 UTC m=+36.157594936
I0409 14:49:11.470242       1 scheduler.go:255] [OnUpdatePod] Updating 'LastStatus' of pod default/silver-class-deploy-15-cb96c7dc4-9m85g in metrics
I0409 14:49:11.470261       1 scheduler.go:197] [PostBind] Metrics updated for pod silver-class-deploy-15-cb96c7dc4-9m85g
I0409 14:49:11.477680       1 scheduler.go:255] [OnUpdatePod] Updating 'LastStatus' of pod default/silver-class-deploy-15-cb96c7dc4-9m85g in metrics
I0409 14:49:11.661210       1 default_preemption.go:51] [PreEnqueue] PreEnqueue called for pod: bronze-class-deploy-16-74dd4696ff-7zksw
I0409 14:49:11.661234       1 default_preemption.go:52] [PreEnqueue] SchedulerName for pod bronze-class-deploy-16-74dd4696ff-7zksw: custom-scheduler
I0409 14:49:11.661227       1 scheduler.go:205] [OnAddPod] Pod added: default/bronze-class-deploy-16-74dd4696ff-7zksw, Annotations: map[acceptablePreemptionOverhead:0.05 controller:bronze-controller-16 kwok.x-k8s.io/usage-cpu:1m kwok.x-k8s.io/usage-memory:1Mi qosMeasuring:average slo:0.5]
E0409 14:49:11.661244       1 types.go:135] Controller bronze-class-deploy-16-74dd4696ff-7zksw_default associated with , which is no valid QoS measure approach.
E0409 14:49:11.661431       1 types.go:564] Pod bronze-class-deploy-16-74dd4696ff-7zksw_default with no valid QoS measure approach associated with.
I0409 14:49:11.663333       1 scheduler.go:164] [PreBind] Validating pod bronze-class-deploy-16-74dd4696ff-7zksw before binding to node kwok-node-1
I0409 14:49:11.668659       1 scheduler.go:172] [PostBind] Called for pod bronze-class-deploy-16-74dd4696ff-7zksw
I0409 14:49:11.668687       1 scheduler.go:255] [OnUpdatePod] Updating 'LastStatus' of pod default/bronze-class-deploy-16-74dd4696ff-7zksw in metrics
I0409 14:49:11.668694       1 scheduler.go:190] [PostBind] Pod bronze-class-deploy-16-74dd4696ff-7zksw - Binding start: 2025-04-09 14:49:11.663349817 +0000 UTC m=+36.350720255, Binding end: 2025-04-09 14:49:11.668689871 +0000 UTC m=+36.356060309
I0409 14:49:11.668716       1 scheduler.go:197] [PostBind] Metrics updated for pod bronze-class-deploy-16-74dd4696ff-7zksw
I0409 14:49:11.676452       1 scheduler.go:255] [OnUpdatePod] Updating 'LastStatus' of pod default/bronze-class-deploy-16-74dd4696ff-7zksw in metrics
I0409 14:49:11.865655       1 default_preemption.go:51] [PreEnqueue] PreEnqueue called for pod: silver-class-deploy-17-59cbf4bc88-s2ngm
I0409 14:49:11.865683       1 default_preemption.go:52] [PreEnqueue] SchedulerName for pod silver-class-deploy-17-59cbf4bc88-s2ngm: custom-scheduler
E0409 14:49:11.865695       1 types.go:135] Controller silver-class-deploy-17-59cbf4bc88-s2ngm_default associated with , which is no valid QoS measure approach.
E0409 14:49:11.865703       1 types.go:564] Pod silver-class-deploy-17-59cbf4bc88-s2ngm_default with no valid QoS measure approach associated with.
I0409 14:49:11.865704       1 scheduler.go:205] [OnAddPod] Pod added: default/silver-class-deploy-17-59cbf4bc88-s2ngm, Annotations: map[acceptablePreemptionOverhead:0.05 controller:silver-controller-17 kwok.x-k8s.io/usage-cpu:1m kwok.x-k8s.io/usage-memory:1Mi qosMeasuring:average slo:0.9]
I0409 14:49:11.867724       1 scheduler.go:164] [PreBind] Validating pod silver-class-deploy-17-59cbf4bc88-s2ngm before binding to node kwok-node-1
I0409 14:49:11.870802       1 scheduler.go:172] [PostBind] Called for pod silver-class-deploy-17-59cbf4bc88-s2ngm
I0409 14:49:11.870832       1 scheduler.go:190] [PostBind] Pod silver-class-deploy-17-59cbf4bc88-s2ngm - Binding start: 2025-04-09 14:49:11.867738009 +0000 UTC m=+36.555108437, Binding end: 2025-04-09 14:49:11.870828631 +0000 UTC m=+36.558199069
I0409 14:49:11.870852       1 scheduler.go:197] [PostBind] Metrics updated for pod silver-class-deploy-17-59cbf4bc88-s2ngm
I0409 14:49:11.870890       1 scheduler.go:255] [OnUpdatePod] Updating 'LastStatus' of pod default/silver-class-deploy-17-59cbf4bc88-s2ngm in metrics
I0409 14:49:11.876813       1 scheduler.go:255] [OnUpdatePod] Updating 'LastStatus' of pod default/silver-class-deploy-17-59cbf4bc88-s2ngm in metrics
I0409 14:49:12.010855       1 scheduler.go:205] [OnAddPod] Pod added: default/silver-class-deploy-18-5dd44b47c5-7d2lh, Annotations: map[acceptablePreemptionOverhead:0.05 controller:silver-controller-18 kwok.x-k8s.io/usage-cpu:1m kwok.x-k8s.io/usage-memory:1Mi qosMeasuring:average slo:0.9]
I0409 14:49:12.010888       1 default_preemption.go:51] [PreEnqueue] PreEnqueue called for pod: silver-class-deploy-18-5dd44b47c5-7d2lh
I0409 14:49:12.010900       1 default_preemption.go:52] [PreEnqueue] SchedulerName for pod silver-class-deploy-18-5dd44b47c5-7d2lh: custom-scheduler
E0409 14:49:12.010912       1 types.go:135] Controller silver-class-deploy-18-5dd44b47c5-7d2lh_default associated with , which is no valid QoS measure approach.
E0409 14:49:12.010919       1 types.go:564] Pod silver-class-deploy-18-5dd44b47c5-7d2lh_default with no valid QoS measure approach associated with.
I0409 14:49:12.012852       1 scheduler.go:164] [PreBind] Validating pod silver-class-deploy-18-5dd44b47c5-7d2lh before binding to node kwok-node-1
I0409 14:49:12.017852       1 scheduler.go:255] [OnUpdatePod] Updating 'LastStatus' of pod default/silver-class-deploy-18-5dd44b47c5-7d2lh in metrics
I0409 14:49:12.017871       1 scheduler.go:172] [PostBind] Called for pod silver-class-deploy-18-5dd44b47c5-7d2lh
I0409 14:49:12.017883       1 scheduler.go:190] [PostBind] Pod silver-class-deploy-18-5dd44b47c5-7d2lh - Binding start: 2025-04-09 14:49:12.012868743 +0000 UTC m=+36.700239171, Binding end: 2025-04-09 14:49:12.017880498 +0000 UTC m=+36.705250936
I0409 14:49:12.017898       1 scheduler.go:197] [PostBind] Metrics updated for pod silver-class-deploy-18-5dd44b47c5-7d2lh
I0409 14:49:12.025190       1 scheduler.go:255] [OnUpdatePod] Updating 'LastStatus' of pod default/silver-class-deploy-18-5dd44b47c5-7d2lh in metrics
I0409 14:49:12.062248       1 default_preemption.go:51] [PreEnqueue] PreEnqueue called for pod: silver-class-deploy-19-7cc4c5b78-v9p7f
I0409 14:49:12.062269       1 default_preemption.go:52] [PreEnqueue] SchedulerName for pod silver-class-deploy-19-7cc4c5b78-v9p7f: custom-scheduler
I0409 14:49:12.062267       1 scheduler.go:205] [OnAddPod] Pod added: default/silver-class-deploy-19-7cc4c5b78-v9p7f, Annotations: map[acceptablePreemptionOverhead:0.05 controller:silver-controller-19 kwok.x-k8s.io/usage-cpu:1m kwok.x-k8s.io/usage-memory:1Mi qosMeasuring:average slo:0.9]
E0409 14:49:12.062279       1 types.go:135] Controller silver-class-deploy-19-7cc4c5b78-v9p7f_default associated with , which is no valid QoS measure approach.
E0409 14:49:12.062286       1 types.go:564] Pod silver-class-deploy-19-7cc4c5b78-v9p7f_default with no valid QoS measure approach associated with.
I0409 14:49:12.064117       1 scheduler.go:164] [PreBind] Validating pod silver-class-deploy-19-7cc4c5b78-v9p7f before binding to node kwok-node-1
I0409 14:49:12.071718       1 scheduler.go:172] [PostBind] Called for pod silver-class-deploy-19-7cc4c5b78-v9p7f
I0409 14:49:12.071746       1 scheduler.go:190] [PostBind] Pod silver-class-deploy-19-7cc4c5b78-v9p7f - Binding start: 2025-04-09 14:49:12.064134931 +0000 UTC m=+36.751505369, Binding end: 2025-04-09 14:49:12.071743769 +0000 UTC m=+36.759114197
I0409 14:49:12.071763       1 scheduler.go:197] [PostBind] Metrics updated for pod silver-class-deploy-19-7cc4c5b78-v9p7f
I0409 14:49:12.071812       1 scheduler.go:255] [OnUpdatePod] Updating 'LastStatus' of pod default/silver-class-deploy-19-7cc4c5b78-v9p7f in metrics
I0409 14:49:12.079993       1 scheduler.go:255] [OnUpdatePod] Updating 'LastStatus' of pod default/silver-class-deploy-19-7cc4c5b78-v9p7f in metrics
I0409 14:49:12.463873       1 default_preemption.go:51] [PreEnqueue] PreEnqueue called for pod: bronze-class-deploy-20-5fd9977fb4-wdm7w
I0409 14:49:12.463893       1 default_preemption.go:52] [PreEnqueue] SchedulerName for pod bronze-class-deploy-20-5fd9977fb4-wdm7w: custom-scheduler
E0409 14:49:12.463903       1 types.go:135] Controller bronze-class-deploy-20-5fd9977fb4-wdm7w_default associated with , which is no valid QoS measure approach.
E0409 14:49:12.463908       1 types.go:564] Pod bronze-class-deploy-20-5fd9977fb4-wdm7w_default with no valid QoS measure approach associated with.
I0409 14:49:12.463900       1 scheduler.go:205] [OnAddPod] Pod added: default/bronze-class-deploy-20-5fd9977fb4-wdm7w, Annotations: map[acceptablePreemptionOverhead:0.05 controller:bronze-controller-20 kwok.x-k8s.io/usage-cpu:1m kwok.x-k8s.io/usage-memory:1Mi qosMeasuring:average slo:0.5]
I0409 14:49:12.466183       1 scheduler.go:164] [PreBind] Validating pod bronze-class-deploy-20-5fd9977fb4-wdm7w before binding to node kwok-node-1
I0409 14:49:12.470654       1 scheduler.go:255] [OnUpdatePod] Updating 'LastStatus' of pod default/bronze-class-deploy-20-5fd9977fb4-wdm7w in metrics
I0409 14:49:12.470712       1 scheduler.go:172] [PostBind] Called for pod bronze-class-deploy-20-5fd9977fb4-wdm7w
I0409 14:49:12.470723       1 scheduler.go:190] [PostBind] Pod bronze-class-deploy-20-5fd9977fb4-wdm7w - Binding start: 2025-04-09 14:49:12.46620259 +0000 UTC m=+37.153573028, Binding end: 2025-04-09 14:49:12.470720096 +0000 UTC m=+37.158090524
I0409 14:49:12.470738       1 scheduler.go:197] [PostBind] Metrics updated for pod bronze-class-deploy-20-5fd9977fb4-wdm7w
I0409 14:49:12.477757       1 scheduler.go:255] [OnUpdatePod] Updating 'LastStatus' of pod default/bronze-class-deploy-20-5fd9977fb4-wdm7w in metrics
I0409 14:49:12.964117       1 default_preemption.go:51] [PreEnqueue] PreEnqueue called for pod: silver-class-deploy-21-7bf557854c-zflrc
I0409 14:49:12.964142       1 default_preemption.go:52] [PreEnqueue] SchedulerName for pod silver-class-deploy-21-7bf557854c-zflrc: custom-scheduler
E0409 14:49:12.964152       1 types.go:135] Controller silver-class-deploy-21-7bf557854c-zflrc_default associated with , which is no valid QoS measure approach.
E0409 14:49:12.964158       1 types.go:564] Pod silver-class-deploy-21-7bf557854c-zflrc_default with no valid QoS measure approach associated with.
I0409 14:49:12.964172       1 scheduler.go:205] [OnAddPod] Pod added: default/silver-class-deploy-21-7bf557854c-zflrc, Annotations: map[acceptablePreemptionOverhead:0.05 controller:silver-controller-21 kwok.x-k8s.io/usage-cpu:1m kwok.x-k8s.io/usage-memory:1Mi qosMeasuring:average slo:0.9]
I0409 14:49:12.966224       1 scheduler.go:164] [PreBind] Validating pod silver-class-deploy-21-7bf557854c-zflrc before binding to node kwok-node-1
I0409 14:49:12.973870       1 scheduler.go:172] [PostBind] Called for pod silver-class-deploy-21-7bf557854c-zflrc
I0409 14:49:12.973931       1 scheduler.go:190] [PostBind] Pod silver-class-deploy-21-7bf557854c-zflrc - Binding start: 2025-04-09 14:49:12.966242667 +0000 UTC m=+37.653613105, Binding end: 2025-04-09 14:49:12.973895957 +0000 UTC m=+37.661266395
I0409 14:49:12.973951       1 scheduler.go:197] [PostBind] Metrics updated for pod silver-class-deploy-21-7bf557854c-zflrc
I0409 14:49:12.973995       1 scheduler.go:255] [OnUpdatePod] Updating 'LastStatus' of pod default/silver-class-deploy-21-7bf557854c-zflrc in metrics
I0409 14:49:12.980079       1 scheduler.go:255] [OnUpdatePod] Updating 'LastStatus' of pod default/silver-class-deploy-21-7bf557854c-zflrc in metrics
I0409 14:49:13.164587       1 default_preemption.go:51] [PreEnqueue] PreEnqueue called for pod: silver-class-deploy-22-8456bfbbc6-jrczs
I0409 14:49:13.164606       1 default_preemption.go:52] [PreEnqueue] SchedulerName for pod silver-class-deploy-22-8456bfbbc6-jrczs: custom-scheduler
E0409 14:49:13.164616       1 types.go:135] Controller silver-class-deploy-22-8456bfbbc6-jrczs_default associated with , which is no valid QoS measure approach.
E0409 14:49:13.164622       1 types.go:564] Pod silver-class-deploy-22-8456bfbbc6-jrczs_default with no valid QoS measure approach associated with.
I0409 14:49:13.164648       1 scheduler.go:205] [OnAddPod] Pod added: default/silver-class-deploy-22-8456bfbbc6-jrczs, Annotations: map[acceptablePreemptionOverhead:0.05 controller:silver-controller-22 kwok.x-k8s.io/usage-cpu:1m kwok.x-k8s.io/usage-memory:1Mi qosMeasuring:average slo:0.9]
I0409 14:49:13.166651       1 scheduler.go:164] [PreBind] Validating pod silver-class-deploy-22-8456bfbbc6-jrczs before binding to node kwok-node-1
I0409 14:49:13.173550       1 scheduler.go:172] [PostBind] Called for pod silver-class-deploy-22-8456bfbbc6-jrczs
I0409 14:49:13.173576       1 scheduler.go:190] [PostBind] Pod silver-class-deploy-22-8456bfbbc6-jrczs - Binding start: 2025-04-09 14:49:13.166667475 +0000 UTC m=+37.854037903, Binding end: 2025-04-09 14:49:13.173572592 +0000 UTC m=+37.860943030
I0409 14:49:13.173599       1 scheduler.go:197] [PostBind] Metrics updated for pod silver-class-deploy-22-8456bfbbc6-jrczs
I0409 14:49:13.173806       1 scheduler.go:255] [OnUpdatePod] Updating 'LastStatus' of pod default/silver-class-deploy-22-8456bfbbc6-jrczs in metrics
I0409 14:49:13.180041       1 scheduler.go:255] [OnUpdatePod] Updating 'LastStatus' of pod default/silver-class-deploy-22-8456bfbbc6-jrczs in metrics
I0409 14:49:13.212941       1 default_preemption.go:51] [PreEnqueue] PreEnqueue called for pod: bronze-class-deploy-23-654ffb5cc5-klsrd
I0409 14:49:13.212970       1 default_preemption.go:52] [PreEnqueue] SchedulerName for pod bronze-class-deploy-23-654ffb5cc5-klsrd: custom-scheduler
I0409 14:49:13.212960       1 scheduler.go:205] [OnAddPod] Pod added: default/bronze-class-deploy-23-654ffb5cc5-klsrd, Annotations: map[acceptablePreemptionOverhead:0.05 controller:bronze-controller-23 kwok.x-k8s.io/usage-cpu:1m kwok.x-k8s.io/usage-memory:1Mi qosMeasuring:average slo:0.5]
E0409 14:49:13.212982       1 types.go:135] Controller bronze-class-deploy-23-654ffb5cc5-klsrd_default associated with , which is no valid QoS measure approach.
E0409 14:49:13.212991       1 types.go:564] Pod bronze-class-deploy-23-654ffb5cc5-klsrd_default with no valid QoS measure approach associated with.
I0409 14:49:13.214861       1 scheduler.go:164] [PreBind] Validating pod bronze-class-deploy-23-654ffb5cc5-klsrd before binding to node kwok-node-1
I0409 14:49:13.221583       1 scheduler.go:172] [PostBind] Called for pod bronze-class-deploy-23-654ffb5cc5-klsrd
I0409 14:49:13.221607       1 scheduler.go:190] [PostBind] Pod bronze-class-deploy-23-654ffb5cc5-klsrd - Binding start: 2025-04-09 14:49:13.214883714 +0000 UTC m=+37.902254152, Binding end: 2025-04-09 14:49:13.221604339 +0000 UTC m=+37.908974777
I0409 14:49:13.221625       1 scheduler.go:197] [PostBind] Metrics updated for pod bronze-class-deploy-23-654ffb5cc5-klsrd
I0409 14:49:13.221654       1 scheduler.go:255] [OnUpdatePod] Updating 'LastStatus' of pod default/bronze-class-deploy-23-654ffb5cc5-klsrd in metrics
I0409 14:49:13.229321       1 scheduler.go:255] [OnUpdatePod] Updating 'LastStatus' of pod default/bronze-class-deploy-23-654ffb5cc5-klsrd in metrics
I0409 14:49:13.463121       1 default_preemption.go:51] [PreEnqueue] PreEnqueue called for pod: bronze-class-deploy-24-668b49b99b-rdj8z
I0409 14:49:13.463131       1 scheduler.go:205] [OnAddPod] Pod added: default/bronze-class-deploy-24-668b49b99b-rdj8z, Annotations: map[acceptablePreemptionOverhead:0.05 controller:bronze-controller-24 kwok.x-k8s.io/usage-cpu:1m kwok.x-k8s.io/usage-memory:1Mi qosMeasuring:average slo:0.5]
I0409 14:49:13.463150       1 default_preemption.go:52] [PreEnqueue] SchedulerName for pod bronze-class-deploy-24-668b49b99b-rdj8z: custom-scheduler
E0409 14:49:13.463161       1 types.go:135] Controller bronze-class-deploy-24-668b49b99b-rdj8z_default associated with , which is no valid QoS measure approach.
E0409 14:49:13.463168       1 types.go:564] Pod bronze-class-deploy-24-668b49b99b-rdj8z_default with no valid QoS measure approach associated with.
I0409 14:49:13.465038       1 scheduler.go:164] [PreBind] Validating pod bronze-class-deploy-24-668b49b99b-rdj8z before binding to node kwok-node-1
I0409 14:49:13.470044       1 scheduler.go:255] [OnUpdatePod] Updating 'LastStatus' of pod default/bronze-class-deploy-24-668b49b99b-rdj8z in metrics
I0409 14:49:13.470046       1 scheduler.go:172] [PostBind] Called for pod bronze-class-deploy-24-668b49b99b-rdj8z
I0409 14:49:13.470093       1 scheduler.go:190] [PostBind] Pod bronze-class-deploy-24-668b49b99b-rdj8z - Binding start: 2025-04-09 14:49:13.465054261 +0000 UTC m=+38.152424699, Binding end: 2025-04-09 14:49:13.470088457 +0000 UTC m=+38.157459015
I0409 14:49:13.470108       1 scheduler.go:197] [PostBind] Metrics updated for pod bronze-class-deploy-24-668b49b99b-rdj8z
I0409 14:49:13.477519       1 scheduler.go:255] [OnUpdatePod] Updating 'LastStatus' of pod default/bronze-class-deploy-24-668b49b99b-rdj8z in metrics
I0409 14:49:13.711752       1 default_preemption.go:51] [PreEnqueue] PreEnqueue called for pod: bronze-class-deploy-25-b94944fb5-x4ztm
I0409 14:49:13.711780       1 default_preemption.go:52] [PreEnqueue] SchedulerName for pod bronze-class-deploy-25-b94944fb5-x4ztm: custom-scheduler
I0409 14:49:13.711777       1 scheduler.go:205] [OnAddPod] Pod added: default/bronze-class-deploy-25-b94944fb5-x4ztm, Annotations: map[acceptablePreemptionOverhead:0.05 controller:bronze-controller-25 kwok.x-k8s.io/usage-cpu:1m kwok.x-k8s.io/usage-memory:1Mi qosMeasuring:average slo:0.5]
E0409 14:49:13.711793       1 types.go:135] Controller bronze-class-deploy-25-b94944fb5-x4ztm_default associated with , which is no valid QoS measure approach.
E0409 14:49:13.711949       1 types.go:564] Pod bronze-class-deploy-25-b94944fb5-x4ztm_default with no valid QoS measure approach associated with.
I0409 14:49:13.714218       1 scheduler.go:164] [PreBind] Validating pod bronze-class-deploy-25-b94944fb5-x4ztm before binding to node kwok-node-1
I0409 14:49:13.719457       1 scheduler.go:172] [PostBind] Called for pod bronze-class-deploy-25-b94944fb5-x4ztm
I0409 14:49:13.719499       1 scheduler.go:190] [PostBind] Pod bronze-class-deploy-25-b94944fb5-x4ztm - Binding start: 2025-04-09 14:49:13.71423805 +0000 UTC m=+38.401608488, Binding end: 2025-04-09 14:49:13.719483269 +0000 UTC m=+38.406853707
I0409 14:49:13.719520       1 scheduler.go:197] [PostBind] Metrics updated for pod bronze-class-deploy-25-b94944fb5-x4ztm
I0409 14:49:13.719545       1 scheduler.go:255] [OnUpdatePod] Updating 'LastStatus' of pod default/bronze-class-deploy-25-b94944fb5-x4ztm in metrics
I0409 14:49:13.727106       1 scheduler.go:255] [OnUpdatePod] Updating 'LastStatus' of pod default/bronze-class-deploy-25-b94944fb5-x4ztm in metrics
I0409 14:49:14.112526       1 default_preemption.go:51] [PreEnqueue] PreEnqueue called for pod: gold-class-deploy-26-6bcb7b6c88-6jh2g
I0409 14:49:14.112544       1 default_preemption.go:52] [PreEnqueue] SchedulerName for pod gold-class-deploy-26-6bcb7b6c88-6jh2g: custom-scheduler
E0409 14:49:14.112555       1 types.go:135] Controller gold-class-deploy-26-6bcb7b6c88-6jh2g_default associated with , which is no valid QoS measure approach.
E0409 14:49:14.112561       1 types.go:564] Pod gold-class-deploy-26-6bcb7b6c88-6jh2g_default with no valid QoS measure approach associated with.
I0409 14:49:14.112560       1 scheduler.go:205] [OnAddPod] Pod added: default/gold-class-deploy-26-6bcb7b6c88-6jh2g, Annotations: map[acceptablePreemptionOverhead:0.05 controller:gold-controller-26 kwok.x-k8s.io/usage-cpu:1m kwok.x-k8s.io/usage-memory:1Mi qosMeasuring:average slo:1]
I0409 14:49:14.117524       1 scheduler.go:103] [HigherPrecedence] Final decision: Does gold-class-deploy-26-6bcb7b6c88-6jh2g have precedence over gold-class-deploy-1-78bb76545-pwz55? true
I0409 14:49:14.117567       1 scheduler.go:103] [HigherPrecedence] Final decision: Does gold-class-deploy-26-6bcb7b6c88-6jh2g have precedence over gold-class-deploy-2-58ff5bfb68-446gs? true
I0409 14:49:14.117590       1 scheduler.go:103] [HigherPrecedence] Final decision: Does gold-class-deploy-26-6bcb7b6c88-6jh2g have precedence over gold-class-deploy-9-868dfbd94f-6hvv5? true
I0409 14:49:14.117612       1 scheduler.go:103] [HigherPrecedence] Final decision: Does gold-class-deploy-26-6bcb7b6c88-6jh2g have precedence over gold-class-deploy-4-b6866bf4b-5dnw5? true
I0409 14:49:14.117635       1 scheduler.go:103] [HigherPrecedence] Final decision: Does gold-class-deploy-26-6bcb7b6c88-6jh2g have precedence over gold-class-deploy-5-c4557676f-pdmbf? true
I0409 14:49:14.117657       1 scheduler.go:103] [HigherPrecedence] Final decision: Does gold-class-deploy-26-6bcb7b6c88-6jh2g have precedence over gold-class-deploy-6-6df4d4d67b-bf8cr? true
I0409 14:49:14.117689       1 scheduler.go:103] [HigherPrecedence] Final decision: Does gold-class-deploy-26-6bcb7b6c88-6jh2g have precedence over gold-class-deploy-12-598494bf8f-jqzbs? true
I0409 14:49:14.117729       1 scheduler.go:103] [HigherPrecedence] Final decision: Does gold-class-deploy-26-6bcb7b6c88-6jh2g have precedence over gold-class-deploy-13-5f585cb744-n2l5p? true
I0409 14:49:14.127587       1 scheduler.go:255] [OnUpdatePod] Updating 'LastStatus' of pod default/bronze-class-deploy-25-b94944fb5-x4ztm in metrics
I0409 14:49:14.133351       1 scheduler.go:255] [OnUpdatePod] Updating 'LastStatus' of pod default/bronze-class-deploy-25-b94944fb5-x4ztm in metrics
I0409 14:49:14.136751       1 default_preemption.go:39] "Preemption successful" pod="default/gold-class-deploy-26-6bcb7b6c88-6jh2g" nominatedNode="kwok-node-1"
I0409 14:49:14.136951       1 scheduler.go:286] [OnDeletePod] Checking the state of pod default/bronze-class-deploy-25-b94944fb5-x4ztm in metrics
I0409 14:49:14.137702       1 default_preemption.go:51] [PreEnqueue] PreEnqueue called for pod: bronze-class-deploy-25-b94944fb5-ghv2p
I0409 14:49:14.137753       1 default_preemption.go:52] [PreEnqueue] SchedulerName for pod bronze-class-deploy-25-b94944fb5-ghv2p: custom-scheduler
I0409 14:49:14.137744       1 scheduler.go:205] [OnAddPod] Pod added: default/bronze-class-deploy-25-b94944fb5-ghv2p, Annotations: map[acceptablePreemptionOverhead:0.05 controller:bronze-controller-25 kwok.x-k8s.io/usage-cpu:1m kwok.x-k8s.io/usage-memory:1Mi qosMeasuring:average slo:0.5]
I0409 14:49:14.145943       1 scheduler.go:255] [OnUpdatePod] Updating 'LastStatus' of pod default/gold-class-deploy-26-6bcb7b6c88-6jh2g in metrics
I0409 14:49:14.147698       1 scheduler.go:103] [HigherPrecedence] Final decision: Does bronze-class-deploy-25-b94944fb5-ghv2p have precedence over bronze-class-deploy-3-775f4fbdd9-d77dm? true
I0409 14:49:14.147815       1 scheduler.go:103] [HigherPrecedence] Final decision: Does bronze-class-deploy-25-b94944fb5-ghv2p have precedence over bronze-class-deploy-8-6fff566748-k8mmd? true
I0409 14:49:14.147890       1 scheduler.go:103] [HigherPrecedence] Final decision: Does bronze-class-deploy-25-b94944fb5-ghv2p have precedence over bronze-class-deploy-11-559c656b44-cgqs5? true
I0409 14:49:14.147994       1 scheduler.go:103] [HigherPrecedence] Final decision: Does bronze-class-deploy-25-b94944fb5-ghv2p have precedence over bronze-class-deploy-16-74dd4696ff-7zksw? true
I0409 14:49:14.148082       1 scheduler.go:103] [HigherPrecedence] Final decision: Does bronze-class-deploy-25-b94944fb5-ghv2p have precedence over bronze-class-deploy-20-5fd9977fb4-wdm7w? true
I0409 14:49:14.148145       1 scheduler.go:103] [HigherPrecedence] Final decision: Does bronze-class-deploy-25-b94944fb5-ghv2p have precedence over bronze-class-deploy-23-654ffb5cc5-klsrd? true
I0409 14:49:14.148184       1 scheduler.go:103] [HigherPrecedence] Final decision: Does bronze-class-deploy-25-b94944fb5-ghv2p have precedence over bronze-class-deploy-24-668b49b99b-rdj8z? true
I0409 14:49:14.148223       1 default_preemption.go:37] "Preemption failed or not needed" pod="default/bronze-class-deploy-25-b94944fb5-ghv2p" status="0/2 nodes are available: 1 No preemption victims found for incoming pod, 1 Preemption is not helpful for scheduling."
I0409 14:49:14.155279       1 scheduler.go:255] [OnUpdatePod] Updating 'LastStatus' of pod default/bronze-class-deploy-25-b94944fb5-ghv2p in metrics
I0409 14:49:14.262766       1 default_preemption.go:51] [PreEnqueue] PreEnqueue called for pod: gold-class-deploy-27-6c45459fb5-m777t
I0409 14:49:14.262787       1 default_preemption.go:52] [PreEnqueue] SchedulerName for pod gold-class-deploy-27-6c45459fb5-m777t: custom-scheduler
E0409 14:49:14.262798       1 types.go:135] Controller gold-class-deploy-27-6c45459fb5-m777t_default associated with , which is no valid QoS measure approach.
E0409 14:49:14.262804       1 types.go:564] Pod gold-class-deploy-27-6c45459fb5-m777t_default with no valid QoS measure approach associated with.
I0409 14:49:14.262811       1 scheduler.go:205] [OnAddPod] Pod added: default/gold-class-deploy-27-6c45459fb5-m777t, Annotations: map[acceptablePreemptionOverhead:0.05 controller:gold-controller-27 kwok.x-k8s.io/usage-cpu:1m kwok.x-k8s.io/usage-memory:1Mi qosMeasuring:average slo:1]
I0409 14:49:14.264915       1 scheduler.go:103] [HigherPrecedence] Final decision: Does gold-class-deploy-27-6c45459fb5-m777t have precedence over gold-class-deploy-1-78bb76545-pwz55? true
I0409 14:49:14.264959       1 scheduler.go:103] [HigherPrecedence] Final decision: Does gold-class-deploy-27-6c45459fb5-m777t have precedence over gold-class-deploy-2-58ff5bfb68-446gs? true
I0409 14:49:14.264989       1 scheduler.go:103] [HigherPrecedence] Final decision: Does gold-class-deploy-27-6c45459fb5-m777t have precedence over gold-class-deploy-9-868dfbd94f-6hvv5? true
I0409 14:49:14.265027       1 scheduler.go:103] [HigherPrecedence] Final decision: Does gold-class-deploy-27-6c45459fb5-m777t have precedence over gold-class-deploy-4-b6866bf4b-5dnw5? true
I0409 14:49:14.265067       1 scheduler.go:103] [HigherPrecedence] Final decision: Does gold-class-deploy-27-6c45459fb5-m777t have precedence over gold-class-deploy-5-c4557676f-pdmbf? true
I0409 14:49:14.265104       1 scheduler.go:103] [HigherPrecedence] Final decision: Does gold-class-deploy-27-6c45459fb5-m777t have precedence over gold-class-deploy-6-6df4d4d67b-bf8cr? true
I0409 14:49:14.265131       1 scheduler.go:103] [HigherPrecedence] Final decision: Does gold-class-deploy-27-6c45459fb5-m777t have precedence over gold-class-deploy-12-598494bf8f-jqzbs? true
I0409 14:49:14.265168       1 scheduler.go:103] [HigherPrecedence] Final decision: Does gold-class-deploy-27-6c45459fb5-m777t have precedence over gold-class-deploy-13-5f585cb744-n2l5p? true
I0409 14:49:14.272289       1 scheduler.go:255] [OnUpdatePod] Updating 'LastStatus' of pod default/bronze-class-deploy-24-668b49b99b-rdj8z in metrics
I0409 14:49:14.277907       1 scheduler.go:255] [OnUpdatePod] Updating 'LastStatus' of pod default/bronze-class-deploy-24-668b49b99b-rdj8z in metrics
I0409 14:49:14.281441       1 scheduler.go:103] [HigherPrecedence] Final decision: Does gold-class-deploy-27-6c45459fb5-m777t have precedence over gold-class-deploy-26-6bcb7b6c88-6jh2g? false
I0409 14:49:14.281469       1 default_preemption.go:39] "Preemption successful" pod="default/gold-class-deploy-27-6c45459fb5-m777t" nominatedNode="kwok-node-1"
I0409 14:49:14.281535       1 scheduler.go:286] [OnDeletePod] Checking the state of pod default/bronze-class-deploy-24-668b49b99b-rdj8z in metrics
I0409 14:49:14.288415       1 scheduler.go:255] [OnUpdatePod] Updating 'LastStatus' of pod default/gold-class-deploy-27-6c45459fb5-m777t in metrics
I0409 14:49:14.461582       1 scheduler.go:205] [OnAddPod] Pod added: default/bronze-class-deploy-24-668b49b99b-ldm7g, Annotations: map[acceptablePreemptionOverhead:0.05 controller:bronze-controller-24 kwok.x-k8s.io/usage-cpu:1m kwok.x-k8s.io/usage-memory:1Mi qosMeasuring:average slo:0.5]
I0409 14:49:14.461600       1 default_preemption.go:51] [PreEnqueue] PreEnqueue called for pod: bronze-class-deploy-24-668b49b99b-ldm7g
I0409 14:49:14.461724       1 default_preemption.go:52] [PreEnqueue] SchedulerName for pod bronze-class-deploy-24-668b49b99b-ldm7g: custom-scheduler
I0409 14:49:14.462065       1 scheduler.go:103] [HigherPrecedence] Final decision: Does bronze-class-deploy-24-668b49b99b-ldm7g have precedence over bronze-class-deploy-3-775f4fbdd9-d77dm? true
I0409 14:49:14.462181       1 scheduler.go:103] [HigherPrecedence] Final decision: Does bronze-class-deploy-24-668b49b99b-ldm7g have precedence over bronze-class-deploy-8-6fff566748-k8mmd? true
I0409 14:49:14.462259       1 scheduler.go:103] [HigherPrecedence] Final decision: Does bronze-class-deploy-24-668b49b99b-ldm7g have precedence over bronze-class-deploy-11-559c656b44-cgqs5? true
I0409 14:49:14.462377       1 scheduler.go:103] [HigherPrecedence] Final decision: Does bronze-class-deploy-24-668b49b99b-ldm7g have precedence over bronze-class-deploy-16-74dd4696ff-7zksw? true
I0409 14:49:14.462466       1 scheduler.go:103] [HigherPrecedence] Final decision: Does bronze-class-deploy-24-668b49b99b-ldm7g have precedence over bronze-class-deploy-20-5fd9977fb4-wdm7w? true
I0409 14:49:14.462524       1 scheduler.go:103] [HigherPrecedence] Final decision: Does bronze-class-deploy-24-668b49b99b-ldm7g have precedence over bronze-class-deploy-23-654ffb5cc5-klsrd? true
I0409 14:49:14.462564       1 default_preemption.go:37] "Preemption failed or not needed" pod="default/bronze-class-deploy-24-668b49b99b-ldm7g" status="0/2 nodes are available: 1 No preemption victims found for incoming pod, 1 Preemption is not helpful for scheduling."
I0409 14:49:14.468798       1 scheduler.go:255] [OnUpdatePod] Updating 'LastStatus' of pod default/bronze-class-deploy-24-668b49b99b-ldm7g in metrics
I0409 14:49:14.511443       1 default_preemption.go:51] [PreEnqueue] PreEnqueue called for pod: bronze-class-deploy-28-946b5bff6-z6khm
I0409 14:49:14.511472       1 default_preemption.go:52] [PreEnqueue] SchedulerName for pod bronze-class-deploy-28-946b5bff6-z6khm: custom-scheduler
I0409 14:49:14.511467       1 scheduler.go:205] [OnAddPod] Pod added: default/bronze-class-deploy-28-946b5bff6-z6khm, Annotations: map[acceptablePreemptionOverhead:0.05 controller:bronze-controller-28 kwok.x-k8s.io/usage-cpu:1m kwok.x-k8s.io/usage-memory:1Mi qosMeasuring:average slo:0.5]
E0409 14:49:14.511484       1 types.go:135] Controller bronze-class-deploy-28-946b5bff6-z6khm_default associated with , which is no valid QoS measure approach.
E0409 14:49:14.511592       1 types.go:564] Pod bronze-class-deploy-28-946b5bff6-z6khm_default with no valid QoS measure approach associated with.
I0409 14:49:14.513269       1 scheduler.go:103] [HigherPrecedence] Final decision: Does bronze-class-deploy-28-946b5bff6-z6khm have precedence over bronze-class-deploy-3-775f4fbdd9-d77dm? true
I0409 14:49:14.513413       1 scheduler.go:103] [HigherPrecedence] Final decision: Does bronze-class-deploy-28-946b5bff6-z6khm have precedence over bronze-class-deploy-8-6fff566748-k8mmd? true
I0409 14:49:14.513485       1 scheduler.go:103] [HigherPrecedence] Final decision: Does bronze-class-deploy-28-946b5bff6-z6khm have precedence over bronze-class-deploy-11-559c656b44-cgqs5? true
I0409 14:49:14.513574       1 scheduler.go:103] [HigherPrecedence] Final decision: Does bronze-class-deploy-28-946b5bff6-z6khm have precedence over bronze-class-deploy-16-74dd4696ff-7zksw? true
I0409 14:49:14.513654       1 scheduler.go:103] [HigherPrecedence] Final decision: Does bronze-class-deploy-28-946b5bff6-z6khm have precedence over bronze-class-deploy-20-5fd9977fb4-wdm7w? true
I0409 14:49:14.513720       1 scheduler.go:103] [HigherPrecedence] Final decision: Does bronze-class-deploy-28-946b5bff6-z6khm have precedence over bronze-class-deploy-23-654ffb5cc5-klsrd? true
I0409 14:49:14.513770       1 default_preemption.go:37] "Preemption failed or not needed" pod="default/bronze-class-deploy-28-946b5bff6-z6khm" status="0/2 nodes are available: 1 No preemption victims found for incoming pod, 1 Preemption is not helpful for scheduling."
I0409 14:49:14.520436       1 scheduler.go:255] [OnUpdatePod] Updating 'LastStatus' of pod default/bronze-class-deploy-28-946b5bff6-z6khm in metrics
I0409 14:49:14.563986       1 default_preemption.go:51] [PreEnqueue] PreEnqueue called for pod: bronze-class-deploy-29-7d6b766b6f-m85bq
I0409 14:49:14.564011       1 default_preemption.go:52] [PreEnqueue] SchedulerName for pod bronze-class-deploy-29-7d6b766b6f-m85bq: custom-scheduler
I0409 14:49:14.563999       1 scheduler.go:205] [OnAddPod] Pod added: default/bronze-class-deploy-29-7d6b766b6f-m85bq, Annotations: map[acceptablePreemptionOverhead:0.05 controller:bronze-controller-29 kwok.x-k8s.io/usage-cpu:1m kwok.x-k8s.io/usage-memory:1Mi qosMeasuring:average slo:0.5]
E0409 14:49:14.564023       1 types.go:135] Controller bronze-class-deploy-29-7d6b766b6f-m85bq_default associated with , which is no valid QoS measure approach.
E0409 14:49:14.564031       1 types.go:564] Pod bronze-class-deploy-29-7d6b766b6f-m85bq_default with no valid QoS measure approach associated with.
I0409 14:49:14.566138       1 scheduler.go:103] [HigherPrecedence] Final decision: Does bronze-class-deploy-29-7d6b766b6f-m85bq have precedence over bronze-class-deploy-3-775f4fbdd9-d77dm? true
I0409 14:49:14.566224       1 scheduler.go:103] [HigherPrecedence] Final decision: Does bronze-class-deploy-29-7d6b766b6f-m85bq have precedence over bronze-class-deploy-8-6fff566748-k8mmd? true
I0409 14:49:14.566297       1 scheduler.go:103] [HigherPrecedence] Final decision: Does bronze-class-deploy-29-7d6b766b6f-m85bq have precedence over bronze-class-deploy-11-559c656b44-cgqs5? true
I0409 14:49:14.566433       1 scheduler.go:103] [HigherPrecedence] Final decision: Does bronze-class-deploy-29-7d6b766b6f-m85bq have precedence over bronze-class-deploy-16-74dd4696ff-7zksw? true
I0409 14:49:14.566505       1 scheduler.go:103] [HigherPrecedence] Final decision: Does bronze-class-deploy-29-7d6b766b6f-m85bq have precedence over bronze-class-deploy-20-5fd9977fb4-wdm7w? true
I0409 14:49:14.566571       1 scheduler.go:103] [HigherPrecedence] Final decision: Does bronze-class-deploy-29-7d6b766b6f-m85bq have precedence over bronze-class-deploy-23-654ffb5cc5-klsrd? true
I0409 14:49:14.566638       1 default_preemption.go:37] "Preemption failed or not needed" pod="default/bronze-class-deploy-29-7d6b766b6f-m85bq" status="0/2 nodes are available: 1 No preemption victims found for incoming pod, 1 Preemption is not helpful for scheduling."
I0409 14:49:14.573078       1 scheduler.go:255] [OnUpdatePod] Updating 'LastStatus' of pod default/bronze-class-deploy-29-7d6b766b6f-m85bq in metrics
I0409 14:49:14.811440       1 default_preemption.go:51] [PreEnqueue] PreEnqueue called for pod: bronze-class-deploy-30-56698788c5-l8dqg
I0409 14:49:14.811462       1 default_preemption.go:52] [PreEnqueue] SchedulerName for pod bronze-class-deploy-30-56698788c5-l8dqg: custom-scheduler
I0409 14:49:14.811456       1 scheduler.go:205] [OnAddPod] Pod added: default/bronze-class-deploy-30-56698788c5-l8dqg, Annotations: map[acceptablePreemptionOverhead:0.05 controller:bronze-controller-30 kwok.x-k8s.io/usage-cpu:1m kwok.x-k8s.io/usage-memory:1Mi qosMeasuring:average slo:0.5]
E0409 14:49:14.811472       1 types.go:135] Controller bronze-class-deploy-30-56698788c5-l8dqg_default associated with , which is no valid QoS measure approach.
E0409 14:49:14.811479       1 types.go:564] Pod bronze-class-deploy-30-56698788c5-l8dqg_default with no valid QoS measure approach associated with.
I0409 14:49:14.813541       1 scheduler.go:103] [HigherPrecedence] Final decision: Does bronze-class-deploy-30-56698788c5-l8dqg have precedence over bronze-class-deploy-3-775f4fbdd9-d77dm? true
I0409 14:49:14.813650       1 scheduler.go:103] [HigherPrecedence] Final decision: Does bronze-class-deploy-30-56698788c5-l8dqg have precedence over bronze-class-deploy-8-6fff566748-k8mmd? true
I0409 14:49:14.813727       1 scheduler.go:103] [HigherPrecedence] Final decision: Does bronze-class-deploy-30-56698788c5-l8dqg have precedence over bronze-class-deploy-11-559c656b44-cgqs5? true
I0409 14:49:14.813833       1 scheduler.go:103] [HigherPrecedence] Final decision: Does bronze-class-deploy-30-56698788c5-l8dqg have precedence over bronze-class-deploy-16-74dd4696ff-7zksw? true
I0409 14:49:14.813922       1 scheduler.go:103] [HigherPrecedence] Final decision: Does bronze-class-deploy-30-56698788c5-l8dqg have precedence over bronze-class-deploy-20-5fd9977fb4-wdm7w? true
I0409 14:49:14.813997       1 scheduler.go:103] [HigherPrecedence] Final decision: Does bronze-class-deploy-30-56698788c5-l8dqg have precedence over bronze-class-deploy-23-654ffb5cc5-klsrd? true
I0409 14:49:14.814046       1 default_preemption.go:37] "Preemption failed or not needed" pod="default/bronze-class-deploy-30-56698788c5-l8dqg" status="0/2 nodes are available: 1 No preemption victims found for incoming pod, 1 Preemption is not helpful for scheduling."
I0409 14:49:14.820159       1 scheduler.go:255] [OnUpdatePod] Updating 'LastStatus' of pod default/bronze-class-deploy-30-56698788c5-l8dqg in metrics
I0409 14:49:15.211647       1 default_preemption.go:51] [PreEnqueue] PreEnqueue called for pod: bronze-class-deploy-31-77756c9778-dqdd6
I0409 14:49:15.211676       1 default_preemption.go:52] [PreEnqueue] SchedulerName for pod bronze-class-deploy-31-77756c9778-dqdd6: custom-scheduler
E0409 14:49:15.211694       1 types.go:135] Controller bronze-class-deploy-31-77756c9778-dqdd6_default associated with , which is no valid QoS measure approach.
E0409 14:49:15.211702       1 types.go:564] Pod bronze-class-deploy-31-77756c9778-dqdd6_default with no valid QoS measure approach associated with.
I0409 14:49:15.211688       1 scheduler.go:205] [OnAddPod] Pod added: default/bronze-class-deploy-31-77756c9778-dqdd6, Annotations: map[acceptablePreemptionOverhead:0.05 controller:bronze-controller-31 kwok.x-k8s.io/usage-cpu:1m kwok.x-k8s.io/usage-memory:1Mi qosMeasuring:average slo:0.5]
I0409 14:49:15.216950       1 scheduler.go:103] [HigherPrecedence] Final decision: Does bronze-class-deploy-31-77756c9778-dqdd6 have precedence over bronze-class-deploy-3-775f4fbdd9-d77dm? true
I0409 14:49:15.217067       1 scheduler.go:103] [HigherPrecedence] Final decision: Does bronze-class-deploy-31-77756c9778-dqdd6 have precedence over bronze-class-deploy-8-6fff566748-k8mmd? true
I0409 14:49:15.217129       1 scheduler.go:103] [HigherPrecedence] Final decision: Does bronze-class-deploy-31-77756c9778-dqdd6 have precedence over bronze-class-deploy-11-559c656b44-cgqs5? true
I0409 14:49:15.217225       1 scheduler.go:103] [HigherPrecedence] Final decision: Does bronze-class-deploy-31-77756c9778-dqdd6 have precedence over bronze-class-deploy-16-74dd4696ff-7zksw? true
I0409 14:49:15.217304       1 scheduler.go:103] [HigherPrecedence] Final decision: Does bronze-class-deploy-31-77756c9778-dqdd6 have precedence over bronze-class-deploy-20-5fd9977fb4-wdm7w? true
I0409 14:49:15.217384       1 scheduler.go:103] [HigherPrecedence] Final decision: Does bronze-class-deploy-31-77756c9778-dqdd6 have precedence over bronze-class-deploy-23-654ffb5cc5-klsrd? true
I0409 14:49:15.217439       1 default_preemption.go:37] "Preemption failed or not needed" pod="default/bronze-class-deploy-31-77756c9778-dqdd6" status="0/2 nodes are available: 1 No preemption victims found for incoming pod, 1 Preemption is not helpful for scheduling."
I0409 14:49:15.223902       1 scheduler.go:255] [OnUpdatePod] Updating 'LastStatus' of pod default/bronze-class-deploy-31-77756c9778-dqdd6 in metrics
I0409 14:49:15.363331       1 scheduler.go:205] [OnAddPod] Pod added: default/silver-class-deploy-32-84b675c847-wwmws, Annotations: map[acceptablePreemptionOverhead:0.05 controller:silver-controller-32 kwok.x-k8s.io/usage-cpu:1m kwok.x-k8s.io/usage-memory:1Mi qosMeasuring:average slo:0.9]
I0409 14:49:15.363413       1 default_preemption.go:51] [PreEnqueue] PreEnqueue called for pod: silver-class-deploy-32-84b675c847-wwmws
I0409 14:49:15.363429       1 default_preemption.go:52] [PreEnqueue] SchedulerName for pod silver-class-deploy-32-84b675c847-wwmws: custom-scheduler
E0409 14:49:15.363440       1 types.go:135] Controller silver-class-deploy-32-84b675c847-wwmws_default associated with , which is no valid QoS measure approach.
E0409 14:49:15.363446       1 types.go:564] Pod silver-class-deploy-32-84b675c847-wwmws_default with no valid QoS measure approach associated with.
I0409 14:49:15.365604       1 scheduler.go:103] [HigherPrecedence] Final decision: Does silver-class-deploy-32-84b675c847-wwmws have precedence over silver-class-deploy-18-5dd44b47c5-7d2lh? true
I0409 14:49:15.365704       1 scheduler.go:103] [HigherPrecedence] Final decision: Does silver-class-deploy-32-84b675c847-wwmws have precedence over silver-class-deploy-7-ff55f69ff-hwmfr? true
I0409 14:49:15.365771       1 scheduler.go:103] [HigherPrecedence] Final decision: Does silver-class-deploy-32-84b675c847-wwmws have precedence over silver-class-deploy-22-8456bfbbc6-jrczs? true
I0409 14:49:15.365824       1 scheduler.go:103] [HigherPrecedence] Final decision: Does silver-class-deploy-32-84b675c847-wwmws have precedence over silver-class-deploy-10-6866d9b887-l2866? true
I0409 14:49:15.365846       1 scheduler.go:103] [HigherPrecedence] Final decision: Does silver-class-deploy-32-84b675c847-wwmws have precedence over silver-class-deploy-21-7bf557854c-zflrc? true
I0409 14:49:15.365905       1 scheduler.go:103] [HigherPrecedence] Final decision: Does silver-class-deploy-32-84b675c847-wwmws have precedence over silver-class-deploy-14-79f95c48b7-jh9nd? true
I0409 14:49:15.365934       1 scheduler.go:103] [HigherPrecedence] Final decision: Does silver-class-deploy-32-84b675c847-wwmws have precedence over silver-class-deploy-15-cb96c7dc4-9m85g? true
I0409 14:49:15.365955       1 scheduler.go:103] [HigherPrecedence] Final decision: Does silver-class-deploy-32-84b675c847-wwmws have precedence over silver-class-deploy-19-7cc4c5b78-v9p7f? true
I0409 14:49:15.365974       1 scheduler.go:103] [HigherPrecedence] Final decision: Does silver-class-deploy-32-84b675c847-wwmws have precedence over silver-class-deploy-17-59cbf4bc88-s2ngm? true
I0409 14:49:15.373108       1 scheduler.go:255] [OnUpdatePod] Updating 'LastStatus' of pod default/bronze-class-deploy-23-654ffb5cc5-klsrd in metrics
I0409 14:49:15.378905       1 scheduler.go:255] [OnUpdatePod] Updating 'LastStatus' of pod default/bronze-class-deploy-23-654ffb5cc5-klsrd in metrics
I0409 14:49:15.381030       1 default_preemption.go:39] "Preemption successful" pod="default/silver-class-deploy-32-84b675c847-wwmws" nominatedNode="kwok-node-1"
I0409 14:49:15.381188       1 scheduler.go:286] [OnDeletePod] Checking the state of pod default/bronze-class-deploy-23-654ffb5cc5-klsrd in metrics
I0409 14:49:15.387637       1 scheduler.go:255] [OnUpdatePod] Updating 'LastStatus' of pod default/silver-class-deploy-32-84b675c847-wwmws in metrics
I0409 14:49:15.561632       1 default_preemption.go:51] [PreEnqueue] PreEnqueue called for pod: bronze-class-deploy-23-654ffb5cc5-879fc
I0409 14:49:15.561650       1 default_preemption.go:52] [PreEnqueue] SchedulerName for pod bronze-class-deploy-23-654ffb5cc5-879fc: custom-scheduler
I0409 14:49:15.561651       1 scheduler.go:205] [OnAddPod] Pod added: default/bronze-class-deploy-23-654ffb5cc5-879fc, Annotations: map[acceptablePreemptionOverhead:0.05 controller:bronze-controller-23 kwok.x-k8s.io/usage-cpu:1m kwok.x-k8s.io/usage-memory:1Mi qosMeasuring:average slo:0.5]
I0409 14:49:15.561983       1 scheduler.go:103] [HigherPrecedence] Final decision: Does bronze-class-deploy-23-654ffb5cc5-879fc have precedence over bronze-class-deploy-3-775f4fbdd9-d77dm? true
I0409 14:49:15.562099       1 scheduler.go:103] [HigherPrecedence] Final decision: Does bronze-class-deploy-23-654ffb5cc5-879fc have precedence over bronze-class-deploy-8-6fff566748-k8mmd? true
I0409 14:49:15.562167       1 scheduler.go:103] [HigherPrecedence] Final decision: Does bronze-class-deploy-23-654ffb5cc5-879fc have precedence over bronze-class-deploy-11-559c656b44-cgqs5? true
I0409 14:49:15.562259       1 scheduler.go:103] [HigherPrecedence] Final decision: Does bronze-class-deploy-23-654ffb5cc5-879fc have precedence over bronze-class-deploy-16-74dd4696ff-7zksw? true
I0409 14:49:15.562354       1 scheduler.go:103] [HigherPrecedence] Final decision: Does bronze-class-deploy-23-654ffb5cc5-879fc have precedence over bronze-class-deploy-20-5fd9977fb4-wdm7w? true
I0409 14:49:15.562487       1 default_preemption.go:37] "Preemption failed or not needed" pod="default/bronze-class-deploy-23-654ffb5cc5-879fc" status="0/2 nodes are available: 1 No preemption victims found for incoming pod, 1 Preemption is not helpful for scheduling."
I0409 14:49:15.568693       1 scheduler.go:255] [OnUpdatePod] Updating 'LastStatus' of pod default/bronze-class-deploy-23-654ffb5cc5-879fc in metrics
I0409 14:49:16.039879       1 default_preemption.go:51] [PreEnqueue] PreEnqueue called for pod: gold-class-deploy-26-6bcb7b6c88-6jh2g
I0409 14:49:16.039905       1 default_preemption.go:52] [PreEnqueue] SchedulerName for pod gold-class-deploy-26-6bcb7b6c88-6jh2g: custom-scheduler
I0409 14:49:16.039959       1 default_preemption.go:51] [PreEnqueue] PreEnqueue called for pod: bronze-class-deploy-25-b94944fb5-ghv2p
I0409 14:49:16.039963       1 default_preemption.go:52] [PreEnqueue] SchedulerName for pod bronze-class-deploy-25-b94944fb5-ghv2p: custom-scheduler
I0409 14:49:16.039991       1 default_preemption.go:51] [PreEnqueue] PreEnqueue called for pod: gold-class-deploy-27-6c45459fb5-m777t
I0409 14:49:16.040002       1 default_preemption.go:52] [PreEnqueue] SchedulerName for pod gold-class-deploy-27-6c45459fb5-m777t: custom-scheduler
I0409 14:49:16.040025       1 scheduler.go:103] [HigherPrecedence] Final decision: Does gold-class-deploy-27-6c45459fb5-m777t have precedence over gold-class-deploy-26-6bcb7b6c88-6jh2g? false
I0409 14:49:16.040041       1 default_preemption.go:51] [PreEnqueue] PreEnqueue called for pod: bronze-class-deploy-24-668b49b99b-ldm7g
I0409 14:49:16.040064       1 default_preemption.go:52] [PreEnqueue] SchedulerName for pod bronze-class-deploy-24-668b49b99b-ldm7g: custom-scheduler
I0409 14:49:16.040099       1 scheduler.go:103] [HigherPrecedence] Final decision: Does bronze-class-deploy-24-668b49b99b-ldm7g have precedence over bronze-class-deploy-25-b94944fb5-ghv2p? false
I0409 14:49:16.040108       1 default_preemption.go:51] [PreEnqueue] PreEnqueue called for pod: bronze-class-deploy-28-946b5bff6-z6khm
I0409 14:49:16.040112       1 default_preemption.go:52] [PreEnqueue] SchedulerName for pod bronze-class-deploy-28-946b5bff6-z6khm: custom-scheduler
I0409 14:49:16.040133       1 scheduler.go:103] [HigherPrecedence] Final decision: Does bronze-class-deploy-28-946b5bff6-z6khm have precedence over bronze-class-deploy-25-b94944fb5-ghv2p? true
I0409 14:49:16.040164       1 default_preemption.go:51] [PreEnqueue] PreEnqueue called for pod: bronze-class-deploy-29-7d6b766b6f-m85bq
I0409 14:49:16.040168       1 default_preemption.go:52] [PreEnqueue] SchedulerName for pod bronze-class-deploy-29-7d6b766b6f-m85bq: custom-scheduler
I0409 14:49:16.040195       1 default_preemption.go:51] [PreEnqueue] PreEnqueue called for pod: bronze-class-deploy-30-56698788c5-l8dqg
I0409 14:49:16.040206       1 default_preemption.go:52] [PreEnqueue] SchedulerName for pod bronze-class-deploy-30-56698788c5-l8dqg: custom-scheduler
I0409 14:49:16.040286       1 scheduler.go:103] [HigherPrecedence] Final decision: Does bronze-class-deploy-29-7d6b766b6f-m85bq have precedence over bronze-class-deploy-30-56698788c5-l8dqg? false
I0409 14:49:16.040637       1 scheduler.go:103] [HigherPrecedence] Final decision: Does bronze-class-deploy-30-56698788c5-l8dqg have precedence over bronze-class-deploy-28-946b5bff6-z6khm? false
I0409 14:49:16.040669       1 scheduler.go:103] [HigherPrecedence] Final decision: Does bronze-class-deploy-28-946b5bff6-z6khm have precedence over bronze-class-deploy-29-7d6b766b6f-m85bq? false
I0409 14:49:16.040741       1 scheduler.go:164] [PreBind] Validating pod gold-class-deploy-26-6bcb7b6c88-6jh2g before binding to node kwok-node-1
I0409 14:49:16.040887       1 scheduler.go:103] [HigherPrecedence] Final decision: Does bronze-class-deploy-30-56698788c5-l8dqg have precedence over bronze-class-deploy-28-946b5bff6-z6khm? false
I0409 14:49:16.040933       1 scheduler.go:103] [HigherPrecedence] Final decision: Does bronze-class-deploy-28-946b5bff6-z6khm have precedence over bronze-class-deploy-25-b94944fb5-ghv2p? true
I0409 14:49:16.040952       1 scheduler.go:103] [HigherPrecedence] Final decision: Does bronze-class-deploy-24-668b49b99b-ldm7g have precedence over bronze-class-deploy-25-b94944fb5-ghv2p? false
I0409 14:49:16.041001       1 scheduler.go:164] [PreBind] Validating pod gold-class-deploy-27-6c45459fb5-m777t before binding to node kwok-node-1
I0409 14:49:16.041328       1 scheduler.go:103] [HigherPrecedence] Final decision: Does bronze-class-deploy-29-7d6b766b6f-m85bq have precedence over bronze-class-deploy-3-775f4fbdd9-d77dm? true
I0409 14:49:16.041491       1 scheduler.go:103] [HigherPrecedence] Final decision: Does bronze-class-deploy-29-7d6b766b6f-m85bq have precedence over bronze-class-deploy-8-6fff566748-k8mmd? true
I0409 14:49:16.041575       1 scheduler.go:103] [HigherPrecedence] Final decision: Does bronze-class-deploy-29-7d6b766b6f-m85bq have precedence over bronze-class-deploy-11-559c656b44-cgqs5? true
I0409 14:49:16.041710       1 scheduler.go:103] [HigherPrecedence] Final decision: Does bronze-class-deploy-29-7d6b766b6f-m85bq have precedence over bronze-class-deploy-16-74dd4696ff-7zksw? true
I0409 14:49:16.041845       1 scheduler.go:103] [HigherPrecedence] Final decision: Does bronze-class-deploy-29-7d6b766b6f-m85bq have precedence over bronze-class-deploy-20-5fd9977fb4-wdm7w? true
I0409 14:49:16.041969       1 default_preemption.go:37] "Preemption failed or not needed" pod="default/bronze-class-deploy-29-7d6b766b6f-m85bq" status="0/2 nodes are available: 1 No preemption victims found for incoming pod, 1 Preemption is not helpful for scheduling."
I0409 14:49:16.042096       1 scheduler.go:103] [HigherPrecedence] Final decision: Does bronze-class-deploy-30-56698788c5-l8dqg have precedence over bronze-class-deploy-25-b94944fb5-ghv2p? true
I0409 14:49:16.042120       1 scheduler.go:103] [HigherPrecedence] Final decision: Does bronze-class-deploy-30-56698788c5-l8dqg have precedence over bronze-class-deploy-24-668b49b99b-ldm7g? true
I0409 14:49:16.042279       1 scheduler.go:103] [HigherPrecedence] Final decision: Does bronze-class-deploy-28-946b5bff6-z6khm have precedence over bronze-class-deploy-3-775f4fbdd9-d77dm? true
I0409 14:49:16.042387       1 scheduler.go:103] [HigherPrecedence] Final decision: Does bronze-class-deploy-28-946b5bff6-z6khm have precedence over bronze-class-deploy-8-6fff566748-k8mmd? true
I0409 14:49:16.042470       1 scheduler.go:103] [HigherPrecedence] Final decision: Does bronze-class-deploy-28-946b5bff6-z6khm have precedence over bronze-class-deploy-11-559c656b44-cgqs5? true
I0409 14:49:16.042565       1 scheduler.go:103] [HigherPrecedence] Final decision: Does bronze-class-deploy-28-946b5bff6-z6khm have precedence over bronze-class-deploy-16-74dd4696ff-7zksw? true
I0409 14:49:16.042673       1 scheduler.go:103] [HigherPrecedence] Final decision: Does bronze-class-deploy-28-946b5bff6-z6khm have precedence over bronze-class-deploy-20-5fd9977fb4-wdm7w? true
I0409 14:49:16.042774       1 default_preemption.go:37] "Preemption failed or not needed" pod="default/bronze-class-deploy-28-946b5bff6-z6khm" status="0/2 nodes are available: 1 No preemption victims found for incoming pod, 1 Preemption is not helpful for scheduling."
I0409 14:49:16.042863       1 scheduler.go:103] [HigherPrecedence] Final decision: Does bronze-class-deploy-25-b94944fb5-ghv2p have precedence over bronze-class-deploy-24-668b49b99b-ldm7g? true
I0409 14:49:16.043052       1 scheduler.go:103] [HigherPrecedence] Final decision: Does bronze-class-deploy-30-56698788c5-l8dqg have precedence over bronze-class-deploy-3-775f4fbdd9-d77dm? true
I0409 14:49:16.043139       1 scheduler.go:103] [HigherPrecedence] Final decision: Does bronze-class-deploy-30-56698788c5-l8dqg have precedence over bronze-class-deploy-8-6fff566748-k8mmd? true
I0409 14:49:16.043215       1 scheduler.go:103] [HigherPrecedence] Final decision: Does bronze-class-deploy-30-56698788c5-l8dqg have precedence over bronze-class-deploy-11-559c656b44-cgqs5? true
I0409 14:49:16.043317       1 scheduler.go:103] [HigherPrecedence] Final decision: Does bronze-class-deploy-30-56698788c5-l8dqg have precedence over bronze-class-deploy-16-74dd4696ff-7zksw? true
I0409 14:49:16.043420       1 scheduler.go:103] [HigherPrecedence] Final decision: Does bronze-class-deploy-30-56698788c5-l8dqg have precedence over bronze-class-deploy-20-5fd9977fb4-wdm7w? true
I0409 14:49:16.043523       1 default_preemption.go:37] "Preemption failed or not needed" pod="default/bronze-class-deploy-30-56698788c5-l8dqg" status="0/2 nodes are available: 1 No preemption victims found for incoming pod, 1 Preemption is not helpful for scheduling."
I0409 14:49:16.043773       1 scheduler.go:103] [HigherPrecedence] Final decision: Does bronze-class-deploy-25-b94944fb5-ghv2p have precedence over bronze-class-deploy-3-775f4fbdd9-d77dm? true
I0409 14:49:16.043882       1 scheduler.go:103] [HigherPrecedence] Final decision: Does bronze-class-deploy-25-b94944fb5-ghv2p have precedence over bronze-class-deploy-8-6fff566748-k8mmd? true
I0409 14:49:16.043957       1 scheduler.go:103] [HigherPrecedence] Final decision: Does bronze-class-deploy-25-b94944fb5-ghv2p have precedence over bronze-class-deploy-11-559c656b44-cgqs5? true
I0409 14:49:16.044074       1 scheduler.go:103] [HigherPrecedence] Final decision: Does bronze-class-deploy-25-b94944fb5-ghv2p have precedence over bronze-class-deploy-16-74dd4696ff-7zksw? true
I0409 14:49:16.044155       1 scheduler.go:103] [HigherPrecedence] Final decision: Does bronze-class-deploy-25-b94944fb5-ghv2p have precedence over bronze-class-deploy-20-5fd9977fb4-wdm7w? true
I0409 14:49:16.044266       1 default_preemption.go:37] "Preemption failed or not needed" pod="default/bronze-class-deploy-25-b94944fb5-ghv2p" status="0/2 nodes are available: 1 No preemption victims found for incoming pod, 1 Preemption is not helpful for scheduling."
I0409 14:49:16.045326       1 scheduler.go:103] [HigherPrecedence] Final decision: Does bronze-class-deploy-24-668b49b99b-ldm7g have precedence over bronze-class-deploy-3-775f4fbdd9-d77dm? true
I0409 14:49:16.045526       1 scheduler.go:103] [HigherPrecedence] Final decision: Does bronze-class-deploy-24-668b49b99b-ldm7g have precedence over bronze-class-deploy-8-6fff566748-k8mmd? true
I0409 14:49:16.045609       1 scheduler.go:103] [HigherPrecedence] Final decision: Does bronze-class-deploy-24-668b49b99b-ldm7g have precedence over bronze-class-deploy-11-559c656b44-cgqs5? true
I0409 14:49:16.046430       1 scheduler.go:103] [HigherPrecedence] Final decision: Does bronze-class-deploy-24-668b49b99b-ldm7g have precedence over bronze-class-deploy-16-74dd4696ff-7zksw? true
I0409 14:49:16.046542       1 scheduler.go:103] [HigherPrecedence] Final decision: Does bronze-class-deploy-24-668b49b99b-ldm7g have precedence over bronze-class-deploy-20-5fd9977fb4-wdm7w? true
I0409 14:49:16.046715       1 default_preemption.go:37] "Preemption failed or not needed" pod="default/bronze-class-deploy-24-668b49b99b-ldm7g" status="0/2 nodes are available: 1 No preemption victims found for incoming pod, 1 Preemption is not helpful for scheduling."
I0409 14:49:16.047144       1 scheduler.go:172] [PostBind] Called for pod gold-class-deploy-27-6c45459fb5-m777t
I0409 14:49:16.047163       1 scheduler.go:190] [PostBind] Pod gold-class-deploy-27-6c45459fb5-m777t - Binding start: 2025-04-09 14:49:16.041024774 +0000 UTC m=+40.728395212, Binding end: 2025-04-09 14:49:16.047159826 +0000 UTC m=+40.734530254
I0409 14:49:16.047179       1 scheduler.go:197] [PostBind] Metrics updated for pod gold-class-deploy-27-6c45459fb5-m777t
I0409 14:49:16.047454       1 scheduler.go:255] [OnUpdatePod] Updating 'LastStatus' of pod default/gold-class-deploy-27-6c45459fb5-m777t in metrics
I0409 14:49:16.050697       1 scheduler.go:172] [PostBind] Called for pod gold-class-deploy-26-6bcb7b6c88-6jh2g
I0409 14:49:16.050717       1 scheduler.go:190] [PostBind] Pod gold-class-deploy-26-6bcb7b6c88-6jh2g - Binding start: 2025-04-09 14:49:16.040761089 +0000 UTC m=+40.728131527, Binding end: 2025-04-09 14:49:16.050713845 +0000 UTC m=+40.738084283
I0409 14:49:16.050737       1 scheduler.go:197] [PostBind] Metrics updated for pod gold-class-deploy-26-6bcb7b6c88-6jh2g
I0409 14:49:16.050777       1 scheduler.go:255] [OnUpdatePod] Updating 'LastStatus' of pod default/gold-class-deploy-26-6bcb7b6c88-6jh2g in metrics
I0409 14:49:16.056419       1 scheduler.go:255] [OnUpdatePod] Updating 'LastStatus' of pod default/gold-class-deploy-27-6c45459fb5-m777t in metrics
I0409 14:49:16.059206       1 scheduler.go:255] [OnUpdatePod] Updating 'LastStatus' of pod default/gold-class-deploy-26-6bcb7b6c88-6jh2g in metrics
I0409 14:49:17.040415       1 default_preemption.go:51] [PreEnqueue] PreEnqueue called for pod: bronze-class-deploy-31-77756c9778-dqdd6
I0409 14:49:17.040438       1 default_preemption.go:52] [PreEnqueue] SchedulerName for pod bronze-class-deploy-31-77756c9778-dqdd6: custom-scheduler
I0409 14:49:17.040490       1 default_preemption.go:51] [PreEnqueue] PreEnqueue called for pod: silver-class-deploy-32-84b675c847-wwmws
I0409 14:49:17.040494       1 default_preemption.go:52] [PreEnqueue] SchedulerName for pod silver-class-deploy-32-84b675c847-wwmws: custom-scheduler
I0409 14:49:17.040792       1 scheduler.go:164] [PreBind] Validating pod silver-class-deploy-32-84b675c847-wwmws before binding to node kwok-node-1
I0409 14:49:17.040964       1 scheduler.go:103] [HigherPrecedence] Final decision: Does bronze-class-deploy-31-77756c9778-dqdd6 have precedence over bronze-class-deploy-3-775f4fbdd9-d77dm? true
I0409 14:49:17.041099       1 scheduler.go:103] [HigherPrecedence] Final decision: Does bronze-class-deploy-31-77756c9778-dqdd6 have precedence over bronze-class-deploy-8-6fff566748-k8mmd? true
I0409 14:49:17.041180       1 scheduler.go:103] [HigherPrecedence] Final decision: Does bronze-class-deploy-31-77756c9778-dqdd6 have precedence over bronze-class-deploy-11-559c656b44-cgqs5? true
I0409 14:49:17.041287       1 scheduler.go:103] [HigherPrecedence] Final decision: Does bronze-class-deploy-31-77756c9778-dqdd6 have precedence over bronze-class-deploy-16-74dd4696ff-7zksw? true
I0409 14:49:17.041399       1 scheduler.go:103] [HigherPrecedence] Final decision: Does bronze-class-deploy-31-77756c9778-dqdd6 have precedence over bronze-class-deploy-20-5fd9977fb4-wdm7w? true
I0409 14:49:17.041505       1 default_preemption.go:37] "Preemption failed or not needed" pod="default/bronze-class-deploy-31-77756c9778-dqdd6" status="0/2 nodes are available: 1 No preemption victims found for incoming pod, 1 Preemption is not helpful for scheduling."
I0409 14:49:17.046337       1 scheduler.go:172] [PostBind] Called for pod silver-class-deploy-32-84b675c847-wwmws
I0409 14:49:17.046384       1 scheduler.go:190] [PostBind] Pod silver-class-deploy-32-84b675c847-wwmws - Binding start: 2025-04-09 14:49:17.040808769 +0000 UTC m=+41.728179207, Binding end: 2025-04-09 14:49:17.046381067 +0000 UTC m=+41.733751505
I0409 14:49:17.046407       1 scheduler.go:197] [PostBind] Metrics updated for pod silver-class-deploy-32-84b675c847-wwmws
I0409 14:49:17.046462       1 scheduler.go:255] [OnUpdatePod] Updating 'LastStatus' of pod default/silver-class-deploy-32-84b675c847-wwmws in metrics
I0409 14:49:17.053845       1 scheduler.go:255] [OnUpdatePod] Updating 'LastStatus' of pod default/silver-class-deploy-32-84b675c847-wwmws in metrics
I0409 14:49:36.017798       1 default_preemption.go:51] [PreEnqueue] PreEnqueue called for pod: bronze-class-deploy-29-7d6b766b6f-m85bq
I0409 14:49:36.017819       1 default_preemption.go:52] [PreEnqueue] SchedulerName for pod bronze-class-deploy-29-7d6b766b6f-m85bq: custom-scheduler
I0409 14:49:36.017859       1 default_preemption.go:51] [PreEnqueue] PreEnqueue called for pod: bronze-class-deploy-28-946b5bff6-z6khm
I0409 14:49:36.017863       1 default_preemption.go:52] [PreEnqueue] SchedulerName for pod bronze-class-deploy-28-946b5bff6-z6khm: custom-scheduler
I0409 14:49:36.017889       1 scheduler.go:103] [HigherPrecedence] Final decision: Does bronze-class-deploy-28-946b5bff6-z6khm have precedence over bronze-class-deploy-29-7d6b766b6f-m85bq? false
I0409 14:49:36.017898       1 default_preemption.go:51] [PreEnqueue] PreEnqueue called for pod: bronze-class-deploy-30-56698788c5-l8dqg
I0409 14:49:36.017905       1 default_preemption.go:52] [PreEnqueue] SchedulerName for pod bronze-class-deploy-30-56698788c5-l8dqg: custom-scheduler
I0409 14:49:36.017927       1 scheduler.go:103] [HigherPrecedence] Final decision: Does bronze-class-deploy-30-56698788c5-l8dqg have precedence over bronze-class-deploy-29-7d6b766b6f-m85bq? false
I0409 14:49:36.017944       1 default_preemption.go:51] [PreEnqueue] PreEnqueue called for pod: bronze-class-deploy-25-b94944fb5-ghv2p
I0409 14:49:36.017947       1 default_preemption.go:52] [PreEnqueue] SchedulerName for pod bronze-class-deploy-25-b94944fb5-ghv2p: custom-scheduler
I0409 14:49:36.017967       1 scheduler.go:103] [HigherPrecedence] Final decision: Does bronze-class-deploy-25-b94944fb5-ghv2p have precedence over bronze-class-deploy-28-946b5bff6-z6khm? false
I0409 14:49:36.017982       1 default_preemption.go:51] [PreEnqueue] PreEnqueue called for pod: bronze-class-deploy-24-668b49b99b-ldm7g
I0409 14:49:36.017985       1 default_preemption.go:52] [PreEnqueue] SchedulerName for pod bronze-class-deploy-24-668b49b99b-ldm7g: custom-scheduler
I0409 14:49:36.018005       1 scheduler.go:103] [HigherPrecedence] Final decision: Does bronze-class-deploy-24-668b49b99b-ldm7g have precedence over bronze-class-deploy-28-946b5bff6-z6khm? false
I0409 14:49:36.018020       1 default_preemption.go:51] [PreEnqueue] PreEnqueue called for pod: bronze-class-deploy-31-77756c9778-dqdd6
I0409 14:49:36.018023       1 default_preemption.go:52] [PreEnqueue] SchedulerName for pod bronze-class-deploy-31-77756c9778-dqdd6: custom-scheduler
I0409 14:49:36.018048       1 scheduler.go:103] [HigherPrecedence] Final decision: Does bronze-class-deploy-31-77756c9778-dqdd6 have precedence over bronze-class-deploy-30-56698788c5-l8dqg? false
I0409 14:49:36.018063       1 default_preemption.go:51] [PreEnqueue] PreEnqueue called for pod: bronze-class-deploy-23-654ffb5cc5-879fc
I0409 14:49:36.018066       1 default_preemption.go:52] [PreEnqueue] SchedulerName for pod bronze-class-deploy-23-654ffb5cc5-879fc: custom-scheduler
I0409 14:49:36.018088       1 scheduler.go:103] [HigherPrecedence] Final decision: Does bronze-class-deploy-23-654ffb5cc5-879fc have precedence over bronze-class-deploy-30-56698788c5-l8dqg? false
I0409 14:49:36.018143       1 scheduler.go:103] [HigherPrecedence] Final decision: Does bronze-class-deploy-30-56698788c5-l8dqg have precedence over bronze-class-deploy-28-946b5bff6-z6khm? false
I0409 14:49:36.018172       1 scheduler.go:103] [HigherPrecedence] Final decision: Does bronze-class-deploy-28-946b5bff6-z6khm have precedence over bronze-class-deploy-23-654ffb5cc5-879fc? true
I0409 14:49:36.018195       1 scheduler.go:103] [HigherPrecedence] Final decision: Does bronze-class-deploy-24-668b49b99b-ldm7g have precedence over bronze-class-deploy-25-b94944fb5-ghv2p? false
I0409 14:49:36.018214       1 scheduler.go:103] [HigherPrecedence] Final decision: Does bronze-class-deploy-25-b94944fb5-ghv2p have precedence over bronze-class-deploy-23-654ffb5cc5-879fc? true
I0409 14:49:36.018517       1 scheduler.go:103] [HigherPrecedence] Final decision: Does bronze-class-deploy-29-7d6b766b6f-m85bq have precedence over bronze-class-deploy-3-775f4fbdd9-d77dm? true
I0409 14:49:36.018653       1 scheduler.go:103] [HigherPrecedence] Final decision: Does bronze-class-deploy-29-7d6b766b6f-m85bq have precedence over bronze-class-deploy-8-6fff566748-k8mmd? true
I0409 14:49:36.018728       1 scheduler.go:103] [HigherPrecedence] Final decision: Does bronze-class-deploy-29-7d6b766b6f-m85bq have precedence over bronze-class-deploy-11-559c656b44-cgqs5? true
I0409 14:49:36.018829       1 scheduler.go:103] [HigherPrecedence] Final decision: Does bronze-class-deploy-29-7d6b766b6f-m85bq have precedence over bronze-class-deploy-16-74dd4696ff-7zksw? true
I0409 14:49:36.018920       1 scheduler.go:103] [HigherPrecedence] Final decision: Does bronze-class-deploy-29-7d6b766b6f-m85bq have precedence over bronze-class-deploy-20-5fd9977fb4-wdm7w? true
I0409 14:49:36.019075       1 default_preemption.go:37] "Preemption failed or not needed" pod="default/bronze-class-deploy-29-7d6b766b6f-m85bq" status="0/2 nodes are available: 1 No preemption victims found for incoming pod, 1 Preemption is not helpful for scheduling."
I0409 14:49:36.019230       1 scheduler.go:103] [HigherPrecedence] Final decision: Does bronze-class-deploy-30-56698788c5-l8dqg have precedence over bronze-class-deploy-25-b94944fb5-ghv2p? true
I0409 14:49:36.019264       1 scheduler.go:103] [HigherPrecedence] Final decision: Does bronze-class-deploy-30-56698788c5-l8dqg have precedence over bronze-class-deploy-31-77756c9778-dqdd6? true
I0409 14:49:36.019450       1 scheduler.go:103] [HigherPrecedence] Final decision: Does bronze-class-deploy-28-946b5bff6-z6khm have precedence over bronze-class-deploy-3-775f4fbdd9-d77dm? true
I0409 14:49:36.019548       1 scheduler.go:103] [HigherPrecedence] Final decision: Does bronze-class-deploy-28-946b5bff6-z6khm have precedence over bronze-class-deploy-8-6fff566748-k8mmd? true
I0409 14:49:36.019608       1 scheduler.go:103] [HigherPrecedence] Final decision: Does bronze-class-deploy-28-946b5bff6-z6khm have precedence over bronze-class-deploy-11-559c656b44-cgqs5? true
I0409 14:49:36.019694       1 scheduler.go:103] [HigherPrecedence] Final decision: Does bronze-class-deploy-28-946b5bff6-z6khm have precedence over bronze-class-deploy-16-74dd4696ff-7zksw? true
I0409 14:49:36.019780       1 scheduler.go:103] [HigherPrecedence] Final decision: Does bronze-class-deploy-28-946b5bff6-z6khm have precedence over bronze-class-deploy-20-5fd9977fb4-wdm7w? true
I0409 14:49:36.019897       1 default_preemption.go:37] "Preemption failed or not needed" pod="default/bronze-class-deploy-28-946b5bff6-z6khm" status="0/2 nodes are available: 1 No preemption victims found for incoming pod, 1 Preemption is not helpful for scheduling."
I0409 14:49:36.019985       1 scheduler.go:103] [HigherPrecedence] Final decision: Does bronze-class-deploy-31-77756c9778-dqdd6 have precedence over bronze-class-deploy-25-b94944fb5-ghv2p? true
I0409 14:49:36.020014       1 scheduler.go:103] [HigherPrecedence] Final decision: Does bronze-class-deploy-31-77756c9778-dqdd6 have precedence over bronze-class-deploy-24-668b49b99b-ldm7g? true
I0409 14:49:36.020137       1 scheduler.go:103] [HigherPrecedence] Final decision: Does bronze-class-deploy-30-56698788c5-l8dqg have precedence over bronze-class-deploy-3-775f4fbdd9-d77dm? true
I0409 14:49:36.020226       1 scheduler.go:103] [HigherPrecedence] Final decision: Does bronze-class-deploy-30-56698788c5-l8dqg have precedence over bronze-class-deploy-8-6fff566748-k8mmd? true
I0409 14:49:36.020286       1 scheduler.go:103] [HigherPrecedence] Final decision: Does bronze-class-deploy-30-56698788c5-l8dqg have precedence over bronze-class-deploy-11-559c656b44-cgqs5? true
I0409 14:49:36.020398       1 scheduler.go:103] [HigherPrecedence] Final decision: Does bronze-class-deploy-30-56698788c5-l8dqg have precedence over bronze-class-deploy-16-74dd4696ff-7zksw? true
I0409 14:49:36.020477       1 scheduler.go:103] [HigherPrecedence] Final decision: Does bronze-class-deploy-30-56698788c5-l8dqg have precedence over bronze-class-deploy-20-5fd9977fb4-wdm7w? true
I0409 14:49:36.020592       1 default_preemption.go:37] "Preemption failed or not needed" pod="default/bronze-class-deploy-30-56698788c5-l8dqg" status="0/2 nodes are available: 1 No preemption victims found for incoming pod, 1 Preemption is not helpful for scheduling."
I0409 14:49:36.020671       1 scheduler.go:103] [HigherPrecedence] Final decision: Does bronze-class-deploy-24-668b49b99b-ldm7g have precedence over bronze-class-deploy-25-b94944fb5-ghv2p? false
I0409 14:49:36.020704       1 scheduler.go:103] [HigherPrecedence] Final decision: Does bronze-class-deploy-25-b94944fb5-ghv2p have precedence over bronze-class-deploy-23-654ffb5cc5-879fc? true
I0409 14:49:36.020834       1 scheduler.go:103] [HigherPrecedence] Final decision: Does bronze-class-deploy-31-77756c9778-dqdd6 have precedence over bronze-class-deploy-3-775f4fbdd9-d77dm? true
I0409 14:49:36.020930       1 scheduler.go:103] [HigherPrecedence] Final decision: Does bronze-class-deploy-31-77756c9778-dqdd6 have precedence over bronze-class-deploy-8-6fff566748-k8mmd? true
I0409 14:49:36.020997       1 scheduler.go:103] [HigherPrecedence] Final decision: Does bronze-class-deploy-31-77756c9778-dqdd6 have precedence over bronze-class-deploy-11-559c656b44-cgqs5? true
I0409 14:49:36.021094       1 scheduler.go:103] [HigherPrecedence] Final decision: Does bronze-class-deploy-31-77756c9778-dqdd6 have precedence over bronze-class-deploy-16-74dd4696ff-7zksw? true
I0409 14:49:36.021165       1 scheduler.go:103] [HigherPrecedence] Final decision: Does bronze-class-deploy-31-77756c9778-dqdd6 have precedence over bronze-class-deploy-20-5fd9977fb4-wdm7w? true
I0409 14:49:36.021289       1 default_preemption.go:37] "Preemption failed or not needed" pod="default/bronze-class-deploy-31-77756c9778-dqdd6" status="0/2 nodes are available: 1 No preemption victims found for incoming pod, 1 Preemption is not helpful for scheduling."
I0409 14:49:36.021419       1 scheduler.go:103] [HigherPrecedence] Final decision: Does bronze-class-deploy-23-654ffb5cc5-879fc have precedence over bronze-class-deploy-24-668b49b99b-ldm7g? false
I0409 14:49:36.021672       1 scheduler.go:103] [HigherPrecedence] Final decision: Does bronze-class-deploy-25-b94944fb5-ghv2p have precedence over bronze-class-deploy-3-775f4fbdd9-d77dm? true
I0409 14:49:36.021891       1 scheduler.go:103] [HigherPrecedence] Final decision: Does bronze-class-deploy-25-b94944fb5-ghv2p have precedence over bronze-class-deploy-8-6fff566748-k8mmd? true
I0409 14:49:36.022005       1 scheduler.go:103] [HigherPrecedence] Final decision: Does bronze-class-deploy-25-b94944fb5-ghv2p have precedence over bronze-class-deploy-11-559c656b44-cgqs5? true
I0409 14:49:36.022117       1 scheduler.go:103] [HigherPrecedence] Final decision: Does bronze-class-deploy-25-b94944fb5-ghv2p have precedence over bronze-class-deploy-16-74dd4696ff-7zksw? true
I0409 14:49:36.022210       1 scheduler.go:103] [HigherPrecedence] Final decision: Does bronze-class-deploy-25-b94944fb5-ghv2p have precedence over bronze-class-deploy-20-5fd9977fb4-wdm7w? true
I0409 14:49:36.022354       1 default_preemption.go:37] "Preemption failed or not needed" pod="default/bronze-class-deploy-25-b94944fb5-ghv2p" status="0/2 nodes are available: 1 No preemption victims found for incoming pod, 1 Preemption is not helpful for scheduling."
I0409 14:49:36.022701       1 scheduler.go:103] [HigherPrecedence] Final decision: Does bronze-class-deploy-24-668b49b99b-ldm7g have precedence over bronze-class-deploy-3-775f4fbdd9-d77dm? true
I0409 14:49:36.022809       1 scheduler.go:103] [HigherPrecedence] Final decision: Does bronze-class-deploy-24-668b49b99b-ldm7g have precedence over bronze-class-deploy-8-6fff566748-k8mmd? true
I0409 14:49:36.022875       1 scheduler.go:103] [HigherPrecedence] Final decision: Does bronze-class-deploy-24-668b49b99b-ldm7g have precedence over bronze-class-deploy-11-559c656b44-cgqs5? true
I0409 14:49:36.022981       1 scheduler.go:103] [HigherPrecedence] Final decision: Does bronze-class-deploy-24-668b49b99b-ldm7g have precedence over bronze-class-deploy-16-74dd4696ff-7zksw? true
I0409 14:49:36.023064       1 scheduler.go:103] [HigherPrecedence] Final decision: Does bronze-class-deploy-24-668b49b99b-ldm7g have precedence over bronze-class-deploy-20-5fd9977fb4-wdm7w? true
I0409 14:49:36.023180       1 default_preemption.go:37] "Preemption failed or not needed" pod="default/bronze-class-deploy-24-668b49b99b-ldm7g" status="0/2 nodes are available: 1 No preemption victims found for incoming pod, 1 Preemption is not helpful for scheduling."
I0409 14:49:36.023481       1 scheduler.go:103] [HigherPrecedence] Final decision: Does bronze-class-deploy-23-654ffb5cc5-879fc have precedence over bronze-class-deploy-3-775f4fbdd9-d77dm? true
I0409 14:49:36.023596       1 scheduler.go:103] [HigherPrecedence] Final decision: Does bronze-class-deploy-23-654ffb5cc5-879fc have precedence over bronze-class-deploy-8-6fff566748-k8mmd? true
I0409 14:49:36.023657       1 scheduler.go:103] [HigherPrecedence] Final decision: Does bronze-class-deploy-23-654ffb5cc5-879fc have precedence over bronze-class-deploy-11-559c656b44-cgqs5? true
I0409 14:49:36.023755       1 scheduler.go:103] [HigherPrecedence] Final decision: Does bronze-class-deploy-23-654ffb5cc5-879fc have precedence over bronze-class-deploy-16-74dd4696ff-7zksw? true
I0409 14:49:36.023839       1 scheduler.go:103] [HigherPrecedence] Final decision: Does bronze-class-deploy-23-654ffb5cc5-879fc have precedence over bronze-class-deploy-20-5fd9977fb4-wdm7w? true
I0409 14:49:36.023967       1 default_preemption.go:37] "Preemption failed or not needed" pod="default/bronze-class-deploy-23-654ffb5cc5-879fc" status="0/2 nodes are available: 1 No preemption victims found for incoming pod, 1 Preemption is not helpful for scheduling."
I0409 14:50:06.018859       1 default_preemption.go:51] [PreEnqueue] PreEnqueue called for pod: bronze-class-deploy-29-7d6b766b6f-m85bq
I0409 14:50:06.018883       1 default_preemption.go:52] [PreEnqueue] SchedulerName for pod bronze-class-deploy-29-7d6b766b6f-m85bq: custom-scheduler
I0409 14:50:06.018919       1 default_preemption.go:51] [PreEnqueue] PreEnqueue called for pod: bronze-class-deploy-28-946b5bff6-z6khm
I0409 14:50:06.018923       1 default_preemption.go:52] [PreEnqueue] SchedulerName for pod bronze-class-deploy-28-946b5bff6-z6khm: custom-scheduler
I0409 14:50:06.018948       1 scheduler.go:103] [HigherPrecedence] Final decision: Does bronze-class-deploy-28-946b5bff6-z6khm have precedence over bronze-class-deploy-29-7d6b766b6f-m85bq? false
I0409 14:50:06.018961       1 default_preemption.go:51] [PreEnqueue] PreEnqueue called for pod: bronze-class-deploy-30-56698788c5-l8dqg
I0409 14:50:06.018970       1 default_preemption.go:52] [PreEnqueue] SchedulerName for pod bronze-class-deploy-30-56698788c5-l8dqg: custom-scheduler
I0409 14:50:06.018996       1 scheduler.go:103] [HigherPrecedence] Final decision: Does bronze-class-deploy-30-56698788c5-l8dqg have precedence over bronze-class-deploy-29-7d6b766b6f-m85bq? false
I0409 14:50:06.019018       1 default_preemption.go:51] [PreEnqueue] PreEnqueue called for pod: bronze-class-deploy-31-77756c9778-dqdd6
I0409 14:50:06.019022       1 default_preemption.go:52] [PreEnqueue] SchedulerName for pod bronze-class-deploy-31-77756c9778-dqdd6: custom-scheduler
I0409 14:50:06.019047       1 scheduler.go:103] [HigherPrecedence] Final decision: Does bronze-class-deploy-31-77756c9778-dqdd6 have precedence over bronze-class-deploy-28-946b5bff6-z6khm? false
I0409 14:50:06.019068       1 default_preemption.go:51] [PreEnqueue] PreEnqueue called for pod: bronze-class-deploy-25-b94944fb5-ghv2p
I0409 14:50:06.019073       1 default_preemption.go:52] [PreEnqueue] SchedulerName for pod bronze-class-deploy-25-b94944fb5-ghv2p: custom-scheduler
I0409 14:50:06.019100       1 scheduler.go:103] [HigherPrecedence] Final decision: Does bronze-class-deploy-25-b94944fb5-ghv2p have precedence over bronze-class-deploy-28-946b5bff6-z6khm? false
I0409 14:50:06.019123       1 default_preemption.go:51] [PreEnqueue] PreEnqueue called for pod: bronze-class-deploy-24-668b49b99b-ldm7g
I0409 14:50:06.019128       1 default_preemption.go:52] [PreEnqueue] SchedulerName for pod bronze-class-deploy-24-668b49b99b-ldm7g: custom-scheduler
I0409 14:50:06.019157       1 scheduler.go:103] [HigherPrecedence] Final decision: Does bronze-class-deploy-24-668b49b99b-ldm7g have precedence over bronze-class-deploy-30-56698788c5-l8dqg? false
I0409 14:50:06.019182       1 default_preemption.go:51] [PreEnqueue] PreEnqueue called for pod: bronze-class-deploy-23-654ffb5cc5-879fc
I0409 14:50:06.019186       1 default_preemption.go:52] [PreEnqueue] SchedulerName for pod bronze-class-deploy-23-654ffb5cc5-879fc: custom-scheduler
I0409 14:50:06.019214       1 scheduler.go:103] [HigherPrecedence] Final decision: Does bronze-class-deploy-23-654ffb5cc5-879fc have precedence over bronze-class-deploy-30-56698788c5-l8dqg? false
I0409 14:50:06.019263       1 scheduler.go:103] [HigherPrecedence] Final decision: Does bronze-class-deploy-30-56698788c5-l8dqg have precedence over bronze-class-deploy-28-946b5bff6-z6khm? false
I0409 14:50:06.019294       1 scheduler.go:103] [HigherPrecedence] Final decision: Does bronze-class-deploy-28-946b5bff6-z6khm have precedence over bronze-class-deploy-23-654ffb5cc5-879fc? true
I0409 14:50:06.019309       1 scheduler.go:103] [HigherPrecedence] Final decision: Does bronze-class-deploy-25-b94944fb5-ghv2p have precedence over bronze-class-deploy-31-77756c9778-dqdd6? false
I0409 14:50:06.019323       1 scheduler.go:103] [HigherPrecedence] Final decision: Does bronze-class-deploy-31-77756c9778-dqdd6 have precedence over bronze-class-deploy-23-654ffb5cc5-879fc? true
I0409 14:50:06.019555       1 scheduler.go:103] [HigherPrecedence] Final decision: Does bronze-class-deploy-29-7d6b766b6f-m85bq have precedence over bronze-class-deploy-3-775f4fbdd9-d77dm? true
I0409 14:50:06.019663       1 scheduler.go:103] [HigherPrecedence] Final decision: Does bronze-class-deploy-29-7d6b766b6f-m85bq have precedence over bronze-class-deploy-8-6fff566748-k8mmd? true
I0409 14:50:06.019759       1 scheduler.go:103] [HigherPrecedence] Final decision: Does bronze-class-deploy-29-7d6b766b6f-m85bq have precedence over bronze-class-deploy-11-559c656b44-cgqs5? true
I0409 14:50:06.019880       1 scheduler.go:103] [HigherPrecedence] Final decision: Does bronze-class-deploy-29-7d6b766b6f-m85bq have precedence over bronze-class-deploy-16-74dd4696ff-7zksw? true
I0409 14:50:06.019997       1 scheduler.go:103] [HigherPrecedence] Final decision: Does bronze-class-deploy-29-7d6b766b6f-m85bq have precedence over bronze-class-deploy-20-5fd9977fb4-wdm7w? true
I0409 14:50:06.027424       1 scheduler.go:255] [OnUpdatePod] Updating 'LastStatus' of pod default/bronze-class-deploy-20-5fd9977fb4-wdm7w in metrics
I0409 14:50:06.033345       1 scheduler.go:255] [OnUpdatePod] Updating 'LastStatus' of pod default/bronze-class-deploy-20-5fd9977fb4-wdm7w in metrics
I0409 14:50:06.037561       1 default_preemption.go:39] "Preemption successful" pod="default/bronze-class-deploy-29-7d6b766b6f-m85bq" nominatedNode="kwok-node-1"
I0409 14:50:06.037728       1 scheduler.go:286] [OnDeletePod] Checking the state of pod default/bronze-class-deploy-20-5fd9977fb4-wdm7w in metrics
I0409 14:50:06.043776       1 scheduler.go:205] [OnAddPod] Pod added: default/bronze-class-deploy-20-5fd9977fb4-hj4vm, Annotations: map[acceptablePreemptionOverhead:0.05 controller:bronze-controller-20 kwok.x-k8s.io/usage-cpu:1m kwok.x-k8s.io/usage-memory:1Mi qosMeasuring:average slo:0.5]
I0409 14:50:06.043824       1 default_preemption.go:51] [PreEnqueue] PreEnqueue called for pod: bronze-class-deploy-20-5fd9977fb4-hj4vm
I0409 14:50:06.043841       1 default_preemption.go:52] [PreEnqueue] SchedulerName for pod bronze-class-deploy-20-5fd9977fb4-hj4vm: custom-scheduler
W0409 14:50:06.043876       1 scheduler.go:118] [cacheMiss] Metrics not found for pod: default/bronze-class-deploy-20-5fd9977fb4-hj4vm
W0409 14:50:06.043883       1 scheduler.go:125] [WaitForPodsOnCache] Pod bronze-class-deploy-20-5fd9977fb4-hj4vm not found in cache. Retrying...
I0409 14:50:06.046638       1 scheduler.go:255] [OnUpdatePod] Updating 'LastStatus' of pod default/bronze-class-deploy-29-7d6b766b6f-m85bq in metrics
I0409 14:50:06.144438       1 scheduler.go:103] [HigherPrecedence] Final decision: Does bronze-class-deploy-20-5fd9977fb4-hj4vm have precedence over bronze-class-deploy-30-56698788c5-l8dqg? false
I0409 14:50:06.144567       1 scheduler.go:103] [HigherPrecedence] Final decision: Does bronze-class-deploy-30-56698788c5-l8dqg have precedence over bronze-class-deploy-31-77756c9778-dqdd6? true
I0409 14:50:06.144603       1 scheduler.go:103] [HigherPrecedence] Final decision: Does bronze-class-deploy-30-56698788c5-l8dqg have precedence over bronze-class-deploy-20-5fd9977fb4-hj4vm? true
I0409 14:50:06.144622       1 scheduler.go:103] [HigherPrecedence] Final decision: Does bronze-class-deploy-24-668b49b99b-ldm7g have precedence over bronze-class-deploy-20-5fd9977fb4-hj4vm? true
I0409 14:50:06.144947       1 scheduler.go:103] [HigherPrecedence] Final decision: Does bronze-class-deploy-28-946b5bff6-z6khm have precedence over bronze-class-deploy-3-775f4fbdd9-d77dm? true
I0409 14:50:06.145055       1 scheduler.go:103] [HigherPrecedence] Final decision: Does bronze-class-deploy-28-946b5bff6-z6khm have precedence over bronze-class-deploy-8-6fff566748-k8mmd? true
I0409 14:50:06.145134       1 scheduler.go:103] [HigherPrecedence] Final decision: Does bronze-class-deploy-28-946b5bff6-z6khm have precedence over bronze-class-deploy-11-559c656b44-cgqs5? true
I0409 14:50:06.145230       1 scheduler.go:103] [HigherPrecedence] Final decision: Does bronze-class-deploy-28-946b5bff6-z6khm have precedence over bronze-class-deploy-16-74dd4696ff-7zksw? true
I0409 14:50:06.152565       1 scheduler.go:255] [OnUpdatePod] Updating 'LastStatus' of pod default/bronze-class-deploy-16-74dd4696ff-7zksw in metrics
I0409 14:50:06.157984       1 scheduler.go:255] [OnUpdatePod] Updating 'LastStatus' of pod default/bronze-class-deploy-16-74dd4696ff-7zksw in metrics
I0409 14:50:06.161424       1 scheduler.go:103] [HigherPrecedence] Final decision: Does bronze-class-deploy-28-946b5bff6-z6khm have precedence over bronze-class-deploy-29-7d6b766b6f-m85bq? false
I0409 14:50:06.161454       1 default_preemption.go:39] "Preemption successful" pod="default/bronze-class-deploy-28-946b5bff6-z6khm" nominatedNode="kwok-node-1"
I0409 14:50:06.161563       1 scheduler.go:286] [OnDeletePod] Checking the state of pod default/bronze-class-deploy-16-74dd4696ff-7zksw in metrics
I0409 14:50:06.164172       1 default_preemption.go:51] [PreEnqueue] PreEnqueue called for pod: bronze-class-deploy-16-74dd4696ff-mkf54
I0409 14:50:06.164204       1 default_preemption.go:52] [PreEnqueue] SchedulerName for pod bronze-class-deploy-16-74dd4696ff-mkf54: custom-scheduler
I0409 14:50:06.164208       1 scheduler.go:205] [OnAddPod] Pod added: default/bronze-class-deploy-16-74dd4696ff-mkf54, Annotations: map[acceptablePreemptionOverhead:0.05 controller:bronze-controller-16 kwok.x-k8s.io/usage-cpu:1m kwok.x-k8s.io/usage-memory:1Mi qosMeasuring:average slo:0.5]
W0409 14:50:06.164248       1 scheduler.go:118] [cacheMiss] Metrics not found for pod: default/bronze-class-deploy-16-74dd4696ff-mkf54
W0409 14:50:06.164254       1 scheduler.go:125] [WaitForPodsOnCache] Pod bronze-class-deploy-16-74dd4696ff-mkf54 not found in cache. Retrying...
I0409 14:50:06.168418       1 scheduler.go:255] [OnUpdatePod] Updating 'LastStatus' of pod default/bronze-class-deploy-28-946b5bff6-z6khm in metrics
I0409 14:50:06.264409       1 scheduler.go:103] [HigherPrecedence] Final decision: Does bronze-class-deploy-16-74dd4696ff-mkf54 have precedence over bronze-class-deploy-24-668b49b99b-ldm7g? false
I0409 14:50:06.264540       1 scheduler.go:103] [HigherPrecedence] Final decision: Does bronze-class-deploy-24-668b49b99b-ldm7g have precedence over bronze-class-deploy-31-77756c9778-dqdd6? false
I0409 14:50:06.264579       1 scheduler.go:103] [HigherPrecedence] Final decision: Does bronze-class-deploy-31-77756c9778-dqdd6 have precedence over bronze-class-deploy-16-74dd4696ff-mkf54? true
I0409 14:50:06.264600       1 scheduler.go:103] [HigherPrecedence] Final decision: Does bronze-class-deploy-25-b94944fb5-ghv2p have precedence over bronze-class-deploy-23-654ffb5cc5-879fc? true
I0409 14:50:06.264625       1 scheduler.go:103] [HigherPrecedence] Final decision: Does bronze-class-deploy-25-b94944fb5-ghv2p have precedence over bronze-class-deploy-16-74dd4696ff-mkf54? true
I0409 14:50:06.264916       1 scheduler.go:103] [HigherPrecedence] Final decision: Does bronze-class-deploy-30-56698788c5-l8dqg have precedence over bronze-class-deploy-3-775f4fbdd9-d77dm? true
I0409 14:50:06.265014       1 scheduler.go:103] [HigherPrecedence] Final decision: Does bronze-class-deploy-30-56698788c5-l8dqg have precedence over bronze-class-deploy-8-6fff566748-k8mmd? true
I0409 14:50:06.265083       1 scheduler.go:103] [HigherPrecedence] Final decision: Does bronze-class-deploy-30-56698788c5-l8dqg have precedence over bronze-class-deploy-11-559c656b44-cgqs5? true
I0409 14:50:06.272244       1 scheduler.go:255] [OnUpdatePod] Updating 'LastStatus' of pod default/bronze-class-deploy-11-559c656b44-cgqs5 in metrics
I0409 14:50:06.275761       1 scheduler.go:255] [OnUpdatePod] Updating 'LastStatus' of pod default/bronze-class-deploy-11-559c656b44-cgqs5 in metrics
I0409 14:50:06.280221       1 default_preemption.go:51] [PreEnqueue] PreEnqueue called for pod: bronze-class-deploy-11-559c656b44-5grsk
I0409 14:50:06.280242       1 default_preemption.go:52] [PreEnqueue] SchedulerName for pod bronze-class-deploy-11-559c656b44-5grsk: custom-scheduler
I0409 14:50:06.280241       1 scheduler.go:205] [OnAddPod] Pod added: default/bronze-class-deploy-11-559c656b44-5grsk, Annotations: map[acceptablePreemptionOverhead:0.05 controller:bronze-controller-11 kwok.x-k8s.io/usage-cpu:1m kwok.x-k8s.io/usage-memory:1Mi qosMeasuring:average slo:0.5]
W0409 14:50:06.280279       1 scheduler.go:118] [cacheMiss] Metrics not found for pod: default/bronze-class-deploy-11-559c656b44-5grsk
W0409 14:50:06.280287       1 scheduler.go:125] [WaitForPodsOnCache] Pod bronze-class-deploy-11-559c656b44-5grsk not found in cache. Retrying...
I0409 14:50:06.281564       1 scheduler.go:286] [OnDeletePod] Checking the state of pod default/bronze-class-deploy-11-559c656b44-cgqs5 in metrics
I0409 14:50:06.380931       1 scheduler.go:103] [HigherPrecedence] Final decision: Does bronze-class-deploy-11-559c656b44-5grsk have precedence over bronze-class-deploy-24-668b49b99b-ldm7g? false
I0409 14:50:06.381109       1 scheduler.go:103] [HigherPrecedence] Final decision: Does bronze-class-deploy-30-56698788c5-l8dqg have precedence over bronze-class-deploy-29-7d6b766b6f-m85bq? false
I0409 14:50:06.381140       1 scheduler.go:103] [HigherPrecedence] Final decision: Does bronze-class-deploy-30-56698788c5-l8dqg have precedence over bronze-class-deploy-28-946b5bff6-z6khm? false
I0409 14:50:06.381160       1 default_preemption.go:39] "Preemption successful" pod="default/bronze-class-deploy-30-56698788c5-l8dqg" nominatedNode="kwok-node-1"
I0409 14:50:06.388305       1 scheduler.go:255] [OnUpdatePod] Updating 'LastStatus' of pod default/bronze-class-deploy-30-56698788c5-l8dqg in metrics
I0409 14:50:06.388416       1 scheduler.go:103] [HigherPrecedence] Final decision: Does bronze-class-deploy-24-668b49b99b-ldm7g have precedence over bronze-class-deploy-25-b94944fb5-ghv2p? false
I0409 14:50:06.388445       1 scheduler.go:103] [HigherPrecedence] Final decision: Does bronze-class-deploy-25-b94944fb5-ghv2p have precedence over bronze-class-deploy-11-559c656b44-5grsk? true
I0409 14:50:06.388475       1 scheduler.go:103] [HigherPrecedence] Final decision: Does bronze-class-deploy-16-74dd4696ff-mkf54 have precedence over bronze-class-deploy-23-654ffb5cc5-879fc? false
I0409 14:50:06.388495       1 scheduler.go:103] [HigherPrecedence] Final decision: Does bronze-class-deploy-23-654ffb5cc5-879fc have precedence over bronze-class-deploy-11-559c656b44-5grsk? true
I0409 14:50:06.388831       1 scheduler.go:103] [HigherPrecedence] Final decision: Does bronze-class-deploy-31-77756c9778-dqdd6 have precedence over bronze-class-deploy-3-775f4fbdd9-d77dm? true
I0409 14:50:06.388962       1 scheduler.go:103] [HigherPrecedence] Final decision: Does bronze-class-deploy-31-77756c9778-dqdd6 have precedence over bronze-class-deploy-8-6fff566748-k8mmd? true
I0409 14:50:06.396401       1 scheduler.go:255] [OnUpdatePod] Updating 'LastStatus' of pod default/bronze-class-deploy-8-6fff566748-k8mmd in metrics
I0409 14:50:06.401993       1 scheduler.go:255] [OnUpdatePod] Updating 'LastStatus' of pod default/bronze-class-deploy-8-6fff566748-k8mmd in metrics
I0409 14:50:06.405724       1 scheduler.go:103] [HigherPrecedence] Final decision: Does bronze-class-deploy-31-77756c9778-dqdd6 have precedence over bronze-class-deploy-29-7d6b766b6f-m85bq? false
I0409 14:50:06.405770       1 scheduler.go:103] [HigherPrecedence] Final decision: Does bronze-class-deploy-31-77756c9778-dqdd6 have precedence over bronze-class-deploy-28-946b5bff6-z6khm? false
I0409 14:50:06.405785       1 scheduler.go:103] [HigherPrecedence] Final decision: Does bronze-class-deploy-31-77756c9778-dqdd6 have precedence over bronze-class-deploy-30-56698788c5-l8dqg? false
I0409 14:50:06.405801       1 default_preemption.go:39] "Preemption successful" pod="default/bronze-class-deploy-31-77756c9778-dqdd6" nominatedNode="kwok-node-1"
I0409 14:50:06.405895       1 scheduler.go:286] [OnDeletePod] Checking the state of pod default/bronze-class-deploy-8-6fff566748-k8mmd in metrics
I0409 14:50:06.406571       1 default_preemption.go:51] [PreEnqueue] PreEnqueue called for pod: bronze-class-deploy-8-6fff566748-tt726
I0409 14:50:06.406582       1 default_preemption.go:52] [PreEnqueue] SchedulerName for pod bronze-class-deploy-8-6fff566748-tt726: custom-scheduler
I0409 14:50:06.406587       1 scheduler.go:205] [OnAddPod] Pod added: default/bronze-class-deploy-8-6fff566748-tt726, Annotations: map[acceptablePreemptionOverhead:0.05 controller:bronze-controller-8 kwok.x-k8s.io/usage-cpu:1m kwok.x-k8s.io/usage-memory:1Mi qosMeasuring:average slo:0.5]
W0409 14:50:06.406619       1 scheduler.go:118] [cacheMiss] Metrics not found for pod: default/bronze-class-deploy-8-6fff566748-tt726
W0409 14:50:06.406626       1 scheduler.go:125] [WaitForPodsOnCache] Pod bronze-class-deploy-8-6fff566748-tt726 not found in cache. Retrying...
I0409 14:50:06.414994       1 scheduler.go:255] [OnUpdatePod] Updating 'LastStatus' of pod default/bronze-class-deploy-31-77756c9778-dqdd6 in metrics
I0409 14:50:06.507195       1 scheduler.go:103] [HigherPrecedence] Final decision: Does bronze-class-deploy-8-6fff566748-tt726 have precedence over bronze-class-deploy-24-668b49b99b-ldm7g? false
I0409 14:50:06.507348       1 scheduler.go:103] [HigherPrecedence] Final decision: Does bronze-class-deploy-24-668b49b99b-ldm7g have precedence over bronze-class-deploy-23-654ffb5cc5-879fc? true
I0409 14:50:06.507399       1 scheduler.go:103] [HigherPrecedence] Final decision: Does bronze-class-deploy-24-668b49b99b-ldm7g have precedence over bronze-class-deploy-8-6fff566748-tt726? true
I0409 14:50:06.507420       1 scheduler.go:103] [HigherPrecedence] Final decision: Does bronze-class-deploy-20-5fd9977fb4-hj4vm have precedence over bronze-class-deploy-8-6fff566748-tt726? true
I0409 14:50:06.507768       1 scheduler.go:103] [HigherPrecedence] Final decision: Does bronze-class-deploy-25-b94944fb5-ghv2p have precedence over bronze-class-deploy-3-775f4fbdd9-d77dm? true
I0409 14:50:06.515650       1 scheduler.go:255] [OnUpdatePod] Updating 'LastStatus' of pod default/bronze-class-deploy-3-775f4fbdd9-d77dm in metrics
I0409 14:50:06.521729       1 scheduler.go:255] [OnUpdatePod] Updating 'LastStatus' of pod default/bronze-class-deploy-3-775f4fbdd9-d77dm in metrics
I0409 14:50:06.525400       1 scheduler.go:103] [HigherPrecedence] Final decision: Does bronze-class-deploy-25-b94944fb5-ghv2p have precedence over bronze-class-deploy-29-7d6b766b6f-m85bq? false
I0409 14:50:06.525468       1 scheduler.go:103] [HigherPrecedence] Final decision: Does bronze-class-deploy-25-b94944fb5-ghv2p have precedence over bronze-class-deploy-28-946b5bff6-z6khm? false
I0409 14:50:06.525494       1 scheduler.go:103] [HigherPrecedence] Final decision: Does bronze-class-deploy-25-b94944fb5-ghv2p have precedence over bronze-class-deploy-30-56698788c5-l8dqg? false
I0409 14:50:06.525513       1 scheduler.go:103] [HigherPrecedence] Final decision: Does bronze-class-deploy-25-b94944fb5-ghv2p have precedence over bronze-class-deploy-31-77756c9778-dqdd6? false
I0409 14:50:06.525542       1 scheduler.go:286] [OnDeletePod] Checking the state of pod default/bronze-class-deploy-3-775f4fbdd9-d77dm in metrics
I0409 14:50:06.525542       1 default_preemption.go:39] "Preemption successful" pod="default/bronze-class-deploy-25-b94944fb5-ghv2p" nominatedNode="kwok-node-1"
I0409 14:50:06.528668       1 default_preemption.go:51] [PreEnqueue] PreEnqueue called for pod: bronze-class-deploy-3-775f4fbdd9-h8pjj
I0409 14:50:06.528688       1 default_preemption.go:52] [PreEnqueue] SchedulerName for pod bronze-class-deploy-3-775f4fbdd9-h8pjj: custom-scheduler
I0409 14:50:06.528688       1 scheduler.go:205] [OnAddPod] Pod added: default/bronze-class-deploy-3-775f4fbdd9-h8pjj, Annotations: map[acceptablePreemptionOverhead:0.05 controller:bronze-controller-3 kwok.x-k8s.io/usage-cpu:1m kwok.x-k8s.io/usage-memory:1Mi qosMeasuring:average slo:0.5]
W0409 14:50:06.528720       1 scheduler.go:118] [cacheMiss] Metrics not found for pod: default/bronze-class-deploy-3-775f4fbdd9-h8pjj
W0409 14:50:06.528727       1 scheduler.go:125] [WaitForPodsOnCache] Pod bronze-class-deploy-3-775f4fbdd9-h8pjj not found in cache. Retrying...
I0409 14:50:06.532503       1 scheduler.go:255] [OnUpdatePod] Updating 'LastStatus' of pod default/bronze-class-deploy-25-b94944fb5-ghv2p in metrics
I0409 14:50:06.629786       1 scheduler.go:103] [HigherPrecedence] Final decision: Does bronze-class-deploy-3-775f4fbdd9-h8pjj have precedence over bronze-class-deploy-20-5fd9977fb4-hj4vm? false
I0409 14:50:06.629932       1 scheduler.go:103] [HigherPrecedence] Final decision: Does bronze-class-deploy-20-5fd9977fb4-hj4vm have precedence over bronze-class-deploy-23-654ffb5cc5-879fc? false
I0409 14:50:06.629983       1 scheduler.go:103] [HigherPrecedence] Final decision: Does bronze-class-deploy-23-654ffb5cc5-879fc have precedence over bronze-class-deploy-3-775f4fbdd9-h8pjj? true
I0409 14:50:06.630013       1 scheduler.go:103] [HigherPrecedence] Final decision: Does bronze-class-deploy-16-74dd4696ff-mkf54 have precedence over bronze-class-deploy-11-559c656b44-5grsk? true
I0409 14:50:06.630031       1 scheduler.go:103] [HigherPrecedence] Final decision: Does bronze-class-deploy-16-74dd4696ff-mkf54 have precedence over bronze-class-deploy-3-775f4fbdd9-h8pjj? true
I0409 14:50:06.630778       1 default_preemption.go:37] "Preemption failed or not needed" pod="default/bronze-class-deploy-24-668b49b99b-ldm7g" status="0/2 nodes are available: 1 No preemption victims found for incoming pod, 1 Preemption is not helpful for scheduling."
I0409 14:50:06.630895       1 scheduler.go:103] [HigherPrecedence] Final decision: Does bronze-class-deploy-20-5fd9977fb4-hj4vm have precedence over bronze-class-deploy-16-74dd4696ff-mkf54? true
I0409 14:50:06.630927       1 scheduler.go:103] [HigherPrecedence] Final decision: Does bronze-class-deploy-20-5fd9977fb4-hj4vm have precedence over bronze-class-deploy-8-6fff566748-tt726? true
I0409 14:50:06.631504       1 default_preemption.go:37] "Preemption failed or not needed" pod="default/bronze-class-deploy-23-654ffb5cc5-879fc" status="0/2 nodes are available: 1 No preemption victims found for incoming pod, 1 Preemption is not helpful for scheduling."
I0409 14:50:06.631605       1 scheduler.go:103] [HigherPrecedence] Final decision: Does bronze-class-deploy-8-6fff566748-tt726 have precedence over bronze-class-deploy-16-74dd4696ff-mkf54? false
I0409 14:50:06.631647       1 scheduler.go:103] [HigherPrecedence] Final decision: Does bronze-class-deploy-16-74dd4696ff-mkf54 have precedence over bronze-class-deploy-3-775f4fbdd9-h8pjj? true
I0409 14:50:06.631671       1 scheduler.go:103] [HigherPrecedence] Final decision: Does bronze-class-deploy-11-559c656b44-5grsk have precedence over bronze-class-deploy-3-775f4fbdd9-h8pjj? true
I0409 14:50:06.631897       1 scheduler.go:103] [HigherPrecedence] Final decision: Does bronze-class-deploy-20-5fd9977fb4-hj4vm have precedence over gold-class-deploy-1-78bb76545-pwz55? false
I0409 14:50:06.631927       1 scheduler.go:103] [HigherPrecedence] Final decision: Does bronze-class-deploy-20-5fd9977fb4-hj4vm have precedence over gold-class-deploy-2-58ff5bfb68-446gs? false
I0409 14:50:06.631951       1 scheduler.go:103] [HigherPrecedence] Final decision: Does bronze-class-deploy-20-5fd9977fb4-hj4vm have precedence over silver-class-deploy-21-7bf557854c-zflrc? false
I0409 14:50:06.631971       1 scheduler.go:103] [HigherPrecedence] Final decision: Does bronze-class-deploy-20-5fd9977fb4-hj4vm have precedence over gold-class-deploy-4-b6866bf4b-5dnw5? false
I0409 14:50:06.632002       1 scheduler.go:103] [HigherPrecedence] Final decision: Does bronze-class-deploy-20-5fd9977fb4-hj4vm have precedence over gold-class-deploy-5-c4557676f-pdmbf? false
I0409 14:50:06.632021       1 scheduler.go:103] [HigherPrecedence] Final decision: Does bronze-class-deploy-20-5fd9977fb4-hj4vm have precedence over gold-class-deploy-6-6df4d4d67b-bf8cr? false
I0409 14:50:06.632051       1 scheduler.go:103] [HigherPrecedence] Final decision: Does bronze-class-deploy-20-5fd9977fb4-hj4vm have precedence over silver-class-deploy-7-ff55f69ff-hwmfr? false
I0409 14:50:06.632071       1 scheduler.go:103] [HigherPrecedence] Final decision: Does bronze-class-deploy-20-5fd9977fb4-hj4vm have precedence over silver-class-deploy-22-8456bfbbc6-jrczs? false
I0409 14:50:06.632099       1 scheduler.go:103] [HigherPrecedence] Final decision: Does bronze-class-deploy-20-5fd9977fb4-hj4vm have precedence over gold-class-deploy-9-868dfbd94f-6hvv5? false
I0409 14:50:06.632128       1 scheduler.go:103] [HigherPrecedence] Final decision: Does bronze-class-deploy-20-5fd9977fb4-hj4vm have precedence over silver-class-deploy-10-6866d9b887-l2866? false
I0409 14:50:06.632159       1 scheduler.go:103] [HigherPrecedence] Final decision: Does bronze-class-deploy-20-5fd9977fb4-hj4vm have precedence over gold-class-deploy-27-6c45459fb5-m777t? false
I0409 14:50:06.632179       1 scheduler.go:103] [HigherPrecedence] Final decision: Does bronze-class-deploy-20-5fd9977fb4-hj4vm have precedence over gold-class-deploy-12-598494bf8f-jqzbs? false
I0409 14:50:06.632207       1 scheduler.go:103] [HigherPrecedence] Final decision: Does bronze-class-deploy-20-5fd9977fb4-hj4vm have precedence over gold-class-deploy-13-5f585cb744-n2l5p? false
I0409 14:50:06.632227       1 scheduler.go:103] [HigherPrecedence] Final decision: Does bronze-class-deploy-20-5fd9977fb4-hj4vm have precedence over silver-class-deploy-14-79f95c48b7-jh9nd? false
I0409 14:50:06.632257       1 scheduler.go:103] [HigherPrecedence] Final decision: Does bronze-class-deploy-20-5fd9977fb4-hj4vm have precedence over silver-class-deploy-15-cb96c7dc4-9m85g? false
I0409 14:50:06.632287       1 scheduler.go:103] [HigherPrecedence] Final decision: Does bronze-class-deploy-20-5fd9977fb4-hj4vm have precedence over gold-class-deploy-26-6bcb7b6c88-6jh2g? false
I0409 14:50:06.632310       1 scheduler.go:103] [HigherPrecedence] Final decision: Does bronze-class-deploy-20-5fd9977fb4-hj4vm have precedence over silver-class-deploy-17-59cbf4bc88-s2ngm? false
I0409 14:50:06.632340       1 scheduler.go:103] [HigherPrecedence] Final decision: Does bronze-class-deploy-20-5fd9977fb4-hj4vm have precedence over silver-class-deploy-18-5dd44b47c5-7d2lh? false
I0409 14:50:06.632383       1 scheduler.go:103] [HigherPrecedence] Final decision: Does bronze-class-deploy-20-5fd9977fb4-hj4vm have precedence over silver-class-deploy-19-7cc4c5b78-v9p7f? false
I0409 14:50:06.632407       1 scheduler.go:103] [HigherPrecedence] Final decision: Does bronze-class-deploy-20-5fd9977fb4-hj4vm have precedence over silver-class-deploy-32-84b675c847-wwmws? false
I0409 14:50:06.632442       1 default_preemption.go:37] "Preemption failed or not needed" pod="default/bronze-class-deploy-20-5fd9977fb4-hj4vm" status="0/2 nodes are available: 1 No preemption victims found for incoming pod, 1 Preemption is not helpful for scheduling."
I0409 14:50:06.638883       1 scheduler.go:103] [HigherPrecedence] Final decision: Does bronze-class-deploy-8-6fff566748-tt726 have precedence over bronze-class-deploy-11-559c656b44-5grsk? false
I0409 14:50:06.638931       1 scheduler.go:103] [HigherPrecedence] Final decision: Does bronze-class-deploy-11-559c656b44-5grsk have precedence over bronze-class-deploy-3-775f4fbdd9-h8pjj? true
I0409 14:50:06.638940       1 scheduler.go:255] [OnUpdatePod] Updating 'LastStatus' of pod default/bronze-class-deploy-20-5fd9977fb4-hj4vm in metrics
I0409 14:50:06.639295       1 scheduler.go:103] [HigherPrecedence] Final decision: Does bronze-class-deploy-16-74dd4696ff-mkf54 have precedence over gold-class-deploy-1-78bb76545-pwz55? false
I0409 14:50:06.639327       1 scheduler.go:103] [HigherPrecedence] Final decision: Does bronze-class-deploy-16-74dd4696ff-mkf54 have precedence over gold-class-deploy-2-58ff5bfb68-446gs? false
I0409 14:50:06.639344       1 scheduler.go:103] [HigherPrecedence] Final decision: Does bronze-class-deploy-16-74dd4696ff-mkf54 have precedence over silver-class-deploy-21-7bf557854c-zflrc? false
I0409 14:50:06.639390       1 scheduler.go:103] [HigherPrecedence] Final decision: Does bronze-class-deploy-16-74dd4696ff-mkf54 have precedence over gold-class-deploy-4-b6866bf4b-5dnw5? false
I0409 14:50:06.639419       1 scheduler.go:103] [HigherPrecedence] Final decision: Does bronze-class-deploy-16-74dd4696ff-mkf54 have precedence over gold-class-deploy-5-c4557676f-pdmbf? false
I0409 14:50:06.639442       1 scheduler.go:103] [HigherPrecedence] Final decision: Does bronze-class-deploy-16-74dd4696ff-mkf54 have precedence over gold-class-deploy-6-6df4d4d67b-bf8cr? false
I0409 14:50:06.639473       1 scheduler.go:103] [HigherPrecedence] Final decision: Does bronze-class-deploy-16-74dd4696ff-mkf54 have precedence over silver-class-deploy-7-ff55f69ff-hwmfr? false
I0409 14:50:06.639494       1 scheduler.go:103] [HigherPrecedence] Final decision: Does bronze-class-deploy-16-74dd4696ff-mkf54 have precedence over silver-class-deploy-22-8456bfbbc6-jrczs? false
I0409 14:50:06.639516       1 scheduler.go:103] [HigherPrecedence] Final decision: Does bronze-class-deploy-16-74dd4696ff-mkf54 have precedence over gold-class-deploy-9-868dfbd94f-6hvv5? false
I0409 14:50:06.639548       1 scheduler.go:103] [HigherPrecedence] Final decision: Does bronze-class-deploy-16-74dd4696ff-mkf54 have precedence over silver-class-deploy-10-6866d9b887-l2866? false
I0409 14:50:06.639564       1 scheduler.go:103] [HigherPrecedence] Final decision: Does bronze-class-deploy-16-74dd4696ff-mkf54 have precedence over gold-class-deploy-27-6c45459fb5-m777t? false
I0409 14:50:06.639586       1 scheduler.go:103] [HigherPrecedence] Final decision: Does bronze-class-deploy-16-74dd4696ff-mkf54 have precedence over gold-class-deploy-12-598494bf8f-jqzbs? false
I0409 14:50:06.639602       1 scheduler.go:103] [HigherPrecedence] Final decision: Does bronze-class-deploy-16-74dd4696ff-mkf54 have precedence over gold-class-deploy-13-5f585cb744-n2l5p? false
I0409 14:50:06.639617       1 scheduler.go:103] [HigherPrecedence] Final decision: Does bronze-class-deploy-16-74dd4696ff-mkf54 have precedence over silver-class-deploy-14-79f95c48b7-jh9nd? false
I0409 14:50:06.639640       1 scheduler.go:103] [HigherPrecedence] Final decision: Does bronze-class-deploy-16-74dd4696ff-mkf54 have precedence over silver-class-deploy-15-cb96c7dc4-9m85g? false
I0409 14:50:06.639656       1 scheduler.go:103] [HigherPrecedence] Final decision: Does bronze-class-deploy-16-74dd4696ff-mkf54 have precedence over gold-class-deploy-26-6bcb7b6c88-6jh2g? false
I0409 14:50:06.639678       1 scheduler.go:103] [HigherPrecedence] Final decision: Does bronze-class-deploy-16-74dd4696ff-mkf54 have precedence over silver-class-deploy-17-59cbf4bc88-s2ngm? false
I0409 14:50:06.639700       1 scheduler.go:103] [HigherPrecedence] Final decision: Does bronze-class-deploy-16-74dd4696ff-mkf54 have precedence over silver-class-deploy-18-5dd44b47c5-7d2lh? false
I0409 14:50:06.639721       1 scheduler.go:103] [HigherPrecedence] Final decision: Does bronze-class-deploy-16-74dd4696ff-mkf54 have precedence over silver-class-deploy-19-7cc4c5b78-v9p7f? false
I0409 14:50:06.639737       1 scheduler.go:103] [HigherPrecedence] Final decision: Does bronze-class-deploy-16-74dd4696ff-mkf54 have precedence over silver-class-deploy-32-84b675c847-wwmws? false
I0409 14:50:06.639775       1 default_preemption.go:37] "Preemption failed or not needed" pod="default/bronze-class-deploy-16-74dd4696ff-mkf54" status="0/2 nodes are available: 1 No preemption victims found for incoming pod, 1 Preemption is not helpful for scheduling."
I0409 14:50:06.646058       1 scheduler.go:103] [HigherPrecedence] Final decision: Does bronze-class-deploy-3-775f4fbdd9-h8pjj have precedence over bronze-class-deploy-8-6fff566748-tt726? false
I0409 14:50:06.646084       1 scheduler.go:255] [OnUpdatePod] Updating 'LastStatus' of pod default/bronze-class-deploy-16-74dd4696ff-mkf54 in metrics
I0409 14:50:06.646467       1 scheduler.go:103] [HigherPrecedence] Final decision: Does bronze-class-deploy-11-559c656b44-5grsk have precedence over gold-class-deploy-1-78bb76545-pwz55? false
I0409 14:50:06.646507       1 scheduler.go:103] [HigherPrecedence] Final decision: Does bronze-class-deploy-11-559c656b44-5grsk have precedence over gold-class-deploy-2-58ff5bfb68-446gs? false
I0409 14:50:06.646523       1 scheduler.go:103] [HigherPrecedence] Final decision: Does bronze-class-deploy-11-559c656b44-5grsk have precedence over silver-class-deploy-21-7bf557854c-zflrc? false
I0409 14:50:06.646538       1 scheduler.go:103] [HigherPrecedence] Final decision: Does bronze-class-deploy-11-559c656b44-5grsk have precedence over gold-class-deploy-4-b6866bf4b-5dnw5? false
I0409 14:50:06.646555       1 scheduler.go:103] [HigherPrecedence] Final decision: Does bronze-class-deploy-11-559c656b44-5grsk have precedence over gold-class-deploy-5-c4557676f-pdmbf? false
I0409 14:50:06.646571       1 scheduler.go:103] [HigherPrecedence] Final decision: Does bronze-class-deploy-11-559c656b44-5grsk have precedence over gold-class-deploy-6-6df4d4d67b-bf8cr? false
I0409 14:50:06.646595       1 scheduler.go:103] [HigherPrecedence] Final decision: Does bronze-class-deploy-11-559c656b44-5grsk have precedence over silver-class-deploy-7-ff55f69ff-hwmfr? false
I0409 14:50:06.646624       1 scheduler.go:103] [HigherPrecedence] Final decision: Does bronze-class-deploy-11-559c656b44-5grsk have precedence over silver-class-deploy-22-8456bfbbc6-jrczs? false
I0409 14:50:06.646652       1 scheduler.go:103] [HigherPrecedence] Final decision: Does bronze-class-deploy-11-559c656b44-5grsk have precedence over gold-class-deploy-9-868dfbd94f-6hvv5? false
I0409 14:50:06.646674       1 scheduler.go:103] [HigherPrecedence] Final decision: Does bronze-class-deploy-11-559c656b44-5grsk have precedence over silver-class-deploy-10-6866d9b887-l2866? false
I0409 14:50:06.646703       1 scheduler.go:103] [HigherPrecedence] Final decision: Does bronze-class-deploy-11-559c656b44-5grsk have precedence over gold-class-deploy-27-6c45459fb5-m777t? false
I0409 14:50:06.646726       1 scheduler.go:103] [HigherPrecedence] Final decision: Does bronze-class-deploy-11-559c656b44-5grsk have precedence over gold-class-deploy-12-598494bf8f-jqzbs? false
I0409 14:50:06.646755       1 scheduler.go:103] [HigherPrecedence] Final decision: Does bronze-class-deploy-11-559c656b44-5grsk have precedence over gold-class-deploy-13-5f585cb744-n2l5p? false
I0409 14:50:06.646774       1 scheduler.go:103] [HigherPrecedence] Final decision: Does bronze-class-deploy-11-559c656b44-5grsk have precedence over silver-class-deploy-14-79f95c48b7-jh9nd? false
I0409 14:50:06.646807       1 scheduler.go:103] [HigherPrecedence] Final decision: Does bronze-class-deploy-11-559c656b44-5grsk have precedence over silver-class-deploy-15-cb96c7dc4-9m85g? false
I0409 14:50:06.646823       1 scheduler.go:103] [HigherPrecedence] Final decision: Does bronze-class-deploy-11-559c656b44-5grsk have precedence over gold-class-deploy-26-6bcb7b6c88-6jh2g? false
I0409 14:50:06.646845       1 scheduler.go:103] [HigherPrecedence] Final decision: Does bronze-class-deploy-11-559c656b44-5grsk have precedence over silver-class-deploy-17-59cbf4bc88-s2ngm? false
I0409 14:50:06.646863       1 scheduler.go:103] [HigherPrecedence] Final decision: Does bronze-class-deploy-11-559c656b44-5grsk have precedence over silver-class-deploy-18-5dd44b47c5-7d2lh? false
I0409 14:50:06.646885       1 scheduler.go:103] [HigherPrecedence] Final decision: Does bronze-class-deploy-11-559c656b44-5grsk have precedence over silver-class-deploy-19-7cc4c5b78-v9p7f? false
I0409 14:50:06.646901       1 scheduler.go:103] [HigherPrecedence] Final decision: Does bronze-class-deploy-11-559c656b44-5grsk have precedence over silver-class-deploy-32-84b675c847-wwmws? false
I0409 14:50:06.646933       1 default_preemption.go:37] "Preemption failed or not needed" pod="default/bronze-class-deploy-11-559c656b44-5grsk" status="0/2 nodes are available: 1 No preemption victims found for incoming pod, 1 Preemption is not helpful for scheduling."
I0409 14:50:06.655713       1 scheduler.go:255] [OnUpdatePod] Updating 'LastStatus' of pod default/bronze-class-deploy-11-559c656b44-5grsk in metrics
I0409 14:50:06.655810       1 scheduler.go:103] [HigherPrecedence] Final decision: Does bronze-class-deploy-8-6fff566748-tt726 have precedence over gold-class-deploy-1-78bb76545-pwz55? false
I0409 14:50:06.655858       1 scheduler.go:103] [HigherPrecedence] Final decision: Does bronze-class-deploy-8-6fff566748-tt726 have precedence over gold-class-deploy-2-58ff5bfb68-446gs? false
I0409 14:50:06.655882       1 scheduler.go:103] [HigherPrecedence] Final decision: Does bronze-class-deploy-8-6fff566748-tt726 have precedence over silver-class-deploy-21-7bf557854c-zflrc? false
I0409 14:50:06.655912       1 scheduler.go:103] [HigherPrecedence] Final decision: Does bronze-class-deploy-8-6fff566748-tt726 have precedence over gold-class-deploy-4-b6866bf4b-5dnw5? false
I0409 14:50:06.655933       1 scheduler.go:103] [HigherPrecedence] Final decision: Does bronze-class-deploy-8-6fff566748-tt726 have precedence over gold-class-deploy-5-c4557676f-pdmbf? false
I0409 14:50:06.655960       1 scheduler.go:103] [HigherPrecedence] Final decision: Does bronze-class-deploy-8-6fff566748-tt726 have precedence over gold-class-deploy-6-6df4d4d67b-bf8cr? false
I0409 14:50:06.655976       1 scheduler.go:103] [HigherPrecedence] Final decision: Does bronze-class-deploy-8-6fff566748-tt726 have precedence over silver-class-deploy-7-ff55f69ff-hwmfr? false
I0409 14:50:06.655996       1 scheduler.go:103] [HigherPrecedence] Final decision: Does bronze-class-deploy-8-6fff566748-tt726 have precedence over silver-class-deploy-22-8456bfbbc6-jrczs? false
I0409 14:50:06.656026       1 scheduler.go:103] [HigherPrecedence] Final decision: Does bronze-class-deploy-8-6fff566748-tt726 have precedence over gold-class-deploy-9-868dfbd94f-6hvv5? false
I0409 14:50:06.656047       1 scheduler.go:103] [HigherPrecedence] Final decision: Does bronze-class-deploy-8-6fff566748-tt726 have precedence over silver-class-deploy-10-6866d9b887-l2866? false
I0409 14:50:06.656073       1 scheduler.go:103] [HigherPrecedence] Final decision: Does bronze-class-deploy-8-6fff566748-tt726 have precedence over gold-class-deploy-27-6c45459fb5-m777t? false
I0409 14:50:06.656109       1 scheduler.go:103] [HigherPrecedence] Final decision: Does bronze-class-deploy-8-6fff566748-tt726 have precedence over gold-class-deploy-12-598494bf8f-jqzbs? false
I0409 14:50:06.656130       1 scheduler.go:103] [HigherPrecedence] Final decision: Does bronze-class-deploy-8-6fff566748-tt726 have precedence over gold-class-deploy-13-5f585cb744-n2l5p? false
I0409 14:50:06.656159       1 scheduler.go:103] [HigherPrecedence] Final decision: Does bronze-class-deploy-8-6fff566748-tt726 have precedence over silver-class-deploy-14-79f95c48b7-jh9nd? false
I0409 14:50:06.656191       1 scheduler.go:103] [HigherPrecedence] Final decision: Does bronze-class-deploy-8-6fff566748-tt726 have precedence over silver-class-deploy-15-cb96c7dc4-9m85g? false
I0409 14:50:06.656225       1 scheduler.go:103] [HigherPrecedence] Final decision: Does bronze-class-deploy-8-6fff566748-tt726 have precedence over gold-class-deploy-26-6bcb7b6c88-6jh2g? false
I0409 14:50:06.656261       1 scheduler.go:103] [HigherPrecedence] Final decision: Does bronze-class-deploy-8-6fff566748-tt726 have precedence over silver-class-deploy-17-59cbf4bc88-s2ngm? false
I0409 14:50:06.656285       1 scheduler.go:103] [HigherPrecedence] Final decision: Does bronze-class-deploy-8-6fff566748-tt726 have precedence over silver-class-deploy-18-5dd44b47c5-7d2lh? false
I0409 14:50:06.656323       1 scheduler.go:103] [HigherPrecedence] Final decision: Does bronze-class-deploy-8-6fff566748-tt726 have precedence over silver-class-deploy-19-7cc4c5b78-v9p7f? false
I0409 14:50:06.656345       1 scheduler.go:103] [HigherPrecedence] Final decision: Does bronze-class-deploy-8-6fff566748-tt726 have precedence over silver-class-deploy-32-84b675c847-wwmws? false
I0409 14:50:06.656415       1 default_preemption.go:37] "Preemption failed or not needed" pod="default/bronze-class-deploy-8-6fff566748-tt726" status="0/2 nodes are available: 1 No preemption victims found for incoming pod, 1 Preemption is not helpful for scheduling."
I0409 14:50:06.663270       1 scheduler.go:255] [OnUpdatePod] Updating 'LastStatus' of pod default/bronze-class-deploy-8-6fff566748-tt726 in metrics
I0409 14:50:06.663537       1 scheduler.go:103] [HigherPrecedence] Final decision: Does bronze-class-deploy-3-775f4fbdd9-h8pjj have precedence over gold-class-deploy-1-78bb76545-pwz55? false
I0409 14:50:06.663580       1 scheduler.go:103] [HigherPrecedence] Final decision: Does bronze-class-deploy-3-775f4fbdd9-h8pjj have precedence over gold-class-deploy-2-58ff5bfb68-446gs? false
I0409 14:50:06.663603       1 scheduler.go:103] [HigherPrecedence] Final decision: Does bronze-class-deploy-3-775f4fbdd9-h8pjj have precedence over silver-class-deploy-21-7bf557854c-zflrc? false
I0409 14:50:06.663634       1 scheduler.go:103] [HigherPrecedence] Final decision: Does bronze-class-deploy-3-775f4fbdd9-h8pjj have precedence over gold-class-deploy-4-b6866bf4b-5dnw5? false
I0409 14:50:06.663676       1 scheduler.go:103] [HigherPrecedence] Final decision: Does bronze-class-deploy-3-775f4fbdd9-h8pjj have precedence over gold-class-deploy-5-c4557676f-pdmbf? false
I0409 14:50:06.663697       1 scheduler.go:103] [HigherPrecedence] Final decision: Does bronze-class-deploy-3-775f4fbdd9-h8pjj have precedence over gold-class-deploy-6-6df4d4d67b-bf8cr? false
I0409 14:50:06.663715       1 scheduler.go:103] [HigherPrecedence] Final decision: Does bronze-class-deploy-3-775f4fbdd9-h8pjj have precedence over silver-class-deploy-7-ff55f69ff-hwmfr? false
I0409 14:50:06.663730       1 scheduler.go:103] [HigherPrecedence] Final decision: Does bronze-class-deploy-3-775f4fbdd9-h8pjj have precedence over silver-class-deploy-22-8456bfbbc6-jrczs? false
I0409 14:50:06.663747       1 scheduler.go:103] [HigherPrecedence] Final decision: Does bronze-class-deploy-3-775f4fbdd9-h8pjj have precedence over gold-class-deploy-9-868dfbd94f-6hvv5? false
I0409 14:50:06.663780       1 scheduler.go:103] [HigherPrecedence] Final decision: Does bronze-class-deploy-3-775f4fbdd9-h8pjj have precedence over silver-class-deploy-10-6866d9b887-l2866? false
I0409 14:50:06.663800       1 scheduler.go:103] [HigherPrecedence] Final decision: Does bronze-class-deploy-3-775f4fbdd9-h8pjj have precedence over gold-class-deploy-27-6c45459fb5-m777t? false
I0409 14:50:06.663826       1 scheduler.go:103] [HigherPrecedence] Final decision: Does bronze-class-deploy-3-775f4fbdd9-h8pjj have precedence over gold-class-deploy-12-598494bf8f-jqzbs? false
I0409 14:50:06.663851       1 scheduler.go:103] [HigherPrecedence] Final decision: Does bronze-class-deploy-3-775f4fbdd9-h8pjj have precedence over gold-class-deploy-13-5f585cb744-n2l5p? false
I0409 14:50:06.663875       1 scheduler.go:103] [HigherPrecedence] Final decision: Does bronze-class-deploy-3-775f4fbdd9-h8pjj have precedence over silver-class-deploy-14-79f95c48b7-jh9nd? false
I0409 14:50:06.663899       1 scheduler.go:103] [HigherPrecedence] Final decision: Does bronze-class-deploy-3-775f4fbdd9-h8pjj have precedence over silver-class-deploy-15-cb96c7dc4-9m85g? false
I0409 14:50:06.663914       1 scheduler.go:103] [HigherPrecedence] Final decision: Does bronze-class-deploy-3-775f4fbdd9-h8pjj have precedence over gold-class-deploy-26-6bcb7b6c88-6jh2g? false
I0409 14:50:06.663937       1 scheduler.go:103] [HigherPrecedence] Final decision: Does bronze-class-deploy-3-775f4fbdd9-h8pjj have precedence over silver-class-deploy-17-59cbf4bc88-s2ngm? false
I0409 14:50:06.663961       1 scheduler.go:103] [HigherPrecedence] Final decision: Does bronze-class-deploy-3-775f4fbdd9-h8pjj have precedence over silver-class-deploy-18-5dd44b47c5-7d2lh? false
I0409 14:50:06.663984       1 scheduler.go:103] [HigherPrecedence] Final decision: Does bronze-class-deploy-3-775f4fbdd9-h8pjj have precedence over silver-class-deploy-19-7cc4c5b78-v9p7f? false
I0409 14:50:06.663999       1 scheduler.go:103] [HigherPrecedence] Final decision: Does bronze-class-deploy-3-775f4fbdd9-h8pjj have precedence over silver-class-deploy-32-84b675c847-wwmws? false
I0409 14:50:06.664036       1 default_preemption.go:37] "Preemption failed or not needed" pod="default/bronze-class-deploy-3-775f4fbdd9-h8pjj" status="0/2 nodes are available: 1 No preemption victims found for incoming pod, 1 Preemption is not helpful for scheduling."
I0409 14:50:06.670753       1 scheduler.go:255] [OnUpdatePod] Updating 'LastStatus' of pod default/bronze-class-deploy-3-775f4fbdd9-h8pjj in metrics
I0409 14:50:14.149446       1 default_preemption.go:51] [PreEnqueue] PreEnqueue called for pod: bronze-class-deploy-29-7d6b766b6f-m85bq
I0409 14:50:14.149473       1 default_preemption.go:52] [PreEnqueue] SchedulerName for pod bronze-class-deploy-29-7d6b766b6f-m85bq: custom-scheduler
I0409 14:50:14.149799       1 scheduler.go:164] [PreBind] Validating pod bronze-class-deploy-29-7d6b766b6f-m85bq before binding to node kwok-node-1
I0409 14:50:14.156249       1 scheduler.go:172] [PostBind] Called for pod bronze-class-deploy-29-7d6b766b6f-m85bq
I0409 14:50:14.156277       1 scheduler.go:190] [PostBind] Pod bronze-class-deploy-29-7d6b766b6f-m85bq - Binding start: 2025-04-09 14:50:14.149811331 +0000 UTC m=+98.837181759, Binding end: 2025-04-09 14:50:14.156273152 +0000 UTC m=+98.843643580
I0409 14:50:14.156296       1 scheduler.go:197] [PostBind] Metrics updated for pod bronze-class-deploy-29-7d6b766b6f-m85bq
I0409 14:50:14.156446       1 scheduler.go:255] [OnUpdatePod] Updating 'LastStatus' of pod default/bronze-class-deploy-29-7d6b766b6f-m85bq in metrics
I0409 14:50:14.164503       1 scheduler.go:255] [OnUpdatePod] Updating 'LastStatus' of pod default/bronze-class-deploy-29-7d6b766b6f-m85bq in metrics
I0409 14:50:15.150597       1 default_preemption.go:51] [PreEnqueue] PreEnqueue called for pod: bronze-class-deploy-28-946b5bff6-z6khm
I0409 14:50:15.150630       1 default_preemption.go:52] [PreEnqueue] SchedulerName for pod bronze-class-deploy-28-946b5bff6-z6khm: custom-scheduler
I0409 14:50:15.150672       1 default_preemption.go:51] [PreEnqueue] PreEnqueue called for pod: bronze-class-deploy-30-56698788c5-l8dqg
I0409 14:50:15.150676       1 default_preemption.go:52] [PreEnqueue] SchedulerName for pod bronze-class-deploy-30-56698788c5-l8dqg: custom-scheduler
I0409 14:50:15.150723       1 scheduler.go:103] [HigherPrecedence] Final decision: Does bronze-class-deploy-30-56698788c5-l8dqg have precedence over bronze-class-deploy-28-946b5bff6-z6khm? false
I0409 14:50:15.150740       1 default_preemption.go:51] [PreEnqueue] PreEnqueue called for pod: bronze-class-deploy-31-77756c9778-dqdd6
I0409 14:50:15.150743       1 default_preemption.go:52] [PreEnqueue] SchedulerName for pod bronze-class-deploy-31-77756c9778-dqdd6: custom-scheduler
I0409 14:50:15.150763       1 scheduler.go:103] [HigherPrecedence] Final decision: Does bronze-class-deploy-31-77756c9778-dqdd6 have precedence over bronze-class-deploy-28-946b5bff6-z6khm? false
I0409 14:50:15.150778       1 default_preemption.go:51] [PreEnqueue] PreEnqueue called for pod: bronze-class-deploy-25-b94944fb5-ghv2p
I0409 14:50:15.150781       1 default_preemption.go:52] [PreEnqueue] SchedulerName for pod bronze-class-deploy-25-b94944fb5-ghv2p: custom-scheduler
I0409 14:50:15.150803       1 scheduler.go:103] [HigherPrecedence] Final decision: Does bronze-class-deploy-25-b94944fb5-ghv2p have precedence over bronze-class-deploy-30-56698788c5-l8dqg? false
I0409 14:50:15.150868       1 scheduler.go:103] [HigherPrecedence] Final decision: Does bronze-class-deploy-31-77756c9778-dqdd6 have precedence over bronze-class-deploy-30-56698788c5-l8dqg? false
I0409 14:50:15.150897       1 scheduler.go:103] [HigherPrecedence] Final decision: Does bronze-class-deploy-30-56698788c5-l8dqg have precedence over bronze-class-deploy-25-b94944fb5-ghv2p? true
I0409 14:50:15.151224       1 scheduler.go:103] [HigherPrecedence] Final decision: Does bronze-class-deploy-25-b94944fb5-ghv2p have precedence over bronze-class-deploy-31-77756c9778-dqdd6? false
I0409 14:50:15.151407       1 scheduler.go:164] [PreBind] Validating pod bronze-class-deploy-28-946b5bff6-z6khm before binding to node kwok-node-1
I0409 14:50:15.151566       1 scheduler.go:164] [PreBind] Validating pod bronze-class-deploy-31-77756c9778-dqdd6 before binding to node kwok-node-1
I0409 14:50:15.151600       1 scheduler.go:164] [PreBind] Validating pod bronze-class-deploy-30-56698788c5-l8dqg before binding to node kwok-node-1
I0409 14:50:15.151797       1 scheduler.go:164] [PreBind] Validating pod bronze-class-deploy-25-b94944fb5-ghv2p before binding to node kwok-node-1
I0409 14:50:15.157221       1 scheduler.go:172] [PostBind] Called for pod bronze-class-deploy-30-56698788c5-l8dqg
I0409 14:50:15.157252       1 scheduler.go:190] [PostBind] Pod bronze-class-deploy-30-56698788c5-l8dqg - Binding start: 2025-04-09 14:50:15.151616529 +0000 UTC m=+99.838986957, Binding end: 2025-04-09 14:50:15.157248161 +0000 UTC m=+99.844618599
I0409 14:50:15.157276       1 scheduler.go:255] [OnUpdatePod] Updating 'LastStatus' of pod default/bronze-class-deploy-30-56698788c5-l8dqg in metrics
I0409 14:50:15.157299       1 scheduler.go:197] [PostBind] Metrics updated for pod bronze-class-deploy-30-56698788c5-l8dqg
I0409 14:50:15.160599       1 scheduler.go:172] [PostBind] Called for pod bronze-class-deploy-25-b94944fb5-ghv2p
I0409 14:50:15.160618       1 scheduler.go:190] [PostBind] Pod bronze-class-deploy-25-b94944fb5-ghv2p - Binding start: 2025-04-09 14:50:15.151817551 +0000 UTC m=+99.839187989, Binding end: 2025-04-09 14:50:15.160614309 +0000 UTC m=+99.847984747
I0409 14:50:15.160639       1 scheduler.go:197] [PostBind] Metrics updated for pod bronze-class-deploy-25-b94944fb5-ghv2p
I0409 14:50:15.160837       1 scheduler.go:255] [OnUpdatePod] Updating 'LastStatus' of pod default/bronze-class-deploy-28-946b5bff6-z6khm in metrics
I0409 14:50:15.160935       1 scheduler.go:255] [OnUpdatePod] Updating 'LastStatus' of pod default/bronze-class-deploy-25-b94944fb5-ghv2p in metrics
I0409 14:50:15.160965       1 scheduler.go:255] [OnUpdatePod] Updating 'LastStatus' of pod default/bronze-class-deploy-31-77756c9778-dqdd6 in metrics
I0409 14:50:15.161056       1 scheduler.go:172] [PostBind] Called for pod bronze-class-deploy-31-77756c9778-dqdd6
I0409 14:50:15.161064       1 scheduler.go:190] [PostBind] Pod bronze-class-deploy-31-77756c9778-dqdd6 - Binding start: 2025-04-09 14:50:15.151581377 +0000 UTC m=+99.838951815, Binding end: 2025-04-09 14:50:15.161061565 +0000 UTC m=+99.848431993
I0409 14:50:15.161076       1 scheduler.go:197] [PostBind] Metrics updated for pod bronze-class-deploy-31-77756c9778-dqdd6
I0409 14:50:15.161094       1 scheduler.go:172] [PostBind] Called for pod bronze-class-deploy-28-946b5bff6-z6khm
I0409 14:50:15.161110       1 scheduler.go:190] [PostBind] Pod bronze-class-deploy-28-946b5bff6-z6khm - Binding start: 2025-04-09 14:50:15.151422238 +0000 UTC m=+99.838792676, Binding end: 2025-04-09 14:50:15.161107098 +0000 UTC m=+99.848477526
I0409 14:50:15.161129       1 scheduler.go:197] [PostBind] Metrics updated for pod bronze-class-deploy-28-946b5bff6-z6khm
I0409 14:50:15.166100       1 scheduler.go:255] [OnUpdatePod] Updating 'LastStatus' of pod default/bronze-class-deploy-30-56698788c5-l8dqg in metrics
I0409 14:50:15.169851       1 scheduler.go:255] [OnUpdatePod] Updating 'LastStatus' of pod default/bronze-class-deploy-31-77756c9778-dqdd6 in metrics
I0409 14:50:15.170074       1 scheduler.go:255] [OnUpdatePod] Updating 'LastStatus' of pod default/bronze-class-deploy-25-b94944fb5-ghv2p in metrics
I0409 14:50:15.170110       1 scheduler.go:255] [OnUpdatePod] Updating 'LastStatus' of pod default/bronze-class-deploy-28-946b5bff6-z6khm in metrics
I0409 14:50:36.019509       1 default_preemption.go:51] [PreEnqueue] PreEnqueue called for pod: bronze-class-deploy-8-6fff566748-tt726
I0409 14:50:36.019533       1 default_preemption.go:52] [PreEnqueue] SchedulerName for pod bronze-class-deploy-8-6fff566748-tt726: custom-scheduler
I0409 14:50:36.019569       1 default_preemption.go:51] [PreEnqueue] PreEnqueue called for pod: bronze-class-deploy-3-775f4fbdd9-h8pjj
I0409 14:50:36.019573       1 default_preemption.go:52] [PreEnqueue] SchedulerName for pod bronze-class-deploy-3-775f4fbdd9-h8pjj: custom-scheduler
I0409 14:50:36.019603       1 scheduler.go:103] [HigherPrecedence] Final decision: Does bronze-class-deploy-3-775f4fbdd9-h8pjj have precedence over bronze-class-deploy-8-6fff566748-tt726? false
I0409 14:50:36.019623       1 default_preemption.go:51] [PreEnqueue] PreEnqueue called for pod: bronze-class-deploy-24-668b49b99b-ldm7g
I0409 14:50:36.019627       1 default_preemption.go:52] [PreEnqueue] SchedulerName for pod bronze-class-deploy-24-668b49b99b-ldm7g: custom-scheduler
I0409 14:50:36.019655       1 scheduler.go:103] [HigherPrecedence] Final decision: Does bronze-class-deploy-24-668b49b99b-ldm7g have precedence over bronze-class-deploy-8-6fff566748-tt726? true
I0409 14:50:36.019680       1 default_preemption.go:51] [PreEnqueue] PreEnqueue called for pod: bronze-class-deploy-23-654ffb5cc5-879fc
I0409 14:50:36.019684       1 default_preemption.go:52] [PreEnqueue] SchedulerName for pod bronze-class-deploy-23-654ffb5cc5-879fc: custom-scheduler
I0409 14:50:36.019705       1 scheduler.go:103] [HigherPrecedence] Final decision: Does bronze-class-deploy-23-654ffb5cc5-879fc have precedence over bronze-class-deploy-3-775f4fbdd9-h8pjj? true
I0409 14:50:36.019729       1 scheduler.go:103] [HigherPrecedence] Final decision: Does bronze-class-deploy-23-654ffb5cc5-879fc have precedence over bronze-class-deploy-24-668b49b99b-ldm7g? false
I0409 14:50:36.019738       1 default_preemption.go:51] [PreEnqueue] PreEnqueue called for pod: bronze-class-deploy-20-5fd9977fb4-hj4vm
I0409 14:50:36.019743       1 default_preemption.go:52] [PreEnqueue] SchedulerName for pod bronze-class-deploy-20-5fd9977fb4-hj4vm: custom-scheduler
I0409 14:50:36.019770       1 scheduler.go:103] [HigherPrecedence] Final decision: Does bronze-class-deploy-20-5fd9977fb4-hj4vm have precedence over bronze-class-deploy-23-654ffb5cc5-879fc? false
I0409 14:50:36.019791       1 default_preemption.go:51] [PreEnqueue] PreEnqueue called for pod: bronze-class-deploy-16-74dd4696ff-mkf54
I0409 14:50:36.019796       1 default_preemption.go:52] [PreEnqueue] SchedulerName for pod bronze-class-deploy-16-74dd4696ff-mkf54: custom-scheduler
I0409 14:50:36.019816       1 scheduler.go:103] [HigherPrecedence] Final decision: Does bronze-class-deploy-16-74dd4696ff-mkf54 have precedence over bronze-class-deploy-8-6fff566748-tt726? true
I0409 14:50:36.019842       1 scheduler.go:103] [HigherPrecedence] Final decision: Does bronze-class-deploy-16-74dd4696ff-mkf54 have precedence over bronze-class-deploy-24-668b49b99b-ldm7g? false
I0409 14:50:36.019857       1 default_preemption.go:51] [PreEnqueue] PreEnqueue called for pod: bronze-class-deploy-11-559c656b44-5grsk
I0409 14:50:36.019861       1 default_preemption.go:52] [PreEnqueue] SchedulerName for pod bronze-class-deploy-11-559c656b44-5grsk: custom-scheduler
I0409 14:50:36.019885       1 scheduler.go:103] [HigherPrecedence] Final decision: Does bronze-class-deploy-11-559c656b44-5grsk have precedence over bronze-class-deploy-16-74dd4696ff-mkf54? false
I0409 14:50:36.019938       1 scheduler.go:103] [HigherPrecedence] Final decision: Does bronze-class-deploy-16-74dd4696ff-mkf54 have precedence over bronze-class-deploy-23-654ffb5cc5-879fc? false
I0409 14:50:36.019963       1 scheduler.go:103] [HigherPrecedence] Final decision: Does bronze-class-deploy-23-654ffb5cc5-879fc have precedence over bronze-class-deploy-11-559c656b44-5grsk? true
I0409 14:50:36.019979       1 scheduler.go:103] [HigherPrecedence] Final decision: Does bronze-class-deploy-20-5fd9977fb4-hj4vm have precedence over bronze-class-deploy-3-775f4fbdd9-h8pjj? true
I0409 14:50:36.019997       1 scheduler.go:103] [HigherPrecedence] Final decision: Does bronze-class-deploy-20-5fd9977fb4-hj4vm have precedence over bronze-class-deploy-11-559c656b44-5grsk? true
I0409 14:50:36.020643       1 scheduler.go:103] [HigherPrecedence] Final decision: Does bronze-class-deploy-24-668b49b99b-ldm7g have precedence over bronze-class-deploy-29-7d6b766b6f-m85bq? true
I0409 14:50:36.020698       1 scheduler.go:103] [HigherPrecedence] Final decision: Does bronze-class-deploy-24-668b49b99b-ldm7g have precedence over bronze-class-deploy-30-56698788c5-l8dqg? true
I0409 14:50:36.020734       1 scheduler.go:103] [HigherPrecedence] Final decision: Does bronze-class-deploy-24-668b49b99b-ldm7g have precedence over bronze-class-deploy-25-b94944fb5-ghv2p? true
I0409 14:50:36.020783       1 scheduler.go:103] [HigherPrecedence] Final decision: Does bronze-class-deploy-24-668b49b99b-ldm7g have precedence over bronze-class-deploy-31-77756c9778-dqdd6? true
I0409 14:50:36.020836       1 scheduler.go:103] [HigherPrecedence] Final decision: Does bronze-class-deploy-24-668b49b99b-ldm7g have precedence over bronze-class-deploy-28-946b5bff6-z6khm? true
I0409 14:50:36.020890       1 default_preemption.go:37] "Preemption failed or not needed" pod="default/bronze-class-deploy-24-668b49b99b-ldm7g" status="0/2 nodes are available: 1 No preemption victims found for incoming pod, 1 Preemption is not helpful for scheduling."
I0409 14:50:36.021029       1 scheduler.go:103] [HigherPrecedence] Final decision: Does bronze-class-deploy-16-74dd4696ff-mkf54 have precedence over bronze-class-deploy-20-5fd9977fb4-hj4vm? false
I0409 14:50:36.021074       1 scheduler.go:103] [HigherPrecedence] Final decision: Does bronze-class-deploy-20-5fd9977fb4-hj4vm have precedence over bronze-class-deploy-8-6fff566748-tt726? true
I0409 14:50:36.021093       1 scheduler.go:103] [HigherPrecedence] Final decision: Does bronze-class-deploy-11-559c656b44-5grsk have precedence over bronze-class-deploy-3-775f4fbdd9-h8pjj? true
I0409 14:50:36.021110       1 scheduler.go:103] [HigherPrecedence] Final decision: Does bronze-class-deploy-11-559c656b44-5grsk have precedence over bronze-class-deploy-8-6fff566748-tt726? true
I0409 14:50:36.021569       1 scheduler.go:103] [HigherPrecedence] Final decision: Does bronze-class-deploy-23-654ffb5cc5-879fc have precedence over bronze-class-deploy-29-7d6b766b6f-m85bq? true
I0409 14:50:36.021604       1 scheduler.go:103] [HigherPrecedence] Final decision: Does bronze-class-deploy-23-654ffb5cc5-879fc have precedence over bronze-class-deploy-30-56698788c5-l8dqg? true
I0409 14:50:36.021631       1 scheduler.go:103] [HigherPrecedence] Final decision: Does bronze-class-deploy-23-654ffb5cc5-879fc have precedence over bronze-class-deploy-25-b94944fb5-ghv2p? true
I0409 14:50:36.021679       1 scheduler.go:103] [HigherPrecedence] Final decision: Does bronze-class-deploy-23-654ffb5cc5-879fc have precedence over bronze-class-deploy-31-77756c9778-dqdd6? true
I0409 14:50:36.021717       1 scheduler.go:103] [HigherPrecedence] Final decision: Does bronze-class-deploy-23-654ffb5cc5-879fc have precedence over bronze-class-deploy-28-946b5bff6-z6khm? true
I0409 14:50:36.021776       1 default_preemption.go:37] "Preemption failed or not needed" pod="default/bronze-class-deploy-23-654ffb5cc5-879fc" status="0/2 nodes are available: 1 No preemption victims found for incoming pod, 1 Preemption is not helpful for scheduling."
I0409 14:50:36.021877       1 scheduler.go:103] [HigherPrecedence] Final decision: Does bronze-class-deploy-16-74dd4696ff-mkf54 have precedence over bronze-class-deploy-11-559c656b44-5grsk? true
I0409 14:50:36.021901       1 scheduler.go:103] [HigherPrecedence] Final decision: Does bronze-class-deploy-16-74dd4696ff-mkf54 have precedence over bronze-class-deploy-8-6fff566748-tt726? true
I0409 14:50:36.022268       1 scheduler.go:103] [HigherPrecedence] Final decision: Does bronze-class-deploy-20-5fd9977fb4-hj4vm have precedence over bronze-class-deploy-29-7d6b766b6f-m85bq? false
I0409 14:50:36.022296       1 scheduler.go:103] [HigherPrecedence] Final decision: Does bronze-class-deploy-20-5fd9977fb4-hj4vm have precedence over bronze-class-deploy-30-56698788c5-l8dqg? false
I0409 14:50:36.022310       1 scheduler.go:103] [HigherPrecedence] Final decision: Does bronze-class-deploy-20-5fd9977fb4-hj4vm have precedence over bronze-class-deploy-25-b94944fb5-ghv2p? false
I0409 14:50:36.022328       1 scheduler.go:103] [HigherPrecedence] Final decision: Does bronze-class-deploy-20-5fd9977fb4-hj4vm have precedence over bronze-class-deploy-31-77756c9778-dqdd6? false
I0409 14:50:36.022381       1 scheduler.go:103] [HigherPrecedence] Final decision: Does bronze-class-deploy-20-5fd9977fb4-hj4vm have precedence over bronze-class-deploy-28-946b5bff6-z6khm? false
I0409 14:50:36.022406       1 default_preemption.go:37] "Preemption failed or not needed" pod="default/bronze-class-deploy-20-5fd9977fb4-hj4vm" status="0/2 nodes are available: 1 No preemption victims found for incoming pod, 1 Preemption is not helpful for scheduling."
I0409 14:50:36.022486       1 scheduler.go:103] [HigherPrecedence] Final decision: Does bronze-class-deploy-8-6fff566748-tt726 have precedence over bronze-class-deploy-11-559c656b44-5grsk? false
I0409 14:50:36.022515       1 scheduler.go:103] [HigherPrecedence] Final decision: Does bronze-class-deploy-11-559c656b44-5grsk have precedence over bronze-class-deploy-3-775f4fbdd9-h8pjj? true
I0409 14:50:36.022860       1 scheduler.go:103] [HigherPrecedence] Final decision: Does bronze-class-deploy-16-74dd4696ff-mkf54 have precedence over bronze-class-deploy-29-7d6b766b6f-m85bq? false
I0409 14:50:36.022893       1 scheduler.go:103] [HigherPrecedence] Final decision: Does bronze-class-deploy-16-74dd4696ff-mkf54 have precedence over bronze-class-deploy-30-56698788c5-l8dqg? false
I0409 14:50:36.022913       1 scheduler.go:103] [HigherPrecedence] Final decision: Does bronze-class-deploy-16-74dd4696ff-mkf54 have precedence over bronze-class-deploy-25-b94944fb5-ghv2p? false
I0409 14:50:36.022934       1 scheduler.go:103] [HigherPrecedence] Final decision: Does bronze-class-deploy-16-74dd4696ff-mkf54 have precedence over bronze-class-deploy-31-77756c9778-dqdd6? false
I0409 14:50:36.022956       1 scheduler.go:103] [HigherPrecedence] Final decision: Does bronze-class-deploy-16-74dd4696ff-mkf54 have precedence over bronze-class-deploy-28-946b5bff6-z6khm? false
I0409 14:50:36.022987       1 default_preemption.go:37] "Preemption failed or not needed" pod="default/bronze-class-deploy-16-74dd4696ff-mkf54" status="0/2 nodes are available: 1 No preemption victims found for incoming pod, 1 Preemption is not helpful for scheduling."
I0409 14:50:36.023060       1 scheduler.go:103] [HigherPrecedence] Final decision: Does bronze-class-deploy-3-775f4fbdd9-h8pjj have precedence over bronze-class-deploy-8-6fff566748-tt726? false
I0409 14:50:36.023526       1 scheduler.go:103] [HigherPrecedence] Final decision: Does bronze-class-deploy-11-559c656b44-5grsk have precedence over bronze-class-deploy-29-7d6b766b6f-m85bq? false
I0409 14:50:36.023563       1 scheduler.go:103] [HigherPrecedence] Final decision: Does bronze-class-deploy-11-559c656b44-5grsk have precedence over bronze-class-deploy-30-56698788c5-l8dqg? false
I0409 14:50:36.023582       1 scheduler.go:103] [HigherPrecedence] Final decision: Does bronze-class-deploy-11-559c656b44-5grsk have precedence over bronze-class-deploy-25-b94944fb5-ghv2p? false
I0409 14:50:36.023606       1 scheduler.go:103] [HigherPrecedence] Final decision: Does bronze-class-deploy-11-559c656b44-5grsk have precedence over bronze-class-deploy-31-77756c9778-dqdd6? false
I0409 14:50:36.023633       1 scheduler.go:103] [HigherPrecedence] Final decision: Does bronze-class-deploy-11-559c656b44-5grsk have precedence over bronze-class-deploy-28-946b5bff6-z6khm? false
I0409 14:50:36.023670       1 default_preemption.go:37] "Preemption failed or not needed" pod="default/bronze-class-deploy-11-559c656b44-5grsk" status="0/2 nodes are available: 1 No preemption victims found for incoming pod, 1 Preemption is not helpful for scheduling."
I0409 14:50:36.024205       1 scheduler.go:103] [HigherPrecedence] Final decision: Does bronze-class-deploy-8-6fff566748-tt726 have precedence over bronze-class-deploy-29-7d6b766b6f-m85bq? false
I0409 14:50:36.024245       1 scheduler.go:103] [HigherPrecedence] Final decision: Does bronze-class-deploy-8-6fff566748-tt726 have precedence over bronze-class-deploy-30-56698788c5-l8dqg? false
I0409 14:50:36.024264       1 scheduler.go:103] [HigherPrecedence] Final decision: Does bronze-class-deploy-8-6fff566748-tt726 have precedence over bronze-class-deploy-25-b94944fb5-ghv2p? false
I0409 14:50:36.024285       1 scheduler.go:103] [HigherPrecedence] Final decision: Does bronze-class-deploy-8-6fff566748-tt726 have precedence over bronze-class-deploy-31-77756c9778-dqdd6? false
I0409 14:50:36.024312       1 scheduler.go:103] [HigherPrecedence] Final decision: Does bronze-class-deploy-8-6fff566748-tt726 have precedence over bronze-class-deploy-28-946b5bff6-z6khm? false
I0409 14:50:36.024341       1 default_preemption.go:37] "Preemption failed or not needed" pod="default/bronze-class-deploy-8-6fff566748-tt726" status="0/2 nodes are available: 1 No preemption victims found for incoming pod, 1 Preemption is not helpful for scheduling."
I0409 14:50:36.024902       1 scheduler.go:103] [HigherPrecedence] Final decision: Does bronze-class-deploy-3-775f4fbdd9-h8pjj have precedence over bronze-class-deploy-29-7d6b766b6f-m85bq? false
I0409 14:50:36.024939       1 scheduler.go:103] [HigherPrecedence] Final decision: Does bronze-class-deploy-3-775f4fbdd9-h8pjj have precedence over bronze-class-deploy-30-56698788c5-l8dqg? false
I0409 14:50:36.024960       1 scheduler.go:103] [HigherPrecedence] Final decision: Does bronze-class-deploy-3-775f4fbdd9-h8pjj have precedence over bronze-class-deploy-25-b94944fb5-ghv2p? false
I0409 14:50:36.024979       1 scheduler.go:103] [HigherPrecedence] Final decision: Does bronze-class-deploy-3-775f4fbdd9-h8pjj have precedence over bronze-class-deploy-31-77756c9778-dqdd6? false
I0409 14:50:36.025010       1 scheduler.go:103] [HigherPrecedence] Final decision: Does bronze-class-deploy-3-775f4fbdd9-h8pjj have precedence over bronze-class-deploy-28-946b5bff6-z6khm? false
I0409 14:50:36.025050       1 default_preemption.go:37] "Preemption failed or not needed" pod="default/bronze-class-deploy-3-775f4fbdd9-h8pjj" status="0/2 nodes are available: 1 No preemption victims found for incoming pod, 1 Preemption is not helpful for scheduling."
I0409 14:51:06.020313       1 default_preemption.go:51] [PreEnqueue] PreEnqueue called for pod: bronze-class-deploy-11-559c656b44-5grsk
I0409 14:51:06.020339       1 default_preemption.go:52] [PreEnqueue] SchedulerName for pod bronze-class-deploy-11-559c656b44-5grsk: custom-scheduler
I0409 14:51:06.020401       1 default_preemption.go:51] [PreEnqueue] PreEnqueue called for pod: bronze-class-deploy-8-6fff566748-tt726
I0409 14:51:06.020406       1 default_preemption.go:52] [PreEnqueue] SchedulerName for pod bronze-class-deploy-8-6fff566748-tt726: custom-scheduler
I0409 14:51:06.020431       1 scheduler.go:103] [HigherPrecedence] Final decision: Does bronze-class-deploy-8-6fff566748-tt726 have precedence over bronze-class-deploy-11-559c656b44-5grsk? false
I0409 14:51:06.020449       1 default_preemption.go:51] [PreEnqueue] PreEnqueue called for pod: bronze-class-deploy-3-775f4fbdd9-h8pjj
I0409 14:51:06.020453       1 default_preemption.go:52] [PreEnqueue] SchedulerName for pod bronze-class-deploy-3-775f4fbdd9-h8pjj: custom-scheduler
I0409 14:51:06.020476       1 scheduler.go:103] [HigherPrecedence] Final decision: Does bronze-class-deploy-3-775f4fbdd9-h8pjj have precedence over bronze-class-deploy-11-559c656b44-5grsk? false
I0409 14:51:06.020494       1 default_preemption.go:51] [PreEnqueue] PreEnqueue called for pod: bronze-class-deploy-24-668b49b99b-ldm7g
I0409 14:51:06.020497       1 default_preemption.go:52] [PreEnqueue] SchedulerName for pod bronze-class-deploy-24-668b49b99b-ldm7g: custom-scheduler
I0409 14:51:06.020517       1 scheduler.go:103] [HigherPrecedence] Final decision: Does bronze-class-deploy-24-668b49b99b-ldm7g have precedence over bronze-class-deploy-8-6fff566748-tt726? true
I0409 14:51:06.020532       1 scheduler.go:103] [HigherPrecedence] Final decision: Does bronze-class-deploy-24-668b49b99b-ldm7g have precedence over bronze-class-deploy-11-559c656b44-5grsk? true
I0409 14:51:06.020541       1 default_preemption.go:51] [PreEnqueue] PreEnqueue called for pod: bronze-class-deploy-23-654ffb5cc5-879fc
I0409 14:51:06.020544       1 default_preemption.go:52] [PreEnqueue] SchedulerName for pod bronze-class-deploy-23-654ffb5cc5-879fc: custom-scheduler
I0409 14:51:06.020565       1 scheduler.go:103] [HigherPrecedence] Final decision: Does bronze-class-deploy-23-654ffb5cc5-879fc have precedence over bronze-class-deploy-11-559c656b44-5grsk? true
I0409 14:51:06.020587       1 scheduler.go:103] [HigherPrecedence] Final decision: Does bronze-class-deploy-23-654ffb5cc5-879fc have precedence over bronze-class-deploy-24-668b49b99b-ldm7g? false
I0409 14:51:06.020595       1 default_preemption.go:51] [PreEnqueue] PreEnqueue called for pod: bronze-class-deploy-20-5fd9977fb4-hj4vm
I0409 14:51:06.020598       1 default_preemption.go:52] [PreEnqueue] SchedulerName for pod bronze-class-deploy-20-5fd9977fb4-hj4vm: custom-scheduler
I0409 14:51:06.020618       1 scheduler.go:103] [HigherPrecedence] Final decision: Does bronze-class-deploy-20-5fd9977fb4-hj4vm have precedence over bronze-class-deploy-3-775f4fbdd9-h8pjj? true
I0409 14:51:06.020638       1 scheduler.go:103] [HigherPrecedence] Final decision: Does bronze-class-deploy-20-5fd9977fb4-hj4vm have precedence over bronze-class-deploy-24-668b49b99b-ldm7g? false
I0409 14:51:06.020647       1 default_preemption.go:51] [PreEnqueue] PreEnqueue called for pod: bronze-class-deploy-16-74dd4696ff-mkf54
I0409 14:51:06.020652       1 default_preemption.go:52] [PreEnqueue] SchedulerName for pod bronze-class-deploy-16-74dd4696ff-mkf54: custom-scheduler
I0409 14:51:06.020682       1 scheduler.go:103] [HigherPrecedence] Final decision: Does bronze-class-deploy-16-74dd4696ff-mkf54 have precedence over bronze-class-deploy-20-5fd9977fb4-hj4vm? false
I0409 14:51:06.020721       1 scheduler.go:103] [HigherPrecedence] Final decision: Does bronze-class-deploy-20-5fd9977fb4-hj4vm have precedence over bronze-class-deploy-23-654ffb5cc5-879fc? false
I0409 14:51:06.020735       1 scheduler.go:103] [HigherPrecedence] Final decision: Does bronze-class-deploy-23-654ffb5cc5-879fc have precedence over bronze-class-deploy-16-74dd4696ff-mkf54? true
I0409 14:51:06.020748       1 scheduler.go:103] [HigherPrecedence] Final decision: Does bronze-class-deploy-11-559c656b44-5grsk have precedence over bronze-class-deploy-8-6fff566748-tt726? true
I0409 14:51:06.020779       1 scheduler.go:103] [HigherPrecedence] Final decision: Does bronze-class-deploy-11-559c656b44-5grsk have precedence over bronze-class-deploy-16-74dd4696ff-mkf54? false
I0409 14:51:06.021841       1 scheduler.go:103] [HigherPrecedence] Final decision: Does bronze-class-deploy-24-668b49b99b-ldm7g have precedence over bronze-class-deploy-29-7d6b766b6f-m85bq? true
I0409 14:51:06.021946       1 scheduler.go:103] [HigherPrecedence] Final decision: Does bronze-class-deploy-24-668b49b99b-ldm7g have precedence over bronze-class-deploy-30-56698788c5-l8dqg? true
I0409 14:51:06.021998       1 scheduler.go:103] [HigherPrecedence] Final decision: Does bronze-class-deploy-24-668b49b99b-ldm7g have precedence over bronze-class-deploy-25-b94944fb5-ghv2p? true
I0409 14:51:06.022047       1 scheduler.go:103] [HigherPrecedence] Final decision: Does bronze-class-deploy-24-668b49b99b-ldm7g have precedence over bronze-class-deploy-31-77756c9778-dqdd6? true
I0409 14:51:06.022145       1 scheduler.go:103] [HigherPrecedence] Final decision: Does bronze-class-deploy-24-668b49b99b-ldm7g have precedence over bronze-class-deploy-28-946b5bff6-z6khm? true
I0409 14:51:06.030789       1 scheduler.go:255] [OnUpdatePod] Updating 'LastStatus' of pod default/bronze-class-deploy-28-946b5bff6-z6khm in metrics
I0409 14:51:06.036509       1 scheduler.go:255] [OnUpdatePod] Updating 'LastStatus' of pod default/bronze-class-deploy-28-946b5bff6-z6khm in metrics
I0409 14:51:06.040080       1 default_preemption.go:39] "Preemption successful" pod="default/bronze-class-deploy-24-668b49b99b-ldm7g" nominatedNode="kwok-node-1"
I0409 14:51:06.040293       1 scheduler.go:286] [OnDeletePod] Checking the state of pod default/bronze-class-deploy-28-946b5bff6-z6khm in metrics
I0409 14:51:06.046412       1 scheduler.go:205] [OnAddPod] Pod added: default/bronze-class-deploy-28-946b5bff6-774x4, Annotations: map[acceptablePreemptionOverhead:0.05 controller:bronze-controller-28 kwok.x-k8s.io/usage-cpu:1m kwok.x-k8s.io/usage-memory:1Mi qosMeasuring:average slo:0.5]
I0409 14:51:06.046440       1 default_preemption.go:51] [PreEnqueue] PreEnqueue called for pod: bronze-class-deploy-28-946b5bff6-774x4
I0409 14:51:06.046592       1 default_preemption.go:52] [PreEnqueue] SchedulerName for pod bronze-class-deploy-28-946b5bff6-774x4: custom-scheduler
W0409 14:51:06.046649       1 scheduler.go:118] [cacheMiss] Metrics not found for pod: default/bronze-class-deploy-28-946b5bff6-774x4
W0409 14:51:06.046668       1 scheduler.go:125] [WaitForPodsOnCache] Pod bronze-class-deploy-28-946b5bff6-774x4 not found in cache. Retrying...
I0409 14:51:06.049285       1 scheduler.go:255] [OnUpdatePod] Updating 'LastStatus' of pod default/bronze-class-deploy-24-668b49b99b-ldm7g in metrics
I0409 14:51:06.147314       1 scheduler.go:103] [HigherPrecedence] Final decision: Does bronze-class-deploy-28-946b5bff6-774x4 have precedence over bronze-class-deploy-20-5fd9977fb4-hj4vm? true
I0409 14:51:06.147390       1 scheduler.go:103] [HigherPrecedence] Final decision: Does bronze-class-deploy-28-946b5bff6-774x4 have precedence over bronze-class-deploy-23-654ffb5cc5-879fc? false
I0409 14:51:06.147527       1 scheduler.go:103] [HigherPrecedence] Final decision: Does bronze-class-deploy-28-946b5bff6-774x4 have precedence over bronze-class-deploy-16-74dd4696ff-mkf54? true
I0409 14:51:06.147574       1 scheduler.go:103] [HigherPrecedence] Final decision: Does bronze-class-deploy-28-946b5bff6-774x4 have precedence over bronze-class-deploy-20-5fd9977fb4-hj4vm? true
I0409 14:51:06.147597       1 scheduler.go:103] [HigherPrecedence] Final decision: Does bronze-class-deploy-3-775f4fbdd9-h8pjj have precedence over bronze-class-deploy-20-5fd9977fb4-hj4vm? false
I0409 14:51:06.148192       1 scheduler.go:103] [HigherPrecedence] Final decision: Does bronze-class-deploy-23-654ffb5cc5-879fc have precedence over bronze-class-deploy-29-7d6b766b6f-m85bq? true
I0409 14:51:06.148250       1 scheduler.go:103] [HigherPrecedence] Final decision: Does bronze-class-deploy-23-654ffb5cc5-879fc have precedence over bronze-class-deploy-30-56698788c5-l8dqg? true
I0409 14:51:06.148299       1 scheduler.go:103] [HigherPrecedence] Final decision: Does bronze-class-deploy-23-654ffb5cc5-879fc have precedence over bronze-class-deploy-25-b94944fb5-ghv2p? true
I0409 14:51:06.148331       1 scheduler.go:103] [HigherPrecedence] Final decision: Does bronze-class-deploy-23-654ffb5cc5-879fc have precedence over bronze-class-deploy-31-77756c9778-dqdd6? true
I0409 14:51:06.156078       1 scheduler.go:255] [OnUpdatePod] Updating 'LastStatus' of pod default/bronze-class-deploy-31-77756c9778-dqdd6 in metrics
I0409 14:51:06.161697       1 scheduler.go:255] [OnUpdatePod] Updating 'LastStatus' of pod default/bronze-class-deploy-31-77756c9778-dqdd6 in metrics
I0409 14:51:06.163619       1 scheduler.go:103] [HigherPrecedence] Final decision: Does bronze-class-deploy-23-654ffb5cc5-879fc have precedence over bronze-class-deploy-24-668b49b99b-ldm7g? false
I0409 14:51:06.163654       1 default_preemption.go:39] "Preemption successful" pod="default/bronze-class-deploy-23-654ffb5cc5-879fc" nominatedNode="kwok-node-1"
I0409 14:51:06.163811       1 scheduler.go:286] [OnDeletePod] Checking the state of pod default/bronze-class-deploy-31-77756c9778-dqdd6 in metrics
I0409 14:51:06.167352       1 default_preemption.go:51] [PreEnqueue] PreEnqueue called for pod: bronze-class-deploy-31-77756c9778-l96pz
I0409 14:51:06.167404       1 default_preemption.go:52] [PreEnqueue] SchedulerName for pod bronze-class-deploy-31-77756c9778-l96pz: custom-scheduler
I0409 14:51:06.167404       1 scheduler.go:205] [OnAddPod] Pod added: default/bronze-class-deploy-31-77756c9778-l96pz, Annotations: map[acceptablePreemptionOverhead:0.05 controller:bronze-controller-31 kwok.x-k8s.io/usage-cpu:1m kwok.x-k8s.io/usage-memory:1Mi qosMeasuring:average slo:0.5]
W0409 14:51:06.167438       1 scheduler.go:118] [cacheMiss] Metrics not found for pod: default/bronze-class-deploy-31-77756c9778-l96pz
W0409 14:51:06.167443       1 scheduler.go:125] [WaitForPodsOnCache] Pod bronze-class-deploy-31-77756c9778-l96pz not found in cache. Retrying...
I0409 14:51:06.170590       1 scheduler.go:255] [OnUpdatePod] Updating 'LastStatus' of pod default/bronze-class-deploy-23-654ffb5cc5-879fc in metrics
I0409 14:51:06.267836       1 scheduler.go:103] [HigherPrecedence] Final decision: Does bronze-class-deploy-31-77756c9778-l96pz have precedence over bronze-class-deploy-20-5fd9977fb4-hj4vm? true
I0409 14:51:06.267897       1 scheduler.go:103] [HigherPrecedence] Final decision: Does bronze-class-deploy-31-77756c9778-l96pz have precedence over bronze-class-deploy-28-946b5bff6-774x4? false
I0409 14:51:06.267998       1 scheduler.go:103] [HigherPrecedence] Final decision: Does bronze-class-deploy-31-77756c9778-l96pz have precedence over bronze-class-deploy-16-74dd4696ff-mkf54? true
I0409 14:51:06.268028       1 scheduler.go:103] [HigherPrecedence] Final decision: Does bronze-class-deploy-31-77756c9778-l96pz have precedence over bronze-class-deploy-20-5fd9977fb4-hj4vm? true
I0409 14:51:06.268044       1 scheduler.go:103] [HigherPrecedence] Final decision: Does bronze-class-deploy-3-775f4fbdd9-h8pjj have precedence over bronze-class-deploy-20-5fd9977fb4-hj4vm? false
I0409 14:51:06.268716       1 scheduler.go:103] [HigherPrecedence] Final decision: Does bronze-class-deploy-28-946b5bff6-774x4 have precedence over bronze-class-deploy-29-7d6b766b6f-m85bq? true
I0409 14:51:06.268764       1 scheduler.go:103] [HigherPrecedence] Final decision: Does bronze-class-deploy-28-946b5bff6-774x4 have precedence over bronze-class-deploy-30-56698788c5-l8dqg? true
I0409 14:51:06.268798       1 scheduler.go:103] [HigherPrecedence] Final decision: Does bronze-class-deploy-28-946b5bff6-774x4 have precedence over bronze-class-deploy-25-b94944fb5-ghv2p? true
I0409 14:51:06.276193       1 scheduler.go:255] [OnUpdatePod] Updating 'LastStatus' of pod default/bronze-class-deploy-25-b94944fb5-ghv2p in metrics
I0409 14:51:06.282044       1 scheduler.go:255] [OnUpdatePod] Updating 'LastStatus' of pod default/bronze-class-deploy-25-b94944fb5-ghv2p in metrics
I0409 14:51:06.286807       1 scheduler.go:103] [HigherPrecedence] Final decision: Does bronze-class-deploy-28-946b5bff6-774x4 have precedence over bronze-class-deploy-24-668b49b99b-ldm7g? false
I0409 14:51:06.286892       1 scheduler.go:103] [HigherPrecedence] Final decision: Does bronze-class-deploy-28-946b5bff6-774x4 have precedence over bronze-class-deploy-23-654ffb5cc5-879fc? false
I0409 14:51:06.286912       1 default_preemption.go:39] "Preemption successful" pod="default/bronze-class-deploy-28-946b5bff6-774x4" nominatedNode="kwok-node-1"
I0409 14:51:06.286921       1 scheduler.go:286] [OnDeletePod] Checking the state of pod default/bronze-class-deploy-25-b94944fb5-ghv2p in metrics
I0409 14:51:06.288728       1 default_preemption.go:51] [PreEnqueue] PreEnqueue called for pod: bronze-class-deploy-25-b94944fb5-4584t
I0409 14:51:06.288750       1 default_preemption.go:52] [PreEnqueue] SchedulerName for pod bronze-class-deploy-25-b94944fb5-4584t: custom-scheduler
I0409 14:51:06.288763       1 scheduler.go:205] [OnAddPod] Pod added: default/bronze-class-deploy-25-b94944fb5-4584t, Annotations: map[acceptablePreemptionOverhead:0.05 controller:bronze-controller-25 kwok.x-k8s.io/usage-cpu:1m kwok.x-k8s.io/usage-memory:1Mi qosMeasuring:average slo:0.5]
W0409 14:51:06.288783       1 scheduler.go:118] [cacheMiss] Metrics not found for pod: default/bronze-class-deploy-25-b94944fb5-4584t
W0409 14:51:06.288790       1 scheduler.go:125] [WaitForPodsOnCache] Pod bronze-class-deploy-25-b94944fb5-4584t not found in cache. Retrying...
I0409 14:51:06.295516       1 scheduler.go:255] [OnUpdatePod] Updating 'LastStatus' of pod default/bronze-class-deploy-28-946b5bff6-774x4 in metrics
I0409 14:51:06.389498       1 scheduler.go:103] [HigherPrecedence] Final decision: Does bronze-class-deploy-25-b94944fb5-4584t have precedence over bronze-class-deploy-20-5fd9977fb4-hj4vm? true
I0409 14:51:06.389536       1 scheduler.go:103] [HigherPrecedence] Final decision: Does bronze-class-deploy-25-b94944fb5-4584t have precedence over bronze-class-deploy-31-77756c9778-l96pz? true
I0409 14:51:06.389661       1 scheduler.go:103] [HigherPrecedence] Final decision: Does bronze-class-deploy-31-77756c9778-l96pz have precedence over bronze-class-deploy-16-74dd4696ff-mkf54? true
I0409 14:51:06.389703       1 scheduler.go:103] [HigherPrecedence] Final decision: Does bronze-class-deploy-31-77756c9778-l96pz have precedence over bronze-class-deploy-20-5fd9977fb4-hj4vm? true
I0409 14:51:06.389725       1 scheduler.go:103] [HigherPrecedence] Final decision: Does bronze-class-deploy-3-775f4fbdd9-h8pjj have precedence over bronze-class-deploy-20-5fd9977fb4-hj4vm? false
I0409 14:51:06.390259       1 scheduler.go:103] [HigherPrecedence] Final decision: Does bronze-class-deploy-25-b94944fb5-4584t have precedence over bronze-class-deploy-29-7d6b766b6f-m85bq? true
I0409 14:51:06.390303       1 scheduler.go:103] [HigherPrecedence] Final decision: Does bronze-class-deploy-25-b94944fb5-4584t have precedence over bronze-class-deploy-30-56698788c5-l8dqg? true
I0409 14:51:06.397984       1 scheduler.go:255] [OnUpdatePod] Updating 'LastStatus' of pod default/bronze-class-deploy-30-56698788c5-l8dqg in metrics
I0409 14:51:06.403727       1 scheduler.go:255] [OnUpdatePod] Updating 'LastStatus' of pod default/bronze-class-deploy-30-56698788c5-l8dqg in metrics
I0409 14:51:06.407288       1 scheduler.go:103] [HigherPrecedence] Final decision: Does bronze-class-deploy-25-b94944fb5-4584t have precedence over bronze-class-deploy-24-668b49b99b-ldm7g? false
I0409 14:51:06.407310       1 scheduler.go:286] [OnDeletePod] Checking the state of pod default/bronze-class-deploy-30-56698788c5-l8dqg in metrics
I0409 14:51:06.407397       1 scheduler.go:103] [HigherPrecedence] Final decision: Does bronze-class-deploy-25-b94944fb5-4584t have precedence over bronze-class-deploy-23-654ffb5cc5-879fc? false
I0409 14:51:06.407443       1 scheduler.go:103] [HigherPrecedence] Final decision: Does bronze-class-deploy-25-b94944fb5-4584t have precedence over bronze-class-deploy-28-946b5bff6-774x4? true
I0409 14:51:06.410416       1 default_preemption.go:51] [PreEnqueue] PreEnqueue called for pod: bronze-class-deploy-30-56698788c5-nzttq
I0409 14:51:06.410451       1 default_preemption.go:52] [PreEnqueue] SchedulerName for pod bronze-class-deploy-30-56698788c5-nzttq: custom-scheduler
W0409 14:51:06.410496       1 scheduler.go:118] [cacheMiss] Metrics not found for pod: default/bronze-class-deploy-30-56698788c5-nzttq
W0409 14:51:06.410506       1 scheduler.go:125] [WaitForPodsOnCache] Pod bronze-class-deploy-30-56698788c5-nzttq not found in cache. Retrying...
I0409 14:51:06.410407       1 scheduler.go:205] [OnAddPod] Pod added: default/bronze-class-deploy-30-56698788c5-nzttq, Annotations: map[acceptablePreemptionOverhead:0.05 controller:bronze-controller-30 kwok.x-k8s.io/usage-cpu:1m kwok.x-k8s.io/usage-memory:1Mi qosMeasuring:average slo:0.5]
I0409 14:51:06.414405       1 scheduler.go:255] [OnUpdatePod] Updating 'LastStatus' of pod default/bronze-class-deploy-28-946b5bff6-774x4 in metrics
I0409 14:51:06.414499       1 default_preemption.go:39] "Preemption successful" pod="default/bronze-class-deploy-25-b94944fb5-4584t" nominatedNode="kwok-node-1"
I0409 14:51:06.511167       1 scheduler.go:103] [HigherPrecedence] Final decision: Does bronze-class-deploy-30-56698788c5-nzttq have precedence over bronze-class-deploy-20-5fd9977fb4-hj4vm? true
I0409 14:51:06.511212       1 scheduler.go:103] [HigherPrecedence] Final decision: Does bronze-class-deploy-30-56698788c5-nzttq have precedence over bronze-class-deploy-31-77756c9778-l96pz? true
I0409 14:51:06.518117       1 scheduler.go:103] [HigherPrecedence] Final decision: Does bronze-class-deploy-31-77756c9778-l96pz have precedence over bronze-class-deploy-16-74dd4696ff-mkf54? true
I0409 14:51:06.518165       1 scheduler.go:103] [HigherPrecedence] Final decision: Does bronze-class-deploy-31-77756c9778-l96pz have precedence over bronze-class-deploy-20-5fd9977fb4-hj4vm? true
I0409 14:51:06.518170       1 scheduler.go:255] [OnUpdatePod] Updating 'LastStatus' of pod default/bronze-class-deploy-25-b94944fb5-4584t in metrics
I0409 14:51:06.518213       1 scheduler.go:103] [HigherPrecedence] Final decision: Does bronze-class-deploy-3-775f4fbdd9-h8pjj have precedence over bronze-class-deploy-20-5fd9977fb4-hj4vm? false
I0409 14:51:06.518504       1 scheduler.go:103] [HigherPrecedence] Final decision: Does bronze-class-deploy-20-5fd9977fb4-hj4vm have precedence over bronze-class-deploy-16-74dd4696ff-mkf54? true
I0409 14:51:06.518534       1 scheduler.go:103] [HigherPrecedence] Final decision: Does bronze-class-deploy-20-5fd9977fb4-hj4vm have precedence over bronze-class-deploy-3-775f4fbdd9-h8pjj? true
I0409 14:51:06.518591       1 scheduler.go:164] [PreBind] Validating pod bronze-class-deploy-30-56698788c5-nzttq before binding to node kwok-node-1
I0409 14:51:06.518960       1 scheduler.go:103] [HigherPrecedence] Final decision: Does bronze-class-deploy-31-77756c9778-l96pz have precedence over bronze-class-deploy-29-7d6b766b6f-m85bq? true
I0409 14:51:06.519012       1 scheduler.go:103] [HigherPrecedence] Final decision: Does bronze-class-deploy-31-77756c9778-l96pz have precedence over bronze-class-deploy-30-56698788c5-nzttq? false
I0409 14:51:06.523828       1 scheduler.go:255] [OnUpdatePod] Updating 'LastStatus' of pod default/bronze-class-deploy-30-56698788c5-nzttq in metrics
I0409 14:51:06.523936       1 scheduler.go:172] [PostBind] Called for pod bronze-class-deploy-30-56698788c5-nzttq
I0409 14:51:06.523950       1 scheduler.go:190] [PostBind] Pod bronze-class-deploy-30-56698788c5-nzttq - Binding start: 2025-04-09 14:51:06.518612329 +0000 UTC m=+151.205982757, Binding end: 2025-04-09 14:51:06.523947454 +0000 UTC m=+151.211317892
I0409 14:51:06.523971       1 scheduler.go:197] [PostBind] Metrics updated for pod bronze-class-deploy-30-56698788c5-nzttq
I0409 14:51:06.526688       1 scheduler.go:255] [OnUpdatePod] Updating 'LastStatus' of pod default/bronze-class-deploy-29-7d6b766b6f-m85bq in metrics
I0409 14:51:06.531539       1 scheduler.go:255] [OnUpdatePod] Updating 'LastStatus' of pod default/bronze-class-deploy-30-56698788c5-nzttq in metrics
I0409 14:51:06.534553       1 scheduler.go:255] [OnUpdatePod] Updating 'LastStatus' of pod default/bronze-class-deploy-29-7d6b766b6f-m85bq in metrics
I0409 14:51:06.538733       1 default_preemption.go:51] [PreEnqueue] PreEnqueue called for pod: bronze-class-deploy-29-7d6b766b6f-q5ptz
I0409 14:51:06.538759       1 default_preemption.go:52] [PreEnqueue] SchedulerName for pod bronze-class-deploy-29-7d6b766b6f-q5ptz: custom-scheduler
I0409 14:51:06.538760       1 scheduler.go:205] [OnAddPod] Pod added: default/bronze-class-deploy-29-7d6b766b6f-q5ptz, Annotations: map[acceptablePreemptionOverhead:0.05 controller:bronze-controller-29 kwok.x-k8s.io/usage-cpu:1m kwok.x-k8s.io/usage-memory:1Mi qosMeasuring:average slo:0.5]
W0409 14:51:06.538796       1 scheduler.go:118] [cacheMiss] Metrics not found for pod: default/bronze-class-deploy-29-7d6b766b6f-q5ptz
W0409 14:51:06.538803       1 scheduler.go:125] [WaitForPodsOnCache] Pod bronze-class-deploy-29-7d6b766b6f-q5ptz not found in cache. Retrying...
I0409 14:51:06.541201       1 scheduler.go:286] [OnDeletePod] Checking the state of pod default/bronze-class-deploy-29-7d6b766b6f-m85bq in metrics
I0409 14:51:06.639594       1 scheduler.go:103] [HigherPrecedence] Final decision: Does bronze-class-deploy-29-7d6b766b6f-q5ptz have precedence over bronze-class-deploy-3-775f4fbdd9-h8pjj? true
I0409 14:51:06.639639       1 scheduler.go:103] [HigherPrecedence] Final decision: Does bronze-class-deploy-29-7d6b766b6f-q5ptz have precedence over bronze-class-deploy-20-5fd9977fb4-hj4vm? true
I0409 14:51:06.639760       1 scheduler.go:103] [HigherPrecedence] Final decision: Does bronze-class-deploy-31-77756c9778-l96pz have precedence over bronze-class-deploy-24-668b49b99b-ldm7g? false
I0409 14:51:06.639789       1 scheduler.go:103] [HigherPrecedence] Final decision: Does bronze-class-deploy-31-77756c9778-l96pz have precedence over bronze-class-deploy-23-654ffb5cc5-879fc? false
I0409 14:51:06.639804       1 scheduler.go:103] [HigherPrecedence] Final decision: Does bronze-class-deploy-31-77756c9778-l96pz have precedence over bronze-class-deploy-25-b94944fb5-4584t? false
I0409 14:51:06.639818       1 default_preemption.go:39] "Preemption successful" pod="default/bronze-class-deploy-31-77756c9778-l96pz" nominatedNode="kwok-node-1"
I0409 14:51:06.646321       1 scheduler.go:255] [OnUpdatePod] Updating 'LastStatus' of pod default/bronze-class-deploy-31-77756c9778-l96pz in metrics
I0409 14:51:06.646501       1 scheduler.go:103] [HigherPrecedence] Final decision: Does bronze-class-deploy-20-5fd9977fb4-hj4vm have precedence over bronze-class-deploy-16-74dd4696ff-mkf54? true
I0409 14:51:06.646535       1 scheduler.go:103] [HigherPrecedence] Final decision: Does bronze-class-deploy-20-5fd9977fb4-hj4vm have precedence over bronze-class-deploy-3-775f4fbdd9-h8pjj? true
I0409 14:51:06.647079       1 scheduler.go:103] [HigherPrecedence] Final decision: Does bronze-class-deploy-29-7d6b766b6f-q5ptz have precedence over bronze-class-deploy-30-56698788c5-nzttq? false
I0409 14:51:06.647126       1 default_preemption.go:37] "Preemption failed or not needed" pod="default/bronze-class-deploy-29-7d6b766b6f-q5ptz" status="0/2 nodes are available: 1 No preemption victims found for incoming pod, 1 Preemption is not helpful for scheduling."
I0409 14:51:06.653245       1 scheduler.go:103] [HigherPrecedence] Final decision: Does bronze-class-deploy-3-775f4fbdd9-h8pjj have precedence over bronze-class-deploy-16-74dd4696ff-mkf54? false
I0409 14:51:06.653267       1 scheduler.go:255] [OnUpdatePod] Updating 'LastStatus' of pod default/bronze-class-deploy-29-7d6b766b6f-q5ptz in metrics
I0409 14:51:06.653299       1 scheduler.go:103] [HigherPrecedence] Final decision: Does bronze-class-deploy-16-74dd4696ff-mkf54 have precedence over bronze-class-deploy-11-559c656b44-5grsk? true
I0409 14:51:06.653319       1 scheduler.go:103] [HigherPrecedence] Final decision: Does bronze-class-deploy-8-6fff566748-tt726 have precedence over bronze-class-deploy-11-559c656b44-5grsk? false
I0409 14:51:06.653937       1 scheduler.go:103] [HigherPrecedence] Final decision: Does bronze-class-deploy-20-5fd9977fb4-hj4vm have precedence over bronze-class-deploy-30-56698788c5-nzttq? false
I0409 14:51:06.654005       1 default_preemption.go:37] "Preemption failed or not needed" pod="default/bronze-class-deploy-20-5fd9977fb4-hj4vm" status="0/2 nodes are available: 1 No preemption victims found for incoming pod, 1 Preemption is not helpful for scheduling."
I0409 14:51:06.654101       1 scheduler.go:103] [HigherPrecedence] Final decision: Does bronze-class-deploy-3-775f4fbdd9-h8pjj have precedence over bronze-class-deploy-11-559c656b44-5grsk? false
I0409 14:51:06.654128       1 scheduler.go:103] [HigherPrecedence] Final decision: Does bronze-class-deploy-11-559c656b44-5grsk have precedence over bronze-class-deploy-8-6fff566748-tt726? true
I0409 14:51:06.654688       1 scheduler.go:103] [HigherPrecedence] Final decision: Does bronze-class-deploy-16-74dd4696ff-mkf54 have precedence over bronze-class-deploy-30-56698788c5-nzttq? false
I0409 14:51:06.654733       1 default_preemption.go:37] "Preemption failed or not needed" pod="default/bronze-class-deploy-16-74dd4696ff-mkf54" status="0/2 nodes are available: 1 No preemption victims found for incoming pod, 1 Preemption is not helpful for scheduling."
I0409 14:51:06.654802       1 scheduler.go:103] [HigherPrecedence] Final decision: Does bronze-class-deploy-8-6fff566748-tt726 have precedence over bronze-class-deploy-3-775f4fbdd9-h8pjj? true
I0409 14:51:06.655208       1 scheduler.go:103] [HigherPrecedence] Final decision: Does bronze-class-deploy-11-559c656b44-5grsk have precedence over bronze-class-deploy-30-56698788c5-nzttq? false
I0409 14:51:06.655247       1 default_preemption.go:37] "Preemption failed or not needed" pod="default/bronze-class-deploy-11-559c656b44-5grsk" status="0/2 nodes are available: 1 No preemption victims found for incoming pod, 1 Preemption is not helpful for scheduling."
I0409 14:51:06.655872       1 scheduler.go:103] [HigherPrecedence] Final decision: Does bronze-class-deploy-8-6fff566748-tt726 have precedence over bronze-class-deploy-30-56698788c5-nzttq? false
I0409 14:51:06.655929       1 default_preemption.go:37] "Preemption failed or not needed" pod="default/bronze-class-deploy-8-6fff566748-tt726" status="0/2 nodes are available: 1 No preemption victims found for incoming pod, 1 Preemption is not helpful for scheduling."
I0409 14:51:06.656556       1 scheduler.go:103] [HigherPrecedence] Final decision: Does bronze-class-deploy-3-775f4fbdd9-h8pjj have precedence over bronze-class-deploy-30-56698788c5-nzttq? false
I0409 14:51:06.656601       1 default_preemption.go:37] "Preemption failed or not needed" pod="default/bronze-class-deploy-3-775f4fbdd9-h8pjj" status="0/2 nodes are available: 1 No preemption victims found for incoming pod, 1 Preemption is not helpful for scheduling."
I0409 14:51:08.269617       1 default_preemption.go:51] [PreEnqueue] PreEnqueue called for pod: bronze-class-deploy-28-946b5bff6-774x4
I0409 14:51:08.269645       1 default_preemption.go:52] [PreEnqueue] SchedulerName for pod bronze-class-deploy-28-946b5bff6-774x4: custom-scheduler
I0409 14:51:08.269702       1 default_preemption.go:51] [PreEnqueue] PreEnqueue called for pod: bronze-class-deploy-25-b94944fb5-4584t
I0409 14:51:08.269706       1 default_preemption.go:52] [PreEnqueue] SchedulerName for pod bronze-class-deploy-25-b94944fb5-4584t: custom-scheduler
I0409 14:51:08.269732       1 scheduler.go:103] [HigherPrecedence] Final decision: Does bronze-class-deploy-25-b94944fb5-4584t have precedence over bronze-class-deploy-28-946b5bff6-774x4? true
I0409 14:51:08.269751       1 default_preemption.go:51] [PreEnqueue] PreEnqueue called for pod: bronze-class-deploy-31-77756c9778-l96pz
I0409 14:51:08.269754       1 default_preemption.go:52] [PreEnqueue] SchedulerName for pod bronze-class-deploy-31-77756c9778-l96pz: custom-scheduler
I0409 14:51:08.269778       1 scheduler.go:103] [HigherPrecedence] Final decision: Does bronze-class-deploy-31-77756c9778-l96pz have precedence over bronze-class-deploy-25-b94944fb5-4584t? false
I0409 14:51:08.269822       1 scheduler.go:103] [HigherPrecedence] Final decision: Does bronze-class-deploy-28-946b5bff6-774x4 have precedence over bronze-class-deploy-31-77756c9778-l96pz? true
I0409 14:51:08.270234       1 scheduler.go:164] [PreBind] Validating pod bronze-class-deploy-25-b94944fb5-4584t before binding to node kwok-node-1
I0409 14:51:08.270581       1 scheduler.go:103] [HigherPrecedence] Final decision: Does bronze-class-deploy-28-946b5bff6-774x4 have precedence over bronze-class-deploy-30-56698788c5-nzttq? true
I0409 14:51:08.270641       1 scheduler.go:103] [HigherPrecedence] Final decision: Does bronze-class-deploy-28-946b5bff6-774x4 have precedence over bronze-class-deploy-25-b94944fb5-4584t? false
I0409 14:51:08.270680       1 default_preemption.go:37] "Preemption failed or not needed" pod="default/bronze-class-deploy-28-946b5bff6-774x4" status="0/2 nodes are available: 1 No preemption victims found for incoming pod, 1 Preemption is not helpful for scheduling."
I0409 14:51:08.275844       1 scheduler.go:172] [PostBind] Called for pod bronze-class-deploy-25-b94944fb5-4584t
I0409 14:51:08.275876       1 scheduler.go:190] [PostBind] Pod bronze-class-deploy-25-b94944fb5-4584t - Binding start: 2025-04-09 14:51:08.270263165 +0000 UTC m=+152.957633603, Binding end: 2025-04-09 14:51:08.275872487 +0000 UTC m=+152.963242925
I0409 14:51:08.275896       1 scheduler.go:197] [PostBind] Metrics updated for pod bronze-class-deploy-25-b94944fb5-4584t
I0409 14:51:08.275918       1 scheduler.go:255] [OnUpdatePod] Updating 'LastStatus' of pod default/bronze-class-deploy-25-b94944fb5-4584t in metrics
I0409 14:51:08.279189       1 scheduler.go:255] [OnUpdatePod] Updating 'LastStatus' of pod default/bronze-class-deploy-28-946b5bff6-774x4 in metrics
I0409 14:51:08.279552       1 scheduler.go:164] [PreBind] Validating pod bronze-class-deploy-31-77756c9778-l96pz before binding to node kwok-node-1
I0409 14:51:08.284395       1 scheduler.go:255] [OnUpdatePod] Updating 'LastStatus' of pod default/bronze-class-deploy-25-b94944fb5-4584t in metrics
I0409 14:51:08.287124       1 scheduler.go:172] [PostBind] Called for pod bronze-class-deploy-31-77756c9778-l96pz
I0409 14:51:08.287151       1 scheduler.go:190] [PostBind] Pod bronze-class-deploy-31-77756c9778-l96pz - Binding start: 2025-04-09 14:51:08.279565545 +0000 UTC m=+152.966935983, Binding end: 2025-04-09 14:51:08.287147402 +0000 UTC m=+152.974517830
I0409 14:51:08.287162       1 scheduler.go:255] [OnUpdatePod] Updating 'LastStatus' of pod default/bronze-class-deploy-31-77756c9778-l96pz in metrics
I0409 14:51:08.287186       1 scheduler.go:197] [PostBind] Metrics updated for pod bronze-class-deploy-31-77756c9778-l96pz
I0409 14:51:08.295664       1 scheduler.go:255] [OnUpdatePod] Updating 'LastStatus' of pod default/bronze-class-deploy-31-77756c9778-l96pz in metrics
I0409 14:51:16.272556       1 default_preemption.go:51] [PreEnqueue] PreEnqueue called for pod: bronze-class-deploy-24-668b49b99b-ldm7g
I0409 14:51:16.272579       1 default_preemption.go:52] [PreEnqueue] SchedulerName for pod bronze-class-deploy-24-668b49b99b-ldm7g: custom-scheduler
I0409 14:51:16.272625       1 default_preemption.go:51] [PreEnqueue] PreEnqueue called for pod: bronze-class-deploy-23-654ffb5cc5-879fc
I0409 14:51:16.272630       1 default_preemption.go:52] [PreEnqueue] SchedulerName for pod bronze-class-deploy-23-654ffb5cc5-879fc: custom-scheduler
I0409 14:51:16.272664       1 scheduler.go:103] [HigherPrecedence] Final decision: Does bronze-class-deploy-23-654ffb5cc5-879fc have precedence over bronze-class-deploy-24-668b49b99b-ldm7g? false
I0409 14:51:16.273671       1 scheduler.go:164] [PreBind] Validating pod bronze-class-deploy-24-668b49b99b-ldm7g before binding to node kwok-node-1
I0409 14:51:16.273744       1 scheduler.go:164] [PreBind] Validating pod bronze-class-deploy-23-654ffb5cc5-879fc before binding to node kwok-node-1
I0409 14:51:16.279855       1 scheduler.go:172] [PostBind] Called for pod bronze-class-deploy-23-654ffb5cc5-879fc
I0409 14:51:16.279891       1 scheduler.go:190] [PostBind] Pod bronze-class-deploy-23-654ffb5cc5-879fc - Binding start: 2025-04-09 14:51:16.273760813 +0000 UTC m=+160.961131251, Binding end: 2025-04-09 14:51:16.279887104 +0000 UTC m=+160.967257532
I0409 14:51:16.279913       1 scheduler.go:197] [PostBind] Metrics updated for pod bronze-class-deploy-23-654ffb5cc5-879fc
I0409 14:51:16.279941       1 scheduler.go:255] [OnUpdatePod] Updating 'LastStatus' of pod default/bronze-class-deploy-23-654ffb5cc5-879fc in metrics
I0409 14:51:16.280472       1 scheduler.go:255] [OnUpdatePod] Updating 'LastStatus' of pod default/bronze-class-deploy-24-668b49b99b-ldm7g in metrics
I0409 14:51:16.280474       1 scheduler.go:172] [PostBind] Called for pod bronze-class-deploy-24-668b49b99b-ldm7g
I0409 14:51:16.280494       1 scheduler.go:190] [PostBind] Pod bronze-class-deploy-24-668b49b99b-ldm7g - Binding start: 2025-04-09 14:51:16.27370876 +0000 UTC m=+160.961079198, Binding end: 2025-04-09 14:51:16.280491119 +0000 UTC m=+160.967861567
I0409 14:51:16.280505       1 scheduler.go:197] [PostBind] Metrics updated for pod bronze-class-deploy-24-668b49b99b-ldm7g
I0409 14:51:16.290267       1 scheduler.go:255] [OnUpdatePod] Updating 'LastStatus' of pod default/bronze-class-deploy-23-654ffb5cc5-879fc in metrics
I0409 14:51:16.290519       1 scheduler.go:255] [OnUpdatePod] Updating 'LastStatus' of pod default/bronze-class-deploy-24-668b49b99b-ldm7g in metrics
I0409 14:51:36.021809       1 default_preemption.go:51] [PreEnqueue] PreEnqueue called for pod: bronze-class-deploy-3-775f4fbdd9-h8pjj
I0409 14:51:36.021835       1 default_preemption.go:52] [PreEnqueue] SchedulerName for pod bronze-class-deploy-3-775f4fbdd9-h8pjj: custom-scheduler
I0409 14:51:36.021874       1 default_preemption.go:51] [PreEnqueue] PreEnqueue called for pod: bronze-class-deploy-28-946b5bff6-774x4
I0409 14:51:36.021878       1 default_preemption.go:52] [PreEnqueue] SchedulerName for pod bronze-class-deploy-28-946b5bff6-774x4: custom-scheduler
I0409 14:51:36.021903       1 scheduler.go:103] [HigherPrecedence] Final decision: Does bronze-class-deploy-28-946b5bff6-774x4 have precedence over bronze-class-deploy-3-775f4fbdd9-h8pjj? true
I0409 14:51:36.021921       1 default_preemption.go:51] [PreEnqueue] PreEnqueue called for pod: bronze-class-deploy-29-7d6b766b6f-q5ptz
I0409 14:51:36.021924       1 default_preemption.go:52] [PreEnqueue] SchedulerName for pod bronze-class-deploy-29-7d6b766b6f-q5ptz: custom-scheduler
I0409 14:51:36.021950       1 scheduler.go:103] [HigherPrecedence] Final decision: Does bronze-class-deploy-29-7d6b766b6f-q5ptz have precedence over bronze-class-deploy-28-946b5bff6-774x4? false
I0409 14:51:36.021971       1 default_preemption.go:51] [PreEnqueue] PreEnqueue called for pod: bronze-class-deploy-20-5fd9977fb4-hj4vm
I0409 14:51:36.021976       1 default_preemption.go:52] [PreEnqueue] SchedulerName for pod bronze-class-deploy-20-5fd9977fb4-hj4vm: custom-scheduler
I0409 14:51:36.022004       1 scheduler.go:103] [HigherPrecedence] Final decision: Does bronze-class-deploy-20-5fd9977fb4-hj4vm have precedence over bronze-class-deploy-3-775f4fbdd9-h8pjj? true
I0409 14:51:36.022029       1 scheduler.go:103] [HigherPrecedence] Final decision: Does bronze-class-deploy-20-5fd9977fb4-hj4vm have precedence over bronze-class-deploy-28-946b5bff6-774x4? false
I0409 14:51:36.022038       1 default_preemption.go:51] [PreEnqueue] PreEnqueue called for pod: bronze-class-deploy-16-74dd4696ff-mkf54
I0409 14:51:36.022042       1 default_preemption.go:52] [PreEnqueue] SchedulerName for pod bronze-class-deploy-16-74dd4696ff-mkf54: custom-scheduler
I0409 14:51:36.022064       1 scheduler.go:103] [HigherPrecedence] Final decision: Does bronze-class-deploy-16-74dd4696ff-mkf54 have precedence over bronze-class-deploy-20-5fd9977fb4-hj4vm? false
I0409 14:51:36.022086       1 default_preemption.go:51] [PreEnqueue] PreEnqueue called for pod: bronze-class-deploy-11-559c656b44-5grsk
I0409 14:51:36.022090       1 default_preemption.go:52] [PreEnqueue] SchedulerName for pod bronze-class-deploy-11-559c656b44-5grsk: custom-scheduler
I0409 14:51:36.022113       1 scheduler.go:103] [HigherPrecedence] Final decision: Does bronze-class-deploy-11-559c656b44-5grsk have precedence over bronze-class-deploy-29-7d6b766b6f-q5ptz? false
I0409 14:51:36.022131       1 default_preemption.go:51] [PreEnqueue] PreEnqueue called for pod: bronze-class-deploy-8-6fff566748-tt726
I0409 14:51:36.022134       1 default_preemption.go:52] [PreEnqueue] SchedulerName for pod bronze-class-deploy-8-6fff566748-tt726: custom-scheduler
I0409 14:51:36.022157       1 scheduler.go:103] [HigherPrecedence] Final decision: Does bronze-class-deploy-8-6fff566748-tt726 have precedence over bronze-class-deploy-29-7d6b766b6f-q5ptz? false
I0409 14:51:36.022230       1 scheduler.go:103] [HigherPrecedence] Final decision: Does bronze-class-deploy-29-7d6b766b6f-q5ptz have precedence over bronze-class-deploy-20-5fd9977fb4-hj4vm? true
I0409 14:51:36.022261       1 scheduler.go:103] [HigherPrecedence] Final decision: Does bronze-class-deploy-29-7d6b766b6f-q5ptz have precedence over bronze-class-deploy-8-6fff566748-tt726? true
I0409 14:51:36.022281       1 scheduler.go:103] [HigherPrecedence] Final decision: Does bronze-class-deploy-11-559c656b44-5grsk have precedence over bronze-class-deploy-8-6fff566748-tt726? true
I0409 14:51:36.022842       1 scheduler.go:103] [HigherPrecedence] Final decision: Does bronze-class-deploy-28-946b5bff6-774x4 have precedence over bronze-class-deploy-30-56698788c5-nzttq? true
I0409 14:51:36.022885       1 scheduler.go:103] [HigherPrecedence] Final decision: Does bronze-class-deploy-28-946b5bff6-774x4 have precedence over bronze-class-deploy-25-b94944fb5-4584t? true
I0409 14:51:36.022907       1 scheduler.go:103] [HigherPrecedence] Final decision: Does bronze-class-deploy-28-946b5bff6-774x4 have precedence over bronze-class-deploy-31-77756c9778-l96pz? true
I0409 14:51:36.022933       1 scheduler.go:103] [HigherPrecedence] Final decision: Does bronze-class-deploy-28-946b5bff6-774x4 have precedence over bronze-class-deploy-23-654ffb5cc5-879fc? false
I0409 14:51:36.022954       1 scheduler.go:103] [HigherPrecedence] Final decision: Does bronze-class-deploy-28-946b5bff6-774x4 have precedence over bronze-class-deploy-24-668b49b99b-ldm7g? false
I0409 14:51:36.023000       1 default_preemption.go:37] "Preemption failed or not needed" pod="default/bronze-class-deploy-28-946b5bff6-774x4" status="0/2 nodes are available: 1 No preemption victims found for incoming pod, 1 Preemption is not helpful for scheduling."
I0409 14:51:36.023118       1 scheduler.go:103] [HigherPrecedence] Final decision: Does bronze-class-deploy-11-559c656b44-5grsk have precedence over bronze-class-deploy-20-5fd9977fb4-hj4vm? false
I0409 14:51:36.023154       1 scheduler.go:103] [HigherPrecedence] Final decision: Does bronze-class-deploy-20-5fd9977fb4-hj4vm have precedence over bronze-class-deploy-8-6fff566748-tt726? true
I0409 14:51:36.023175       1 scheduler.go:103] [HigherPrecedence] Final decision: Does bronze-class-deploy-16-74dd4696ff-mkf54 have precedence over bronze-class-deploy-3-775f4fbdd9-h8pjj? true
I0409 14:51:36.023201       1 scheduler.go:103] [HigherPrecedence] Final decision: Does bronze-class-deploy-16-74dd4696ff-mkf54 have precedence over bronze-class-deploy-8-6fff566748-tt726? true
I0409 14:51:36.023644       1 scheduler.go:103] [HigherPrecedence] Final decision: Does bronze-class-deploy-29-7d6b766b6f-q5ptz have precedence over bronze-class-deploy-30-56698788c5-nzttq? true
I0409 14:51:36.023686       1 scheduler.go:103] [HigherPrecedence] Final decision: Does bronze-class-deploy-29-7d6b766b6f-q5ptz have precedence over bronze-class-deploy-25-b94944fb5-4584t? true
I0409 14:51:36.023712       1 scheduler.go:103] [HigherPrecedence] Final decision: Does bronze-class-deploy-29-7d6b766b6f-q5ptz have precedence over bronze-class-deploy-31-77756c9778-l96pz? true
I0409 14:51:36.023750       1 scheduler.go:103] [HigherPrecedence] Final decision: Does bronze-class-deploy-29-7d6b766b6f-q5ptz have precedence over bronze-class-deploy-23-654ffb5cc5-879fc? false
I0409 14:51:36.023777       1 scheduler.go:103] [HigherPrecedence] Final decision: Does bronze-class-deploy-29-7d6b766b6f-q5ptz have precedence over bronze-class-deploy-24-668b49b99b-ldm7g? false
I0409 14:51:36.023802       1 default_preemption.go:37] "Preemption failed or not needed" pod="default/bronze-class-deploy-29-7d6b766b6f-q5ptz" status="0/2 nodes are available: 1 No preemption victims found for incoming pod, 1 Preemption is not helpful for scheduling."
I0409 14:51:36.023877       1 scheduler.go:103] [HigherPrecedence] Final decision: Does bronze-class-deploy-11-559c656b44-5grsk have precedence over bronze-class-deploy-16-74dd4696ff-mkf54? false
I0409 14:51:36.023907       1 scheduler.go:103] [HigherPrecedence] Final decision: Does bronze-class-deploy-16-74dd4696ff-mkf54 have precedence over bronze-class-deploy-8-6fff566748-tt726? true
I0409 14:51:36.023935       1 scheduler.go:103] [HigherPrecedence] Final decision: Does bronze-class-deploy-3-775f4fbdd9-h8pjj have precedence over bronze-class-deploy-8-6fff566748-tt726? false
I0409 14:51:36.024433       1 scheduler.go:103] [HigherPrecedence] Final decision: Does bronze-class-deploy-20-5fd9977fb4-hj4vm have precedence over bronze-class-deploy-30-56698788c5-nzttq? true
I0409 14:51:36.024484       1 scheduler.go:103] [HigherPrecedence] Final decision: Does bronze-class-deploy-20-5fd9977fb4-hj4vm have precedence over bronze-class-deploy-25-b94944fb5-4584t? true
I0409 14:51:36.024517       1 scheduler.go:103] [HigherPrecedence] Final decision: Does bronze-class-deploy-20-5fd9977fb4-hj4vm have precedence over bronze-class-deploy-31-77756c9778-l96pz? true
I0409 14:51:36.024555       1 scheduler.go:103] [HigherPrecedence] Final decision: Does bronze-class-deploy-20-5fd9977fb4-hj4vm have precedence over bronze-class-deploy-23-654ffb5cc5-879fc? false
I0409 14:51:36.024572       1 scheduler.go:103] [HigherPrecedence] Final decision: Does bronze-class-deploy-20-5fd9977fb4-hj4vm have precedence over bronze-class-deploy-24-668b49b99b-ldm7g? false
I0409 14:51:36.024621       1 default_preemption.go:37] "Preemption failed or not needed" pod="default/bronze-class-deploy-20-5fd9977fb4-hj4vm" status="0/2 nodes are available: 1 No preemption victims found for incoming pod, 1 Preemption is not helpful for scheduling."
I0409 14:51:36.024767       1 scheduler.go:103] [HigherPrecedence] Final decision: Does bronze-class-deploy-11-559c656b44-5grsk have precedence over bronze-class-deploy-8-6fff566748-tt726? true
I0409 14:51:36.024805       1 scheduler.go:103] [HigherPrecedence] Final decision: Does bronze-class-deploy-11-559c656b44-5grsk have precedence over bronze-class-deploy-3-775f4fbdd9-h8pjj? true
I0409 14:51:36.025240       1 scheduler.go:103] [HigherPrecedence] Final decision: Does bronze-class-deploy-16-74dd4696ff-mkf54 have precedence over bronze-class-deploy-30-56698788c5-nzttq? true
I0409 14:51:36.025291       1 scheduler.go:103] [HigherPrecedence] Final decision: Does bronze-class-deploy-16-74dd4696ff-mkf54 have precedence over bronze-class-deploy-25-b94944fb5-4584t? true
I0409 14:51:36.025321       1 scheduler.go:103] [HigherPrecedence] Final decision: Does bronze-class-deploy-16-74dd4696ff-mkf54 have precedence over bronze-class-deploy-31-77756c9778-l96pz? true
I0409 14:51:36.025353       1 scheduler.go:103] [HigherPrecedence] Final decision: Does bronze-class-deploy-16-74dd4696ff-mkf54 have precedence over bronze-class-deploy-23-654ffb5cc5-879fc? false
I0409 14:51:36.025415       1 scheduler.go:103] [HigherPrecedence] Final decision: Does bronze-class-deploy-16-74dd4696ff-mkf54 have precedence over bronze-class-deploy-24-668b49b99b-ldm7g? false
I0409 14:51:36.025449       1 default_preemption.go:37] "Preemption failed or not needed" pod="default/bronze-class-deploy-16-74dd4696ff-mkf54" status="0/2 nodes are available: 1 No preemption victims found for incoming pod, 1 Preemption is not helpful for scheduling."
I0409 14:51:36.025560       1 scheduler.go:103] [HigherPrecedence] Final decision: Does bronze-class-deploy-8-6fff566748-tt726 have precedence over bronze-class-deploy-3-775f4fbdd9-h8pjj? true
I0409 14:51:36.025960       1 scheduler.go:103] [HigherPrecedence] Final decision: Does bronze-class-deploy-11-559c656b44-5grsk have precedence over bronze-class-deploy-30-56698788c5-nzttq? true
I0409 14:51:36.025999       1 scheduler.go:103] [HigherPrecedence] Final decision: Does bronze-class-deploy-11-559c656b44-5grsk have precedence over bronze-class-deploy-25-b94944fb5-4584t? true
I0409 14:51:36.026025       1 scheduler.go:103] [HigherPrecedence] Final decision: Does bronze-class-deploy-11-559c656b44-5grsk have precedence over bronze-class-deploy-31-77756c9778-l96pz? true
I0409 14:51:36.026053       1 scheduler.go:103] [HigherPrecedence] Final decision: Does bronze-class-deploy-11-559c656b44-5grsk have precedence over bronze-class-deploy-23-654ffb5cc5-879fc? false
I0409 14:51:36.026128       1 scheduler.go:103] [HigherPrecedence] Final decision: Does bronze-class-deploy-11-559c656b44-5grsk have precedence over bronze-class-deploy-24-668b49b99b-ldm7g? false
I0409 14:51:36.026225       1 default_preemption.go:37] "Preemption failed or not needed" pod="default/bronze-class-deploy-11-559c656b44-5grsk" status="0/2 nodes are available: 1 No preemption victims found for incoming pod, 1 Preemption is not helpful for scheduling."
I0409 14:51:36.026883       1 scheduler.go:103] [HigherPrecedence] Final decision: Does bronze-class-deploy-8-6fff566748-tt726 have precedence over bronze-class-deploy-30-56698788c5-nzttq? true
I0409 14:51:36.026938       1 scheduler.go:103] [HigherPrecedence] Final decision: Does bronze-class-deploy-8-6fff566748-tt726 have precedence over bronze-class-deploy-25-b94944fb5-4584t? true
I0409 14:51:36.026968       1 scheduler.go:103] [HigherPrecedence] Final decision: Does bronze-class-deploy-8-6fff566748-tt726 have precedence over bronze-class-deploy-31-77756c9778-l96pz? true
I0409 14:51:36.027016       1 scheduler.go:103] [HigherPrecedence] Final decision: Does bronze-class-deploy-8-6fff566748-tt726 have precedence over bronze-class-deploy-23-654ffb5cc5-879fc? false
I0409 14:51:36.027039       1 scheduler.go:103] [HigherPrecedence] Final decision: Does bronze-class-deploy-8-6fff566748-tt726 have precedence over bronze-class-deploy-24-668b49b99b-ldm7g? false
I0409 14:51:36.027087       1 default_preemption.go:37] "Preemption failed or not needed" pod="default/bronze-class-deploy-8-6fff566748-tt726" status="0/2 nodes are available: 1 No preemption victims found for incoming pod, 1 Preemption is not helpful for scheduling."
I0409 14:51:36.027640       1 scheduler.go:103] [HigherPrecedence] Final decision: Does bronze-class-deploy-3-775f4fbdd9-h8pjj have precedence over bronze-class-deploy-30-56698788c5-nzttq? true
I0409 14:51:36.027693       1 scheduler.go:103] [HigherPrecedence] Final decision: Does bronze-class-deploy-3-775f4fbdd9-h8pjj have precedence over bronze-class-deploy-25-b94944fb5-4584t? true
I0409 14:51:36.027721       1 scheduler.go:103] [HigherPrecedence] Final decision: Does bronze-class-deploy-3-775f4fbdd9-h8pjj have precedence over bronze-class-deploy-31-77756c9778-l96pz? true
I0409 14:51:36.027753       1 scheduler.go:103] [HigherPrecedence] Final decision: Does bronze-class-deploy-3-775f4fbdd9-h8pjj have precedence over bronze-class-deploy-23-654ffb5cc5-879fc? false
I0409 14:51:36.027780       1 scheduler.go:103] [HigherPrecedence] Final decision: Does bronze-class-deploy-3-775f4fbdd9-h8pjj have precedence over bronze-class-deploy-24-668b49b99b-ldm7g? false
I0409 14:51:36.027821       1 default_preemption.go:37] "Preemption failed or not needed" pod="default/bronze-class-deploy-3-775f4fbdd9-h8pjj" status="0/2 nodes are available: 1 No preemption victims found for incoming pod, 1 Preemption is not helpful for scheduling."
I0409 14:52:06.023169       1 default_preemption.go:51] [PreEnqueue] PreEnqueue called for pod: bronze-class-deploy-29-7d6b766b6f-q5ptz
I0409 14:52:06.023196       1 default_preemption.go:52] [PreEnqueue] SchedulerName for pod bronze-class-deploy-29-7d6b766b6f-q5ptz: custom-scheduler
I0409 14:52:06.023233       1 default_preemption.go:51] [PreEnqueue] PreEnqueue called for pod: bronze-class-deploy-20-5fd9977fb4-hj4vm
I0409 14:52:06.023236       1 default_preemption.go:52] [PreEnqueue] SchedulerName for pod bronze-class-deploy-20-5fd9977fb4-hj4vm: custom-scheduler
I0409 14:52:06.023261       1 scheduler.go:103] [HigherPrecedence] Final decision: Does bronze-class-deploy-20-5fd9977fb4-hj4vm have precedence over bronze-class-deploy-29-7d6b766b6f-q5ptz? false
I0409 14:52:06.023272       1 default_preemption.go:51] [PreEnqueue] PreEnqueue called for pod: bronze-class-deploy-16-74dd4696ff-mkf54
I0409 14:52:06.023276       1 default_preemption.go:52] [PreEnqueue] SchedulerName for pod bronze-class-deploy-16-74dd4696ff-mkf54: custom-scheduler
I0409 14:52:06.023302       1 scheduler.go:103] [HigherPrecedence] Final decision: Does bronze-class-deploy-16-74dd4696ff-mkf54 have precedence over bronze-class-deploy-29-7d6b766b6f-q5ptz? false
I0409 14:52:06.023319       1 default_preemption.go:51] [PreEnqueue] PreEnqueue called for pod: bronze-class-deploy-11-559c656b44-5grsk
I0409 14:52:06.023324       1 default_preemption.go:52] [PreEnqueue] SchedulerName for pod bronze-class-deploy-11-559c656b44-5grsk: custom-scheduler
I0409 14:52:06.023347       1 scheduler.go:103] [HigherPrecedence] Final decision: Does bronze-class-deploy-11-559c656b44-5grsk have precedence over bronze-class-deploy-20-5fd9977fb4-hj4vm? false
I0409 14:52:06.023383       1 default_preemption.go:51] [PreEnqueue] PreEnqueue called for pod: bronze-class-deploy-8-6fff566748-tt726
I0409 14:52:06.023393       1 default_preemption.go:52] [PreEnqueue] SchedulerName for pod bronze-class-deploy-8-6fff566748-tt726: custom-scheduler
I0409 14:52:06.023414       1 scheduler.go:103] [HigherPrecedence] Final decision: Does bronze-class-deploy-8-6fff566748-tt726 have precedence over bronze-class-deploy-20-5fd9977fb4-hj4vm? false
I0409 14:52:06.023424       1 default_preemption.go:51] [PreEnqueue] PreEnqueue called for pod: bronze-class-deploy-3-775f4fbdd9-h8pjj
I0409 14:52:06.023428       1 default_preemption.go:52] [PreEnqueue] SchedulerName for pod bronze-class-deploy-3-775f4fbdd9-h8pjj: custom-scheduler
I0409 14:52:06.023451       1 scheduler.go:103] [HigherPrecedence] Final decision: Does bronze-class-deploy-3-775f4fbdd9-h8pjj have precedence over bronze-class-deploy-16-74dd4696ff-mkf54? false
I0409 14:52:06.023472       1 default_preemption.go:51] [PreEnqueue] PreEnqueue called for pod: bronze-class-deploy-28-946b5bff6-774x4
I0409 14:52:06.023476       1 default_preemption.go:52] [PreEnqueue] SchedulerName for pod bronze-class-deploy-28-946b5bff6-774x4: custom-scheduler
I0409 14:52:06.023499       1 scheduler.go:103] [HigherPrecedence] Final decision: Does bronze-class-deploy-28-946b5bff6-774x4 have precedence over bronze-class-deploy-16-74dd4696ff-mkf54? true
I0409 14:52:06.023522       1 scheduler.go:103] [HigherPrecedence] Final decision: Does bronze-class-deploy-28-946b5bff6-774x4 have precedence over bronze-class-deploy-29-7d6b766b6f-q5ptz? true
I0409 14:52:06.023561       1 scheduler.go:103] [HigherPrecedence] Final decision: Does bronze-class-deploy-29-7d6b766b6f-q5ptz have precedence over bronze-class-deploy-20-5fd9977fb4-hj4vm? true
I0409 14:52:06.023582       1 scheduler.go:103] [HigherPrecedence] Final decision: Does bronze-class-deploy-29-7d6b766b6f-q5ptz have precedence over bronze-class-deploy-16-74dd4696ff-mkf54? true
I0409 14:52:06.023605       1 scheduler.go:103] [HigherPrecedence] Final decision: Does bronze-class-deploy-3-775f4fbdd9-h8pjj have precedence over bronze-class-deploy-16-74dd4696ff-mkf54? false
I0409 14:52:06.024162       1 scheduler.go:103] [HigherPrecedence] Final decision: Does bronze-class-deploy-28-946b5bff6-774x4 have precedence over bronze-class-deploy-30-56698788c5-nzttq? true
I0409 14:52:06.024236       1 scheduler.go:103] [HigherPrecedence] Final decision: Does bronze-class-deploy-28-946b5bff6-774x4 have precedence over bronze-class-deploy-25-b94944fb5-4584t? true
I0409 14:52:06.024307       1 scheduler.go:103] [HigherPrecedence] Final decision: Does bronze-class-deploy-28-946b5bff6-774x4 have precedence over bronze-class-deploy-31-77756c9778-l96pz? true
I0409 14:52:06.024401       1 scheduler.go:103] [HigherPrecedence] Final decision: Does bronze-class-deploy-28-946b5bff6-774x4 have precedence over bronze-class-deploy-23-654ffb5cc5-879fc? true
I0409 14:52:06.024468       1 scheduler.go:103] [HigherPrecedence] Final decision: Does bronze-class-deploy-28-946b5bff6-774x4 have precedence over bronze-class-deploy-24-668b49b99b-ldm7g? false
I0409 14:52:06.032349       1 scheduler.go:255] [OnUpdatePod] Updating 'LastStatus' of pod default/bronze-class-deploy-23-654ffb5cc5-879fc in metrics
I0409 14:52:06.037785       1 scheduler.go:255] [OnUpdatePod] Updating 'LastStatus' of pod default/bronze-class-deploy-23-654ffb5cc5-879fc in metrics
I0409 14:52:06.039976       1 default_preemption.go:39] "Preemption successful" pod="default/bronze-class-deploy-28-946b5bff6-774x4" nominatedNode="kwok-node-1"
I0409 14:52:06.040113       1 scheduler.go:286] [OnDeletePod] Checking the state of pod default/bronze-class-deploy-23-654ffb5cc5-879fc in metrics
I0409 14:52:06.047110       1 scheduler.go:103] [HigherPrecedence] Final decision: Does bronze-class-deploy-16-74dd4696ff-mkf54 have precedence over bronze-class-deploy-20-5fd9977fb4-hj4vm? false
I0409 14:52:06.047117       1 scheduler.go:255] [OnUpdatePod] Updating 'LastStatus' of pod default/bronze-class-deploy-28-946b5bff6-774x4 in metrics
I0409 14:52:06.047169       1 scheduler.go:103] [HigherPrecedence] Final decision: Does bronze-class-deploy-20-5fd9977fb4-hj4vm have precedence over bronze-class-deploy-3-775f4fbdd9-h8pjj? true
I0409 14:52:06.047198       1 scheduler.go:103] [HigherPrecedence] Final decision: Does bronze-class-deploy-8-6fff566748-tt726 have precedence over bronze-class-deploy-11-559c656b44-5grsk? false
I0409 14:52:06.047218       1 scheduler.go:103] [HigherPrecedence] Final decision: Does bronze-class-deploy-11-559c656b44-5grsk have precedence over bronze-class-deploy-3-775f4fbdd9-h8pjj? true
I0409 14:52:06.047899       1 scheduler.go:103] [HigherPrecedence] Final decision: Does bronze-class-deploy-29-7d6b766b6f-q5ptz have precedence over bronze-class-deploy-30-56698788c5-nzttq? true
I0409 14:52:06.047952       1 scheduler.go:103] [HigherPrecedence] Final decision: Does bronze-class-deploy-29-7d6b766b6f-q5ptz have precedence over bronze-class-deploy-25-b94944fb5-4584t? true
I0409 14:52:06.047979       1 scheduler.go:103] [HigherPrecedence] Final decision: Does bronze-class-deploy-29-7d6b766b6f-q5ptz have precedence over bronze-class-deploy-31-77756c9778-l96pz? true
I0409 14:52:06.048012       1 scheduler.go:103] [HigherPrecedence] Final decision: Does bronze-class-deploy-29-7d6b766b6f-q5ptz have precedence over bronze-class-deploy-24-668b49b99b-ldm7g? false
I0409 14:52:06.050232       1 default_preemption.go:51] [PreEnqueue] PreEnqueue called for pod: bronze-class-deploy-23-654ffb5cc5-btltf
I0409 14:52:06.050272       1 scheduler.go:205] [OnAddPod] Pod added: default/bronze-class-deploy-23-654ffb5cc5-btltf, Annotations: map[acceptablePreemptionOverhead:0.05 controller:bronze-controller-23 kwok.x-k8s.io/usage-cpu:1m kwok.x-k8s.io/usage-memory:1Mi qosMeasuring:average slo:0.5]
I0409 14:52:06.050294       1 default_preemption.go:52] [PreEnqueue] SchedulerName for pod bronze-class-deploy-23-654ffb5cc5-btltf: custom-scheduler
W0409 14:52:06.050381       1 scheduler.go:118] [cacheMiss] Metrics not found for pod: default/bronze-class-deploy-23-654ffb5cc5-btltf
W0409 14:52:06.050437       1 scheduler.go:125] [WaitForPodsOnCache] Pod bronze-class-deploy-23-654ffb5cc5-btltf not found in cache. Retrying...
I0409 14:52:06.055552       1 scheduler.go:255] [OnUpdatePod] Updating 'LastStatus' of pod default/bronze-class-deploy-31-77756c9778-l96pz in metrics
I0409 14:52:06.061914       1 scheduler.go:255] [OnUpdatePod] Updating 'LastStatus' of pod default/bronze-class-deploy-31-77756c9778-l96pz in metrics
I0409 14:52:06.068063       1 scheduler.go:205] [OnAddPod] Pod added: default/bronze-class-deploy-31-77756c9778-d8hft, Annotations: map[acceptablePreemptionOverhead:0.05 controller:bronze-controller-31 kwok.x-k8s.io/usage-cpu:1m kwok.x-k8s.io/usage-memory:1Mi qosMeasuring:average slo:0.5]
I0409 14:52:06.074719       1 scheduler.go:286] [OnDeletePod] Checking the state of pod default/bronze-class-deploy-31-77756c9778-l96pz in metrics
I0409 14:52:06.150840       1 scheduler.go:103] [HigherPrecedence] Final decision: Does bronze-class-deploy-23-654ffb5cc5-btltf have precedence over bronze-class-deploy-16-74dd4696ff-mkf54? true
I0409 14:52:06.150881       1 scheduler.go:103] [HigherPrecedence] Final decision: Does bronze-class-deploy-23-654ffb5cc5-btltf have precedence over bronze-class-deploy-20-5fd9977fb4-hj4vm? true
I0409 14:52:06.151000       1 scheduler.go:103] [HigherPrecedence] Final decision: Does bronze-class-deploy-29-7d6b766b6f-q5ptz have precedence over bronze-class-deploy-28-946b5bff6-774x4? false
I0409 14:52:06.151025       1 default_preemption.go:39] "Preemption successful" pod="default/bronze-class-deploy-29-7d6b766b6f-q5ptz" nominatedNode="kwok-node-1"
I0409 14:52:06.151123       1 default_preemption.go:51] [PreEnqueue] PreEnqueue called for pod: bronze-class-deploy-31-77756c9778-d8hft
I0409 14:52:06.151142       1 default_preemption.go:52] [PreEnqueue] SchedulerName for pod bronze-class-deploy-31-77756c9778-d8hft: custom-scheduler
I0409 14:52:06.151177       1 scheduler.go:103] [HigherPrecedence] Final decision: Does bronze-class-deploy-31-77756c9778-d8hft have precedence over bronze-class-deploy-20-5fd9977fb4-hj4vm? false
I0409 14:52:06.158430       1 scheduler.go:255] [OnUpdatePod] Updating 'LastStatus' of pod default/bronze-class-deploy-29-7d6b766b6f-q5ptz in metrics
I0409 14:52:06.158512       1 scheduler.go:103] [HigherPrecedence] Final decision: Does bronze-class-deploy-20-5fd9977fb4-hj4vm have precedence over bronze-class-deploy-11-559c656b44-5grsk? true
I0409 14:52:06.158545       1 scheduler.go:103] [HigherPrecedence] Final decision: Does bronze-class-deploy-20-5fd9977fb4-hj4vm have precedence over bronze-class-deploy-31-77756c9778-d8hft? true
I0409 14:52:06.158567       1 scheduler.go:103] [HigherPrecedence] Final decision: Does bronze-class-deploy-16-74dd4696ff-mkf54 have precedence over bronze-class-deploy-31-77756c9778-d8hft? true
I0409 14:52:06.159148       1 scheduler.go:103] [HigherPrecedence] Final decision: Does bronze-class-deploy-23-654ffb5cc5-btltf have precedence over bronze-class-deploy-30-56698788c5-nzttq? true
I0409 14:52:06.159205       1 scheduler.go:103] [HigherPrecedence] Final decision: Does bronze-class-deploy-23-654ffb5cc5-btltf have precedence over bronze-class-deploy-25-b94944fb5-4584t? true
I0409 14:52:06.159239       1 scheduler.go:103] [HigherPrecedence] Final decision: Does bronze-class-deploy-23-654ffb5cc5-btltf have precedence over bronze-class-deploy-24-668b49b99b-ldm7g? false
I0409 14:52:06.166599       1 scheduler.go:255] [OnUpdatePod] Updating 'LastStatus' of pod default/bronze-class-deploy-25-b94944fb5-4584t in metrics
I0409 14:52:06.172043       1 scheduler.go:255] [OnUpdatePod] Updating 'LastStatus' of pod default/bronze-class-deploy-25-b94944fb5-4584t in metrics
I0409 14:52:06.177244       1 scheduler.go:103] [HigherPrecedence] Final decision: Does bronze-class-deploy-23-654ffb5cc5-btltf have precedence over bronze-class-deploy-28-946b5bff6-774x4? false
I0409 14:52:06.177292       1 scheduler.go:103] [HigherPrecedence] Final decision: Does bronze-class-deploy-23-654ffb5cc5-btltf have precedence over bronze-class-deploy-29-7d6b766b6f-q5ptz? true
I0409 14:52:06.177426       1 scheduler.go:286] [OnDeletePod] Checking the state of pod default/bronze-class-deploy-25-b94944fb5-4584t in metrics
I0409 14:52:06.177978       1 default_preemption.go:51] [PreEnqueue] PreEnqueue called for pod: bronze-class-deploy-25-b94944fb5-r6wph
I0409 14:52:06.177998       1 default_preemption.go:52] [PreEnqueue] SchedulerName for pod bronze-class-deploy-25-b94944fb5-r6wph: custom-scheduler
I0409 14:52:06.177994       1 scheduler.go:205] [OnAddPod] Pod added: default/bronze-class-deploy-25-b94944fb5-r6wph, Annotations: map[acceptablePreemptionOverhead:0.05 controller:bronze-controller-25 kwok.x-k8s.io/usage-cpu:1m kwok.x-k8s.io/usage-memory:1Mi qosMeasuring:average slo:0.5]
W0409 14:52:06.178034       1 scheduler.go:118] [cacheMiss] Metrics not found for pod: default/bronze-class-deploy-25-b94944fb5-r6wph
W0409 14:52:06.178044       1 scheduler.go:125] [WaitForPodsOnCache] Pod bronze-class-deploy-25-b94944fb5-r6wph not found in cache. Retrying...
I0409 14:52:06.186192       1 scheduler.go:255] [OnUpdatePod] Updating 'LastStatus' of pod default/bronze-class-deploy-29-7d6b766b6f-q5ptz in metrics
I0409 14:52:06.186352       1 default_preemption.go:39] "Preemption successful" pod="default/bronze-class-deploy-23-654ffb5cc5-btltf" nominatedNode="kwok-node-1"
I0409 14:52:06.278925       1 scheduler.go:103] [HigherPrecedence] Final decision: Does bronze-class-deploy-25-b94944fb5-r6wph have precedence over bronze-class-deploy-16-74dd4696ff-mkf54? false
I0409 14:52:06.285296       1 scheduler.go:103] [HigherPrecedence] Final decision: Does bronze-class-deploy-16-74dd4696ff-mkf54 have precedence over bronze-class-deploy-11-559c656b44-5grsk? true
I0409 14:52:06.285341       1 scheduler.go:255] [OnUpdatePod] Updating 'LastStatus' of pod default/bronze-class-deploy-23-654ffb5cc5-btltf in metrics
I0409 14:52:06.285439       1 scheduler.go:103] [HigherPrecedence] Final decision: Does bronze-class-deploy-16-74dd4696ff-mkf54 have precedence over bronze-class-deploy-25-b94944fb5-r6wph? true
I0409 14:52:06.285482       1 scheduler.go:103] [HigherPrecedence] Final decision: Does bronze-class-deploy-31-77756c9778-d8hft have precedence over bronze-class-deploy-25-b94944fb5-r6wph? false
I0409 14:52:06.285761       1 scheduler.go:103] [HigherPrecedence] Final decision: Does bronze-class-deploy-25-b94944fb5-r6wph have precedence over bronze-class-deploy-11-559c656b44-5grsk? false
I0409 14:52:06.285792       1 scheduler.go:103] [HigherPrecedence] Final decision: Does bronze-class-deploy-11-559c656b44-5grsk have precedence over bronze-class-deploy-31-77756c9778-d8hft? true
I0409 14:52:06.285811       1 scheduler.go:103] [HigherPrecedence] Final decision: Does bronze-class-deploy-8-6fff566748-tt726 have precedence over bronze-class-deploy-3-775f4fbdd9-h8pjj? true
I0409 14:52:06.285827       1 scheduler.go:103] [HigherPrecedence] Final decision: Does bronze-class-deploy-8-6fff566748-tt726 have precedence over bronze-class-deploy-31-77756c9778-d8hft? true
I0409 14:52:06.285862       1 scheduler.go:164] [PreBind] Validating pod bronze-class-deploy-20-5fd9977fb4-hj4vm before binding to node kwok-node-1
I0409 14:52:06.286386       1 scheduler.go:103] [HigherPrecedence] Final decision: Does bronze-class-deploy-16-74dd4696ff-mkf54 have precedence over bronze-class-deploy-30-56698788c5-nzttq? true
I0409 14:52:06.286439       1 scheduler.go:103] [HigherPrecedence] Final decision: Does bronze-class-deploy-16-74dd4696ff-mkf54 have precedence over bronze-class-deploy-24-668b49b99b-ldm7g? false
I0409 14:52:06.286460       1 scheduler.go:103] [HigherPrecedence] Final decision: Does bronze-class-deploy-16-74dd4696ff-mkf54 have precedence over bronze-class-deploy-20-5fd9977fb4-hj4vm? false
I0409 14:52:06.291284       1 scheduler.go:172] [PostBind] Called for pod bronze-class-deploy-20-5fd9977fb4-hj4vm
I0409 14:52:06.291311       1 scheduler.go:190] [PostBind] Pod bronze-class-deploy-20-5fd9977fb4-hj4vm - Binding start: 2025-04-09 14:52:06.285879543 +0000 UTC m=+210.973249971, Binding end: 2025-04-09 14:52:06.291308083 +0000 UTC m=+210.978678521
I0409 14:52:06.291332       1 scheduler.go:197] [PostBind] Metrics updated for pod bronze-class-deploy-20-5fd9977fb4-hj4vm
I0409 14:52:06.291585       1 scheduler.go:255] [OnUpdatePod] Updating 'LastStatus' of pod default/bronze-class-deploy-20-5fd9977fb4-hj4vm in metrics
I0409 14:52:06.294686       1 scheduler.go:255] [OnUpdatePod] Updating 'LastStatus' of pod default/bronze-class-deploy-30-56698788c5-nzttq in metrics
I0409 14:52:06.299932       1 scheduler.go:255] [OnUpdatePod] Updating 'LastStatus' of pod default/bronze-class-deploy-20-5fd9977fb4-hj4vm in metrics
I0409 14:52:06.303038       1 scheduler.go:255] [OnUpdatePod] Updating 'LastStatus' of pod default/bronze-class-deploy-30-56698788c5-nzttq in metrics
I0409 14:52:06.307535       1 default_preemption.go:51] [PreEnqueue] PreEnqueue called for pod: bronze-class-deploy-30-56698788c5-dkftl
I0409 14:52:06.307640       1 default_preemption.go:52] [PreEnqueue] SchedulerName for pod bronze-class-deploy-30-56698788c5-dkftl: custom-scheduler
I0409 14:52:06.307544       1 scheduler.go:205] [OnAddPod] Pod added: default/bronze-class-deploy-30-56698788c5-dkftl, Annotations: map[acceptablePreemptionOverhead:0.05 controller:bronze-controller-30 kwok.x-k8s.io/usage-cpu:1m kwok.x-k8s.io/usage-memory:1Mi qosMeasuring:average slo:0.5]
W0409 14:52:06.307689       1 scheduler.go:118] [cacheMiss] Metrics not found for pod: default/bronze-class-deploy-30-56698788c5-dkftl
W0409 14:52:06.307704       1 scheduler.go:125] [WaitForPodsOnCache] Pod bronze-class-deploy-30-56698788c5-dkftl not found in cache. Retrying...
I0409 14:52:06.310288       1 scheduler.go:286] [OnDeletePod] Checking the state of pod default/bronze-class-deploy-30-56698788c5-nzttq in metrics
I0409 14:52:06.408423       1 scheduler.go:103] [HigherPrecedence] Final decision: Does bronze-class-deploy-30-56698788c5-dkftl have precedence over bronze-class-deploy-25-b94944fb5-r6wph? false
I0409 14:52:06.408597       1 scheduler.go:103] [HigherPrecedence] Final decision: Does bronze-class-deploy-16-74dd4696ff-mkf54 have precedence over bronze-class-deploy-28-946b5bff6-774x4? false
I0409 14:52:06.408631       1 scheduler.go:103] [HigherPrecedence] Final decision: Does bronze-class-deploy-16-74dd4696ff-mkf54 have precedence over bronze-class-deploy-23-654ffb5cc5-btltf? false
I0409 14:52:06.408649       1 default_preemption.go:39] "Preemption successful" pod="default/bronze-class-deploy-16-74dd4696ff-mkf54" nominatedNode="kwok-node-1"
I0409 14:52:06.415146       1 scheduler.go:103] [HigherPrecedence] Final decision: Does bronze-class-deploy-25-b94944fb5-r6wph have precedence over bronze-class-deploy-8-6fff566748-tt726? false
I0409 14:52:06.415181       1 scheduler.go:103] [HigherPrecedence] Final decision: Does bronze-class-deploy-8-6fff566748-tt726 have precedence over bronze-class-deploy-30-56698788c5-dkftl? true
I0409 14:52:06.415188       1 scheduler.go:255] [OnUpdatePod] Updating 'LastStatus' of pod default/bronze-class-deploy-16-74dd4696ff-mkf54 in metrics
I0409 14:52:06.415232       1 scheduler.go:103] [HigherPrecedence] Final decision: Does bronze-class-deploy-31-77756c9778-d8hft have precedence over bronze-class-deploy-3-775f4fbdd9-h8pjj? false
I0409 14:52:06.415266       1 scheduler.go:103] [HigherPrecedence] Final decision: Does bronze-class-deploy-3-775f4fbdd9-h8pjj have precedence over bronze-class-deploy-30-56698788c5-dkftl? true
I0409 14:52:06.415893       1 scheduler.go:103] [HigherPrecedence] Final decision: Does bronze-class-deploy-11-559c656b44-5grsk have precedence over bronze-class-deploy-20-5fd9977fb4-hj4vm? false
I0409 14:52:06.415923       1 scheduler.go:103] [HigherPrecedence] Final decision: Does bronze-class-deploy-11-559c656b44-5grsk have precedence over bronze-class-deploy-24-668b49b99b-ldm7g? false
I0409 14:52:06.415952       1 default_preemption.go:37] "Preemption failed or not needed" pod="default/bronze-class-deploy-11-559c656b44-5grsk" status="0/2 nodes are available: 1 No preemption victims found for incoming pod, 1 Preemption is not helpful for scheduling."
I0409 14:52:06.416059       1 scheduler.go:103] [HigherPrecedence] Final decision: Does bronze-class-deploy-25-b94944fb5-r6wph have precedence over bronze-class-deploy-3-775f4fbdd9-h8pjj? false
I0409 14:52:06.416090       1 scheduler.go:103] [HigherPrecedence] Final decision: Does bronze-class-deploy-3-775f4fbdd9-h8pjj have precedence over bronze-class-deploy-31-77756c9778-d8hft? true
I0409 14:52:06.416106       1 scheduler.go:103] [HigherPrecedence] Final decision: Does bronze-class-deploy-30-56698788c5-dkftl have precedence over bronze-class-deploy-31-77756c9778-d8hft? false
I0409 14:52:06.416547       1 scheduler.go:103] [HigherPrecedence] Final decision: Does bronze-class-deploy-8-6fff566748-tt726 have precedence over bronze-class-deploy-20-5fd9977fb4-hj4vm? false
I0409 14:52:06.416583       1 scheduler.go:103] [HigherPrecedence] Final decision: Does bronze-class-deploy-8-6fff566748-tt726 have precedence over bronze-class-deploy-24-668b49b99b-ldm7g? false
I0409 14:52:06.416611       1 default_preemption.go:37] "Preemption failed or not needed" pod="default/bronze-class-deploy-8-6fff566748-tt726" status="0/2 nodes are available: 1 No preemption victims found for incoming pod, 1 Preemption is not helpful for scheduling."
I0409 14:52:06.416705       1 scheduler.go:103] [HigherPrecedence] Final decision: Does bronze-class-deploy-25-b94944fb5-r6wph have precedence over bronze-class-deploy-31-77756c9778-d8hft? true
I0409 14:52:06.416731       1 scheduler.go:103] [HigherPrecedence] Final decision: Does bronze-class-deploy-25-b94944fb5-r6wph have precedence over bronze-class-deploy-30-56698788c5-dkftl? true
I0409 14:52:06.417791       1 scheduler.go:103] [HigherPrecedence] Final decision: Does bronze-class-deploy-3-775f4fbdd9-h8pjj have precedence over bronze-class-deploy-20-5fd9977fb4-hj4vm? false
I0409 14:52:06.417838       1 scheduler.go:103] [HigherPrecedence] Final decision: Does bronze-class-deploy-3-775f4fbdd9-h8pjj have precedence over bronze-class-deploy-24-668b49b99b-ldm7g? false
I0409 14:52:06.417869       1 default_preemption.go:37] "Preemption failed or not needed" pod="default/bronze-class-deploy-3-775f4fbdd9-h8pjj" status="0/2 nodes are available: 1 No preemption victims found for incoming pod, 1 Preemption is not helpful for scheduling."
I0409 14:52:06.418005       1 scheduler.go:103] [HigherPrecedence] Final decision: Does bronze-class-deploy-31-77756c9778-d8hft have precedence over bronze-class-deploy-30-56698788c5-dkftl? true
I0409 14:52:06.418558       1 scheduler.go:103] [HigherPrecedence] Final decision: Does bronze-class-deploy-25-b94944fb5-r6wph have precedence over gold-class-deploy-1-78bb76545-pwz55? false
I0409 14:52:06.418862       1 scheduler.go:103] [HigherPrecedence] Final decision: Does bronze-class-deploy-25-b94944fb5-r6wph have precedence over gold-class-deploy-2-58ff5bfb68-446gs? false
I0409 14:52:06.418882       1 scheduler.go:103] [HigherPrecedence] Final decision: Does bronze-class-deploy-25-b94944fb5-r6wph have precedence over silver-class-deploy-21-7bf557854c-zflrc? false
I0409 14:52:06.418902       1 scheduler.go:103] [HigherPrecedence] Final decision: Does bronze-class-deploy-25-b94944fb5-r6wph have precedence over gold-class-deploy-4-b6866bf4b-5dnw5? false
I0409 14:52:06.418933       1 scheduler.go:103] [HigherPrecedence] Final decision: Does bronze-class-deploy-25-b94944fb5-r6wph have precedence over gold-class-deploy-5-c4557676f-pdmbf? false
I0409 14:52:06.418961       1 scheduler.go:103] [HigherPrecedence] Final decision: Does bronze-class-deploy-25-b94944fb5-r6wph have precedence over gold-class-deploy-6-6df4d4d67b-bf8cr? false
I0409 14:52:06.418977       1 scheduler.go:103] [HigherPrecedence] Final decision: Does bronze-class-deploy-25-b94944fb5-r6wph have precedence over silver-class-deploy-7-ff55f69ff-hwmfr? false
I0409 14:52:06.418998       1 scheduler.go:103] [HigherPrecedence] Final decision: Does bronze-class-deploy-25-b94944fb5-r6wph have precedence over silver-class-deploy-22-8456bfbbc6-jrczs? false
I0409 14:52:06.419020       1 scheduler.go:103] [HigherPrecedence] Final decision: Does bronze-class-deploy-25-b94944fb5-r6wph have precedence over gold-class-deploy-9-868dfbd94f-6hvv5? false
I0409 14:52:06.419046       1 scheduler.go:103] [HigherPrecedence] Final decision: Does bronze-class-deploy-25-b94944fb5-r6wph have precedence over silver-class-deploy-10-6866d9b887-l2866? false
I0409 14:52:06.419062       1 scheduler.go:103] [HigherPrecedence] Final decision: Does bronze-class-deploy-25-b94944fb5-r6wph have precedence over gold-class-deploy-27-6c45459fb5-m777t? false
I0409 14:52:06.419079       1 scheduler.go:103] [HigherPrecedence] Final decision: Does bronze-class-deploy-25-b94944fb5-r6wph have precedence over gold-class-deploy-12-598494bf8f-jqzbs? false
I0409 14:52:06.419102       1 scheduler.go:103] [HigherPrecedence] Final decision: Does bronze-class-deploy-25-b94944fb5-r6wph have precedence over gold-class-deploy-13-5f585cb744-n2l5p? false
I0409 14:52:06.419118       1 scheduler.go:103] [HigherPrecedence] Final decision: Does bronze-class-deploy-25-b94944fb5-r6wph have precedence over silver-class-deploy-14-79f95c48b7-jh9nd? false
I0409 14:52:06.419141       1 scheduler.go:103] [HigherPrecedence] Final decision: Does bronze-class-deploy-25-b94944fb5-r6wph have precedence over silver-class-deploy-15-cb96c7dc4-9m85g? false
I0409 14:52:06.419163       1 scheduler.go:103] [HigherPrecedence] Final decision: Does bronze-class-deploy-25-b94944fb5-r6wph have precedence over gold-class-deploy-26-6bcb7b6c88-6jh2g? false
I0409 14:52:06.419187       1 scheduler.go:103] [HigherPrecedence] Final decision: Does bronze-class-deploy-25-b94944fb5-r6wph have precedence over silver-class-deploy-17-59cbf4bc88-s2ngm? false
I0409 14:52:06.419210       1 scheduler.go:103] [HigherPrecedence] Final decision: Does bronze-class-deploy-25-b94944fb5-r6wph have precedence over silver-class-deploy-18-5dd44b47c5-7d2lh? false
I0409 14:52:06.419226       1 scheduler.go:103] [HigherPrecedence] Final decision: Does bronze-class-deploy-25-b94944fb5-r6wph have precedence over silver-class-deploy-19-7cc4c5b78-v9p7f? false
I0409 14:52:06.419248       1 scheduler.go:103] [HigherPrecedence] Final decision: Does bronze-class-deploy-25-b94944fb5-r6wph have precedence over silver-class-deploy-32-84b675c847-wwmws? false
I0409 14:52:06.419264       1 scheduler.go:103] [HigherPrecedence] Final decision: Does bronze-class-deploy-25-b94944fb5-r6wph have precedence over bronze-class-deploy-20-5fd9977fb4-hj4vm? false
I0409 14:52:06.419286       1 scheduler.go:103] [HigherPrecedence] Final decision: Does bronze-class-deploy-25-b94944fb5-r6wph have precedence over bronze-class-deploy-24-668b49b99b-ldm7g? false
I0409 14:52:06.419320       1 default_preemption.go:37] "Preemption failed or not needed" pod="default/bronze-class-deploy-25-b94944fb5-r6wph" status="0/2 nodes are available: 1 No preemption victims found for incoming pod, 1 Preemption is not helpful for scheduling."
I0409 14:52:06.426633       1 scheduler.go:103] [HigherPrecedence] Final decision: Does bronze-class-deploy-31-77756c9778-d8hft have precedence over gold-class-deploy-1-78bb76545-pwz55? false
I0409 14:52:06.426640       1 scheduler.go:255] [OnUpdatePod] Updating 'LastStatus' of pod default/bronze-class-deploy-25-b94944fb5-r6wph in metrics
I0409 14:52:06.426689       1 scheduler.go:103] [HigherPrecedence] Final decision: Does bronze-class-deploy-31-77756c9778-d8hft have precedence over gold-class-deploy-2-58ff5bfb68-446gs? false
I0409 14:52:06.426708       1 scheduler.go:103] [HigherPrecedence] Final decision: Does bronze-class-deploy-31-77756c9778-d8hft have precedence over silver-class-deploy-21-7bf557854c-zflrc? false
I0409 14:52:06.426725       1 scheduler.go:103] [HigherPrecedence] Final decision: Does bronze-class-deploy-31-77756c9778-d8hft have precedence over gold-class-deploy-4-b6866bf4b-5dnw5? false
I0409 14:52:06.426748       1 scheduler.go:103] [HigherPrecedence] Final decision: Does bronze-class-deploy-31-77756c9778-d8hft have precedence over gold-class-deploy-5-c4557676f-pdmbf? false
I0409 14:52:06.426764       1 scheduler.go:103] [HigherPrecedence] Final decision: Does bronze-class-deploy-31-77756c9778-d8hft have precedence over gold-class-deploy-6-6df4d4d67b-bf8cr? false
I0409 14:52:06.426787       1 scheduler.go:103] [HigherPrecedence] Final decision: Does bronze-class-deploy-31-77756c9778-d8hft have precedence over silver-class-deploy-7-ff55f69ff-hwmfr? false
I0409 14:52:06.426802       1 scheduler.go:103] [HigherPrecedence] Final decision: Does bronze-class-deploy-31-77756c9778-d8hft have precedence over silver-class-deploy-22-8456bfbbc6-jrczs? false
I0409 14:52:06.426826       1 scheduler.go:103] [HigherPrecedence] Final decision: Does bronze-class-deploy-31-77756c9778-d8hft have precedence over gold-class-deploy-9-868dfbd94f-6hvv5? false
I0409 14:52:06.426846       1 scheduler.go:103] [HigherPrecedence] Final decision: Does bronze-class-deploy-31-77756c9778-d8hft have precedence over silver-class-deploy-10-6866d9b887-l2866? false
I0409 14:52:06.426863       1 scheduler.go:103] [HigherPrecedence] Final decision: Does bronze-class-deploy-31-77756c9778-d8hft have precedence over gold-class-deploy-27-6c45459fb5-m777t? false
I0409 14:52:06.426885       1 scheduler.go:103] [HigherPrecedence] Final decision: Does bronze-class-deploy-31-77756c9778-d8hft have precedence over gold-class-deploy-12-598494bf8f-jqzbs? false
I0409 14:52:06.426906       1 scheduler.go:103] [HigherPrecedence] Final decision: Does bronze-class-deploy-31-77756c9778-d8hft have precedence over gold-class-deploy-13-5f585cb744-n2l5p? false
I0409 14:52:06.426922       1 scheduler.go:103] [HigherPrecedence] Final decision: Does bronze-class-deploy-31-77756c9778-d8hft have precedence over silver-class-deploy-14-79f95c48b7-jh9nd? false
I0409 14:52:06.426946       1 scheduler.go:103] [HigherPrecedence] Final decision: Does bronze-class-deploy-31-77756c9778-d8hft have precedence over silver-class-deploy-15-cb96c7dc4-9m85g? false
I0409 14:52:06.426966       1 scheduler.go:103] [HigherPrecedence] Final decision: Does bronze-class-deploy-31-77756c9778-d8hft have precedence over gold-class-deploy-26-6bcb7b6c88-6jh2g? false
I0409 14:52:06.426994       1 scheduler.go:103] [HigherPrecedence] Final decision: Does bronze-class-deploy-31-77756c9778-d8hft have precedence over silver-class-deploy-17-59cbf4bc88-s2ngm? false
I0409 14:52:06.427016       1 scheduler.go:103] [HigherPrecedence] Final decision: Does bronze-class-deploy-31-77756c9778-d8hft have precedence over silver-class-deploy-18-5dd44b47c5-7d2lh? false
I0409 14:52:06.427034       1 scheduler.go:103] [HigherPrecedence] Final decision: Does bronze-class-deploy-31-77756c9778-d8hft have precedence over silver-class-deploy-19-7cc4c5b78-v9p7f? false
I0409 14:52:06.427055       1 scheduler.go:103] [HigherPrecedence] Final decision: Does bronze-class-deploy-31-77756c9778-d8hft have precedence over silver-class-deploy-32-84b675c847-wwmws? false
I0409 14:52:06.427085       1 scheduler.go:103] [HigherPrecedence] Final decision: Does bronze-class-deploy-31-77756c9778-d8hft have precedence over bronze-class-deploy-20-5fd9977fb4-hj4vm? false
I0409 14:52:06.427117       1 scheduler.go:103] [HigherPrecedence] Final decision: Does bronze-class-deploy-31-77756c9778-d8hft have precedence over bronze-class-deploy-24-668b49b99b-ldm7g? false
I0409 14:52:06.427156       1 default_preemption.go:37] "Preemption failed or not needed" pod="default/bronze-class-deploy-31-77756c9778-d8hft" status="0/2 nodes are available: 1 No preemption victims found for incoming pod, 1 Preemption is not helpful for scheduling."
I0409 14:52:06.433660       1 scheduler.go:255] [OnUpdatePod] Updating 'LastStatus' of pod default/bronze-class-deploy-31-77756c9778-d8hft in metrics
I0409 14:52:06.433950       1 scheduler.go:103] [HigherPrecedence] Final decision: Does bronze-class-deploy-30-56698788c5-dkftl have precedence over gold-class-deploy-1-78bb76545-pwz55? false
I0409 14:52:06.433982       1 scheduler.go:103] [HigherPrecedence] Final decision: Does bronze-class-deploy-30-56698788c5-dkftl have precedence over gold-class-deploy-2-58ff5bfb68-446gs? false
I0409 14:52:06.433999       1 scheduler.go:103] [HigherPrecedence] Final decision: Does bronze-class-deploy-30-56698788c5-dkftl have precedence over silver-class-deploy-21-7bf557854c-zflrc? false
I0409 14:52:06.434016       1 scheduler.go:103] [HigherPrecedence] Final decision: Does bronze-class-deploy-30-56698788c5-dkftl have precedence over gold-class-deploy-4-b6866bf4b-5dnw5? false
I0409 14:52:06.434032       1 scheduler.go:103] [HigherPrecedence] Final decision: Does bronze-class-deploy-30-56698788c5-dkftl have precedence over gold-class-deploy-5-c4557676f-pdmbf? false
I0409 14:52:06.434049       1 scheduler.go:103] [HigherPrecedence] Final decision: Does bronze-class-deploy-30-56698788c5-dkftl have precedence over gold-class-deploy-6-6df4d4d67b-bf8cr? false
I0409 14:52:06.434070       1 scheduler.go:103] [HigherPrecedence] Final decision: Does bronze-class-deploy-30-56698788c5-dkftl have precedence over silver-class-deploy-7-ff55f69ff-hwmfr? false
I0409 14:52:06.434086       1 scheduler.go:103] [HigherPrecedence] Final decision: Does bronze-class-deploy-30-56698788c5-dkftl have precedence over silver-class-deploy-22-8456bfbbc6-jrczs? false
I0409 14:52:06.434114       1 scheduler.go:103] [HigherPrecedence] Final decision: Does bronze-class-deploy-30-56698788c5-dkftl have precedence over gold-class-deploy-9-868dfbd94f-6hvv5? false
I0409 14:52:06.434137       1 scheduler.go:103] [HigherPrecedence] Final decision: Does bronze-class-deploy-30-56698788c5-dkftl have precedence over silver-class-deploy-10-6866d9b887-l2866? false
I0409 14:52:06.434171       1 scheduler.go:103] [HigherPrecedence] Final decision: Does bronze-class-deploy-30-56698788c5-dkftl have precedence over gold-class-deploy-27-6c45459fb5-m777t? false
I0409 14:52:06.434192       1 scheduler.go:103] [HigherPrecedence] Final decision: Does bronze-class-deploy-30-56698788c5-dkftl have precedence over gold-class-deploy-12-598494bf8f-jqzbs? false
I0409 14:52:06.434214       1 scheduler.go:103] [HigherPrecedence] Final decision: Does bronze-class-deploy-30-56698788c5-dkftl have precedence over gold-class-deploy-13-5f585cb744-n2l5p? false
I0409 14:52:06.434247       1 scheduler.go:103] [HigherPrecedence] Final decision: Does bronze-class-deploy-30-56698788c5-dkftl have precedence over silver-class-deploy-14-79f95c48b7-jh9nd? false
I0409 14:52:06.434279       1 scheduler.go:103] [HigherPrecedence] Final decision: Does bronze-class-deploy-30-56698788c5-dkftl have precedence over silver-class-deploy-15-cb96c7dc4-9m85g? false
I0409 14:52:06.434299       1 scheduler.go:103] [HigherPrecedence] Final decision: Does bronze-class-deploy-30-56698788c5-dkftl have precedence over gold-class-deploy-26-6bcb7b6c88-6jh2g? false
I0409 14:52:06.434328       1 scheduler.go:103] [HigherPrecedence] Final decision: Does bronze-class-deploy-30-56698788c5-dkftl have precedence over silver-class-deploy-17-59cbf4bc88-s2ngm? false
I0409 14:52:06.434352       1 scheduler.go:103] [HigherPrecedence] Final decision: Does bronze-class-deploy-30-56698788c5-dkftl have precedence over silver-class-deploy-18-5dd44b47c5-7d2lh? false
I0409 14:52:06.434405       1 scheduler.go:103] [HigherPrecedence] Final decision: Does bronze-class-deploy-30-56698788c5-dkftl have precedence over silver-class-deploy-19-7cc4c5b78-v9p7f? false
I0409 14:52:06.434430       1 scheduler.go:103] [HigherPrecedence] Final decision: Does bronze-class-deploy-30-56698788c5-dkftl have precedence over silver-class-deploy-32-84b675c847-wwmws? false
I0409 14:52:06.434447       1 scheduler.go:103] [HigherPrecedence] Final decision: Does bronze-class-deploy-30-56698788c5-dkftl have precedence over bronze-class-deploy-20-5fd9977fb4-hj4vm? false
I0409 14:52:06.434473       1 scheduler.go:103] [HigherPrecedence] Final decision: Does bronze-class-deploy-30-56698788c5-dkftl have precedence over bronze-class-deploy-24-668b49b99b-ldm7g? false
I0409 14:52:06.434516       1 default_preemption.go:37] "Preemption failed or not needed" pod="default/bronze-class-deploy-30-56698788c5-dkftl" status="0/2 nodes are available: 1 No preemption victims found for incoming pod, 1 Preemption is not helpful for scheduling."
I0409 14:52:06.441504       1 scheduler.go:255] [OnUpdatePod] Updating 'LastStatus' of pod default/bronze-class-deploy-30-56698788c5-dkftl in metrics
I0409 14:52:07.300760       1 default_preemption.go:51] [PreEnqueue] PreEnqueue called for pod: bronze-class-deploy-23-654ffb5cc5-btltf
I0409 14:52:07.300785       1 default_preemption.go:52] [PreEnqueue] SchedulerName for pod bronze-class-deploy-23-654ffb5cc5-btltf: custom-scheduler
I0409 14:52:07.301164       1 scheduler.go:164] [PreBind] Validating pod bronze-class-deploy-23-654ffb5cc5-btltf before binding to node kwok-node-1
I0409 14:52:07.306811       1 scheduler.go:255] [OnUpdatePod] Updating 'LastStatus' of pod default/bronze-class-deploy-23-654ffb5cc5-btltf in metrics
I0409 14:52:07.307039       1 scheduler.go:172] [PostBind] Called for pod bronze-class-deploy-23-654ffb5cc5-btltf
I0409 14:52:07.307056       1 scheduler.go:190] [PostBind] Pod bronze-class-deploy-23-654ffb5cc5-btltf - Binding start: 2025-04-09 14:52:07.30117889 +0000 UTC m=+211.988549328, Binding end: 2025-04-09 14:52:07.307053127 +0000 UTC m=+211.994423565
I0409 14:52:07.307073       1 scheduler.go:197] [PostBind] Metrics updated for pod bronze-class-deploy-23-654ffb5cc5-btltf
I0409 14:52:07.315021       1 scheduler.go:255] [OnUpdatePod] Updating 'LastStatus' of pod default/bronze-class-deploy-23-654ffb5cc5-btltf in metrics
I0409 14:52:10.302211       1 default_preemption.go:51] [PreEnqueue] PreEnqueue called for pod: bronze-class-deploy-29-7d6b766b6f-q5ptz
I0409 14:52:10.302240       1 default_preemption.go:52] [PreEnqueue] SchedulerName for pod bronze-class-deploy-29-7d6b766b6f-q5ptz: custom-scheduler
I0409 14:52:10.302874       1 scheduler.go:103] [HigherPrecedence] Final decision: Does bronze-class-deploy-29-7d6b766b6f-q5ptz have precedence over bronze-class-deploy-20-5fd9977fb4-hj4vm? true
I0409 14:52:10.302918       1 scheduler.go:103] [HigherPrecedence] Final decision: Does bronze-class-deploy-29-7d6b766b6f-q5ptz have precedence over bronze-class-deploy-24-668b49b99b-ldm7g? true
I0409 14:52:10.302958       1 scheduler.go:103] [HigherPrecedence] Final decision: Does bronze-class-deploy-29-7d6b766b6f-q5ptz have precedence over bronze-class-deploy-23-654ffb5cc5-btltf? true
I0409 14:52:10.309921       1 scheduler.go:255] [OnUpdatePod] Updating 'LastStatus' of pod default/bronze-class-deploy-24-668b49b99b-ldm7g in metrics
I0409 14:52:10.315531       1 scheduler.go:255] [OnUpdatePod] Updating 'LastStatus' of pod default/bronze-class-deploy-24-668b49b99b-ldm7g in metrics
I0409 14:52:10.319130       1 default_preemption.go:51] [PreEnqueue] PreEnqueue called for pod: bronze-class-deploy-25-b94944fb5-r6wph
I0409 14:52:10.319153       1 default_preemption.go:52] [PreEnqueue] SchedulerName for pod bronze-class-deploy-25-b94944fb5-r6wph: custom-scheduler
I0409 14:52:10.319192       1 default_preemption.go:51] [PreEnqueue] PreEnqueue called for pod: bronze-class-deploy-31-77756c9778-d8hft
I0409 14:52:10.319197       1 default_preemption.go:52] [PreEnqueue] SchedulerName for pod bronze-class-deploy-31-77756c9778-d8hft: custom-scheduler
I0409 14:52:10.319231       1 scheduler.go:103] [HigherPrecedence] Final decision: Does bronze-class-deploy-31-77756c9778-d8hft have precedence over bronze-class-deploy-25-b94944fb5-r6wph? false
I0409 14:52:10.319261       1 default_preemption.go:51] [PreEnqueue] PreEnqueue called for pod: bronze-class-deploy-30-56698788c5-dkftl
I0409 14:52:10.319265       1 default_preemption.go:52] [PreEnqueue] SchedulerName for pod bronze-class-deploy-30-56698788c5-dkftl: custom-scheduler
I0409 14:52:10.319295       1 scheduler.go:103] [HigherPrecedence] Final decision: Does bronze-class-deploy-30-56698788c5-dkftl have precedence over bronze-class-deploy-25-b94944fb5-r6wph? false
I0409 14:52:10.319326       1 scheduler.go:286] [OnDeletePod] Checking the state of pod default/bronze-class-deploy-24-668b49b99b-ldm7g in metrics
I0409 14:52:10.319421       1 scheduler.go:103] [HigherPrecedence] Final decision: Does bronze-class-deploy-29-7d6b766b6f-q5ptz have precedence over bronze-class-deploy-28-946b5bff6-774x4? false
I0409 14:52:10.319462       1 scheduler.go:103] [HigherPrecedence] Final decision: Does bronze-class-deploy-29-7d6b766b6f-q5ptz have precedence over bronze-class-deploy-16-74dd4696ff-mkf54? true
I0409 14:52:10.320303       1 default_preemption.go:51] [PreEnqueue] PreEnqueue called for pod: bronze-class-deploy-24-668b49b99b-wcmrw
I0409 14:52:10.320319       1 default_preemption.go:52] [PreEnqueue] SchedulerName for pod bronze-class-deploy-24-668b49b99b-wcmrw: custom-scheduler
I0409 14:52:10.320338       1 scheduler.go:205] [OnAddPod] Pod added: default/bronze-class-deploy-24-668b49b99b-wcmrw, Annotations: map[acceptablePreemptionOverhead:0.05 controller:bronze-controller-24 kwok.x-k8s.io/usage-cpu:1m kwok.x-k8s.io/usage-memory:1Mi qosMeasuring:average slo:0.5]
W0409 14:52:10.320353       1 scheduler.go:118] [cacheMiss] Metrics not found for pod: default/bronze-class-deploy-24-668b49b99b-wcmrw
W0409 14:52:10.320390       1 scheduler.go:125] [WaitForPodsOnCache] Pod bronze-class-deploy-24-668b49b99b-wcmrw not found in cache. Retrying...
I0409 14:52:10.327780       1 scheduler.go:255] [OnUpdatePod] Updating 'LastStatus' of pod default/bronze-class-deploy-16-74dd4696ff-mkf54 in metrics
I0409 14:52:10.327820       1 default_preemption.go:39] "Preemption successful" pod="default/bronze-class-deploy-29-7d6b766b6f-q5ptz" nominatedNode="kwok-node-1"
I0409 14:52:10.420748       1 scheduler.go:103] [HigherPrecedence] Final decision: Does bronze-class-deploy-24-668b49b99b-wcmrw have precedence over bronze-class-deploy-31-77756c9778-d8hft? true
I0409 14:52:10.420795       1 scheduler.go:103] [HigherPrecedence] Final decision: Does bronze-class-deploy-24-668b49b99b-wcmrw have precedence over bronze-class-deploy-25-b94944fb5-r6wph? true
I0409 14:52:10.427541       1 scheduler.go:255] [OnUpdatePod] Updating 'LastStatus' of pod default/bronze-class-deploy-29-7d6b766b6f-q5ptz in metrics
I0409 14:52:10.427616       1 scheduler.go:103] [HigherPrecedence] Final decision: Does bronze-class-deploy-30-56698788c5-dkftl have precedence over bronze-class-deploy-25-b94944fb5-r6wph? false
I0409 14:52:10.427643       1 scheduler.go:103] [HigherPrecedence] Final decision: Does bronze-class-deploy-25-b94944fb5-r6wph have precedence over bronze-class-deploy-31-77756c9778-d8hft? true
I0409 14:52:10.427949       1 scheduler.go:103] [HigherPrecedence] Final decision: Does bronze-class-deploy-31-77756c9778-d8hft have precedence over bronze-class-deploy-30-56698788c5-dkftl? true
I0409 14:52:10.428034       1 scheduler.go:164] [PreBind] Validating pod bronze-class-deploy-24-668b49b99b-wcmrw before binding to node kwok-node-1
I0409 14:52:10.428145       1 scheduler.go:103] [HigherPrecedence] Final decision: Does bronze-class-deploy-25-b94944fb5-r6wph have precedence over gold-class-deploy-1-78bb76545-pwz55? false
I0409 14:52:10.428178       1 scheduler.go:103] [HigherPrecedence] Final decision: Does bronze-class-deploy-25-b94944fb5-r6wph have precedence over gold-class-deploy-2-58ff5bfb68-446gs? false
I0409 14:52:10.428200       1 scheduler.go:103] [HigherPrecedence] Final decision: Does bronze-class-deploy-25-b94944fb5-r6wph have precedence over silver-class-deploy-21-7bf557854c-zflrc? false
I0409 14:52:10.428220       1 scheduler.go:103] [HigherPrecedence] Final decision: Does bronze-class-deploy-25-b94944fb5-r6wph have precedence over gold-class-deploy-4-b6866bf4b-5dnw5? false
I0409 14:52:10.428252       1 scheduler.go:103] [HigherPrecedence] Final decision: Does bronze-class-deploy-25-b94944fb5-r6wph have precedence over gold-class-deploy-5-c4557676f-pdmbf? false
I0409 14:52:10.428284       1 scheduler.go:103] [HigherPrecedence] Final decision: Does bronze-class-deploy-25-b94944fb5-r6wph have precedence over gold-class-deploy-6-6df4d4d67b-bf8cr? false
I0409 14:52:10.428314       1 scheduler.go:103] [HigherPrecedence] Final decision: Does bronze-class-deploy-25-b94944fb5-r6wph have precedence over silver-class-deploy-7-ff55f69ff-hwmfr? false
I0409 14:52:10.428332       1 scheduler.go:103] [HigherPrecedence] Final decision: Does bronze-class-deploy-25-b94944fb5-r6wph have precedence over silver-class-deploy-22-8456bfbbc6-jrczs? false
I0409 14:52:10.428348       1 scheduler.go:103] [HigherPrecedence] Final decision: Does bronze-class-deploy-25-b94944fb5-r6wph have precedence over gold-class-deploy-9-868dfbd94f-6hvv5? false
I0409 14:52:10.428395       1 scheduler.go:103] [HigherPrecedence] Final decision: Does bronze-class-deploy-25-b94944fb5-r6wph have precedence over silver-class-deploy-10-6866d9b887-l2866? false
I0409 14:52:10.428430       1 scheduler.go:103] [HigherPrecedence] Final decision: Does bronze-class-deploy-25-b94944fb5-r6wph have precedence over gold-class-deploy-27-6c45459fb5-m777t? false
I0409 14:52:10.428450       1 scheduler.go:103] [HigherPrecedence] Final decision: Does bronze-class-deploy-25-b94944fb5-r6wph have precedence over gold-class-deploy-12-598494bf8f-jqzbs? false
I0409 14:52:10.428480       1 scheduler.go:103] [HigherPrecedence] Final decision: Does bronze-class-deploy-25-b94944fb5-r6wph have precedence over gold-class-deploy-13-5f585cb744-n2l5p? false
I0409 14:52:10.428497       1 scheduler.go:103] [HigherPrecedence] Final decision: Does bronze-class-deploy-25-b94944fb5-r6wph have precedence over silver-class-deploy-14-79f95c48b7-jh9nd? false
I0409 14:52:10.428515       1 scheduler.go:103] [HigherPrecedence] Final decision: Does bronze-class-deploy-25-b94944fb5-r6wph have precedence over silver-class-deploy-15-cb96c7dc4-9m85g? false
I0409 14:52:10.428546       1 scheduler.go:103] [HigherPrecedence] Final decision: Does bronze-class-deploy-25-b94944fb5-r6wph have precedence over gold-class-deploy-26-6bcb7b6c88-6jh2g? false
I0409 14:52:10.428577       1 scheduler.go:103] [HigherPrecedence] Final decision: Does bronze-class-deploy-25-b94944fb5-r6wph have precedence over silver-class-deploy-17-59cbf4bc88-s2ngm? false
I0409 14:52:10.428599       1 scheduler.go:103] [HigherPrecedence] Final decision: Does bronze-class-deploy-25-b94944fb5-r6wph have precedence over silver-class-deploy-18-5dd44b47c5-7d2lh? false
I0409 14:52:10.428631       1 scheduler.go:103] [HigherPrecedence] Final decision: Does bronze-class-deploy-25-b94944fb5-r6wph have precedence over silver-class-deploy-19-7cc4c5b78-v9p7f? false
I0409 14:52:10.428653       1 scheduler.go:103] [HigherPrecedence] Final decision: Does bronze-class-deploy-25-b94944fb5-r6wph have precedence over silver-class-deploy-32-84b675c847-wwmws? false
I0409 14:52:10.428678       1 scheduler.go:103] [HigherPrecedence] Final decision: Does bronze-class-deploy-25-b94944fb5-r6wph have precedence over bronze-class-deploy-20-5fd9977fb4-hj4vm? false
I0409 14:52:10.428696       1 scheduler.go:103] [HigherPrecedence] Final decision: Does bronze-class-deploy-25-b94944fb5-r6wph have precedence over bronze-class-deploy-23-654ffb5cc5-btltf? false
I0409 14:52:10.428724       1 scheduler.go:103] [HigherPrecedence] Final decision: Does bronze-class-deploy-25-b94944fb5-r6wph have precedence over bronze-class-deploy-24-668b49b99b-wcmrw? false
I0409 14:52:10.428762       1 default_preemption.go:37] "Preemption failed or not needed" pod="default/bronze-class-deploy-25-b94944fb5-r6wph" status="0/2 nodes are available: 1 No preemption victims found for incoming pod, 1 Preemption is not helpful for scheduling."
I0409 14:52:10.428976       1 scheduler.go:103] [HigherPrecedence] Final decision: Does bronze-class-deploy-31-77756c9778-d8hft have precedence over gold-class-deploy-1-78bb76545-pwz55? false
I0409 14:52:10.429004       1 scheduler.go:103] [HigherPrecedence] Final decision: Does bronze-class-deploy-31-77756c9778-d8hft have precedence over gold-class-deploy-2-58ff5bfb68-446gs? false
I0409 14:52:10.429021       1 scheduler.go:103] [HigherPrecedence] Final decision: Does bronze-class-deploy-31-77756c9778-d8hft have precedence over silver-class-deploy-21-7bf557854c-zflrc? false
I0409 14:52:10.429037       1 scheduler.go:103] [HigherPrecedence] Final decision: Does bronze-class-deploy-31-77756c9778-d8hft have precedence over gold-class-deploy-4-b6866bf4b-5dnw5? false
I0409 14:52:10.429067       1 scheduler.go:103] [HigherPrecedence] Final decision: Does bronze-class-deploy-31-77756c9778-d8hft have precedence over gold-class-deploy-5-c4557676f-pdmbf? false
I0409 14:52:10.429097       1 scheduler.go:103] [HigherPrecedence] Final decision: Does bronze-class-deploy-31-77756c9778-d8hft have precedence over gold-class-deploy-6-6df4d4d67b-bf8cr? false
I0409 14:52:10.429128       1 scheduler.go:103] [HigherPrecedence] Final decision: Does bronze-class-deploy-31-77756c9778-d8hft have precedence over silver-class-deploy-7-ff55f69ff-hwmfr? false
I0409 14:52:10.429144       1 scheduler.go:103] [HigherPrecedence] Final decision: Does bronze-class-deploy-31-77756c9778-d8hft have precedence over silver-class-deploy-22-8456bfbbc6-jrczs? false
I0409 14:52:10.429172       1 scheduler.go:103] [HigherPrecedence] Final decision: Does bronze-class-deploy-31-77756c9778-d8hft have precedence over gold-class-deploy-9-868dfbd94f-6hvv5? false
I0409 14:52:10.429200       1 scheduler.go:103] [HigherPrecedence] Final decision: Does bronze-class-deploy-31-77756c9778-d8hft have precedence over silver-class-deploy-10-6866d9b887-l2866? false
I0409 14:52:10.429226       1 scheduler.go:103] [HigherPrecedence] Final decision: Does bronze-class-deploy-31-77756c9778-d8hft have precedence over gold-class-deploy-27-6c45459fb5-m777t? false
I0409 14:52:10.429244       1 scheduler.go:103] [HigherPrecedence] Final decision: Does bronze-class-deploy-31-77756c9778-d8hft have precedence over gold-class-deploy-12-598494bf8f-jqzbs? false
I0409 14:52:10.429273       1 scheduler.go:103] [HigherPrecedence] Final decision: Does bronze-class-deploy-31-77756c9778-d8hft have precedence over gold-class-deploy-13-5f585cb744-n2l5p? false
I0409 14:52:10.429302       1 scheduler.go:103] [HigherPrecedence] Final decision: Does bronze-class-deploy-31-77756c9778-d8hft have precedence over silver-class-deploy-14-79f95c48b7-jh9nd? false
I0409 14:52:10.429318       1 scheduler.go:103] [HigherPrecedence] Final decision: Does bronze-class-deploy-31-77756c9778-d8hft have precedence over silver-class-deploy-15-cb96c7dc4-9m85g? false
I0409 14:52:10.429337       1 scheduler.go:103] [HigherPrecedence] Final decision: Does bronze-class-deploy-31-77756c9778-d8hft have precedence over gold-class-deploy-26-6bcb7b6c88-6jh2g? false
I0409 14:52:10.429379       1 scheduler.go:103] [HigherPrecedence] Final decision: Does bronze-class-deploy-31-77756c9778-d8hft have precedence over silver-class-deploy-17-59cbf4bc88-s2ngm? false
I0409 14:52:10.429412       1 scheduler.go:103] [HigherPrecedence] Final decision: Does bronze-class-deploy-31-77756c9778-d8hft have precedence over silver-class-deploy-18-5dd44b47c5-7d2lh? false
I0409 14:52:10.429429       1 scheduler.go:103] [HigherPrecedence] Final decision: Does bronze-class-deploy-31-77756c9778-d8hft have precedence over silver-class-deploy-19-7cc4c5b78-v9p7f? false
I0409 14:52:10.429446       1 scheduler.go:103] [HigherPrecedence] Final decision: Does bronze-class-deploy-31-77756c9778-d8hft have precedence over silver-class-deploy-32-84b675c847-wwmws? false
I0409 14:52:10.429466       1 scheduler.go:103] [HigherPrecedence] Final decision: Does bronze-class-deploy-31-77756c9778-d8hft have precedence over bronze-class-deploy-20-5fd9977fb4-hj4vm? false
I0409 14:52:10.429484       1 scheduler.go:103] [HigherPrecedence] Final decision: Does bronze-class-deploy-31-77756c9778-d8hft have precedence over bronze-class-deploy-23-654ffb5cc5-btltf? false
I0409 14:52:10.429502       1 scheduler.go:103] [HigherPrecedence] Final decision: Does bronze-class-deploy-31-77756c9778-d8hft have precedence over bronze-class-deploy-24-668b49b99b-wcmrw? false
I0409 14:52:10.429540       1 default_preemption.go:37] "Preemption failed or not needed" pod="default/bronze-class-deploy-31-77756c9778-d8hft" status="0/2 nodes are available: 1 No preemption victims found for incoming pod, 1 Preemption is not helpful for scheduling."
I0409 14:52:10.429821       1 scheduler.go:103] [HigherPrecedence] Final decision: Does bronze-class-deploy-30-56698788c5-dkftl have precedence over gold-class-deploy-1-78bb76545-pwz55? false
I0409 14:52:10.429860       1 scheduler.go:103] [HigherPrecedence] Final decision: Does bronze-class-deploy-30-56698788c5-dkftl have precedence over gold-class-deploy-2-58ff5bfb68-446gs? false
I0409 14:52:10.429882       1 scheduler.go:103] [HigherPrecedence] Final decision: Does bronze-class-deploy-30-56698788c5-dkftl have precedence over silver-class-deploy-21-7bf557854c-zflrc? false
I0409 14:52:10.429903       1 scheduler.go:103] [HigherPrecedence] Final decision: Does bronze-class-deploy-30-56698788c5-dkftl have precedence over gold-class-deploy-4-b6866bf4b-5dnw5? false
I0409 14:52:10.429928       1 scheduler.go:103] [HigherPrecedence] Final decision: Does bronze-class-deploy-30-56698788c5-dkftl have precedence over gold-class-deploy-5-c4557676f-pdmbf? false
I0409 14:52:10.429944       1 scheduler.go:103] [HigherPrecedence] Final decision: Does bronze-class-deploy-30-56698788c5-dkftl have precedence over gold-class-deploy-6-6df4d4d67b-bf8cr? false
I0409 14:52:10.429974       1 scheduler.go:103] [HigherPrecedence] Final decision: Does bronze-class-deploy-30-56698788c5-dkftl have precedence over silver-class-deploy-7-ff55f69ff-hwmfr? false
I0409 14:52:10.429996       1 scheduler.go:103] [HigherPrecedence] Final decision: Does bronze-class-deploy-30-56698788c5-dkftl have precedence over silver-class-deploy-22-8456bfbbc6-jrczs? false
I0409 14:52:10.430024       1 scheduler.go:103] [HigherPrecedence] Final decision: Does bronze-class-deploy-30-56698788c5-dkftl have precedence over gold-class-deploy-9-868dfbd94f-6hvv5? false
I0409 14:52:10.430041       1 scheduler.go:103] [HigherPrecedence] Final decision: Does bronze-class-deploy-30-56698788c5-dkftl have precedence over silver-class-deploy-10-6866d9b887-l2866? false
I0409 14:52:10.430063       1 scheduler.go:103] [HigherPrecedence] Final decision: Does bronze-class-deploy-30-56698788c5-dkftl have precedence over gold-class-deploy-27-6c45459fb5-m777t? false
I0409 14:52:10.430091       1 scheduler.go:103] [HigherPrecedence] Final decision: Does bronze-class-deploy-30-56698788c5-dkftl have precedence over gold-class-deploy-12-598494bf8f-jqzbs? false
I0409 14:52:10.430107       1 scheduler.go:103] [HigherPrecedence] Final decision: Does bronze-class-deploy-30-56698788c5-dkftl have precedence over gold-class-deploy-13-5f585cb744-n2l5p? false
I0409 14:52:10.430126       1 scheduler.go:103] [HigherPrecedence] Final decision: Does bronze-class-deploy-30-56698788c5-dkftl have precedence over silver-class-deploy-14-79f95c48b7-jh9nd? false
I0409 14:52:10.430161       1 scheduler.go:103] [HigherPrecedence] Final decision: Does bronze-class-deploy-30-56698788c5-dkftl have precedence over silver-class-deploy-15-cb96c7dc4-9m85g? false
I0409 14:52:10.430179       1 scheduler.go:103] [HigherPrecedence] Final decision: Does bronze-class-deploy-30-56698788c5-dkftl have precedence over gold-class-deploy-26-6bcb7b6c88-6jh2g? false
I0409 14:52:10.430207       1 scheduler.go:103] [HigherPrecedence] Final decision: Does bronze-class-deploy-30-56698788c5-dkftl have precedence over silver-class-deploy-17-59cbf4bc88-s2ngm? false
I0409 14:52:10.430230       1 scheduler.go:103] [HigherPrecedence] Final decision: Does bronze-class-deploy-30-56698788c5-dkftl have precedence over silver-class-deploy-18-5dd44b47c5-7d2lh? false
I0409 14:52:10.430264       1 scheduler.go:103] [HigherPrecedence] Final decision: Does bronze-class-deploy-30-56698788c5-dkftl have precedence over silver-class-deploy-19-7cc4c5b78-v9p7f? false
I0409 14:52:10.430296       1 scheduler.go:103] [HigherPrecedence] Final decision: Does bronze-class-deploy-30-56698788c5-dkftl have precedence over silver-class-deploy-32-84b675c847-wwmws? false
I0409 14:52:10.430318       1 scheduler.go:103] [HigherPrecedence] Final decision: Does bronze-class-deploy-30-56698788c5-dkftl have precedence over bronze-class-deploy-20-5fd9977fb4-hj4vm? false
I0409 14:52:10.430387       1 scheduler.go:103] [HigherPrecedence] Final decision: Does bronze-class-deploy-30-56698788c5-dkftl have precedence over bronze-class-deploy-23-654ffb5cc5-btltf? false
I0409 14:52:10.430428       1 scheduler.go:103] [HigherPrecedence] Final decision: Does bronze-class-deploy-30-56698788c5-dkftl have precedence over bronze-class-deploy-24-668b49b99b-wcmrw? false
I0409 14:52:10.430468       1 default_preemption.go:37] "Preemption failed or not needed" pod="default/bronze-class-deploy-30-56698788c5-dkftl" status="0/2 nodes are available: 1 No preemption victims found for incoming pod, 1 Preemption is not helpful for scheduling."
I0409 14:52:10.431502       1 scheduler.go:172] [PostBind] Called for pod bronze-class-deploy-24-668b49b99b-wcmrw
I0409 14:52:10.431527       1 scheduler.go:190] [PostBind] Pod bronze-class-deploy-24-668b49b99b-wcmrw - Binding start: 2025-04-09 14:52:10.428052746 +0000 UTC m=+215.115423174, Binding end: 2025-04-09 14:52:10.431524161 +0000 UTC m=+215.118894599
I0409 14:52:10.431508       1 scheduler.go:255] [OnUpdatePod] Updating 'LastStatus' of pod default/bronze-class-deploy-24-668b49b99b-wcmrw in metrics
I0409 14:52:10.431558       1 scheduler.go:197] [PostBind] Metrics updated for pod bronze-class-deploy-24-668b49b99b-wcmrw
I0409 14:52:10.438548       1 scheduler.go:255] [OnUpdatePod] Updating 'LastStatus' of pod default/bronze-class-deploy-24-668b49b99b-wcmrw in metrics
I0409 14:52:14.303563       1 default_preemption.go:51] [PreEnqueue] PreEnqueue called for pod: bronze-class-deploy-28-946b5bff6-774x4
I0409 14:52:14.303590       1 default_preemption.go:52] [PreEnqueue] SchedulerName for pod bronze-class-deploy-28-946b5bff6-774x4: custom-scheduler
I0409 14:52:14.303910       1 scheduler.go:164] [PreBind] Validating pod bronze-class-deploy-28-946b5bff6-774x4 before binding to node kwok-node-1
I0409 14:52:14.307204       1 scheduler.go:172] [PostBind] Called for pod bronze-class-deploy-28-946b5bff6-774x4
I0409 14:52:14.307234       1 scheduler.go:190] [PostBind] Pod bronze-class-deploy-28-946b5bff6-774x4 - Binding start: 2025-04-09 14:52:14.30392687 +0000 UTC m=+218.991297308, Binding end: 2025-04-09 14:52:14.307229826 +0000 UTC m=+218.994600254
I0409 14:52:14.307258       1 scheduler.go:197] [PostBind] Metrics updated for pod bronze-class-deploy-28-946b5bff6-774x4
I0409 14:52:14.307339       1 scheduler.go:255] [OnUpdatePod] Updating 'LastStatus' of pod default/bronze-class-deploy-28-946b5bff6-774x4 in metrics
I0409 14:52:14.315508       1 scheduler.go:255] [OnUpdatePod] Updating 'LastStatus' of pod default/bronze-class-deploy-28-946b5bff6-774x4 in metrics
I0409 14:52:17.304796       1 default_preemption.go:51] [PreEnqueue] PreEnqueue called for pod: bronze-class-deploy-16-74dd4696ff-mkf54
I0409 14:52:17.304823       1 default_preemption.go:52] [PreEnqueue] SchedulerName for pod bronze-class-deploy-16-74dd4696ff-mkf54: custom-scheduler
I0409 14:52:17.304865       1 default_preemption.go:51] [PreEnqueue] PreEnqueue called for pod: bronze-class-deploy-11-559c656b44-5grsk
I0409 14:52:17.304869       1 default_preemption.go:52] [PreEnqueue] SchedulerName for pod bronze-class-deploy-11-559c656b44-5grsk: custom-scheduler
I0409 14:52:17.304898       1 scheduler.go:103] [HigherPrecedence] Final decision: Does bronze-class-deploy-11-559c656b44-5grsk have precedence over bronze-class-deploy-16-74dd4696ff-mkf54? false
I0409 14:52:17.304919       1 default_preemption.go:51] [PreEnqueue] PreEnqueue called for pod: bronze-class-deploy-8-6fff566748-tt726
I0409 14:52:17.304923       1 default_preemption.go:52] [PreEnqueue] SchedulerName for pod bronze-class-deploy-8-6fff566748-tt726: custom-scheduler
I0409 14:52:17.304944       1 scheduler.go:103] [HigherPrecedence] Final decision: Does bronze-class-deploy-8-6fff566748-tt726 have precedence over bronze-class-deploy-16-74dd4696ff-mkf54? false
I0409 14:52:17.304959       1 default_preemption.go:51] [PreEnqueue] PreEnqueue called for pod: bronze-class-deploy-3-775f4fbdd9-h8pjj
I0409 14:52:17.304962       1 default_preemption.go:52] [PreEnqueue] SchedulerName for pod bronze-class-deploy-3-775f4fbdd9-h8pjj: custom-scheduler
I0409 14:52:17.304983       1 scheduler.go:103] [HigherPrecedence] Final decision: Does bronze-class-deploy-3-775f4fbdd9-h8pjj have precedence over bronze-class-deploy-11-559c656b44-5grsk? false
I0409 14:52:17.305026       1 scheduler.go:103] [HigherPrecedence] Final decision: Does bronze-class-deploy-8-6fff566748-tt726 have precedence over bronze-class-deploy-11-559c656b44-5grsk? false
I0409 14:52:17.305040       1 scheduler.go:103] [HigherPrecedence] Final decision: Does bronze-class-deploy-11-559c656b44-5grsk have precedence over bronze-class-deploy-3-775f4fbdd9-h8pjj? true
I0409 14:52:17.305663       1 scheduler.go:103] [HigherPrecedence] Final decision: Does bronze-class-deploy-16-74dd4696ff-mkf54 have precedence over bronze-class-deploy-20-5fd9977fb4-hj4vm? true
I0409 14:52:17.305705       1 scheduler.go:103] [HigherPrecedence] Final decision: Does bronze-class-deploy-16-74dd4696ff-mkf54 have precedence over bronze-class-deploy-23-654ffb5cc5-btltf? true
I0409 14:52:17.305735       1 scheduler.go:103] [HigherPrecedence] Final decision: Does bronze-class-deploy-16-74dd4696ff-mkf54 have precedence over bronze-class-deploy-24-668b49b99b-wcmrw? true
I0409 14:52:17.305761       1 scheduler.go:103] [HigherPrecedence] Final decision: Does bronze-class-deploy-16-74dd4696ff-mkf54 have precedence over bronze-class-deploy-28-946b5bff6-774x4? true
I0409 14:52:17.305818       1 default_preemption.go:37] "Preemption failed or not needed" pod="default/bronze-class-deploy-16-74dd4696ff-mkf54" status="0/2 nodes are available: 1 No preemption victims found for incoming pod, 1 Preemption is not helpful for scheduling."
I0409 14:52:17.313067       1 scheduler.go:255] [OnUpdatePod] Updating 'LastStatus' of pod default/bronze-class-deploy-16-74dd4696ff-mkf54 in metrics
I0409 14:52:17.313158       1 scheduler.go:103] [HigherPrecedence] Final decision: Does bronze-class-deploy-3-775f4fbdd9-h8pjj have precedence over bronze-class-deploy-8-6fff566748-tt726? false
I0409 14:52:17.313777       1 scheduler.go:103] [HigherPrecedence] Final decision: Does bronze-class-deploy-11-559c656b44-5grsk have precedence over bronze-class-deploy-20-5fd9977fb4-hj4vm? true
I0409 14:52:17.313823       1 scheduler.go:103] [HigherPrecedence] Final decision: Does bronze-class-deploy-11-559c656b44-5grsk have precedence over bronze-class-deploy-23-654ffb5cc5-btltf? true
I0409 14:52:17.313846       1 scheduler.go:103] [HigherPrecedence] Final decision: Does bronze-class-deploy-11-559c656b44-5grsk have precedence over bronze-class-deploy-24-668b49b99b-wcmrw? true
I0409 14:52:17.313874       1 scheduler.go:103] [HigherPrecedence] Final decision: Does bronze-class-deploy-11-559c656b44-5grsk have precedence over bronze-class-deploy-28-946b5bff6-774x4? true
I0409 14:52:17.313926       1 default_preemption.go:37] "Preemption failed or not needed" pod="default/bronze-class-deploy-11-559c656b44-5grsk" status="0/2 nodes are available: 1 No preemption victims found for incoming pod, 1 Preemption is not helpful for scheduling."
I0409 14:52:17.314421       1 scheduler.go:103] [HigherPrecedence] Final decision: Does bronze-class-deploy-8-6fff566748-tt726 have precedence over bronze-class-deploy-20-5fd9977fb4-hj4vm? true
I0409 14:52:17.314463       1 scheduler.go:103] [HigherPrecedence] Final decision: Does bronze-class-deploy-8-6fff566748-tt726 have precedence over bronze-class-deploy-23-654ffb5cc5-btltf? true
I0409 14:52:17.314490       1 scheduler.go:103] [HigherPrecedence] Final decision: Does bronze-class-deploy-8-6fff566748-tt726 have precedence over bronze-class-deploy-24-668b49b99b-wcmrw? true
I0409 14:52:17.314532       1 scheduler.go:103] [HigherPrecedence] Final decision: Does bronze-class-deploy-8-6fff566748-tt726 have precedence over bronze-class-deploy-28-946b5bff6-774x4? false
I0409 14:52:17.314573       1 default_preemption.go:37] "Preemption failed or not needed" pod="default/bronze-class-deploy-8-6fff566748-tt726" status="0/2 nodes are available: 1 No preemption victims found for incoming pod, 1 Preemption is not helpful for scheduling."
I0409 14:52:17.315034       1 scheduler.go:103] [HigherPrecedence] Final decision: Does bronze-class-deploy-3-775f4fbdd9-h8pjj have precedence over bronze-class-deploy-20-5fd9977fb4-hj4vm? true
I0409 14:52:17.315077       1 scheduler.go:103] [HigherPrecedence] Final decision: Does bronze-class-deploy-3-775f4fbdd9-h8pjj have precedence over bronze-class-deploy-23-654ffb5cc5-btltf? true
I0409 14:52:17.315105       1 scheduler.go:103] [HigherPrecedence] Final decision: Does bronze-class-deploy-3-775f4fbdd9-h8pjj have precedence over bronze-class-deploy-24-668b49b99b-wcmrw? true
I0409 14:52:17.315131       1 scheduler.go:103] [HigherPrecedence] Final decision: Does bronze-class-deploy-3-775f4fbdd9-h8pjj have precedence over bronze-class-deploy-28-946b5bff6-774x4? false
I0409 14:52:17.315170       1 default_preemption.go:37] "Preemption failed or not needed" pod="default/bronze-class-deploy-3-775f4fbdd9-h8pjj" status="0/2 nodes are available: 1 No preemption victims found for incoming pod, 1 Preemption is not helpful for scheduling."
I0409 14:52:19.306875       1 default_preemption.go:51] [PreEnqueue] PreEnqueue called for pod: bronze-class-deploy-29-7d6b766b6f-q5ptz
I0409 14:52:19.306907       1 default_preemption.go:52] [PreEnqueue] SchedulerName for pod bronze-class-deploy-29-7d6b766b6f-q5ptz: custom-scheduler
I0409 14:52:19.307254       1 scheduler.go:164] [PreBind] Validating pod bronze-class-deploy-29-7d6b766b6f-q5ptz before binding to node kwok-node-1
I0409 14:52:19.310591       1 scheduler.go:172] [PostBind] Called for pod bronze-class-deploy-29-7d6b766b6f-q5ptz
I0409 14:52:19.310607       1 scheduler.go:190] [PostBind] Pod bronze-class-deploy-29-7d6b766b6f-q5ptz - Binding start: 2025-04-09 14:52:19.307281501 +0000 UTC m=+223.994651939, Binding end: 2025-04-09 14:52:19.310604548 +0000 UTC m=+223.997974986
I0409 14:52:19.310625       1 scheduler.go:197] [PostBind] Metrics updated for pod bronze-class-deploy-29-7d6b766b6f-q5ptz
I0409 14:52:19.310726       1 scheduler.go:255] [OnUpdatePod] Updating 'LastStatus' of pod default/bronze-class-deploy-29-7d6b766b6f-q5ptz in metrics
I0409 14:52:19.317044       1 scheduler.go:255] [OnUpdatePod] Updating 'LastStatus' of pod default/bronze-class-deploy-29-7d6b766b6f-q5ptz in metrics
I0409 14:52:36.024600       1 default_preemption.go:51] [PreEnqueue] PreEnqueue called for pod: bronze-class-deploy-25-b94944fb5-r6wph
I0409 14:52:36.024623       1 default_preemption.go:52] [PreEnqueue] SchedulerName for pod bronze-class-deploy-25-b94944fb5-r6wph: custom-scheduler
I0409 14:52:36.024662       1 default_preemption.go:51] [PreEnqueue] PreEnqueue called for pod: bronze-class-deploy-31-77756c9778-d8hft
I0409 14:52:36.024666       1 default_preemption.go:52] [PreEnqueue] SchedulerName for pod bronze-class-deploy-31-77756c9778-d8hft: custom-scheduler
I0409 14:52:36.024694       1 scheduler.go:103] [HigherPrecedence] Final decision: Does bronze-class-deploy-31-77756c9778-d8hft have precedence over bronze-class-deploy-25-b94944fb5-r6wph? false
I0409 14:52:36.024716       1 default_preemption.go:51] [PreEnqueue] PreEnqueue called for pod: bronze-class-deploy-30-56698788c5-dkftl
I0409 14:52:36.024720       1 default_preemption.go:52] [PreEnqueue] SchedulerName for pod bronze-class-deploy-30-56698788c5-dkftl: custom-scheduler
I0409 14:52:36.024754       1 scheduler.go:103] [HigherPrecedence] Final decision: Does bronze-class-deploy-30-56698788c5-dkftl have precedence over bronze-class-deploy-25-b94944fb5-r6wph? false
I0409 14:52:36.024778       1 default_preemption.go:51] [PreEnqueue] PreEnqueue called for pod: bronze-class-deploy-16-74dd4696ff-mkf54
I0409 14:52:36.024782       1 default_preemption.go:52] [PreEnqueue] SchedulerName for pod bronze-class-deploy-16-74dd4696ff-mkf54: custom-scheduler
I0409 14:52:36.024809       1 scheduler.go:103] [HigherPrecedence] Final decision: Does bronze-class-deploy-16-74dd4696ff-mkf54 have precedence over bronze-class-deploy-31-77756c9778-d8hft? true
I0409 14:52:36.024841       1 scheduler.go:103] [HigherPrecedence] Final decision: Does bronze-class-deploy-16-74dd4696ff-mkf54 have precedence over bronze-class-deploy-25-b94944fb5-r6wph? true
I0409 14:52:36.024857       1 default_preemption.go:51] [PreEnqueue] PreEnqueue called for pod: bronze-class-deploy-11-559c656b44-5grsk
I0409 14:52:36.024861       1 default_preemption.go:52] [PreEnqueue] SchedulerName for pod bronze-class-deploy-11-559c656b44-5grsk: custom-scheduler
I0409 14:52:36.024895       1 scheduler.go:103] [HigherPrecedence] Final decision: Does bronze-class-deploy-11-559c656b44-5grsk have precedence over bronze-class-deploy-25-b94944fb5-r6wph? true
I0409 14:52:36.024926       1 scheduler.go:103] [HigherPrecedence] Final decision: Does bronze-class-deploy-11-559c656b44-5grsk have precedence over bronze-class-deploy-16-74dd4696ff-mkf54? false
I0409 14:52:36.024942       1 default_preemption.go:51] [PreEnqueue] PreEnqueue called for pod: bronze-class-deploy-8-6fff566748-tt726
I0409 14:52:36.024947       1 default_preemption.go:52] [PreEnqueue] SchedulerName for pod bronze-class-deploy-8-6fff566748-tt726: custom-scheduler
I0409 14:52:36.024976       1 scheduler.go:103] [HigherPrecedence] Final decision: Does bronze-class-deploy-8-6fff566748-tt726 have precedence over bronze-class-deploy-30-56698788c5-dkftl? true
I0409 14:52:36.025009       1 scheduler.go:103] [HigherPrecedence] Final decision: Does bronze-class-deploy-8-6fff566748-tt726 have precedence over bronze-class-deploy-16-74dd4696ff-mkf54? false
I0409 14:52:36.025024       1 default_preemption.go:51] [PreEnqueue] PreEnqueue called for pod: bronze-class-deploy-3-775f4fbdd9-h8pjj
I0409 14:52:36.025028       1 default_preemption.go:52] [PreEnqueue] SchedulerName for pod bronze-class-deploy-3-775f4fbdd9-h8pjj: custom-scheduler
I0409 14:52:36.025059       1 scheduler.go:103] [HigherPrecedence] Final decision: Does bronze-class-deploy-3-775f4fbdd9-h8pjj have precedence over bronze-class-deploy-8-6fff566748-tt726? false
I0409 14:52:36.025138       1 scheduler.go:103] [HigherPrecedence] Final decision: Does bronze-class-deploy-8-6fff566748-tt726 have precedence over bronze-class-deploy-11-559c656b44-5grsk? false
I0409 14:52:36.025176       1 scheduler.go:103] [HigherPrecedence] Final decision: Does bronze-class-deploy-11-559c656b44-5grsk have precedence over bronze-class-deploy-3-775f4fbdd9-h8pjj? true
I0409 14:52:36.025200       1 scheduler.go:103] [HigherPrecedence] Final decision: Does bronze-class-deploy-25-b94944fb5-r6wph have precedence over bronze-class-deploy-31-77756c9778-d8hft? true
I0409 14:52:36.025232       1 scheduler.go:103] [HigherPrecedence] Final decision: Does bronze-class-deploy-25-b94944fb5-r6wph have precedence over bronze-class-deploy-3-775f4fbdd9-h8pjj? false
I0409 14:52:36.025795       1 scheduler.go:103] [HigherPrecedence] Final decision: Does bronze-class-deploy-16-74dd4696ff-mkf54 have precedence over bronze-class-deploy-20-5fd9977fb4-hj4vm? true
I0409 14:52:36.025834       1 scheduler.go:103] [HigherPrecedence] Final decision: Does bronze-class-deploy-16-74dd4696ff-mkf54 have precedence over bronze-class-deploy-23-654ffb5cc5-btltf? true
I0409 14:52:36.025856       1 scheduler.go:103] [HigherPrecedence] Final decision: Does bronze-class-deploy-16-74dd4696ff-mkf54 have precedence over bronze-class-deploy-24-668b49b99b-wcmrw? true
I0409 14:52:36.025887       1 scheduler.go:103] [HigherPrecedence] Final decision: Does bronze-class-deploy-16-74dd4696ff-mkf54 have precedence over bronze-class-deploy-28-946b5bff6-774x4? true
I0409 14:52:36.025920       1 scheduler.go:103] [HigherPrecedence] Final decision: Does bronze-class-deploy-16-74dd4696ff-mkf54 have precedence over bronze-class-deploy-29-7d6b766b6f-q5ptz? true
I0409 14:52:36.025964       1 default_preemption.go:37] "Preemption failed or not needed" pod="default/bronze-class-deploy-16-74dd4696ff-mkf54" status="0/2 nodes are available: 1 No preemption victims found for incoming pod, 1 Preemption is not helpful for scheduling."
I0409 14:52:36.026091       1 scheduler.go:103] [HigherPrecedence] Final decision: Does bronze-class-deploy-8-6fff566748-tt726 have precedence over bronze-class-deploy-3-775f4fbdd9-h8pjj? true
I0409 14:52:36.026144       1 scheduler.go:103] [HigherPrecedence] Final decision: Does bronze-class-deploy-8-6fff566748-tt726 have precedence over bronze-class-deploy-30-56698788c5-dkftl? true
I0409 14:52:36.026612       1 scheduler.go:103] [HigherPrecedence] Final decision: Does bronze-class-deploy-11-559c656b44-5grsk have precedence over bronze-class-deploy-20-5fd9977fb4-hj4vm? true
I0409 14:52:36.026652       1 scheduler.go:103] [HigherPrecedence] Final decision: Does bronze-class-deploy-11-559c656b44-5grsk have precedence over bronze-class-deploy-23-654ffb5cc5-btltf? true
I0409 14:52:36.026673       1 scheduler.go:103] [HigherPrecedence] Final decision: Does bronze-class-deploy-11-559c656b44-5grsk have precedence over bronze-class-deploy-24-668b49b99b-wcmrw? true
I0409 14:52:36.026693       1 scheduler.go:103] [HigherPrecedence] Final decision: Does bronze-class-deploy-11-559c656b44-5grsk have precedence over bronze-class-deploy-28-946b5bff6-774x4? true
I0409 14:52:36.026712       1 scheduler.go:103] [HigherPrecedence] Final decision: Does bronze-class-deploy-11-559c656b44-5grsk have precedence over bronze-class-deploy-29-7d6b766b6f-q5ptz? true
I0409 14:52:36.026753       1 default_preemption.go:37] "Preemption failed or not needed" pod="default/bronze-class-deploy-11-559c656b44-5grsk" status="0/2 nodes are available: 1 No preemption victims found for incoming pod, 1 Preemption is not helpful for scheduling."
I0409 14:52:36.026820       1 scheduler.go:103] [HigherPrecedence] Final decision: Does bronze-class-deploy-30-56698788c5-dkftl have precedence over bronze-class-deploy-3-775f4fbdd9-h8pjj? false
I0409 14:52:36.026848       1 scheduler.go:103] [HigherPrecedence] Final decision: Does bronze-class-deploy-3-775f4fbdd9-h8pjj have precedence over bronze-class-deploy-25-b94944fb5-r6wph? true
I0409 14:52:36.026863       1 scheduler.go:103] [HigherPrecedence] Final decision: Does bronze-class-deploy-31-77756c9778-d8hft have precedence over bronze-class-deploy-25-b94944fb5-r6wph? false
I0409 14:52:36.027184       1 scheduler.go:103] [HigherPrecedence] Final decision: Does bronze-class-deploy-8-6fff566748-tt726 have precedence over bronze-class-deploy-20-5fd9977fb4-hj4vm? true
I0409 14:52:36.027217       1 scheduler.go:103] [HigherPrecedence] Final decision: Does bronze-class-deploy-8-6fff566748-tt726 have precedence over bronze-class-deploy-23-654ffb5cc5-btltf? true
I0409 14:52:36.027237       1 scheduler.go:103] [HigherPrecedence] Final decision: Does bronze-class-deploy-8-6fff566748-tt726 have precedence over bronze-class-deploy-24-668b49b99b-wcmrw? true
I0409 14:52:36.027255       1 scheduler.go:103] [HigherPrecedence] Final decision: Does bronze-class-deploy-8-6fff566748-tt726 have precedence over bronze-class-deploy-28-946b5bff6-774x4? true
I0409 14:52:36.027283       1 scheduler.go:103] [HigherPrecedence] Final decision: Does bronze-class-deploy-8-6fff566748-tt726 have precedence over bronze-class-deploy-29-7d6b766b6f-q5ptz? true
I0409 14:52:36.027312       1 default_preemption.go:37] "Preemption failed or not needed" pod="default/bronze-class-deploy-8-6fff566748-tt726" status="0/2 nodes are available: 1 No preemption victims found for incoming pod, 1 Preemption is not helpful for scheduling."
I0409 14:52:36.027435       1 scheduler.go:103] [HigherPrecedence] Final decision: Does bronze-class-deploy-30-56698788c5-dkftl have precedence over bronze-class-deploy-25-b94944fb5-r6wph? false
I0409 14:52:36.027470       1 scheduler.go:103] [HigherPrecedence] Final decision: Does bronze-class-deploy-25-b94944fb5-r6wph have precedence over bronze-class-deploy-31-77756c9778-d8hft? true
I0409 14:52:36.027814       1 scheduler.go:103] [HigherPrecedence] Final decision: Does bronze-class-deploy-3-775f4fbdd9-h8pjj have precedence over bronze-class-deploy-20-5fd9977fb4-hj4vm? true
I0409 14:52:36.027851       1 scheduler.go:103] [HigherPrecedence] Final decision: Does bronze-class-deploy-3-775f4fbdd9-h8pjj have precedence over bronze-class-deploy-23-654ffb5cc5-btltf? true
I0409 14:52:36.027870       1 scheduler.go:103] [HigherPrecedence] Final decision: Does bronze-class-deploy-3-775f4fbdd9-h8pjj have precedence over bronze-class-deploy-24-668b49b99b-wcmrw? true
I0409 14:52:36.027890       1 scheduler.go:103] [HigherPrecedence] Final decision: Does bronze-class-deploy-3-775f4fbdd9-h8pjj have precedence over bronze-class-deploy-28-946b5bff6-774x4? true
I0409 14:52:36.027918       1 scheduler.go:103] [HigherPrecedence] Final decision: Does bronze-class-deploy-3-775f4fbdd9-h8pjj have precedence over bronze-class-deploy-29-7d6b766b6f-q5ptz? true
I0409 14:52:36.027950       1 default_preemption.go:37] "Preemption failed or not needed" pod="default/bronze-class-deploy-3-775f4fbdd9-h8pjj" status="0/2 nodes are available: 1 No preemption victims found for incoming pod, 1 Preemption is not helpful for scheduling."
I0409 14:52:36.028026       1 scheduler.go:103] [HigherPrecedence] Final decision: Does bronze-class-deploy-31-77756c9778-d8hft have precedence over bronze-class-deploy-30-56698788c5-dkftl? true
I0409 14:52:36.028410       1 scheduler.go:103] [HigherPrecedence] Final decision: Does bronze-class-deploy-25-b94944fb5-r6wph have precedence over bronze-class-deploy-20-5fd9977fb4-hj4vm? false
I0409 14:52:36.028449       1 scheduler.go:103] [HigherPrecedence] Final decision: Does bronze-class-deploy-25-b94944fb5-r6wph have precedence over bronze-class-deploy-23-654ffb5cc5-btltf? false
I0409 14:52:36.028466       1 scheduler.go:103] [HigherPrecedence] Final decision: Does bronze-class-deploy-25-b94944fb5-r6wph have precedence over bronze-class-deploy-24-668b49b99b-wcmrw? false
I0409 14:52:36.028486       1 scheduler.go:103] [HigherPrecedence] Final decision: Does bronze-class-deploy-25-b94944fb5-r6wph have precedence over bronze-class-deploy-28-946b5bff6-774x4? false
I0409 14:52:36.028504       1 scheduler.go:103] [HigherPrecedence] Final decision: Does bronze-class-deploy-25-b94944fb5-r6wph have precedence over bronze-class-deploy-29-7d6b766b6f-q5ptz? false
I0409 14:52:36.028548       1 default_preemption.go:37] "Preemption failed or not needed" pod="default/bronze-class-deploy-25-b94944fb5-r6wph" status="0/2 nodes are available: 1 No preemption victims found for incoming pod, 1 Preemption is not helpful for scheduling."
I0409 14:52:36.029316       1 scheduler.go:103] [HigherPrecedence] Final decision: Does bronze-class-deploy-31-77756c9778-d8hft have precedence over bronze-class-deploy-20-5fd9977fb4-hj4vm? false
I0409 14:52:36.029389       1 scheduler.go:103] [HigherPrecedence] Final decision: Does bronze-class-deploy-31-77756c9778-d8hft have precedence over bronze-class-deploy-23-654ffb5cc5-btltf? false
I0409 14:52:36.029416       1 scheduler.go:103] [HigherPrecedence] Final decision: Does bronze-class-deploy-31-77756c9778-d8hft have precedence over bronze-class-deploy-24-668b49b99b-wcmrw? false
I0409 14:52:36.029438       1 scheduler.go:103] [HigherPrecedence] Final decision: Does bronze-class-deploy-31-77756c9778-d8hft have precedence over bronze-class-deploy-28-946b5bff6-774x4? false
I0409 14:52:36.029470       1 scheduler.go:103] [HigherPrecedence] Final decision: Does bronze-class-deploy-31-77756c9778-d8hft have precedence over bronze-class-deploy-29-7d6b766b6f-q5ptz? false
I0409 14:52:36.029499       1 default_preemption.go:37] "Preemption failed or not needed" pod="default/bronze-class-deploy-31-77756c9778-d8hft" status="0/2 nodes are available: 1 No preemption victims found for incoming pod, 1 Preemption is not helpful for scheduling."
I0409 14:52:36.029981       1 scheduler.go:103] [HigherPrecedence] Final decision: Does bronze-class-deploy-30-56698788c5-dkftl have precedence over bronze-class-deploy-20-5fd9977fb4-hj4vm? false
I0409 14:52:36.030016       1 scheduler.go:103] [HigherPrecedence] Final decision: Does bronze-class-deploy-30-56698788c5-dkftl have precedence over bronze-class-deploy-23-654ffb5cc5-btltf? false
I0409 14:52:36.030035       1 scheduler.go:103] [HigherPrecedence] Final decision: Does bronze-class-deploy-30-56698788c5-dkftl have precedence over bronze-class-deploy-24-668b49b99b-wcmrw? false
I0409 14:52:36.030054       1 scheduler.go:103] [HigherPrecedence] Final decision: Does bronze-class-deploy-30-56698788c5-dkftl have precedence over bronze-class-deploy-28-946b5bff6-774x4? false
I0409 14:52:36.030084       1 scheduler.go:103] [HigherPrecedence] Final decision: Does bronze-class-deploy-30-56698788c5-dkftl have precedence over bronze-class-deploy-29-7d6b766b6f-q5ptz? false
I0409 14:52:36.030117       1 default_preemption.go:37] "Preemption failed or not needed" pod="default/bronze-class-deploy-30-56698788c5-dkftl" status="0/2 nodes are available: 1 No preemption victims found for incoming pod, 1 Preemption is not helpful for scheduling."
I0409 14:53:06.025766       1 default_preemption.go:51] [PreEnqueue] PreEnqueue called for pod: bronze-class-deploy-31-77756c9778-d8hft
I0409 14:53:06.025792       1 default_preemption.go:52] [PreEnqueue] SchedulerName for pod bronze-class-deploy-31-77756c9778-d8hft: custom-scheduler
I0409 14:53:06.025832       1 default_preemption.go:51] [PreEnqueue] PreEnqueue called for pod: bronze-class-deploy-30-56698788c5-dkftl
I0409 14:53:06.025835       1 default_preemption.go:52] [PreEnqueue] SchedulerName for pod bronze-class-deploy-30-56698788c5-dkftl: custom-scheduler
I0409 14:53:06.025862       1 scheduler.go:103] [HigherPrecedence] Final decision: Does bronze-class-deploy-30-56698788c5-dkftl have precedence over bronze-class-deploy-31-77756c9778-d8hft? false
I0409 14:53:06.025878       1 default_preemption.go:51] [PreEnqueue] PreEnqueue called for pod: bronze-class-deploy-16-74dd4696ff-mkf54
I0409 14:53:06.025882       1 default_preemption.go:52] [PreEnqueue] SchedulerName for pod bronze-class-deploy-16-74dd4696ff-mkf54: custom-scheduler
I0409 14:53:06.025903       1 scheduler.go:103] [HigherPrecedence] Final decision: Does bronze-class-deploy-16-74dd4696ff-mkf54 have precedence over bronze-class-deploy-31-77756c9778-d8hft? true
I0409 14:53:06.025920       1 default_preemption.go:51] [PreEnqueue] PreEnqueue called for pod: bronze-class-deploy-11-559c656b44-5grsk
I0409 14:53:06.025927       1 default_preemption.go:52] [PreEnqueue] SchedulerName for pod bronze-class-deploy-11-559c656b44-5grsk: custom-scheduler
I0409 14:53:06.025954       1 scheduler.go:103] [HigherPrecedence] Final decision: Does bronze-class-deploy-11-559c656b44-5grsk have precedence over bronze-class-deploy-30-56698788c5-dkftl? true
I0409 14:53:06.025974       1 scheduler.go:103] [HigherPrecedence] Final decision: Does bronze-class-deploy-11-559c656b44-5grsk have precedence over bronze-class-deploy-16-74dd4696ff-mkf54? false
I0409 14:53:06.025984       1 default_preemption.go:51] [PreEnqueue] PreEnqueue called for pod: bronze-class-deploy-8-6fff566748-tt726
I0409 14:53:06.025993       1 default_preemption.go:52] [PreEnqueue] SchedulerName for pod bronze-class-deploy-8-6fff566748-tt726: custom-scheduler
I0409 14:53:06.026013       1 scheduler.go:103] [HigherPrecedence] Final decision: Does bronze-class-deploy-8-6fff566748-tt726 have precedence over bronze-class-deploy-11-559c656b44-5grsk? false
I0409 14:53:06.026030       1 default_preemption.go:51] [PreEnqueue] PreEnqueue called for pod: bronze-class-deploy-3-775f4fbdd9-h8pjj
I0409 14:53:06.026034       1 default_preemption.go:52] [PreEnqueue] SchedulerName for pod bronze-class-deploy-3-775f4fbdd9-h8pjj: custom-scheduler
I0409 14:53:06.026057       1 scheduler.go:103] [HigherPrecedence] Final decision: Does bronze-class-deploy-3-775f4fbdd9-h8pjj have precedence over bronze-class-deploy-31-77756c9778-d8hft? true
I0409 14:53:06.026078       1 scheduler.go:103] [HigherPrecedence] Final decision: Does bronze-class-deploy-3-775f4fbdd9-h8pjj have precedence over bronze-class-deploy-16-74dd4696ff-mkf54? false
I0409 14:53:06.026086       1 default_preemption.go:51] [PreEnqueue] PreEnqueue called for pod: bronze-class-deploy-25-b94944fb5-r6wph
I0409 14:53:06.026096       1 default_preemption.go:52] [PreEnqueue] SchedulerName for pod bronze-class-deploy-25-b94944fb5-r6wph: custom-scheduler
I0409 14:53:06.026121       1 scheduler.go:103] [HigherPrecedence] Final decision: Does bronze-class-deploy-25-b94944fb5-r6wph have precedence over bronze-class-deploy-3-775f4fbdd9-h8pjj? false
I0409 14:53:06.026179       1 scheduler.go:103] [HigherPrecedence] Final decision: Does bronze-class-deploy-3-775f4fbdd9-h8pjj have precedence over bronze-class-deploy-11-559c656b44-5grsk? false
I0409 14:53:06.026218       1 scheduler.go:103] [HigherPrecedence] Final decision: Does bronze-class-deploy-11-559c656b44-5grsk have precedence over bronze-class-deploy-25-b94944fb5-r6wph? true
I0409 14:53:06.026238       1 scheduler.go:103] [HigherPrecedence] Final decision: Does bronze-class-deploy-8-6fff566748-tt726 have precedence over bronze-class-deploy-30-56698788c5-dkftl? true
I0409 14:53:06.026258       1 scheduler.go:103] [HigherPrecedence] Final decision: Does bronze-class-deploy-8-6fff566748-tt726 have precedence over bronze-class-deploy-25-b94944fb5-r6wph? true
I0409 14:53:06.026885       1 scheduler.go:103] [HigherPrecedence] Final decision: Does bronze-class-deploy-16-74dd4696ff-mkf54 have precedence over bronze-class-deploy-20-5fd9977fb4-hj4vm? true
I0409 14:53:06.026952       1 scheduler.go:103] [HigherPrecedence] Final decision: Does bronze-class-deploy-16-74dd4696ff-mkf54 have precedence over bronze-class-deploy-23-654ffb5cc5-btltf? true
I0409 14:53:06.026987       1 scheduler.go:103] [HigherPrecedence] Final decision: Does bronze-class-deploy-16-74dd4696ff-mkf54 have precedence over bronze-class-deploy-24-668b49b99b-wcmrw? true
I0409 14:53:06.027028       1 scheduler.go:103] [HigherPrecedence] Final decision: Does bronze-class-deploy-16-74dd4696ff-mkf54 have precedence over bronze-class-deploy-28-946b5bff6-774x4? true
I0409 14:53:06.027056       1 scheduler.go:103] [HigherPrecedence] Final decision: Does bronze-class-deploy-16-74dd4696ff-mkf54 have precedence over bronze-class-deploy-29-7d6b766b6f-q5ptz? true
I0409 14:53:06.034877       1 scheduler.go:255] [OnUpdatePod] Updating 'LastStatus' of pod default/bronze-class-deploy-29-7d6b766b6f-q5ptz in metrics
I0409 14:53:06.040965       1 scheduler.go:255] [OnUpdatePod] Updating 'LastStatus' of pod default/bronze-class-deploy-29-7d6b766b6f-q5ptz in metrics
I0409 14:53:06.044737       1 default_preemption.go:39] "Preemption successful" pod="default/bronze-class-deploy-16-74dd4696ff-mkf54" nominatedNode="kwok-node-1"
I0409 14:53:06.044905       1 scheduler.go:286] [OnDeletePod] Checking the state of pod default/bronze-class-deploy-29-7d6b766b6f-q5ptz in metrics
I0409 14:53:06.051916       1 default_preemption.go:51] [PreEnqueue] PreEnqueue called for pod: bronze-class-deploy-29-7d6b766b6f-vd84q
I0409 14:53:06.051955       1 default_preemption.go:52] [PreEnqueue] SchedulerName for pod bronze-class-deploy-29-7d6b766b6f-vd84q: custom-scheduler
W0409 14:53:06.051989       1 scheduler.go:118] [cacheMiss] Metrics not found for pod: default/bronze-class-deploy-29-7d6b766b6f-vd84q
W0409 14:53:06.051994       1 scheduler.go:125] [WaitForPodsOnCache] Pod bronze-class-deploy-29-7d6b766b6f-vd84q not found in cache. Retrying...
I0409 14:53:06.051911       1 scheduler.go:205] [OnAddPod] Pod added: default/bronze-class-deploy-29-7d6b766b6f-vd84q, Annotations: map[acceptablePreemptionOverhead:0.05 controller:bronze-controller-29 kwok.x-k8s.io/usage-cpu:1m kwok.x-k8s.io/usage-memory:1Mi qosMeasuring:average slo:0.5]
I0409 14:53:06.055033       1 scheduler.go:255] [OnUpdatePod] Updating 'LastStatus' of pod default/bronze-class-deploy-16-74dd4696ff-mkf54 in metrics
I0409 14:53:06.152708       1 scheduler.go:103] [HigherPrecedence] Final decision: Does bronze-class-deploy-29-7d6b766b6f-vd84q have precedence over bronze-class-deploy-3-775f4fbdd9-h8pjj? false
I0409 14:53:06.152868       1 scheduler.go:103] [HigherPrecedence] Final decision: Does bronze-class-deploy-3-775f4fbdd9-h8pjj have precedence over bronze-class-deploy-8-6fff566748-tt726? false
I0409 14:53:06.152916       1 scheduler.go:103] [HigherPrecedence] Final decision: Does bronze-class-deploy-8-6fff566748-tt726 have precedence over bronze-class-deploy-29-7d6b766b6f-vd84q? true
I0409 14:53:06.152954       1 scheduler.go:103] [HigherPrecedence] Final decision: Does bronze-class-deploy-25-b94944fb5-r6wph have precedence over bronze-class-deploy-30-56698788c5-dkftl? true
I0409 14:53:06.152972       1 scheduler.go:103] [HigherPrecedence] Final decision: Does bronze-class-deploy-25-b94944fb5-r6wph have precedence over bronze-class-deploy-29-7d6b766b6f-vd84q? false
I0409 14:53:06.153685       1 scheduler.go:103] [HigherPrecedence] Final decision: Does bronze-class-deploy-11-559c656b44-5grsk have precedence over bronze-class-deploy-20-5fd9977fb4-hj4vm? true
I0409 14:53:06.153741       1 scheduler.go:103] [HigherPrecedence] Final decision: Does bronze-class-deploy-11-559c656b44-5grsk have precedence over bronze-class-deploy-23-654ffb5cc5-btltf? true
I0409 14:53:06.153769       1 scheduler.go:103] [HigherPrecedence] Final decision: Does bronze-class-deploy-11-559c656b44-5grsk have precedence over bronze-class-deploy-24-668b49b99b-wcmrw? true
I0409 14:53:06.153806       1 scheduler.go:103] [HigherPrecedence] Final decision: Does bronze-class-deploy-11-559c656b44-5grsk have precedence over bronze-class-deploy-28-946b5bff6-774x4? true
I0409 14:53:06.161042       1 scheduler.go:255] [OnUpdatePod] Updating 'LastStatus' of pod default/bronze-class-deploy-28-946b5bff6-774x4 in metrics
I0409 14:53:06.167118       1 scheduler.go:255] [OnUpdatePod] Updating 'LastStatus' of pod default/bronze-class-deploy-28-946b5bff6-774x4 in metrics
I0409 14:53:06.172907       1 scheduler.go:103] [HigherPrecedence] Final decision: Does bronze-class-deploy-11-559c656b44-5grsk have precedence over bronze-class-deploy-16-74dd4696ff-mkf54? false
I0409 14:53:06.172945       1 default_preemption.go:39] "Preemption successful" pod="default/bronze-class-deploy-11-559c656b44-5grsk" nominatedNode="kwok-node-1"
I0409 14:53:06.173075       1 scheduler.go:286] [OnDeletePod] Checking the state of pod default/bronze-class-deploy-28-946b5bff6-774x4 in metrics
I0409 14:53:06.173739       1 default_preemption.go:51] [PreEnqueue] PreEnqueue called for pod: bronze-class-deploy-28-946b5bff6-nnq2g
I0409 14:53:06.173763       1 default_preemption.go:52] [PreEnqueue] SchedulerName for pod bronze-class-deploy-28-946b5bff6-nnq2g: custom-scheduler
W0409 14:53:06.173801       1 scheduler.go:118] [cacheMiss] Metrics not found for pod: default/bronze-class-deploy-28-946b5bff6-nnq2g
W0409 14:53:06.173823       1 scheduler.go:125] [WaitForPodsOnCache] Pod bronze-class-deploy-28-946b5bff6-nnq2g not found in cache. Retrying...
I0409 14:53:06.173869       1 scheduler.go:205] [OnAddPod] Pod added: default/bronze-class-deploy-28-946b5bff6-nnq2g, Annotations: map[acceptablePreemptionOverhead:0.05 controller:bronze-controller-28 kwok.x-k8s.io/usage-cpu:1m kwok.x-k8s.io/usage-memory:1Mi qosMeasuring:average slo:0.5]
I0409 14:53:06.179870       1 scheduler.go:255] [OnUpdatePod] Updating 'LastStatus' of pod default/bronze-class-deploy-11-559c656b44-5grsk in metrics
I0409 14:53:06.274517       1 scheduler.go:103] [HigherPrecedence] Final decision: Does bronze-class-deploy-28-946b5bff6-nnq2g have precedence over bronze-class-deploy-3-775f4fbdd9-h8pjj? false
I0409 14:53:06.274674       1 scheduler.go:103] [HigherPrecedence] Final decision: Does bronze-class-deploy-3-775f4fbdd9-h8pjj have precedence over bronze-class-deploy-29-7d6b766b6f-vd84q? true
I0409 14:53:06.274713       1 scheduler.go:103] [HigherPrecedence] Final decision: Does bronze-class-deploy-3-775f4fbdd9-h8pjj have precedence over bronze-class-deploy-28-946b5bff6-nnq2g? true
I0409 14:53:06.274736       1 scheduler.go:103] [HigherPrecedence] Final decision: Does bronze-class-deploy-31-77756c9778-d8hft have precedence over bronze-class-deploy-28-946b5bff6-nnq2g? false
I0409 14:53:06.275305       1 scheduler.go:103] [HigherPrecedence] Final decision: Does bronze-class-deploy-8-6fff566748-tt726 have precedence over bronze-class-deploy-20-5fd9977fb4-hj4vm? true
I0409 14:53:06.275385       1 scheduler.go:103] [HigherPrecedence] Final decision: Does bronze-class-deploy-8-6fff566748-tt726 have precedence over bronze-class-deploy-23-654ffb5cc5-btltf? true
I0409 14:53:06.275427       1 scheduler.go:103] [HigherPrecedence] Final decision: Does bronze-class-deploy-8-6fff566748-tt726 have precedence over bronze-class-deploy-24-668b49b99b-wcmrw? true
I0409 14:53:06.282538       1 scheduler.go:255] [OnUpdatePod] Updating 'LastStatus' of pod default/bronze-class-deploy-24-668b49b99b-wcmrw in metrics
I0409 14:53:06.288297       1 scheduler.go:255] [OnUpdatePod] Updating 'LastStatus' of pod default/bronze-class-deploy-24-668b49b99b-wcmrw in metrics
I0409 14:53:06.292046       1 scheduler.go:103] [HigherPrecedence] Final decision: Does bronze-class-deploy-8-6fff566748-tt726 have precedence over bronze-class-deploy-16-74dd4696ff-mkf54? false
I0409 14:53:06.292091       1 scheduler.go:103] [HigherPrecedence] Final decision: Does bronze-class-deploy-8-6fff566748-tt726 have precedence over bronze-class-deploy-11-559c656b44-5grsk? false
I0409 14:53:06.292111       1 default_preemption.go:39] "Preemption successful" pod="default/bronze-class-deploy-8-6fff566748-tt726" nominatedNode="kwok-node-1"
I0409 14:53:06.292186       1 scheduler.go:286] [OnDeletePod] Checking the state of pod default/bronze-class-deploy-24-668b49b99b-wcmrw in metrics
I0409 14:53:06.292911       1 default_preemption.go:51] [PreEnqueue] PreEnqueue called for pod: bronze-class-deploy-24-668b49b99b-m2rb7
I0409 14:53:06.292986       1 default_preemption.go:52] [PreEnqueue] SchedulerName for pod bronze-class-deploy-24-668b49b99b-m2rb7: custom-scheduler
W0409 14:53:06.293022       1 scheduler.go:118] [cacheMiss] Metrics not found for pod: default/bronze-class-deploy-24-668b49b99b-m2rb7
W0409 14:53:06.293029       1 scheduler.go:125] [WaitForPodsOnCache] Pod bronze-class-deploy-24-668b49b99b-m2rb7 not found in cache. Retrying...
I0409 14:53:06.292946       1 scheduler.go:205] [OnAddPod] Pod added: default/bronze-class-deploy-24-668b49b99b-m2rb7, Annotations: map[acceptablePreemptionOverhead:0.05 controller:bronze-controller-24 kwok.x-k8s.io/usage-cpu:1m kwok.x-k8s.io/usage-memory:1Mi qosMeasuring:average slo:0.5]
I0409 14:53:06.300674       1 scheduler.go:255] [OnUpdatePod] Updating 'LastStatus' of pod default/bronze-class-deploy-8-6fff566748-tt726 in metrics
I0409 14:53:06.393716       1 scheduler.go:103] [HigherPrecedence] Final decision: Does bronze-class-deploy-24-668b49b99b-m2rb7 have precedence over bronze-class-deploy-28-946b5bff6-nnq2g? false
I0409 14:53:06.393828       1 scheduler.go:103] [HigherPrecedence] Final decision: Does bronze-class-deploy-28-946b5bff6-nnq2g have precedence over bronze-class-deploy-29-7d6b766b6f-vd84q? false
I0409 14:53:06.393863       1 scheduler.go:103] [HigherPrecedence] Final decision: Does bronze-class-deploy-29-7d6b766b6f-vd84q have precedence over bronze-class-deploy-24-668b49b99b-m2rb7? true
I0409 14:53:06.393884       1 scheduler.go:103] [HigherPrecedence] Final decision: Does bronze-class-deploy-25-b94944fb5-r6wph have precedence over bronze-class-deploy-30-56698788c5-dkftl? true
I0409 14:53:06.393912       1 scheduler.go:103] [HigherPrecedence] Final decision: Does bronze-class-deploy-25-b94944fb5-r6wph have precedence over bronze-class-deploy-24-668b49b99b-m2rb7? true
I0409 14:53:06.394591       1 scheduler.go:103] [HigherPrecedence] Final decision: Does bronze-class-deploy-3-775f4fbdd9-h8pjj have precedence over bronze-class-deploy-20-5fd9977fb4-hj4vm? true
I0409 14:53:06.394656       1 scheduler.go:103] [HigherPrecedence] Final decision: Does bronze-class-deploy-3-775f4fbdd9-h8pjj have precedence over bronze-class-deploy-23-654ffb5cc5-btltf? true
I0409 14:53:06.402257       1 scheduler.go:255] [OnUpdatePod] Updating 'LastStatus' of pod default/bronze-class-deploy-23-654ffb5cc5-btltf in metrics
I0409 14:53:06.407873       1 scheduler.go:255] [OnUpdatePod] Updating 'LastStatus' of pod default/bronze-class-deploy-23-654ffb5cc5-btltf in metrics
I0409 14:53:06.411795       1 scheduler.go:103] [HigherPrecedence] Final decision: Does bronze-class-deploy-3-775f4fbdd9-h8pjj have precedence over bronze-class-deploy-16-74dd4696ff-mkf54? false
I0409 14:53:06.411834       1 scheduler.go:103] [HigherPrecedence] Final decision: Does bronze-class-deploy-3-775f4fbdd9-h8pjj have precedence over bronze-class-deploy-11-559c656b44-5grsk? false
I0409 14:53:06.411856       1 scheduler.go:103] [HigherPrecedence] Final decision: Does bronze-class-deploy-3-775f4fbdd9-h8pjj have precedence over bronze-class-deploy-8-6fff566748-tt726? false
I0409 14:53:06.411859       1 scheduler.go:286] [OnDeletePod] Checking the state of pod default/bronze-class-deploy-23-654ffb5cc5-btltf in metrics
I0409 14:53:06.411873       1 default_preemption.go:39] "Preemption successful" pod="default/bronze-class-deploy-3-775f4fbdd9-h8pjj" nominatedNode="kwok-node-1"
I0409 14:53:06.415046       1 default_preemption.go:51] [PreEnqueue] PreEnqueue called for pod: bronze-class-deploy-23-654ffb5cc5-nsc48
I0409 14:53:06.415067       1 default_preemption.go:52] [PreEnqueue] SchedulerName for pod bronze-class-deploy-23-654ffb5cc5-nsc48: custom-scheduler
I0409 14:53:06.415077       1 scheduler.go:205] [OnAddPod] Pod added: default/bronze-class-deploy-23-654ffb5cc5-nsc48, Annotations: map[acceptablePreemptionOverhead:0.05 controller:bronze-controller-23 kwok.x-k8s.io/usage-cpu:1m kwok.x-k8s.io/usage-memory:1Mi qosMeasuring:average slo:0.5]
W0409 14:53:06.415099       1 scheduler.go:118] [cacheMiss] Metrics not found for pod: default/bronze-class-deploy-23-654ffb5cc5-nsc48
W0409 14:53:06.415105       1 scheduler.go:125] [WaitForPodsOnCache] Pod bronze-class-deploy-23-654ffb5cc5-nsc48 not found in cache. Retrying...
I0409 14:53:06.418128       1 scheduler.go:255] [OnUpdatePod] Updating 'LastStatus' of pod default/bronze-class-deploy-3-775f4fbdd9-h8pjj in metrics
I0409 14:53:06.516040       1 scheduler.go:103] [HigherPrecedence] Final decision: Does bronze-class-deploy-23-654ffb5cc5-nsc48 have precedence over bronze-class-deploy-28-946b5bff6-nnq2g? false
I0409 14:53:06.516190       1 scheduler.go:103] [HigherPrecedence] Final decision: Does bronze-class-deploy-28-946b5bff6-nnq2g have precedence over bronze-class-deploy-25-b94944fb5-r6wph? true
I0409 14:53:06.516224       1 scheduler.go:103] [HigherPrecedence] Final decision: Does bronze-class-deploy-28-946b5bff6-nnq2g have precedence over bronze-class-deploy-23-654ffb5cc5-nsc48? true
I0409 14:53:06.516246       1 scheduler.go:103] [HigherPrecedence] Final decision: Does bronze-class-deploy-31-77756c9778-d8hft have precedence over bronze-class-deploy-23-654ffb5cc5-nsc48? true
I0409 14:53:06.516925       1 scheduler.go:103] [HigherPrecedence] Final decision: Does bronze-class-deploy-29-7d6b766b6f-vd84q have precedence over bronze-class-deploy-20-5fd9977fb4-hj4vm? true
I0409 14:53:06.524377       1 scheduler.go:255] [OnUpdatePod] Updating 'LastStatus' of pod default/bronze-class-deploy-20-5fd9977fb4-hj4vm in metrics
I0409 14:53:06.529807       1 scheduler.go:255] [OnUpdatePod] Updating 'LastStatus' of pod default/bronze-class-deploy-20-5fd9977fb4-hj4vm in metrics
I0409 14:53:06.535881       1 scheduler.go:103] [HigherPrecedence] Final decision: Does bronze-class-deploy-29-7d6b766b6f-vd84q have precedence over bronze-class-deploy-16-74dd4696ff-mkf54? false
I0409 14:53:06.535922       1 scheduler.go:103] [HigherPrecedence] Final decision: Does bronze-class-deploy-29-7d6b766b6f-vd84q have precedence over bronze-class-deploy-11-559c656b44-5grsk? false
I0409 14:53:06.535943       1 scheduler.go:103] [HigherPrecedence] Final decision: Does bronze-class-deploy-29-7d6b766b6f-vd84q have precedence over bronze-class-deploy-8-6fff566748-tt726? false
I0409 14:53:06.535969       1 scheduler.go:103] [HigherPrecedence] Final decision: Does bronze-class-deploy-29-7d6b766b6f-vd84q have precedence over bronze-class-deploy-3-775f4fbdd9-h8pjj? false
I0409 14:53:06.535984       1 default_preemption.go:39] "Preemption successful" pod="default/bronze-class-deploy-29-7d6b766b6f-vd84q" nominatedNode="kwok-node-1"
I0409 14:53:06.536016       1 scheduler.go:286] [OnDeletePod] Checking the state of pod default/bronze-class-deploy-20-5fd9977fb4-hj4vm in metrics
I0409 14:53:06.536270       1 default_preemption.go:51] [PreEnqueue] PreEnqueue called for pod: bronze-class-deploy-20-5fd9977fb4-kwjjw
I0409 14:53:06.536289       1 default_preemption.go:52] [PreEnqueue] SchedulerName for pod bronze-class-deploy-20-5fd9977fb4-kwjjw: custom-scheduler
W0409 14:53:06.536311       1 scheduler.go:118] [cacheMiss] Metrics not found for pod: default/bronze-class-deploy-20-5fd9977fb4-kwjjw
W0409 14:53:06.536317       1 scheduler.go:125] [WaitForPodsOnCache] Pod bronze-class-deploy-20-5fd9977fb4-kwjjw not found in cache. Retrying...
I0409 14:53:06.536513       1 scheduler.go:205] [OnAddPod] Pod added: default/bronze-class-deploy-20-5fd9977fb4-kwjjw, Annotations: map[acceptablePreemptionOverhead:0.05 controller:bronze-controller-20 kwok.x-k8s.io/usage-cpu:1m kwok.x-k8s.io/usage-memory:1Mi qosMeasuring:average slo:0.5]
I0409 14:53:06.545486       1 scheduler.go:255] [OnUpdatePod] Updating 'LastStatus' of pod default/bronze-class-deploy-29-7d6b766b6f-vd84q in metrics
I0409 14:53:06.637434       1 scheduler.go:103] [HigherPrecedence] Final decision: Does bronze-class-deploy-20-5fd9977fb4-kwjjw have precedence over bronze-class-deploy-31-77756c9778-d8hft? false
I0409 14:53:06.637557       1 scheduler.go:103] [HigherPrecedence] Final decision: Does bronze-class-deploy-31-77756c9778-d8hft have precedence over bronze-class-deploy-25-b94944fb5-r6wph? false
I0409 14:53:06.637595       1 scheduler.go:103] [HigherPrecedence] Final decision: Does bronze-class-deploy-25-b94944fb5-r6wph have precedence over bronze-class-deploy-20-5fd9977fb4-kwjjw? true
I0409 14:53:06.637620       1 scheduler.go:103] [HigherPrecedence] Final decision: Does bronze-class-deploy-24-668b49b99b-m2rb7 have precedence over bronze-class-deploy-30-56698788c5-dkftl? true
I0409 14:53:06.637651       1 scheduler.go:103] [HigherPrecedence] Final decision: Does bronze-class-deploy-24-668b49b99b-m2rb7 have precedence over bronze-class-deploy-20-5fd9977fb4-kwjjw? true
I0409 14:53:06.638311       1 default_preemption.go:37] "Preemption failed or not needed" pod="default/bronze-class-deploy-28-946b5bff6-nnq2g" status="0/2 nodes are available: 1 No preemption victims found for incoming pod, 1 Preemption is not helpful for scheduling."
I0409 14:53:06.646966       1 scheduler.go:255] [OnUpdatePod] Updating 'LastStatus' of pod default/bronze-class-deploy-28-946b5bff6-nnq2g in metrics
I0409 14:53:06.647028       1 scheduler.go:103] [HigherPrecedence] Final decision: Does bronze-class-deploy-31-77756c9778-d8hft have precedence over bronze-class-deploy-24-668b49b99b-m2rb7? true
I0409 14:53:06.647052       1 scheduler.go:103] [HigherPrecedence] Final decision: Does bronze-class-deploy-31-77756c9778-d8hft have precedence over bronze-class-deploy-23-654ffb5cc5-nsc48? true
I0409 14:53:06.647677       1 default_preemption.go:37] "Preemption failed or not needed" pod="default/bronze-class-deploy-25-b94944fb5-r6wph" status="0/2 nodes are available: 1 No preemption victims found for incoming pod, 1 Preemption is not helpful for scheduling."
I0409 14:53:06.647767       1 scheduler.go:103] [HigherPrecedence] Final decision: Does bronze-class-deploy-23-654ffb5cc5-nsc48 have precedence over bronze-class-deploy-24-668b49b99b-m2rb7? false
I0409 14:53:06.647793       1 scheduler.go:103] [HigherPrecedence] Final decision: Does bronze-class-deploy-24-668b49b99b-m2rb7 have precedence over bronze-class-deploy-20-5fd9977fb4-kwjjw? true
I0409 14:53:06.647809       1 scheduler.go:103] [HigherPrecedence] Final decision: Does bronze-class-deploy-30-56698788c5-dkftl have precedence over bronze-class-deploy-20-5fd9977fb4-kwjjw? true
I0409 14:53:06.648211       1 default_preemption.go:37] "Preemption failed or not needed" pod="default/bronze-class-deploy-31-77756c9778-d8hft" status="0/2 nodes are available: 1 No preemption victims found for incoming pod, 1 Preemption is not helpful for scheduling."
I0409 14:53:06.648287       1 scheduler.go:103] [HigherPrecedence] Final decision: Does bronze-class-deploy-23-654ffb5cc5-nsc48 have precedence over bronze-class-deploy-30-56698788c5-dkftl? true
I0409 14:53:06.648316       1 scheduler.go:103] [HigherPrecedence] Final decision: Does bronze-class-deploy-23-654ffb5cc5-nsc48 have precedence over bronze-class-deploy-20-5fd9977fb4-kwjjw? true
I0409 14:53:06.648726       1 default_preemption.go:37] "Preemption failed or not needed" pod="default/bronze-class-deploy-24-668b49b99b-m2rb7" status="0/2 nodes are available: 1 No preemption victims found for incoming pod, 1 Preemption is not helpful for scheduling."
I0409 14:53:06.655470       1 scheduler.go:103] [HigherPrecedence] Final decision: Does bronze-class-deploy-30-56698788c5-dkftl have precedence over bronze-class-deploy-20-5fd9977fb4-kwjjw? true
I0409 14:53:06.655492       1 scheduler.go:255] [OnUpdatePod] Updating 'LastStatus' of pod default/bronze-class-deploy-24-668b49b99b-m2rb7 in metrics
I0409 14:53:06.656156       1 default_preemption.go:37] "Preemption failed or not needed" pod="default/bronze-class-deploy-23-654ffb5cc5-nsc48" status="0/2 nodes are available: 1 No preemption victims found for incoming pod, 1 Preemption is not helpful for scheduling."
I0409 14:53:06.662839       1 scheduler.go:255] [OnUpdatePod] Updating 'LastStatus' of pod default/bronze-class-deploy-23-654ffb5cc5-nsc48 in metrics
I0409 14:53:06.663444       1 default_preemption.go:37] "Preemption failed or not needed" pod="default/bronze-class-deploy-30-56698788c5-dkftl" status="0/2 nodes are available: 1 No preemption victims found for incoming pod, 1 Preemption is not helpful for scheduling."
I0409 14:53:06.663999       1 default_preemption.go:37] "Preemption failed or not needed" pod="default/bronze-class-deploy-20-5fd9977fb4-kwjjw" status="0/2 nodes are available: 1 No preemption victims found for incoming pod, 1 Preemption is not helpful for scheduling."
I0409 14:53:06.670819       1 scheduler.go:255] [OnUpdatePod] Updating 'LastStatus' of pod default/bronze-class-deploy-20-5fd9977fb4-kwjjw in metrics
I0409 14:53:08.394470       1 default_preemption.go:51] [PreEnqueue] PreEnqueue called for pod: bronze-class-deploy-29-7d6b766b6f-vd84q
I0409 14:53:08.394507       1 default_preemption.go:52] [PreEnqueue] SchedulerName for pod bronze-class-deploy-29-7d6b766b6f-vd84q: custom-scheduler
I0409 14:53:08.394967       1 scheduler.go:164] [PreBind] Validating pod bronze-class-deploy-29-7d6b766b6f-vd84q before binding to node kwok-node-1
I0409 14:53:08.398091       1 scheduler.go:172] [PostBind] Called for pod bronze-class-deploy-29-7d6b766b6f-vd84q
I0409 14:53:08.398114       1 scheduler.go:190] [PostBind] Pod bronze-class-deploy-29-7d6b766b6f-vd84q - Binding start: 2025-04-09 14:53:08.394980262 +0000 UTC m=+273.082350700, Binding end: 2025-04-09 14:53:08.398110488 +0000 UTC m=+273.085480916
I0409 14:53:08.398134       1 scheduler.go:197] [PostBind] Metrics updated for pod bronze-class-deploy-29-7d6b766b6f-vd84q
I0409 14:53:08.398161       1 scheduler.go:255] [OnUpdatePod] Updating 'LastStatus' of pod default/bronze-class-deploy-29-7d6b766b6f-vd84q in metrics
I0409 14:53:08.405891       1 scheduler.go:255] [OnUpdatePod] Updating 'LastStatus' of pod default/bronze-class-deploy-29-7d6b766b6f-vd84q in metrics
I0409 14:53:16.398940       1 default_preemption.go:51] [PreEnqueue] PreEnqueue called for pod: bronze-class-deploy-16-74dd4696ff-mkf54
I0409 14:53:16.398966       1 default_preemption.go:52] [PreEnqueue] SchedulerName for pod bronze-class-deploy-16-74dd4696ff-mkf54: custom-scheduler
I0409 14:53:16.399012       1 default_preemption.go:51] [PreEnqueue] PreEnqueue called for pod: bronze-class-deploy-11-559c656b44-5grsk
I0409 14:53:16.399017       1 default_preemption.go:52] [PreEnqueue] SchedulerName for pod bronze-class-deploy-11-559c656b44-5grsk: custom-scheduler
I0409 14:53:16.399055       1 scheduler.go:103] [HigherPrecedence] Final decision: Does bronze-class-deploy-11-559c656b44-5grsk have precedence over bronze-class-deploy-16-74dd4696ff-mkf54? false
I0409 14:53:16.399079       1 default_preemption.go:51] [PreEnqueue] PreEnqueue called for pod: bronze-class-deploy-8-6fff566748-tt726
I0409 14:53:16.399083       1 default_preemption.go:52] [PreEnqueue] SchedulerName for pod bronze-class-deploy-8-6fff566748-tt726: custom-scheduler
I0409 14:53:16.399105       1 scheduler.go:103] [HigherPrecedence] Final decision: Does bronze-class-deploy-8-6fff566748-tt726 have precedence over bronze-class-deploy-16-74dd4696ff-mkf54? false
I0409 14:53:16.399162       1 scheduler.go:103] [HigherPrecedence] Final decision: Does bronze-class-deploy-11-559c656b44-5grsk have precedence over bronze-class-deploy-8-6fff566748-tt726? true
I0409 14:53:16.399610       1 scheduler.go:164] [PreBind] Validating pod bronze-class-deploy-16-74dd4696ff-mkf54 before binding to node kwok-node-1
I0409 14:53:16.399676       1 scheduler.go:164] [PreBind] Validating pod bronze-class-deploy-8-6fff566748-tt726 before binding to node kwok-node-1
I0409 14:53:16.399723       1 scheduler.go:164] [PreBind] Validating pod bronze-class-deploy-11-559c656b44-5grsk before binding to node kwok-node-1
I0409 14:53:16.405550       1 scheduler.go:255] [OnUpdatePod] Updating 'LastStatus' of pod default/bronze-class-deploy-11-559c656b44-5grsk in metrics
I0409 14:53:16.405603       1 scheduler.go:172] [PostBind] Called for pod bronze-class-deploy-8-6fff566748-tt726
I0409 14:53:16.405619       1 scheduler.go:190] [PostBind] Pod bronze-class-deploy-8-6fff566748-tt726 - Binding start: 2025-04-09 14:53:16.399684378 +0000 UTC m=+281.087054816, Binding end: 2025-04-09 14:53:16.405614921 +0000 UTC m=+281.092985359
I0409 14:53:16.405637       1 scheduler.go:197] [PostBind] Metrics updated for pod bronze-class-deploy-8-6fff566748-tt726
I0409 14:53:16.405658       1 scheduler.go:172] [PostBind] Called for pod bronze-class-deploy-16-74dd4696ff-mkf54
I0409 14:53:16.405679       1 scheduler.go:190] [PostBind] Pod bronze-class-deploy-16-74dd4696ff-mkf54 - Binding start: 2025-04-09 14:53:16.399635885 +0000 UTC m=+281.087006323, Binding end: 2025-04-09 14:53:16.405676735 +0000 UTC m=+281.093047163
I0409 14:53:16.405689       1 scheduler.go:197] [PostBind] Metrics updated for pod bronze-class-deploy-16-74dd4696ff-mkf54
I0409 14:53:16.405808       1 scheduler.go:255] [OnUpdatePod] Updating 'LastStatus' of pod default/bronze-class-deploy-8-6fff566748-tt726 in metrics
I0409 14:53:16.405819       1 scheduler.go:172] [PostBind] Called for pod bronze-class-deploy-11-559c656b44-5grsk
I0409 14:53:16.405861       1 scheduler.go:190] [PostBind] Pod bronze-class-deploy-11-559c656b44-5grsk - Binding start: 2025-04-09 14:53:16.399739962 +0000 UTC m=+281.087110400, Binding end: 2025-04-09 14:53:16.405846885 +0000 UTC m=+281.093217323
I0409 14:53:16.405841       1 scheduler.go:255] [OnUpdatePod] Updating 'LastStatus' of pod default/bronze-class-deploy-16-74dd4696ff-mkf54 in metrics
I0409 14:53:16.405919       1 scheduler.go:197] [PostBind] Metrics updated for pod bronze-class-deploy-11-559c656b44-5grsk
I0409 14:53:16.414517       1 scheduler.go:255] [OnUpdatePod] Updating 'LastStatus' of pod default/bronze-class-deploy-11-559c656b44-5grsk in metrics
I0409 14:53:16.414774       1 scheduler.go:255] [OnUpdatePod] Updating 'LastStatus' of pod default/bronze-class-deploy-16-74dd4696ff-mkf54 in metrics
I0409 14:53:16.416543       1 scheduler.go:255] [OnUpdatePod] Updating 'LastStatus' of pod default/bronze-class-deploy-8-6fff566748-tt726 in metrics
I0409 14:53:17.399882       1 default_preemption.go:51] [PreEnqueue] PreEnqueue called for pod: bronze-class-deploy-3-775f4fbdd9-h8pjj
I0409 14:53:17.399907       1 default_preemption.go:52] [PreEnqueue] SchedulerName for pod bronze-class-deploy-3-775f4fbdd9-h8pjj: custom-scheduler
I0409 14:53:17.400210       1 scheduler.go:164] [PreBind] Validating pod bronze-class-deploy-3-775f4fbdd9-h8pjj before binding to node kwok-node-1
I0409 14:53:17.403847       1 scheduler.go:255] [OnUpdatePod] Updating 'LastStatus' of pod default/bronze-class-deploy-3-775f4fbdd9-h8pjj in metrics
I0409 14:53:17.404057       1 scheduler.go:172] [PostBind] Called for pod bronze-class-deploy-3-775f4fbdd9-h8pjj
I0409 14:53:17.404077       1 scheduler.go:190] [PostBind] Pod bronze-class-deploy-3-775f4fbdd9-h8pjj - Binding start: 2025-04-09 14:53:17.400226608 +0000 UTC m=+282.087597036, Binding end: 2025-04-09 14:53:17.404072797 +0000 UTC m=+282.091443225
I0409 14:53:17.404092       1 scheduler.go:197] [PostBind] Metrics updated for pod bronze-class-deploy-3-775f4fbdd9-h8pjj
I0409 14:53:17.412330       1 scheduler.go:255] [OnUpdatePod] Updating 'LastStatus' of pod default/bronze-class-deploy-3-775f4fbdd9-h8pjj in metrics
I0409 14:53:36.026559       1 default_preemption.go:51] [PreEnqueue] PreEnqueue called for pod: bronze-class-deploy-23-654ffb5cc5-nsc48
I0409 14:53:36.026602       1 default_preemption.go:52] [PreEnqueue] SchedulerName for pod bronze-class-deploy-23-654ffb5cc5-nsc48: custom-scheduler
I0409 14:53:36.026649       1 default_preemption.go:51] [PreEnqueue] PreEnqueue called for pod: bronze-class-deploy-30-56698788c5-dkftl
I0409 14:53:36.026654       1 default_preemption.go:52] [PreEnqueue] SchedulerName for pod bronze-class-deploy-30-56698788c5-dkftl: custom-scheduler
I0409 14:53:36.026694       1 scheduler.go:103] [HigherPrecedence] Final decision: Does bronze-class-deploy-30-56698788c5-dkftl have precedence over bronze-class-deploy-23-654ffb5cc5-nsc48? false
I0409 14:53:36.026721       1 default_preemption.go:51] [PreEnqueue] PreEnqueue called for pod: bronze-class-deploy-20-5fd9977fb4-kwjjw
I0409 14:53:36.026725       1 default_preemption.go:52] [PreEnqueue] SchedulerName for pod bronze-class-deploy-20-5fd9977fb4-kwjjw: custom-scheduler
I0409 14:53:36.026751       1 scheduler.go:103] [HigherPrecedence] Final decision: Does bronze-class-deploy-20-5fd9977fb4-kwjjw have precedence over bronze-class-deploy-23-654ffb5cc5-nsc48? false
I0409 14:53:36.026779       1 default_preemption.go:51] [PreEnqueue] PreEnqueue called for pod: bronze-class-deploy-28-946b5bff6-nnq2g
I0409 14:53:36.026784       1 default_preemption.go:52] [PreEnqueue] SchedulerName for pod bronze-class-deploy-28-946b5bff6-nnq2g: custom-scheduler
I0409 14:53:36.026813       1 scheduler.go:103] [HigherPrecedence] Final decision: Does bronze-class-deploy-28-946b5bff6-nnq2g have precedence over bronze-class-deploy-30-56698788c5-dkftl? true
I0409 14:53:36.026835       1 scheduler.go:103] [HigherPrecedence] Final decision: Does bronze-class-deploy-28-946b5bff6-nnq2g have precedence over bronze-class-deploy-23-654ffb5cc5-nsc48? true
I0409 14:53:36.026856       1 default_preemption.go:51] [PreEnqueue] PreEnqueue called for pod: bronze-class-deploy-25-b94944fb5-r6wph
I0409 14:53:36.026859       1 default_preemption.go:52] [PreEnqueue] SchedulerName for pod bronze-class-deploy-25-b94944fb5-r6wph: custom-scheduler
I0409 14:53:36.026882       1 scheduler.go:103] [HigherPrecedence] Final decision: Does bronze-class-deploy-25-b94944fb5-r6wph have precedence over bronze-class-deploy-23-654ffb5cc5-nsc48? true
I0409 14:53:36.026902       1 scheduler.go:103] [HigherPrecedence] Final decision: Does bronze-class-deploy-25-b94944fb5-r6wph have precedence over bronze-class-deploy-28-946b5bff6-nnq2g? false
I0409 14:53:36.026915       1 default_preemption.go:51] [PreEnqueue] PreEnqueue called for pod: bronze-class-deploy-31-77756c9778-d8hft
I0409 14:53:36.026919       1 default_preemption.go:52] [PreEnqueue] SchedulerName for pod bronze-class-deploy-31-77756c9778-d8hft: custom-scheduler
I0409 14:53:36.026946       1 scheduler.go:103] [HigherPrecedence] Final decision: Does bronze-class-deploy-31-77756c9778-d8hft have precedence over bronze-class-deploy-20-5fd9977fb4-kwjjw? true
I0409 14:53:36.026971       1 scheduler.go:103] [HigherPrecedence] Final decision: Does bronze-class-deploy-31-77756c9778-d8hft have precedence over bronze-class-deploy-28-946b5bff6-nnq2g? false
I0409 14:53:36.026981       1 default_preemption.go:51] [PreEnqueue] PreEnqueue called for pod: bronze-class-deploy-24-668b49b99b-m2rb7
I0409 14:53:36.026984       1 default_preemption.go:52] [PreEnqueue] SchedulerName for pod bronze-class-deploy-24-668b49b99b-m2rb7: custom-scheduler
I0409 14:53:36.027004       1 scheduler.go:103] [HigherPrecedence] Final decision: Does bronze-class-deploy-24-668b49b99b-m2rb7 have precedence over bronze-class-deploy-31-77756c9778-d8hft? false
I0409 14:53:36.027057       1 scheduler.go:103] [HigherPrecedence] Final decision: Does bronze-class-deploy-31-77756c9778-d8hft have precedence over bronze-class-deploy-25-b94944fb5-r6wph? false
I0409 14:53:36.027090       1 scheduler.go:103] [HigherPrecedence] Final decision: Does bronze-class-deploy-25-b94944fb5-r6wph have precedence over bronze-class-deploy-24-668b49b99b-m2rb7? true
I0409 14:53:36.027110       1 scheduler.go:103] [HigherPrecedence] Final decision: Does bronze-class-deploy-23-654ffb5cc5-nsc48 have precedence over bronze-class-deploy-30-56698788c5-dkftl? true
I0409 14:53:36.027132       1 scheduler.go:103] [HigherPrecedence] Final decision: Does bronze-class-deploy-23-654ffb5cc5-nsc48 have precedence over bronze-class-deploy-24-668b49b99b-m2rb7? false
I0409 14:53:36.027728       1 scheduler.go:103] [HigherPrecedence] Final decision: Does bronze-class-deploy-28-946b5bff6-nnq2g have precedence over bronze-class-deploy-29-7d6b766b6f-vd84q? true
I0409 14:53:36.027777       1 scheduler.go:103] [HigherPrecedence] Final decision: Does bronze-class-deploy-28-946b5bff6-nnq2g have precedence over bronze-class-deploy-16-74dd4696ff-mkf54? false
I0409 14:53:36.027795       1 scheduler.go:103] [HigherPrecedence] Final decision: Does bronze-class-deploy-28-946b5bff6-nnq2g have precedence over bronze-class-deploy-11-559c656b44-5grsk? false
I0409 14:53:36.027815       1 scheduler.go:103] [HigherPrecedence] Final decision: Does bronze-class-deploy-28-946b5bff6-nnq2g have precedence over bronze-class-deploy-8-6fff566748-tt726? false
I0409 14:53:36.027854       1 scheduler.go:103] [HigherPrecedence] Final decision: Does bronze-class-deploy-28-946b5bff6-nnq2g have precedence over bronze-class-deploy-3-775f4fbdd9-h8pjj? false
I0409 14:53:36.027911       1 default_preemption.go:37] "Preemption failed or not needed" pod="default/bronze-class-deploy-28-946b5bff6-nnq2g" status="0/2 nodes are available: 1 No preemption victims found for incoming pod, 1 Preemption is not helpful for scheduling."
I0409 14:53:36.028045       1 scheduler.go:103] [HigherPrecedence] Final decision: Does bronze-class-deploy-31-77756c9778-d8hft have precedence over bronze-class-deploy-24-668b49b99b-m2rb7? true
I0409 14:53:36.028078       1 scheduler.go:103] [HigherPrecedence] Final decision: Does bronze-class-deploy-31-77756c9778-d8hft have precedence over bronze-class-deploy-20-5fd9977fb4-kwjjw? true
I0409 14:53:36.028469       1 scheduler.go:103] [HigherPrecedence] Final decision: Does bronze-class-deploy-25-b94944fb5-r6wph have precedence over bronze-class-deploy-29-7d6b766b6f-vd84q? true
I0409 14:53:36.028503       1 scheduler.go:103] [HigherPrecedence] Final decision: Does bronze-class-deploy-25-b94944fb5-r6wph have precedence over bronze-class-deploy-16-74dd4696ff-mkf54? false
I0409 14:53:36.028518       1 scheduler.go:103] [HigherPrecedence] Final decision: Does bronze-class-deploy-25-b94944fb5-r6wph have precedence over bronze-class-deploy-11-559c656b44-5grsk? false
I0409 14:53:36.028532       1 scheduler.go:103] [HigherPrecedence] Final decision: Does bronze-class-deploy-25-b94944fb5-r6wph have precedence over bronze-class-deploy-8-6fff566748-tt726? false
I0409 14:53:36.028546       1 scheduler.go:103] [HigherPrecedence] Final decision: Does bronze-class-deploy-25-b94944fb5-r6wph have precedence over bronze-class-deploy-3-775f4fbdd9-h8pjj? false
I0409 14:53:36.028570       1 default_preemption.go:37] "Preemption failed or not needed" pod="default/bronze-class-deploy-25-b94944fb5-r6wph" status="0/2 nodes are available: 1 No preemption victims found for incoming pod, 1 Preemption is not helpful for scheduling."
I0409 14:53:36.028653       1 scheduler.go:103] [HigherPrecedence] Final decision: Does bronze-class-deploy-20-5fd9977fb4-kwjjw have precedence over bronze-class-deploy-24-668b49b99b-m2rb7? false
I0409 14:53:36.028683       1 scheduler.go:103] [HigherPrecedence] Final decision: Does bronze-class-deploy-24-668b49b99b-m2rb7 have precedence over bronze-class-deploy-23-654ffb5cc5-nsc48? true
I0409 14:53:36.028702       1 scheduler.go:103] [HigherPrecedence] Final decision: Does bronze-class-deploy-30-56698788c5-dkftl have precedence over bronze-class-deploy-23-654ffb5cc5-nsc48? false
I0409 14:53:36.029072       1 scheduler.go:103] [HigherPrecedence] Final decision: Does bronze-class-deploy-31-77756c9778-d8hft have precedence over bronze-class-deploy-29-7d6b766b6f-vd84q? true
I0409 14:53:36.029114       1 scheduler.go:103] [HigherPrecedence] Final decision: Does bronze-class-deploy-31-77756c9778-d8hft have precedence over bronze-class-deploy-16-74dd4696ff-mkf54? false
I0409 14:53:36.029135       1 scheduler.go:103] [HigherPrecedence] Final decision: Does bronze-class-deploy-31-77756c9778-d8hft have precedence over bronze-class-deploy-11-559c656b44-5grsk? false
I0409 14:53:36.029153       1 scheduler.go:103] [HigherPrecedence] Final decision: Does bronze-class-deploy-31-77756c9778-d8hft have precedence over bronze-class-deploy-8-6fff566748-tt726? false
I0409 14:53:36.029185       1 scheduler.go:103] [HigherPrecedence] Final decision: Does bronze-class-deploy-31-77756c9778-d8hft have precedence over bronze-class-deploy-3-775f4fbdd9-h8pjj? false
I0409 14:53:36.029219       1 default_preemption.go:37] "Preemption failed or not needed" pod="default/bronze-class-deploy-31-77756c9778-d8hft" status="0/2 nodes are available: 1 No preemption victims found for incoming pod, 1 Preemption is not helpful for scheduling."
I0409 14:53:36.029311       1 scheduler.go:103] [HigherPrecedence] Final decision: Does bronze-class-deploy-20-5fd9977fb4-kwjjw have precedence over bronze-class-deploy-23-654ffb5cc5-nsc48? false
I0409 14:53:36.029337       1 scheduler.go:103] [HigherPrecedence] Final decision: Does bronze-class-deploy-23-654ffb5cc5-nsc48 have precedence over bronze-class-deploy-30-56698788c5-dkftl? true
I0409 14:53:36.029722       1 scheduler.go:103] [HigherPrecedence] Final decision: Does bronze-class-deploy-24-668b49b99b-m2rb7 have precedence over bronze-class-deploy-29-7d6b766b6f-vd84q? true
I0409 14:53:36.029758       1 scheduler.go:103] [HigherPrecedence] Final decision: Does bronze-class-deploy-24-668b49b99b-m2rb7 have precedence over bronze-class-deploy-16-74dd4696ff-mkf54? false
I0409 14:53:36.029773       1 scheduler.go:103] [HigherPrecedence] Final decision: Does bronze-class-deploy-24-668b49b99b-m2rb7 have precedence over bronze-class-deploy-11-559c656b44-5grsk? false
I0409 14:53:36.029788       1 scheduler.go:103] [HigherPrecedence] Final decision: Does bronze-class-deploy-24-668b49b99b-m2rb7 have precedence over bronze-class-deploy-8-6fff566748-tt726? false
I0409 14:53:36.029810       1 scheduler.go:103] [HigherPrecedence] Final decision: Does bronze-class-deploy-24-668b49b99b-m2rb7 have precedence over bronze-class-deploy-3-775f4fbdd9-h8pjj? false
I0409 14:53:36.029841       1 default_preemption.go:37] "Preemption failed or not needed" pod="default/bronze-class-deploy-24-668b49b99b-m2rb7" status="0/2 nodes are available: 1 No preemption victims found for incoming pod, 1 Preemption is not helpful for scheduling."
I0409 14:53:36.029933       1 scheduler.go:103] [HigherPrecedence] Final decision: Does bronze-class-deploy-30-56698788c5-dkftl have precedence over bronze-class-deploy-20-5fd9977fb4-kwjjw? true
I0409 14:53:36.030340       1 scheduler.go:103] [HigherPrecedence] Final decision: Does bronze-class-deploy-23-654ffb5cc5-nsc48 have precedence over bronze-class-deploy-29-7d6b766b6f-vd84q? true
I0409 14:53:36.030412       1 scheduler.go:103] [HigherPrecedence] Final decision: Does bronze-class-deploy-23-654ffb5cc5-nsc48 have precedence over bronze-class-deploy-16-74dd4696ff-mkf54? false
I0409 14:53:36.030433       1 scheduler.go:103] [HigherPrecedence] Final decision: Does bronze-class-deploy-23-654ffb5cc5-nsc48 have precedence over bronze-class-deploy-11-559c656b44-5grsk? false
I0409 14:53:36.030451       1 scheduler.go:103] [HigherPrecedence] Final decision: Does bronze-class-deploy-23-654ffb5cc5-nsc48 have precedence over bronze-class-deploy-8-6fff566748-tt726? false
I0409 14:53:36.030470       1 scheduler.go:103] [HigherPrecedence] Final decision: Does bronze-class-deploy-23-654ffb5cc5-nsc48 have precedence over bronze-class-deploy-3-775f4fbdd9-h8pjj? false
I0409 14:53:36.030505       1 default_preemption.go:37] "Preemption failed or not needed" pod="default/bronze-class-deploy-23-654ffb5cc5-nsc48" status="0/2 nodes are available: 1 No preemption victims found for incoming pod, 1 Preemption is not helpful for scheduling."
I0409 14:53:36.031104       1 scheduler.go:103] [HigherPrecedence] Final decision: Does bronze-class-deploy-30-56698788c5-dkftl have precedence over bronze-class-deploy-29-7d6b766b6f-vd84q? true
I0409 14:53:36.031151       1 scheduler.go:103] [HigherPrecedence] Final decision: Does bronze-class-deploy-30-56698788c5-dkftl have precedence over bronze-class-deploy-16-74dd4696ff-mkf54? false
I0409 14:53:36.031170       1 scheduler.go:103] [HigherPrecedence] Final decision: Does bronze-class-deploy-30-56698788c5-dkftl have precedence over bronze-class-deploy-11-559c656b44-5grsk? false
I0409 14:53:36.031197       1 scheduler.go:103] [HigherPrecedence] Final decision: Does bronze-class-deploy-30-56698788c5-dkftl have precedence over bronze-class-deploy-8-6fff566748-tt726? false
I0409 14:53:36.031227       1 scheduler.go:103] [HigherPrecedence] Final decision: Does bronze-class-deploy-30-56698788c5-dkftl have precedence over bronze-class-deploy-3-775f4fbdd9-h8pjj? false
I0409 14:53:36.031268       1 default_preemption.go:37] "Preemption failed or not needed" pod="default/bronze-class-deploy-30-56698788c5-dkftl" status="0/2 nodes are available: 1 No preemption victims found for incoming pod, 1 Preemption is not helpful for scheduling."
I0409 14:53:36.031722       1 scheduler.go:103] [HigherPrecedence] Final decision: Does bronze-class-deploy-20-5fd9977fb4-kwjjw have precedence over bronze-class-deploy-29-7d6b766b6f-vd84q? true
I0409 14:53:36.031767       1 scheduler.go:103] [HigherPrecedence] Final decision: Does bronze-class-deploy-20-5fd9977fb4-kwjjw have precedence over bronze-class-deploy-16-74dd4696ff-mkf54? false
I0409 14:53:36.031786       1 scheduler.go:103] [HigherPrecedence] Final decision: Does bronze-class-deploy-20-5fd9977fb4-kwjjw have precedence over bronze-class-deploy-11-559c656b44-5grsk? false
I0409 14:53:36.031814       1 scheduler.go:103] [HigherPrecedence] Final decision: Does bronze-class-deploy-20-5fd9977fb4-kwjjw have precedence over bronze-class-deploy-8-6fff566748-tt726? false
I0409 14:53:36.031835       1 scheduler.go:103] [HigherPrecedence] Final decision: Does bronze-class-deploy-20-5fd9977fb4-kwjjw have precedence over bronze-class-deploy-3-775f4fbdd9-h8pjj? false
I0409 14:53:36.031851       1 default_preemption.go:37] "Preemption failed or not needed" pod="default/bronze-class-deploy-20-5fd9977fb4-kwjjw" status="0/2 nodes are available: 1 No preemption victims found for incoming pod, 1 Preemption is not helpful for scheduling."
I0409 14:54:06.027189       1 default_preemption.go:51] [PreEnqueue] PreEnqueue called for pod: bronze-class-deploy-30-56698788c5-dkftl
I0409 14:54:06.027212       1 default_preemption.go:52] [PreEnqueue] SchedulerName for pod bronze-class-deploy-30-56698788c5-dkftl: custom-scheduler
I0409 14:54:06.027257       1 default_preemption.go:51] [PreEnqueue] PreEnqueue called for pod: bronze-class-deploy-20-5fd9977fb4-kwjjw
I0409 14:54:06.027262       1 default_preemption.go:52] [PreEnqueue] SchedulerName for pod bronze-class-deploy-20-5fd9977fb4-kwjjw: custom-scheduler
I0409 14:54:06.027296       1 scheduler.go:103] [HigherPrecedence] Final decision: Does bronze-class-deploy-20-5fd9977fb4-kwjjw have precedence over bronze-class-deploy-30-56698788c5-dkftl? false
I0409 14:54:06.027322       1 default_preemption.go:51] [PreEnqueue] PreEnqueue called for pod: bronze-class-deploy-28-946b5bff6-nnq2g
I0409 14:54:06.027325       1 default_preemption.go:52] [PreEnqueue] SchedulerName for pod bronze-class-deploy-28-946b5bff6-nnq2g: custom-scheduler
I0409 14:54:06.027348       1 scheduler.go:103] [HigherPrecedence] Final decision: Does bronze-class-deploy-28-946b5bff6-nnq2g have precedence over bronze-class-deploy-30-56698788c5-dkftl? true
I0409 14:54:06.027396       1 default_preemption.go:51] [PreEnqueue] PreEnqueue called for pod: bronze-class-deploy-25-b94944fb5-r6wph
I0409 14:54:06.027404       1 default_preemption.go:52] [PreEnqueue] SchedulerName for pod bronze-class-deploy-25-b94944fb5-r6wph: custom-scheduler
I0409 14:54:06.027426       1 scheduler.go:103] [HigherPrecedence] Final decision: Does bronze-class-deploy-25-b94944fb5-r6wph have precedence over bronze-class-deploy-20-5fd9977fb4-kwjjw? true
I0409 14:54:06.027440       1 scheduler.go:103] [HigherPrecedence] Final decision: Does bronze-class-deploy-25-b94944fb5-r6wph have precedence over bronze-class-deploy-28-946b5bff6-nnq2g? false
I0409 14:54:06.027450       1 default_preemption.go:51] [PreEnqueue] PreEnqueue called for pod: bronze-class-deploy-31-77756c9778-d8hft
I0409 14:54:06.027453       1 default_preemption.go:52] [PreEnqueue] SchedulerName for pod bronze-class-deploy-31-77756c9778-d8hft: custom-scheduler
I0409 14:54:06.027482       1 scheduler.go:103] [HigherPrecedence] Final decision: Does bronze-class-deploy-31-77756c9778-d8hft have precedence over bronze-class-deploy-25-b94944fb5-r6wph? false
I0409 14:54:06.027505       1 default_preemption.go:51] [PreEnqueue] PreEnqueue called for pod: bronze-class-deploy-24-668b49b99b-m2rb7
I0409 14:54:06.027508       1 default_preemption.go:52] [PreEnqueue] SchedulerName for pod bronze-class-deploy-24-668b49b99b-m2rb7: custom-scheduler
I0409 14:54:06.027529       1 scheduler.go:103] [HigherPrecedence] Final decision: Does bronze-class-deploy-24-668b49b99b-m2rb7 have precedence over bronze-class-deploy-30-56698788c5-dkftl? true
I0409 14:54:06.027547       1 scheduler.go:103] [HigherPrecedence] Final decision: Does bronze-class-deploy-24-668b49b99b-m2rb7 have precedence over bronze-class-deploy-28-946b5bff6-nnq2g? false
I0409 14:54:06.027559       1 default_preemption.go:51] [PreEnqueue] PreEnqueue called for pod: bronze-class-deploy-23-654ffb5cc5-nsc48
I0409 14:54:06.027564       1 default_preemption.go:52] [PreEnqueue] SchedulerName for pod bronze-class-deploy-23-654ffb5cc5-nsc48: custom-scheduler
I0409 14:54:06.027587       1 scheduler.go:103] [HigherPrecedence] Final decision: Does bronze-class-deploy-23-654ffb5cc5-nsc48 have precedence over bronze-class-deploy-24-668b49b99b-m2rb7? false
I0409 14:54:06.027640       1 scheduler.go:103] [HigherPrecedence] Final decision: Does bronze-class-deploy-24-668b49b99b-m2rb7 have precedence over bronze-class-deploy-25-b94944fb5-r6wph? false
I0409 14:54:06.027661       1 scheduler.go:103] [HigherPrecedence] Final decision: Does bronze-class-deploy-25-b94944fb5-r6wph have precedence over bronze-class-deploy-23-654ffb5cc5-nsc48? true
I0409 14:54:06.027680       1 scheduler.go:103] [HigherPrecedence] Final decision: Does bronze-class-deploy-31-77756c9778-d8hft have precedence over bronze-class-deploy-20-5fd9977fb4-kwjjw? true
I0409 14:54:06.027706       1 scheduler.go:103] [HigherPrecedence] Final decision: Does bronze-class-deploy-31-77756c9778-d8hft have precedence over bronze-class-deploy-23-654ffb5cc5-nsc48? true
I0409 14:54:06.027958       1 scheduler.go:103] [HigherPrecedence] Final decision: Does bronze-class-deploy-28-946b5bff6-nnq2g have precedence over silver-class-deploy-21-7bf557854c-zflrc? true
I0409 14:54:06.028061       1 scheduler.go:103] [HigherPrecedence] Final decision: Does bronze-class-deploy-28-946b5bff6-nnq2g have precedence over silver-class-deploy-7-ff55f69ff-hwmfr? true
I0409 14:54:06.028110       1 scheduler.go:103] [HigherPrecedence] Final decision: Does bronze-class-deploy-28-946b5bff6-nnq2g have precedence over silver-class-deploy-22-8456bfbbc6-jrczs? true
I0409 14:54:06.028172       1 scheduler.go:103] [HigherPrecedence] Final decision: Does bronze-class-deploy-28-946b5bff6-nnq2g have precedence over silver-class-deploy-10-6866d9b887-l2866? true
I0409 14:54:06.028257       1 scheduler.go:103] [HigherPrecedence] Final decision: Does bronze-class-deploy-28-946b5bff6-nnq2g have precedence over silver-class-deploy-14-79f95c48b7-jh9nd? true
I0409 14:54:06.028298       1 scheduler.go:103] [HigherPrecedence] Final decision: Does bronze-class-deploy-28-946b5bff6-nnq2g have precedence over silver-class-deploy-15-cb96c7dc4-9m85g? true
I0409 14:54:06.028391       1 scheduler.go:103] [HigherPrecedence] Final decision: Does bronze-class-deploy-28-946b5bff6-nnq2g have precedence over silver-class-deploy-17-59cbf4bc88-s2ngm? true
I0409 14:54:06.028435       1 scheduler.go:103] [HigherPrecedence] Final decision: Does bronze-class-deploy-28-946b5bff6-nnq2g have precedence over silver-class-deploy-18-5dd44b47c5-7d2lh? true
I0409 14:54:06.028487       1 scheduler.go:103] [HigherPrecedence] Final decision: Does bronze-class-deploy-28-946b5bff6-nnq2g have precedence over silver-class-deploy-19-7cc4c5b78-v9p7f? true
I0409 14:54:06.028529       1 scheduler.go:103] [HigherPrecedence] Final decision: Does bronze-class-deploy-28-946b5bff6-nnq2g have precedence over silver-class-deploy-32-84b675c847-wwmws? true
I0409 14:54:06.028588       1 scheduler.go:103] [HigherPrecedence] Final decision: Does bronze-class-deploy-28-946b5bff6-nnq2g have precedence over bronze-class-deploy-29-7d6b766b6f-vd84q? true
I0409 14:54:06.028640       1 scheduler.go:103] [HigherPrecedence] Final decision: Does bronze-class-deploy-28-946b5bff6-nnq2g have precedence over bronze-class-deploy-16-74dd4696ff-mkf54? false
I0409 14:54:06.028665       1 scheduler.go:103] [HigherPrecedence] Final decision: Does bronze-class-deploy-28-946b5bff6-nnq2g have precedence over bronze-class-deploy-11-559c656b44-5grsk? true
I0409 14:54:06.028720       1 scheduler.go:103] [HigherPrecedence] Final decision: Does bronze-class-deploy-28-946b5bff6-nnq2g have precedence over bronze-class-deploy-8-6fff566748-tt726? true
I0409 14:54:06.028769       1 scheduler.go:103] [HigherPrecedence] Final decision: Does bronze-class-deploy-28-946b5bff6-nnq2g have precedence over bronze-class-deploy-3-775f4fbdd9-h8pjj? true
I0409 14:54:06.036422       1 scheduler.go:255] [OnUpdatePod] Updating 'LastStatus' of pod default/bronze-class-deploy-3-775f4fbdd9-h8pjj in metrics
I0409 14:54:06.042198       1 scheduler.go:255] [OnUpdatePod] Updating 'LastStatus' of pod default/bronze-class-deploy-3-775f4fbdd9-h8pjj in metrics
I0409 14:54:06.046016       1 default_preemption.go:39] "Preemption successful" pod="default/bronze-class-deploy-28-946b5bff6-nnq2g" nominatedNode="kwok-node-1"
I0409 14:54:06.046205       1 scheduler.go:286] [OnDeletePod] Checking the state of pod default/bronze-class-deploy-3-775f4fbdd9-h8pjj in metrics
I0409 14:54:06.055456       1 default_preemption.go:51] [PreEnqueue] PreEnqueue called for pod: bronze-class-deploy-3-775f4fbdd9-5jd8w
I0409 14:54:06.055493       1 default_preemption.go:52] [PreEnqueue] SchedulerName for pod bronze-class-deploy-3-775f4fbdd9-5jd8w: custom-scheduler
I0409 14:54:06.055446       1 scheduler.go:205] [OnAddPod] Pod added: default/bronze-class-deploy-3-775f4fbdd9-5jd8w, Annotations: map[acceptablePreemptionOverhead:0.05 controller:bronze-controller-3 kwok.x-k8s.io/usage-cpu:1m kwok.x-k8s.io/usage-memory:1Mi qosMeasuring:average slo:0.5]
I0409 14:54:06.055537       1 scheduler.go:103] [HigherPrecedence] Final decision: Does bronze-class-deploy-24-668b49b99b-m2rb7 have precedence over bronze-class-deploy-31-77756c9778-d8hft? false
I0409 14:54:06.055564       1 scheduler.go:103] [HigherPrecedence] Final decision: Does bronze-class-deploy-31-77756c9778-d8hft have precedence over bronze-class-deploy-30-56698788c5-dkftl? true
I0409 14:54:06.055605       1 scheduler.go:103] [HigherPrecedence] Final decision: Does bronze-class-deploy-23-654ffb5cc5-nsc48 have precedence over bronze-class-deploy-20-5fd9977fb4-kwjjw? true
I0409 14:54:06.055635       1 scheduler.go:103] [HigherPrecedence] Final decision: Does bronze-class-deploy-23-654ffb5cc5-nsc48 have precedence over bronze-class-deploy-30-56698788c5-dkftl? true
I0409 14:54:06.055723       1 scheduler.go:255] [OnUpdatePod] Updating 'LastStatus' of pod default/bronze-class-deploy-28-946b5bff6-nnq2g in metrics
I0409 14:54:06.055801       1 scheduler.go:103] [HigherPrecedence] Final decision: Does bronze-class-deploy-3-775f4fbdd9-5jd8w have precedence over bronze-class-deploy-24-668b49b99b-m2rb7? true
I0409 14:54:06.055825       1 scheduler.go:103] [HigherPrecedence] Final decision: Does bronze-class-deploy-3-775f4fbdd9-5jd8w have precedence over bronze-class-deploy-31-77756c9778-d8hft? true
I0409 14:54:06.056124       1 scheduler.go:103] [HigherPrecedence] Final decision: Does bronze-class-deploy-25-b94944fb5-r6wph have precedence over silver-class-deploy-21-7bf557854c-zflrc? true
I0409 14:54:06.056231       1 scheduler.go:103] [HigherPrecedence] Final decision: Does bronze-class-deploy-25-b94944fb5-r6wph have precedence over silver-class-deploy-7-ff55f69ff-hwmfr? true
I0409 14:54:06.056272       1 scheduler.go:103] [HigherPrecedence] Final decision: Does bronze-class-deploy-25-b94944fb5-r6wph have precedence over silver-class-deploy-22-8456bfbbc6-jrczs? true
I0409 14:54:06.056317       1 scheduler.go:103] [HigherPrecedence] Final decision: Does bronze-class-deploy-25-b94944fb5-r6wph have precedence over silver-class-deploy-10-6866d9b887-l2866? true
I0409 14:54:06.056444       1 scheduler.go:103] [HigherPrecedence] Final decision: Does bronze-class-deploy-25-b94944fb5-r6wph have precedence over silver-class-deploy-14-79f95c48b7-jh9nd? true
I0409 14:54:06.056485       1 scheduler.go:103] [HigherPrecedence] Final decision: Does bronze-class-deploy-25-b94944fb5-r6wph have precedence over silver-class-deploy-15-cb96c7dc4-9m85g? true
I0409 14:54:06.056522       1 scheduler.go:103] [HigherPrecedence] Final decision: Does bronze-class-deploy-25-b94944fb5-r6wph have precedence over silver-class-deploy-17-59cbf4bc88-s2ngm? true
I0409 14:54:06.056558       1 scheduler.go:103] [HigherPrecedence] Final decision: Does bronze-class-deploy-25-b94944fb5-r6wph have precedence over silver-class-deploy-18-5dd44b47c5-7d2lh? true
I0409 14:54:06.056587       1 scheduler.go:103] [HigherPrecedence] Final decision: Does bronze-class-deploy-25-b94944fb5-r6wph have precedence over silver-class-deploy-19-7cc4c5b78-v9p7f? true
I0409 14:54:06.056619       1 scheduler.go:103] [HigherPrecedence] Final decision: Does bronze-class-deploy-25-b94944fb5-r6wph have precedence over silver-class-deploy-32-84b675c847-wwmws? true
I0409 14:54:06.056644       1 scheduler.go:103] [HigherPrecedence] Final decision: Does bronze-class-deploy-25-b94944fb5-r6wph have precedence over bronze-class-deploy-29-7d6b766b6f-vd84q? true
I0409 14:54:06.056676       1 scheduler.go:103] [HigherPrecedence] Final decision: Does bronze-class-deploy-25-b94944fb5-r6wph have precedence over bronze-class-deploy-16-74dd4696ff-mkf54? false
I0409 14:54:06.056705       1 scheduler.go:103] [HigherPrecedence] Final decision: Does bronze-class-deploy-25-b94944fb5-r6wph have precedence over bronze-class-deploy-11-559c656b44-5grsk? false
I0409 14:54:06.056735       1 scheduler.go:103] [HigherPrecedence] Final decision: Does bronze-class-deploy-25-b94944fb5-r6wph have precedence over bronze-class-deploy-8-6fff566748-tt726? false
I0409 14:54:06.065457       1 scheduler.go:255] [OnUpdatePod] Updating 'LastStatus' of pod default/bronze-class-deploy-29-7d6b766b6f-vd84q in metrics
I0409 14:54:06.073427       1 scheduler.go:255] [OnUpdatePod] Updating 'LastStatus' of pod default/bronze-class-deploy-29-7d6b766b6f-vd84q in metrics
I0409 14:54:06.079334       1 default_preemption.go:51] [PreEnqueue] PreEnqueue called for pod: bronze-class-deploy-29-7d6b766b6f-s6rrh
I0409 14:54:06.079388       1 default_preemption.go:52] [PreEnqueue] SchedulerName for pod bronze-class-deploy-29-7d6b766b6f-s6rrh: custom-scheduler
W0409 14:54:06.079422       1 scheduler.go:118] [cacheMiss] Metrics not found for pod: default/bronze-class-deploy-29-7d6b766b6f-s6rrh
W0409 14:54:06.079429       1 scheduler.go:125] [WaitForPodsOnCache] Pod bronze-class-deploy-29-7d6b766b6f-s6rrh not found in cache. Retrying...
I0409 14:54:06.079450       1 scheduler.go:205] [OnAddPod] Pod added: default/bronze-class-deploy-29-7d6b766b6f-s6rrh, Annotations: map[acceptablePreemptionOverhead:0.05 controller:bronze-controller-29 kwok.x-k8s.io/usage-cpu:1m kwok.x-k8s.io/usage-memory:1Mi qosMeasuring:average slo:0.5]
I0409 14:54:06.081335       1 scheduler.go:286] [OnDeletePod] Checking the state of pod default/bronze-class-deploy-29-7d6b766b6f-vd84q in metrics
I0409 14:54:06.179918       1 scheduler.go:103] [HigherPrecedence] Final decision: Does bronze-class-deploy-29-7d6b766b6f-s6rrh have precedence over bronze-class-deploy-31-77756c9778-d8hft? false
I0409 14:54:06.180064       1 scheduler.go:103] [HigherPrecedence] Final decision: Does bronze-class-deploy-25-b94944fb5-r6wph have precedence over bronze-class-deploy-28-946b5bff6-nnq2g? false
I0409 14:54:06.180090       1 default_preemption.go:39] "Preemption successful" pod="default/bronze-class-deploy-25-b94944fb5-r6wph" nominatedNode="kwok-node-1"
I0409 14:54:06.186875       1 scheduler.go:255] [OnUpdatePod] Updating 'LastStatus' of pod default/bronze-class-deploy-25-b94944fb5-r6wph in metrics
I0409 14:54:06.186932       1 scheduler.go:103] [HigherPrecedence] Final decision: Does bronze-class-deploy-31-77756c9778-d8hft have precedence over bronze-class-deploy-23-654ffb5cc5-nsc48? true
I0409 14:54:06.186951       1 scheduler.go:103] [HigherPrecedence] Final decision: Does bronze-class-deploy-31-77756c9778-d8hft have precedence over bronze-class-deploy-29-7d6b766b6f-s6rrh? true
I0409 14:54:06.186968       1 scheduler.go:103] [HigherPrecedence] Final decision: Does bronze-class-deploy-24-668b49b99b-m2rb7 have precedence over bronze-class-deploy-29-7d6b766b6f-s6rrh? true
I0409 14:54:06.187297       1 scheduler.go:103] [HigherPrecedence] Final decision: Does bronze-class-deploy-3-775f4fbdd9-5jd8w have precedence over silver-class-deploy-21-7bf557854c-zflrc? true
I0409 14:54:06.187413       1 scheduler.go:103] [HigherPrecedence] Final decision: Does bronze-class-deploy-3-775f4fbdd9-5jd8w have precedence over silver-class-deploy-7-ff55f69ff-hwmfr? true
I0409 14:54:06.187468       1 scheduler.go:103] [HigherPrecedence] Final decision: Does bronze-class-deploy-3-775f4fbdd9-5jd8w have precedence over silver-class-deploy-22-8456bfbbc6-jrczs? true
I0409 14:54:06.187523       1 scheduler.go:103] [HigherPrecedence] Final decision: Does bronze-class-deploy-3-775f4fbdd9-5jd8w have precedence over silver-class-deploy-10-6866d9b887-l2866? true
I0409 14:54:06.187597       1 scheduler.go:103] [HigherPrecedence] Final decision: Does bronze-class-deploy-3-775f4fbdd9-5jd8w have precedence over silver-class-deploy-14-79f95c48b7-jh9nd? true
I0409 14:54:06.187633       1 scheduler.go:103] [HigherPrecedence] Final decision: Does bronze-class-deploy-3-775f4fbdd9-5jd8w have precedence over silver-class-deploy-15-cb96c7dc4-9m85g? true
I0409 14:54:06.187685       1 scheduler.go:103] [HigherPrecedence] Final decision: Does bronze-class-deploy-3-775f4fbdd9-5jd8w have precedence over silver-class-deploy-17-59cbf4bc88-s2ngm? true
I0409 14:54:06.187723       1 scheduler.go:103] [HigherPrecedence] Final decision: Does bronze-class-deploy-3-775f4fbdd9-5jd8w have precedence over silver-class-deploy-18-5dd44b47c5-7d2lh? true
I0409 14:54:06.187763       1 scheduler.go:103] [HigherPrecedence] Final decision: Does bronze-class-deploy-3-775f4fbdd9-5jd8w have precedence over silver-class-deploy-19-7cc4c5b78-v9p7f? true
I0409 14:54:06.187796       1 scheduler.go:103] [HigherPrecedence] Final decision: Does bronze-class-deploy-3-775f4fbdd9-5jd8w have precedence over silver-class-deploy-32-84b675c847-wwmws? true
I0409 14:54:06.187836       1 scheduler.go:103] [HigherPrecedence] Final decision: Does bronze-class-deploy-3-775f4fbdd9-5jd8w have precedence over bronze-class-deploy-8-6fff566748-tt726? true
I0409 14:54:06.187872       1 scheduler.go:103] [HigherPrecedence] Final decision: Does bronze-class-deploy-3-775f4fbdd9-5jd8w have precedence over bronze-class-deploy-16-74dd4696ff-mkf54? false
I0409 14:54:06.187896       1 scheduler.go:103] [HigherPrecedence] Final decision: Does bronze-class-deploy-3-775f4fbdd9-5jd8w have precedence over bronze-class-deploy-11-559c656b44-5grsk? true
I0409 14:54:06.195720       1 scheduler.go:255] [OnUpdatePod] Updating 'LastStatus' of pod default/bronze-class-deploy-11-559c656b44-5grsk in metrics
I0409 14:54:06.201873       1 scheduler.go:255] [OnUpdatePod] Updating 'LastStatus' of pod default/bronze-class-deploy-11-559c656b44-5grsk in metrics
I0409 14:54:06.205516       1 scheduler.go:103] [HigherPrecedence] Final decision: Does bronze-class-deploy-3-775f4fbdd9-5jd8w have precedence over bronze-class-deploy-28-946b5bff6-nnq2g? false
I0409 14:54:06.205556       1 scheduler.go:103] [HigherPrecedence] Final decision: Does bronze-class-deploy-3-775f4fbdd9-5jd8w have precedence over bronze-class-deploy-25-b94944fb5-r6wph? true
I0409 14:54:06.205660       1 scheduler.go:286] [OnDeletePod] Checking the state of pod default/bronze-class-deploy-11-559c656b44-5grsk in metrics
I0409 14:54:06.206588       1 default_preemption.go:51] [PreEnqueue] PreEnqueue called for pod: bronze-class-deploy-11-559c656b44-n59zx
I0409 14:54:06.206613       1 default_preemption.go:52] [PreEnqueue] SchedulerName for pod bronze-class-deploy-11-559c656b44-n59zx: custom-scheduler
W0409 14:54:06.206660       1 scheduler.go:118] [cacheMiss] Metrics not found for pod: default/bronze-class-deploy-11-559c656b44-n59zx
W0409 14:54:06.206667       1 scheduler.go:125] [WaitForPodsOnCache] Pod bronze-class-deploy-11-559c656b44-n59zx not found in cache. Retrying...
I0409 14:54:06.206589       1 scheduler.go:205] [OnAddPod] Pod added: default/bronze-class-deploy-11-559c656b44-n59zx, Annotations: map[acceptablePreemptionOverhead:0.05 controller:bronze-controller-11 kwok.x-k8s.io/usage-cpu:1m kwok.x-k8s.io/usage-memory:1Mi qosMeasuring:average slo:0.5]
I0409 14:54:06.214252       1 default_preemption.go:39] "Preemption successful" pod="default/bronze-class-deploy-3-775f4fbdd9-5jd8w" nominatedNode="kwok-node-1"
I0409 14:54:06.214257       1 scheduler.go:255] [OnUpdatePod] Updating 'LastStatus' of pod default/bronze-class-deploy-25-b94944fb5-r6wph in metrics
I0409 14:54:06.307403       1 scheduler.go:103] [HigherPrecedence] Final decision: Does bronze-class-deploy-11-559c656b44-n59zx have precedence over bronze-class-deploy-24-668b49b99b-m2rb7? true
I0409 14:54:06.307445       1 scheduler.go:103] [HigherPrecedence] Final decision: Does bronze-class-deploy-11-559c656b44-n59zx have precedence over bronze-class-deploy-31-77756c9778-d8hft? true
I0409 14:54:06.313859       1 scheduler.go:103] [HigherPrecedence] Final decision: Does bronze-class-deploy-31-77756c9778-d8hft have precedence over bronze-class-deploy-23-654ffb5cc5-nsc48? true
I0409 14:54:06.313907       1 scheduler.go:103] [HigherPrecedence] Final decision: Does bronze-class-deploy-31-77756c9778-d8hft have precedence over bronze-class-deploy-24-668b49b99b-m2rb7? true
I0409 14:54:06.313928       1 scheduler.go:103] [HigherPrecedence] Final decision: Does bronze-class-deploy-29-7d6b766b6f-s6rrh have precedence over bronze-class-deploy-24-668b49b99b-m2rb7? false
I0409 14:54:06.314012       1 scheduler.go:255] [OnUpdatePod] Updating 'LastStatus' of pod default/bronze-class-deploy-3-775f4fbdd9-5jd8w in metrics
I0409 14:54:06.314236       1 scheduler.go:103] [HigherPrecedence] Final decision: Does bronze-class-deploy-24-668b49b99b-m2rb7 have precedence over bronze-class-deploy-23-654ffb5cc5-nsc48? true
I0409 14:54:06.314269       1 scheduler.go:164] [PreBind] Validating pod bronze-class-deploy-11-559c656b44-n59zx before binding to node kwok-node-1
I0409 14:54:06.314275       1 scheduler.go:103] [HigherPrecedence] Final decision: Does bronze-class-deploy-24-668b49b99b-m2rb7 have precedence over bronze-class-deploy-29-7d6b766b6f-s6rrh? true
I0409 14:54:06.314541       1 scheduler.go:103] [HigherPrecedence] Final decision: Does bronze-class-deploy-31-77756c9778-d8hft have precedence over silver-class-deploy-21-7bf557854c-zflrc? true
I0409 14:54:06.314641       1 scheduler.go:103] [HigherPrecedence] Final decision: Does bronze-class-deploy-31-77756c9778-d8hft have precedence over silver-class-deploy-7-ff55f69ff-hwmfr? true
I0409 14:54:06.314675       1 scheduler.go:103] [HigherPrecedence] Final decision: Does bronze-class-deploy-31-77756c9778-d8hft have precedence over silver-class-deploy-22-8456bfbbc6-jrczs? true
I0409 14:54:06.314713       1 scheduler.go:103] [HigherPrecedence] Final decision: Does bronze-class-deploy-31-77756c9778-d8hft have precedence over silver-class-deploy-10-6866d9b887-l2866? true
I0409 14:54:06.314783       1 scheduler.go:103] [HigherPrecedence] Final decision: Does bronze-class-deploy-31-77756c9778-d8hft have precedence over silver-class-deploy-14-79f95c48b7-jh9nd? true
I0409 14:54:06.314818       1 scheduler.go:103] [HigherPrecedence] Final decision: Does bronze-class-deploy-31-77756c9778-d8hft have precedence over silver-class-deploy-15-cb96c7dc4-9m85g? true
I0409 14:54:06.314862       1 scheduler.go:103] [HigherPrecedence] Final decision: Does bronze-class-deploy-31-77756c9778-d8hft have precedence over silver-class-deploy-17-59cbf4bc88-s2ngm? true
I0409 14:54:06.314892       1 scheduler.go:103] [HigherPrecedence] Final decision: Does bronze-class-deploy-31-77756c9778-d8hft have precedence over silver-class-deploy-18-5dd44b47c5-7d2lh? true
I0409 14:54:06.314916       1 scheduler.go:103] [HigherPrecedence] Final decision: Does bronze-class-deploy-31-77756c9778-d8hft have precedence over silver-class-deploy-19-7cc4c5b78-v9p7f? true
I0409 14:54:06.314949       1 scheduler.go:103] [HigherPrecedence] Final decision: Does bronze-class-deploy-31-77756c9778-d8hft have precedence over silver-class-deploy-32-84b675c847-wwmws? true
I0409 14:54:06.314974       1 scheduler.go:103] [HigherPrecedence] Final decision: Does bronze-class-deploy-31-77756c9778-d8hft have precedence over bronze-class-deploy-8-6fff566748-tt726? false
I0409 14:54:06.314997       1 scheduler.go:103] [HigherPrecedence] Final decision: Does bronze-class-deploy-31-77756c9778-d8hft have precedence over bronze-class-deploy-16-74dd4696ff-mkf54? false
I0409 14:54:06.315011       1 scheduler.go:103] [HigherPrecedence] Final decision: Does bronze-class-deploy-31-77756c9778-d8hft have precedence over bronze-class-deploy-11-559c656b44-n59zx? false
I0409 14:54:06.319652       1 scheduler.go:255] [OnUpdatePod] Updating 'LastStatus' of pod default/bronze-class-deploy-11-559c656b44-n59zx in metrics
I0409 14:54:06.319739       1 scheduler.go:172] [PostBind] Called for pod bronze-class-deploy-11-559c656b44-n59zx
I0409 14:54:06.319750       1 scheduler.go:190] [PostBind] Pod bronze-class-deploy-11-559c656b44-n59zx - Binding start: 2025-04-09 14:54:06.314276197 +0000 UTC m=+331.001646635, Binding end: 2025-04-09 14:54:06.319747396 +0000 UTC m=+331.007117824
I0409 14:54:06.319763       1 scheduler.go:197] [PostBind] Metrics updated for pod bronze-class-deploy-11-559c656b44-n59zx
I0409 14:54:06.322640       1 scheduler.go:255] [OnUpdatePod] Updating 'LastStatus' of pod default/silver-class-deploy-32-84b675c847-wwmws in metrics
I0409 14:54:06.327974       1 scheduler.go:255] [OnUpdatePod] Updating 'LastStatus' of pod default/bronze-class-deploy-11-559c656b44-n59zx in metrics
I0409 14:54:06.331585       1 scheduler.go:255] [OnUpdatePod] Updating 'LastStatus' of pod default/silver-class-deploy-32-84b675c847-wwmws in metrics
I0409 14:54:06.333713       1 scheduler.go:286] [OnDeletePod] Checking the state of pod default/silver-class-deploy-32-84b675c847-wwmws in metrics
I0409 14:54:06.333777       1 scheduler.go:103] [HigherPrecedence] Final decision: Does bronze-class-deploy-31-77756c9778-d8hft have precedence over bronze-class-deploy-28-946b5bff6-nnq2g? false
I0409 14:54:06.333799       1 scheduler.go:103] [HigherPrecedence] Final decision: Does bronze-class-deploy-31-77756c9778-d8hft have precedence over bronze-class-deploy-3-775f4fbdd9-5jd8w? false
I0409 14:54:06.333838       1 default_preemption.go:39] "Preemption successful" pod="default/bronze-class-deploy-31-77756c9778-d8hft" nominatedNode="kwok-node-1"
I0409 14:54:06.337905       1 default_preemption.go:51] [PreEnqueue] PreEnqueue called for pod: silver-class-deploy-32-84b675c847-vchfj
I0409 14:54:06.337932       1 default_preemption.go:52] [PreEnqueue] SchedulerName for pod silver-class-deploy-32-84b675c847-vchfj: custom-scheduler
I0409 14:54:06.337950       1 scheduler.go:205] [OnAddPod] Pod added: default/silver-class-deploy-32-84b675c847-vchfj, Annotations: map[acceptablePreemptionOverhead:0.05 controller:silver-controller-32 kwok.x-k8s.io/usage-cpu:1m kwok.x-k8s.io/usage-memory:1Mi qosMeasuring:average slo:0.9]
W0409 14:54:06.337967       1 scheduler.go:118] [cacheMiss] Metrics not found for pod: default/silver-class-deploy-32-84b675c847-vchfj
W0409 14:54:06.337974       1 scheduler.go:125] [WaitForPodsOnCache] Pod silver-class-deploy-32-84b675c847-vchfj not found in cache. Retrying...
I0409 14:54:06.343636       1 scheduler.go:255] [OnUpdatePod] Updating 'LastStatus' of pod default/bronze-class-deploy-31-77756c9778-d8hft in metrics
I0409 14:54:06.438423       1 scheduler.go:103] [HigherPrecedence] Final decision: Does bronze-class-deploy-24-668b49b99b-m2rb7 have precedence over bronze-class-deploy-23-654ffb5cc5-nsc48? true
I0409 14:54:06.438463       1 scheduler.go:103] [HigherPrecedence] Final decision: Does bronze-class-deploy-24-668b49b99b-m2rb7 have precedence over bronze-class-deploy-29-7d6b766b6f-s6rrh? true
I0409 14:54:06.438720       1 scheduler.go:103] [HigherPrecedence] Final decision: Does bronze-class-deploy-29-7d6b766b6f-s6rrh have precedence over bronze-class-deploy-23-654ffb5cc5-nsc48? false
I0409 14:54:06.438757       1 scheduler.go:103] [HigherPrecedence] Final decision: Does bronze-class-deploy-23-654ffb5cc5-nsc48 have precedence over bronze-class-deploy-30-56698788c5-dkftl? true
I0409 14:54:06.438780       1 scheduler.go:103] [HigherPrecedence] Final decision: Does bronze-class-deploy-20-5fd9977fb4-kwjjw have precedence over bronze-class-deploy-30-56698788c5-dkftl? false
I0409 14:54:06.438802       1 scheduler.go:164] [PreBind] Validating pod silver-class-deploy-32-84b675c847-vchfj before binding to node kwok-node-1
I0409 14:54:06.439028       1 scheduler.go:103] [HigherPrecedence] Final decision: Does bronze-class-deploy-24-668b49b99b-m2rb7 have precedence over silver-class-deploy-21-7bf557854c-zflrc? true
I0409 14:54:06.439148       1 scheduler.go:103] [HigherPrecedence] Final decision: Does bronze-class-deploy-24-668b49b99b-m2rb7 have precedence over silver-class-deploy-7-ff55f69ff-hwmfr? true
I0409 14:54:06.439192       1 scheduler.go:103] [HigherPrecedence] Final decision: Does bronze-class-deploy-24-668b49b99b-m2rb7 have precedence over silver-class-deploy-22-8456bfbbc6-jrczs? true
I0409 14:54:06.439243       1 scheduler.go:103] [HigherPrecedence] Final decision: Does bronze-class-deploy-24-668b49b99b-m2rb7 have precedence over silver-class-deploy-10-6866d9b887-l2866? true
I0409 14:54:06.439307       1 scheduler.go:103] [HigherPrecedence] Final decision: Does bronze-class-deploy-24-668b49b99b-m2rb7 have precedence over silver-class-deploy-14-79f95c48b7-jh9nd? true
I0409 14:54:06.439341       1 scheduler.go:103] [HigherPrecedence] Final decision: Does bronze-class-deploy-24-668b49b99b-m2rb7 have precedence over silver-class-deploy-15-cb96c7dc4-9m85g? true
I0409 14:54:06.439421       1 scheduler.go:103] [HigherPrecedence] Final decision: Does bronze-class-deploy-24-668b49b99b-m2rb7 have precedence over silver-class-deploy-17-59cbf4bc88-s2ngm? true
I0409 14:54:06.439461       1 scheduler.go:103] [HigherPrecedence] Final decision: Does bronze-class-deploy-24-668b49b99b-m2rb7 have precedence over silver-class-deploy-18-5dd44b47c5-7d2lh? true
I0409 14:54:06.439485       1 scheduler.go:103] [HigherPrecedence] Final decision: Does bronze-class-deploy-24-668b49b99b-m2rb7 have precedence over silver-class-deploy-19-7cc4c5b78-v9p7f? true
I0409 14:54:06.439520       1 scheduler.go:103] [HigherPrecedence] Final decision: Does bronze-class-deploy-24-668b49b99b-m2rb7 have precedence over bronze-class-deploy-11-559c656b44-n59zx? false
I0409 14:54:06.439538       1 scheduler.go:103] [HigherPrecedence] Final decision: Does bronze-class-deploy-24-668b49b99b-m2rb7 have precedence over bronze-class-deploy-8-6fff566748-tt726? false
I0409 14:54:06.439558       1 scheduler.go:103] [HigherPrecedence] Final decision: Does bronze-class-deploy-24-668b49b99b-m2rb7 have precedence over bronze-class-deploy-16-74dd4696ff-mkf54? false
I0409 14:54:06.442495       1 scheduler.go:255] [OnUpdatePod] Updating 'LastStatus' of pod default/silver-class-deploy-32-84b675c847-vchfj in metrics
I0409 14:54:06.442564       1 scheduler.go:172] [PostBind] Called for pod silver-class-deploy-32-84b675c847-vchfj
I0409 14:54:06.442574       1 scheduler.go:190] [PostBind] Pod silver-class-deploy-32-84b675c847-vchfj - Binding start: 2025-04-09 14:54:06.4388275 +0000 UTC m=+331.126197938, Binding end: 2025-04-09 14:54:06.442571617 +0000 UTC m=+331.129942055
I0409 14:54:06.442591       1 scheduler.go:197] [PostBind] Metrics updated for pod silver-class-deploy-32-84b675c847-vchfj
I0409 14:54:06.447348       1 scheduler.go:255] [OnUpdatePod] Updating 'LastStatus' of pod default/silver-class-deploy-19-7cc4c5b78-v9p7f in metrics
I0409 14:54:06.450568       1 scheduler.go:255] [OnUpdatePod] Updating 'LastStatus' of pod default/silver-class-deploy-22-8456bfbbc6-jrczs in metrics
I0409 14:54:06.450596       1 scheduler.go:255] [OnUpdatePod] Updating 'LastStatus' of pod default/silver-class-deploy-32-84b675c847-vchfj in metrics
I0409 14:54:06.454880       1 scheduler.go:255] [OnUpdatePod] Updating 'LastStatus' of pod default/silver-class-deploy-19-7cc4c5b78-v9p7f in metrics
I0409 14:54:06.460695       1 scheduler.go:255] [OnUpdatePod] Updating 'LastStatus' of pod default/silver-class-deploy-22-8456bfbbc6-jrczs in metrics
I0409 14:54:06.461575       1 default_preemption.go:51] [PreEnqueue] PreEnqueue called for pod: silver-class-deploy-19-7cc4c5b78-sfn22
I0409 14:54:06.461602       1 default_preemption.go:52] [PreEnqueue] SchedulerName for pod silver-class-deploy-19-7cc4c5b78-sfn22: custom-scheduler
I0409 14:54:06.461606       1 scheduler.go:205] [OnAddPod] Pod added: default/silver-class-deploy-19-7cc4c5b78-sfn22, Annotations: map[acceptablePreemptionOverhead:0.05 controller:silver-controller-19 kwok.x-k8s.io/usage-cpu:1m kwok.x-k8s.io/usage-memory:1Mi qosMeasuring:average slo:0.9]
W0409 14:54:06.461639       1 scheduler.go:118] [cacheMiss] Metrics not found for pod: default/silver-class-deploy-19-7cc4c5b78-sfn22
W0409 14:54:06.461661       1 scheduler.go:125] [WaitForPodsOnCache] Pod silver-class-deploy-19-7cc4c5b78-sfn22 not found in cache. Retrying...
I0409 14:54:06.464928       1 scheduler.go:286] [OnDeletePod] Checking the state of pod default/silver-class-deploy-19-7cc4c5b78-v9p7f in metrics
I0409 14:54:06.467855       1 scheduler.go:286] [OnDeletePod] Checking the state of pod default/silver-class-deploy-22-8456bfbbc6-jrczs in metrics
I0409 14:54:06.468047       1 scheduler.go:205] [OnAddPod] Pod added: default/silver-class-deploy-22-8456bfbbc6-5gkgw, Annotations: map[acceptablePreemptionOverhead:0.05 controller:silver-controller-22 kwok.x-k8s.io/usage-cpu:1m kwok.x-k8s.io/usage-memory:1Mi qosMeasuring:average slo:0.9]
I0409 14:54:06.562121       1 scheduler.go:103] [HigherPrecedence] Final decision: Does silver-class-deploy-19-7cc4c5b78-sfn22 have precedence over bronze-class-deploy-30-56698788c5-dkftl? false
I0409 14:54:06.562303       1 scheduler.go:103] [HigherPrecedence] Final decision: Does bronze-class-deploy-24-668b49b99b-m2rb7 have precedence over bronze-class-deploy-28-946b5bff6-nnq2g? false
I0409 14:54:06.562352       1 scheduler.go:103] [HigherPrecedence] Final decision: Does bronze-class-deploy-24-668b49b99b-m2rb7 have precedence over bronze-class-deploy-3-775f4fbdd9-5jd8w? false
I0409 14:54:06.562400       1 scheduler.go:103] [HigherPrecedence] Final decision: Does bronze-class-deploy-24-668b49b99b-m2rb7 have precedence over bronze-class-deploy-31-77756c9778-d8hft? false
I0409 14:54:06.562418       1 default_preemption.go:39] "Preemption successful" pod="default/bronze-class-deploy-24-668b49b99b-m2rb7" nominatedNode="kwok-node-1"
I0409 14:54:06.562423       1 default_preemption.go:51] [PreEnqueue] PreEnqueue called for pod: silver-class-deploy-22-8456bfbbc6-5gkgw
I0409 14:54:06.562432       1 default_preemption.go:52] [PreEnqueue] SchedulerName for pod silver-class-deploy-22-8456bfbbc6-5gkgw: custom-scheduler
I0409 14:54:06.562466       1 scheduler.go:103] [HigherPrecedence] Final decision: Does silver-class-deploy-22-8456bfbbc6-5gkgw have precedence over bronze-class-deploy-29-7d6b766b6f-s6rrh? false
I0409 14:54:06.570237       1 scheduler.go:255] [OnUpdatePod] Updating 'LastStatus' of pod default/bronze-class-deploy-24-668b49b99b-m2rb7 in metrics
I0409 14:54:06.570348       1 scheduler.go:103] [HigherPrecedence] Final decision: Does bronze-class-deploy-29-7d6b766b6f-s6rrh have precedence over bronze-class-deploy-30-56698788c5-dkftl? false
I0409 14:54:06.570409       1 scheduler.go:103] [HigherPrecedence] Final decision: Does bronze-class-deploy-30-56698788c5-dkftl have precedence over silver-class-deploy-22-8456bfbbc6-5gkgw? true
I0409 14:54:06.570429       1 scheduler.go:103] [HigherPrecedence] Final decision: Does silver-class-deploy-19-7cc4c5b78-sfn22 have precedence over bronze-class-deploy-20-5fd9977fb4-kwjjw? false
I0409 14:54:06.570453       1 scheduler.go:103] [HigherPrecedence] Final decision: Does bronze-class-deploy-20-5fd9977fb4-kwjjw have precedence over silver-class-deploy-22-8456bfbbc6-5gkgw? true
I0409 14:54:06.570864       1 scheduler.go:103] [HigherPrecedence] Final decision: Does bronze-class-deploy-23-654ffb5cc5-nsc48 have precedence over silver-class-deploy-21-7bf557854c-zflrc? true
I0409 14:54:06.570969       1 scheduler.go:103] [HigherPrecedence] Final decision: Does bronze-class-deploy-23-654ffb5cc5-nsc48 have precedence over silver-class-deploy-7-ff55f69ff-hwmfr? true
I0409 14:54:06.571053       1 scheduler.go:103] [HigherPrecedence] Final decision: Does bronze-class-deploy-23-654ffb5cc5-nsc48 have precedence over silver-class-deploy-10-6866d9b887-l2866? true
I0409 14:54:06.571140       1 scheduler.go:103] [HigherPrecedence] Final decision: Does bronze-class-deploy-23-654ffb5cc5-nsc48 have precedence over silver-class-deploy-14-79f95c48b7-jh9nd? true
I0409 14:54:06.571188       1 scheduler.go:103] [HigherPrecedence] Final decision: Does bronze-class-deploy-23-654ffb5cc5-nsc48 have precedence over silver-class-deploy-15-cb96c7dc4-9m85g? true
I0409 14:54:06.571229       1 scheduler.go:103] [HigherPrecedence] Final decision: Does bronze-class-deploy-23-654ffb5cc5-nsc48 have precedence over silver-class-deploy-17-59cbf4bc88-s2ngm? true
I0409 14:54:06.571267       1 scheduler.go:103] [HigherPrecedence] Final decision: Does bronze-class-deploy-23-654ffb5cc5-nsc48 have precedence over silver-class-deploy-18-5dd44b47c5-7d2lh? true
I0409 14:54:06.571293       1 scheduler.go:103] [HigherPrecedence] Final decision: Does bronze-class-deploy-23-654ffb5cc5-nsc48 have precedence over bronze-class-deploy-16-74dd4696ff-mkf54? false
I0409 14:54:06.571314       1 scheduler.go:103] [HigherPrecedence] Final decision: Does bronze-class-deploy-23-654ffb5cc5-nsc48 have precedence over bronze-class-deploy-11-559c656b44-n59zx? false
I0409 14:54:06.571329       1 scheduler.go:103] [HigherPrecedence] Final decision: Does bronze-class-deploy-23-654ffb5cc5-nsc48 have precedence over bronze-class-deploy-8-6fff566748-tt726? false
I0409 14:54:06.578899       1 scheduler.go:255] [OnUpdatePod] Updating 'LastStatus' of pod default/silver-class-deploy-18-5dd44b47c5-7d2lh in metrics
I0409 14:54:06.584536       1 scheduler.go:255] [OnUpdatePod] Updating 'LastStatus' of pod default/silver-class-deploy-18-5dd44b47c5-7d2lh in metrics
I0409 14:54:06.588348       1 scheduler.go:103] [HigherPrecedence] Final decision: Does bronze-class-deploy-23-654ffb5cc5-nsc48 have precedence over bronze-class-deploy-28-946b5bff6-nnq2g? false
I0409 14:54:06.588424       1 scheduler.go:103] [HigherPrecedence] Final decision: Does bronze-class-deploy-23-654ffb5cc5-nsc48 have precedence over bronze-class-deploy-3-775f4fbdd9-5jd8w? false
I0409 14:54:06.588451       1 scheduler.go:103] [HigherPrecedence] Final decision: Does bronze-class-deploy-23-654ffb5cc5-nsc48 have precedence over bronze-class-deploy-31-77756c9778-d8hft? false
I0409 14:54:06.588475       1 scheduler.go:286] [OnDeletePod] Checking the state of pod default/silver-class-deploy-18-5dd44b47c5-7d2lh in metrics
I0409 14:54:06.588535       1 scheduler.go:103] [HigherPrecedence] Final decision: Does bronze-class-deploy-23-654ffb5cc5-nsc48 have precedence over bronze-class-deploy-24-668b49b99b-m2rb7? false
I0409 14:54:06.588555       1 default_preemption.go:39] "Preemption successful" pod="default/bronze-class-deploy-23-654ffb5cc5-nsc48" nominatedNode="kwok-node-1"
I0409 14:54:06.591236       1 scheduler.go:205] [OnAddPod] Pod added: default/silver-class-deploy-18-5dd44b47c5-6tvlk, Annotations: map[acceptablePreemptionOverhead:0.05 controller:silver-controller-18 kwok.x-k8s.io/usage-cpu:1m kwok.x-k8s.io/usage-memory:1Mi qosMeasuring:average slo:0.9]
I0409 14:54:06.591314       1 default_preemption.go:51] [PreEnqueue] PreEnqueue called for pod: silver-class-deploy-18-5dd44b47c5-6tvlk
I0409 14:54:06.591327       1 default_preemption.go:52] [PreEnqueue] SchedulerName for pod silver-class-deploy-18-5dd44b47c5-6tvlk: custom-scheduler
W0409 14:54:06.591381       1 scheduler.go:118] [cacheMiss] Metrics not found for pod: default/silver-class-deploy-18-5dd44b47c5-6tvlk
W0409 14:54:06.591397       1 scheduler.go:125] [WaitForPodsOnCache] Pod silver-class-deploy-18-5dd44b47c5-6tvlk not found in cache. Retrying...
I0409 14:54:06.595438       1 scheduler.go:255] [OnUpdatePod] Updating 'LastStatus' of pod default/bronze-class-deploy-23-654ffb5cc5-nsc48 in metrics
I0409 14:54:06.692094       1 scheduler.go:103] [HigherPrecedence] Final decision: Does silver-class-deploy-18-5dd44b47c5-6tvlk have precedence over bronze-class-deploy-29-7d6b766b6f-s6rrh? false
I0409 14:54:06.692192       1 scheduler.go:103] [HigherPrecedence] Final decision: Does bronze-class-deploy-29-7d6b766b6f-s6rrh have precedence over bronze-class-deploy-20-5fd9977fb4-kwjjw? false
I0409 14:54:06.692217       1 scheduler.go:103] [HigherPrecedence] Final decision: Does bronze-class-deploy-20-5fd9977fb4-kwjjw have precedence over silver-class-deploy-18-5dd44b47c5-6tvlk? true
I0409 14:54:06.692238       1 scheduler.go:103] [HigherPrecedence] Final decision: Does silver-class-deploy-19-7cc4c5b78-sfn22 have precedence over silver-class-deploy-22-8456bfbbc6-5gkgw? false
I0409 14:54:06.692259       1 scheduler.go:103] [HigherPrecedence] Final decision: Does silver-class-deploy-22-8456bfbbc6-5gkgw have precedence over silver-class-deploy-18-5dd44b47c5-6tvlk? true
I0409 14:54:06.692660       1 scheduler.go:103] [HigherPrecedence] Final decision: Does bronze-class-deploy-30-56698788c5-dkftl have precedence over silver-class-deploy-21-7bf557854c-zflrc? true
I0409 14:54:06.692763       1 scheduler.go:103] [HigherPrecedence] Final decision: Does bronze-class-deploy-30-56698788c5-dkftl have precedence over silver-class-deploy-7-ff55f69ff-hwmfr? true
I0409 14:54:06.692844       1 scheduler.go:103] [HigherPrecedence] Final decision: Does bronze-class-deploy-30-56698788c5-dkftl have precedence over silver-class-deploy-10-6866d9b887-l2866? true
I0409 14:54:06.692931       1 scheduler.go:103] [HigherPrecedence] Final decision: Does bronze-class-deploy-30-56698788c5-dkftl have precedence over silver-class-deploy-14-79f95c48b7-jh9nd? true
I0409 14:54:06.692981       1 scheduler.go:103] [HigherPrecedence] Final decision: Does bronze-class-deploy-30-56698788c5-dkftl have precedence over silver-class-deploy-15-cb96c7dc4-9m85g? true
I0409 14:54:06.693032       1 scheduler.go:103] [HigherPrecedence] Final decision: Does bronze-class-deploy-30-56698788c5-dkftl have precedence over silver-class-deploy-17-59cbf4bc88-s2ngm? true
I0409 14:54:06.693074       1 scheduler.go:103] [HigherPrecedence] Final decision: Does bronze-class-deploy-30-56698788c5-dkftl have precedence over bronze-class-deploy-8-6fff566748-tt726? false
I0409 14:54:06.693098       1 scheduler.go:103] [HigherPrecedence] Final decision: Does bronze-class-deploy-30-56698788c5-dkftl have precedence over bronze-class-deploy-16-74dd4696ff-mkf54? false
I0409 14:54:06.693113       1 scheduler.go:103] [HigherPrecedence] Final decision: Does bronze-class-deploy-30-56698788c5-dkftl have precedence over bronze-class-deploy-11-559c656b44-n59zx? false
I0409 14:54:06.700833       1 scheduler.go:255] [OnUpdatePod] Updating 'LastStatus' of pod default/silver-class-deploy-21-7bf557854c-zflrc in metrics
I0409 14:54:06.706437       1 scheduler.go:255] [OnUpdatePod] Updating 'LastStatus' of pod default/silver-class-deploy-21-7bf557854c-zflrc in metrics
I0409 14:54:06.709760       1 scheduler.go:103] [HigherPrecedence] Final decision: Does bronze-class-deploy-30-56698788c5-dkftl have precedence over bronze-class-deploy-28-946b5bff6-nnq2g? false
I0409 14:54:06.709795       1 scheduler.go:103] [HigherPrecedence] Final decision: Does bronze-class-deploy-30-56698788c5-dkftl have precedence over bronze-class-deploy-3-775f4fbdd9-5jd8w? false
I0409 14:54:06.709811       1 scheduler.go:103] [HigherPrecedence] Final decision: Does bronze-class-deploy-30-56698788c5-dkftl have precedence over bronze-class-deploy-31-77756c9778-d8hft? false
I0409 14:54:06.709827       1 scheduler.go:103] [HigherPrecedence] Final decision: Does bronze-class-deploy-30-56698788c5-dkftl have precedence over bronze-class-deploy-24-668b49b99b-m2rb7? false
I0409 14:54:06.709841       1 scheduler.go:103] [HigherPrecedence] Final decision: Does bronze-class-deploy-30-56698788c5-dkftl have precedence over bronze-class-deploy-23-654ffb5cc5-nsc48? false
I0409 14:54:06.709858       1 default_preemption.go:39] "Preemption successful" pod="default/bronze-class-deploy-30-56698788c5-dkftl" nominatedNode="kwok-node-1"
I0409 14:54:06.709878       1 scheduler.go:286] [OnDeletePod] Checking the state of pod default/silver-class-deploy-21-7bf557854c-zflrc in metrics
I0409 14:54:06.711024       1 default_preemption.go:51] [PreEnqueue] PreEnqueue called for pod: silver-class-deploy-21-7bf557854c-5rmcc
I0409 14:54:06.711050       1 default_preemption.go:52] [PreEnqueue] SchedulerName for pod silver-class-deploy-21-7bf557854c-5rmcc: custom-scheduler
I0409 14:54:06.711053       1 scheduler.go:205] [OnAddPod] Pod added: default/silver-class-deploy-21-7bf557854c-5rmcc, Annotations: map[acceptablePreemptionOverhead:0.05 controller:silver-controller-21 kwok.x-k8s.io/usage-cpu:1m kwok.x-k8s.io/usage-memory:1Mi qosMeasuring:average slo:0.9]
W0409 14:54:06.711086       1 scheduler.go:118] [cacheMiss] Metrics not found for pod: default/silver-class-deploy-21-7bf557854c-5rmcc
W0409 14:54:06.711132       1 scheduler.go:125] [WaitForPodsOnCache] Pod silver-class-deploy-21-7bf557854c-5rmcc not found in cache. Retrying...
I0409 14:54:06.718665       1 scheduler.go:255] [OnUpdatePod] Updating 'LastStatus' of pod default/bronze-class-deploy-30-56698788c5-dkftl in metrics
I0409 14:54:06.812028       1 scheduler.go:103] [HigherPrecedence] Final decision: Does silver-class-deploy-21-7bf557854c-5rmcc have precedence over bronze-class-deploy-29-7d6b766b6f-s6rrh? false
I0409 14:54:06.812150       1 scheduler.go:103] [HigherPrecedence] Final decision: Does bronze-class-deploy-29-7d6b766b6f-s6rrh have precedence over silver-class-deploy-22-8456bfbbc6-5gkgw? true
I0409 14:54:06.812178       1 scheduler.go:103] [HigherPrecedence] Final decision: Does bronze-class-deploy-29-7d6b766b6f-s6rrh have precedence over silver-class-deploy-21-7bf557854c-5rmcc? true
I0409 14:54:06.812531       1 scheduler.go:103] [HigherPrecedence] Final decision: Does bronze-class-deploy-20-5fd9977fb4-kwjjw have precedence over bronze-class-deploy-11-559c656b44-n59zx? false
I0409 14:54:06.812591       1 scheduler.go:103] [HigherPrecedence] Final decision: Does bronze-class-deploy-20-5fd9977fb4-kwjjw have precedence over silver-class-deploy-7-ff55f69ff-hwmfr? true
I0409 14:54:06.812658       1 scheduler.go:103] [HigherPrecedence] Final decision: Does bronze-class-deploy-20-5fd9977fb4-kwjjw have precedence over silver-class-deploy-10-6866d9b887-l2866? true
I0409 14:54:06.812728       1 scheduler.go:103] [HigherPrecedence] Final decision: Does bronze-class-deploy-20-5fd9977fb4-kwjjw have precedence over silver-class-deploy-14-79f95c48b7-jh9nd? true
I0409 14:54:06.812771       1 scheduler.go:103] [HigherPrecedence] Final decision: Does bronze-class-deploy-20-5fd9977fb4-kwjjw have precedence over silver-class-deploy-15-cb96c7dc4-9m85g? true
I0409 14:54:06.812808       1 scheduler.go:103] [HigherPrecedence] Final decision: Does bronze-class-deploy-20-5fd9977fb4-kwjjw have precedence over silver-class-deploy-17-59cbf4bc88-s2ngm? true
I0409 14:54:06.812845       1 scheduler.go:103] [HigherPrecedence] Final decision: Does bronze-class-deploy-20-5fd9977fb4-kwjjw have precedence over bronze-class-deploy-8-6fff566748-tt726? false
I0409 14:54:06.812860       1 scheduler.go:103] [HigherPrecedence] Final decision: Does bronze-class-deploy-20-5fd9977fb4-kwjjw have precedence over bronze-class-deploy-16-74dd4696ff-mkf54? false
I0409 14:54:06.820437       1 scheduler.go:255] [OnUpdatePod] Updating 'LastStatus' of pod default/silver-class-deploy-17-59cbf4bc88-s2ngm in metrics
I0409 14:54:06.825825       1 scheduler.go:255] [OnUpdatePod] Updating 'LastStatus' of pod default/silver-class-deploy-17-59cbf4bc88-s2ngm in metrics
I0409 14:54:06.828067       1 scheduler.go:103] [HigherPrecedence] Final decision: Does bronze-class-deploy-20-5fd9977fb4-kwjjw have precedence over bronze-class-deploy-28-946b5bff6-nnq2g? false
I0409 14:54:06.828085       1 scheduler.go:286] [OnDeletePod] Checking the state of pod default/silver-class-deploy-17-59cbf4bc88-s2ngm in metrics
I0409 14:54:06.828127       1 scheduler.go:103] [HigherPrecedence] Final decision: Does bronze-class-deploy-20-5fd9977fb4-kwjjw have precedence over bronze-class-deploy-3-775f4fbdd9-5jd8w? false
I0409 14:54:06.828147       1 scheduler.go:103] [HigherPrecedence] Final decision: Does bronze-class-deploy-20-5fd9977fb4-kwjjw have precedence over bronze-class-deploy-31-77756c9778-d8hft? false
I0409 14:54:06.828166       1 scheduler.go:103] [HigherPrecedence] Final decision: Does bronze-class-deploy-20-5fd9977fb4-kwjjw have precedence over bronze-class-deploy-24-668b49b99b-m2rb7? false
I0409 14:54:06.828198       1 scheduler.go:103] [HigherPrecedence] Final decision: Does bronze-class-deploy-20-5fd9977fb4-kwjjw have precedence over bronze-class-deploy-23-654ffb5cc5-nsc48? false
I0409 14:54:06.828226       1 scheduler.go:103] [HigherPrecedence] Final decision: Does bronze-class-deploy-20-5fd9977fb4-kwjjw have precedence over bronze-class-deploy-30-56698788c5-dkftl? false
I0409 14:54:06.828246       1 default_preemption.go:39] "Preemption successful" pod="default/bronze-class-deploy-20-5fd9977fb4-kwjjw" nominatedNode="kwok-node-1"
I0409 14:54:06.829785       1 default_preemption.go:51] [PreEnqueue] PreEnqueue called for pod: silver-class-deploy-17-59cbf4bc88-qzxbk
I0409 14:54:06.829809       1 default_preemption.go:52] [PreEnqueue] SchedulerName for pod silver-class-deploy-17-59cbf4bc88-qzxbk: custom-scheduler
W0409 14:54:06.829845       1 scheduler.go:118] [cacheMiss] Metrics not found for pod: default/silver-class-deploy-17-59cbf4bc88-qzxbk
