I0123 20:13:52.676292       1 serving.go:386] Generated self-signed cert in-memory
W0123 20:13:52.677623       1 client_config.go:659] Neither --kubeconfig nor --master was specified.  Using the inClusterConfig.  This might not work.
I0123 20:13:53.701132       1 scheduler.go:213] [OnAddPod] Pod adicionado: kube-system/coredns-6f6b679f8f-j8ddm, Anotações: map[]
I0123 20:13:53.707297       1 scheduler.go:69] Estado no Informer: map[]
I0123 20:13:53.707430       1 scheduler.go:70] Estado real no cluster: map[]
I0123 20:13:53.707474       1 scheduler.go:213] [OnAddPod] Pod adicionado: kube-system/custom-scheduler-868c6bbc7d-tz2br, Anotações: map[]
I0123 20:13:53.710389       1 scheduler.go:69] Estado no Informer: map[]
I0123 20:13:53.710518       1 scheduler.go:70] Estado real no cluster: map[]
I0123 20:13:53.710625       1 scheduler.go:213] [OnAddPod] Pod adicionado: kube-system/etcd-minikube, Anotações: map[kubeadm.kubernetes.io/etcd.advertise-client-urls:https://192.168.39.253:2379 kubernetes.io/config.hash:83b49ae0e8ec1d939c80919a7e7e502b kubernetes.io/config.mirror:83b49ae0e8ec1d939c80919a7e7e502b kubernetes.io/config.seen:2025-01-23T13:21:10.529429156Z kubernetes.io/config.source:file]
I0123 20:13:53.713737       1 scheduler.go:69] Estado no Informer: map[kubeadm.kubernetes.io/etcd.advertise-client-urls:https://192.168.39.253:2379 kubernetes.io/config.hash:83b49ae0e8ec1d939c80919a7e7e502b kubernetes.io/config.mirror:83b49ae0e8ec1d939c80919a7e7e502b kubernetes.io/config.seen:2025-01-23T13:21:10.529429156Z kubernetes.io/config.source:file]
I0123 20:13:53.716239       1 scheduler.go:70] Estado real no cluster: map[kubeadm.kubernetes.io/etcd.advertise-client-urls:https://192.168.39.253:2379 kubernetes.io/config.hash:83b49ae0e8ec1d939c80919a7e7e502b kubernetes.io/config.mirror:83b49ae0e8ec1d939c80919a7e7e502b kubernetes.io/config.seen:2025-01-23T13:21:10.529429156Z kubernetes.io/config.source:file]
I0123 20:13:53.716993       1 scheduler.go:213] [OnAddPod] Pod adicionado: kube-system/kube-apiserver-minikube, Anotações: map[kubeadm.kubernetes.io/kube-apiserver.advertise-address.endpoint:192.168.39.253:8443 kubernetes.io/config.hash:c85c19863b26fc8fc8ebf5568d420510 kubernetes.io/config.mirror:c85c19863b26fc8fc8ebf5568d420510 kubernetes.io/config.seen:2025-01-23T13:21:10.529440623Z kubernetes.io/config.source:file]
I0123 20:13:53.722391       1 scheduler.go:69] Estado no Informer: map[kubeadm.kubernetes.io/kube-apiserver.advertise-address.endpoint:192.168.39.253:8443 kubernetes.io/config.hash:c85c19863b26fc8fc8ebf5568d420510 kubernetes.io/config.mirror:c85c19863b26fc8fc8ebf5568d420510 kubernetes.io/config.seen:2025-01-23T13:21:10.529440623Z kubernetes.io/config.source:file]
I0123 20:13:53.722529       1 scheduler.go:70] Estado real no cluster: map[kubeadm.kubernetes.io/kube-apiserver.advertise-address.endpoint:192.168.39.253:8443 kubernetes.io/config.hash:c85c19863b26fc8fc8ebf5568d420510 kubernetes.io/config.mirror:c85c19863b26fc8fc8ebf5568d420510 kubernetes.io/config.seen:2025-01-23T13:21:10.529440623Z kubernetes.io/config.source:file]
I0123 20:13:53.722664       1 scheduler.go:213] [OnAddPod] Pod adicionado: kube-system/kube-controller-manager-minikube, Anotações: map[kubernetes.io/config.hash:6e07439efa4d6dab7ea55fed1a35452a kubernetes.io/config.mirror:6e07439efa4d6dab7ea55fed1a35452a kubernetes.io/config.seen:2025-01-23T13:21:10.529446212Z kubernetes.io/config.source:file]
I0123 20:13:53.725446       1 scheduler.go:69] Estado no Informer: map[kubernetes.io/config.hash:6e07439efa4d6dab7ea55fed1a35452a kubernetes.io/config.mirror:6e07439efa4d6dab7ea55fed1a35452a kubernetes.io/config.seen:2025-01-23T13:21:10.529446212Z kubernetes.io/config.source:file]
I0123 20:13:53.725531       1 scheduler.go:70] Estado real no cluster: map[kubernetes.io/config.hash:6e07439efa4d6dab7ea55fed1a35452a kubernetes.io/config.mirror:6e07439efa4d6dab7ea55fed1a35452a kubernetes.io/config.seen:2025-01-23T13:21:10.529446212Z kubernetes.io/config.source:file]
I0123 20:13:53.726142       1 scheduler.go:213] [OnAddPod] Pod adicionado: kube-system/kube-proxy-4x8nj, Anotações: map[]
I0123 20:13:53.729280       1 scheduler.go:69] Estado no Informer: map[]
I0123 20:13:53.729346       1 scheduler.go:70] Estado real no cluster: map[]
I0123 20:13:53.729693       1 scheduler.go:213] [OnAddPod] Pod adicionado: kube-system/kube-scheduler-minikube, Anotações: map[kubernetes.io/config.hash:e039200acb850c82bb901653cc38ff6e kubernetes.io/config.mirror:e039200acb850c82bb901653cc38ff6e kubernetes.io/config.seen:2025-01-23T13:21:10.529450432Z kubernetes.io/config.source:file]
I0123 20:13:53.733310       1 scheduler.go:69] Estado no Informer: map[kubernetes.io/config.hash:e039200acb850c82bb901653cc38ff6e kubernetes.io/config.mirror:e039200acb850c82bb901653cc38ff6e kubernetes.io/config.seen:2025-01-23T13:21:10.529450432Z kubernetes.io/config.source:file]
I0123 20:13:53.733709       1 scheduler.go:70] Estado real no cluster: map[kubernetes.io/config.hash:e039200acb850c82bb901653cc38ff6e kubernetes.io/config.mirror:e039200acb850c82bb901653cc38ff6e kubernetes.io/config.seen:2025-01-23T13:21:10.529450432Z kubernetes.io/config.source:file]
I0123 20:13:53.734218       1 scheduler.go:213] [OnAddPod] Pod adicionado: kube-system/storage-provisioner, Anotações: map[kubectl.kubernetes.io/last-applied-configuration:{"apiVersion":"v1","kind":"Pod","metadata":{"annotations":{},"labels":{"addonmanager.kubernetes.io/mode":"Reconcile","integration-test":"storage-provisioner"},"name":"storage-provisioner","namespace":"kube-system"},"spec":{"containers":[{"command":["/storage-provisioner"],"image":"gcr.io/k8s-minikube/storage-provisioner:v5","imagePullPolicy":"IfNotPresent","name":"storage-provisioner","volumeMounts":[{"mountPath":"/tmp","name":"tmp"}]}],"hostNetwork":true,"serviceAccountName":"storage-provisioner","volumes":[{"hostPath":{"path":"/tmp","type":"Directory"},"name":"tmp"}]}}
]
I0123 20:13:53.739328       1 scheduler.go:69] Estado no Informer: map[kubectl.kubernetes.io/last-applied-configuration:{"apiVersion":"v1","kind":"Pod","metadata":{"annotations":{},"labels":{"addonmanager.kubernetes.io/mode":"Reconcile","integration-test":"storage-provisioner"},"name":"storage-provisioner","namespace":"kube-system"},"spec":{"containers":[{"command":["/storage-provisioner"],"image":"gcr.io/k8s-minikube/storage-provisioner:v5","imagePullPolicy":"IfNotPresent","name":"storage-provisioner","volumeMounts":[{"mountPath":"/tmp","name":"tmp"}]}],"hostNetwork":true,"serviceAccountName":"storage-provisioner","volumes":[{"hostPath":{"path":"/tmp","type":"Directory"},"name":"tmp"}]}}
]
I0123 20:13:53.740030       1 scheduler.go:70] Estado real no cluster: map[kubectl.kubernetes.io/last-applied-configuration:{"apiVersion":"v1","kind":"Pod","metadata":{"annotations":{},"labels":{"addonmanager.kubernetes.io/mode":"Reconcile","integration-test":"storage-provisioner"},"name":"storage-provisioner","namespace":"kube-system"},"spec":{"containers":[{"command":["/storage-provisioner"],"image":"gcr.io/k8s-minikube/storage-provisioner:v5","imagePullPolicy":"IfNotPresent","name":"storage-provisioner","volumeMounts":[{"mountPath":"/tmp","name":"tmp"}]}],"hostNetwork":true,"serviceAccountName":"storage-provisioner","volumes":[{"hostPath":{"path":"/tmp","type":"Directory"},"name":"tmp"}]}}
]
I0123 20:13:53.782699       1 scheduler.go:634] PodInformer sincronizado com sucesso
I0123 20:13:53.788053       1 server.go:167] "Starting Kubernetes Scheduler" version="v0.0.0-master+$Format:%H$"
I0123 20:13:53.788189       1 server.go:169] "Golang settings" GOGC="" GOMAXPROCS="" GOTRACEBACK=""
I0123 20:13:53.794207       1 secure_serving.go:213] Serving securely on [::]:10259
I0123 20:13:53.794442       1 leaderelection.go:254] attempting to acquire leader lease kube-system/kube-scheduler...
I0123 20:13:53.794766       1 tlsconfig.go:243] "Starting DynamicServingCertificateController"
I0123 20:13:53.795282       1 requestheader_controller.go:172] Starting RequestHeaderAuthRequestController
I0123 20:13:53.795737       1 shared_informer.go:313] Waiting for caches to sync for RequestHeaderAuthRequestController
I0123 20:13:53.795426       1 configmap_cafile_content.go:205] "Starting controller" name="client-ca::kube-system::extension-apiserver-authentication::client-ca-file"
I0123 20:13:53.795979       1 shared_informer.go:313] Waiting for caches to sync for client-ca::kube-system::extension-apiserver-authentication::client-ca-file
I0123 20:13:53.797632       1 configmap_cafile_content.go:205] "Starting controller" name="client-ca::kube-system::extension-apiserver-authentication::requestheader-client-ca-file"
I0123 20:13:53.797727       1 shared_informer.go:313] Waiting for caches to sync for client-ca::kube-system::extension-apiserver-authentication::requestheader-client-ca-file
I0123 20:13:53.810133       1 leaderelection.go:268] successfully acquired lease kube-system/kube-scheduler
I0123 20:13:53.896402       1 shared_informer.go:320] Caches are synced for RequestHeaderAuthRequestController
I0123 20:13:53.896689       1 shared_informer.go:320] Caches are synced for client-ca::kube-system::extension-apiserver-authentication::client-ca-file
I0123 20:13:53.898472       1 shared_informer.go:320] Caches are synced for client-ca::kube-system::extension-apiserver-authentication::requestheader-client-ca-file
I0123 20:15:20.066415       1 scheduler.go:213] [OnAddPod] Pod adicionado: default/test-deployment2-59c6b78cd5-srwkk, Anotações: map[controller:test-controller2]
I0123 20:15:20.079536       1 scheduler.go:145] [Reserve] resources reserved at node minikube for pod test-deployment2-59c6b78cd5-srwkk_default at 2025-01-23 20:15:20.079493706 +0000 UTC m=+87.977115764
I0123 20:15:20.085697       1 types.go:743] [ControllerName] Verificando as anotações do pod default/test-deployment2-59c6b78cd5-srwkk
I0123 20:15:20.086722       1 types.go:761] [ControllerName] Anotação 'controller' encontrada para o pod default/test-deployment2-59c6b78cd5-srwkk: test-controller2
I0123 20:15:20.199623       1 scheduler.go:69] Estado no Informer: map[controller:test-controller2]
I0123 20:15:20.203462       1 scheduler.go:70] Estado real no cluster: map[controller:test-controller2]
I0123 20:15:20.207485       1 scheduler.go:223] Pods test-deployment2-59c6b78cd5-srwkk_default being added:
I0123 20:15:20.203435       1 scheduler.go:147] [Reserve] Status de alocação atual para o pod test-deployment2-59c6b78cd5-srwkk_default: 
I0123 20:15:20.209579       1 scheduler.go:149] [Reserve] Status de alocação atualizado para o pod test-deployment2-59c6b78cd5-srwkk_default: allocating
I0123 20:15:20.210783       1 types.go:743] [ControllerName] Verificando as anotações do pod default/test-deployment2-59c6b78cd5-srwkk
I0123 20:15:20.210930       1 types.go:761] [ControllerName] Anotação 'controller' encontrada para o pod default/test-deployment2-59c6b78cd5-srwkk: test-controller2
I0123 20:15:20.210947       1 types.go:743] [ControllerName] Verificando as anotações do pod default/test-deployment2-59c6b78cd5-srwkk
I0123 20:15:20.210956       1 types.go:761] [ControllerName] Anotação 'controller' encontrada para o pod default/test-deployment2-59c6b78cd5-srwkk: test-controller2
I0123 20:15:20.216576       1 scheduler.go:173] [PreBind] Validando o pod test-deployment2-59c6b78cd5-srwkk antes de vincular ao node minikube
I0123 20:15:20.244579       1 scheduler.go:247] [OnUpdatePod] Pod atualizado: default/test-deployment2-59c6b78cd5-srwkk, Anotações: map[controller:test-controller2]
I0123 20:15:20.245311       1 scheduler.go:181] [PostBind] Chamado para pod test-deployment2-59c6b78cd5-srwkk
I0123 20:15:20.245333       1 scheduler.go:199] [PostBind] Pod test-deployment2-59c6b78cd5-srwkk - Início do binding: 2025-01-23 20:15:20.216630687 +0000 UTC m=+88.114252969, Fim do binding: 2025-01-23 20:15:20.245326792 +0000 UTC m=+88.142948935
I0123 20:15:20.245369       1 types.go:743] [ControllerName] Verificando as anotações do pod default/test-deployment2-59c6b78cd5-srwkk
I0123 20:15:20.245378       1 types.go:761] [ControllerName] Anotação 'controller' encontrada para o pod default/test-deployment2-59c6b78cd5-srwkk: test-controller2
I0123 20:15:20.245402       1 scheduler.go:206] [PostBind] Métricas atualizadas para o pod test-deployment2-59c6b78cd5-srwkk
I0123 20:15:20.273385       1 scheduler.go:69] Estado no Informer: map[controller:test-controller2]
I0123 20:15:20.278046       1 scheduler.go:70] Estado real no cluster: map[controller:test-controller2]
I0123 20:15:20.278155       1 types.go:743] [ControllerName] Verificando as anotações do pod default/test-deployment2-59c6b78cd5-srwkk
I0123 20:15:20.278167       1 types.go:761] [ControllerName] Anotação 'controller' encontrada para o pod default/test-deployment2-59c6b78cd5-srwkk: test-controller2
I0123 20:15:20.368303       1 scheduler.go:247] [OnUpdatePod] Pod atualizado: default/test-deployment2-59c6b78cd5-srwkk, Anotações: map[controller:test-controller2]
I0123 20:15:20.379197       1 scheduler.go:69] Estado no Informer: map[controller:test-controller2]
I0123 20:15:20.379369       1 scheduler.go:70] Estado real no cluster: map[controller:test-controller2]
I0123 20:15:20.379386       1 types.go:743] [ControllerName] Verificando as anotações do pod default/test-deployment2-59c6b78cd5-srwkk
I0123 20:15:20.379395       1 types.go:761] [ControllerName] Anotação 'controller' encontrada para o pod default/test-deployment2-59c6b78cd5-srwkk: test-controller2
I0123 20:15:30.121399       1 scheduler.go:247] [OnUpdatePod] Pod atualizado: default/test-deployment2-59c6b78cd5-srwkk, Anotações: map[controller:test-controller2]
I0123 20:15:30.141537       1 scheduler.go:69] Estado no Informer: map[controller:test-controller2]
I0123 20:15:30.152138       1 scheduler.go:70] Estado real no cluster: map[controller:test-controller2]
I0123 20:15:30.153503       1 types.go:743] [ControllerName] Verificando as anotações do pod default/test-deployment2-59c6b78cd5-srwkk
I0123 20:15:30.153527       1 types.go:761] [ControllerName] Anotação 'controller' encontrada para o pod default/test-deployment2-59c6b78cd5-srwkk: test-controller2
I0123 20:18:38.987622       1 scheduler.go:213] [OnAddPod] Pod adicionado: default/test-deployment3-6c95cffb97-zhc9h, Anotações: map[controller:test-controller3]
I0123 20:18:38.995334       1 postFilter.go:69] Comparando pod original com o atualizado...
I0123 20:18:38.995416       1 postFilter.go:76] Successfully retrieved updated pod default/test-deployment3-6c95cffb97-zhc9h from lister
I0123 20:18:39.011709       1 scheduler.go:69] Estado no Informer: map[controller:test-controller3]
I0123 20:18:39.011777       1 scheduler.go:70] Estado real no cluster: map[controller:test-controller3]
I0123 20:18:39.017972       1 scheduler.go:223] Pods test-deployment3-6c95cffb97-zhc9h_default being added:
I0123 20:18:39.018104       1 types.go:743] [ControllerName] Verificando as anotações do pod default/test-deployment3-6c95cffb97-zhc9h
I0123 20:18:39.018127       1 types.go:761] [ControllerName] Anotação 'controller' encontrada para o pod default/test-deployment3-6c95cffb97-zhc9h: test-controller3
I0123 20:18:39.027933       1 postFilter.go:218] [compareNodeResources] Recursos calculados no nó minikube: CPU = 1750 mCPU, Memória = 178257920 bytes
I0123 20:18:39.027986       1 postFilter.go:219] [compareNodeResources] Recursos do snapshot no nó minikube: CPU = 1750 mCPU, Memória = 178257920 bytes
I0123 20:18:39.027996       1 postFilter.go:225] [compareNodeResources] Recursos de CPU do nó minikube estão sincronizados: 1750 mCPU
I0123 20:18:39.037081       1 postFilter.go:231] [compareNodeResources] Recursos de memória do nó minikube estão sincronizados: 178257920 bytes
I0123 20:18:39.037498       1 scheduler.go:578] [GetControllerMetricInfo] Iniciando para o pod: default/test-deployment2-59c6b78cd5-srwkk
I0123 20:18:39.043958       1 types.go:743] [ControllerName] Verificando as anotações do pod default/test-deployment3-6c95cffb97-zhc9h
I0123 20:18:39.043997       1 types.go:761] [ControllerName] Anotação 'controller' encontrada para o pod default/test-deployment3-6c95cffb97-zhc9h: test-controller3
I0123 20:18:39.044040       1 scheduler.go:583] [GetControllerMetricInfo] Obtendo o nome do controlador para o pod: default/test-deployment2-59c6b78cd5-srwkk
I0123 20:18:39.044048       1 types.go:743] [ControllerName] Verificando as anotações do pod default/test-deployment2-59c6b78cd5-srwkk
I0123 20:18:39.044072       1 types.go:761] [ControllerName] Anotação 'controller' encontrada para o pod default/test-deployment2-59c6b78cd5-srwkk: test-controller2
I0123 20:18:39.044079       1 scheduler.go:586] [GetControllerMetricInfo] Métricas do controlador definidas para o pod: default/test-deployment2-59c6b78cd5-srwkk
I0123 20:18:39.044086       1 scheduler.go:83] [HigherPrecedence] Calculando precedência entre test-deployment3-6c95cffb97-zhc9h e test-deployment2-59c6b78cd5-srwkk
I0123 20:18:39.044091       1 scheduler.go:116] [WaitForPodsOnCache] Verificando se o pod test-deployment3-6c95cffb97-zhc9h está no cache...
I0123 20:18:39.044099       1 scheduler.go:578] [GetControllerMetricInfo] Iniciando para o pod: default/test-deployment3-6c95cffb97-zhc9h
I0123 20:18:39.044104       1 scheduler.go:583] [GetControllerMetricInfo] Obtendo o nome do controlador para o pod: default/test-deployment3-6c95cffb97-zhc9h
I0123 20:18:39.044109       1 types.go:743] [ControllerName] Verificando as anotações do pod default/test-deployment3-6c95cffb97-zhc9h
I0123 20:18:39.044114       1 types.go:761] [ControllerName] Anotação 'controller' encontrada para o pod default/test-deployment3-6c95cffb97-zhc9h: test-controller3
I0123 20:18:39.044120       1 scheduler.go:586] [GetControllerMetricInfo] Métricas do controlador definidas para o pod: default/test-deployment3-6c95cffb97-zhc9h
I0123 20:18:39.064489       1 scheduler.go:69] Estado no Informer: map[controller:test-controller3]
I0123 20:18:39.064613       1 scheduler.go:70] Estado real no cluster: map[controller:test-controller3]
I0123 20:18:39.064624       1 scheduler.go:138] [WaitForPodsOnCache] Pod test-deployment3-6c95cffb97-zhc9h encontrado no cache.
I0123 20:18:39.064630       1 scheduler.go:116] [WaitForPodsOnCache] Verificando se o pod test-deployment2-59c6b78cd5-srwkk está no cache...
I0123 20:18:39.064637       1 scheduler.go:578] [GetControllerMetricInfo] Iniciando para o pod: default/test-deployment2-59c6b78cd5-srwkk
I0123 20:18:39.064643       1 scheduler.go:583] [GetControllerMetricInfo] Obtendo o nome do controlador para o pod: default/test-deployment2-59c6b78cd5-srwkk
I0123 20:18:39.064651       1 types.go:743] [ControllerName] Verificando as anotações do pod default/test-deployment2-59c6b78cd5-srwkk
I0123 20:18:39.064756       1 types.go:761] [ControllerName] Anotação 'controller' encontrada para o pod default/test-deployment2-59c6b78cd5-srwkk: test-controller2
I0123 20:18:39.064767       1 scheduler.go:586] [GetControllerMetricInfo] Métricas do controlador definidas para o pod: default/test-deployment2-59c6b78cd5-srwkk
I0123 20:18:39.103325       1 scheduler.go:69] Estado no Informer: map[controller:test-controller2]
I0123 20:18:39.103379       1 scheduler.go:70] Estado real no cluster: map[controller:test-controller2]
I0123 20:18:39.103388       1 scheduler.go:138] [WaitForPodsOnCache] Pod test-deployment2-59c6b78cd5-srwkk encontrado no cache.
I0123 20:18:39.103395       1 scheduler.go:578] [GetControllerMetricInfo] Iniciando para o pod: default/test-deployment3-6c95cffb97-zhc9h
I0123 20:18:39.103401       1 scheduler.go:583] [GetControllerMetricInfo] Obtendo o nome do controlador para o pod: default/test-deployment3-6c95cffb97-zhc9h
I0123 20:18:39.103407       1 types.go:743] [ControllerName] Verificando as anotações do pod default/test-deployment3-6c95cffb97-zhc9h
I0123 20:18:39.105929       1 types.go:761] [ControllerName] Anotação 'controller' encontrada para o pod default/test-deployment3-6c95cffb97-zhc9h: test-controller3
I0123 20:18:39.106210       1 scheduler.go:586] [GetControllerMetricInfo] Métricas do controlador definidas para o pod: default/test-deployment3-6c95cffb97-zhc9h
I0123 20:18:39.106341       1 scheduler.go:578] [GetControllerMetricInfo] Iniciando para o pod: default/test-deployment2-59c6b78cd5-srwkk
I0123 20:18:39.106363       1 scheduler.go:583] [GetControllerMetricInfo] Obtendo o nome do controlador para o pod: default/test-deployment2-59c6b78cd5-srwkk
I0123 20:18:39.106581       1 types.go:743] [ControllerName] Verificando as anotações do pod default/test-deployment2-59c6b78cd5-srwkk
I0123 20:18:39.106684       1 types.go:761] [ControllerName] Anotação 'controller' encontrada para o pod default/test-deployment2-59c6b78cd5-srwkk: test-controller2
I0123 20:18:39.106779       1 scheduler.go:586] [GetControllerMetricInfo] Métricas do controlador definidas para o pod: default/test-deployment2-59c6b78cd5-srwkk
I0123 20:18:39.106806       1 scheduler.go:97] [HigherPrecedence] Métricas para test-deployment3-6c95cffb97-zhc9h: QoS = -3.444082, Importância = 0.80
I0123 20:18:39.106978       1 scheduler.go:98] [HigherPrecedence] Métricas para test-deployment2-59c6b78cd5-srwkk: QoS = 49.425666, Importância = 0.80
I0123 20:18:39.107034       1 scheduler.go:109] [HigherPrecedence] Decisão final: test-deployment3-6c95cffb97-zhc9h tem precedência sobre test-deployment2-59c6b78cd5-srwkk? true
I0123 20:18:39.107048       1 types.go:743] [ControllerName] Verificando as anotações do pod default/test-deployment3-6c95cffb97-zhc9h
I0123 20:18:39.107060       1 types.go:761] [ControllerName] Anotação 'controller' encontrada para o pod default/test-deployment3-6c95cffb97-zhc9h: test-controller3
I0123 20:18:39.107130       1 types.go:743] [ControllerName] Verificando as anotações do pod default/test-deployment2-59c6b78cd5-srwkk
I0123 20:18:39.107152       1 types.go:761] [ControllerName] Anotação 'controller' encontrada para o pod default/test-deployment2-59c6b78cd5-srwkk: test-controller2
I0123 20:18:39.107164       1 scheduler.go:578] [GetControllerMetricInfo] Iniciando para o pod: default/test-deployment2-59c6b78cd5-srwkk
I0123 20:18:39.107177       1 scheduler.go:583] [GetControllerMetricInfo] Obtendo o nome do controlador para o pod: default/test-deployment2-59c6b78cd5-srwkk
I0123 20:18:39.107259       1 types.go:743] [ControllerName] Verificando as anotações do pod default/test-deployment2-59c6b78cd5-srwkk
I0123 20:18:39.107272       1 types.go:761] [ControllerName] Anotação 'controller' encontrada para o pod default/test-deployment2-59c6b78cd5-srwkk: test-controller2
I0123 20:18:39.107284       1 scheduler.go:586] [GetControllerMetricInfo] Métricas do controlador definidas para o pod: default/test-deployment2-59c6b78cd5-srwkk
I0123 20:18:39.107357       1 scheduler.go:578] [GetControllerMetricInfo] Iniciando para o pod: default/test-deployment2-59c6b78cd5-srwkk
I0123 20:18:39.107373       1 scheduler.go:583] [GetControllerMetricInfo] Obtendo o nome do controlador para o pod: default/test-deployment2-59c6b78cd5-srwkk
I0123 20:18:39.107385       1 types.go:743] [ControllerName] Verificando as anotações do pod default/test-deployment2-59c6b78cd5-srwkk
I0123 20:18:39.107397       1 types.go:761] [ControllerName] Anotação 'controller' encontrada para o pod default/test-deployment2-59c6b78cd5-srwkk: test-controller2
I0123 20:18:39.107465       1 scheduler.go:586] [GetControllerMetricInfo] Métricas do controlador definidas para o pod: default/test-deployment2-59c6b78cd5-srwkk
I0123 20:18:39.107482       1 types.go:743] [ControllerName] Verificando as anotações do pod default/test-deployment2-59c6b78cd5-srwkk
I0123 20:18:39.107494       1 types.go:761] [ControllerName] Anotação 'controller' encontrada para o pod default/test-deployment2-59c6b78cd5-srwkk: test-controller2
I0123 20:18:39.108284       1 scheduler.go:578] [GetControllerMetricInfo] Iniciando para o pod: default/test-deployment2-59c6b78cd5-srwkk
I0123 20:18:39.108407       1 scheduler.go:583] [GetControllerMetricInfo] Obtendo o nome do controlador para o pod: default/test-deployment2-59c6b78cd5-srwkk
I0123 20:18:39.108425       1 types.go:743] [ControllerName] Verificando as anotações do pod default/test-deployment2-59c6b78cd5-srwkk
I0123 20:18:39.108438       1 types.go:761] [ControllerName] Anotação 'controller' encontrada para o pod default/test-deployment2-59c6b78cd5-srwkk: test-controller2
I0123 20:18:39.108627       1 scheduler.go:586] [GetControllerMetricInfo] Métricas do controlador definidas para o pod: default/test-deployment2-59c6b78cd5-srwkk
I0123 20:18:39.108737       1 scheduler.go:578] [GetControllerMetricInfo] Iniciando para o pod: default/test-deployment2-59c6b78cd5-srwkk
I0123 20:18:39.108754       1 scheduler.go:583] [GetControllerMetricInfo] Obtendo o nome do controlador para o pod: default/test-deployment2-59c6b78cd5-srwkk
I0123 20:18:39.108766       1 types.go:743] [ControllerName] Verificando as anotações do pod default/test-deployment2-59c6b78cd5-srwkk
I0123 20:18:39.108827       1 types.go:761] [ControllerName] Anotação 'controller' encontrada para o pod default/test-deployment2-59c6b78cd5-srwkk: test-controller2
I0123 20:18:39.108947       1 scheduler.go:586] [GetControllerMetricInfo] Métricas do controlador definidas para o pod: default/test-deployment2-59c6b78cd5-srwkk
I0123 20:18:39.108974       1 postFilter.go:140] [PREEMPT CALL] The node minikube  was chosen to allocate pod test-deployment3-6c95cffb97-zhc9h
I0123 20:18:39.109042       1 postFilter.go:144] [Preempt] Iniciando a remoção dos pods preemptados no nó minikube para alocar o pod default/test-deployment3-6c95cffb97-zhc9h. Total de vítimas: 1
I0123 20:18:39.109308       1 postFilter.go:148] [Preempt] Tentando remover o pod default/test-deployment2-59c6b78cd5-srwkk no nó minikube
I0123 20:18:39.454926       1 postFilter.go:153] [Preempt] Pod default/test-deployment2-59c6b78cd5-srwkk removido com sucesso no nó minikube
I0123 20:18:39.455001       1 postFilter.go:159] test-deployment2-59c6b78cd5-srwkk_default preempted by test-deployment3-6c95cffb97-zhc9h_default on node minikube
I0123 20:18:39.455058       1 postFilter.go:164] [Preempt] Total de pods preemptados no nó minikube: 1
I0123 20:18:39.455113       1 postFilter.go:171] [Preempt] Verificando pods de menor precedência no nó minikube que precisam ter o campo NominatedNodeName limpo
I0123 20:18:39.455133       1 postFilter.go:181] [Preempt] Finalizado para o nó minikube. Pod default/test-deployment3-6c95cffb97-zhc9h deve ser alocado agora.
I0123 20:18:39.464531       1 scheduler.go:247] [OnUpdatePod] Pod atualizado: default/test-deployment2-59c6b78cd5-srwkk, Anotações: map[controller:test-controller2]
I0123 20:18:40.898413       1 scheduler.go:69] Estado no Informer: map[controller:test-controller2]
I0123 20:18:40.906121       1 scheduler.go:70] Estado real no cluster: map[controller:test-controller2]
I0123 20:18:40.906175       1 types.go:743] [ControllerName] Verificando as anotações do pod default/test-deployment2-59c6b78cd5-srwkk
I0123 20:18:40.906192       1 types.go:761] [ControllerName] Anotação 'controller' encontrada para o pod default/test-deployment2-59c6b78cd5-srwkk: test-controller2
I0123 20:18:40.906264       1 scheduler.go:213] [OnAddPod] Pod adicionado: default/test-deployment2-59c6b78cd5-csvbh, Anotações: map[controller:test-controller2]
I0123 20:18:40.915686       1 postFilter.go:69] Comparando pod original com o atualizado...
I0123 20:18:40.916964       1 postFilter.go:76] Successfully retrieved updated pod default/test-deployment2-59c6b78cd5-csvbh from lister
I0123 20:18:40.917112       1 types.go:743] [ControllerName] Verificando as anotações do pod default/test-deployment2-59c6b78cd5-srwkk
I0123 20:18:40.917120       1 types.go:761] [ControllerName] Anotação 'controller' encontrada para o pod default/test-deployment2-59c6b78cd5-srwkk: test-controller2
I0123 20:18:41.038801       1 scheduler.go:69] Estado no Informer: map[controller:test-controller2]
I0123 20:18:41.039153       1 scheduler.go:70] Estado real no cluster: map[controller:test-controller2]
I0123 20:18:41.039639       1 scheduler.go:223] Pods test-deployment2-59c6b78cd5-csvbh_default being added:
I0123 20:18:41.040282       1 types.go:743] [ControllerName] Verificando as anotações do pod default/test-deployment2-59c6b78cd5-csvbh
I0123 20:18:41.040383       1 types.go:761] [ControllerName] Anotação 'controller' encontrada para o pod default/test-deployment2-59c6b78cd5-csvbh: test-controller2
I0123 20:18:41.040619       1 types.go:743] [ControllerName] Verificando as anotações do pod default/test-deployment2-59c6b78cd5-csvbh
I0123 20:18:41.040714       1 types.go:761] [ControllerName] Anotação 'controller' encontrada para o pod default/test-deployment2-59c6b78cd5-csvbh: test-controller2
I0123 20:18:41.040895       1 scheduler.go:247] [OnUpdatePod] Pod atualizado: default/test-deployment3-6c95cffb97-zhc9h, Anotações: map[controller:test-controller3]
I0123 20:18:41.049369       1 postFilter.go:218] [compareNodeResources] Recursos calculados no nó minikube: CPU = 1750 mCPU, Memória = 178257920 bytes
I0123 20:18:41.049417       1 postFilter.go:219] [compareNodeResources] Recursos do snapshot no nó minikube: CPU = 1750 mCPU, Memória = 178257920 bytes
I0123 20:18:41.049426       1 postFilter.go:225] [compareNodeResources] Recursos de CPU do nó minikube estão sincronizados: 1750 mCPU
I0123 20:18:41.049433       1 postFilter.go:231] [compareNodeResources] Recursos de memória do nó minikube estão sincronizados: 178257920 bytes
I0123 20:18:41.049588       1 scheduler.go:578] [GetControllerMetricInfo] Iniciando para o pod: default/test-deployment2-59c6b78cd5-srwkk
I0123 20:18:41.049635       1 scheduler.go:583] [GetControllerMetricInfo] Obtendo o nome do controlador para o pod: default/test-deployment2-59c6b78cd5-srwkk
I0123 20:18:41.049644       1 types.go:743] [ControllerName] Verificando as anotações do pod default/test-deployment2-59c6b78cd5-srwkk
I0123 20:18:41.049651       1 types.go:761] [ControllerName] Anotação 'controller' encontrada para o pod default/test-deployment2-59c6b78cd5-srwkk: test-controller2
I0123 20:18:41.049657       1 scheduler.go:586] [GetControllerMetricInfo] Métricas do controlador definidas para o pod: default/test-deployment2-59c6b78cd5-srwkk
I0123 20:18:41.049664       1 scheduler.go:83] [HigherPrecedence] Calculando precedência entre test-deployment2-59c6b78cd5-csvbh e test-deployment2-59c6b78cd5-srwkk
I0123 20:18:41.049669       1 scheduler.go:116] [WaitForPodsOnCache] Verificando se o pod test-deployment2-59c6b78cd5-csvbh está no cache...
I0123 20:18:41.049674       1 scheduler.go:578] [GetControllerMetricInfo] Iniciando para o pod: default/test-deployment2-59c6b78cd5-csvbh
I0123 20:18:41.049679       1 scheduler.go:583] [GetControllerMetricInfo] Obtendo o nome do controlador para o pod: default/test-deployment2-59c6b78cd5-csvbh
I0123 20:18:41.049685       1 types.go:743] [ControllerName] Verificando as anotações do pod default/test-deployment2-59c6b78cd5-csvbh
I0123 20:18:41.049690       1 types.go:761] [ControllerName] Anotação 'controller' encontrada para o pod default/test-deployment2-59c6b78cd5-csvbh: test-controller2
I0123 20:18:41.049696       1 scheduler.go:586] [GetControllerMetricInfo] Métricas do controlador definidas para o pod: default/test-deployment2-59c6b78cd5-csvbh
I0123 20:18:41.368521       1 scheduler.go:69] Estado no Informer: map[controller:test-controller2]
I0123 20:18:41.376135       1 scheduler.go:69] Estado no Informer: map[controller:test-controller3]
I0123 20:18:41.380749       1 scheduler.go:70] Estado real no cluster: map[controller:test-controller3]
I0123 20:18:41.380800       1 scheduler.go:70] Estado real no cluster: map[controller:test-controller2]
I0123 20:18:41.380814       1 scheduler.go:138] [WaitForPodsOnCache] Pod test-deployment2-59c6b78cd5-csvbh encontrado no cache.
I0123 20:18:41.380824       1 scheduler.go:116] [WaitForPodsOnCache] Verificando se o pod test-deployment2-59c6b78cd5-srwkk está no cache...
I0123 20:18:41.380835       1 scheduler.go:578] [GetControllerMetricInfo] Iniciando para o pod: default/test-deployment2-59c6b78cd5-srwkk
I0123 20:18:41.381004       1 types.go:743] [ControllerName] Verificando as anotações do pod default/test-deployment3-6c95cffb97-zhc9h
I0123 20:18:41.381023       1 types.go:761] [ControllerName] Anotação 'controller' encontrada para o pod default/test-deployment3-6c95cffb97-zhc9h: test-controller3
I0123 20:18:41.381064       1 scheduler.go:583] [GetControllerMetricInfo] Obtendo o nome do controlador para o pod: default/test-deployment2-59c6b78cd5-srwkk
I0123 20:18:41.381075       1 types.go:743] [ControllerName] Verificando as anotações do pod default/test-deployment2-59c6b78cd5-srwkk
I0123 20:18:41.381084       1 types.go:761] [ControllerName] Anotação 'controller' encontrada para o pod default/test-deployment2-59c6b78cd5-srwkk: test-controller2
I0123 20:18:41.381094       1 scheduler.go:586] [GetControllerMetricInfo] Métricas do controlador definidas para o pod: default/test-deployment2-59c6b78cd5-srwkk
I0123 20:18:41.450167       1 scheduler.go:69] Estado no Informer: map[controller:test-controller2]
I0123 20:18:41.450270       1 scheduler.go:70] Estado real no cluster: map[controller:test-controller2]
I0123 20:18:41.450287       1 scheduler.go:138] [WaitForPodsOnCache] Pod test-deployment2-59c6b78cd5-srwkk encontrado no cache.
I0123 20:18:41.450299       1 scheduler.go:578] [GetControllerMetricInfo] Iniciando para o pod: default/test-deployment2-59c6b78cd5-csvbh
I0123 20:18:41.450354       1 scheduler.go:583] [GetControllerMetricInfo] Obtendo o nome do controlador para o pod: default/test-deployment2-59c6b78cd5-csvbh
I0123 20:18:41.450367       1 types.go:743] [ControllerName] Verificando as anotações do pod default/test-deployment2-59c6b78cd5-csvbh
I0123 20:18:41.450378       1 types.go:761] [ControllerName] Anotação 'controller' encontrada para o pod default/test-deployment2-59c6b78cd5-csvbh: test-controller2
I0123 20:18:41.459746       1 scheduler.go:586] [GetControllerMetricInfo] Métricas do controlador definidas para o pod: default/test-deployment2-59c6b78cd5-csvbh
I0123 20:18:41.459824       1 scheduler.go:578] [GetControllerMetricInfo] Iniciando para o pod: default/test-deployment2-59c6b78cd5-srwkk
I0123 20:18:41.459835       1 scheduler.go:583] [GetControllerMetricInfo] Obtendo o nome do controlador para o pod: default/test-deployment2-59c6b78cd5-srwkk
I0123 20:18:41.460717       1 types.go:743] [ControllerName] Verificando as anotações do pod default/test-deployment2-59c6b78cd5-srwkk
I0123 20:18:41.460743       1 types.go:761] [ControllerName] Anotação 'controller' encontrada para o pod default/test-deployment2-59c6b78cd5-srwkk: test-controller2
I0123 20:18:41.460755       1 scheduler.go:586] [GetControllerMetricInfo] Métricas do controlador definidas para o pod: default/test-deployment2-59c6b78cd5-srwkk
I0123 20:18:41.460777       1 scheduler.go:97] [HigherPrecedence] Métricas para test-deployment2-59c6b78cd5-csvbh: QoS = 47.891748, Importância = 0.80
I0123 20:18:41.460791       1 scheduler.go:98] [HigherPrecedence] Métricas para test-deployment2-59c6b78cd5-srwkk: QoS = 21.277250, Importância = 0.80
I0123 20:18:41.460807       1 scheduler.go:109] [HigherPrecedence] Decisão final: test-deployment2-59c6b78cd5-csvbh tem precedência sobre test-deployment2-59c6b78cd5-srwkk? false
I0123 20:18:41.460938       1 postFilter.go:137] [PREEMPT CALL] No node was chosen to allocate pod test-deployment2-59c6b78cd5-csvbh
I0123 20:18:41.481982       1 scheduler.go:247] [OnUpdatePod] Pod atualizado: default/test-deployment2-59c6b78cd5-csvbh, Anotações: map[controller:test-controller2]
I0123 20:18:41.490976       1 scheduler.go:69] Estado no Informer: map[controller:test-controller2]
I0123 20:18:41.491000       1 scheduler.go:70] Estado real no cluster: map[controller:test-controller2]
I0123 20:18:41.491011       1 types.go:743] [ControllerName] Verificando as anotações do pod default/test-deployment2-59c6b78cd5-csvbh
I0123 20:18:41.491017       1 types.go:761] [ControllerName] Anotação 'controller' encontrada para o pod default/test-deployment2-59c6b78cd5-csvbh: test-controller2
I0123 20:18:44.442304       1 scheduler.go:263] [OnDeletePod] Iniciando a execução do OnDeletePod
I0123 20:18:44.443046       1 scheduler.go:272] [OnDeletePod] DeepCopy realizado para o pod default/test-deployment2-59c6b78cd5-srwkk
I0123 20:18:44.448825       1 scheduler.go:279] [OnDeletePod] Pod deletado detectado: default/test-deployment2-59c6b78cd5-srwkk
I0123 20:18:44.449009       1 scheduler.go:281] [OnDeletePod] Atualizando métricas do pod default/test-deployment2-59c6b78cd5-srwkk
I0123 20:18:44.449026       1 types.go:743] [ControllerName] Verificando as anotações do pod default/test-deployment2-59c6b78cd5-srwkk
I0123 20:18:44.449037       1 types.go:761] [ControllerName] Anotação 'controller' encontrada para o pod default/test-deployment2-59c6b78cd5-srwkk: test-controller2
I0123 20:18:44.449054       1 scheduler.go:283] [OnDeletePod] Verificando o estado do pod default/test-deployment2-59c6b78cd5-srwkk nas métricas
I0123 20:18:44.449067       1 scheduler.go:293] [OnDeletePod] EndTime atualizado para o pod default/test-deployment2-59c6b78cd5-srwkk: 2025-01-23 20:18:44.449060138 +0000 UTC m=+292.346682682
I0123 20:18:44.449522       1 scheduler.go:297] [OnDeletePod] Finalizando a execução do OnDeletePod para o pod default/test-deployment2-59c6b78cd5-srwkk
I0123 20:18:44.449951       1 scheduler.go:53] [QueueSort] Comparando prioridade de test-deployment3-6c95cffb97-zhc9h com test-deployment2-59c6b78cd5-csvbh
I0123 20:18:44.451733       1 scheduler.go:83] [HigherPrecedence] Calculando precedência entre test-deployment3-6c95cffb97-zhc9h e test-deployment2-59c6b78cd5-csvbh
I0123 20:18:44.452429       1 scheduler.go:116] [WaitForPodsOnCache] Verificando se o pod test-deployment3-6c95cffb97-zhc9h está no cache...
I0123 20:18:44.452450       1 scheduler.go:578] [GetControllerMetricInfo] Iniciando para o pod: default/test-deployment3-6c95cffb97-zhc9h
I0123 20:18:44.453008       1 scheduler.go:583] [GetControllerMetricInfo] Obtendo o nome do controlador para o pod: default/test-deployment3-6c95cffb97-zhc9h
I0123 20:18:44.453361       1 types.go:743] [ControllerName] Verificando as anotações do pod default/test-deployment3-6c95cffb97-zhc9h
I0123 20:18:44.453600       1 types.go:761] [ControllerName] Anotação 'controller' encontrada para o pod default/test-deployment3-6c95cffb97-zhc9h: test-controller3
I0123 20:18:44.454174       1 scheduler.go:586] [GetControllerMetricInfo] Métricas do controlador definidas para o pod: default/test-deployment3-6c95cffb97-zhc9h
I0123 20:18:44.468353       1 scheduler.go:69] Estado no Informer: map[controller:test-controller3]
I0123 20:18:44.468603       1 scheduler.go:70] Estado real no cluster: map[controller:test-controller3]
I0123 20:18:44.468689       1 scheduler.go:138] [WaitForPodsOnCache] Pod test-deployment3-6c95cffb97-zhc9h encontrado no cache.
I0123 20:18:44.468718       1 scheduler.go:116] [WaitForPodsOnCache] Verificando se o pod test-deployment2-59c6b78cd5-csvbh está no cache...
I0123 20:18:44.468806       1 scheduler.go:578] [GetControllerMetricInfo] Iniciando para o pod: default/test-deployment2-59c6b78cd5-csvbh
I0123 20:18:44.469124       1 scheduler.go:583] [GetControllerMetricInfo] Obtendo o nome do controlador para o pod: default/test-deployment2-59c6b78cd5-csvbh
I0123 20:18:44.469227       1 types.go:743] [ControllerName] Verificando as anotações do pod default/test-deployment2-59c6b78cd5-csvbh
I0123 20:18:44.469345       1 types.go:761] [ControllerName] Anotação 'controller' encontrada para o pod default/test-deployment2-59c6b78cd5-csvbh: test-controller2
I0123 20:18:44.469405       1 scheduler.go:586] [GetControllerMetricInfo] Métricas do controlador definidas para o pod: default/test-deployment2-59c6b78cd5-csvbh
I0123 20:18:44.478021       1 scheduler.go:69] Estado no Informer: map[controller:test-controller2]
I0123 20:18:44.478094       1 scheduler.go:70] Estado real no cluster: map[controller:test-controller2]
I0123 20:18:44.478111       1 scheduler.go:138] [WaitForPodsOnCache] Pod test-deployment2-59c6b78cd5-csvbh encontrado no cache.
I0123 20:18:44.478121       1 scheduler.go:578] [GetControllerMetricInfo] Iniciando para o pod: default/test-deployment3-6c95cffb97-zhc9h
I0123 20:18:44.478444       1 scheduler.go:583] [GetControllerMetricInfo] Obtendo o nome do controlador para o pod: default/test-deployment3-6c95cffb97-zhc9h
I0123 20:18:44.482603       1 types.go:743] [ControllerName] Verificando as anotações do pod default/test-deployment3-6c95cffb97-zhc9h
I0123 20:18:44.486184       1 types.go:761] [ControllerName] Anotação 'controller' encontrada para o pod default/test-deployment3-6c95cffb97-zhc9h: test-controller3
I0123 20:18:44.488136       1 scheduler.go:586] [GetControllerMetricInfo] Métricas do controlador definidas para o pod: default/test-deployment3-6c95cffb97-zhc9h
I0123 20:18:44.488194       1 scheduler.go:578] [GetControllerMetricInfo] Iniciando para o pod: default/test-deployment2-59c6b78cd5-csvbh
I0123 20:18:44.488204       1 scheduler.go:583] [GetControllerMetricInfo] Obtendo o nome do controlador para o pod: default/test-deployment2-59c6b78cd5-csvbh
I0123 20:18:44.488211       1 types.go:743] [ControllerName] Verificando as anotações do pod default/test-deployment2-59c6b78cd5-csvbh
I0123 20:18:44.488219       1 types.go:761] [ControllerName] Anotação 'controller' encontrada para o pod default/test-deployment2-59c6b78cd5-csvbh: test-controller2
I0123 20:18:44.488226       1 scheduler.go:586] [GetControllerMetricInfo] Métricas do controlador definidas para o pod: default/test-deployment2-59c6b78cd5-csvbh
I0123 20:18:44.488244       1 scheduler.go:97] [HigherPrecedence] Métricas para test-deployment3-6c95cffb97-zhc9h: QoS = -8.849964, Importância = 0.80
I0123 20:18:44.488257       1 scheduler.go:98] [HigherPrecedence] Métricas para test-deployment2-59c6b78cd5-csvbh: QoS = 45.341295, Importância = 0.80
I0123 20:18:44.488268       1 scheduler.go:109] [HigherPrecedence] Decisão final: test-deployment3-6c95cffb97-zhc9h tem precedência sobre test-deployment2-59c6b78cd5-csvbh? true
I0123 20:18:44.488297       1 scheduler.go:59] [QueueSort] Precedência determinada: test-deployment3-6c95cffb97-zhc9h tem precedência sobre test-deployment2-59c6b78cd5-csvbh? true
I0123 20:18:44.492015       1 scheduler.go:145] [Reserve] resources reserved at node minikube for pod test-deployment3-6c95cffb97-zhc9h_default at 2025-01-23 20:18:44.492003623 +0000 UTC m=+292.389625690
I0123 20:18:44.492118       1 types.go:743] [ControllerName] Verificando as anotações do pod default/test-deployment3-6c95cffb97-zhc9h
I0123 20:18:44.492128       1 types.go:761] [ControllerName] Anotação 'controller' encontrada para o pod default/test-deployment3-6c95cffb97-zhc9h: test-controller3
I0123 20:18:44.492142       1 scheduler.go:147] [Reserve] Status de alocação atual para o pod test-deployment3-6c95cffb97-zhc9h_default: 
I0123 20:18:44.492150       1 scheduler.go:149] [Reserve] Status de alocação atualizado para o pod test-deployment3-6c95cffb97-zhc9h_default: allocating
I0123 20:18:44.492358       1 postFilter.go:69] Comparando pod original com o atualizado...
I0123 20:18:44.492371       1 postFilter.go:76] Successfully retrieved updated pod default/test-deployment2-59c6b78cd5-csvbh from lister
I0123 20:18:44.493784       1 scheduler.go:173] [PreBind] Validando o pod test-deployment3-6c95cffb97-zhc9h antes de vincular ao node minikube
I0123 20:18:44.671837       1 scheduler.go:247] [OnUpdatePod] Pod atualizado: default/test-deployment3-6c95cffb97-zhc9h, Anotações: map[controller:test-controller3]
I0123 20:18:44.673368       1 postFilter.go:218] [compareNodeResources] Recursos calculados no nó minikube: CPU = 1750 mCPU, Memória = 178257920 bytes
I0123 20:18:44.673467       1 postFilter.go:219] [compareNodeResources] Recursos do snapshot no nó minikube: CPU = 1750 mCPU, Memória = 178257920 bytes
I0123 20:18:44.673487       1 postFilter.go:225] [compareNodeResources] Recursos de CPU do nó minikube estão sincronizados: 1750 mCPU
I0123 20:18:44.673559       1 postFilter.go:231] [compareNodeResources] Recursos de memória do nó minikube estão sincronizados: 178257920 bytes
I0123 20:18:44.679968       1 scheduler.go:181] [PostBind] Chamado para pod test-deployment3-6c95cffb97-zhc9h
I0123 20:18:44.680325       1 scheduler.go:199] [PostBind] Pod test-deployment3-6c95cffb97-zhc9h - Início do binding: 2025-01-23 20:18:44.493795026 +0000 UTC m=+292.391417081, Fim do binding: 2025-01-23 20:18:44.680313407 +0000 UTC m=+292.577935859
I0123 20:18:44.680730       1 types.go:743] [ControllerName] Verificando as anotações do pod default/test-deployment3-6c95cffb97-zhc9h
I0123 20:18:44.681186       1 types.go:761] [ControllerName] Anotação 'controller' encontrada para o pod default/test-deployment3-6c95cffb97-zhc9h: test-controller3
I0123 20:18:44.681784       1 scheduler.go:206] [PostBind] Métricas atualizadas para o pod test-deployment3-6c95cffb97-zhc9h
I0123 20:18:44.688661       1 scheduler.go:578] [GetControllerMetricInfo] Iniciando para o pod: default/test-deployment3-6c95cffb97-zhc9h
I0123 20:18:44.688698       1 scheduler.go:583] [GetControllerMetricInfo] Obtendo o nome do controlador para o pod: default/test-deployment3-6c95cffb97-zhc9h
I0123 20:18:44.688710       1 types.go:743] [ControllerName] Verificando as anotações do pod default/test-deployment3-6c95cffb97-zhc9h
I0123 20:18:44.688721       1 types.go:761] [ControllerName] Anotação 'controller' encontrada para o pod default/test-deployment3-6c95cffb97-zhc9h: test-controller3
I0123 20:18:44.688733       1 scheduler.go:586] [GetControllerMetricInfo] Métricas do controlador definidas para o pod: default/test-deployment3-6c95cffb97-zhc9h
I0123 20:18:44.688746       1 scheduler.go:83] [HigherPrecedence] Calculando precedência entre test-deployment2-59c6b78cd5-csvbh e test-deployment3-6c95cffb97-zhc9h
I0123 20:18:44.688755       1 scheduler.go:116] [WaitForPodsOnCache] Verificando se o pod test-deployment2-59c6b78cd5-csvbh está no cache...
I0123 20:18:44.688763       1 scheduler.go:578] [GetControllerMetricInfo] Iniciando para o pod: default/test-deployment2-59c6b78cd5-csvbh
I0123 20:18:44.688779       1 scheduler.go:583] [GetControllerMetricInfo] Obtendo o nome do controlador para o pod: default/test-deployment2-59c6b78cd5-csvbh
I0123 20:18:44.688787       1 types.go:743] [ControllerName] Verificando as anotações do pod default/test-deployment2-59c6b78cd5-csvbh
I0123 20:18:44.688797       1 types.go:761] [ControllerName] Anotação 'controller' encontrada para o pod default/test-deployment2-59c6b78cd5-csvbh: test-controller2
I0123 20:18:44.688807       1 scheduler.go:586] [GetControllerMetricInfo] Métricas do controlador definidas para o pod: default/test-deployment2-59c6b78cd5-csvbh
I0123 20:18:44.717136       1 scheduler.go:69] Estado no Informer: map[controller:test-controller2]
I0123 20:18:44.717275       1 scheduler.go:70] Estado real no cluster: map[controller:test-controller2]
I0123 20:18:44.718771       1 scheduler.go:138] [WaitForPodsOnCache] Pod test-deployment2-59c6b78cd5-csvbh encontrado no cache.
I0123 20:18:44.718800       1 scheduler.go:116] [WaitForPodsOnCache] Verificando se o pod test-deployment3-6c95cffb97-zhc9h está no cache...
I0123 20:18:44.719090       1 scheduler.go:578] [GetControllerMetricInfo] Iniciando para o pod: default/test-deployment3-6c95cffb97-zhc9h
I0123 20:18:44.719104       1 scheduler.go:583] [GetControllerMetricInfo] Obtendo o nome do controlador para o pod: default/test-deployment3-6c95cffb97-zhc9h
I0123 20:18:44.719255       1 types.go:743] [ControllerName] Verificando as anotações do pod default/test-deployment3-6c95cffb97-zhc9h
I0123 20:18:44.719270       1 types.go:761] [ControllerName] Anotação 'controller' encontrada para o pod default/test-deployment3-6c95cffb97-zhc9h: test-controller3
I0123 20:18:44.719539       1 scheduler.go:586] [GetControllerMetricInfo] Métricas do controlador definidas para o pod: default/test-deployment3-6c95cffb97-zhc9h
I0123 20:18:44.723429       1 scheduler.go:69] Estado no Informer: map[controller:test-controller3]
I0123 20:18:44.725976       1 scheduler.go:70] Estado real no cluster: map[controller:test-controller3]
I0123 20:18:44.871075       1 scheduler.go:69] Estado no Informer: map[controller:test-controller3]
I0123 20:18:44.881540       1 scheduler.go:70] Estado real no cluster: map[controller:test-controller3]
I0123 20:18:44.881968       1 scheduler.go:138] [WaitForPodsOnCache] Pod test-deployment3-6c95cffb97-zhc9h encontrado no cache.
I0123 20:18:44.882096       1 types.go:743] [ControllerName] Verificando as anotações do pod default/test-deployment3-6c95cffb97-zhc9h
I0123 20:18:44.882210       1 types.go:761] [ControllerName] Anotação 'controller' encontrada para o pod default/test-deployment3-6c95cffb97-zhc9h: test-controller3
I0123 20:18:44.882398       1 scheduler.go:247] [OnUpdatePod] Pod atualizado: default/test-deployment3-6c95cffb97-zhc9h, Anotações: map[controller:test-controller3]
I0123 20:18:44.893675       1 scheduler.go:69] Estado no Informer: map[controller:test-controller3]
I0123 20:18:44.893790       1 scheduler.go:70] Estado real no cluster: map[controller:test-controller3]
I0123 20:18:44.893904       1 types.go:743] [ControllerName] Verificando as anotações do pod default/test-deployment3-6c95cffb97-zhc9h
I0123 20:18:44.893933       1 types.go:761] [ControllerName] Anotação 'controller' encontrada para o pod default/test-deployment3-6c95cffb97-zhc9h: test-controller3
I0123 20:18:44.894031       1 scheduler.go:578] [GetControllerMetricInfo] Iniciando para o pod: default/test-deployment2-59c6b78cd5-csvbh
I0123 20:18:44.894043       1 scheduler.go:583] [GetControllerMetricInfo] Obtendo o nome do controlador para o pod: default/test-deployment2-59c6b78cd5-csvbh
I0123 20:18:44.894048       1 types.go:743] [ControllerName] Verificando as anotações do pod default/test-deployment2-59c6b78cd5-csvbh
I0123 20:18:44.894054       1 types.go:761] [ControllerName] Anotação 'controller' encontrada para o pod default/test-deployment2-59c6b78cd5-csvbh: test-controller2
I0123 20:18:44.894060       1 scheduler.go:586] [GetControllerMetricInfo] Métricas do controlador definidas para o pod: default/test-deployment2-59c6b78cd5-csvbh
I0123 20:18:44.894069       1 scheduler.go:578] [GetControllerMetricInfo] Iniciando para o pod: default/test-deployment3-6c95cffb97-zhc9h
I0123 20:18:44.894145       1 scheduler.go:583] [GetControllerMetricInfo] Obtendo o nome do controlador para o pod: default/test-deployment3-6c95cffb97-zhc9h
I0123 20:18:44.894152       1 types.go:743] [ControllerName] Verificando as anotações do pod default/test-deployment3-6c95cffb97-zhc9h
I0123 20:18:44.894158       1 types.go:761] [ControllerName] Anotação 'controller' encontrada para o pod default/test-deployment3-6c95cffb97-zhc9h: test-controller3
I0123 20:18:44.894163       1 scheduler.go:586] [GetControllerMetricInfo] Métricas do controlador definidas para o pod: default/test-deployment3-6c95cffb97-zhc9h
I0123 20:18:44.894186       1 scheduler.go:97] [HigherPrecedence] Métricas para test-deployment2-59c6b78cd5-csvbh: QoS = 45.102519, Importância = 0.80
I0123 20:18:44.894261       1 scheduler.go:98] [HigherPrecedence] Métricas para test-deployment3-6c95cffb97-zhc9h: QoS = -6.864726, Importância = 0.80
I0123 20:18:44.894269       1 scheduler.go:109] [HigherPrecedence] Decisão final: test-deployment2-59c6b78cd5-csvbh tem precedência sobre test-deployment3-6c95cffb97-zhc9h? false
I0123 20:18:44.894377       1 postFilter.go:137] [PREEMPT CALL] No node was chosen to allocate pod test-deployment2-59c6b78cd5-csvbh
I0123 20:18:47.100834       1 postFilter.go:69] Comparando pod original com o atualizado...
I0123 20:18:47.111814       1 postFilter.go:76] Successfully retrieved updated pod default/test-deployment2-59c6b78cd5-csvbh from lister
I0123 20:18:47.128018       1 postFilter.go:218] [compareNodeResources] Recursos calculados no nó minikube: CPU = 1750 mCPU, Memória = 178257920 bytes
I0123 20:18:47.134793       1 postFilter.go:219] [compareNodeResources] Recursos do snapshot no nó minikube: CPU = 1750 mCPU, Memória = 178257920 bytes
I0123 20:18:47.134833       1 postFilter.go:225] [compareNodeResources] Recursos de CPU do nó minikube estão sincronizados: 1750 mCPU
I0123 20:18:47.134966       1 postFilter.go:231] [compareNodeResources] Recursos de memória do nó minikube estão sincronizados: 178257920 bytes
I0123 20:18:47.148714       1 scheduler.go:578] [GetControllerMetricInfo] Iniciando para o pod: default/test-deployment3-6c95cffb97-zhc9h
I0123 20:18:47.148750       1 scheduler.go:583] [GetControllerMetricInfo] Obtendo o nome do controlador para o pod: default/test-deployment3-6c95cffb97-zhc9h
I0123 20:18:47.148762       1 types.go:743] [ControllerName] Verificando as anotações do pod default/test-deployment3-6c95cffb97-zhc9h
I0123 20:18:47.148776       1 types.go:761] [ControllerName] Anotação 'controller' encontrada para o pod default/test-deployment3-6c95cffb97-zhc9h: test-controller3
I0123 20:18:47.148788       1 scheduler.go:586] [GetControllerMetricInfo] Métricas do controlador definidas para o pod: default/test-deployment3-6c95cffb97-zhc9h
I0123 20:18:47.148801       1 scheduler.go:83] [HigherPrecedence] Calculando precedência entre test-deployment2-59c6b78cd5-csvbh e test-deployment3-6c95cffb97-zhc9h
I0123 20:18:47.148812       1 scheduler.go:116] [WaitForPodsOnCache] Verificando se o pod test-deployment2-59c6b78cd5-csvbh está no cache...
I0123 20:18:47.148821       1 scheduler.go:578] [GetControllerMetricInfo] Iniciando para o pod: default/test-deployment2-59c6b78cd5-csvbh
I0123 20:18:47.148831       1 scheduler.go:583] [GetControllerMetricInfo] Obtendo o nome do controlador para o pod: default/test-deployment2-59c6b78cd5-csvbh
I0123 20:18:47.148840       1 types.go:743] [ControllerName] Verificando as anotações do pod default/test-deployment2-59c6b78cd5-csvbh
I0123 20:18:47.148955       1 types.go:761] [ControllerName] Anotação 'controller' encontrada para o pod default/test-deployment2-59c6b78cd5-csvbh: test-controller2
I0123 20:18:47.148969       1 scheduler.go:586] [GetControllerMetricInfo] Métricas do controlador definidas para o pod: default/test-deployment2-59c6b78cd5-csvbh
I0123 20:18:47.170302       1 scheduler.go:69] Estado no Informer: map[controller:test-controller2]
I0123 20:18:47.170334       1 scheduler.go:70] Estado real no cluster: map[controller:test-controller2]
I0123 20:18:47.170343       1 scheduler.go:138] [WaitForPodsOnCache] Pod test-deployment2-59c6b78cd5-csvbh encontrado no cache.
I0123 20:18:47.170350       1 scheduler.go:116] [WaitForPodsOnCache] Verificando se o pod test-deployment3-6c95cffb97-zhc9h está no cache...
I0123 20:18:47.170359       1 scheduler.go:578] [GetControllerMetricInfo] Iniciando para o pod: default/test-deployment3-6c95cffb97-zhc9h
I0123 20:18:47.170366       1 scheduler.go:583] [GetControllerMetricInfo] Obtendo o nome do controlador para o pod: default/test-deployment3-6c95cffb97-zhc9h
I0123 20:18:47.170373       1 types.go:743] [ControllerName] Verificando as anotações do pod default/test-deployment3-6c95cffb97-zhc9h
I0123 20:18:47.170381       1 types.go:761] [ControllerName] Anotação 'controller' encontrada para o pod default/test-deployment3-6c95cffb97-zhc9h: test-controller3
I0123 20:18:47.170390       1 scheduler.go:586] [GetControllerMetricInfo] Métricas do controlador definidas para o pod: default/test-deployment3-6c95cffb97-zhc9h
I0123 20:18:47.179811       1 scheduler.go:69] Estado no Informer: map[controller:test-controller3]
I0123 20:18:47.179936       1 scheduler.go:70] Estado real no cluster: map[controller:test-controller3]
I0123 20:18:47.179952       1 scheduler.go:138] [WaitForPodsOnCache] Pod test-deployment3-6c95cffb97-zhc9h encontrado no cache.
I0123 20:18:47.179959       1 scheduler.go:578] [GetControllerMetricInfo] Iniciando para o pod: default/test-deployment2-59c6b78cd5-csvbh
I0123 20:18:47.179968       1 scheduler.go:583] [GetControllerMetricInfo] Obtendo o nome do controlador para o pod: default/test-deployment2-59c6b78cd5-csvbh
I0123 20:18:47.180066       1 types.go:743] [ControllerName] Verificando as anotações do pod default/test-deployment2-59c6b78cd5-csvbh
I0123 20:18:47.180298       1 types.go:761] [ControllerName] Anotação 'controller' encontrada para o pod default/test-deployment2-59c6b78cd5-csvbh: test-controller2
I0123 20:18:47.180309       1 scheduler.go:586] [GetControllerMetricInfo] Métricas do controlador definidas para o pod: default/test-deployment2-59c6b78cd5-csvbh
I0123 20:18:47.180319       1 scheduler.go:578] [GetControllerMetricInfo] Iniciando para o pod: default/test-deployment3-6c95cffb97-zhc9h
I0123 20:18:47.180325       1 scheduler.go:583] [GetControllerMetricInfo] Obtendo o nome do controlador para o pod: default/test-deployment3-6c95cffb97-zhc9h
I0123 20:18:47.180329       1 types.go:743] [ControllerName] Verificando as anotações do pod default/test-deployment3-6c95cffb97-zhc9h
I0123 20:18:47.180335       1 types.go:761] [ControllerName] Anotação 'controller' encontrada para o pod default/test-deployment3-6c95cffb97-zhc9h: test-controller3
I0123 20:18:47.180423       1 scheduler.go:586] [GetControllerMetricInfo] Métricas do controlador definidas para o pod: default/test-deployment3-6c95cffb97-zhc9h
I0123 20:18:47.180447       1 scheduler.go:97] [HigherPrecedence] Métricas para test-deployment2-59c6b78cd5-csvbh: QoS = 42.642464, Importância = 0.80
I0123 20:18:47.180459       1 scheduler.go:98] [HigherPrecedence] Métricas para test-deployment3-6c95cffb97-zhc9h: QoS = -6.249712, Importância = 0.80
I0123 20:18:47.180551       1 scheduler.go:109] [HigherPrecedence] Decisão final: test-deployment2-59c6b78cd5-csvbh tem precedência sobre test-deployment3-6c95cffb97-zhc9h? false
I0123 20:18:47.180696       1 postFilter.go:137] [PREEMPT CALL] No node was chosen to allocate pod test-deployment2-59c6b78cd5-csvbh
I0123 20:18:54.779748       1 scheduler.go:247] [OnUpdatePod] Pod atualizado: default/test-deployment3-6c95cffb97-zhc9h, Anotações: map[controller:test-controller3]
I0123 20:18:54.804312       1 scheduler.go:69] Estado no Informer: map[controller:test-controller3]
I0123 20:18:54.804540       1 scheduler.go:70] Estado real no cluster: map[controller:test-controller3]
I0123 20:18:54.804734       1 types.go:743] [ControllerName] Verificando as anotações do pod default/test-deployment3-6c95cffb97-zhc9h
I0123 20:18:54.805003       1 types.go:761] [ControllerName] Anotação 'controller' encontrada para o pod default/test-deployment3-6c95cffb97-zhc9h: test-controller3

























I0123 20:23:53.834052       1 postFilter.go:69] Comparando pod original com o atualizado...
I0123 20:23:53.837740       1 postFilter.go:76] Successfully retrieved updated pod default/test-deployment2-59c6b78cd5-csvbh from lister
I0123 20:23:53.856732       1 postFilter.go:218] [compareNodeResources] Recursos calculados no nó minikube: CPU = 1750 mCPU, Memória = 178257920 bytes
I0123 20:23:53.859075       1 postFilter.go:219] [compareNodeResources] Recursos do snapshot no nó minikube: CPU = 1750 mCPU, Memória = 178257920 bytes
I0123 20:23:53.859105       1 postFilter.go:225] [compareNodeResources] Recursos de CPU do nó minikube estão sincronizados: 1750 mCPU
I0123 20:23:53.859209       1 postFilter.go:231] [compareNodeResources] Recursos de memória do nó minikube estão sincronizados: 178257920 bytes
I0123 20:23:53.860167       1 scheduler.go:578] [GetControllerMetricInfo] Iniciando para o pod: default/test-deployment3-6c95cffb97-zhc9h
I0123 20:23:53.860204       1 scheduler.go:583] [GetControllerMetricInfo] Obtendo o nome do controlador para o pod: default/test-deployment3-6c95cffb97-zhc9h
I0123 20:23:53.860261       1 types.go:743] [ControllerName] Verificando as anotações do pod default/test-deployment3-6c95cffb97-zhc9h
I0123 20:23:53.860293       1 types.go:761] [ControllerName] Anotação 'controller' encontrada para o pod default/test-deployment3-6c95cffb97-zhc9h: test-controller3
I0123 20:23:53.860338       1 scheduler.go:586] [GetControllerMetricInfo] Métricas do controlador definidas para o pod: default/test-deployment3-6c95cffb97-zhc9h
I0123 20:23:53.860370       1 scheduler.go:83] [HigherPrecedence] Calculando precedência entre test-deployment2-59c6b78cd5-csvbh e test-deployment3-6c95cffb97-zhc9h
I0123 20:23:53.860395       1 scheduler.go:116] [WaitForPodsOnCache] Verificando se o pod test-deployment2-59c6b78cd5-csvbh está no cache...
I0123 20:23:53.860406       1 scheduler.go:578] [GetControllerMetricInfo] Iniciando para o pod: default/test-deployment2-59c6b78cd5-csvbh
I0123 20:23:53.860416       1 scheduler.go:583] [GetControllerMetricInfo] Obtendo o nome do controlador para o pod: default/test-deployment2-59c6b78cd5-csvbh
I0123 20:23:53.860425       1 types.go:743] [ControllerName] Verificando as anotações do pod default/test-deployment2-59c6b78cd5-csvbh
I0123 20:23:53.860437       1 types.go:761] [ControllerName] Anotação 'controller' encontrada para o pod default/test-deployment2-59c6b78cd5-csvbh: test-controller2
I0123 20:23:53.860447       1 scheduler.go:586] [GetControllerMetricInfo] Métricas do controlador definidas para o pod: default/test-deployment2-59c6b78cd5-csvbh
I0123 20:23:53.881803       1 scheduler.go:69] Estado no Informer: map[controller:test-controller2]
I0123 20:23:53.882185       1 scheduler.go:70] Estado real no cluster: map[controller:test-controller2]
I0123 20:23:53.882391       1 scheduler.go:138] [WaitForPodsOnCache] Pod test-deployment2-59c6b78cd5-csvbh encontrado no cache.
I0123 20:23:53.882563       1 scheduler.go:116] [WaitForPodsOnCache] Verificando se o pod test-deployment3-6c95cffb97-zhc9h está no cache...
I0123 20:23:53.882666       1 scheduler.go:578] [GetControllerMetricInfo] Iniciando para o pod: default/test-deployment3-6c95cffb97-zhc9h
I0123 20:23:53.882790       1 scheduler.go:583] [GetControllerMetricInfo] Obtendo o nome do controlador para o pod: default/test-deployment3-6c95cffb97-zhc9h
I0123 20:23:53.882814       1 types.go:743] [ControllerName] Verificando as anotações do pod default/test-deployment3-6c95cffb97-zhc9h
I0123 20:23:53.882837       1 types.go:761] [ControllerName] Anotação 'controller' encontrada para o pod default/test-deployment3-6c95cffb97-zhc9h: test-controller3
I0123 20:23:53.882987       1 scheduler.go:586] [GetControllerMetricInfo] Métricas do controlador definidas para o pod: default/test-deployment3-6c95cffb97-zhc9h
I0123 20:23:53.890169       1 scheduler.go:69] Estado no Informer: map[controller:test-controller3]
I0123 20:23:53.890241       1 scheduler.go:70] Estado real no cluster: map[controller:test-controller3]
I0123 20:23:53.890254       1 scheduler.go:138] [WaitForPodsOnCache] Pod test-deployment3-6c95cffb97-zhc9h encontrado no cache.
I0123 20:23:53.890282       1 scheduler.go:578] [GetControllerMetricInfo] Iniciando para o pod: default/test-deployment2-59c6b78cd5-csvbh
I0123 20:23:53.890291       1 scheduler.go:583] [GetControllerMetricInfo] Obtendo o nome do controlador para o pod: default/test-deployment2-59c6b78cd5-csvbh
I0123 20:23:53.890307       1 types.go:743] [ControllerName] Verificando as anotações do pod default/test-deployment2-59c6b78cd5-csvbh
I0123 20:23:53.890316       1 types.go:761] [ControllerName] Anotação 'controller' encontrada para o pod default/test-deployment2-59c6b78cd5-csvbh: test-controller2
I0123 20:23:53.890326       1 scheduler.go:586] [GetControllerMetricInfo] Métricas do controlador definidas para o pod: default/test-deployment2-59c6b78cd5-csvbh
I0123 20:23:53.890340       1 scheduler.go:578] [GetControllerMetricInfo] Iniciando para o pod: default/test-deployment3-6c95cffb97-zhc9h
I0123 20:23:53.890382       1 scheduler.go:583] [GetControllerMetricInfo] Obtendo o nome do controlador para o pod: default/test-deployment3-6c95cffb97-zhc9h
I0123 20:23:53.890391       1 types.go:743] [ControllerName] Verificando as anotações do pod default/test-deployment3-6c95cffb97-zhc9h
I0123 20:23:53.890402       1 types.go:761] [ControllerName] Anotação 'controller' encontrada para o pod default/test-deployment3-6c95cffb97-zhc9h: test-controller3
I0123 20:23:53.890442       1 scheduler.go:586] [GetControllerMetricInfo] Métricas do controlador definidas para o pod: default/test-deployment3-6c95cffb97-zhc9h
I0123 20:23:53.890470       1 scheduler.go:97] [HigherPrecedence] Métricas para test-deployment2-59c6b78cd5-csvbh: QoS = -264.069087, Importância = 0.80
I0123 20:23:53.890547       1 scheduler.go:98] [HigherPrecedence] Métricas para test-deployment3-6c95cffb97-zhc9h: QoS = 70.428176, Importância = 0.80
I0123 20:23:53.890561       1 scheduler.go:109] [HigherPrecedence] Decisão final: test-deployment2-59c6b78cd5-csvbh tem precedência sobre test-deployment3-6c95cffb97-zhc9h? true
I0123 20:23:53.890573       1 types.go:743] [ControllerName] Verificando as anotações do pod default/test-deployment2-59c6b78cd5-csvbh
I0123 20:23:53.890580       1 types.go:761] [ControllerName] Anotação 'controller' encontrada para o pod default/test-deployment2-59c6b78cd5-csvbh: test-controller2
I0123 20:23:53.890586       1 types.go:743] [ControllerName] Verificando as anotações do pod default/test-deployment3-6c95cffb97-zhc9h
I0123 20:23:53.890591       1 types.go:761] [ControllerName] Anotação 'controller' encontrada para o pod default/test-deployment3-6c95cffb97-zhc9h: test-controller3
I0123 20:23:53.890597       1 scheduler.go:578] [GetControllerMetricInfo] Iniciando para o pod: default/test-deployment3-6c95cffb97-zhc9h
I0123 20:23:53.890603       1 scheduler.go:583] [GetControllerMetricInfo] Obtendo o nome do controlador para o pod: default/test-deployment3-6c95cffb97-zhc9h
I0123 20:23:53.890612       1 types.go:743] [ControllerName] Verificando as anotações do pod default/test-deployment3-6c95cffb97-zhc9h
I0123 20:23:53.890649       1 types.go:761] [ControllerName] Anotação 'controller' encontrada para o pod default/test-deployment3-6c95cffb97-zhc9h: test-controller3
I0123 20:23:53.890659       1 scheduler.go:586] [GetControllerMetricInfo] Métricas do controlador definidas para o pod: default/test-deployment3-6c95cffb97-zhc9h
I0123 20:23:53.890666       1 scheduler.go:578] [GetControllerMetricInfo] Iniciando para o pod: default/test-deployment3-6c95cffb97-zhc9h
I0123 20:23:53.890673       1 scheduler.go:583] [GetControllerMetricInfo] Obtendo o nome do controlador para o pod: default/test-deployment3-6c95cffb97-zhc9h
I0123 20:23:53.890680       1 types.go:743] [ControllerName] Verificando as anotações do pod default/test-deployment3-6c95cffb97-zhc9h
I0123 20:23:53.890716       1 types.go:761] [ControllerName] Anotação 'controller' encontrada para o pod default/test-deployment3-6c95cffb97-zhc9h: test-controller3
I0123 20:23:53.890726       1 scheduler.go:586] [GetControllerMetricInfo] Métricas do controlador definidas para o pod: default/test-deployment3-6c95cffb97-zhc9h
I0123 20:23:53.890734       1 types.go:743] [ControllerName] Verificando as anotações do pod default/test-deployment3-6c95cffb97-zhc9h
I0123 20:23:53.890772       1 types.go:761] [ControllerName] Anotação 'controller' encontrada para o pod default/test-deployment3-6c95cffb97-zhc9h: test-controller3
I0123 20:23:53.890980       1 scheduler.go:578] [GetControllerMetricInfo] Iniciando para o pod: default/test-deployment3-6c95cffb97-zhc9h
I0123 20:23:53.891020       1 scheduler.go:583] [GetControllerMetricInfo] Obtendo o nome do controlador para o pod: default/test-deployment3-6c95cffb97-zhc9h
I0123 20:23:53.891028       1 types.go:743] [ControllerName] Verificando as anotações do pod default/test-deployment3-6c95cffb97-zhc9h
I0123 20:23:53.891035       1 types.go:761] [ControllerName] Anotação 'controller' encontrada para o pod default/test-deployment3-6c95cffb97-zhc9h: test-controller3
I0123 20:23:53.891043       1 scheduler.go:586] [GetControllerMetricInfo] Métricas do controlador definidas para o pod: default/test-deployment3-6c95cffb97-zhc9h
I0123 20:23:53.891052       1 scheduler.go:578] [GetControllerMetricInfo] Iniciando para o pod: default/test-deployment3-6c95cffb97-zhc9h
I0123 20:23:53.891058       1 scheduler.go:583] [GetControllerMetricInfo] Obtendo o nome do controlador para o pod: default/test-deployment3-6c95cffb97-zhc9h
I0123 20:23:53.891063       1 types.go:743] [ControllerName] Verificando as anotações do pod default/test-deployment3-6c95cffb97-zhc9h
I0123 20:23:53.891069       1 types.go:761] [ControllerName] Anotação 'controller' encontrada para o pod default/test-deployment3-6c95cffb97-zhc9h: test-controller3
I0123 20:23:53.891075       1 scheduler.go:586] [GetControllerMetricInfo] Métricas do controlador definidas para o pod: default/test-deployment3-6c95cffb97-zhc9h
I0123 20:23:53.891094       1 postFilter.go:140] [PREEMPT CALL] The node minikube  was chosen to allocate pod test-deployment2-59c6b78cd5-csvbh
I0123 20:23:53.891106       1 postFilter.go:144] [Preempt] Iniciando a remoção dos pods preemptados no nó minikube para alocar o pod default/test-deployment2-59c6b78cd5-csvbh. Total de vítimas: 1
I0123 20:23:53.891134       1 postFilter.go:148] [Preempt] Tentando remover o pod default/test-deployment3-6c95cffb97-zhc9h no nó minikube
I0123 20:23:53.948766       1 scheduler.go:247] [OnUpdatePod] Pod atualizado: default/test-deployment3-6c95cffb97-zhc9h, Anotações: map[controller:test-controller3]
I0123 20:23:53.952570       1 postFilter.go:153] [Preempt] Pod default/test-deployment3-6c95cffb97-zhc9h removido com sucesso no nó minikube
I0123 20:23:53.965473       1 postFilter.go:159] test-deployment3-6c95cffb97-zhc9h_default preempted by test-deployment2-59c6b78cd5-csvbh_default on node minikube
I0123 20:23:53.967290       1 postFilter.go:164] [Preempt] Total de pods preemptados no nó minikube: 1
I0123 20:23:53.967405       1 postFilter.go:171] [Preempt] Verificando pods de menor precedência no nó minikube que precisam ter o campo NominatedNodeName limpo
I0123 20:23:53.967420       1 postFilter.go:181] [Preempt] Finalizado para o nó minikube. Pod default/test-deployment2-59c6b78cd5-csvbh deve ser alocado agora.
I0123 20:23:54.293186       1 scheduler.go:69] Estado no Informer: map[controller:test-controller3]
I0123 20:23:54.293282       1 scheduler.go:70] Estado real no cluster: map[controller:test-controller3]
I0123 20:23:54.293304       1 types.go:743] [ControllerName] Verificando as anotações do pod default/test-deployment3-6c95cffb97-zhc9h
I0123 20:23:54.293320       1 types.go:761] [ControllerName] Anotação 'controller' encontrada para o pod default/test-deployment3-6c95cffb97-zhc9h: test-controller3
I0123 20:23:54.293479       1 scheduler.go:247] [OnUpdatePod] Pod atualizado: default/test-deployment2-59c6b78cd5-csvbh, Anotações: map[controller:test-controller2]
I0123 20:23:54.293943       1 types.go:743] [ControllerName] Verificando as anotações do pod default/test-deployment3-6c95cffb97-zhc9h
I0123 20:23:54.294008       1 types.go:761] [ControllerName] Anotação 'controller' encontrada para o pod default/test-deployment3-6c95cffb97-zhc9h: test-controller3
I0123 20:23:54.319602       1 scheduler.go:69] Estado no Informer: map[controller:test-controller2]
I0123 20:23:54.319666       1 scheduler.go:70] Estado real no cluster: map[controller:test-controller2]
I0123 20:23:54.319681       1 types.go:743] [ControllerName] Verificando as anotações do pod default/test-deployment2-59c6b78cd5-csvbh
I0123 20:23:54.319690       1 types.go:761] [ControllerName] Anotação 'controller' encontrada para o pod default/test-deployment2-59c6b78cd5-csvbh: test-controller2
I0123 20:23:54.637013       1 scheduler.go:213] [OnAddPod] Pod adicionado: default/test-deployment3-6c95cffb97-sns7c, Anotações: map[controller:test-controller3]
I0123 20:23:54.648114       1 postFilter.go:69] Comparando pod original com o atualizado...
I0123 20:23:54.648192       1 postFilter.go:76] Successfully retrieved updated pod default/test-deployment3-6c95cffb97-sns7c from lister
I0123 20:23:55.053225       1 scheduler.go:69] Estado no Informer: map[controller:test-controller3]
I0123 20:23:55.053257       1 scheduler.go:70] Estado real no cluster: map[controller:test-controller3]
I0123 20:23:55.055177       1 scheduler.go:223] Pods test-deployment3-6c95cffb97-sns7c_default being added:
I0123 20:23:55.055248       1 types.go:743] [ControllerName] Verificando as anotações do pod default/test-deployment3-6c95cffb97-sns7c
I0123 20:23:55.055261       1 types.go:761] [ControllerName] Anotação 'controller' encontrada para o pod default/test-deployment3-6c95cffb97-sns7c: test-controller3
I0123 20:23:55.055283       1 types.go:743] [ControllerName] Verificando as anotações do pod default/test-deployment3-6c95cffb97-sns7c
I0123 20:23:55.055317       1 types.go:761] [ControllerName] Anotação 'controller' encontrada para o pod default/test-deployment3-6c95cffb97-sns7c: test-controller3
I0123 20:23:55.082774       1 postFilter.go:218] [compareNodeResources] Recursos calculados no nó minikube: CPU = 1750 mCPU, Memória = 178257920 bytes
I0123 20:23:55.082821       1 postFilter.go:219] [compareNodeResources] Recursos do snapshot no nó minikube: CPU = 1750 mCPU, Memória = 178257920 bytes
I0123 20:23:55.082830       1 postFilter.go:225] [compareNodeResources] Recursos de CPU do nó minikube estão sincronizados: 1750 mCPU
I0123 20:23:55.101728       1 postFilter.go:231] [compareNodeResources] Recursos de memória do nó minikube estão sincronizados: 178257920 bytes
I0123 20:23:55.104512       1 scheduler.go:578] [GetControllerMetricInfo] Iniciando para o pod: default/test-deployment3-6c95cffb97-zhc9h
I0123 20:23:55.104562       1 scheduler.go:583] [GetControllerMetricInfo] Obtendo o nome do controlador para o pod: default/test-deployment3-6c95cffb97-zhc9h
I0123 20:23:55.104570       1 types.go:743] [ControllerName] Verificando as anotações do pod default/test-deployment3-6c95cffb97-zhc9h
I0123 20:23:55.104576       1 types.go:761] [ControllerName] Anotação 'controller' encontrada para o pod default/test-deployment3-6c95cffb97-zhc9h: test-controller3
I0123 20:23:55.104582       1 scheduler.go:586] [GetControllerMetricInfo] Métricas do controlador definidas para o pod: default/test-deployment3-6c95cffb97-zhc9h
I0123 20:23:55.104656       1 scheduler.go:83] [HigherPrecedence] Calculando precedência entre test-deployment3-6c95cffb97-sns7c e test-deployment3-6c95cffb97-zhc9h
I0123 20:23:55.104664       1 scheduler.go:116] [WaitForPodsOnCache] Verificando se o pod test-deployment3-6c95cffb97-sns7c está no cache...
I0123 20:23:55.104668       1 scheduler.go:578] [GetControllerMetricInfo] Iniciando para o pod: default/test-deployment3-6c95cffb97-sns7c
I0123 20:23:55.104672       1 scheduler.go:583] [GetControllerMetricInfo] Obtendo o nome do controlador para o pod: default/test-deployment3-6c95cffb97-sns7c
I0123 20:23:55.104676       1 types.go:743] [ControllerName] Verificando as anotações do pod default/test-deployment3-6c95cffb97-sns7c
I0123 20:23:55.104680       1 types.go:761] [ControllerName] Anotação 'controller' encontrada para o pod default/test-deployment3-6c95cffb97-sns7c: test-controller3
I0123 20:23:55.104685       1 scheduler.go:586] [GetControllerMetricInfo] Métricas do controlador definidas para o pod: default/test-deployment3-6c95cffb97-sns7c
I0123 20:23:55.508517       1 scheduler.go:69] Estado no Informer: map[controller:test-controller3]
I0123 20:23:55.509129       1 scheduler.go:70] Estado real no cluster: map[controller:test-controller3]
I0123 20:23:55.509656       1 scheduler.go:138] [WaitForPodsOnCache] Pod test-deployment3-6c95cffb97-sns7c encontrado no cache.
I0123 20:23:55.509829       1 scheduler.go:116] [WaitForPodsOnCache] Verificando se o pod test-deployment3-6c95cffb97-zhc9h está no cache...
I0123 20:23:55.510037       1 scheduler.go:578] [GetControllerMetricInfo] Iniciando para o pod: default/test-deployment3-6c95cffb97-zhc9h
I0123 20:23:55.510235       1 scheduler.go:583] [GetControllerMetricInfo] Obtendo o nome do controlador para o pod: default/test-deployment3-6c95cffb97-zhc9h
I0123 20:23:55.510652       1 types.go:743] [ControllerName] Verificando as anotações do pod default/test-deployment3-6c95cffb97-zhc9h
I0123 20:23:55.510812       1 types.go:761] [ControllerName] Anotação 'controller' encontrada para o pod default/test-deployment3-6c95cffb97-zhc9h: test-controller3
I0123 20:23:55.511703       1 scheduler.go:586] [GetControllerMetricInfo] Métricas do controlador definidas para o pod: default/test-deployment3-6c95cffb97-zhc9h
I0123 20:23:55.534577       1 scheduler.go:69] Estado no Informer: map[controller:test-controller3]
I0123 20:23:55.546780       1 scheduler.go:70] Estado real no cluster: map[controller:test-controller3]
I0123 20:23:55.552203       1 scheduler.go:138] [WaitForPodsOnCache] Pod test-deployment3-6c95cffb97-zhc9h encontrado no cache.
I0123 20:23:55.552241       1 scheduler.go:578] [GetControllerMetricInfo] Iniciando para o pod: default/test-deployment3-6c95cffb97-sns7c
I0123 20:23:55.552260       1 scheduler.go:583] [GetControllerMetricInfo] Obtendo o nome do controlador para o pod: default/test-deployment3-6c95cffb97-sns7c
I0123 20:23:55.552275       1 types.go:743] [ControllerName] Verificando as anotações do pod default/test-deployment3-6c95cffb97-sns7c
I0123 20:23:55.552312       1 types.go:761] [ControllerName] Anotação 'controller' encontrada para o pod default/test-deployment3-6c95cffb97-sns7c: test-controller3
I0123 20:23:55.552332       1 scheduler.go:586] [GetControllerMetricInfo] Métricas do controlador definidas para o pod: default/test-deployment3-6c95cffb97-sns7c
I0123 20:23:55.552355       1 scheduler.go:578] [GetControllerMetricInfo] Iniciando para o pod: default/test-deployment3-6c95cffb97-zhc9h
I0123 20:23:55.552370       1 scheduler.go:583] [GetControllerMetricInfo] Obtendo o nome do controlador para o pod: default/test-deployment3-6c95cffb97-zhc9h
I0123 20:23:55.552382       1 types.go:743] [ControllerName] Verificando as anotações do pod default/test-deployment3-6c95cffb97-zhc9h
I0123 20:23:55.552398       1 types.go:761] [ControllerName] Anotação 'controller' encontrada para o pod default/test-deployment3-6c95cffb97-zhc9h: test-controller3
I0123 20:23:55.552412       1 scheduler.go:586] [GetControllerMetricInfo] Métricas do controlador definidas para o pod: default/test-deployment3-6c95cffb97-zhc9h
I0123 20:23:55.552442       1 scheduler.go:97] [HigherPrecedence] Métricas para test-deployment3-6c95cffb97-sns7c: QoS = 69.727910, Importância = 0.80
I0123 20:23:55.552467       1 scheduler.go:98] [HigherPrecedence] Métricas para test-deployment3-6c95cffb97-zhc9h: QoS = 30.938371, Importância = 0.80
I0123 20:23:55.552488       1 scheduler.go:109] [HigherPrecedence] Decisão final: test-deployment3-6c95cffb97-sns7c tem precedência sobre test-deployment3-6c95cffb97-zhc9h? false
I0123 20:23:55.552636       1 postFilter.go:137] [PREEMPT CALL] No node was chosen to allocate pod test-deployment3-6c95cffb97-sns7c
I0123 20:23:55.834137       1 scheduler.go:247] [OnUpdatePod] Pod atualizado: default/test-deployment3-6c95cffb97-sns7c, Anotações: map[controller:test-controller3]
I0123 20:23:55.853248       1 scheduler.go:69] Estado no Informer: map[controller:test-controller3]
I0123 20:23:55.853441       1 scheduler.go:70] Estado real no cluster: map[controller:test-controller3]
I0123 20:23:55.853497       1 types.go:743] [ControllerName] Verificando as anotações do pod default/test-deployment3-6c95cffb97-sns7c
I0123 20:23:55.853534       1 types.go:761] [ControllerName] Anotação 'controller' encontrada para o pod default/test-deployment3-6c95cffb97-sns7c: test-controller3
I0123 20:23:56.720168       1 scheduler.go:263] [OnDeletePod] Iniciando a execução do OnDeletePod
I0123 20:23:56.720235       1 scheduler.go:272] [OnDeletePod] DeepCopy realizado para o pod default/test-deployment3-6c95cffb97-zhc9h
I0123 20:23:56.729283       1 scheduler.go:279] [OnDeletePod] Pod deletado detectado: default/test-deployment3-6c95cffb97-zhc9h
I0123 20:23:56.729546       1 scheduler.go:281] [OnDeletePod] Atualizando métricas do pod default/test-deployment3-6c95cffb97-zhc9h
I0123 20:23:56.729595       1 types.go:743] [ControllerName] Verificando as anotações do pod default/test-deployment3-6c95cffb97-zhc9h
I0123 20:23:56.729637       1 types.go:761] [ControllerName] Anotação 'controller' encontrada para o pod default/test-deployment3-6c95cffb97-zhc9h: test-controller3
I0123 20:23:56.729680       1 scheduler.go:283] [OnDeletePod] Verificando o estado do pod default/test-deployment3-6c95cffb97-zhc9h nas métricas
I0123 20:23:56.729718       1 scheduler.go:293] [OnDeletePod] EndTime atualizado para o pod default/test-deployment3-6c95cffb97-zhc9h: 2025-01-23 20:23:56.729709435 +0000 UTC m=+604.627332036
I0123 20:23:56.729838       1 scheduler.go:297] [OnDeletePod] Finalizando a execução do OnDeletePod para o pod default/test-deployment3-6c95cffb97-zhc9h
I0123 20:23:56.747782       1 postFilter.go:69] Comparando pod original com o atualizado...
I0123 20:23:56.747975       1 postFilter.go:76] Successfully retrieved updated pod default/test-deployment3-6c95cffb97-sns7c from lister
I0123 20:23:56.760681       1 postFilter.go:218] [compareNodeResources] Recursos calculados no nó minikube: CPU = 750 mCPU, Memória = 178257920 bytes
I0123 20:23:56.760757       1 postFilter.go:219] [compareNodeResources] Recursos do snapshot no nó minikube: CPU = 750 mCPU, Memória = 178257920 bytes
I0123 20:23:56.760772       1 postFilter.go:225] [compareNodeResources] Recursos de CPU do nó minikube estão sincronizados: 750 mCPU
I0123 20:23:56.760783       1 postFilter.go:231] [compareNodeResources] Recursos de memória do nó minikube estão sincronizados: 178257920 bytes
I0123 20:23:56.765404       1 postFilter.go:140] [PREEMPT CALL] The node minikube  was chosen to allocate pod test-deployment3-6c95cffb97-sns7c
I0123 20:23:56.765668       1 postFilter.go:144] [Preempt] Iniciando a remoção dos pods preemptados no nó minikube para alocar o pod default/test-deployment3-6c95cffb97-sns7c. Total de vítimas: 0
I0123 20:23:56.765696       1 postFilter.go:164] [Preempt] Total de pods preemptados no nó minikube: 0
I0123 20:23:56.766090       1 scheduler.go:83] [HigherPrecedence] Calculando precedência entre test-deployment3-6c95cffb97-sns7c e test-deployment2-59c6b78cd5-csvbh
I0123 20:23:56.766105       1 scheduler.go:116] [WaitForPodsOnCache] Verificando se o pod test-deployment3-6c95cffb97-sns7c está no cache...
I0123 20:23:56.766122       1 scheduler.go:578] [GetControllerMetricInfo] Iniciando para o pod: default/test-deployment3-6c95cffb97-sns7c
I0123 20:23:56.771058       1 scheduler.go:583] [GetControllerMetricInfo] Obtendo o nome do controlador para o pod: default/test-deployment3-6c95cffb97-sns7c
I0123 20:23:56.771177       1 types.go:743] [ControllerName] Verificando as anotações do pod default/test-deployment3-6c95cffb97-sns7c
I0123 20:23:56.771190       1 types.go:761] [ControllerName] Anotação 'controller' encontrada para o pod default/test-deployment3-6c95cffb97-sns7c: test-controller3
I0123 20:23:56.771200       1 scheduler.go:586] [GetControllerMetricInfo] Métricas do controlador definidas para o pod: default/test-deployment3-6c95cffb97-sns7c
I0123 20:23:56.797153       1 scheduler.go:69] Estado no Informer: map[controller:test-controller3]
I0123 20:23:56.797290       1 scheduler.go:70] Estado real no cluster: map[controller:test-controller3]
I0123 20:23:56.797303       1 scheduler.go:138] [WaitForPodsOnCache] Pod test-deployment3-6c95cffb97-sns7c encontrado no cache.
I0123 20:23:56.797311       1 scheduler.go:116] [WaitForPodsOnCache] Verificando se o pod test-deployment2-59c6b78cd5-csvbh está no cache...
I0123 20:23:56.797319       1 scheduler.go:578] [GetControllerMetricInfo] Iniciando para o pod: default/test-deployment2-59c6b78cd5-csvbh
I0123 20:23:56.797326       1 scheduler.go:583] [GetControllerMetricInfo] Obtendo o nome do controlador para o pod: default/test-deployment2-59c6b78cd5-csvbh
I0123 20:23:56.797333       1 types.go:743] [ControllerName] Verificando as anotações do pod default/test-deployment2-59c6b78cd5-csvbh
I0123 20:23:56.797341       1 types.go:761] [ControllerName] Anotação 'controller' encontrada para o pod default/test-deployment2-59c6b78cd5-csvbh: test-controller2
I0123 20:23:56.797355       1 scheduler.go:586] [GetControllerMetricInfo] Métricas do controlador definidas para o pod: default/test-deployment2-59c6b78cd5-csvbh
I0123 20:23:56.814591       1 scheduler.go:69] Estado no Informer: map[controller:test-controller2]
I0123 20:23:56.814618       1 scheduler.go:70] Estado real no cluster: map[controller:test-controller2]
I0123 20:23:56.814625       1 scheduler.go:138] [WaitForPodsOnCache] Pod test-deployment2-59c6b78cd5-csvbh encontrado no cache.
I0123 20:23:56.814632       1 scheduler.go:578] [GetControllerMetricInfo] Iniciando para o pod: default/test-deployment3-6c95cffb97-sns7c
I0123 20:23:56.814638       1 scheduler.go:583] [GetControllerMetricInfo] Obtendo o nome do controlador para o pod: default/test-deployment3-6c95cffb97-sns7c
I0123 20:23:56.814644       1 types.go:743] [ControllerName] Verificando as anotações do pod default/test-deployment3-6c95cffb97-sns7c
I0123 20:23:56.814651       1 types.go:761] [ControllerName] Anotação 'controller' encontrada para o pod default/test-deployment3-6c95cffb97-sns7c: test-controller3
I0123 20:23:56.814665       1 scheduler.go:586] [GetControllerMetricInfo] Métricas do controlador definidas para o pod: default/test-deployment3-6c95cffb97-sns7c
I0123 20:23:56.814687       1 scheduler.go:578] [GetControllerMetricInfo] Iniciando para o pod: default/test-deployment2-59c6b78cd5-csvbh
I0123 20:23:56.814692       1 scheduler.go:583] [GetControllerMetricInfo] Obtendo o nome do controlador para o pod: default/test-deployment2-59c6b78cd5-csvbh
I0123 20:23:56.814696       1 types.go:743] [ControllerName] Verificando as anotações do pod default/test-deployment2-59c6b78cd5-csvbh
I0123 20:23:56.814701       1 types.go:761] [ControllerName] Anotação 'controller' encontrada para o pod default/test-deployment2-59c6b78cd5-csvbh: test-controller2
I0123 20:23:56.814706       1 scheduler.go:586] [GetControllerMetricInfo] Métricas do controlador definidas para o pod: default/test-deployment2-59c6b78cd5-csvbh
I0123 20:23:56.814724       1 scheduler.go:97] [HigherPrecedence] Métricas para test-deployment3-6c95cffb97-sns7c: QoS = 68.472795, Importância = 0.80
I0123 20:23:56.814735       1 scheduler.go:98] [HigherPrecedence] Métricas para test-deployment2-59c6b78cd5-csvbh: QoS = -266.974722, Importância = 0.80
I0123 20:23:56.814741       1 scheduler.go:109] [HigherPrecedence] Decisão final: test-deployment3-6c95cffb97-sns7c tem precedência sobre test-deployment2-59c6b78cd5-csvbh? false
I0123 20:23:56.814756       1 postFilter.go:171] [Preempt] Verificando pods de menor precedência no nó minikube que precisam ter o campo NominatedNodeName limpo
I0123 20:23:56.814771       1 postFilter.go:181] [Preempt] Finalizado para o nó minikube. Pod default/test-deployment3-6c95cffb97-sns7c deve ser alocado agora.
I0123 20:23:56.878905       1 scheduler.go:247] [OnUpdatePod] Pod atualizado: default/test-deployment3-6c95cffb97-sns7c, Anotações: map[controller:test-controller3]
I0123 20:23:56.883938       1 scheduler.go:69] Estado no Informer: map[controller:test-controller3]
I0123 20:23:56.884130       1 scheduler.go:70] Estado real no cluster: map[controller:test-controller3]
I0123 20:23:56.886164       1 types.go:743] [ControllerName] Verificando as anotações do pod default/test-deployment3-6c95cffb97-sns7c
I0123 20:23:56.886242       1 types.go:761] [ControllerName] Anotação 'controller' encontrada para o pod default/test-deployment3-6c95cffb97-sns7c: test-controller3
I0123 20:24:02.421948       1 postFilter.go:69] Comparando pod original com o atualizado...
I0123 20:24:02.421999       1 postFilter.go:76] Successfully retrieved updated pod default/test-deployment2-59c6b78cd5-csvbh from lister
I0123 20:24:02.430498       1 postFilter.go:218] [compareNodeResources] Recursos calculados no nó minikube: CPU = 750 mCPU, Memória = 178257920 bytes
I0123 20:24:02.430544       1 postFilter.go:219] [compareNodeResources] Recursos do snapshot no nó minikube: CPU = 750 mCPU, Memória = 178257920 bytes
I0123 20:24:02.430553       1 postFilter.go:225] [compareNodeResources] Recursos de CPU do nó minikube estão sincronizados: 750 mCPU
I0123 20:24:02.430561       1 postFilter.go:231] [compareNodeResources] Recursos de memória do nó minikube estão sincronizados: 178257920 bytes
I0123 20:24:02.430784       1 postFilter.go:140] [PREEMPT CALL] The node minikube  was chosen to allocate pod test-deployment2-59c6b78cd5-csvbh
I0123 20:24:02.430810       1 postFilter.go:144] [Preempt] Iniciando a remoção dos pods preemptados no nó minikube para alocar o pod default/test-deployment2-59c6b78cd5-csvbh. Total de vítimas: 0
I0123 20:24:02.430825       1 postFilter.go:164] [Preempt] Total de pods preemptados no nó minikube: 0
W0123 20:24:02.431211       1 scheduler.go:78] [HigherPrecedence] Tentativa de comparar o pod test-deployment2-59c6b78cd5-csvbh consigo mesmo. Retornando false.
I0123 20:24:02.431265       1 scheduler.go:83] [HigherPrecedence] Calculando precedência entre test-deployment2-59c6b78cd5-csvbh e test-deployment3-6c95cffb97-sns7c
I0123 20:24:02.431273       1 scheduler.go:116] [WaitForPodsOnCache] Verificando se o pod test-deployment2-59c6b78cd5-csvbh está no cache...
I0123 20:24:02.431289       1 scheduler.go:578] [GetControllerMetricInfo] Iniciando para o pod: default/test-deployment2-59c6b78cd5-csvbh
I0123 20:24:02.431295       1 scheduler.go:583] [GetControllerMetricInfo] Obtendo o nome do controlador para o pod: default/test-deployment2-59c6b78cd5-csvbh
I0123 20:24:02.431309       1 types.go:743] [ControllerName] Verificando as anotações do pod default/test-deployment2-59c6b78cd5-csvbh
I0123 20:24:02.431315       1 types.go:761] [ControllerName] Anotação 'controller' encontrada para o pod default/test-deployment2-59c6b78cd5-csvbh: test-controller2
I0123 20:24:02.431322       1 scheduler.go:586] [GetControllerMetricInfo] Métricas do controlador definidas para o pod: default/test-deployment2-59c6b78cd5-csvbh
I0123 20:24:02.444401       1 scheduler.go:69] Estado no Informer: map[controller:test-controller2]
I0123 20:24:02.444455       1 scheduler.go:70] Estado real no cluster: map[controller:test-controller2]
I0123 20:24:02.444465       1 scheduler.go:138] [WaitForPodsOnCache] Pod test-deployment2-59c6b78cd5-csvbh encontrado no cache.
I0123 20:24:02.444471       1 scheduler.go:116] [WaitForPodsOnCache] Verificando se o pod test-deployment3-6c95cffb97-sns7c está no cache...
I0123 20:24:02.444478       1 scheduler.go:578] [GetControllerMetricInfo] Iniciando para o pod: default/test-deployment3-6c95cffb97-sns7c
I0123 20:24:02.444484       1 scheduler.go:583] [GetControllerMetricInfo] Obtendo o nome do controlador para o pod: default/test-deployment3-6c95cffb97-sns7c
I0123 20:24:02.444489       1 types.go:743] [ControllerName] Verificando as anotações do pod default/test-deployment3-6c95cffb97-sns7c
I0123 20:24:02.444546       1 types.go:761] [ControllerName] Anotação 'controller' encontrada para o pod default/test-deployment3-6c95cffb97-sns7c: test-controller3
I0123 20:24:02.444561       1 scheduler.go:586] [GetControllerMetricInfo] Métricas do controlador definidas para o pod: default/test-deployment3-6c95cffb97-sns7c
I0123 20:24:02.456499       1 scheduler.go:69] Estado no Informer: map[controller:test-controller3]
I0123 20:24:02.456542       1 scheduler.go:70] Estado real no cluster: map[controller:test-controller3]
I0123 20:24:02.456555       1 scheduler.go:138] [WaitForPodsOnCache] Pod test-deployment3-6c95cffb97-sns7c encontrado no cache.
I0123 20:24:02.456567       1 scheduler.go:578] [GetControllerMetricInfo] Iniciando para o pod: default/test-deployment2-59c6b78cd5-csvbh
I0123 20:24:02.456578       1 scheduler.go:583] [GetControllerMetricInfo] Obtendo o nome do controlador para o pod: default/test-deployment2-59c6b78cd5-csvbh
I0123 20:24:02.456589       1 types.go:743] [ControllerName] Verificando as anotações do pod default/test-deployment2-59c6b78cd5-csvbh
I0123 20:24:02.456600       1 types.go:761] [ControllerName] Anotação 'controller' encontrada para o pod default/test-deployment2-59c6b78cd5-csvbh: test-controller2
I0123 20:24:02.456611       1 scheduler.go:586] [GetControllerMetricInfo] Métricas do controlador definidas para o pod: default/test-deployment2-59c6b78cd5-csvbh
I0123 20:24:02.456650       1 scheduler.go:578] [GetControllerMetricInfo] Iniciando para o pod: default/test-deployment3-6c95cffb97-sns7c
I0123 20:24:02.456661       1 scheduler.go:583] [GetControllerMetricInfo] Obtendo o nome do controlador para o pod: default/test-deployment3-6c95cffb97-sns7c
I0123 20:24:02.456670       1 types.go:743] [ControllerName] Verificando as anotações do pod default/test-deployment3-6c95cffb97-sns7c
I0123 20:24:02.456680       1 types.go:761] [ControllerName] Anotação 'controller' encontrada para o pod default/test-deployment3-6c95cffb97-sns7c: test-controller3
I0123 20:24:02.456690       1 scheduler.go:586] [GetControllerMetricInfo] Métricas do controlador definidas para o pod: default/test-deployment3-6c95cffb97-sns7c
I0123 20:24:02.456722       1 scheduler.go:97] [HigherPrecedence] Métricas para test-deployment2-59c6b78cd5-csvbh: QoS = -272.640002, Importância = 0.80
I0123 20:24:02.456739       1 scheduler.go:98] [HigherPrecedence] Métricas para test-deployment3-6c95cffb97-sns7c: QoS = 62.807515, Importância = 0.80
I0123 20:24:02.456752       1 scheduler.go:109] [HigherPrecedence] Decisão final: test-deployment2-59c6b78cd5-csvbh tem precedência sobre test-deployment3-6c95cffb97-sns7c? true
I0123 20:24:02.456784       1 postFilter.go:171] [Preempt] Verificando pods de menor precedência no nó minikube que precisam ter o campo NominatedNodeName limpo
I0123 20:24:02.456816       1 postFilter.go:173] [Preempt] Limpando o campo NominatedNodeName do pod default/test-deployment3-6c95cffb97-sns7c
I0123 20:24:02.684164       1 postFilter.go:181] [Preempt] Finalizado para o nó minikube. Pod default/test-deployment2-59c6b78cd5-csvbh deve ser alocado agora.
I0123 20:24:02.685495       1 scheduler.go:247] [OnUpdatePod] Pod atualizado: default/test-deployment3-6c95cffb97-sns7c, Anotações: map[controller:test-controller3]
I0123 20:24:02.716130       1 scheduler.go:69] Estado no Informer: map[controller:test-controller3]
I0123 20:24:02.716420       1 scheduler.go:70] Estado real no cluster: map[controller:test-controller3]
I0123 20:24:02.716439       1 types.go:743] [ControllerName] Verificando as anotações do pod default/test-deployment3-6c95cffb97-sns7c
I0123 20:24:02.716448       1 types.go:761] [ControllerName] Anotação 'controller' encontrada para o pod default/test-deployment3-6c95cffb97-sns7c: test-controller3
