I0307 13:14:17.178533       1 serving.go:386] Generated self-signed cert in-memory
W0307 13:14:17.179267       1 client_config.go:667] Neither --kubeconfig nor --master was specified.  Using the inClusterConfig.  This might not work.
I0307 13:14:17.491942       1 server.go:166] "Starting Kubernetes Scheduler" version="v0.0.0-master+$Format:%H$"
I0307 13:14:17.491972       1 server.go:168] "Golang settings" GOGC="" GOMAXPROCS="" GOTRACEBACK=""
I0307 13:14:17.495464       1 requestheader_controller.go:180] Starting RequestHeaderAuthRequestController
I0307 13:14:17.495468       1 configmap_cafile_content.go:205] "Starting controller" name="client-ca::kube-system::extension-apiserver-authentication::client-ca-file"
I0307 13:14:17.495516       1 configmap_cafile_content.go:205] "Starting controller" name="client-ca::kube-system::extension-apiserver-authentication::requestheader-client-ca-file"
I0307 13:14:17.495530       1 shared_informer.go:313] Waiting for caches to sync for client-ca::kube-system::extension-apiserver-authentication::client-ca-file
I0307 13:14:17.495534       1 shared_informer.go:313] Waiting for caches to sync for RequestHeaderAuthRequestController
I0307 13:14:17.495537       1 shared_informer.go:313] Waiting for caches to sync for client-ca::kube-system::extension-apiserver-authentication::requestheader-client-ca-file
I0307 13:14:17.495618       1 secure_serving.go:213] Serving securely on [::]:10259
I0307 13:14:17.495673       1 tlsconfig.go:243] "Starting DynamicServingCertificateController"
I0307 13:14:17.501169       1 scheduler.go:220] [OnAddPod] Pod adicionado: kube-system/coredns-668d6bf9bc-tbzv9, Anotações: map[]
I0307 13:14:17.502945       1 scheduler.go:75] Estado no Informer: map[]
I0307 13:14:17.502963       1 scheduler.go:76] Estado real no cluster: map[]
I0307 13:14:17.502968       1 scheduler.go:226] [OnAddPod] Ignorando pod kube-system/coredns-668d6bf9bc-tbzv9 pois pertence ao namespace kube-system
I0307 13:14:17.502992       1 scheduler.go:220] [OnAddPod] Pod adicionado: kube-system/custom-scheduler-8dcdbb8b5-lvx5k, Anotações: map[]
I0307 13:14:17.504186       1 scheduler.go:75] Estado no Informer: map[]
I0307 13:14:17.504203       1 scheduler.go:76] Estado real no cluster: map[]
I0307 13:14:17.504207       1 scheduler.go:226] [OnAddPod] Ignorando pod kube-system/custom-scheduler-8dcdbb8b5-lvx5k pois pertence ao namespace kube-system
I0307 13:14:17.504234       1 scheduler.go:220] [OnAddPod] Pod adicionado: kube-system/etcd-minikube, Anotações: map[kubeadm.kubernetes.io/etcd.advertise-client-urls:https://192.168.49.2:2379 kubernetes.io/config.hash:2b4b75c2a289008e0b381891e9683040 kubernetes.io/config.mirror:2b4b75c2a289008e0b381891e9683040 kubernetes.io/config.seen:2025-02-28T14:06:38.491414868Z kubernetes.io/config.source:file]
I0307 13:14:17.505480       1 scheduler.go:75] Estado no Informer: map[kubeadm.kubernetes.io/etcd.advertise-client-urls:https://192.168.49.2:2379 kubernetes.io/config.hash:2b4b75c2a289008e0b381891e9683040 kubernetes.io/config.mirror:2b4b75c2a289008e0b381891e9683040 kubernetes.io/config.seen:2025-02-28T14:06:38.491414868Z kubernetes.io/config.source:file]
I0307 13:14:17.505502       1 scheduler.go:76] Estado real no cluster: map[kubeadm.kubernetes.io/etcd.advertise-client-urls:https://192.168.49.2:2379 kubernetes.io/config.hash:2b4b75c2a289008e0b381891e9683040 kubernetes.io/config.mirror:2b4b75c2a289008e0b381891e9683040 kubernetes.io/config.seen:2025-02-28T14:06:38.491414868Z kubernetes.io/config.source:file]
I0307 13:14:17.505512       1 scheduler.go:226] [OnAddPod] Ignorando pod kube-system/etcd-minikube pois pertence ao namespace kube-system
I0307 13:14:17.505547       1 scheduler.go:220] [OnAddPod] Pod adicionado: kube-system/kube-apiserver-minikube, Anotações: map[kubeadm.kubernetes.io/kube-apiserver.advertise-address.endpoint:192.168.49.2:8443 kubernetes.io/config.hash:d72d0a4cf4be077c9919d46b7358a5e8 kubernetes.io/config.mirror:d72d0a4cf4be077c9919d46b7358a5e8 kubernetes.io/config.seen:2025-02-28T14:06:38.491410078Z kubernetes.io/config.source:file]
I0307 13:14:17.506971       1 scheduler.go:75] Estado no Informer: map[kubeadm.kubernetes.io/kube-apiserver.advertise-address.endpoint:192.168.49.2:8443 kubernetes.io/config.hash:d72d0a4cf4be077c9919d46b7358a5e8 kubernetes.io/config.mirror:d72d0a4cf4be077c9919d46b7358a5e8 kubernetes.io/config.seen:2025-02-28T14:06:38.491410078Z kubernetes.io/config.source:file]
I0307 13:14:17.506990       1 scheduler.go:76] Estado real no cluster: map[kubeadm.kubernetes.io/kube-apiserver.advertise-address.endpoint:192.168.49.2:8443 kubernetes.io/config.hash:d72d0a4cf4be077c9919d46b7358a5e8 kubernetes.io/config.mirror:d72d0a4cf4be077c9919d46b7358a5e8 kubernetes.io/config.seen:2025-02-28T14:06:38.491410078Z kubernetes.io/config.source:file]
I0307 13:14:17.506997       1 scheduler.go:226] [OnAddPod] Ignorando pod kube-system/kube-apiserver-minikube pois pertence ao namespace kube-system
I0307 13:14:17.507039       1 scheduler.go:220] [OnAddPod] Pod adicionado: kube-system/kube-controller-manager-minikube, Anotações: map[kubernetes.io/config.hash:843c74f7b3bc7d7040a05c31708a6a30 kubernetes.io/config.mirror:843c74f7b3bc7d7040a05c31708a6a30 kubernetes.io/config.seen:2025-02-28T14:06:38.491412428Z kubernetes.io/config.source:file]
I0307 13:14:17.508477       1 scheduler.go:75] Estado no Informer: map[kubernetes.io/config.hash:843c74f7b3bc7d7040a05c31708a6a30 kubernetes.io/config.mirror:843c74f7b3bc7d7040a05c31708a6a30 kubernetes.io/config.seen:2025-02-28T14:06:38.491412428Z kubernetes.io/config.source:file]
I0307 13:14:17.508500       1 scheduler.go:76] Estado real no cluster: map[kubernetes.io/config.hash:843c74f7b3bc7d7040a05c31708a6a30 kubernetes.io/config.mirror:843c74f7b3bc7d7040a05c31708a6a30 kubernetes.io/config.seen:2025-02-28T14:06:38.491412428Z kubernetes.io/config.source:file]
I0307 13:14:17.508507       1 scheduler.go:226] [OnAddPod] Ignorando pod kube-system/kube-controller-manager-minikube pois pertence ao namespace kube-system
I0307 13:14:17.508539       1 scheduler.go:220] [OnAddPod] Pod adicionado: kube-system/kube-proxy-hqbh2, Anotações: map[]
I0307 13:14:17.510053       1 scheduler.go:75] Estado no Informer: map[]
I0307 13:14:17.510069       1 scheduler.go:76] Estado real no cluster: map[]
I0307 13:14:17.510073       1 scheduler.go:226] [OnAddPod] Ignorando pod kube-system/kube-proxy-hqbh2 pois pertence ao namespace kube-system
I0307 13:14:17.510098       1 scheduler.go:220] [OnAddPod] Pod adicionado: kube-system/kube-scheduler-minikube, Anotações: map[kubernetes.io/config.hash:d14ce008bee3a1f3bd7cf547688f9dfe kubernetes.io/config.mirror:d14ce008bee3a1f3bd7cf547688f9dfe kubernetes.io/config.seen:2025-02-28T14:06:38.491413718Z kubernetes.io/config.source:file]
I0307 13:14:17.511408       1 scheduler.go:75] Estado no Informer: map[kubernetes.io/config.hash:d14ce008bee3a1f3bd7cf547688f9dfe kubernetes.io/config.mirror:d14ce008bee3a1f3bd7cf547688f9dfe kubernetes.io/config.seen:2025-02-28T14:06:38.491413718Z kubernetes.io/config.source:file]
I0307 13:14:17.511441       1 scheduler.go:76] Estado real no cluster: map[kubernetes.io/config.hash:d14ce008bee3a1f3bd7cf547688f9dfe kubernetes.io/config.mirror:d14ce008bee3a1f3bd7cf547688f9dfe kubernetes.io/config.seen:2025-02-28T14:06:38.491413718Z kubernetes.io/config.source:file]
I0307 13:14:17.511449       1 scheduler.go:226] [OnAddPod] Ignorando pod kube-system/kube-scheduler-minikube pois pertence ao namespace kube-system
I0307 13:14:17.511478       1 scheduler.go:220] [OnAddPod] Pod adicionado: kube-system/storage-provisioner, Anotações: map[kubectl.kubernetes.io/last-applied-configuration:{"apiVersion":"v1","kind":"Pod","metadata":{"annotations":{},"labels":{"addonmanager.kubernetes.io/mode":"Reconcile","integration-test":"storage-provisioner"},"name":"storage-provisioner","namespace":"kube-system"},"spec":{"containers":[{"command":["/storage-provisioner"],"image":"gcr.io/k8s-minikube/storage-provisioner:v5","imagePullPolicy":"IfNotPresent","name":"storage-provisioner","volumeMounts":[{"mountPath":"/tmp","name":"tmp"}]}],"hostNetwork":true,"serviceAccountName":"storage-provisioner","volumes":[{"hostPath":{"path":"/tmp","type":"Directory"},"name":"tmp"}]}}
]
I0307 13:14:17.512972       1 scheduler.go:75] Estado no Informer: map[kubectl.kubernetes.io/last-applied-configuration:{"apiVersion":"v1","kind":"Pod","metadata":{"annotations":{},"labels":{"addonmanager.kubernetes.io/mode":"Reconcile","integration-test":"storage-provisioner"},"name":"storage-provisioner","namespace":"kube-system"},"spec":{"containers":[{"command":["/storage-provisioner"],"image":"gcr.io/k8s-minikube/storage-provisioner:v5","imagePullPolicy":"IfNotPresent","name":"storage-provisioner","volumeMounts":[{"mountPath":"/tmp","name":"tmp"}]}],"hostNetwork":true,"serviceAccountName":"storage-provisioner","volumes":[{"hostPath":{"path":"/tmp","type":"Directory"},"name":"tmp"}]}}
]
I0307 13:14:17.512999       1 scheduler.go:76] Estado real no cluster: map[kubectl.kubernetes.io/last-applied-configuration:{"apiVersion":"v1","kind":"Pod","metadata":{"annotations":{},"labels":{"addonmanager.kubernetes.io/mode":"Reconcile","integration-test":"storage-provisioner"},"name":"storage-provisioner","namespace":"kube-system"},"spec":{"containers":[{"command":["/storage-provisioner"],"image":"gcr.io/k8s-minikube/storage-provisioner:v5","imagePullPolicy":"IfNotPresent","name":"storage-provisioner","volumeMounts":[{"mountPath":"/tmp","name":"tmp"}]}],"hostNetwork":true,"serviceAccountName":"storage-provisioner","volumes":[{"hostPath":{"path":"/tmp","type":"Directory"},"name":"tmp"}]}}
]
I0307 13:14:17.513015       1 scheduler.go:226] [OnAddPod] Ignorando pod kube-system/storage-provisioner pois pertence ao namespace kube-system
I0307 13:14:17.595696       1 shared_informer.go:320] Caches are synced for client-ca::kube-system::extension-apiserver-authentication::requestheader-client-ca-file
I0307 13:14:17.595716       1 shared_informer.go:320] Caches are synced for client-ca::kube-system::extension-apiserver-authentication::client-ca-file
I0307 13:14:17.595829       1 shared_informer.go:320] Caches are synced for RequestHeaderAuthRequestController
I0307 13:14:17.595879       1 leaderelection.go:257] attempting to acquire leader lease kube-system/kube-scheduler...
I0307 13:14:17.601426       1 leaderelection.go:271] successfully acquired lease kube-system/kube-scheduler
I0307 14:16:36.570458       1 scheduler.go:220] [OnAddPod] Pod adicionado: default/prod-deployment-average-2-77dcb68421de-85f497d589-lzcpd, Anotações: map[acceptablePreemptionOverhead:0.05 controller:prod-deployment-average-2-77dcb68421de qosMeasuring:average slo:0.8]
I0307 14:16:36.570660       1 scheduler.go:151] [Reserve] resources reserved at node minikube for pod prod-deployment-average-2-77dcb68421de-85f497d589-lzcpd_default at 2025-03-07 14:16:36.570652507 +0000 UTC m=+3739.834646510
I0307 14:16:36.570690       1 types.go:751] [ControllerName] Verificando as anotações do pod default/prod-deployment-average-2-77dcb68421de-85f497d589-lzcpd
I0307 14:16:36.570695       1 types.go:769] [ControllerName] Anotação 'controller' encontrada para o pod default/prod-deployment-average-2-77dcb68421de-85f497d589-lzcpd: prod-deployment-average-2-77dcb68421de
I0307 14:16:36.576689       1 scheduler.go:75] Estado no Informer: map[acceptablePreemptionOverhead:0.05 controller:prod-deployment-average-2-77dcb68421de qosMeasuring:average slo:0.8]
I0307 14:16:36.576761       1 scheduler.go:76] Estado real no cluster: map[acceptablePreemptionOverhead:0.05 controller:prod-deployment-average-2-77dcb68421de qosMeasuring:average slo:0.8]
I0307 14:16:36.576711       1 scheduler.go:153] [Reserve] Status de alocação atual para o pod prod-deployment-average-2-77dcb68421de-85f497d589-lzcpd_default: 
I0307 14:16:36.576951       1 scheduler.go:155] [Reserve] Status de alocação atualizado para o pod prod-deployment-average-2-77dcb68421de-85f497d589-lzcpd_default: allocating
I0307 14:16:36.577142       1 scheduler.go:179] [PreBind] Validando o pod prod-deployment-average-2-77dcb68421de-85f497d589-lzcpd antes de vincular ao node minikube
I0307 14:16:36.577117       1 default_preemption.go:28] "PostFilter called" pod="default/prod-deployment-average-1-3e1f1596b5ac-79665659cd-kw48q"
I0307 14:16:36.577638       1 scheduler.go:231] [OnAddPod] Adicionando pod default/prod-deployment-average-2-77dcb68421de-85f497d589-lzcpd com os seguintes detalhes:
I0307 14:16:36.577650       1 types.go:751] [ControllerName] Verificando as anotações do pod default/prod-deployment-average-2-77dcb68421de-85f497d589-lzcpd
I0307 14:16:36.577659       1 types.go:769] [ControllerName] Anotação 'controller' encontrada para o pod default/prod-deployment-average-2-77dcb68421de-85f497d589-lzcpd: prod-deployment-average-2-77dcb68421de
I0307 14:16:36.577666       1 scheduler.go:240] [OnAddPod] Atualizando métricas para o pod default/prod-deployment-average-2-77dcb68421de-85f497d589-lzcpd
I0307 14:16:36.577671       1 types.go:751] [ControllerName] Verificando as anotações do pod default/prod-deployment-average-2-77dcb68421de-85f497d589-lzcpd
I0307 14:16:36.577638       1 preemption.go:244] Lista de nós obtidaallNodes[&NodeInfo{Pods:[coredns-668d6bf9bc-tbzv9 custom-scheduler-8dcdbb8b5-lvx5k etcd-minikube kube-apiserver-minikube kube-controller-manager-minikube kube-proxy-hqbh2 kube-scheduler-minikube storage-provisioner prod-deployment-average-2-77dcb68421de-85f497d589-lzcpd], RequestedResource:&framework.Resource{MilliCPU:8750, Memory:280657920, EphemeralStorage:0, AllowedPodNumber:0, ScalarResources:map[v1.ResourceName]int64(nil)}, NonZeroRequest: &framework.Resource{MilliCPU:9050, Memory:1538949120, EphemeralStorage:0, AllowedPodNumber:0, ScalarResources:map[v1.ResourceName]int64(nil)}, UsedPort: framework.HostPortInfo{}, AllocatableResource:&framework.Resource{MilliCPU:16000, Memory:33260953600, EphemeralStorage:30083776512, AllowedPodNumber:110, ScalarResources:map[v1.ResourceName]int64{"hugepages-1Gi":0, "hugepages-2Mi":0}}}]
I0307 14:16:36.577676       1 types.go:769] [ControllerName] Anotação 'controller' encontrada para o pod default/prod-deployment-average-2-77dcb68421de-85f497d589-lzcpd: prod-deployment-average-2-77dcb68421de
I0307 14:16:36.577684       1 scheduler.go:253] [OnAddPod] Pod default/prod-deployment-average-2-77dcb68421de-85f497d589-lzcpd adicionado com sucesso
I0307 14:16:36.577679       1 preemption.go:308] "Starting candidate search for preemption" pod="default/prod-deployment-average-1-3e1f1596b5ac-79665659cd-kw48q" totalNodes=1
I0307 14:16:36.577694       1 preemption.go:327] "Potential node for preemption identified" pod="default/prod-deployment-average-1-3e1f1596b5ac-79665659cd-kw48q" node="minikube"
I0307 14:16:36.577700       1 preemption.go:342] "candidatesNum was 0, setting it to 1 to ensure preemption is attempted" pod="default/prod-deployment-average-1-3e1f1596b5ac-79665659cd-kw48q"
I0307 14:16:36.577706       1 preemption.go:346] "Calling DryRunPreemption" pod="default/prod-deployment-average-1-3e1f1596b5ac-79665659cd-kw48q" numPotentialNodes=1
I0307 14:16:36.577720       1 scheduler.go:220] [OnAddPod] Pod adicionado: default/prod-deployment-average-1-3e1f1596b5ac-79665659cd-kw48q, Anotações: map[acceptablePreemptionOverhead:0.05 controller:prod-deployment-average-1-3e1f1596b5ac qosMeasuring:average slo:0.8]
I0307 14:16:36.577710       1 preemption.go:347] "Calculated offset and candidatesNum" pod="default/prod-deployment-average-1-3e1f1596b5ac-79665659cd-kw48q" offset=0 candidatesNum=1
I0307 14:16:36.577844       1 preemption.go:623] "Starting DryRunPreemption" pod="default/prod-deployment-average-1-3e1f1596b5ac-79665659cd-kw48q" potentialNodesNumber=1 pdbsNumber=0 offset=0 candidatesNumber=1
I0307 14:16:36.577874       1 preemption.go:629] "Checking node for preemption" pod="default/prod-deployment-average-1-3e1f1596b5ac-79665659cd-kw48q" node="minikube"
I0307 14:16:36.577922       1 preemption.go:641] "No victim pods found on node" pod="default/prod-deployment-average-1-3e1f1596b5ac-79665659cd-kw48q" node="minikube"
I0307 14:16:36.577966       1 preemption.go:682] "Preemption evaluation completed" pod="default/prod-deployment-average-1-3e1f1596b5ac-79665659cd-kw48q" nonViolatingCandidates=0 violatingCandidates=0
I0307 14:16:36.577980       1 preemption.go:357] "Preemption candidates found" pod="default/prod-deployment-average-1-3e1f1596b5ac-79665659cd-kw48q" numCandidates=0
I0307 14:16:36.577986       1 preemption.go:251] Número de candidatos encontradoscount0
I0307 14:16:36.577991       1 preemption.go:252] Mapa de status dos nósnodeToStatusMap&{map[minikube:0xc000d46640] 0xc000d46380}
I0307 14:16:36.578002       1 preemption.go:261] "No preemption candidate is found; preemption is not helpful for scheduling" pod="default/prod-deployment-average-1-3e1f1596b5ac-79665659cd-kw48q"
I0307 14:16:36.578021       1 default_preemption.go:37] "Preemption failed or not needed" pod="default/prod-deployment-average-1-3e1f1596b5ac-79665659cd-kw48q" status="0/1 nodes are available: 1 Insufficient cpu."
I0307 14:16:36.581188       1 scheduler.go:75] Estado no Informer: map[acceptablePreemptionOverhead:0.05 controller:prod-deployment-average-1-3e1f1596b5ac qosMeasuring:average slo:0.8]
I0307 14:16:36.581220       1 scheduler.go:76] Estado real no cluster: map[acceptablePreemptionOverhead:0.05 controller:prod-deployment-average-1-3e1f1596b5ac qosMeasuring:average slo:0.8]
I0307 14:16:36.581390       1 scheduler.go:231] [OnAddPod] Adicionando pod default/prod-deployment-average-1-3e1f1596b5ac-79665659cd-kw48q com os seguintes detalhes:
I0307 14:16:36.581414       1 types.go:751] [ControllerName] Verificando as anotações do pod default/prod-deployment-average-1-3e1f1596b5ac-79665659cd-kw48q
I0307 14:16:36.581421       1 types.go:769] [ControllerName] Anotação 'controller' encontrada para o pod default/prod-deployment-average-1-3e1f1596b5ac-79665659cd-kw48q: prod-deployment-average-1-3e1f1596b5ac
I0307 14:16:36.584453       1 scheduler.go:187] [PostBind] Chamado para pod prod-deployment-average-2-77dcb68421de-85f497d589-lzcpd
I0307 14:16:36.584491       1 scheduler.go:205] [PostBind] Pod prod-deployment-average-2-77dcb68421de-85f497d589-lzcpd - Início do binding: 2025-03-07 14:16:36.577164748 +0000 UTC m=+3739.841158751, Fim do binding: 2025-03-07 14:16:36.584487213 +0000 UTC m=+3739.848481216
I0307 14:16:36.590925       1 scheduler.go:240] [OnAddPod] Atualizando métricas para o pod default/prod-deployment-average-1-3e1f1596b5ac-79665659cd-kw48q
I0307 14:16:36.590958       1 types.go:751] [ControllerName] Verificando as anotações do pod default/prod-deployment-average-1-3e1f1596b5ac-79665659cd-kw48q
I0307 14:16:36.590964       1 types.go:769] [ControllerName] Anotação 'controller' encontrada para o pod default/prod-deployment-average-1-3e1f1596b5ac-79665659cd-kw48q: prod-deployment-average-1-3e1f1596b5ac
I0307 14:16:36.590982       1 scheduler.go:253] [OnAddPod] Pod default/prod-deployment-average-1-3e1f1596b5ac-79665659cd-kw48q adicionado com sucesso
I0307 14:16:36.590994       1 types.go:751] [ControllerName] Verificando as anotações do pod default/prod-deployment-average-2-77dcb68421de-85f497d589-lzcpd
I0307 14:16:36.590999       1 types.go:769] [ControllerName] Anotação 'controller' encontrada para o pod default/prod-deployment-average-2-77dcb68421de-85f497d589-lzcpd: prod-deployment-average-2-77dcb68421de
I0307 14:16:36.591006       1 scheduler.go:212] [PostBind] Métricas atualizadas para o pod prod-deployment-average-2-77dcb68421de-85f497d589-lzcpd
I0307 14:16:36.591002       1 scheduler.go:258] [OnUpdatePod] Iniciando processamento de atualização de pod
I0307 14:16:36.591085       1 scheduler.go:262] [OnUpdatePod] Pod atualizado detectado: default/prod-deployment-average-2-77dcb68421de-85f497d589-lzcpd, Anotações: map[acceptablePreemptionOverhead:0.05 controller:prod-deployment-average-2-77dcb68421de qosMeasuring:average slo:0.8]
I0307 14:16:36.591112       1 scheduler.go:265] [OnUpdatePod] Comparando estado no Informer e estado real no cluster para o pod default/prod-deployment-average-2-77dcb68421de-85f497d589-lzcpd
I0307 14:16:36.592913       1 scheduler.go:75] Estado no Informer: map[acceptablePreemptionOverhead:0.05 controller:prod-deployment-average-2-77dcb68421de qosMeasuring:average slo:0.8]
I0307 14:16:36.592936       1 scheduler.go:76] Estado real no cluster: map[acceptablePreemptionOverhead:0.05 controller:prod-deployment-average-2-77dcb68421de qosMeasuring:average slo:0.8]
I0307 14:16:36.592943       1 scheduler.go:275] [OnUpdatePod] Atualizando informações de métricas para o pod default/prod-deployment-average-2-77dcb68421de-85f497d589-lzcpd
I0307 14:16:36.592949       1 types.go:751] [ControllerName] Verificando as anotações do pod default/prod-deployment-average-2-77dcb68421de-85f497d589-lzcpd
I0307 14:16:36.592953       1 types.go:769] [ControllerName] Anotação 'controller' encontrada para o pod default/prod-deployment-average-2-77dcb68421de-85f497d589-lzcpd: prod-deployment-average-2-77dcb68421de
I0307 14:16:36.592960       1 scheduler.go:277] [OnUpdatePod] Atualizando 'LastStatus' do pod default/prod-deployment-average-2-77dcb68421de-85f497d589-lzcpd nas métricas
I0307 14:16:36.592963       1 scheduler.go:279] [OnUpdatePod] Métrica atualizada para o pod default/prod-deployment-average-2-77dcb68421de-85f497d589-lzcpd
I0307 14:16:36.592970       1 scheduler.go:283] [OnUpdatePod] Finalizando processamento de atualização de pod para default/prod-deployment-average-2-77dcb68421de-85f497d589-lzcpd
I0307 14:16:36.592986       1 scheduler.go:258] [OnUpdatePod] Iniciando processamento de atualização de pod
I0307 14:16:36.593001       1 scheduler.go:262] [OnUpdatePod] Pod atualizado detectado: default/prod-deployment-average-1-3e1f1596b5ac-79665659cd-kw48q, Anotações: map[acceptablePreemptionOverhead:0.05 controller:prod-deployment-average-1-3e1f1596b5ac qosMeasuring:average slo:0.8]
I0307 14:16:36.593015       1 scheduler.go:265] [OnUpdatePod] Comparando estado no Informer e estado real no cluster para o pod default/prod-deployment-average-1-3e1f1596b5ac-79665659cd-kw48q
I0307 14:16:36.595415       1 scheduler.go:75] Estado no Informer: map[acceptablePreemptionOverhead:0.05 controller:prod-deployment-average-1-3e1f1596b5ac qosMeasuring:average slo:0.8]
I0307 14:16:36.595440       1 scheduler.go:76] Estado real no cluster: map[acceptablePreemptionOverhead:0.05 controller:prod-deployment-average-1-3e1f1596b5ac qosMeasuring:average slo:0.8]
I0307 14:16:36.595448       1 scheduler.go:275] [OnUpdatePod] Atualizando informações de métricas para o pod default/prod-deployment-average-1-3e1f1596b5ac-79665659cd-kw48q
I0307 14:16:36.595452       1 types.go:751] [ControllerName] Verificando as anotações do pod default/prod-deployment-average-1-3e1f1596b5ac-79665659cd-kw48q
I0307 14:16:36.595456       1 types.go:769] [ControllerName] Anotação 'controller' encontrada para o pod default/prod-deployment-average-1-3e1f1596b5ac-79665659cd-kw48q: prod-deployment-average-1-3e1f1596b5ac
I0307 14:16:36.595462       1 scheduler.go:277] [OnUpdatePod] Atualizando 'LastStatus' do pod default/prod-deployment-average-1-3e1f1596b5ac-79665659cd-kw48q nas métricas
I0307 14:16:36.595465       1 scheduler.go:279] [OnUpdatePod] Métrica atualizada para o pod default/prod-deployment-average-1-3e1f1596b5ac-79665659cd-kw48q
I0307 14:16:36.595471       1 scheduler.go:283] [OnUpdatePod] Finalizando processamento de atualização de pod para default/prod-deployment-average-1-3e1f1596b5ac-79665659cd-kw48q
I0307 14:16:36.598977       1 scheduler.go:258] [OnUpdatePod] Iniciando processamento de atualização de pod
I0307 14:16:36.599008       1 scheduler.go:262] [OnUpdatePod] Pod atualizado detectado: default/prod-deployment-average-2-77dcb68421de-85f497d589-lzcpd, Anotações: map[acceptablePreemptionOverhead:0.05 controller:prod-deployment-average-2-77dcb68421de qosMeasuring:average slo:0.8]
I0307 14:16:36.599018       1 scheduler.go:265] [OnUpdatePod] Comparando estado no Informer e estado real no cluster para o pod default/prod-deployment-average-2-77dcb68421de-85f497d589-lzcpd
I0307 14:16:36.600535       1 scheduler.go:75] Estado no Informer: map[acceptablePreemptionOverhead:0.05 controller:prod-deployment-average-2-77dcb68421de qosMeasuring:average slo:0.8]
I0307 14:16:36.600557       1 scheduler.go:76] Estado real no cluster: map[acceptablePreemptionOverhead:0.05 controller:prod-deployment-average-2-77dcb68421de qosMeasuring:average slo:0.8]
I0307 14:16:36.600564       1 scheduler.go:275] [OnUpdatePod] Atualizando informações de métricas para o pod default/prod-deployment-average-2-77dcb68421de-85f497d589-lzcpd
I0307 14:16:36.600568       1 types.go:751] [ControllerName] Verificando as anotações do pod default/prod-deployment-average-2-77dcb68421de-85f497d589-lzcpd
I0307 14:16:36.600572       1 types.go:769] [ControllerName] Anotação 'controller' encontrada para o pod default/prod-deployment-average-2-77dcb68421de-85f497d589-lzcpd: prod-deployment-average-2-77dcb68421de
I0307 14:16:36.600577       1 scheduler.go:277] [OnUpdatePod] Atualizando 'LastStatus' do pod default/prod-deployment-average-2-77dcb68421de-85f497d589-lzcpd nas métricas
I0307 14:16:36.600580       1 scheduler.go:279] [OnUpdatePod] Métrica atualizada para o pod default/prod-deployment-average-2-77dcb68421de-85f497d589-lzcpd
I0307 14:16:36.600586       1 scheduler.go:283] [OnUpdatePod] Finalizando processamento de atualização de pod para default/prod-deployment-average-2-77dcb68421de-85f497d589-lzcpd
I0307 14:16:37.482451       1 scheduler.go:258] [OnUpdatePod] Iniciando processamento de atualização de pod
I0307 14:16:37.482494       1 scheduler.go:262] [OnUpdatePod] Pod atualizado detectado: default/prod-deployment-average-2-77dcb68421de-85f497d589-lzcpd, Anotações: map[acceptablePreemptionOverhead:0.05 controller:prod-deployment-average-2-77dcb68421de qosMeasuring:average slo:0.8]
I0307 14:16:37.482511       1 scheduler.go:265] [OnUpdatePod] Comparando estado no Informer e estado real no cluster para o pod default/prod-deployment-average-2-77dcb68421de-85f497d589-lzcpd
I0307 14:16:37.484533       1 scheduler.go:75] Estado no Informer: map[acceptablePreemptionOverhead:0.05 controller:prod-deployment-average-2-77dcb68421de qosMeasuring:average slo:0.8]
I0307 14:16:37.484561       1 scheduler.go:76] Estado real no cluster: map[acceptablePreemptionOverhead:0.05 controller:prod-deployment-average-2-77dcb68421de qosMeasuring:average slo:0.8]
I0307 14:16:37.484570       1 scheduler.go:275] [OnUpdatePod] Atualizando informações de métricas para o pod default/prod-deployment-average-2-77dcb68421de-85f497d589-lzcpd
I0307 14:16:37.484575       1 types.go:751] [ControllerName] Verificando as anotações do pod default/prod-deployment-average-2-77dcb68421de-85f497d589-lzcpd
I0307 14:16:37.484579       1 types.go:769] [ControllerName] Anotação 'controller' encontrada para o pod default/prod-deployment-average-2-77dcb68421de-85f497d589-lzcpd: prod-deployment-average-2-77dcb68421de
I0307 14:16:37.484586       1 scheduler.go:277] [OnUpdatePod] Atualizando 'LastStatus' do pod default/prod-deployment-average-2-77dcb68421de-85f497d589-lzcpd nas métricas
I0307 14:16:37.484589       1 scheduler.go:279] [OnUpdatePod] Métrica atualizada para o pod default/prod-deployment-average-2-77dcb68421de-85f497d589-lzcpd
I0307 14:16:37.484596       1 scheduler.go:283] [OnUpdatePod] Finalizando processamento de atualização de pod para default/prod-deployment-average-2-77dcb68421de-85f497d589-lzcpd
I0307 14:16:47.672941       1 default_preemption.go:28] "PostFilter called" pod="default/prod-deployment-average-1-3e1f1596b5ac-79665659cd-kw48q"
I0307 14:16:47.672965       1 preemption.go:244] Lista de nós obtidaallNodes[&NodeInfo{Pods:[coredns-668d6bf9bc-tbzv9 custom-scheduler-8dcdbb8b5-lvx5k etcd-minikube kube-apiserver-minikube kube-controller-manager-minikube kube-proxy-hqbh2 kube-scheduler-minikube storage-provisioner prod-deployment-average-2-77dcb68421de-85f497d589-lzcpd], RequestedResource:&framework.Resource{MilliCPU:8750, Memory:280657920, EphemeralStorage:0, AllowedPodNumber:0, ScalarResources:map[v1.ResourceName]int64(nil)}, NonZeroRequest: &framework.Resource{MilliCPU:9050, Memory:1538949120, EphemeralStorage:0, AllowedPodNumber:0, ScalarResources:map[v1.ResourceName]int64(nil)}, UsedPort: framework.HostPortInfo{}, AllocatableResource:&framework.Resource{MilliCPU:16000, Memory:33260953600, EphemeralStorage:30083776512, AllowedPodNumber:110, ScalarResources:map[v1.ResourceName]int64{"hugepages-1Gi":0, "hugepages-2Mi":0}}}]
I0307 14:16:47.673004       1 preemption.go:308] "Starting candidate search for preemption" pod="default/prod-deployment-average-1-3e1f1596b5ac-79665659cd-kw48q" totalNodes=1
I0307 14:16:47.673017       1 preemption.go:327] "Potential node for preemption identified" pod="default/prod-deployment-average-1-3e1f1596b5ac-79665659cd-kw48q" node="minikube"
I0307 14:16:47.673024       1 preemption.go:342] "candidatesNum was 0, setting it to 1 to ensure preemption is attempted" pod="default/prod-deployment-average-1-3e1f1596b5ac-79665659cd-kw48q"
I0307 14:16:47.673029       1 preemption.go:346] "Calling DryRunPreemption" pod="default/prod-deployment-average-1-3e1f1596b5ac-79665659cd-kw48q" numPotentialNodes=1
I0307 14:16:47.673033       1 preemption.go:347] "Calculated offset and candidatesNum" pod="default/prod-deployment-average-1-3e1f1596b5ac-79665659cd-kw48q" offset=0 candidatesNum=1
I0307 14:16:47.673042       1 preemption.go:623] "Starting DryRunPreemption" pod="default/prod-deployment-average-1-3e1f1596b5ac-79665659cd-kw48q" potentialNodesNumber=1 pdbsNumber=0 offset=0 candidatesNumber=1
I0307 14:16:47.673069       1 preemption.go:629] "Checking node for preemption" pod="default/prod-deployment-average-1-3e1f1596b5ac-79665659cd-kw48q" node="minikube"
I0307 14:16:47.673107       1 preemption.go:641] "No victim pods found on node" pod="default/prod-deployment-average-1-3e1f1596b5ac-79665659cd-kw48q" node="minikube"
I0307 14:16:47.673122       1 preemption.go:682] "Preemption evaluation completed" pod="default/prod-deployment-average-1-3e1f1596b5ac-79665659cd-kw48q" nonViolatingCandidates=0 violatingCandidates=0
I0307 14:16:47.673144       1 preemption.go:357] "Preemption candidates found" pod="default/prod-deployment-average-1-3e1f1596b5ac-79665659cd-kw48q" numCandidates=0
I0307 14:16:47.673149       1 preemption.go:251] Número de candidatos encontradoscount0
I0307 14:16:47.673154       1 preemption.go:252] Mapa de status dos nósnodeToStatusMap&{map[minikube:0xc000f86d00] 0xc000f86b80}
I0307 14:16:47.673163       1 preemption.go:261] "No preemption candidate is found; preemption is not helpful for scheduling" pod="default/prod-deployment-average-1-3e1f1596b5ac-79665659cd-kw48q"
I0307 14:16:47.673172       1 default_preemption.go:37] "Preemption failed or not needed" pod="default/prod-deployment-average-1-3e1f1596b5ac-79665659cd-kw48q" status="0/1 nodes are available: 1 Insufficient cpu."
I0307 14:17:17.673651       1 default_preemption.go:28] "PostFilter called" pod="default/prod-deployment-average-1-3e1f1596b5ac-79665659cd-kw48q"
I0307 14:17:17.673676       1 preemption.go:244] Lista de nós obtidaallNodes[&NodeInfo{Pods:[coredns-668d6bf9bc-tbzv9 custom-scheduler-8dcdbb8b5-lvx5k etcd-minikube kube-apiserver-minikube kube-controller-manager-minikube kube-proxy-hqbh2 kube-scheduler-minikube storage-provisioner prod-deployment-average-2-77dcb68421de-85f497d589-lzcpd], RequestedResource:&framework.Resource{MilliCPU:8750, Memory:280657920, EphemeralStorage:0, AllowedPodNumber:0, ScalarResources:map[v1.ResourceName]int64(nil)}, NonZeroRequest: &framework.Resource{MilliCPU:9050, Memory:1538949120, EphemeralStorage:0, AllowedPodNumber:0, ScalarResources:map[v1.ResourceName]int64(nil)}, UsedPort: framework.HostPortInfo{}, AllocatableResource:&framework.Resource{MilliCPU:16000, Memory:33260953600, EphemeralStorage:30083776512, AllowedPodNumber:110, ScalarResources:map[v1.ResourceName]int64{"hugepages-1Gi":0, "hugepages-2Mi":0}}}]
I0307 14:17:17.673712       1 preemption.go:308] "Starting candidate search for preemption" pod="default/prod-deployment-average-1-3e1f1596b5ac-79665659cd-kw48q" totalNodes=1
I0307 14:17:17.673728       1 preemption.go:327] "Potential node for preemption identified" pod="default/prod-deployment-average-1-3e1f1596b5ac-79665659cd-kw48q" node="minikube"
I0307 14:17:17.673773       1 preemption.go:342] "candidatesNum was 0, setting it to 1 to ensure preemption is attempted" pod="default/prod-deployment-average-1-3e1f1596b5ac-79665659cd-kw48q"
I0307 14:17:17.673781       1 preemption.go:346] "Calling DryRunPreemption" pod="default/prod-deployment-average-1-3e1f1596b5ac-79665659cd-kw48q" numPotentialNodes=1
I0307 14:17:17.673788       1 preemption.go:347] "Calculated offset and candidatesNum" pod="default/prod-deployment-average-1-3e1f1596b5ac-79665659cd-kw48q" offset=0 candidatesNum=1
I0307 14:17:17.673798       1 preemption.go:623] "Starting DryRunPreemption" pod="default/prod-deployment-average-1-3e1f1596b5ac-79665659cd-kw48q" potentialNodesNumber=1 pdbsNumber=0 offset=0 candidatesNumber=1
I0307 14:17:17.673848       1 preemption.go:629] "Checking node for preemption" pod="default/prod-deployment-average-1-3e1f1596b5ac-79665659cd-kw48q" node="minikube"
I0307 14:17:17.673905       1 preemption.go:641] "No victim pods found on node" pod="default/prod-deployment-average-1-3e1f1596b5ac-79665659cd-kw48q" node="minikube"
I0307 14:17:17.673934       1 preemption.go:682] "Preemption evaluation completed" pod="default/prod-deployment-average-1-3e1f1596b5ac-79665659cd-kw48q" nonViolatingCandidates=0 violatingCandidates=0
I0307 14:17:17.673942       1 preemption.go:357] "Preemption candidates found" pod="default/prod-deployment-average-1-3e1f1596b5ac-79665659cd-kw48q" numCandidates=0
I0307 14:17:17.673954       1 preemption.go:251] Número de candidatos encontradoscount0
I0307 14:17:17.673959       1 preemption.go:252] Mapa de status dos nósnodeToStatusMap&{map[minikube:0xc000f1ee00] 0xc000f1ec80}
I0307 14:17:17.673969       1 preemption.go:261] "No preemption candidate is found; preemption is not helpful for scheduling" pod="default/prod-deployment-average-1-3e1f1596b5ac-79665659cd-kw48q"
I0307 14:17:17.673983       1 default_preemption.go:37] "Preemption failed or not needed" pod="default/prod-deployment-average-1-3e1f1596b5ac-79665659cd-kw48q" status="0/1 nodes are available: 1 Insufficient cpu."
I0307 14:17:47.674391       1 default_preemption.go:28] "PostFilter called" pod="default/prod-deployment-average-1-3e1f1596b5ac-79665659cd-kw48q"
I0307 14:17:47.674421       1 preemption.go:244] Lista de nós obtidaallNodes[&NodeInfo{Pods:[coredns-668d6bf9bc-tbzv9 custom-scheduler-8dcdbb8b5-lvx5k etcd-minikube kube-apiserver-minikube kube-controller-manager-minikube kube-proxy-hqbh2 kube-scheduler-minikube storage-provisioner prod-deployment-average-2-77dcb68421de-85f497d589-lzcpd], RequestedResource:&framework.Resource{MilliCPU:8750, Memory:280657920, EphemeralStorage:0, AllowedPodNumber:0, ScalarResources:map[v1.ResourceName]int64(nil)}, NonZeroRequest: &framework.Resource{MilliCPU:9050, Memory:1538949120, EphemeralStorage:0, AllowedPodNumber:0, ScalarResources:map[v1.ResourceName]int64(nil)}, UsedPort: framework.HostPortInfo{}, AllocatableResource:&framework.Resource{MilliCPU:16000, Memory:33260953600, EphemeralStorage:30083776512, AllowedPodNumber:110, ScalarResources:map[v1.ResourceName]int64{"hugepages-1Gi":0, "hugepages-2Mi":0}}}]
I0307 14:17:47.674453       1 preemption.go:308] "Starting candidate search for preemption" pod="default/prod-deployment-average-1-3e1f1596b5ac-79665659cd-kw48q" totalNodes=1
I0307 14:17:47.674465       1 preemption.go:327] "Potential node for preemption identified" pod="default/prod-deployment-average-1-3e1f1596b5ac-79665659cd-kw48q" node="minikube"
I0307 14:17:47.674472       1 preemption.go:342] "candidatesNum was 0, setting it to 1 to ensure preemption is attempted" pod="default/prod-deployment-average-1-3e1f1596b5ac-79665659cd-kw48q"
I0307 14:17:47.674477       1 preemption.go:346] "Calling DryRunPreemption" pod="default/prod-deployment-average-1-3e1f1596b5ac-79665659cd-kw48q" numPotentialNodes=1
I0307 14:17:47.674481       1 preemption.go:347] "Calculated offset and candidatesNum" pod="default/prod-deployment-average-1-3e1f1596b5ac-79665659cd-kw48q" offset=0 candidatesNum=1
I0307 14:17:47.674491       1 preemption.go:623] "Starting DryRunPreemption" pod="default/prod-deployment-average-1-3e1f1596b5ac-79665659cd-kw48q" potentialNodesNumber=1 pdbsNumber=0 offset=0 candidatesNumber=1
I0307 14:17:47.674527       1 preemption.go:629] "Checking node for preemption" pod="default/prod-deployment-average-1-3e1f1596b5ac-79665659cd-kw48q" node="minikube"
I0307 14:17:47.674574       1 preemption.go:641] "No victim pods found on node" pod="default/prod-deployment-average-1-3e1f1596b5ac-79665659cd-kw48q" node="minikube"
I0307 14:17:47.674598       1 preemption.go:682] "Preemption evaluation completed" pod="default/prod-deployment-average-1-3e1f1596b5ac-79665659cd-kw48q" nonViolatingCandidates=0 violatingCandidates=0
I0307 14:17:47.674604       1 preemption.go:357] "Preemption candidates found" pod="default/prod-deployment-average-1-3e1f1596b5ac-79665659cd-kw48q" numCandidates=0
I0307 14:17:47.674609       1 preemption.go:251] Número de candidatos encontradoscount0
I0307 14:17:47.674617       1 preemption.go:252] Mapa de status dos nósnodeToStatusMap&{map[minikube:0xc000bc2180] 0xc000bc2000}
I0307 14:17:47.674626       1 preemption.go:261] "No preemption candidate is found; preemption is not helpful for scheduling" pod="default/prod-deployment-average-1-3e1f1596b5ac-79665659cd-kw48q"
I0307 14:17:47.674642       1 default_preemption.go:37] "Preemption failed or not needed" pod="default/prod-deployment-average-1-3e1f1596b5ac-79665659cd-kw48q" status="0/1 nodes are available: 1 Insufficient cpu."
I0307 14:18:17.675083       1 default_preemption.go:28] "PostFilter called" pod="default/prod-deployment-average-1-3e1f1596b5ac-79665659cd-kw48q"
I0307 14:18:17.675119       1 preemption.go:244] Lista de nós obtidaallNodes[&NodeInfo{Pods:[coredns-668d6bf9bc-tbzv9 custom-scheduler-8dcdbb8b5-lvx5k etcd-minikube kube-apiserver-minikube kube-controller-manager-minikube kube-proxy-hqbh2 kube-scheduler-minikube storage-provisioner prod-deployment-average-2-77dcb68421de-85f497d589-lzcpd], RequestedResource:&framework.Resource{MilliCPU:8750, Memory:280657920, EphemeralStorage:0, AllowedPodNumber:0, ScalarResources:map[v1.ResourceName]int64(nil)}, NonZeroRequest: &framework.Resource{MilliCPU:9050, Memory:1538949120, EphemeralStorage:0, AllowedPodNumber:0, ScalarResources:map[v1.ResourceName]int64(nil)}, UsedPort: framework.HostPortInfo{}, AllocatableResource:&framework.Resource{MilliCPU:16000, Memory:33260953600, EphemeralStorage:30083776512, AllowedPodNumber:110, ScalarResources:map[v1.ResourceName]int64{"hugepages-1Gi":0, "hugepages-2Mi":0}}}]
I0307 14:18:17.675164       1 preemption.go:308] "Starting candidate search for preemption" pod="default/prod-deployment-average-1-3e1f1596b5ac-79665659cd-kw48q" totalNodes=1
I0307 14:18:17.675192       1 preemption.go:327] "Potential node for preemption identified" pod="default/prod-deployment-average-1-3e1f1596b5ac-79665659cd-kw48q" node="minikube"
I0307 14:18:17.675200       1 preemption.go:342] "candidatesNum was 0, setting it to 1 to ensure preemption is attempted" pod="default/prod-deployment-average-1-3e1f1596b5ac-79665659cd-kw48q"
I0307 14:18:17.675205       1 preemption.go:346] "Calling DryRunPreemption" pod="default/prod-deployment-average-1-3e1f1596b5ac-79665659cd-kw48q" numPotentialNodes=1
I0307 14:18:17.675210       1 preemption.go:347] "Calculated offset and candidatesNum" pod="default/prod-deployment-average-1-3e1f1596b5ac-79665659cd-kw48q" offset=0 candidatesNum=1
I0307 14:18:17.675217       1 preemption.go:623] "Starting DryRunPreemption" pod="default/prod-deployment-average-1-3e1f1596b5ac-79665659cd-kw48q" potentialNodesNumber=1 pdbsNumber=0 offset=0 candidatesNumber=1
I0307 14:18:17.675250       1 preemption.go:629] "Checking node for preemption" pod="default/prod-deployment-average-1-3e1f1596b5ac-79665659cd-kw48q" node="minikube"
I0307 14:18:17.675289       1 preemption.go:641] "No victim pods found on node" pod="default/prod-deployment-average-1-3e1f1596b5ac-79665659cd-kw48q" node="minikube"
I0307 14:18:17.675305       1 preemption.go:682] "Preemption evaluation completed" pod="default/prod-deployment-average-1-3e1f1596b5ac-79665659cd-kw48q" nonViolatingCandidates=0 violatingCandidates=0
I0307 14:18:17.675312       1 preemption.go:357] "Preemption candidates found" pod="default/prod-deployment-average-1-3e1f1596b5ac-79665659cd-kw48q" numCandidates=0
I0307 14:18:17.675317       1 preemption.go:251] Número de candidatos encontradoscount0
I0307 14:18:17.675322       1 preemption.go:252] Mapa de status dos nósnodeToStatusMap&{map[minikube:0xc000bc3340] 0xc000bc31c0}
I0307 14:18:17.675336       1 preemption.go:261] "No preemption candidate is found; preemption is not helpful for scheduling" pod="default/prod-deployment-average-1-3e1f1596b5ac-79665659cd-kw48q"
I0307 14:18:17.675345       1 default_preemption.go:37] "Preemption failed or not needed" pod="default/prod-deployment-average-1-3e1f1596b5ac-79665659cd-kw48q" status="0/1 nodes are available: 1 Insufficient cpu."
I0307 14:18:47.675298       1 default_preemption.go:28] "PostFilter called" pod="default/prod-deployment-average-1-3e1f1596b5ac-79665659cd-kw48q"
I0307 14:18:47.675325       1 preemption.go:244] Lista de nós obtidaallNodes[&NodeInfo{Pods:[coredns-668d6bf9bc-tbzv9 custom-scheduler-8dcdbb8b5-lvx5k etcd-minikube kube-apiserver-minikube kube-controller-manager-minikube kube-proxy-hqbh2 kube-scheduler-minikube storage-provisioner prod-deployment-average-2-77dcb68421de-85f497d589-lzcpd], RequestedResource:&framework.Resource{MilliCPU:8750, Memory:280657920, EphemeralStorage:0, AllowedPodNumber:0, ScalarResources:map[v1.ResourceName]int64(nil)}, NonZeroRequest: &framework.Resource{MilliCPU:9050, Memory:1538949120, EphemeralStorage:0, AllowedPodNumber:0, ScalarResources:map[v1.ResourceName]int64(nil)}, UsedPort: framework.HostPortInfo{}, AllocatableResource:&framework.Resource{MilliCPU:16000, Memory:33260953600, EphemeralStorage:30083776512, AllowedPodNumber:110, ScalarResources:map[v1.ResourceName]int64{"hugepages-1Gi":0, "hugepages-2Mi":0}}}]
I0307 14:18:47.675379       1 preemption.go:308] "Starting candidate search for preemption" pod="default/prod-deployment-average-1-3e1f1596b5ac-79665659cd-kw48q" totalNodes=1
I0307 14:18:47.675393       1 preemption.go:327] "Potential node for preemption identified" pod="default/prod-deployment-average-1-3e1f1596b5ac-79665659cd-kw48q" node="minikube"
I0307 14:18:47.675400       1 preemption.go:342] "candidatesNum was 0, setting it to 1 to ensure preemption is attempted" pod="default/prod-deployment-average-1-3e1f1596b5ac-79665659cd-kw48q"
I0307 14:18:47.675405       1 preemption.go:346] "Calling DryRunPreemption" pod="default/prod-deployment-average-1-3e1f1596b5ac-79665659cd-kw48q" numPotentialNodes=1
I0307 14:18:47.675410       1 preemption.go:347] "Calculated offset and candidatesNum" pod="default/prod-deployment-average-1-3e1f1596b5ac-79665659cd-kw48q" offset=0 candidatesNum=1
I0307 14:18:47.675425       1 preemption.go:623] "Starting DryRunPreemption" pod="default/prod-deployment-average-1-3e1f1596b5ac-79665659cd-kw48q" potentialNodesNumber=1 pdbsNumber=0 offset=0 candidatesNumber=1
I0307 14:18:47.675455       1 preemption.go:629] "Checking node for preemption" pod="default/prod-deployment-average-1-3e1f1596b5ac-79665659cd-kw48q" node="minikube"
I0307 14:18:47.675496       1 preemption.go:641] "No victim pods found on node" pod="default/prod-deployment-average-1-3e1f1596b5ac-79665659cd-kw48q" node="minikube"
I0307 14:18:47.675517       1 preemption.go:682] "Preemption evaluation completed" pod="default/prod-deployment-average-1-3e1f1596b5ac-79665659cd-kw48q" nonViolatingCandidates=0 violatingCandidates=0
I0307 14:18:47.675524       1 preemption.go:357] "Preemption candidates found" pod="default/prod-deployment-average-1-3e1f1596b5ac-79665659cd-kw48q" numCandidates=0
I0307 14:18:47.675529       1 preemption.go:251] Número de candidatos encontradoscount0
I0307 14:18:47.675534       1 preemption.go:252] Mapa de status dos nósnodeToStatusMap&{map[minikube:0xc000f1ed40] 0xc000f1ebc0}
I0307 14:18:47.675550       1 preemption.go:261] "No preemption candidate is found; preemption is not helpful for scheduling" pod="default/prod-deployment-average-1-3e1f1596b5ac-79665659cd-kw48q"
I0307 14:18:47.675560       1 default_preemption.go:37] "Preemption failed or not needed" pod="default/prod-deployment-average-1-3e1f1596b5ac-79665659cd-kw48q" status="0/1 nodes are available: 1 Insufficient cpu."
I0307 14:19:17.675487       1 default_preemption.go:28] "PostFilter called" pod="default/prod-deployment-average-1-3e1f1596b5ac-79665659cd-kw48q"
I0307 14:19:17.675513       1 preemption.go:244] Lista de nós obtidaallNodes[&NodeInfo{Pods:[coredns-668d6bf9bc-tbzv9 custom-scheduler-8dcdbb8b5-lvx5k etcd-minikube kube-apiserver-minikube kube-controller-manager-minikube kube-proxy-hqbh2 kube-scheduler-minikube storage-provisioner prod-deployment-average-2-77dcb68421de-85f497d589-lzcpd], RequestedResource:&framework.Resource{MilliCPU:8750, Memory:280657920, EphemeralStorage:0, AllowedPodNumber:0, ScalarResources:map[v1.ResourceName]int64(nil)}, NonZeroRequest: &framework.Resource{MilliCPU:9050, Memory:1538949120, EphemeralStorage:0, AllowedPodNumber:0, ScalarResources:map[v1.ResourceName]int64(nil)}, UsedPort: framework.HostPortInfo{}, AllocatableResource:&framework.Resource{MilliCPU:16000, Memory:33260953600, EphemeralStorage:30083776512, AllowedPodNumber:110, ScalarResources:map[v1.ResourceName]int64{"hugepages-1Gi":0, "hugepages-2Mi":0}}}]
I0307 14:19:17.675543       1 preemption.go:308] "Starting candidate search for preemption" pod="default/prod-deployment-average-1-3e1f1596b5ac-79665659cd-kw48q" totalNodes=1
I0307 14:19:17.675555       1 preemption.go:327] "Potential node for preemption identified" pod="default/prod-deployment-average-1-3e1f1596b5ac-79665659cd-kw48q" node="minikube"
I0307 14:19:17.675562       1 preemption.go:342] "candidatesNum was 0, setting it to 1 to ensure preemption is attempted" pod="default/prod-deployment-average-1-3e1f1596b5ac-79665659cd-kw48q"
I0307 14:19:17.675567       1 preemption.go:346] "Calling DryRunPreemption" pod="default/prod-deployment-average-1-3e1f1596b5ac-79665659cd-kw48q" numPotentialNodes=1
I0307 14:19:17.675572       1 preemption.go:347] "Calculated offset and candidatesNum" pod="default/prod-deployment-average-1-3e1f1596b5ac-79665659cd-kw48q" offset=0 candidatesNum=1
I0307 14:19:17.675579       1 preemption.go:623] "Starting DryRunPreemption" pod="default/prod-deployment-average-1-3e1f1596b5ac-79665659cd-kw48q" potentialNodesNumber=1 pdbsNumber=0 offset=0 candidatesNumber=1
I0307 14:19:17.675618       1 preemption.go:629] "Checking node for preemption" pod="default/prod-deployment-average-1-3e1f1596b5ac-79665659cd-kw48q" node="minikube"
I0307 14:19:17.675656       1 preemption.go:641] "No victim pods found on node" pod="default/prod-deployment-average-1-3e1f1596b5ac-79665659cd-kw48q" node="minikube"
I0307 14:19:17.675678       1 preemption.go:682] "Preemption evaluation completed" pod="default/prod-deployment-average-1-3e1f1596b5ac-79665659cd-kw48q" nonViolatingCandidates=0 violatingCandidates=0
I0307 14:19:17.675685       1 preemption.go:357] "Preemption candidates found" pod="default/prod-deployment-average-1-3e1f1596b5ac-79665659cd-kw48q" numCandidates=0
I0307 14:19:17.675690       1 preemption.go:251] Número de candidatos encontradoscount0
I0307 14:19:17.675702       1 preemption.go:252] Mapa de status dos nósnodeToStatusMap&{map[minikube:0xc000adb580] 0xc000adb400}
I0307 14:19:17.675711       1 preemption.go:261] "No preemption candidate is found; preemption is not helpful for scheduling" pod="default/prod-deployment-average-1-3e1f1596b5ac-79665659cd-kw48q"
I0307 14:19:17.675720       1 default_preemption.go:37] "Preemption failed or not needed" pod="default/prod-deployment-average-1-3e1f1596b5ac-79665659cd-kw48q" status="0/1 nodes are available: 1 Insufficient cpu."
I0307 14:19:47.676166       1 default_preemption.go:28] "PostFilter called" pod="default/prod-deployment-average-1-3e1f1596b5ac-79665659cd-kw48q"
I0307 14:19:47.676192       1 preemption.go:244] Lista de nós obtidaallNodes[&NodeInfo{Pods:[coredns-668d6bf9bc-tbzv9 custom-scheduler-8dcdbb8b5-lvx5k etcd-minikube kube-apiserver-minikube kube-controller-manager-minikube kube-proxy-hqbh2 kube-scheduler-minikube storage-provisioner prod-deployment-average-2-77dcb68421de-85f497d589-lzcpd], RequestedResource:&framework.Resource{MilliCPU:8750, Memory:280657920, EphemeralStorage:0, AllowedPodNumber:0, ScalarResources:map[v1.ResourceName]int64(nil)}, NonZeroRequest: &framework.Resource{MilliCPU:9050, Memory:1538949120, EphemeralStorage:0, AllowedPodNumber:0, ScalarResources:map[v1.ResourceName]int64(nil)}, UsedPort: framework.HostPortInfo{}, AllocatableResource:&framework.Resource{MilliCPU:16000, Memory:33260953600, EphemeralStorage:30083776512, AllowedPodNumber:110, ScalarResources:map[v1.ResourceName]int64{"hugepages-1Gi":0, "hugepages-2Mi":0}}}]
I0307 14:19:47.676221       1 preemption.go:308] "Starting candidate search for preemption" pod="default/prod-deployment-average-1-3e1f1596b5ac-79665659cd-kw48q" totalNodes=1
I0307 14:19:47.676234       1 preemption.go:327] "Potential node for preemption identified" pod="default/prod-deployment-average-1-3e1f1596b5ac-79665659cd-kw48q" node="minikube"
I0307 14:19:47.676241       1 preemption.go:342] "candidatesNum was 0, setting it to 1 to ensure preemption is attempted" pod="default/prod-deployment-average-1-3e1f1596b5ac-79665659cd-kw48q"
I0307 14:19:47.676246       1 preemption.go:346] "Calling DryRunPreemption" pod="default/prod-deployment-average-1-3e1f1596b5ac-79665659cd-kw48q" numPotentialNodes=1
I0307 14:19:47.676251       1 preemption.go:347] "Calculated offset and candidatesNum" pod="default/prod-deployment-average-1-3e1f1596b5ac-79665659cd-kw48q" offset=0 candidatesNum=1
I0307 14:19:47.676258       1 preemption.go:623] "Starting DryRunPreemption" pod="default/prod-deployment-average-1-3e1f1596b5ac-79665659cd-kw48q" potentialNodesNumber=1 pdbsNumber=0 offset=0 candidatesNumber=1
I0307 14:19:47.676287       1 preemption.go:629] "Checking node for preemption" pod="default/prod-deployment-average-1-3e1f1596b5ac-79665659cd-kw48q" node="minikube"
I0307 14:19:47.676324       1 preemption.go:641] "No victim pods found on node" pod="default/prod-deployment-average-1-3e1f1596b5ac-79665659cd-kw48q" node="minikube"
I0307 14:19:47.676340       1 preemption.go:682] "Preemption evaluation completed" pod="default/prod-deployment-average-1-3e1f1596b5ac-79665659cd-kw48q" nonViolatingCandidates=0 violatingCandidates=0
I0307 14:19:47.676347       1 preemption.go:357] "Preemption candidates found" pod="default/prod-deployment-average-1-3e1f1596b5ac-79665659cd-kw48q" numCandidates=0
I0307 14:19:47.676360       1 preemption.go:251] Número de candidatos encontradoscount0
I0307 14:19:47.676367       1 preemption.go:252] Mapa de status dos nósnodeToStatusMap&{map[minikube:0xc000c19c40] 0xc000c19ac0}
I0307 14:19:47.676378       1 preemption.go:261] "No preemption candidate is found; preemption is not helpful for scheduling" pod="default/prod-deployment-average-1-3e1f1596b5ac-79665659cd-kw48q"
I0307 14:19:47.676391       1 default_preemption.go:37] "Preemption failed or not needed" pod="default/prod-deployment-average-1-3e1f1596b5ac-79665659cd-kw48q" status="0/1 nodes are available: 1 Insufficient cpu."
I0307 14:20:17.677096       1 default_preemption.go:28] "PostFilter called" pod="default/prod-deployment-average-1-3e1f1596b5ac-79665659cd-kw48q"
I0307 14:20:17.677120       1 preemption.go:244] Lista de nós obtidaallNodes[&NodeInfo{Pods:[coredns-668d6bf9bc-tbzv9 custom-scheduler-8dcdbb8b5-lvx5k etcd-minikube kube-apiserver-minikube kube-controller-manager-minikube kube-proxy-hqbh2 kube-scheduler-minikube storage-provisioner prod-deployment-average-2-77dcb68421de-85f497d589-lzcpd], RequestedResource:&framework.Resource{MilliCPU:8750, Memory:280657920, EphemeralStorage:0, AllowedPodNumber:0, ScalarResources:map[v1.ResourceName]int64(nil)}, NonZeroRequest: &framework.Resource{MilliCPU:9050, Memory:1538949120, EphemeralStorage:0, AllowedPodNumber:0, ScalarResources:map[v1.ResourceName]int64(nil)}, UsedPort: framework.HostPortInfo{}, AllocatableResource:&framework.Resource{MilliCPU:16000, Memory:33260953600, EphemeralStorage:30083776512, AllowedPodNumber:110, ScalarResources:map[v1.ResourceName]int64{"hugepages-1Gi":0, "hugepages-2Mi":0}}}]
I0307 14:20:17.677152       1 preemption.go:308] "Starting candidate search for preemption" pod="default/prod-deployment-average-1-3e1f1596b5ac-79665659cd-kw48q" totalNodes=1
I0307 14:20:17.677163       1 preemption.go:327] "Potential node for preemption identified" pod="default/prod-deployment-average-1-3e1f1596b5ac-79665659cd-kw48q" node="minikube"
I0307 14:20:17.677170       1 preemption.go:342] "candidatesNum was 0, setting it to 1 to ensure preemption is attempted" pod="default/prod-deployment-average-1-3e1f1596b5ac-79665659cd-kw48q"
I0307 14:20:17.677175       1 preemption.go:346] "Calling DryRunPreemption" pod="default/prod-deployment-average-1-3e1f1596b5ac-79665659cd-kw48q" numPotentialNodes=1
I0307 14:20:17.677180       1 preemption.go:347] "Calculated offset and candidatesNum" pod="default/prod-deployment-average-1-3e1f1596b5ac-79665659cd-kw48q" offset=0 candidatesNum=1
I0307 14:20:17.677188       1 preemption.go:623] "Starting DryRunPreemption" pod="default/prod-deployment-average-1-3e1f1596b5ac-79665659cd-kw48q" potentialNodesNumber=1 pdbsNumber=0 offset=0 candidatesNumber=1
I0307 14:20:17.677226       1 preemption.go:629] "Checking node for preemption" pod="default/prod-deployment-average-1-3e1f1596b5ac-79665659cd-kw48q" node="minikube"
I0307 14:20:17.677257       1 preemption.go:641] "No victim pods found on node" pod="default/prod-deployment-average-1-3e1f1596b5ac-79665659cd-kw48q" node="minikube"
I0307 14:20:17.677273       1 preemption.go:682] "Preemption evaluation completed" pod="default/prod-deployment-average-1-3e1f1596b5ac-79665659cd-kw48q" nonViolatingCandidates=0 violatingCandidates=0
I0307 14:20:17.677278       1 preemption.go:357] "Preemption candidates found" pod="default/prod-deployment-average-1-3e1f1596b5ac-79665659cd-kw48q" numCandidates=0
I0307 14:20:17.677300       1 preemption.go:251] Número de candidatos encontradoscount0
I0307 14:20:17.677305       1 preemption.go:252] Mapa de status dos nósnodeToStatusMap&{map[minikube:0xc000bc3080] 0xc000bc2f00}
I0307 14:20:17.677313       1 preemption.go:261] "No preemption candidate is found; preemption is not helpful for scheduling" pod="default/prod-deployment-average-1-3e1f1596b5ac-79665659cd-kw48q"
I0307 14:20:17.677322       1 default_preemption.go:37] "Preemption failed or not needed" pod="default/prod-deployment-average-1-3e1f1596b5ac-79665659cd-kw48q" status="0/1 nodes are available: 1 Insufficient cpu."
I0307 14:20:47.678124       1 default_preemption.go:28] "PostFilter called" pod="default/prod-deployment-average-1-3e1f1596b5ac-79665659cd-kw48q"
I0307 14:20:47.678156       1 preemption.go:244] Lista de nós obtidaallNodes[&NodeInfo{Pods:[coredns-668d6bf9bc-tbzv9 custom-scheduler-8dcdbb8b5-lvx5k etcd-minikube kube-apiserver-minikube kube-controller-manager-minikube kube-proxy-hqbh2 kube-scheduler-minikube storage-provisioner prod-deployment-average-2-77dcb68421de-85f497d589-lzcpd], RequestedResource:&framework.Resource{MilliCPU:8750, Memory:280657920, EphemeralStorage:0, AllowedPodNumber:0, ScalarResources:map[v1.ResourceName]int64(nil)}, NonZeroRequest: &framework.Resource{MilliCPU:9050, Memory:1538949120, EphemeralStorage:0, AllowedPodNumber:0, ScalarResources:map[v1.ResourceName]int64(nil)}, UsedPort: framework.HostPortInfo{}, AllocatableResource:&framework.Resource{MilliCPU:16000, Memory:33260953600, EphemeralStorage:30083776512, AllowedPodNumber:110, ScalarResources:map[v1.ResourceName]int64{"hugepages-1Gi":0, "hugepages-2Mi":0}}}]
I0307 14:20:47.678238       1 preemption.go:308] "Starting candidate search for preemption" pod="default/prod-deployment-average-1-3e1f1596b5ac-79665659cd-kw48q" totalNodes=1
I0307 14:20:47.678258       1 preemption.go:327] "Potential node for preemption identified" pod="default/prod-deployment-average-1-3e1f1596b5ac-79665659cd-kw48q" node="minikube"
I0307 14:20:47.678265       1 preemption.go:342] "candidatesNum was 0, setting it to 1 to ensure preemption is attempted" pod="default/prod-deployment-average-1-3e1f1596b5ac-79665659cd-kw48q"
I0307 14:20:47.678270       1 preemption.go:346] "Calling DryRunPreemption" pod="default/prod-deployment-average-1-3e1f1596b5ac-79665659cd-kw48q" numPotentialNodes=1
I0307 14:20:47.678282       1 preemption.go:347] "Calculated offset and candidatesNum" pod="default/prod-deployment-average-1-3e1f1596b5ac-79665659cd-kw48q" offset=0 candidatesNum=1
I0307 14:20:47.678290       1 preemption.go:623] "Starting DryRunPreemption" pod="default/prod-deployment-average-1-3e1f1596b5ac-79665659cd-kw48q" potentialNodesNumber=1 pdbsNumber=0 offset=0 candidatesNumber=1
I0307 14:20:47.678320       1 preemption.go:629] "Checking node for preemption" pod="default/prod-deployment-average-1-3e1f1596b5ac-79665659cd-kw48q" node="minikube"
I0307 14:20:47.678359       1 preemption.go:641] "No victim pods found on node" pod="default/prod-deployment-average-1-3e1f1596b5ac-79665659cd-kw48q" node="minikube"
I0307 14:20:47.678375       1 preemption.go:682] "Preemption evaluation completed" pod="default/prod-deployment-average-1-3e1f1596b5ac-79665659cd-kw48q" nonViolatingCandidates=0 violatingCandidates=0
I0307 14:20:47.678388       1 preemption.go:357] "Preemption candidates found" pod="default/prod-deployment-average-1-3e1f1596b5ac-79665659cd-kw48q" numCandidates=0
I0307 14:20:47.678393       1 preemption.go:251] Número de candidatos encontradoscount0
I0307 14:20:47.678398       1 preemption.go:252] Mapa de status dos nósnodeToStatusMap&{map[minikube:0xc000bc2f00] 0xc000bc2d80}
I0307 14:20:47.678407       1 preemption.go:261] "No preemption candidate is found; preemption is not helpful for scheduling" pod="default/prod-deployment-average-1-3e1f1596b5ac-79665659cd-kw48q"
I0307 14:20:47.678416       1 default_preemption.go:37] "Preemption failed or not needed" pod="default/prod-deployment-average-1-3e1f1596b5ac-79665659cd-kw48q" status="0/1 nodes are available: 1 Insufficient cpu."
I0307 14:21:17.678716       1 default_preemption.go:28] "PostFilter called" pod="default/prod-deployment-average-1-3e1f1596b5ac-79665659cd-kw48q"
I0307 14:21:17.678783       1 preemption.go:244] Lista de nós obtidaallNodes[&NodeInfo{Pods:[coredns-668d6bf9bc-tbzv9 custom-scheduler-8dcdbb8b5-lvx5k etcd-minikube kube-apiserver-minikube kube-controller-manager-minikube kube-proxy-hqbh2 kube-scheduler-minikube storage-provisioner prod-deployment-average-2-77dcb68421de-85f497d589-lzcpd], RequestedResource:&framework.Resource{MilliCPU:8750, Memory:280657920, EphemeralStorage:0, AllowedPodNumber:0, ScalarResources:map[v1.ResourceName]int64(nil)}, NonZeroRequest: &framework.Resource{MilliCPU:9050, Memory:1538949120, EphemeralStorage:0, AllowedPodNumber:0, ScalarResources:map[v1.ResourceName]int64(nil)}, UsedPort: framework.HostPortInfo{}, AllocatableResource:&framework.Resource{MilliCPU:16000, Memory:33260953600, EphemeralStorage:30083776512, AllowedPodNumber:110, ScalarResources:map[v1.ResourceName]int64{"hugepages-1Gi":0, "hugepages-2Mi":0}}}]
I0307 14:21:17.678818       1 preemption.go:308] "Starting candidate search for preemption" pod="default/prod-deployment-average-1-3e1f1596b5ac-79665659cd-kw48q" totalNodes=1
I0307 14:21:17.678829       1 preemption.go:327] "Potential node for preemption identified" pod="default/prod-deployment-average-1-3e1f1596b5ac-79665659cd-kw48q" node="minikube"
I0307 14:21:17.678836       1 preemption.go:342] "candidatesNum was 0, setting it to 1 to ensure preemption is attempted" pod="default/prod-deployment-average-1-3e1f1596b5ac-79665659cd-kw48q"
I0307 14:21:17.678841       1 preemption.go:346] "Calling DryRunPreemption" pod="default/prod-deployment-average-1-3e1f1596b5ac-79665659cd-kw48q" numPotentialNodes=1
I0307 14:21:17.678846       1 preemption.go:347] "Calculated offset and candidatesNum" pod="default/prod-deployment-average-1-3e1f1596b5ac-79665659cd-kw48q" offset=0 candidatesNum=1
I0307 14:21:17.678853       1 preemption.go:623] "Starting DryRunPreemption" pod="default/prod-deployment-average-1-3e1f1596b5ac-79665659cd-kw48q" potentialNodesNumber=1 pdbsNumber=0 offset=0 candidatesNumber=1
I0307 14:21:17.678886       1 preemption.go:629] "Checking node for preemption" pod="default/prod-deployment-average-1-3e1f1596b5ac-79665659cd-kw48q" node="minikube"
I0307 14:21:17.678925       1 preemption.go:641] "No victim pods found on node" pod="default/prod-deployment-average-1-3e1f1596b5ac-79665659cd-kw48q" node="minikube"
I0307 14:21:17.678947       1 preemption.go:682] "Preemption evaluation completed" pod="default/prod-deployment-average-1-3e1f1596b5ac-79665659cd-kw48q" nonViolatingCandidates=0 violatingCandidates=0
I0307 14:21:17.678953       1 preemption.go:357] "Preemption candidates found" pod="default/prod-deployment-average-1-3e1f1596b5ac-79665659cd-kw48q" numCandidates=0
I0307 14:21:17.678958       1 preemption.go:251] Número de candidatos encontradoscount0
I0307 14:21:17.678963       1 preemption.go:252] Mapa de status dos nósnodeToStatusMap&{map[minikube:0xc000a31840] 0xc000a316c0}
I0307 14:21:17.678972       1 preemption.go:261] "No preemption candidate is found; preemption is not helpful for scheduling" pod="default/prod-deployment-average-1-3e1f1596b5ac-79665659cd-kw48q"
I0307 14:21:17.678984       1 default_preemption.go:37] "Preemption failed or not needed" pod="default/prod-deployment-average-1-3e1f1596b5ac-79665659cd-kw48q" status="0/1 nodes are available: 1 Insufficient cpu."
I0307 14:21:35.570992       1 scheduler.go:258] [OnUpdatePod] Iniciando processamento de atualização de pod
I0307 14:21:35.571047       1 scheduler.go:262] [OnUpdatePod] Pod atualizado detectado: default/prod-deployment-average-1-3e1f1596b5ac-79665659cd-kw48q, Anotações: map[acceptablePreemptionOverhead:0.05 controller:prod-deployment-average-1-3e1f1596b5ac qosMeasuring:average slo:0.8]
I0307 14:21:35.571063       1 scheduler.go:265] [OnUpdatePod] Comparando estado no Informer e estado real no cluster para o pod default/prod-deployment-average-1-3e1f1596b5ac-79665659cd-kw48q
E0307 14:21:35.574111       1 scheduler.go:72] Erro ao buscar estado real do pod prod-deployment-average-1-3e1f1596b5ac-79665659cd-kw48q: pods "prod-deployment-average-1-3e1f1596b5ac-79665659cd-kw48q" not found
I0307 14:21:35.574166       1 scheduler.go:275] [OnUpdatePod] Atualizando informações de métricas para o pod default/prod-deployment-average-1-3e1f1596b5ac-79665659cd-kw48q
I0307 14:21:35.574175       1 types.go:751] [ControllerName] Verificando as anotações do pod default/prod-deployment-average-1-3e1f1596b5ac-79665659cd-kw48q
I0307 14:21:35.574183       1 types.go:769] [ControllerName] Anotação 'controller' encontrada para o pod default/prod-deployment-average-1-3e1f1596b5ac-79665659cd-kw48q: prod-deployment-average-1-3e1f1596b5ac
I0307 14:21:35.574192       1 scheduler.go:277] [OnUpdatePod] Atualizando 'LastStatus' do pod default/prod-deployment-average-1-3e1f1596b5ac-79665659cd-kw48q nas métricas
I0307 14:21:35.574197       1 scheduler.go:279] [OnUpdatePod] Métrica atualizada para o pod default/prod-deployment-average-1-3e1f1596b5ac-79665659cd-kw48q
I0307 14:21:35.574234       1 scheduler.go:283] [OnUpdatePod] Finalizando processamento de atualização de pod para default/prod-deployment-average-1-3e1f1596b5ac-79665659cd-kw48q
I0307 14:21:35.574262       1 types.go:751] [ControllerName] Verificando as anotações do pod default/prod-deployment-average-1-3e1f1596b5ac-79665659cd-kw48q
I0307 14:21:35.574286       1 types.go:769] [ControllerName] Anotação 'controller' encontrada para o pod default/prod-deployment-average-1-3e1f1596b5ac-79665659cd-kw48q: prod-deployment-average-1-3e1f1596b5ac
I0307 14:21:35.574298       1 types.go:532] [QoS DEBUG] effectiveRunning: 0.000000 | discardedRunning: 0.000000 | waiting: 299.574290 | binding: 0.000000 | denominator: 299.574290
I0307 14:21:35.574319       1 types.go:538] [QoS DEBUG] QoS calculado: 0.000000
I0307 14:21:35.574323       1 types.go:546] [QoSMetric] qosMeasuringApproach: average
I0307 14:21:35.574329       1 types.go:532] [QoS DEBUG] effectiveRunning: 0.000000 | discardedRunning: 0.000000 | waiting: 299.574290 | binding: 0.000000 | denominator: 299.574290
I0307 14:21:35.574334       1 types.go:538] [QoS DEBUG] QoS calculado: 0.000000
I0307 14:21:35.574339       1 types.go:611] [COMPUTE QoS METRIC - AVERAGE] The pod prod-deployment-average-1-3e1f1596b5ac-79665659cd-kw48q: availability 0.000000 | runtime 0.000000 | pendingTime 299.574290 | nRunning: 0 | nWaiting: 0 | residualContr 0 | estimatedOverhead 2.400000 | QoSMetric -301.974290
I0307 14:21:35.574380       1 scheduler.go:288] [OnDeletePod] Iniciando a execução do OnDeletePod
I0307 14:21:35.574424       1 scheduler.go:297] [OnDeletePod] DeepCopy realizado para o pod default/prod-deployment-average-1-3e1f1596b5ac-79665659cd-kw48q
I0307 14:21:35.574661       1 scheduler.go:304] [OnDeletePod] Pod deletado detectado: default/prod-deployment-average-1-3e1f1596b5ac-79665659cd-kw48q
I0307 14:21:35.574686       1 scheduler.go:306] [OnDeletePod] Atualizando métricas do pod default/prod-deployment-average-1-3e1f1596b5ac-79665659cd-kw48q
I0307 14:21:35.574692       1 types.go:751] [ControllerName] Verificando as anotações do pod default/prod-deployment-average-1-3e1f1596b5ac-79665659cd-kw48q
I0307 14:21:35.574697       1 types.go:769] [ControllerName] Anotação 'controller' encontrada para o pod default/prod-deployment-average-1-3e1f1596b5ac-79665659cd-kw48q: prod-deployment-average-1-3e1f1596b5ac
I0307 14:21:35.574706       1 scheduler.go:308] [OnDeletePod] Verificando o estado do pod default/prod-deployment-average-1-3e1f1596b5ac-79665659cd-kw48q nas métricas
I0307 14:21:35.574711       1 scheduler.go:318] [OnDeletePod] EndTime atualizado para o pod default/prod-deployment-average-1-3e1f1596b5ac-79665659cd-kw48q: 2025-03-07 14:21:35.574708347 +0000 UTC m=+4038.838702340
I0307 14:21:35.574724       1 scheduler.go:322] [OnDeletePod] Finalizando a execução do OnDeletePod para o pod default/prod-deployment-average-1-3e1f1596b5ac-79665659cd-kw48q
I0307 14:21:35.583551       1 scheduler.go:258] [OnUpdatePod] Iniciando processamento de atualização de pod
I0307 14:21:35.583604       1 scheduler.go:262] [OnUpdatePod] Pod atualizado detectado: default/prod-deployment-average-2-77dcb68421de-85f497d589-lzcpd, Anotações: map[acceptablePreemptionOverhead:0.05 controller:prod-deployment-average-2-77dcb68421de qosMeasuring:average slo:0.8]
I0307 14:21:35.583617       1 scheduler.go:265] [OnUpdatePod] Comparando estado no Informer e estado real no cluster para o pod default/prod-deployment-average-2-77dcb68421de-85f497d589-lzcpd
E0307 14:21:35.585795       1 scheduler.go:72] Erro ao buscar estado real do pod prod-deployment-average-2-77dcb68421de-85f497d589-lzcpd: pods "prod-deployment-average-2-77dcb68421de-85f497d589-lzcpd" not found
I0307 14:21:35.585827       1 scheduler.go:275] [OnUpdatePod] Atualizando informações de métricas para o pod default/prod-deployment-average-2-77dcb68421de-85f497d589-lzcpd
I0307 14:21:35.585835       1 types.go:751] [ControllerName] Verificando as anotações do pod default/prod-deployment-average-2-77dcb68421de-85f497d589-lzcpd
I0307 14:21:35.585857       1 types.go:769] [ControllerName] Anotação 'controller' encontrada para o pod default/prod-deployment-average-2-77dcb68421de-85f497d589-lzcpd: prod-deployment-average-2-77dcb68421de
I0307 14:21:35.585865       1 scheduler.go:277] [OnUpdatePod] Atualizando 'LastStatus' do pod default/prod-deployment-average-2-77dcb68421de-85f497d589-lzcpd nas métricas
I0307 14:21:35.585869       1 scheduler.go:279] [OnUpdatePod] Métrica atualizada para o pod default/prod-deployment-average-2-77dcb68421de-85f497d589-lzcpd
I0307 14:21:35.585889       1 scheduler.go:283] [OnUpdatePod] Finalizando processamento de atualização de pod para default/prod-deployment-average-2-77dcb68421de-85f497d589-lzcpd
I0307 14:21:35.585895       1 scheduler.go:288] [OnDeletePod] Iniciando a execução do OnDeletePod
I0307 14:21:35.585920       1 scheduler.go:297] [OnDeletePod] DeepCopy realizado para o pod default/prod-deployment-average-2-77dcb68421de-85f497d589-lzcpd
I0307 14:21:35.586000       1 types.go:751] [ControllerName] Verificando as anotações do pod default/prod-deployment-average-2-77dcb68421de-85f497d589-lzcpd
I0307 14:21:35.586016       1 types.go:769] [ControllerName] Anotação 'controller' encontrada para o pod default/prod-deployment-average-2-77dcb68421de-85f497d589-lzcpd: prod-deployment-average-2-77dcb68421de
I0307 14:21:35.586025       1 types.go:532] [QoS DEBUG] effectiveRunning: 299.001531 | discardedRunning: 0.000000 | waiting: 0.577165 | binding: 0.007322 | denominator: 299.586019
I0307 14:21:35.586043       1 types.go:538] [QoS DEBUG] QoS calculado: 0.998049
I0307 14:21:35.586048       1 types.go:546] [QoSMetric] qosMeasuringApproach: average
I0307 14:21:35.586053       1 types.go:532] [QoS DEBUG] effectiveRunning: 299.001531 | discardedRunning: 0.000000 | waiting: 0.577165 | binding: 0.007322 | denominator: 299.586019
I0307 14:21:35.586063       1 types.go:538] [QoS DEBUG] QoS calculado: 0.998049
I0307 14:21:35.586070       1 types.go:611] [COMPUTE QoS METRIC - AVERAGE] The pod prod-deployment-average-2-77dcb68421de-85f497d589-lzcpd: availability 0.998049 | runtime 299.001531 | pendingTime 0.577165 | nRunning: 0 | nWaiting: 0 | residualContr -1 | estimatedOverhead 0.007322 | QoSMetric 59.325394
I0307 14:21:35.586136       1 scheduler.go:304] [OnDeletePod] Pod deletado detectado: default/prod-deployment-average-2-77dcb68421de-85f497d589-lzcpd
I0307 14:21:35.586162       1 scheduler.go:306] [OnDeletePod] Atualizando métricas do pod default/prod-deployment-average-2-77dcb68421de-85f497d589-lzcpd
I0307 14:21:35.586169       1 types.go:751] [ControllerName] Verificando as anotações do pod default/prod-deployment-average-2-77dcb68421de-85f497d589-lzcpd
I0307 14:21:35.586174       1 types.go:769] [ControllerName] Anotação 'controller' encontrada para o pod default/prod-deployment-average-2-77dcb68421de-85f497d589-lzcpd: prod-deployment-average-2-77dcb68421de
I0307 14:21:35.586179       1 scheduler.go:308] [OnDeletePod] Verificando o estado do pod default/prod-deployment-average-2-77dcb68421de-85f497d589-lzcpd nas métricas
I0307 14:21:35.586184       1 scheduler.go:318] [OnDeletePod] EndTime atualizado para o pod default/prod-deployment-average-2-77dcb68421de-85f497d589-lzcpd: 2025-03-07 14:21:35.58618179 +0000 UTC m=+4038.850175793
I0307 14:21:35.586194       1 scheduler.go:322] [OnDeletePod] Finalizando a execução do OnDeletePod para o pod default/prod-deployment-average-2-77dcb68421de-85f497d589-lzcpd
