I0303 17:33:44.065860       1 serving.go:386] Generated self-signed cert in-memory
W0303 17:33:44.066652       1 client_config.go:667] Neither --kubeconfig nor --master was specified.  Using the inClusterConfig.  This might not work.
I0303 17:33:44.438829       1 server.go:166] "Starting Kubernetes Scheduler" version="v0.0.0-master+$Format:%H$"
I0303 17:33:44.438858       1 server.go:168] "Golang settings" GOGC="" GOMAXPROCS="" GOTRACEBACK=""
I0303 17:33:44.442517       1 requestheader_controller.go:180] Starting RequestHeaderAuthRequestController
I0303 17:33:44.442560       1 shared_informer.go:313] Waiting for caches to sync for RequestHeaderAuthRequestController
I0303 17:33:44.442602       1 configmap_cafile_content.go:205] "Starting controller" name="client-ca::kube-system::extension-apiserver-authentication::client-ca-file"
I0303 17:33:44.442630       1 shared_informer.go:313] Waiting for caches to sync for client-ca::kube-system::extension-apiserver-authentication::client-ca-file
I0303 17:33:44.442631       1 configmap_cafile_content.go:205] "Starting controller" name="client-ca::kube-system::extension-apiserver-authentication::requestheader-client-ca-file"
I0303 17:33:44.442649       1 shared_informer.go:313] Waiting for caches to sync for client-ca::kube-system::extension-apiserver-authentication::requestheader-client-ca-file
I0303 17:33:44.442707       1 secure_serving.go:213] Serving securely on [::]:10259
I0303 17:33:44.442723       1 tlsconfig.go:243] "Starting DynamicServingCertificateController"
I0303 17:33:44.448739       1 scheduler.go:219] [OnAddPod] Pod adicionado: kube-system/coredns-668d6bf9bc-tbzv9, Anotações: map[]
I0303 17:33:44.450526       1 scheduler.go:74] Estado no Informer: map[]
I0303 17:33:44.450548       1 scheduler.go:75] Estado real no cluster: map[]
I0303 17:33:44.450553       1 scheduler.go:225] [OnAddPod] Ignorando pod kube-system/coredns-668d6bf9bc-tbzv9 pois pertence ao namespace kube-system
I0303 17:33:44.450587       1 scheduler.go:219] [OnAddPod] Pod adicionado: kube-system/custom-scheduler-8dcdbb8b5-2tv8d, Anotações: map[]
I0303 17:33:44.451897       1 scheduler.go:74] Estado no Informer: map[]
I0303 17:33:44.451919       1 scheduler.go:75] Estado real no cluster: map[]
I0303 17:33:44.451925       1 scheduler.go:225] [OnAddPod] Ignorando pod kube-system/custom-scheduler-8dcdbb8b5-2tv8d pois pertence ao namespace kube-system
I0303 17:33:44.451964       1 scheduler.go:219] [OnAddPod] Pod adicionado: kube-system/etcd-minikube, Anotações: map[kubeadm.kubernetes.io/etcd.advertise-client-urls:https://192.168.49.2:2379 kubernetes.io/config.hash:2b4b75c2a289008e0b381891e9683040 kubernetes.io/config.mirror:2b4b75c2a289008e0b381891e9683040 kubernetes.io/config.seen:2025-02-28T14:06:38.491414868Z kubernetes.io/config.source:file]
I0303 17:33:44.453225       1 scheduler.go:74] Estado no Informer: map[kubeadm.kubernetes.io/etcd.advertise-client-urls:https://192.168.49.2:2379 kubernetes.io/config.hash:2b4b75c2a289008e0b381891e9683040 kubernetes.io/config.mirror:2b4b75c2a289008e0b381891e9683040 kubernetes.io/config.seen:2025-02-28T14:06:38.491414868Z kubernetes.io/config.source:file]
I0303 17:33:44.453250       1 scheduler.go:75] Estado real no cluster: map[kubeadm.kubernetes.io/etcd.advertise-client-urls:https://192.168.49.2:2379 kubernetes.io/config.hash:2b4b75c2a289008e0b381891e9683040 kubernetes.io/config.mirror:2b4b75c2a289008e0b381891e9683040 kubernetes.io/config.seen:2025-02-28T14:06:38.491414868Z kubernetes.io/config.source:file]
I0303 17:33:44.453264       1 scheduler.go:225] [OnAddPod] Ignorando pod kube-system/etcd-minikube pois pertence ao namespace kube-system
I0303 17:33:44.453295       1 scheduler.go:219] [OnAddPod] Pod adicionado: kube-system/kube-apiserver-minikube, Anotações: map[kubeadm.kubernetes.io/kube-apiserver.advertise-address.endpoint:192.168.49.2:8443 kubernetes.io/config.hash:d72d0a4cf4be077c9919d46b7358a5e8 kubernetes.io/config.mirror:d72d0a4cf4be077c9919d46b7358a5e8 kubernetes.io/config.seen:2025-02-28T14:06:38.491410078Z kubernetes.io/config.source:file]
I0303 17:33:44.454692       1 scheduler.go:74] Estado no Informer: map[kubeadm.kubernetes.io/kube-apiserver.advertise-address.endpoint:192.168.49.2:8443 kubernetes.io/config.hash:d72d0a4cf4be077c9919d46b7358a5e8 kubernetes.io/config.mirror:d72d0a4cf4be077c9919d46b7358a5e8 kubernetes.io/config.seen:2025-02-28T14:06:38.491410078Z kubernetes.io/config.source:file]
I0303 17:33:44.454713       1 scheduler.go:75] Estado real no cluster: map[kubeadm.kubernetes.io/kube-apiserver.advertise-address.endpoint:192.168.49.2:8443 kubernetes.io/config.hash:d72d0a4cf4be077c9919d46b7358a5e8 kubernetes.io/config.mirror:d72d0a4cf4be077c9919d46b7358a5e8 kubernetes.io/config.seen:2025-02-28T14:06:38.491410078Z kubernetes.io/config.source:file]
I0303 17:33:44.454720       1 scheduler.go:225] [OnAddPod] Ignorando pod kube-system/kube-apiserver-minikube pois pertence ao namespace kube-system
I0303 17:33:44.454745       1 scheduler.go:219] [OnAddPod] Pod adicionado: kube-system/kube-controller-manager-minikube, Anotações: map[kubernetes.io/config.hash:843c74f7b3bc7d7040a05c31708a6a30 kubernetes.io/config.mirror:843c74f7b3bc7d7040a05c31708a6a30 kubernetes.io/config.seen:2025-02-28T14:06:38.491412428Z kubernetes.io/config.source:file]
I0303 17:33:44.455974       1 scheduler.go:74] Estado no Informer: map[kubernetes.io/config.hash:843c74f7b3bc7d7040a05c31708a6a30 kubernetes.io/config.mirror:843c74f7b3bc7d7040a05c31708a6a30 kubernetes.io/config.seen:2025-02-28T14:06:38.491412428Z kubernetes.io/config.source:file]
I0303 17:33:44.455995       1 scheduler.go:75] Estado real no cluster: map[kubernetes.io/config.hash:843c74f7b3bc7d7040a05c31708a6a30 kubernetes.io/config.mirror:843c74f7b3bc7d7040a05c31708a6a30 kubernetes.io/config.seen:2025-02-28T14:06:38.491412428Z kubernetes.io/config.source:file]
I0303 17:33:44.456002       1 scheduler.go:225] [OnAddPod] Ignorando pod kube-system/kube-controller-manager-minikube pois pertence ao namespace kube-system
I0303 17:33:44.456063       1 scheduler.go:219] [OnAddPod] Pod adicionado: kube-system/kube-proxy-hqbh2, Anotações: map[]
I0303 17:33:44.457310       1 scheduler.go:74] Estado no Informer: map[]
I0303 17:33:44.457326       1 scheduler.go:75] Estado real no cluster: map[]
I0303 17:33:44.457330       1 scheduler.go:225] [OnAddPod] Ignorando pod kube-system/kube-proxy-hqbh2 pois pertence ao namespace kube-system
I0303 17:33:44.457353       1 scheduler.go:219] [OnAddPod] Pod adicionado: kube-system/kube-scheduler-minikube, Anotações: map[kubernetes.io/config.hash:d14ce008bee3a1f3bd7cf547688f9dfe kubernetes.io/config.mirror:d14ce008bee3a1f3bd7cf547688f9dfe kubernetes.io/config.seen:2025-02-28T14:06:38.491413718Z kubernetes.io/config.source:file]
I0303 17:33:44.458587       1 scheduler.go:74] Estado no Informer: map[kubernetes.io/config.hash:d14ce008bee3a1f3bd7cf547688f9dfe kubernetes.io/config.mirror:d14ce008bee3a1f3bd7cf547688f9dfe kubernetes.io/config.seen:2025-02-28T14:06:38.491413718Z kubernetes.io/config.source:file]
I0303 17:33:44.458614       1 scheduler.go:75] Estado real no cluster: map[kubernetes.io/config.hash:d14ce008bee3a1f3bd7cf547688f9dfe kubernetes.io/config.mirror:d14ce008bee3a1f3bd7cf547688f9dfe kubernetes.io/config.seen:2025-02-28T14:06:38.491413718Z kubernetes.io/config.source:file]
I0303 17:33:44.458625       1 scheduler.go:225] [OnAddPod] Ignorando pod kube-system/kube-scheduler-minikube pois pertence ao namespace kube-system
I0303 17:33:44.458664       1 scheduler.go:219] [OnAddPod] Pod adicionado: kube-system/storage-provisioner, Anotações: map[kubectl.kubernetes.io/last-applied-configuration:{"apiVersion":"v1","kind":"Pod","metadata":{"annotations":{},"labels":{"addonmanager.kubernetes.io/mode":"Reconcile","integration-test":"storage-provisioner"},"name":"storage-provisioner","namespace":"kube-system"},"spec":{"containers":[{"command":["/storage-provisioner"],"image":"gcr.io/k8s-minikube/storage-provisioner:v5","imagePullPolicy":"IfNotPresent","name":"storage-provisioner","volumeMounts":[{"mountPath":"/tmp","name":"tmp"}]}],"hostNetwork":true,"serviceAccountName":"storage-provisioner","volumes":[{"hostPath":{"path":"/tmp","type":"Directory"},"name":"tmp"}]}}
]
I0303 17:33:44.459882       1 scheduler.go:74] Estado no Informer: map[kubectl.kubernetes.io/last-applied-configuration:{"apiVersion":"v1","kind":"Pod","metadata":{"annotations":{},"labels":{"addonmanager.kubernetes.io/mode":"Reconcile","integration-test":"storage-provisioner"},"name":"storage-provisioner","namespace":"kube-system"},"spec":{"containers":[{"command":["/storage-provisioner"],"image":"gcr.io/k8s-minikube/storage-provisioner:v5","imagePullPolicy":"IfNotPresent","name":"storage-provisioner","volumeMounts":[{"mountPath":"/tmp","name":"tmp"}]}],"hostNetwork":true,"serviceAccountName":"storage-provisioner","volumes":[{"hostPath":{"path":"/tmp","type":"Directory"},"name":"tmp"}]}}
]
I0303 17:33:44.459904       1 scheduler.go:75] Estado real no cluster: map[kubectl.kubernetes.io/last-applied-configuration:{"apiVersion":"v1","kind":"Pod","metadata":{"annotations":{},"labels":{"addonmanager.kubernetes.io/mode":"Reconcile","integration-test":"storage-provisioner"},"name":"storage-provisioner","namespace":"kube-system"},"spec":{"containers":[{"command":["/storage-provisioner"],"image":"gcr.io/k8s-minikube/storage-provisioner:v5","imagePullPolicy":"IfNotPresent","name":"storage-provisioner","volumeMounts":[{"mountPath":"/tmp","name":"tmp"}]}],"hostNetwork":true,"serviceAccountName":"storage-provisioner","volumes":[{"hostPath":{"path":"/tmp","type":"Directory"},"name":"tmp"}]}}
]
I0303 17:33:44.459911       1 scheduler.go:225] [OnAddPod] Ignorando pod kube-system/storage-provisioner pois pertence ao namespace kube-system
I0303 17:33:44.543093       1 leaderelection.go:257] attempting to acquire leader lease kube-system/kube-scheduler...
I0303 17:33:44.543148       1 shared_informer.go:320] Caches are synced for RequestHeaderAuthRequestController
I0303 17:33:44.543194       1 shared_informer.go:320] Caches are synced for client-ca::kube-system::extension-apiserver-authentication::client-ca-file
I0303 17:33:44.543157       1 shared_informer.go:320] Caches are synced for client-ca::kube-system::extension-apiserver-authentication::requestheader-client-ca-file
I0303 17:33:44.547595       1 leaderelection.go:271] successfully acquired lease kube-system/kube-scheduler
I0303 17:36:11.133091       1 scheduler.go:219] [OnAddPod] Pod adicionado: default/low-priority-pod, Anotações: map[controller:test-controller2 kubectl.kubernetes.io/last-applied-configuration:{"apiVersion":"v1","kind":"Pod","metadata":{"annotations":{"controller":"test-controller2"},"labels":{"app":"test-app"},"name":"low-priority-pod","namespace":"default"},"spec":{"containers":[{"image":"nginx:latest","imagePullPolicy":"IfNotPresent","name":"nginx","resources":{"limits":{"cpu":"8000m","memory":"268Mi"},"requests":{"cpu":"8000m","memory":"268Mi"}}}],"priorityClassName":"free-priority","schedulerName":"custom-scheduler"}}
]
I0303 17:36:11.133335       1 scheduler.go:150] [Reserve] resources reserved at node minikube for pod low-priority-pod_default at 2025-03-03 17:36:11.133327447 +0000 UTC m=+147.381928660
I0303 17:36:11.133364       1 types.go:751] [ControllerName] Verificando as anotações do pod default/low-priority-pod
I0303 17:36:11.133369       1 types.go:769] [ControllerName] Anotação 'controller' encontrada para o pod default/low-priority-pod: test-controller2
I0303 17:36:11.133376       1 scheduler.go:152] [Reserve] Status de alocação atual para o pod low-priority-pod_default: 
I0303 17:36:11.133381       1 scheduler.go:154] [Reserve] Status de alocação atualizado para o pod low-priority-pod_default: allocating
I0303 17:36:11.133420       1 scheduler.go:178] [PreBind] Validando o pod low-priority-pod antes de vincular ao node minikube
I0303 17:36:11.134823       1 scheduler.go:74] Estado no Informer: map[controller:test-controller2 kubectl.kubernetes.io/last-applied-configuration:{"apiVersion":"v1","kind":"Pod","metadata":{"annotations":{"controller":"test-controller2"},"labels":{"app":"test-app"},"name":"low-priority-pod","namespace":"default"},"spec":{"containers":[{"image":"nginx:latest","imagePullPolicy":"IfNotPresent","name":"nginx","resources":{"limits":{"cpu":"8000m","memory":"268Mi"},"requests":{"cpu":"8000m","memory":"268Mi"}}}],"priorityClassName":"free-priority","schedulerName":"custom-scheduler"}}
]
I0303 17:36:11.134845       1 scheduler.go:75] Estado real no cluster: map[controller:test-controller2 kubectl.kubernetes.io/last-applied-configuration:{"apiVersion":"v1","kind":"Pod","metadata":{"annotations":{"controller":"test-controller2"},"labels":{"app":"test-app"},"name":"low-priority-pod","namespace":"default"},"spec":{"containers":[{"image":"nginx:latest","imagePullPolicy":"IfNotPresent","name":"nginx","resources":{"limits":{"cpu":"8000m","memory":"268Mi"},"requests":{"cpu":"8000m","memory":"268Mi"}}}],"priorityClassName":"free-priority","schedulerName":"custom-scheduler"}}
]
I0303 17:36:11.135591       1 scheduler.go:230] [OnAddPod] Adicionando pod default/low-priority-pod com os seguintes detalhes:
&Pod{ObjectMeta:{low-priority-pod  default  477e5da3-da12-412b-a82f-513749ebe981 54322 0 2025-03-03 17:36:11 +0000 UTC <nil> <nil> map[app:test-app] map[controller:test-controller2 kubectl.kubernetes.io/last-applied-configuration:{"apiVersion":"v1","kind":"Pod","metadata":{"annotations":{"controller":"test-controller2"},"labels":{"app":"test-app"},"name":"low-priority-pod","namespace":"default"},"spec":{"containers":[{"image":"nginx:latest","imagePullPolicy":"IfNotPresent","name":"nginx","resources":{"limits":{"cpu":"8000m","memory":"268Mi"},"requests":{"cpu":"8000m","memory":"268Mi"}}}],"priorityClassName":"free-priority","schedulerName":"custom-scheduler"}}
] [] [] [{kubectl-client-side-apply Update v1 2025-03-03 17:36:11 +0000 UTC FieldsV1 {"f:metadata":{"f:annotations":{".":{},"f:controller":{},"f:kubectl.kubernetes.io/last-applied-configuration":{}},"f:labels":{".":{},"f:app":{}}},"f:spec":{"f:containers":{"k:{\"name\":\"nginx\"}":{".":{},"f:image":{},"f:imagePullPolicy":{},"f:name":{},"f:resources":{".":{},"f:limits":{".":{},"f:cpu":{},"f:memory":{}},"f:requests":{".":{},"f:cpu":{},"f:memory":{}}},"f:terminationMessagePath":{},"f:terminationMessagePolicy":{}}},"f:dnsPolicy":{},"f:enableServiceLinks":{},"f:priorityClassName":{},"f:restartPolicy":{},"f:schedulerName":{},"f:securityContext":{},"f:terminationGracePeriodSeconds":{}}} }]},Spec:PodSpec{Volumes:[]Volume{Volume{Name:kube-api-access-xrhdb,VolumeSource:VolumeSource{HostPath:nil,EmptyDir:nil,GCEPersistentDisk:nil,AWSElasticBlockStore:nil,GitRepo:nil,Secret:nil,NFS:nil,ISCSI:nil,Glusterfs:nil,PersistentVolumeClaim:nil,RBD:nil,FlexVolume:nil,Cinder:nil,CephFS:nil,Flocker:nil,DownwardAPI:nil,FC:nil,AzureFile:nil,ConfigMap:nil,VsphereVolume:nil,Quobyte:nil,AzureDisk:nil,PhotonPersistentDisk:nil,PortworxVolume:nil,ScaleIO:nil,Projected:&ProjectedVolumeSource{Sources:[]VolumeProjection{VolumeProjection{Secret:nil,DownwardAPI:nil,ConfigMap:nil,ServiceAccountToken:&ServiceAccountTokenProjection{Audience:,ExpirationSeconds:*3607,Path:token,},ClusterTrustBundle:nil,},VolumeProjection{Secret:nil,DownwardAPI:nil,ConfigMap:&ConfigMapProjection{LocalObjectReference:LocalObjectReference{Name:kube-root-ca.crt,},Items:[]KeyToPath{KeyToPath{Key:ca.crt,Path:ca.crt,Mode:nil,},},Optional:nil,},ServiceAccountToken:nil,ClusterTrustBundle:nil,},VolumeProjection{Secret:nil,DownwardAPI:&DownwardAPIProjection{Items:[]DownwardAPIVolumeFile{DownwardAPIVolumeFile{Path:namespace,FieldRef:&ObjectFieldSelector{APIVersion:v1,FieldPath:metadata.namespace,},ResourceFieldRef:nil,Mode:nil,},},},ConfigMap:nil,ServiceAccountToken:nil,ClusterTrustBundle:nil,},},DefaultMode:*420,},StorageOS:nil,CSI:nil,Ephemeral:nil,Image:nil,},},},Containers:[]Container{Container{Name:nginx,Image:nginx:latest,Command:[],Args:[],WorkingDir:,Ports:[]ContainerPort{},Env:[]EnvVar{},Resources:ResourceRequirements{Limits:ResourceList{cpu: {{8 0} {<nil>} 8 DecimalSI},memory: {{281018368 0} {<nil>} 268Mi BinarySI},},Requests:ResourceList{cpu: {{8 0} {<nil>} 8 DecimalSI},memory: {{281018368 0} {<nil>} 268Mi BinarySI},},Claims:[]ResourceClaim{},},VolumeMounts:[]VolumeMount{VolumeMount{Name:kube-api-access-xrhdb,ReadOnly:true,MountPath:/var/run/secrets/kubernetes.io/serviceaccount,SubPath:,MountPropagation:nil,SubPathExpr:,RecursiveReadOnly:nil,},},LivenessProbe:nil,ReadinessProbe:nil,Lifecycle:nil,TerminationMessagePath:/dev/termination-log,ImagePullPolicy:IfNotPresent,SecurityContext:nil,Stdin:false,StdinOnce:false,TTY:false,EnvFrom:[]EnvFromSource{},TerminationMessagePolicy:File,VolumeDevices:[]VolumeDevice{},StartupProbe:nil,ResizePolicy:[]ContainerResizePolicy{},RestartPolicy:nil,},},RestartPolicy:Always,TerminationGracePeriodSeconds:*30,ActiveDeadlineSeconds:nil,DNSPolicy:ClusterFirst,NodeSelector:map[string]string{},ServiceAccountName:default,DeprecatedServiceAccount:default,NodeName:,HostNetwork:false,HostPID:false,HostIPC:false,SecurityContext:&PodSecurityContext{SELinuxOptions:nil,RunAsUser:nil,RunAsNonRoot:nil,SupplementalGroups:[],FSGroup:nil,RunAsGroup:nil,Sysctls:[]Sysctl{},WindowsOptions:nil,FSGroupChangePolicy:nil,SeccompProfile:nil,AppArmorProfile:nil,SupplementalGroupsPolicy:nil,SELinuxChangePolicy:nil,},ImagePullSecrets:[]LocalObjectReference{},Hostname:,Subdomain:,Affinity:nil,SchedulerName:custom-scheduler,InitContainers:[]Container{},AutomountServiceAccountToken:nil,Tolerations:[]Toleration{Toleration{Key:node.kubernetes.io/not-ready,Operator:Exists,Value:,Effect:NoExecute,TolerationSeconds:*300,},Toleration{Key:node.kubernetes.io/unreachable,Operator:Exists,Value:,Effect:NoExecute,TolerationSeconds:*300,},},HostAliases:[]HostAlias{},PriorityClassName:free-priority,Priority:*1,DNSConfig:nil,ShareProcessNamespace:nil,ReadinessGates:[]PodReadinessGate{},RuntimeClassName:nil,EnableServiceLinks:*true,PreemptionPolicy:*PreemptLowerPriority,Overhead:ResourceList{},TopologySpreadConstraints:[]TopologySpreadConstraint{},EphemeralContainers:[]EphemeralContainer{},SetHostnameAsFQDN:nil,OS:nil,HostUsers:nil,SchedulingGates:[]PodSchedulingGate{},ResourceClaims:[]PodResourceClaim{},Resources:nil,},Status:PodStatus{Phase:Pending,Conditions:[]PodCondition{},Message:,Reason:,HostIP:,PodIP:,StartTime:<nil>,ContainerStatuses:[]ContainerStatus{},QOSClass:Guaranteed,InitContainerStatuses:[]ContainerStatus{},NominatedNodeName:,PodIPs:[]PodIP{},EphemeralContainerStatuses:[]ContainerStatus{},Resize:,ResourceClaimStatuses:[]PodResourceClaimStatus{},HostIPs:[]HostIP{},},}
I0303 17:36:11.135611       1 types.go:751] [ControllerName] Verificando as anotações do pod default/low-priority-pod
I0303 17:36:11.135616       1 types.go:769] [ControllerName] Anotação 'controller' encontrada para o pod default/low-priority-pod: test-controller2
I0303 17:36:11.135620       1 scheduler.go:239] [OnAddPod] Atualizando métricas para o pod default/low-priority-pod
I0303 17:36:11.135624       1 types.go:751] [ControllerName] Verificando as anotações do pod default/low-priority-pod
I0303 17:36:11.135627       1 types.go:769] [ControllerName] Anotação 'controller' encontrada para o pod default/low-priority-pod: test-controller2
I0303 17:36:11.135633       1 scheduler.go:252] [OnAddPod] Pod default/low-priority-pod adicionado com sucesso
I0303 17:36:11.136254       1 scheduler.go:186] [PostBind] Chamado para pod low-priority-pod
I0303 17:36:11.136280       1 scheduler.go:204] [PostBind] Pod low-priority-pod - Início do binding: 2025-03-03 17:36:11.133430952 +0000 UTC m=+147.382032175, Fim do binding: 2025-03-03 17:36:11.13627675 +0000 UTC m=+147.384877983
I0303 17:36:11.136289       1 types.go:751] [ControllerName] Verificando as anotações do pod default/low-priority-pod
I0303 17:36:11.136294       1 types.go:769] [ControllerName] Anotação 'controller' encontrada para o pod default/low-priority-pod: test-controller2
I0303 17:36:11.136301       1 scheduler.go:211] [PostBind] Métricas atualizadas para o pod low-priority-pod
I0303 17:36:11.136529       1 scheduler.go:257] [OnUpdatePod] Iniciando processamento de atualização de pod
I0303 17:36:11.136620       1 scheduler.go:261] [OnUpdatePod] Pod atualizado detectado: default/low-priority-pod, Anotações: map[controller:test-controller2 kubectl.kubernetes.io/last-applied-configuration:{"apiVersion":"v1","kind":"Pod","metadata":{"annotations":{"controller":"test-controller2"},"labels":{"app":"test-app"},"name":"low-priority-pod","namespace":"default"},"spec":{"containers":[{"image":"nginx:latest","imagePullPolicy":"IfNotPresent","name":"nginx","resources":{"limits":{"cpu":"8000m","memory":"268Mi"},"requests":{"cpu":"8000m","memory":"268Mi"}}}],"priorityClassName":"free-priority","schedulerName":"custom-scheduler"}}
]
I0303 17:36:11.136648       1 scheduler.go:264] [OnUpdatePod] Comparando estado no Informer e estado real no cluster para o pod default/low-priority-pod
I0303 17:36:11.138080       1 scheduler.go:74] Estado no Informer: map[controller:test-controller2 kubectl.kubernetes.io/last-applied-configuration:{"apiVersion":"v1","kind":"Pod","metadata":{"annotations":{"controller":"test-controller2"},"labels":{"app":"test-app"},"name":"low-priority-pod","namespace":"default"},"spec":{"containers":[{"image":"nginx:latest","imagePullPolicy":"IfNotPresent","name":"nginx","resources":{"limits":{"cpu":"8000m","memory":"268Mi"},"requests":{"cpu":"8000m","memory":"268Mi"}}}],"priorityClassName":"free-priority","schedulerName":"custom-scheduler"}}
]
I0303 17:36:11.138098       1 scheduler.go:75] Estado real no cluster: map[controller:test-controller2 kubectl.kubernetes.io/last-applied-configuration:{"apiVersion":"v1","kind":"Pod","metadata":{"annotations":{"controller":"test-controller2"},"labels":{"app":"test-app"},"name":"low-priority-pod","namespace":"default"},"spec":{"containers":[{"image":"nginx:latest","imagePullPolicy":"IfNotPresent","name":"nginx","resources":{"limits":{"cpu":"8000m","memory":"268Mi"},"requests":{"cpu":"8000m","memory":"268Mi"}}}],"priorityClassName":"free-priority","schedulerName":"custom-scheduler"}}
]
I0303 17:36:11.138112       1 scheduler.go:274] [OnUpdatePod] Atualizando informações de métricas para o pod default/low-priority-pod
I0303 17:36:11.138116       1 types.go:751] [ControllerName] Verificando as anotações do pod default/low-priority-pod
I0303 17:36:11.138120       1 types.go:769] [ControllerName] Anotação 'controller' encontrada para o pod default/low-priority-pod: test-controller2
I0303 17:36:11.138125       1 scheduler.go:276] [OnUpdatePod] Atualizando 'LastStatus' do pod default/low-priority-pod nas métricas
I0303 17:36:11.138129       1 scheduler.go:278] [OnUpdatePod] Métrica atualizada para o pod default/low-priority-pod
I0303 17:36:11.138135       1 scheduler.go:282] [OnUpdatePod] Finalizando processamento de atualização de pod para default/low-priority-pod
I0303 17:36:11.144198       1 scheduler.go:257] [OnUpdatePod] Iniciando processamento de atualização de pod
I0303 17:36:11.144245       1 scheduler.go:261] [OnUpdatePod] Pod atualizado detectado: default/low-priority-pod, Anotações: map[controller:test-controller2 kubectl.kubernetes.io/last-applied-configuration:{"apiVersion":"v1","kind":"Pod","metadata":{"annotations":{"controller":"test-controller2"},"labels":{"app":"test-app"},"name":"low-priority-pod","namespace":"default"},"spec":{"containers":[{"image":"nginx:latest","imagePullPolicy":"IfNotPresent","name":"nginx","resources":{"limits":{"cpu":"8000m","memory":"268Mi"},"requests":{"cpu":"8000m","memory":"268Mi"}}}],"priorityClassName":"free-priority","schedulerName":"custom-scheduler"}}
]
I0303 17:36:11.144261       1 scheduler.go:264] [OnUpdatePod] Comparando estado no Informer e estado real no cluster para o pod default/low-priority-pod
I0303 17:36:11.145809       1 scheduler.go:74] Estado no Informer: map[controller:test-controller2 kubectl.kubernetes.io/last-applied-configuration:{"apiVersion":"v1","kind":"Pod","metadata":{"annotations":{"controller":"test-controller2"},"labels":{"app":"test-app"},"name":"low-priority-pod","namespace":"default"},"spec":{"containers":[{"image":"nginx:latest","imagePullPolicy":"IfNotPresent","name":"nginx","resources":{"limits":{"cpu":"8000m","memory":"268Mi"},"requests":{"cpu":"8000m","memory":"268Mi"}}}],"priorityClassName":"free-priority","schedulerName":"custom-scheduler"}}
]
I0303 17:36:11.145829       1 scheduler.go:75] Estado real no cluster: map[controller:test-controller2 kubectl.kubernetes.io/last-applied-configuration:{"apiVersion":"v1","kind":"Pod","metadata":{"annotations":{"controller":"test-controller2"},"labels":{"app":"test-app"},"name":"low-priority-pod","namespace":"default"},"spec":{"containers":[{"image":"nginx:latest","imagePullPolicy":"IfNotPresent","name":"nginx","resources":{"limits":{"cpu":"8000m","memory":"268Mi"},"requests":{"cpu":"8000m","memory":"268Mi"}}}],"priorityClassName":"free-priority","schedulerName":"custom-scheduler"}}
]
I0303 17:36:11.145836       1 scheduler.go:274] [OnUpdatePod] Atualizando informações de métricas para o pod default/low-priority-pod
I0303 17:36:11.145842       1 types.go:751] [ControllerName] Verificando as anotações do pod default/low-priority-pod
I0303 17:36:11.145846       1 types.go:769] [ControllerName] Anotação 'controller' encontrada para o pod default/low-priority-pod: test-controller2
I0303 17:36:11.145852       1 scheduler.go:276] [OnUpdatePod] Atualizando 'LastStatus' do pod default/low-priority-pod nas métricas
I0303 17:36:11.145855       1 scheduler.go:278] [OnUpdatePod] Métrica atualizada para o pod default/low-priority-pod
I0303 17:36:11.145863       1 scheduler.go:282] [OnUpdatePod] Finalizando processamento de atualização de pod para default/low-priority-pod
I0303 17:36:12.658943       1 scheduler.go:257] [OnUpdatePod] Iniciando processamento de atualização de pod
I0303 17:36:12.658995       1 scheduler.go:261] [OnUpdatePod] Pod atualizado detectado: default/low-priority-pod, Anotações: map[controller:test-controller2 kubectl.kubernetes.io/last-applied-configuration:{"apiVersion":"v1","kind":"Pod","metadata":{"annotations":{"controller":"test-controller2"},"labels":{"app":"test-app"},"name":"low-priority-pod","namespace":"default"},"spec":{"containers":[{"image":"nginx:latest","imagePullPolicy":"IfNotPresent","name":"nginx","resources":{"limits":{"cpu":"8000m","memory":"268Mi"},"requests":{"cpu":"8000m","memory":"268Mi"}}}],"priorityClassName":"free-priority","schedulerName":"custom-scheduler"}}
]
I0303 17:36:12.659009       1 scheduler.go:264] [OnUpdatePod] Comparando estado no Informer e estado real no cluster para o pod default/low-priority-pod
I0303 17:36:12.660559       1 scheduler.go:74] Estado no Informer: map[controller:test-controller2 kubectl.kubernetes.io/last-applied-configuration:{"apiVersion":"v1","kind":"Pod","metadata":{"annotations":{"controller":"test-controller2"},"labels":{"app":"test-app"},"name":"low-priority-pod","namespace":"default"},"spec":{"containers":[{"image":"nginx:latest","imagePullPolicy":"IfNotPresent","name":"nginx","resources":{"limits":{"cpu":"8000m","memory":"268Mi"},"requests":{"cpu":"8000m","memory":"268Mi"}}}],"priorityClassName":"free-priority","schedulerName":"custom-scheduler"}}
]
I0303 17:36:12.660579       1 scheduler.go:75] Estado real no cluster: map[controller:test-controller2 kubectl.kubernetes.io/last-applied-configuration:{"apiVersion":"v1","kind":"Pod","metadata":{"annotations":{"controller":"test-controller2"},"labels":{"app":"test-app"},"name":"low-priority-pod","namespace":"default"},"spec":{"containers":[{"image":"nginx:latest","imagePullPolicy":"IfNotPresent","name":"nginx","resources":{"limits":{"cpu":"8000m","memory":"268Mi"},"requests":{"cpu":"8000m","memory":"268Mi"}}}],"priorityClassName":"free-priority","schedulerName":"custom-scheduler"}}
]
I0303 17:36:12.660586       1 scheduler.go:274] [OnUpdatePod] Atualizando informações de métricas para o pod default/low-priority-pod
I0303 17:36:12.660592       1 types.go:751] [ControllerName] Verificando as anotações do pod default/low-priority-pod
I0303 17:36:12.660597       1 types.go:769] [ControllerName] Anotação 'controller' encontrada para o pod default/low-priority-pod: test-controller2
I0303 17:36:12.660604       1 scheduler.go:276] [OnUpdatePod] Atualizando 'LastStatus' do pod default/low-priority-pod nas métricas
I0303 17:36:12.660609       1 scheduler.go:278] [OnUpdatePod] Métrica atualizada para o pod default/low-priority-pod
I0303 17:36:12.660617       1 scheduler.go:282] [OnUpdatePod] Finalizando processamento de atualização de pod para default/low-priority-pod
I0303 17:37:09.842908       1 scheduler.go:219] [OnAddPod] Pod adicionado: default/high-priority-pod, Anotações: map[controller:test-controller kubectl.kubernetes.io/last-applied-configuration:{"apiVersion":"v1","kind":"Pod","metadata":{"annotations":{"controller":"test-controller"},"labels":{"app":"test-app"},"name":"high-priority-pod","namespace":"default"},"spec":{"containers":[{"image":"nginx:latest","imagePullPolicy":"IfNotPresent","name":"nginx","resources":{"limits":{"cpu":"8000m","memory":"268Mi"},"requests":{"cpu":"8000m","memory":"268Mi"}}}],"priorityClassName":"prod-priority","schedulerName":"custom-scheduler"}}
]
I0303 17:37:09.843030       1 default_preemption.go:25] "PostFilter called" pod="default/high-priority-pod"
I0303 17:37:09.843059       1 preemption.go:242] Lista de nós obtidaallNodes[&NodeInfo{Pods:[coredns-668d6bf9bc-tbzv9 custom-scheduler-8dcdbb8b5-2tv8d etcd-minikube kube-apiserver-minikube kube-controller-manager-minikube kube-proxy-hqbh2 kube-scheduler-minikube storage-provisioner low-priority-pod], RequestedResource:&framework.Resource{MilliCPU:8750, Memory:459276288, EphemeralStorage:0, AllowedPodNumber:0, ScalarResources:map[v1.ResourceName]int64(nil)}, NonZeroRequest: &framework.Resource{MilliCPU:9050, Memory:1717567488, EphemeralStorage:0, AllowedPodNumber:0, ScalarResources:map[v1.ResourceName]int64(nil)}, UsedPort: framework.HostPortInfo{}, AllocatableResource:&framework.Resource{MilliCPU:16000, Memory:33260965888, EphemeralStorage:30083776512, AllowedPodNumber:110, ScalarResources:map[v1.ResourceName]int64{"hugepages-1Gi":0, "hugepages-2Mi":0}}}]
I0303 17:37:09.843284       1 preemption.go:249] Número de candidatos encontradoscount0
I0303 17:37:09.843304       1 preemption.go:250] Mapa de status dos nósnodeToStatusMap&{map[] 0xc000a35380}
I0303 17:37:09.843316       1 preemption.go:259] "No preemption candidate is found; preemption is not helpful for scheduling" pod="default/high-priority-pod"
I0303 17:37:09.843327       1 default_preemption.go:34] "Preemption failed or not needed" pod="default/high-priority-pod" status="0/1 nodes are available: 1 Preemption is not helpful for scheduling."
I0303 17:37:09.844884       1 scheduler.go:74] Estado no Informer: map[controller:test-controller kubectl.kubernetes.io/last-applied-configuration:{"apiVersion":"v1","kind":"Pod","metadata":{"annotations":{"controller":"test-controller"},"labels":{"app":"test-app"},"name":"high-priority-pod","namespace":"default"},"spec":{"containers":[{"image":"nginx:latest","imagePullPolicy":"IfNotPresent","name":"nginx","resources":{"limits":{"cpu":"8000m","memory":"268Mi"},"requests":{"cpu":"8000m","memory":"268Mi"}}}],"priorityClassName":"prod-priority","schedulerName":"custom-scheduler"}}
]
I0303 17:37:09.844909       1 scheduler.go:75] Estado real no cluster: map[controller:test-controller kubectl.kubernetes.io/last-applied-configuration:{"apiVersion":"v1","kind":"Pod","metadata":{"annotations":{"controller":"test-controller"},"labels":{"app":"test-app"},"name":"high-priority-pod","namespace":"default"},"spec":{"containers":[{"image":"nginx:latest","imagePullPolicy":"IfNotPresent","name":"nginx","resources":{"limits":{"cpu":"8000m","memory":"268Mi"},"requests":{"cpu":"8000m","memory":"268Mi"}}}],"priorityClassName":"prod-priority","schedulerName":"custom-scheduler"}}
]
I0303 17:37:09.845092       1 scheduler.go:230] [OnAddPod] Adicionando pod default/high-priority-pod com os seguintes detalhes:
&Pod{ObjectMeta:{high-priority-pod  default  052284dd-274b-4584-a542-af1d3cd5d71d 54406 0 2025-03-03 17:37:09 +0000 UTC <nil> <nil> map[app:test-app] map[controller:test-controller kubectl.kubernetes.io/last-applied-configuration:{"apiVersion":"v1","kind":"Pod","metadata":{"annotations":{"controller":"test-controller"},"labels":{"app":"test-app"},"name":"high-priority-pod","namespace":"default"},"spec":{"containers":[{"image":"nginx:latest","imagePullPolicy":"IfNotPresent","name":"nginx","resources":{"limits":{"cpu":"8000m","memory":"268Mi"},"requests":{"cpu":"8000m","memory":"268Mi"}}}],"priorityClassName":"prod-priority","schedulerName":"custom-scheduler"}}
] [] [] [{kubectl-client-side-apply Update v1 2025-03-03 17:37:09 +0000 UTC FieldsV1 {"f:metadata":{"f:annotations":{".":{},"f:controller":{},"f:kubectl.kubernetes.io/last-applied-configuration":{}},"f:labels":{".":{},"f:app":{}}},"f:spec":{"f:containers":{"k:{\"name\":\"nginx\"}":{".":{},"f:image":{},"f:imagePullPolicy":{},"f:name":{},"f:resources":{".":{},"f:limits":{".":{},"f:cpu":{},"f:memory":{}},"f:requests":{".":{},"f:cpu":{},"f:memory":{}}},"f:terminationMessagePath":{},"f:terminationMessagePolicy":{}}},"f:dnsPolicy":{},"f:enableServiceLinks":{},"f:priorityClassName":{},"f:restartPolicy":{},"f:schedulerName":{},"f:securityContext":{},"f:terminationGracePeriodSeconds":{}}} }]},Spec:PodSpec{Volumes:[]Volume{Volume{Name:kube-api-access-lbbnq,VolumeSource:VolumeSource{HostPath:nil,EmptyDir:nil,GCEPersistentDisk:nil,AWSElasticBlockStore:nil,GitRepo:nil,Secret:nil,NFS:nil,ISCSI:nil,Glusterfs:nil,PersistentVolumeClaim:nil,RBD:nil,FlexVolume:nil,Cinder:nil,CephFS:nil,Flocker:nil,DownwardAPI:nil,FC:nil,AzureFile:nil,ConfigMap:nil,VsphereVolume:nil,Quobyte:nil,AzureDisk:nil,PhotonPersistentDisk:nil,PortworxVolume:nil,ScaleIO:nil,Projected:&ProjectedVolumeSource{Sources:[]VolumeProjection{VolumeProjection{Secret:nil,DownwardAPI:nil,ConfigMap:nil,ServiceAccountToken:&ServiceAccountTokenProjection{Audience:,ExpirationSeconds:*3607,Path:token,},ClusterTrustBundle:nil,},VolumeProjection{Secret:nil,DownwardAPI:nil,ConfigMap:&ConfigMapProjection{LocalObjectReference:LocalObjectReference{Name:kube-root-ca.crt,},Items:[]KeyToPath{KeyToPath{Key:ca.crt,Path:ca.crt,Mode:nil,},},Optional:nil,},ServiceAccountToken:nil,ClusterTrustBundle:nil,},VolumeProjection{Secret:nil,DownwardAPI:&DownwardAPIProjection{Items:[]DownwardAPIVolumeFile{DownwardAPIVolumeFile{Path:namespace,FieldRef:&ObjectFieldSelector{APIVersion:v1,FieldPath:metadata.namespace,},ResourceFieldRef:nil,Mode:nil,},},},ConfigMap:nil,ServiceAccountToken:nil,ClusterTrustBundle:nil,},},DefaultMode:*420,},StorageOS:nil,CSI:nil,Ephemeral:nil,Image:nil,},},},Containers:[]Container{Container{Name:nginx,Image:nginx:latest,Command:[],Args:[],WorkingDir:,Ports:[]ContainerPort{},Env:[]EnvVar{},Resources:ResourceRequirements{Limits:ResourceList{cpu: {{8 0} {<nil>} 8 DecimalSI},memory: {{281018368 0} {<nil>} 268Mi BinarySI},},Requests:ResourceList{cpu: {{8 0} {<nil>} 8 DecimalSI},memory: {{281018368 0} {<nil>} 268Mi BinarySI},},Claims:[]ResourceClaim{},},VolumeMounts:[]VolumeMount{VolumeMount{Name:kube-api-access-lbbnq,ReadOnly:true,MountPath:/var/run/secrets/kubernetes.io/serviceaccount,SubPath:,MountPropagation:nil,SubPathExpr:,RecursiveReadOnly:nil,},},LivenessProbe:nil,ReadinessProbe:nil,Lifecycle:nil,TerminationMessagePath:/dev/termination-log,ImagePullPolicy:IfNotPresent,SecurityContext:nil,Stdin:false,StdinOnce:false,TTY:false,EnvFrom:[]EnvFromSource{},TerminationMessagePolicy:File,VolumeDevices:[]VolumeDevice{},StartupProbe:nil,ResizePolicy:[]ContainerResizePolicy{},RestartPolicy:nil,},},RestartPolicy:Always,TerminationGracePeriodSeconds:*30,ActiveDeadlineSeconds:nil,DNSPolicy:ClusterFirst,NodeSelector:map[string]string{},ServiceAccountName:default,DeprecatedServiceAccount:default,NodeName:,HostNetwork:false,HostPID:false,HostIPC:false,SecurityContext:&PodSecurityContext{SELinuxOptions:nil,RunAsUser:nil,RunAsNonRoot:nil,SupplementalGroups:[],FSGroup:nil,RunAsGroup:nil,Sysctls:[]Sysctl{},WindowsOptions:nil,FSGroupChangePolicy:nil,SeccompProfile:nil,AppArmorProfile:nil,SupplementalGroupsPolicy:nil,SELinuxChangePolicy:nil,},ImagePullSecrets:[]LocalObjectReference{},Hostname:,Subdomain:,Affinity:nil,SchedulerName:custom-scheduler,InitContainers:[]Container{},AutomountServiceAccountToken:nil,Tolerations:[]Toleration{Toleration{Key:node.kubernetes.io/not-ready,Operator:Exists,Value:,Effect:NoExecute,TolerationSeconds:*300,},Toleration{Key:node.kubernetes.io/unreachable,Operator:Exists,Value:,Effect:NoExecute,TolerationSeconds:*300,},},HostAliases:[]HostAlias{},PriorityClassName:prod-priority,Priority:*11,DNSConfig:nil,ShareProcessNamespace:nil,ReadinessGates:[]PodReadinessGate{},RuntimeClassName:nil,EnableServiceLinks:*true,PreemptionPolicy:*PreemptLowerPriority,Overhead:ResourceList{},TopologySpreadConstraints:[]TopologySpreadConstraint{},EphemeralContainers:[]EphemeralContainer{},SetHostnameAsFQDN:nil,OS:nil,HostUsers:nil,SchedulingGates:[]PodSchedulingGate{},ResourceClaims:[]PodResourceClaim{},Resources:nil,},Status:PodStatus{Phase:Pending,Conditions:[]PodCondition{},Message:,Reason:,HostIP:,PodIP:,StartTime:<nil>,ContainerStatuses:[]ContainerStatus{},QOSClass:Guaranteed,InitContainerStatuses:[]ContainerStatus{},NominatedNodeName:,PodIPs:[]PodIP{},EphemeralContainerStatuses:[]ContainerStatus{},Resize:,ResourceClaimStatuses:[]PodResourceClaimStatus{},HostIPs:[]HostIP{},},}
I0303 17:37:09.845111       1 types.go:751] [ControllerName] Verificando as anotações do pod default/high-priority-pod
I0303 17:37:09.845116       1 types.go:769] [ControllerName] Anotação 'controller' encontrada para o pod default/high-priority-pod: test-controller
I0303 17:37:09.845125       1 scheduler.go:239] [OnAddPod] Atualizando métricas para o pod default/high-priority-pod
I0303 17:37:09.845129       1 types.go:751] [ControllerName] Verificando as anotações do pod default/high-priority-pod
I0303 17:37:09.845134       1 types.go:769] [ControllerName] Anotação 'controller' encontrada para o pod default/high-priority-pod: test-controller
I0303 17:37:09.845144       1 scheduler.go:252] [OnAddPod] Pod default/high-priority-pod adicionado com sucesso
I0303 17:37:09.850975       1 scheduler.go:257] [OnUpdatePod] Iniciando processamento de atualização de pod
I0303 17:37:09.851015       1 scheduler.go:261] [OnUpdatePod] Pod atualizado detectado: default/high-priority-pod, Anotações: map[controller:test-controller kubectl.kubernetes.io/last-applied-configuration:{"apiVersion":"v1","kind":"Pod","metadata":{"annotations":{"controller":"test-controller"},"labels":{"app":"test-app"},"name":"high-priority-pod","namespace":"default"},"spec":{"containers":[{"image":"nginx:latest","imagePullPolicy":"IfNotPresent","name":"nginx","resources":{"limits":{"cpu":"8000m","memory":"268Mi"},"requests":{"cpu":"8000m","memory":"268Mi"}}}],"priorityClassName":"prod-priority","schedulerName":"custom-scheduler"}}
]
I0303 17:37:09.851028       1 scheduler.go:264] [OnUpdatePod] Comparando estado no Informer e estado real no cluster para o pod default/high-priority-pod
I0303 17:37:09.852458       1 scheduler.go:74] Estado no Informer: map[controller:test-controller kubectl.kubernetes.io/last-applied-configuration:{"apiVersion":"v1","kind":"Pod","metadata":{"annotations":{"controller":"test-controller"},"labels":{"app":"test-app"},"name":"high-priority-pod","namespace":"default"},"spec":{"containers":[{"image":"nginx:latest","imagePullPolicy":"IfNotPresent","name":"nginx","resources":{"limits":{"cpu":"8000m","memory":"268Mi"},"requests":{"cpu":"8000m","memory":"268Mi"}}}],"priorityClassName":"prod-priority","schedulerName":"custom-scheduler"}}
]
I0303 17:37:09.852502       1 scheduler.go:75] Estado real no cluster: map[controller:test-controller kubectl.kubernetes.io/last-applied-configuration:{"apiVersion":"v1","kind":"Pod","metadata":{"annotations":{"controller":"test-controller"},"labels":{"app":"test-app"},"name":"high-priority-pod","namespace":"default"},"spec":{"containers":[{"image":"nginx:latest","imagePullPolicy":"IfNotPresent","name":"nginx","resources":{"limits":{"cpu":"8000m","memory":"268Mi"},"requests":{"cpu":"8000m","memory":"268Mi"}}}],"priorityClassName":"prod-priority","schedulerName":"custom-scheduler"}}
]
I0303 17:37:09.852511       1 scheduler.go:274] [OnUpdatePod] Atualizando informações de métricas para o pod default/high-priority-pod
I0303 17:37:09.852516       1 types.go:751] [ControllerName] Verificando as anotações do pod default/high-priority-pod
I0303 17:37:09.852520       1 types.go:769] [ControllerName] Anotação 'controller' encontrada para o pod default/high-priority-pod: test-controller
I0303 17:37:09.852525       1 scheduler.go:276] [OnUpdatePod] Atualizando 'LastStatus' do pod default/high-priority-pod nas métricas
I0303 17:37:09.852529       1 scheduler.go:278] [OnUpdatePod] Métrica atualizada para o pod default/high-priority-pod
I0303 17:37:09.852535       1 scheduler.go:282] [OnUpdatePod] Finalizando processamento de atualização de pod para default/high-priority-pod
I0303 17:37:44.553545       1 default_preemption.go:25] "PostFilter called" pod="default/high-priority-pod"
I0303 17:37:44.553581       1 preemption.go:242] Lista de nós obtidaallNodes[&NodeInfo{Pods:[coredns-668d6bf9bc-tbzv9 custom-scheduler-8dcdbb8b5-2tv8d etcd-minikube kube-apiserver-minikube kube-controller-manager-minikube kube-proxy-hqbh2 kube-scheduler-minikube storage-provisioner low-priority-pod], RequestedResource:&framework.Resource{MilliCPU:8750, Memory:459276288, EphemeralStorage:0, AllowedPodNumber:0, ScalarResources:map[v1.ResourceName]int64(nil)}, NonZeroRequest: &framework.Resource{MilliCPU:9050, Memory:1717567488, EphemeralStorage:0, AllowedPodNumber:0, ScalarResources:map[v1.ResourceName]int64(nil)}, UsedPort: framework.HostPortInfo{}, AllocatableResource:&framework.Resource{MilliCPU:16000, Memory:33260965888, EphemeralStorage:30083776512, AllowedPodNumber:110, ScalarResources:map[v1.ResourceName]int64{"hugepages-1Gi":0, "hugepages-2Mi":0}}}]
I0303 17:37:44.553720       1 preemption.go:249] Número de candidatos encontradoscount0
I0303 17:37:44.553739       1 preemption.go:250] Mapa de status dos nósnodeToStatusMap&{map[] 0xc000982b40}
I0303 17:37:44.553749       1 preemption.go:259] "No preemption candidate is found; preemption is not helpful for scheduling" pod="default/high-priority-pod"
I0303 17:37:44.553761       1 default_preemption.go:34] "Preemption failed or not needed" pod="default/high-priority-pod" status="0/1 nodes are available: 1 Preemption is not helpful for scheduling."
I0303 17:38:14.554470       1 default_preemption.go:25] "PostFilter called" pod="default/high-priority-pod"
I0303 17:38:14.554520       1 preemption.go:242] Lista de nós obtidaallNodes[&NodeInfo{Pods:[coredns-668d6bf9bc-tbzv9 custom-scheduler-8dcdbb8b5-2tv8d etcd-minikube kube-apiserver-minikube kube-controller-manager-minikube kube-proxy-hqbh2 kube-scheduler-minikube storage-provisioner low-priority-pod], RequestedResource:&framework.Resource{MilliCPU:8750, Memory:459276288, EphemeralStorage:0, AllowedPodNumber:0, ScalarResources:map[v1.ResourceName]int64(nil)}, NonZeroRequest: &framework.Resource{MilliCPU:9050, Memory:1717567488, EphemeralStorage:0, AllowedPodNumber:0, ScalarResources:map[v1.ResourceName]int64(nil)}, UsedPort: framework.HostPortInfo{}, AllocatableResource:&framework.Resource{MilliCPU:16000, Memory:33260965888, EphemeralStorage:30083776512, AllowedPodNumber:110, ScalarResources:map[v1.ResourceName]int64{"hugepages-1Gi":0, "hugepages-2Mi":0}}}]
I0303 17:38:14.554652       1 preemption.go:249] Número de candidatos encontradoscount0
I0303 17:38:14.554666       1 preemption.go:250] Mapa de status dos nósnodeToStatusMap&{map[] 0xc000c37940}
I0303 17:38:14.554675       1 preemption.go:259] "No preemption candidate is found; preemption is not helpful for scheduling" pod="default/high-priority-pod"
I0303 17:38:14.554685       1 default_preemption.go:34] "Preemption failed or not needed" pod="default/high-priority-pod" status="0/1 nodes are available: 1 Preemption is not helpful for scheduling."
I0303 17:38:44.554632       1 default_preemption.go:25] "PostFilter called" pod="default/high-priority-pod"
I0303 17:38:44.554657       1 preemption.go:242] Lista de nós obtidaallNodes[&NodeInfo{Pods:[coredns-668d6bf9bc-tbzv9 custom-scheduler-8dcdbb8b5-2tv8d etcd-minikube kube-apiserver-minikube kube-controller-manager-minikube kube-proxy-hqbh2 kube-scheduler-minikube storage-provisioner low-priority-pod], RequestedResource:&framework.Resource{MilliCPU:8750, Memory:459276288, EphemeralStorage:0, AllowedPodNumber:0, ScalarResources:map[v1.ResourceName]int64(nil)}, NonZeroRequest: &framework.Resource{MilliCPU:9050, Memory:1717567488, EphemeralStorage:0, AllowedPodNumber:0, ScalarResources:map[v1.ResourceName]int64(nil)}, UsedPort: framework.HostPortInfo{}, AllocatableResource:&framework.Resource{MilliCPU:16000, Memory:33260965888, EphemeralStorage:30083776512, AllowedPodNumber:110, ScalarResources:map[v1.ResourceName]int64{"hugepages-1Gi":0, "hugepages-2Mi":0}}}]
I0303 17:38:44.554818       1 preemption.go:249] Número de candidatos encontradoscount0
I0303 17:38:44.554834       1 preemption.go:250] Mapa de status dos nósnodeToStatusMap&{map[] 0xc000b08740}
I0303 17:38:44.554843       1 preemption.go:259] "No preemption candidate is found; preemption is not helpful for scheduling" pod="default/high-priority-pod"
I0303 17:38:44.554853       1 default_preemption.go:34] "Preemption failed or not needed" pod="default/high-priority-pod" status="0/1 nodes are available: 1 Preemption is not helpful for scheduling."
