I0205 12:06:54.205118       1 serving.go:386] Generated self-signed cert in-memory
W0205 12:06:54.205870       1 client_config.go:659] Neither --kubeconfig nor --master was specified.  Using the inClusterConfig.  This might not work.
I0205 12:06:54.596829       1 scheduler.go:214] [OnAddPod] Pod adicionado: kube-system/coredns-668d6bf9bc-d5rfg, Anotações: map[]
I0205 12:06:54.598562       1 scheduler.go:69] Estado no Informer: map[]
I0205 12:06:54.598590       1 scheduler.go:70] Estado real no cluster: map[]
I0205 12:06:54.598596       1 scheduler.go:220] [OnAddPod] Ignorando pod kube-system/coredns-668d6bf9bc-d5rfg pois pertence ao namespace kube-system
I0205 12:06:54.598637       1 scheduler.go:214] [OnAddPod] Pod adicionado: kube-system/custom-scheduler-8dcdbb8b5-xlc4v, Anotações: map[]
I0205 12:06:54.599875       1 scheduler.go:69] Estado no Informer: map[]
I0205 12:06:54.599895       1 scheduler.go:70] Estado real no cluster: map[]
I0205 12:06:54.599899       1 scheduler.go:220] [OnAddPod] Ignorando pod kube-system/custom-scheduler-8dcdbb8b5-xlc4v pois pertence ao namespace kube-system
I0205 12:06:54.599930       1 scheduler.go:214] [OnAddPod] Pod adicionado: kube-system/etcd-minikube, Anotações: map[kubeadm.kubernetes.io/etcd.advertise-client-urls:https://192.168.49.2:2379 kubernetes.io/config.hash:2b4b75c2a289008e0b381891e9683040 kubernetes.io/config.mirror:2b4b75c2a289008e0b381891e9683040 kubernetes.io/config.seen:2025-02-04T15:54:51.518019519Z kubernetes.io/config.source:file]
I0205 12:06:54.601396       1 scheduler.go:69] Estado no Informer: map[kubeadm.kubernetes.io/etcd.advertise-client-urls:https://192.168.49.2:2379 kubernetes.io/config.hash:2b4b75c2a289008e0b381891e9683040 kubernetes.io/config.mirror:2b4b75c2a289008e0b381891e9683040 kubernetes.io/config.seen:2025-02-04T15:54:51.518019519Z kubernetes.io/config.source:file]
I0205 12:06:54.601419       1 scheduler.go:70] Estado real no cluster: map[kubeadm.kubernetes.io/etcd.advertise-client-urls:https://192.168.49.2:2379 kubernetes.io/config.hash:2b4b75c2a289008e0b381891e9683040 kubernetes.io/config.mirror:2b4b75c2a289008e0b381891e9683040 kubernetes.io/config.seen:2025-02-04T15:54:51.518019519Z kubernetes.io/config.source:file]
I0205 12:06:54.601426       1 scheduler.go:220] [OnAddPod] Ignorando pod kube-system/etcd-minikube pois pertence ao namespace kube-system
I0205 12:06:54.601457       1 scheduler.go:214] [OnAddPod] Pod adicionado: kube-system/kube-apiserver-minikube, Anotações: map[kubeadm.kubernetes.io/kube-apiserver.advertise-address.endpoint:192.168.49.2:8443 kubernetes.io/config.hash:d72d0a4cf4be077c9919d46b7358a5e8 kubernetes.io/config.mirror:d72d0a4cf4be077c9919d46b7358a5e8 kubernetes.io/config.seen:2025-02-04T15:54:55.687286899Z kubernetes.io/config.source:file]
I0205 12:06:54.602633       1 scheduler.go:69] Estado no Informer: map[kubeadm.kubernetes.io/kube-apiserver.advertise-address.endpoint:192.168.49.2:8443 kubernetes.io/config.hash:d72d0a4cf4be077c9919d46b7358a5e8 kubernetes.io/config.mirror:d72d0a4cf4be077c9919d46b7358a5e8 kubernetes.io/config.seen:2025-02-04T15:54:55.687286899Z kubernetes.io/config.source:file]
I0205 12:06:54.602654       1 scheduler.go:70] Estado real no cluster: map[kubeadm.kubernetes.io/kube-apiserver.advertise-address.endpoint:192.168.49.2:8443 kubernetes.io/config.hash:d72d0a4cf4be077c9919d46b7358a5e8 kubernetes.io/config.mirror:d72d0a4cf4be077c9919d46b7358a5e8 kubernetes.io/config.seen:2025-02-04T15:54:55.687286899Z kubernetes.io/config.source:file]
I0205 12:06:54.602661       1 scheduler.go:220] [OnAddPod] Ignorando pod kube-system/kube-apiserver-minikube pois pertence ao namespace kube-system
I0205 12:06:54.602692       1 scheduler.go:214] [OnAddPod] Pod adicionado: kube-system/kube-controller-manager-minikube, Anotações: map[kubernetes.io/config.hash:843c74f7b3bc7d7040a05c31708a6a30 kubernetes.io/config.mirror:843c74f7b3bc7d7040a05c31708a6a30 kubernetes.io/config.seen:2025-02-04T15:54:55.687288679Z kubernetes.io/config.source:file]
I0205 12:06:54.604036       1 scheduler.go:69] Estado no Informer: map[kubernetes.io/config.hash:843c74f7b3bc7d7040a05c31708a6a30 kubernetes.io/config.mirror:843c74f7b3bc7d7040a05c31708a6a30 kubernetes.io/config.seen:2025-02-04T15:54:55.687288679Z kubernetes.io/config.source:file]
I0205 12:06:54.604067       1 scheduler.go:70] Estado real no cluster: map[kubernetes.io/config.hash:843c74f7b3bc7d7040a05c31708a6a30 kubernetes.io/config.mirror:843c74f7b3bc7d7040a05c31708a6a30 kubernetes.io/config.seen:2025-02-04T15:54:55.687288679Z kubernetes.io/config.source:file]
I0205 12:06:54.604075       1 scheduler.go:220] [OnAddPod] Ignorando pod kube-system/kube-controller-manager-minikube pois pertence ao namespace kube-system
I0205 12:06:54.604126       1 scheduler.go:214] [OnAddPod] Pod adicionado: kube-system/kube-proxy-w2kkv, Anotações: map[]
I0205 12:06:54.605516       1 scheduler.go:69] Estado no Informer: map[]
I0205 12:06:54.605535       1 scheduler.go:70] Estado real no cluster: map[]
I0205 12:06:54.605539       1 scheduler.go:220] [OnAddPod] Ignorando pod kube-system/kube-proxy-w2kkv pois pertence ao namespace kube-system
I0205 12:06:54.605588       1 scheduler.go:214] [OnAddPod] Pod adicionado: kube-system/kube-scheduler-minikube, Anotações: map[kubernetes.io/config.hash:d14ce008bee3a1f3bd7cf547688f9dfe kubernetes.io/config.mirror:d14ce008bee3a1f3bd7cf547688f9dfe kubernetes.io/config.seen:2025-02-04T15:54:51.518024909Z kubernetes.io/config.source:file]
I0205 12:06:54.606876       1 scheduler.go:69] Estado no Informer: map[kubernetes.io/config.hash:d14ce008bee3a1f3bd7cf547688f9dfe kubernetes.io/config.mirror:d14ce008bee3a1f3bd7cf547688f9dfe kubernetes.io/config.seen:2025-02-04T15:54:51.518024909Z kubernetes.io/config.source:file]
I0205 12:06:54.606897       1 scheduler.go:70] Estado real no cluster: map[kubernetes.io/config.hash:d14ce008bee3a1f3bd7cf547688f9dfe kubernetes.io/config.mirror:d14ce008bee3a1f3bd7cf547688f9dfe kubernetes.io/config.seen:2025-02-04T15:54:51.518024909Z kubernetes.io/config.source:file]
I0205 12:06:54.606904       1 scheduler.go:220] [OnAddPod] Ignorando pod kube-system/kube-scheduler-minikube pois pertence ao namespace kube-system
I0205 12:06:54.606927       1 scheduler.go:214] [OnAddPod] Pod adicionado: kube-system/metrics-server-7fbb699795-m84df, Anotações: map[]
I0205 12:06:54.608115       1 scheduler.go:69] Estado no Informer: map[]
I0205 12:06:54.608131       1 scheduler.go:70] Estado real no cluster: map[]
I0205 12:06:54.608135       1 scheduler.go:220] [OnAddPod] Ignorando pod kube-system/metrics-server-7fbb699795-m84df pois pertence ao namespace kube-system
I0205 12:06:54.608161       1 scheduler.go:214] [OnAddPod] Pod adicionado: kube-system/storage-provisioner, Anotações: map[kubectl.kubernetes.io/last-applied-configuration:{"apiVersion":"v1","kind":"Pod","metadata":{"annotations":{},"labels":{"addonmanager.kubernetes.io/mode":"Reconcile","integration-test":"storage-provisioner"},"name":"storage-provisioner","namespace":"kube-system"},"spec":{"containers":[{"command":["/storage-provisioner"],"image":"gcr.io/k8s-minikube/storage-provisioner:v5","imagePullPolicy":"IfNotPresent","name":"storage-provisioner","volumeMounts":[{"mountPath":"/tmp","name":"tmp"}]}],"hostNetwork":true,"serviceAccountName":"storage-provisioner","volumes":[{"hostPath":{"path":"/tmp","type":"Directory"},"name":"tmp"}]}}
]
I0205 12:06:54.609522       1 scheduler.go:69] Estado no Informer: map[kubectl.kubernetes.io/last-applied-configuration:{"apiVersion":"v1","kind":"Pod","metadata":{"annotations":{},"labels":{"addonmanager.kubernetes.io/mode":"Reconcile","integration-test":"storage-provisioner"},"name":"storage-provisioner","namespace":"kube-system"},"spec":{"containers":[{"command":["/storage-provisioner"],"image":"gcr.io/k8s-minikube/storage-provisioner:v5","imagePullPolicy":"IfNotPresent","name":"storage-provisioner","volumeMounts":[{"mountPath":"/tmp","name":"tmp"}]}],"hostNetwork":true,"serviceAccountName":"storage-provisioner","volumes":[{"hostPath":{"path":"/tmp","type":"Directory"},"name":"tmp"}]}}
]
I0205 12:06:54.609546       1 scheduler.go:70] Estado real no cluster: map[kubectl.kubernetes.io/last-applied-configuration:{"apiVersion":"v1","kind":"Pod","metadata":{"annotations":{},"labels":{"addonmanager.kubernetes.io/mode":"Reconcile","integration-test":"storage-provisioner"},"name":"storage-provisioner","namespace":"kube-system"},"spec":{"containers":[{"command":["/storage-provisioner"],"image":"gcr.io/k8s-minikube/storage-provisioner:v5","imagePullPolicy":"IfNotPresent","name":"storage-provisioner","volumeMounts":[{"mountPath":"/tmp","name":"tmp"}]}],"hostNetwork":true,"serviceAccountName":"storage-provisioner","volumes":[{"hostPath":{"path":"/tmp","type":"Directory"},"name":"tmp"}]}}
]
I0205 12:06:54.609552       1 scheduler.go:220] [OnAddPod] Ignorando pod kube-system/storage-provisioner pois pertence ao namespace kube-system
I0205 12:06:54.693615       1 scheduler.go:653] PodInformer sincronizado com sucesso
I0205 12:06:54.695623       1 server.go:167] "Starting Kubernetes Scheduler" version="v0.0.0-master+$Format:%H$"
I0205 12:06:54.695647       1 server.go:169] "Golang settings" GOGC="" GOMAXPROCS="" GOTRACEBACK=""
I0205 12:06:54.700759       1 requestheader_controller.go:172] Starting RequestHeaderAuthRequestController
I0205 12:06:54.700791       1 shared_informer.go:313] Waiting for caches to sync for RequestHeaderAuthRequestController
I0205 12:06:54.700782       1 configmap_cafile_content.go:205] "Starting controller" name="client-ca::kube-system::extension-apiserver-authentication::client-ca-file"
I0205 12:06:54.700803       1 shared_informer.go:313] Waiting for caches to sync for client-ca::kube-system::extension-apiserver-authentication::client-ca-file
I0205 12:06:54.700818       1 configmap_cafile_content.go:205] "Starting controller" name="client-ca::kube-system::extension-apiserver-authentication::requestheader-client-ca-file"
I0205 12:06:54.700836       1 shared_informer.go:313] Waiting for caches to sync for client-ca::kube-system::extension-apiserver-authentication::requestheader-client-ca-file
I0205 12:06:54.700840       1 secure_serving.go:213] Serving securely on [::]:10259
I0205 12:06:54.700913       1 tlsconfig.go:243] "Starting DynamicServingCertificateController"
I0205 12:06:54.801499       1 shared_informer.go:320] Caches are synced for client-ca::kube-system::extension-apiserver-authentication::client-ca-file
I0205 12:06:54.801502       1 shared_informer.go:320] Caches are synced for RequestHeaderAuthRequestController
I0205 12:06:54.801621       1 leaderelection.go:254] attempting to acquire leader lease kube-system/kube-scheduler...
I0205 12:06:54.801519       1 shared_informer.go:320] Caches are synced for client-ca::kube-system::extension-apiserver-authentication::requestheader-client-ca-file
I0205 12:06:54.810262       1 leaderelection.go:268] successfully acquired lease kube-system/kube-scheduler
I0205 12:11:41.722251       1 scheduler.go:214] [OnAddPod] Pod adicionado: default/onepending-58f8995468-qfdxk, Anotações: map[acceptablePreemptionOverhead:0.05 controller:onepending-controller qosMeasuring:independent slo:0.8]
I0205 12:11:41.722508       1 scheduler.go:145] [Reserve] resources reserved at node minikube for pod onepending-58f8995468-qfdxk_default at 2025-02-05 12:11:41.722499069 +0000 UTC m=+288.040502630
I0205 12:11:41.722543       1 types.go:749] [ControllerName] Verificando as anotações do pod default/onepending-58f8995468-qfdxk
I0205 12:11:41.722549       1 types.go:767] [ControllerName] Anotação 'controller' encontrada para o pod default/onepending-58f8995468-qfdxk: onepending-controller
I0205 12:11:41.727343       1 scheduler.go:69] Estado no Informer: map[acceptablePreemptionOverhead:0.05 controller:onepending-controller qosMeasuring:independent slo:0.8]
I0205 12:11:41.727375       1 scheduler.go:70] Estado real no cluster: map[acceptablePreemptionOverhead:0.05 controller:onepending-controller qosMeasuring:independent slo:0.8]
I0205 12:11:41.727623       1 scheduler.go:225] [OnAddPod] Adicionando pod default/onepending-58f8995468-qfdxk com os seguintes detalhes:
I0205 12:11:41.728207       1 scheduler.go:147] [Reserve] Status de alocação atual para o pod onepending-58f8995468-qfdxk_default: 
I0205 12:11:41.728228       1 scheduler.go:149] [Reserve] Status de alocação atualizado para o pod onepending-58f8995468-qfdxk_default: allocating
I0205 12:11:41.728322       1 types.go:749] [ControllerName] Verificando as anotações do pod default/onepending-58f8995468-qfdxk
I0205 12:11:41.728354       1 types.go:767] [ControllerName] Anotação 'controller' encontrada para o pod default/onepending-58f8995468-qfdxk: onepending-controller
I0205 12:11:41.728363       1 scheduler.go:234] [OnAddPod] Atualizando métricas para o pod default/onepending-58f8995468-qfdxk
I0205 12:11:41.728367       1 types.go:749] [ControllerName] Verificando as anotações do pod default/onepending-58f8995468-qfdxk
I0205 12:11:41.728371       1 types.go:767] [ControllerName] Anotação 'controller' encontrada para o pod default/onepending-58f8995468-qfdxk: onepending-controller
I0205 12:11:41.728382       1 scheduler.go:247] [OnAddPod] Pod default/onepending-58f8995468-qfdxk adicionado com sucesso
I0205 12:11:41.728389       1 postFilter.go:29] [PostFilter] PostFilter chamado para pod: default/onepending-58f8995468-cxvtf
I0205 12:11:41.728403       1 postFilter.go:76] Comparando pod original com o atualizado...
I0205 12:11:41.728404       1 scheduler.go:173] [PreBind] Validando o pod onepending-58f8995468-qfdxk antes de vincular ao node minikube
I0205 12:11:41.728426       1 scheduler.go:214] [OnAddPod] Pod adicionado: default/onepending-58f8995468-cxvtf, Anotações: map[acceptablePreemptionOverhead:0.05 controller:onepending-controller qosMeasuring:independent slo:0.8]
I0205 12:11:41.728409       1 postFilter.go:83] Successfully retrieved updated pod default/onepending-58f8995468-cxvtf from lister
I0205 12:11:41.730451       1 postFilter.go:226] [compareNodeResources] Recursos calculados no nó minikube: CPU = 8850 mCPU, Memória = 387973120 bytes
I0205 12:11:41.730483       1 postFilter.go:227] [compareNodeResources] Recursos do snapshot no nó minikube: CPU = 8850 mCPU, Memória = 387973120 bytes
I0205 12:11:41.730490       1 postFilter.go:233] [compareNodeResources] Recursos de CPU do nó minikube estão sincronizados: 8850 mCPU
I0205 12:11:41.730496       1 postFilter.go:239] [compareNodeResources] Recursos de memória do nó minikube estão sincronizados: 387973120 bytes
I0205 12:11:41.730611       1 scheduler.go:597] [GetControllerMetricInfo] Iniciando para o pod: default/onepending-58f8995468-qfdxk
I0205 12:11:41.730633       1 scheduler.go:602] [GetControllerMetricInfo] Obtendo o nome do controlador para o pod: default/onepending-58f8995468-qfdxk
I0205 12:11:41.730638       1 types.go:749] [ControllerName] Verificando as anotações do pod default/onepending-58f8995468-qfdxk
I0205 12:11:41.730643       1 types.go:767] [ControllerName] Anotação 'controller' encontrada para o pod default/onepending-58f8995468-qfdxk: onepending-controller
I0205 12:11:41.730664       1 scheduler.go:605] [GetControllerMetricInfo] Métricas do controlador definidas para o pod: default/onepending-58f8995468-qfdxk
I0205 12:11:41.730679       1 scheduler.go:83] [HigherPrecedence] Calculando precedência entre onepending-58f8995468-cxvtf e onepending-58f8995468-qfdxk
I0205 12:11:41.730684       1 scheduler.go:116] [WaitForPodsOnCache] Verificando se o pod onepending-58f8995468-cxvtf está no cache...
I0205 12:11:41.730689       1 scheduler.go:597] [GetControllerMetricInfo] Iniciando para o pod: default/onepending-58f8995468-cxvtf
I0205 12:11:41.730693       1 scheduler.go:602] [GetControllerMetricInfo] Obtendo o nome do controlador para o pod: default/onepending-58f8995468-cxvtf
I0205 12:11:41.730698       1 types.go:749] [ControllerName] Verificando as anotações do pod default/onepending-58f8995468-cxvtf
I0205 12:11:41.730702       1 types.go:767] [ControllerName] Anotação 'controller' encontrada para o pod default/onepending-58f8995468-cxvtf: onepending-controller
I0205 12:11:41.730707       1 scheduler.go:605] [GetControllerMetricInfo] Métricas do controlador definidas para o pod: default/onepending-58f8995468-cxvtf
W0205 12:11:41.730715       1 scheduler.go:124] [cacheMiss] Métricas não encontradas para o pod: default/onepending-58f8995468-cxvtf
I0205 12:11:41.731233       1 scheduler.go:69] Estado no Informer: map[acceptablePreemptionOverhead:0.05 controller:onepending-controller qosMeasuring:independent slo:0.8]
I0205 12:11:41.731267       1 scheduler.go:70] Estado real no cluster: map[acceptablePreemptionOverhead:0.05 controller:onepending-controller qosMeasuring:independent slo:0.8]
I0205 12:11:41.731447       1 scheduler.go:225] [OnAddPod] Adicionando pod default/onepending-58f8995468-cxvtf com os seguintes detalhes:
I0205 12:11:41.734898       1 scheduler.go:69] Estado no Informer: map[acceptablePreemptionOverhead:0.05 controller:onepending-controller qosMeasuring:independent slo:0.8]
I0205 12:11:41.734946       1 scheduler.go:70] Estado real no cluster: map[acceptablePreemptionOverhead:0.05 controller:onepending-controller qosMeasuring:independent slo:0.8]
W0205 12:11:41.734957       1 scheduler.go:134] [WaitForPodsOnCache] Pod onepending-58f8995468-cxvtf não encontrado no cache. Tentando novamente...
I0205 12:11:41.734994       1 types.go:749] [ControllerName] Verificando as anotações do pod default/onepending-58f8995468-cxvtf
I0205 12:11:41.735001       1 types.go:767] [ControllerName] Anotação 'controller' encontrada para o pod default/onepending-58f8995468-cxvtf: onepending-controller
I0205 12:11:41.735011       1 scheduler.go:234] [OnAddPod] Atualizando métricas para o pod default/onepending-58f8995468-cxvtf
I0205 12:11:41.735031       1 types.go:749] [ControllerName] Verificando as anotações do pod default/onepending-58f8995468-cxvtf
I0205 12:11:41.735036       1 types.go:767] [ControllerName] Anotação 'controller' encontrada para o pod default/onepending-58f8995468-cxvtf: onepending-controller
I0205 12:11:41.735055       1 scheduler.go:247] [OnAddPod] Pod default/onepending-58f8995468-cxvtf adicionado com sucesso
I0205 12:11:41.735061       1 scheduler.go:252] [OnUpdatePod] Iniciando processamento de atualização de pod
I0205 12:11:41.735080       1 scheduler.go:256] [OnUpdatePod] Pod atualizado detectado: default/onepending-58f8995468-qfdxk, Anotações: map[acceptablePreemptionOverhead:0.05 controller:onepending-controller qosMeasuring:independent slo:0.8]
I0205 12:11:41.735093       1 scheduler.go:259] [OnUpdatePod] Comparando estado no Informer e estado real no cluster para o pod default/onepending-58f8995468-qfdxk
I0205 12:11:41.735023       1 scheduler.go:181] [PostBind] Chamado para pod onepending-58f8995468-qfdxk
I0205 12:11:41.735119       1 scheduler.go:199] [PostBind] Pod onepending-58f8995468-qfdxk - Início do binding: 2025-02-05 12:11:41.728416248 +0000 UTC m=+288.046419799, Fim do binding: 2025-02-05 12:11:41.735113459 +0000 UTC m=+288.053117020
I0205 12:11:41.735150       1 types.go:749] [ControllerName] Verificando as anotações do pod default/onepending-58f8995468-qfdxk
I0205 12:11:41.735156       1 types.go:767] [ControllerName] Anotação 'controller' encontrada para o pod default/onepending-58f8995468-qfdxk: onepending-controller
I0205 12:11:41.735163       1 scheduler.go:206] [PostBind] Métricas atualizadas para o pod onepending-58f8995468-qfdxk
I0205 12:11:41.736971       1 scheduler.go:69] Estado no Informer: map[acceptablePreemptionOverhead:0.05 controller:onepending-controller qosMeasuring:independent slo:0.8]
I0205 12:11:41.737002       1 scheduler.go:70] Estado real no cluster: map[acceptablePreemptionOverhead:0.05 controller:onepending-controller qosMeasuring:independent slo:0.8]
I0205 12:11:41.737012       1 scheduler.go:269] [OnUpdatePod] Atualizando informações de métricas para o pod default/onepending-58f8995468-qfdxk
I0205 12:11:41.737018       1 types.go:749] [ControllerName] Verificando as anotações do pod default/onepending-58f8995468-qfdxk
I0205 12:11:41.737023       1 types.go:767] [ControllerName] Anotação 'controller' encontrada para o pod default/onepending-58f8995468-qfdxk: onepending-controller
I0205 12:11:41.737031       1 scheduler.go:271] [OnUpdatePod] Atualizando 'LastStatus' do pod default/onepending-58f8995468-qfdxk nas métricas
I0205 12:11:41.737035       1 scheduler.go:273] [OnUpdatePod] Métrica atualizada para o pod default/onepending-58f8995468-qfdxk
I0205 12:11:41.737044       1 scheduler.go:277] [OnUpdatePod] Finalizando processamento de atualização de pod para default/onepending-58f8995468-qfdxk
I0205 12:11:41.744892       1 scheduler.go:252] [OnUpdatePod] Iniciando processamento de atualização de pod
I0205 12:11:41.744944       1 scheduler.go:256] [OnUpdatePod] Pod atualizado detectado: default/onepending-58f8995468-qfdxk, Anotações: map[acceptablePreemptionOverhead:0.05 controller:onepending-controller qosMeasuring:independent slo:0.8]
I0205 12:11:41.744975       1 scheduler.go:259] [OnUpdatePod] Comparando estado no Informer e estado real no cluster para o pod default/onepending-58f8995468-qfdxk
I0205 12:11:41.748006       1 scheduler.go:69] Estado no Informer: map[acceptablePreemptionOverhead:0.05 controller:onepending-controller qosMeasuring:independent slo:0.8]
I0205 12:11:41.748044       1 scheduler.go:70] Estado real no cluster: map[acceptablePreemptionOverhead:0.05 controller:onepending-controller qosMeasuring:independent slo:0.8]
I0205 12:11:41.748055       1 scheduler.go:269] [OnUpdatePod] Atualizando informações de métricas para o pod default/onepending-58f8995468-qfdxk
I0205 12:11:41.748063       1 types.go:749] [ControllerName] Verificando as anotações do pod default/onepending-58f8995468-qfdxk
I0205 12:11:41.748068       1 types.go:767] [ControllerName] Anotação 'controller' encontrada para o pod default/onepending-58f8995468-qfdxk: onepending-controller
I0205 12:11:41.748077       1 scheduler.go:271] [OnUpdatePod] Atualizando 'LastStatus' do pod default/onepending-58f8995468-qfdxk nas métricas
I0205 12:11:41.748081       1 scheduler.go:273] [OnUpdatePod] Métrica atualizada para o pod default/onepending-58f8995468-qfdxk
I0205 12:11:41.748107       1 scheduler.go:277] [OnUpdatePod] Finalizando processamento de atualização de pod para default/onepending-58f8995468-qfdxk
I0205 12:11:41.835047       1 scheduler.go:597] [GetControllerMetricInfo] Iniciando para o pod: default/onepending-58f8995468-cxvtf
I0205 12:11:41.835084       1 scheduler.go:602] [GetControllerMetricInfo] Obtendo o nome do controlador para o pod: default/onepending-58f8995468-cxvtf
I0205 12:11:41.835089       1 types.go:749] [ControllerName] Verificando as anotações do pod default/onepending-58f8995468-cxvtf
I0205 12:11:41.835096       1 types.go:767] [ControllerName] Anotação 'controller' encontrada para o pod default/onepending-58f8995468-cxvtf: onepending-controller
I0205 12:11:41.835101       1 scheduler.go:605] [GetControllerMetricInfo] Métricas do controlador definidas para o pod: default/onepending-58f8995468-cxvtf
I0205 12:11:41.836995       1 scheduler.go:69] Estado no Informer: map[acceptablePreemptionOverhead:0.05 controller:onepending-controller qosMeasuring:independent slo:0.8]
I0205 12:11:41.837021       1 scheduler.go:70] Estado real no cluster: map[acceptablePreemptionOverhead:0.05 controller:onepending-controller qosMeasuring:independent slo:0.8]
I0205 12:11:41.837027       1 scheduler.go:138] [WaitForPodsOnCache] Pod onepending-58f8995468-cxvtf encontrado no cache.
I0205 12:11:41.837031       1 scheduler.go:116] [WaitForPodsOnCache] Verificando se o pod onepending-58f8995468-qfdxk está no cache...
I0205 12:11:41.837034       1 scheduler.go:597] [GetControllerMetricInfo] Iniciando para o pod: default/onepending-58f8995468-qfdxk
I0205 12:11:41.837038       1 scheduler.go:602] [GetControllerMetricInfo] Obtendo o nome do controlador para o pod: default/onepending-58f8995468-qfdxk
I0205 12:11:41.837041       1 types.go:749] [ControllerName] Verificando as anotações do pod default/onepending-58f8995468-qfdxk
I0205 12:11:41.837046       1 types.go:767] [ControllerName] Anotação 'controller' encontrada para o pod default/onepending-58f8995468-qfdxk: onepending-controller
I0205 12:11:41.837050       1 scheduler.go:605] [GetControllerMetricInfo] Métricas do controlador definidas para o pod: default/onepending-58f8995468-qfdxk
I0205 12:11:41.838877       1 scheduler.go:69] Estado no Informer: map[acceptablePreemptionOverhead:0.05 controller:onepending-controller qosMeasuring:independent slo:0.8]
I0205 12:11:41.838905       1 scheduler.go:70] Estado real no cluster: map[acceptablePreemptionOverhead:0.05 controller:onepending-controller qosMeasuring:independent slo:0.8]
I0205 12:11:41.838911       1 scheduler.go:138] [WaitForPodsOnCache] Pod onepending-58f8995468-qfdxk encontrado no cache.
I0205 12:11:41.838916       1 scheduler.go:597] [GetControllerMetricInfo] Iniciando para o pod: default/onepending-58f8995468-cxvtf
I0205 12:11:41.838920       1 scheduler.go:602] [GetControllerMetricInfo] Obtendo o nome do controlador para o pod: default/onepending-58f8995468-cxvtf
I0205 12:11:41.838924       1 types.go:749] [ControllerName] Verificando as anotações do pod default/onepending-58f8995468-cxvtf
I0205 12:11:41.838929       1 types.go:767] [ControllerName] Anotação 'controller' encontrada para o pod default/onepending-58f8995468-cxvtf: onepending-controller
I0205 12:11:41.838934       1 scheduler.go:605] [GetControllerMetricInfo] Métricas do controlador definidas para o pod: default/onepending-58f8995468-cxvtf
I0205 12:11:41.838941       1 scheduler.go:597] [GetControllerMetricInfo] Iniciando para o pod: default/onepending-58f8995468-qfdxk
I0205 12:11:41.838945       1 scheduler.go:602] [GetControllerMetricInfo] Obtendo o nome do controlador para o pod: default/onepending-58f8995468-qfdxk
I0205 12:11:41.838950       1 types.go:749] [ControllerName] Verificando as anotações do pod default/onepending-58f8995468-qfdxk
I0205 12:11:41.838954       1 types.go:767] [ControllerName] Anotação 'controller' encontrada para o pod default/onepending-58f8995468-qfdxk: onepending-controller
I0205 12:11:41.838958       1 scheduler.go:605] [GetControllerMetricInfo] Métricas do controlador definidas para o pod: default/onepending-58f8995468-qfdxk
I0205 12:11:41.838965       1 scheduler.go:97] [HigherPrecedence] Métricas para onepending-58f8995468-cxvtf: QoS = -3.130676, Importância = 0.80
I0205 12:11:41.838981       1 scheduler.go:98] [HigherPrecedence] Métricas para onepending-58f8995468-qfdxk: QoS = -0.742920, Importância = 0.80
I0205 12:11:41.838986       1 scheduler.go:109] [HigherPrecedence] Decisão final: onepending-58f8995468-cxvtf tem precedência sobre onepending-58f8995468-qfdxk? true
I0205 12:11:41.838990       1 types.go:749] [ControllerName] Verificando as anotações do pod default/onepending-58f8995468-cxvtf
I0205 12:11:41.839003       1 types.go:767] [ControllerName] Anotação 'controller' encontrada para o pod default/onepending-58f8995468-cxvtf: onepending-controller
I0205 12:11:41.839006       1 types.go:749] [ControllerName] Verificando as anotações do pod default/onepending-58f8995468-qfdxk
I0205 12:11:41.839009       1 types.go:767] [ControllerName] Anotação 'controller' encontrada para o pod default/onepending-58f8995468-qfdxk: onepending-controller
I0205 12:11:41.839013       1 scheduler.go:597] [GetControllerMetricInfo] Iniciando para o pod: default/onepending-58f8995468-qfdxk
I0205 12:11:41.839016       1 scheduler.go:602] [GetControllerMetricInfo] Obtendo o nome do controlador para o pod: default/onepending-58f8995468-qfdxk
I0205 12:11:41.839019       1 types.go:749] [ControllerName] Verificando as anotações do pod default/onepending-58f8995468-qfdxk
I0205 12:11:41.839023       1 types.go:767] [ControllerName] Anotação 'controller' encontrada para o pod default/onepending-58f8995468-qfdxk: onepending-controller
I0205 12:11:41.839027       1 scheduler.go:605] [GetControllerMetricInfo] Métricas do controlador definidas para o pod: default/onepending-58f8995468-qfdxk
I0205 12:11:41.839031       1 scheduler.go:597] [GetControllerMetricInfo] Iniciando para o pod: default/onepending-58f8995468-qfdxk
I0205 12:11:41.839034       1 scheduler.go:602] [GetControllerMetricInfo] Obtendo o nome do controlador para o pod: default/onepending-58f8995468-qfdxk
I0205 12:11:41.839037       1 types.go:749] [ControllerName] Verificando as anotações do pod default/onepending-58f8995468-qfdxk
I0205 12:11:41.839041       1 types.go:767] [ControllerName] Anotação 'controller' encontrada para o pod default/onepending-58f8995468-qfdxk: onepending-controller
I0205 12:11:41.839045       1 scheduler.go:605] [GetControllerMetricInfo] Métricas do controlador definidas para o pod: default/onepending-58f8995468-qfdxk
I0205 12:11:41.839049       1 types.go:749] [ControllerName] Verificando as anotações do pod default/onepending-58f8995468-qfdxk
I0205 12:11:41.839052       1 types.go:767] [ControllerName] Anotação 'controller' encontrada para o pod default/onepending-58f8995468-qfdxk: onepending-controller
I0205 12:11:41.839107       1 postFilter.go:144] [PREEMPT CALL] No node was chosen to allocate pod onepending-58f8995468-cxvtf
W0205 12:11:41.839119       1 postFilter.go:45] [PostFilter] Nenhum nó nominado após a preempção para o pod: default/onepending-58f8995468-cxvtf
I0205 12:11:41.845503       1 scheduler.go:252] [OnUpdatePod] Iniciando processamento de atualização de pod
I0205 12:11:41.845559       1 scheduler.go:256] [OnUpdatePod] Pod atualizado detectado: default/onepending-58f8995468-cxvtf, Anotações: map[acceptablePreemptionOverhead:0.05 controller:onepending-controller qosMeasuring:independent slo:0.8]
I0205 12:11:41.845576       1 scheduler.go:259] [OnUpdatePod] Comparando estado no Informer e estado real no cluster para o pod default/onepending-58f8995468-cxvtf
I0205 12:11:41.847295       1 scheduler.go:69] Estado no Informer: map[acceptablePreemptionOverhead:0.05 controller:onepending-controller qosMeasuring:independent slo:0.8]
I0205 12:11:41.847319       1 scheduler.go:70] Estado real no cluster: map[acceptablePreemptionOverhead:0.05 controller:onepending-controller qosMeasuring:independent slo:0.8]
I0205 12:11:41.847330       1 scheduler.go:269] [OnUpdatePod] Atualizando informações de métricas para o pod default/onepending-58f8995468-cxvtf
I0205 12:11:41.847338       1 types.go:749] [ControllerName] Verificando as anotações do pod default/onepending-58f8995468-cxvtf
I0205 12:11:41.847343       1 types.go:767] [ControllerName] Anotação 'controller' encontrada para o pod default/onepending-58f8995468-cxvtf: onepending-controller
I0205 12:11:41.847349       1 scheduler.go:271] [OnUpdatePod] Atualizando 'LastStatus' do pod default/onepending-58f8995468-cxvtf nas métricas
I0205 12:11:41.847353       1 scheduler.go:273] [OnUpdatePod] Métrica atualizada para o pod default/onepending-58f8995468-cxvtf
I0205 12:11:41.847360       1 scheduler.go:277] [OnUpdatePod] Finalizando processamento de atualização de pod para default/onepending-58f8995468-cxvtf
I0205 12:11:42.997953       1 postFilter.go:29] [PostFilter] PostFilter chamado para pod: default/onepending-58f8995468-cxvtf
I0205 12:11:42.997977       1 postFilter.go:76] Comparando pod original com o atualizado...
I0205 12:11:42.997984       1 postFilter.go:83] Successfully retrieved updated pod default/onepending-58f8995468-cxvtf from lister
I0205 12:11:43.000028       1 postFilter.go:226] [compareNodeResources] Recursos calculados no nó minikube: CPU = 8850 mCPU, Memória = 387973120 bytes
I0205 12:11:43.000051       1 postFilter.go:227] [compareNodeResources] Recursos do snapshot no nó minikube: CPU = 8850 mCPU, Memória = 387973120 bytes
I0205 12:11:43.000056       1 postFilter.go:233] [compareNodeResources] Recursos de CPU do nó minikube estão sincronizados: 8850 mCPU
I0205 12:11:43.000061       1 postFilter.go:239] [compareNodeResources] Recursos de memória do nó minikube estão sincronizados: 387973120 bytes
I0205 12:11:43.000200       1 scheduler.go:597] [GetControllerMetricInfo] Iniciando para o pod: default/onepending-58f8995468-qfdxk
I0205 12:11:43.000213       1 scheduler.go:602] [GetControllerMetricInfo] Obtendo o nome do controlador para o pod: default/onepending-58f8995468-qfdxk
I0205 12:11:43.000218       1 types.go:749] [ControllerName] Verificando as anotações do pod default/onepending-58f8995468-qfdxk
I0205 12:11:43.000222       1 types.go:767] [ControllerName] Anotação 'controller' encontrada para o pod default/onepending-58f8995468-qfdxk: onepending-controller
I0205 12:11:43.000227       1 scheduler.go:605] [GetControllerMetricInfo] Métricas do controlador definidas para o pod: default/onepending-58f8995468-qfdxk
I0205 12:11:43.000232       1 scheduler.go:83] [HigherPrecedence] Calculando precedência entre onepending-58f8995468-cxvtf e onepending-58f8995468-qfdxk
I0205 12:11:43.000236       1 scheduler.go:116] [WaitForPodsOnCache] Verificando se o pod onepending-58f8995468-cxvtf está no cache...
I0205 12:11:43.000239       1 scheduler.go:597] [GetControllerMetricInfo] Iniciando para o pod: default/onepending-58f8995468-cxvtf
I0205 12:11:43.000242       1 scheduler.go:602] [GetControllerMetricInfo] Obtendo o nome do controlador para o pod: default/onepending-58f8995468-cxvtf
I0205 12:11:43.000245       1 types.go:749] [ControllerName] Verificando as anotações do pod default/onepending-58f8995468-cxvtf
I0205 12:11:43.000248       1 types.go:767] [ControllerName] Anotação 'controller' encontrada para o pod default/onepending-58f8995468-cxvtf: onepending-controller
I0205 12:11:43.000251       1 scheduler.go:605] [GetControllerMetricInfo] Métricas do controlador definidas para o pod: default/onepending-58f8995468-cxvtf
I0205 12:11:43.002027       1 scheduler.go:69] Estado no Informer: map[acceptablePreemptionOverhead:0.05 controller:onepending-controller qosMeasuring:independent slo:0.8]
I0205 12:11:43.002056       1 scheduler.go:70] Estado real no cluster: map[acceptablePreemptionOverhead:0.05 controller:onepending-controller qosMeasuring:independent slo:0.8]
I0205 12:11:43.002062       1 scheduler.go:138] [WaitForPodsOnCache] Pod onepending-58f8995468-cxvtf encontrado no cache.
I0205 12:11:43.002066       1 scheduler.go:116] [WaitForPodsOnCache] Verificando se o pod onepending-58f8995468-qfdxk está no cache...
I0205 12:11:43.002069       1 scheduler.go:597] [GetControllerMetricInfo] Iniciando para o pod: default/onepending-58f8995468-qfdxk
I0205 12:11:43.002073       1 scheduler.go:602] [GetControllerMetricInfo] Obtendo o nome do controlador para o pod: default/onepending-58f8995468-qfdxk
I0205 12:11:43.002077       1 types.go:749] [ControllerName] Verificando as anotações do pod default/onepending-58f8995468-qfdxk
I0205 12:11:43.002081       1 types.go:767] [ControllerName] Anotação 'controller' encontrada para o pod default/onepending-58f8995468-qfdxk: onepending-controller
I0205 12:11:43.002085       1 scheduler.go:605] [GetControllerMetricInfo] Métricas do controlador definidas para o pod: default/onepending-58f8995468-qfdxk
I0205 12:11:43.003696       1 scheduler.go:69] Estado no Informer: map[acceptablePreemptionOverhead:0.05 controller:onepending-controller qosMeasuring:independent slo:0.8]
I0205 12:11:43.003723       1 scheduler.go:70] Estado real no cluster: map[acceptablePreemptionOverhead:0.05 controller:onepending-controller qosMeasuring:independent slo:0.8]
I0205 12:11:43.003728       1 scheduler.go:138] [WaitForPodsOnCache] Pod onepending-58f8995468-qfdxk encontrado no cache.
I0205 12:11:43.003732       1 scheduler.go:597] [GetControllerMetricInfo] Iniciando para o pod: default/onepending-58f8995468-cxvtf
I0205 12:11:43.003736       1 scheduler.go:602] [GetControllerMetricInfo] Obtendo o nome do controlador para o pod: default/onepending-58f8995468-cxvtf
I0205 12:11:43.003739       1 types.go:749] [ControllerName] Verificando as anotações do pod default/onepending-58f8995468-cxvtf
I0205 12:11:43.003743       1 types.go:767] [ControllerName] Anotação 'controller' encontrada para o pod default/onepending-58f8995468-cxvtf: onepending-controller
I0205 12:11:43.003747       1 scheduler.go:605] [GetControllerMetricInfo] Métricas do controlador definidas para o pod: default/onepending-58f8995468-cxvtf
I0205 12:11:43.003754       1 scheduler.go:597] [GetControllerMetricInfo] Iniciando para o pod: default/onepending-58f8995468-qfdxk
I0205 12:11:43.003760       1 scheduler.go:602] [GetControllerMetricInfo] Obtendo o nome do controlador para o pod: default/onepending-58f8995468-qfdxk
I0205 12:11:43.003762       1 types.go:749] [ControllerName] Verificando as anotações do pod default/onepending-58f8995468-qfdxk
I0205 12:11:43.003766       1 types.go:767] [ControllerName] Anotação 'controller' encontrada para o pod default/onepending-58f8995468-qfdxk: onepending-controller
I0205 12:11:43.003769       1 scheduler.go:605] [GetControllerMetricInfo] Métricas do controlador definidas para o pod: default/onepending-58f8995468-qfdxk
I0205 12:11:43.003776       1 scheduler.go:97] [HigherPrecedence] Métricas para onepending-58f8995468-cxvtf: QoS = -4.400229, Importância = 0.80
I0205 12:11:43.003790       1 scheduler.go:98] [HigherPrecedence] Métricas para onepending-58f8995468-qfdxk: QoS = -0.425532, Importância = 0.80
I0205 12:11:43.003795       1 scheduler.go:109] [HigherPrecedence] Decisão final: onepending-58f8995468-cxvtf tem precedência sobre onepending-58f8995468-qfdxk? true
I0205 12:11:43.003799       1 types.go:749] [ControllerName] Verificando as anotações do pod default/onepending-58f8995468-cxvtf
I0205 12:11:43.003803       1 types.go:767] [ControllerName] Anotação 'controller' encontrada para o pod default/onepending-58f8995468-cxvtf: onepending-controller
I0205 12:11:43.003806       1 types.go:749] [ControllerName] Verificando as anotações do pod default/onepending-58f8995468-qfdxk
I0205 12:11:43.003809       1 types.go:767] [ControllerName] Anotação 'controller' encontrada para o pod default/onepending-58f8995468-qfdxk: onepending-controller
I0205 12:11:43.003812       1 scheduler.go:597] [GetControllerMetricInfo] Iniciando para o pod: default/onepending-58f8995468-qfdxk
I0205 12:11:43.003815       1 scheduler.go:602] [GetControllerMetricInfo] Obtendo o nome do controlador para o pod: default/onepending-58f8995468-qfdxk
I0205 12:11:43.003818       1 types.go:749] [ControllerName] Verificando as anotações do pod default/onepending-58f8995468-qfdxk
I0205 12:11:43.003821       1 types.go:767] [ControllerName] Anotação 'controller' encontrada para o pod default/onepending-58f8995468-qfdxk: onepending-controller
I0205 12:11:43.003825       1 scheduler.go:605] [GetControllerMetricInfo] Métricas do controlador definidas para o pod: default/onepending-58f8995468-qfdxk
I0205 12:11:43.003828       1 scheduler.go:597] [GetControllerMetricInfo] Iniciando para o pod: default/onepending-58f8995468-qfdxk
I0205 12:11:43.003831       1 scheduler.go:602] [GetControllerMetricInfo] Obtendo o nome do controlador para o pod: default/onepending-58f8995468-qfdxk
I0205 12:11:43.003834       1 types.go:749] [ControllerName] Verificando as anotações do pod default/onepending-58f8995468-qfdxk
I0205 12:11:43.003837       1 types.go:767] [ControllerName] Anotação 'controller' encontrada para o pod default/onepending-58f8995468-qfdxk: onepending-controller
I0205 12:11:43.003840       1 scheduler.go:605] [GetControllerMetricInfo] Métricas do controlador definidas para o pod: default/onepending-58f8995468-qfdxk
I0205 12:11:43.003844       1 types.go:749] [ControllerName] Verificando as anotações do pod default/onepending-58f8995468-qfdxk
I0205 12:11:43.003847       1 types.go:767] [ControllerName] Anotação 'controller' encontrada para o pod default/onepending-58f8995468-qfdxk: onepending-controller
I0205 12:11:43.003878       1 postFilter.go:144] [PREEMPT CALL] No node was chosen to allocate pod onepending-58f8995468-cxvtf
W0205 12:11:43.003890       1 postFilter.go:45] [PostFilter] Nenhum nó nominado após a preempção para o pod: default/onepending-58f8995468-cxvtf
I0205 12:11:43.017602       1 scheduler.go:252] [OnUpdatePod] Iniciando processamento de atualização de pod
I0205 12:11:43.017641       1 scheduler.go:256] [OnUpdatePod] Pod atualizado detectado: default/onepending-58f8995468-qfdxk, Anotações: map[acceptablePreemptionOverhead:0.05 controller:onepending-controller qosMeasuring:independent slo:0.8]
I0205 12:11:43.017663       1 scheduler.go:259] [OnUpdatePod] Comparando estado no Informer e estado real no cluster para o pod default/onepending-58f8995468-qfdxk
I0205 12:11:43.019442       1 scheduler.go:69] Estado no Informer: map[acceptablePreemptionOverhead:0.05 controller:onepending-controller qosMeasuring:independent slo:0.8]
I0205 12:11:43.019473       1 scheduler.go:70] Estado real no cluster: map[acceptablePreemptionOverhead:0.05 controller:onepending-controller qosMeasuring:independent slo:0.8]
I0205 12:11:43.019484       1 scheduler.go:269] [OnUpdatePod] Atualizando informações de métricas para o pod default/onepending-58f8995468-qfdxk
I0205 12:11:43.019490       1 types.go:749] [ControllerName] Verificando as anotações do pod default/onepending-58f8995468-qfdxk
I0205 12:11:43.019495       1 types.go:767] [ControllerName] Anotação 'controller' encontrada para o pod default/onepending-58f8995468-qfdxk: onepending-controller
I0205 12:11:43.019503       1 scheduler.go:271] [OnUpdatePod] Atualizando 'LastStatus' do pod default/onepending-58f8995468-qfdxk nas métricas
I0205 12:11:43.019508       1 scheduler.go:273] [OnUpdatePod] Métrica atualizada para o pod default/onepending-58f8995468-qfdxk
I0205 12:11:43.019517       1 scheduler.go:277] [OnUpdatePod] Finalizando processamento de atualização de pod para default/onepending-58f8995468-qfdxk
I0205 12:11:54.815626       1 postFilter.go:29] [PostFilter] PostFilter chamado para pod: default/onepending-58f8995468-cxvtf
I0205 12:11:54.815654       1 postFilter.go:76] Comparando pod original com o atualizado...
I0205 12:11:54.815662       1 postFilter.go:83] Successfully retrieved updated pod default/onepending-58f8995468-cxvtf from lister
I0205 12:11:54.817919       1 postFilter.go:226] [compareNodeResources] Recursos calculados no nó minikube: CPU = 8850 mCPU, Memória = 387973120 bytes
I0205 12:11:54.817945       1 postFilter.go:227] [compareNodeResources] Recursos do snapshot no nó minikube: CPU = 8850 mCPU, Memória = 387973120 bytes
I0205 12:11:54.817951       1 postFilter.go:233] [compareNodeResources] Recursos de CPU do nó minikube estão sincronizados: 8850 mCPU
I0205 12:11:54.817965       1 postFilter.go:239] [compareNodeResources] Recursos de memória do nó minikube estão sincronizados: 387973120 bytes
I0205 12:11:54.818066       1 scheduler.go:597] [GetControllerMetricInfo] Iniciando para o pod: default/onepending-58f8995468-qfdxk
I0205 12:11:54.818083       1 scheduler.go:602] [GetControllerMetricInfo] Obtendo o nome do controlador para o pod: default/onepending-58f8995468-qfdxk
I0205 12:11:54.818088       1 types.go:749] [ControllerName] Verificando as anotações do pod default/onepending-58f8995468-qfdxk
I0205 12:11:54.818092       1 types.go:767] [ControllerName] Anotação 'controller' encontrada para o pod default/onepending-58f8995468-qfdxk: onepending-controller
I0205 12:11:54.818096       1 scheduler.go:605] [GetControllerMetricInfo] Métricas do controlador definidas para o pod: default/onepending-58f8995468-qfdxk
I0205 12:11:54.818101       1 scheduler.go:83] [HigherPrecedence] Calculando precedência entre onepending-58f8995468-cxvtf e onepending-58f8995468-qfdxk
I0205 12:11:54.818105       1 scheduler.go:116] [WaitForPodsOnCache] Verificando se o pod onepending-58f8995468-cxvtf está no cache...
I0205 12:11:54.818108       1 scheduler.go:597] [GetControllerMetricInfo] Iniciando para o pod: default/onepending-58f8995468-cxvtf
I0205 12:11:54.818111       1 scheduler.go:602] [GetControllerMetricInfo] Obtendo o nome do controlador para o pod: default/onepending-58f8995468-cxvtf
I0205 12:11:54.818114       1 types.go:749] [ControllerName] Verificando as anotações do pod default/onepending-58f8995468-cxvtf
I0205 12:11:54.818118       1 types.go:767] [ControllerName] Anotação 'controller' encontrada para o pod default/onepending-58f8995468-cxvtf: onepending-controller
I0205 12:11:54.818122       1 scheduler.go:605] [GetControllerMetricInfo] Métricas do controlador definidas para o pod: default/onepending-58f8995468-cxvtf
I0205 12:11:54.819808       1 scheduler.go:69] Estado no Informer: map[acceptablePreemptionOverhead:0.05 controller:onepending-controller qosMeasuring:independent slo:0.8]
I0205 12:11:54.819835       1 scheduler.go:70] Estado real no cluster: map[acceptablePreemptionOverhead:0.05 controller:onepending-controller qosMeasuring:independent slo:0.8]
I0205 12:11:54.819841       1 scheduler.go:138] [WaitForPodsOnCache] Pod onepending-58f8995468-cxvtf encontrado no cache.
I0205 12:11:54.819844       1 scheduler.go:116] [WaitForPodsOnCache] Verificando se o pod onepending-58f8995468-qfdxk está no cache...
I0205 12:11:54.819847       1 scheduler.go:597] [GetControllerMetricInfo] Iniciando para o pod: default/onepending-58f8995468-qfdxk
I0205 12:11:54.819851       1 scheduler.go:602] [GetControllerMetricInfo] Obtendo o nome do controlador para o pod: default/onepending-58f8995468-qfdxk
I0205 12:11:54.819854       1 types.go:749] [ControllerName] Verificando as anotações do pod default/onepending-58f8995468-qfdxk
I0205 12:11:54.819867       1 types.go:767] [ControllerName] Anotação 'controller' encontrada para o pod default/onepending-58f8995468-qfdxk: onepending-controller
I0205 12:11:54.819871       1 scheduler.go:605] [GetControllerMetricInfo] Métricas do controlador definidas para o pod: default/onepending-58f8995468-qfdxk
I0205 12:11:54.821690       1 scheduler.go:69] Estado no Informer: map[acceptablePreemptionOverhead:0.05 controller:onepending-controller qosMeasuring:independent slo:0.8]
I0205 12:11:54.821713       1 scheduler.go:70] Estado real no cluster: map[acceptablePreemptionOverhead:0.05 controller:onepending-controller qosMeasuring:independent slo:0.8]
I0205 12:11:54.821718       1 scheduler.go:138] [WaitForPodsOnCache] Pod onepending-58f8995468-qfdxk encontrado no cache.
I0205 12:11:54.821722       1 scheduler.go:597] [GetControllerMetricInfo] Iniciando para o pod: default/onepending-58f8995468-cxvtf
I0205 12:11:54.821725       1 scheduler.go:602] [GetControllerMetricInfo] Obtendo o nome do controlador para o pod: default/onepending-58f8995468-cxvtf
I0205 12:11:54.821729       1 types.go:749] [ControllerName] Verificando as anotações do pod default/onepending-58f8995468-cxvtf
I0205 12:11:54.821733       1 types.go:767] [ControllerName] Anotação 'controller' encontrada para o pod default/onepending-58f8995468-cxvtf: onepending-controller
I0205 12:11:54.821737       1 scheduler.go:605] [GetControllerMetricInfo] Métricas do controlador definidas para o pod: default/onepending-58f8995468-cxvtf
I0205 12:11:54.821743       1 scheduler.go:597] [GetControllerMetricInfo] Iniciando para o pod: default/onepending-58f8995468-qfdxk
I0205 12:11:54.821746       1 scheduler.go:602] [GetControllerMetricInfo] Obtendo o nome do controlador para o pod: default/onepending-58f8995468-qfdxk
I0205 12:11:54.821749       1 types.go:749] [ControllerName] Verificando as anotações do pod default/onepending-58f8995468-qfdxk
I0205 12:11:54.821753       1 types.go:767] [ControllerName] Anotação 'controller' encontrada para o pod default/onepending-58f8995468-qfdxk: onepending-controller
I0205 12:11:54.821757       1 scheduler.go:605] [GetControllerMetricInfo] Métricas do controlador definidas para o pod: default/onepending-58f8995468-qfdxk
I0205 12:11:54.821770       1 scheduler.go:97] [HigherPrecedence] Métricas para onepending-58f8995468-cxvtf: QoS = -16.218099, Importância = 0.80
I0205 12:11:54.821786       1 scheduler.go:98] [HigherPrecedence] Métricas para onepending-58f8995468-qfdxk: QoS = 2.528936, Importância = 0.80
I0205 12:11:54.821791       1 scheduler.go:109] [HigherPrecedence] Decisão final: onepending-58f8995468-cxvtf tem precedência sobre onepending-58f8995468-qfdxk? true
I0205 12:11:54.821795       1 types.go:749] [ControllerName] Verificando as anotações do pod default/onepending-58f8995468-cxvtf
I0205 12:11:54.821798       1 types.go:767] [ControllerName] Anotação 'controller' encontrada para o pod default/onepending-58f8995468-cxvtf: onepending-controller
I0205 12:11:54.821801       1 types.go:749] [ControllerName] Verificando as anotações do pod default/onepending-58f8995468-qfdxk
I0205 12:11:54.821805       1 types.go:767] [ControllerName] Anotação 'controller' encontrada para o pod default/onepending-58f8995468-qfdxk: onepending-controller
I0205 12:11:54.821808       1 scheduler.go:597] [GetControllerMetricInfo] Iniciando para o pod: default/onepending-58f8995468-qfdxk
I0205 12:11:54.821812       1 scheduler.go:602] [GetControllerMetricInfo] Obtendo o nome do controlador para o pod: default/onepending-58f8995468-qfdxk
I0205 12:11:54.821815       1 types.go:749] [ControllerName] Verificando as anotações do pod default/onepending-58f8995468-qfdxk
I0205 12:11:54.821819       1 types.go:767] [ControllerName] Anotação 'controller' encontrada para o pod default/onepending-58f8995468-qfdxk: onepending-controller
I0205 12:11:54.821823       1 scheduler.go:605] [GetControllerMetricInfo] Métricas do controlador definidas para o pod: default/onepending-58f8995468-qfdxk
I0205 12:11:54.821826       1 scheduler.go:597] [GetControllerMetricInfo] Iniciando para o pod: default/onepending-58f8995468-qfdxk
I0205 12:11:54.821830       1 scheduler.go:602] [GetControllerMetricInfo] Obtendo o nome do controlador para o pod: default/onepending-58f8995468-qfdxk
I0205 12:11:54.821833       1 types.go:749] [ControllerName] Verificando as anotações do pod default/onepending-58f8995468-qfdxk
I0205 12:11:54.821836       1 types.go:767] [ControllerName] Anotação 'controller' encontrada para o pod default/onepending-58f8995468-qfdxk: onepending-controller
I0205 12:11:54.821840       1 scheduler.go:605] [GetControllerMetricInfo] Métricas do controlador definidas para o pod: default/onepending-58f8995468-qfdxk
I0205 12:11:54.821844       1 types.go:749] [ControllerName] Verificando as anotações do pod default/onepending-58f8995468-qfdxk
I0205 12:11:54.821848       1 types.go:767] [ControllerName] Anotação 'controller' encontrada para o pod default/onepending-58f8995468-qfdxk: onepending-controller
I0205 12:11:54.821882       1 postFilter.go:144] [PREEMPT CALL] No node was chosen to allocate pod onepending-58f8995468-cxvtf
W0205 12:11:54.821894       1 postFilter.go:45] [PostFilter] Nenhum nó nominado após a preempção para o pod: default/onepending-58f8995468-cxvtf
I0205 12:12:24.816540       1 postFilter.go:29] [PostFilter] PostFilter chamado para pod: default/onepending-58f8995468-cxvtf
I0205 12:12:24.816564       1 postFilter.go:76] Comparando pod original com o atualizado...
I0205 12:12:24.816570       1 postFilter.go:83] Successfully retrieved updated pod default/onepending-58f8995468-cxvtf from lister
I0205 12:12:24.818522       1 postFilter.go:226] [compareNodeResources] Recursos calculados no nó minikube: CPU = 8850 mCPU, Memória = 387973120 bytes
I0205 12:12:24.818540       1 postFilter.go:227] [compareNodeResources] Recursos do snapshot no nó minikube: CPU = 8850 mCPU, Memória = 387973120 bytes
I0205 12:12:24.818545       1 postFilter.go:233] [compareNodeResources] Recursos de CPU do nó minikube estão sincronizados: 8850 mCPU
I0205 12:12:24.818550       1 postFilter.go:239] [compareNodeResources] Recursos de memória do nó minikube estão sincronizados: 387973120 bytes
I0205 12:12:24.818665       1 scheduler.go:597] [GetControllerMetricInfo] Iniciando para o pod: default/onepending-58f8995468-qfdxk
I0205 12:12:24.818688       1 scheduler.go:602] [GetControllerMetricInfo] Obtendo o nome do controlador para o pod: default/onepending-58f8995468-qfdxk
I0205 12:12:24.818692       1 types.go:749] [ControllerName] Verificando as anotações do pod default/onepending-58f8995468-qfdxk
I0205 12:12:24.818696       1 types.go:767] [ControllerName] Anotação 'controller' encontrada para o pod default/onepending-58f8995468-qfdxk: onepending-controller
I0205 12:12:24.818701       1 scheduler.go:605] [GetControllerMetricInfo] Métricas do controlador definidas para o pod: default/onepending-58f8995468-qfdxk
I0205 12:12:24.818705       1 scheduler.go:83] [HigherPrecedence] Calculando precedência entre onepending-58f8995468-cxvtf e onepending-58f8995468-qfdxk
I0205 12:12:24.818709       1 scheduler.go:116] [WaitForPodsOnCache] Verificando se o pod onepending-58f8995468-cxvtf está no cache...
I0205 12:12:24.818712       1 scheduler.go:597] [GetControllerMetricInfo] Iniciando para o pod: default/onepending-58f8995468-cxvtf
I0205 12:12:24.818715       1 scheduler.go:602] [GetControllerMetricInfo] Obtendo o nome do controlador para o pod: default/onepending-58f8995468-cxvtf
I0205 12:12:24.818718       1 types.go:749] [ControllerName] Verificando as anotações do pod default/onepending-58f8995468-cxvtf
I0205 12:12:24.818721       1 types.go:767] [ControllerName] Anotação 'controller' encontrada para o pod default/onepending-58f8995468-cxvtf: onepending-controller
I0205 12:12:24.818725       1 scheduler.go:605] [GetControllerMetricInfo] Métricas do controlador definidas para o pod: default/onepending-58f8995468-cxvtf
I0205 12:12:24.820312       1 scheduler.go:69] Estado no Informer: map[acceptablePreemptionOverhead:0.05 controller:onepending-controller qosMeasuring:independent slo:0.8]
I0205 12:12:24.820338       1 scheduler.go:70] Estado real no cluster: map[acceptablePreemptionOverhead:0.05 controller:onepending-controller qosMeasuring:independent slo:0.8]
I0205 12:12:24.820344       1 scheduler.go:138] [WaitForPodsOnCache] Pod onepending-58f8995468-cxvtf encontrado no cache.
I0205 12:12:24.820348       1 scheduler.go:116] [WaitForPodsOnCache] Verificando se o pod onepending-58f8995468-qfdxk está no cache...
I0205 12:12:24.820351       1 scheduler.go:597] [GetControllerMetricInfo] Iniciando para o pod: default/onepending-58f8995468-qfdxk
I0205 12:12:24.820355       1 scheduler.go:602] [GetControllerMetricInfo] Obtendo o nome do controlador para o pod: default/onepending-58f8995468-qfdxk
I0205 12:12:24.820358       1 types.go:749] [ControllerName] Verificando as anotações do pod default/onepending-58f8995468-qfdxk
I0205 12:12:24.820362       1 types.go:767] [ControllerName] Anotação 'controller' encontrada para o pod default/onepending-58f8995468-qfdxk: onepending-controller
I0205 12:12:24.820366       1 scheduler.go:605] [GetControllerMetricInfo] Métricas do controlador definidas para o pod: default/onepending-58f8995468-qfdxk
I0205 12:12:24.821758       1 scheduler.go:69] Estado no Informer: map[acceptablePreemptionOverhead:0.05 controller:onepending-controller qosMeasuring:independent slo:0.8]
I0205 12:12:24.821796       1 scheduler.go:70] Estado real no cluster: map[acceptablePreemptionOverhead:0.05 controller:onepending-controller qosMeasuring:independent slo:0.8]
I0205 12:12:24.821805       1 scheduler.go:138] [WaitForPodsOnCache] Pod onepending-58f8995468-qfdxk encontrado no cache.
I0205 12:12:24.821811       1 scheduler.go:597] [GetControllerMetricInfo] Iniciando para o pod: default/onepending-58f8995468-cxvtf
I0205 12:12:24.821817       1 scheduler.go:602] [GetControllerMetricInfo] Obtendo o nome do controlador para o pod: default/onepending-58f8995468-cxvtf
I0205 12:12:24.821822       1 types.go:749] [ControllerName] Verificando as anotações do pod default/onepending-58f8995468-cxvtf
I0205 12:12:24.821827       1 types.go:767] [ControllerName] Anotação 'controller' encontrada para o pod default/onepending-58f8995468-cxvtf: onepending-controller
I0205 12:12:24.821834       1 scheduler.go:605] [GetControllerMetricInfo] Métricas do controlador definidas para o pod: default/onepending-58f8995468-cxvtf
I0205 12:12:24.821853       1 scheduler.go:597] [GetControllerMetricInfo] Iniciando para o pod: default/onepending-58f8995468-qfdxk
I0205 12:12:24.821871       1 scheduler.go:602] [GetControllerMetricInfo] Obtendo o nome do controlador para o pod: default/onepending-58f8995468-qfdxk
I0205 12:12:24.821875       1 types.go:749] [ControllerName] Verificando as anotações do pod default/onepending-58f8995468-qfdxk
I0205 12:12:24.821879       1 types.go:767] [ControllerName] Anotação 'controller' encontrada para o pod default/onepending-58f8995468-qfdxk: onepending-controller
I0205 12:12:24.821885       1 scheduler.go:605] [GetControllerMetricInfo] Métricas do controlador definidas para o pod: default/onepending-58f8995468-qfdxk
I0205 12:12:24.821904       1 scheduler.go:97] [HigherPrecedence] Métricas para onepending-58f8995468-cxvtf: QoS = -46.218703, Importância = 0.80
I0205 12:12:24.821923       1 scheduler.go:98] [HigherPrecedence] Métricas para onepending-58f8995468-qfdxk: QoS = 10.029087, Importância = 0.80
I0205 12:12:24.821930       1 scheduler.go:109] [HigherPrecedence] Decisão final: onepending-58f8995468-cxvtf tem precedência sobre onepending-58f8995468-qfdxk? true
I0205 12:12:24.821936       1 types.go:749] [ControllerName] Verificando as anotações do pod default/onepending-58f8995468-cxvtf
I0205 12:12:24.821941       1 types.go:767] [ControllerName] Anotação 'controller' encontrada para o pod default/onepending-58f8995468-cxvtf: onepending-controller
I0205 12:12:24.821945       1 types.go:749] [ControllerName] Verificando as anotações do pod default/onepending-58f8995468-qfdxk
I0205 12:12:24.821949       1 types.go:767] [ControllerName] Anotação 'controller' encontrada para o pod default/onepending-58f8995468-qfdxk: onepending-controller
I0205 12:12:24.821955       1 scheduler.go:597] [GetControllerMetricInfo] Iniciando para o pod: default/onepending-58f8995468-qfdxk
I0205 12:12:24.821959       1 scheduler.go:602] [GetControllerMetricInfo] Obtendo o nome do controlador para o pod: default/onepending-58f8995468-qfdxk
I0205 12:12:24.821964       1 types.go:749] [ControllerName] Verificando as anotações do pod default/onepending-58f8995468-qfdxk
I0205 12:12:24.821968       1 types.go:767] [ControllerName] Anotação 'controller' encontrada para o pod default/onepending-58f8995468-qfdxk: onepending-controller
I0205 12:12:24.821973       1 scheduler.go:605] [GetControllerMetricInfo] Métricas do controlador definidas para o pod: default/onepending-58f8995468-qfdxk
I0205 12:12:24.821978       1 scheduler.go:597] [GetControllerMetricInfo] Iniciando para o pod: default/onepending-58f8995468-qfdxk
I0205 12:12:24.821983       1 scheduler.go:602] [GetControllerMetricInfo] Obtendo o nome do controlador para o pod: default/onepending-58f8995468-qfdxk
I0205 12:12:24.821987       1 types.go:749] [ControllerName] Verificando as anotações do pod default/onepending-58f8995468-qfdxk
I0205 12:12:24.821991       1 types.go:767] [ControllerName] Anotação 'controller' encontrada para o pod default/onepending-58f8995468-qfdxk: onepending-controller
I0205 12:12:24.821995       1 scheduler.go:605] [GetControllerMetricInfo] Métricas do controlador definidas para o pod: default/onepending-58f8995468-qfdxk
I0205 12:12:24.822006       1 types.go:749] [ControllerName] Verificando as anotações do pod default/onepending-58f8995468-qfdxk
I0205 12:12:24.822010       1 types.go:767] [ControllerName] Anotação 'controller' encontrada para o pod default/onepending-58f8995468-qfdxk: onepending-controller
I0205 12:12:24.822083       1 scheduler.go:597] [GetControllerMetricInfo] Iniciando para o pod: default/onepending-58f8995468-qfdxk
I0205 12:12:24.822099       1 scheduler.go:602] [GetControllerMetricInfo] Obtendo o nome do controlador para o pod: default/onepending-58f8995468-qfdxk
I0205 12:12:24.822102       1 types.go:749] [ControllerName] Verificando as anotações do pod default/onepending-58f8995468-qfdxk
I0205 12:12:24.822105       1 types.go:767] [ControllerName] Anotação 'controller' encontrada para o pod default/onepending-58f8995468-qfdxk: onepending-controller
I0205 12:12:24.822109       1 scheduler.go:605] [GetControllerMetricInfo] Métricas do controlador definidas para o pod: default/onepending-58f8995468-qfdxk
I0205 12:12:24.822115       1 scheduler.go:597] [GetControllerMetricInfo] Iniciando para o pod: default/onepending-58f8995468-qfdxk
I0205 12:12:24.822118       1 scheduler.go:602] [GetControllerMetricInfo] Obtendo o nome do controlador para o pod: default/onepending-58f8995468-qfdxk
I0205 12:12:24.822122       1 types.go:749] [ControllerName] Verificando as anotações do pod default/onepending-58f8995468-qfdxk
I0205 12:12:24.822126       1 types.go:767] [ControllerName] Anotação 'controller' encontrada para o pod default/onepending-58f8995468-qfdxk: onepending-controller
I0205 12:12:24.822137       1 scheduler.go:605] [GetControllerMetricInfo] Métricas do controlador definidas para o pod: default/onepending-58f8995468-qfdxk
I0205 12:12:24.822150       1 postFilter.go:147] [PREEMPT CALL] The node minikube  was chosen to allocate pod onepending-58f8995468-cxvtf
I0205 12:12:24.822164       1 postFilter.go:151] [Preempt] Iniciando a remoção dos pods preemptados no nó minikube para alocar o pod default/onepending-58f8995468-cxvtf. Total de vítimas: 1
I0205 12:12:24.822172       1 postFilter.go:155] [Preempt] Tentando remover o pod default/onepending-58f8995468-qfdxk no nó minikube
I0205 12:12:24.827891       1 scheduler.go:252] [OnUpdatePod] Iniciando processamento de atualização de pod
I0205 12:12:24.827930       1 scheduler.go:256] [OnUpdatePod] Pod atualizado detectado: default/onepending-58f8995468-qfdxk, Anotações: map[acceptablePreemptionOverhead:0.05 controller:onepending-controller qosMeasuring:independent slo:0.8]
I0205 12:12:24.827943       1 scheduler.go:259] [OnUpdatePod] Comparando estado no Informer e estado real no cluster para o pod default/onepending-58f8995468-qfdxk
I0205 12:12:24.829880       1 postFilter.go:161] [Preempt] Pod default/onepending-58f8995468-qfdxk removido com sucesso no nó minikube
I0205 12:12:24.829907       1 postFilter.go:167] onepending-58f8995468-qfdxk_default preempted by onepending-58f8995468-cxvtf_default on node minikube
E0205 12:12:24.829905       1 scheduler.go:66] Erro ao buscar estado real do pod onepending-58f8995468-qfdxk: pods "onepending-58f8995468-qfdxk" not found
I0205 12:12:24.829930       1 scheduler.go:269] [OnUpdatePod] Atualizando informações de métricas para o pod default/onepending-58f8995468-qfdxk
I0205 12:12:24.829938       1 types.go:749] [ControllerName] Verificando as anotações do pod default/onepending-58f8995468-qfdxk
I0205 12:12:24.829945       1 types.go:767] [ControllerName] Anotação 'controller' encontrada para o pod default/onepending-58f8995468-qfdxk: onepending-controller
I0205 12:12:24.829930       1 postFilter.go:172] [Preempt] Total de pods preemptados no nó minikube: 1
I0205 12:12:24.829955       1 scheduler.go:271] [OnUpdatePod] Atualizando 'LastStatus' do pod default/onepending-58f8995468-qfdxk nas métricas
I0205 12:12:24.829970       1 postFilter.go:179] [Preempt] Verificando pods de menor precedência no nó minikube que precisam ter o campo NominatedNodeName limpo
I0205 12:12:24.829973       1 scheduler.go:273] [OnUpdatePod] Métrica atualizada para o pod default/onepending-58f8995468-qfdxk
I0205 12:12:24.829985       1 postFilter.go:189] [Preempt] Finalizado para o nó minikube. Pod default/onepending-58f8995468-cxvtf deve ser alocado agora.
I0205 12:12:24.829988       1 scheduler.go:277] [OnUpdatePod] Finalizando processamento de atualização de pod para default/onepending-58f8995468-qfdxk
I0205 12:12:24.829992       1 postFilter.go:49] [PostFilter] Nó nominado para o pod default/onepending-58f8995468-cxvtf: minikube
I0205 12:12:24.829997       1 scheduler.go:282] [OnDeletePod] Iniciando a execução do OnDeletePod
I0205 12:12:24.830036       1 scheduler.go:291] [OnDeletePod] DeepCopy realizado para o pod default/onepending-58f8995468-qfdxk
I0205 12:12:24.830090       1 types.go:749] [ControllerName] Verificando as anotações do pod default/onepending-58f8995468-qfdxk
I0205 12:12:24.830100       1 types.go:767] [ControllerName] Anotação 'controller' encontrada para o pod default/onepending-58f8995468-qfdxk: onepending-controller
I0205 12:12:24.830116       1 types.go:532] [QoS DEBUG] effectiveRunning: 43.094991 | discardedRunning: 0.000000 | waiting: 0.728416 | binding: 0.006697 | denominator: 43.830105
I0205 12:12:24.830151       1 types.go:538] [QoS DEBUG] QoS calculado: 0.983228
I0205 12:12:24.831030       1 scheduler.go:298] [OnDeletePod] Pod deletado detectado: default/onepending-58f8995468-qfdxk
I0205 12:12:24.831126       1 scheduler.go:300] [OnDeletePod] Atualizando métricas do pod default/onepending-58f8995468-qfdxk
I0205 12:12:24.831136       1 types.go:749] [ControllerName] Verificando as anotações do pod default/onepending-58f8995468-qfdxk
I0205 12:12:24.831145       1 types.go:767] [ControllerName] Anotação 'controller' encontrada para o pod default/onepending-58f8995468-qfdxk: onepending-controller
I0205 12:12:24.831158       1 scheduler.go:302] [OnDeletePod] Verificando o estado do pod default/onepending-58f8995468-qfdxk nas métricas
I0205 12:12:24.831164       1 scheduler.go:312] [OnDeletePod] EndTime atualizado para o pod default/onepending-58f8995468-qfdxk: 2025-02-05 12:12:24.831161177 +0000 UTC m=+331.149164738
I0205 12:12:24.831204       1 scheduler.go:316] [OnDeletePod] Finalizando a execução do OnDeletePod para o pod default/onepending-58f8995468-qfdxk
I0205 12:12:24.836612       1 scheduler.go:252] [OnUpdatePod] Iniciando processamento de atualização de pod
I0205 12:12:24.836668       1 scheduler.go:256] [OnUpdatePod] Pod atualizado detectado: default/onepending-58f8995468-cxvtf, Anotações: map[acceptablePreemptionOverhead:0.05 controller:onepending-controller qosMeasuring:independent slo:0.8]
I0205 12:12:24.836688       1 scheduler.go:259] [OnUpdatePod] Comparando estado no Informer e estado real no cluster para o pod default/onepending-58f8995468-cxvtf
I0205 12:12:24.841221       1 scheduler.go:69] Estado no Informer: map[acceptablePreemptionOverhead:0.05 controller:onepending-controller qosMeasuring:independent slo:0.8]
I0205 12:12:24.841257       1 scheduler.go:70] Estado real no cluster: map[acceptablePreemptionOverhead:0.05 controller:onepending-controller qosMeasuring:independent slo:0.8]
I0205 12:12:24.841266       1 scheduler.go:269] [OnUpdatePod] Atualizando informações de métricas para o pod default/onepending-58f8995468-cxvtf
I0205 12:12:24.841270       1 types.go:749] [ControllerName] Verificando as anotações do pod default/onepending-58f8995468-cxvtf
I0205 12:12:24.841275       1 types.go:767] [ControllerName] Anotação 'controller' encontrada para o pod default/onepending-58f8995468-cxvtf: onepending-controller
I0205 12:12:24.841282       1 scheduler.go:271] [OnUpdatePod] Atualizando 'LastStatus' do pod default/onepending-58f8995468-cxvtf nas métricas
I0205 12:12:24.841286       1 scheduler.go:273] [OnUpdatePod] Métrica atualizada para o pod default/onepending-58f8995468-cxvtf
I0205 12:12:24.841294       1 scheduler.go:277] [OnUpdatePod] Finalizando processamento de atualização de pod para default/onepending-58f8995468-cxvtf
I0205 12:12:24.841323       1 scheduler.go:214] [OnAddPod] Pod adicionado: default/onepending-58f8995468-7xcqr, Anotações: map[acceptablePreemptionOverhead:0.05 controller:onepending-controller qosMeasuring:independent slo:0.8]
I0205 12:12:24.841369       1 postFilter.go:29] [PostFilter] PostFilter chamado para pod: default/onepending-58f8995468-7xcqr
I0205 12:12:24.841395       1 postFilter.go:76] Comparando pod original com o atualizado...
I0205 12:12:24.841403       1 postFilter.go:83] Successfully retrieved updated pod default/onepending-58f8995468-7xcqr from lister
I0205 12:12:24.844900       1 scheduler.go:69] Estado no Informer: map[acceptablePreemptionOverhead:0.05 controller:onepending-controller qosMeasuring:independent slo:0.8]
I0205 12:12:24.844938       1 scheduler.go:70] Estado real no cluster: map[acceptablePreemptionOverhead:0.05 controller:onepending-controller qosMeasuring:independent slo:0.8]
I0205 12:12:24.845105       1 postFilter.go:226] [compareNodeResources] Recursos calculados no nó minikube: CPU = 850 mCPU, Memória = 387973120 bytes
I0205 12:12:24.845125       1 postFilter.go:227] [compareNodeResources] Recursos do snapshot no nó minikube: CPU = 850 mCPU, Memória = 387973120 bytes
I0205 12:12:24.845132       1 postFilter.go:233] [compareNodeResources] Recursos de CPU do nó minikube estão sincronizados: 850 mCPU
I0205 12:12:24.845132       1 scheduler.go:225] [OnAddPod] Adicionando pod default/onepending-58f8995468-7xcqr com os seguintes detalhes:
I0205 12:12:24.845139       1 postFilter.go:239] [compareNodeResources] Recursos de memória do nó minikube estão sincronizados: 387973120 bytes
I0205 12:12:24.845144       1 types.go:749] [ControllerName] Verificando as anotações do pod default/onepending-58f8995468-7xcqr
I0205 12:12:24.845152       1 types.go:767] [ControllerName] Anotação 'controller' encontrada para o pod default/onepending-58f8995468-7xcqr: onepending-controller
I0205 12:12:24.845160       1 scheduler.go:234] [OnAddPod] Atualizando métricas para o pod default/onepending-58f8995468-7xcqr
I0205 12:12:24.845163       1 types.go:749] [ControllerName] Verificando as anotações do pod default/onepending-58f8995468-7xcqr
I0205 12:12:24.845167       1 types.go:767] [ControllerName] Anotação 'controller' encontrada para o pod default/onepending-58f8995468-7xcqr: onepending-controller
I0205 12:12:24.845208       1 scheduler.go:247] [OnAddPod] Pod default/onepending-58f8995468-7xcqr adicionado com sucesso
I0205 12:12:24.845318       1 postFilter.go:147] [PREEMPT CALL] The node minikube  was chosen to allocate pod onepending-58f8995468-7xcqr
I0205 12:12:24.845339       1 postFilter.go:151] [Preempt] Iniciando a remoção dos pods preemptados no nó minikube para alocar o pod default/onepending-58f8995468-7xcqr. Total de vítimas: 0
I0205 12:12:24.845349       1 postFilter.go:172] [Preempt] Total de pods preemptados no nó minikube: 0
I0205 12:12:24.845378       1 scheduler.go:83] [HigherPrecedence] Calculando precedência entre onepending-58f8995468-7xcqr e onepending-58f8995468-cxvtf
I0205 12:12:24.845392       1 scheduler.go:116] [WaitForPodsOnCache] Verificando se o pod onepending-58f8995468-7xcqr está no cache...
I0205 12:12:24.845396       1 scheduler.go:597] [GetControllerMetricInfo] Iniciando para o pod: default/onepending-58f8995468-7xcqr
I0205 12:12:24.845400       1 scheduler.go:602] [GetControllerMetricInfo] Obtendo o nome do controlador para o pod: default/onepending-58f8995468-7xcqr
I0205 12:12:24.845405       1 types.go:749] [ControllerName] Verificando as anotações do pod default/onepending-58f8995468-7xcqr
I0205 12:12:24.845409       1 types.go:767] [ControllerName] Anotação 'controller' encontrada para o pod default/onepending-58f8995468-7xcqr: onepending-controller
I0205 12:12:24.845414       1 scheduler.go:605] [GetControllerMetricInfo] Métricas do controlador definidas para o pod: default/onepending-58f8995468-7xcqr
I0205 12:12:24.848101       1 scheduler.go:69] Estado no Informer: map[acceptablePreemptionOverhead:0.05 controller:onepending-controller qosMeasuring:independent slo:0.8]
I0205 12:12:24.848134       1 scheduler.go:70] Estado real no cluster: map[acceptablePreemptionOverhead:0.05 controller:onepending-controller qosMeasuring:independent slo:0.8]
I0205 12:12:24.848142       1 scheduler.go:138] [WaitForPodsOnCache] Pod onepending-58f8995468-7xcqr encontrado no cache.
I0205 12:12:24.848146       1 scheduler.go:116] [WaitForPodsOnCache] Verificando se o pod onepending-58f8995468-cxvtf está no cache...
I0205 12:12:24.848153       1 scheduler.go:597] [GetControllerMetricInfo] Iniciando para o pod: default/onepending-58f8995468-cxvtf
I0205 12:12:24.848158       1 scheduler.go:602] [GetControllerMetricInfo] Obtendo o nome do controlador para o pod: default/onepending-58f8995468-cxvtf
I0205 12:12:24.848162       1 types.go:749] [ControllerName] Verificando as anotações do pod default/onepending-58f8995468-cxvtf
I0205 12:12:24.848167       1 types.go:767] [ControllerName] Anotação 'controller' encontrada para o pod default/onepending-58f8995468-cxvtf: onepending-controller
I0205 12:12:24.848173       1 scheduler.go:605] [GetControllerMetricInfo] Métricas do controlador definidas para o pod: default/onepending-58f8995468-cxvtf
I0205 12:12:24.849888       1 scheduler.go:69] Estado no Informer: map[acceptablePreemptionOverhead:0.05 controller:onepending-controller qosMeasuring:independent slo:0.8]
I0205 12:12:24.849916       1 scheduler.go:70] Estado real no cluster: map[acceptablePreemptionOverhead:0.05 controller:onepending-controller qosMeasuring:independent slo:0.8]
I0205 12:12:24.849922       1 scheduler.go:138] [WaitForPodsOnCache] Pod onepending-58f8995468-cxvtf encontrado no cache.
I0205 12:12:24.849926       1 scheduler.go:597] [GetControllerMetricInfo] Iniciando para o pod: default/onepending-58f8995468-7xcqr
I0205 12:12:24.849930       1 scheduler.go:602] [GetControllerMetricInfo] Obtendo o nome do controlador para o pod: default/onepending-58f8995468-7xcqr
I0205 12:12:24.849933       1 types.go:749] [ControllerName] Verificando as anotações do pod default/onepending-58f8995468-7xcqr
I0205 12:12:24.849938       1 types.go:767] [ControllerName] Anotação 'controller' encontrada para o pod default/onepending-58f8995468-7xcqr: onepending-controller
I0205 12:12:24.849943       1 scheduler.go:605] [GetControllerMetricInfo] Métricas do controlador definidas para o pod: default/onepending-58f8995468-7xcqr
I0205 12:12:24.849952       1 scheduler.go:597] [GetControllerMetricInfo] Iniciando para o pod: default/onepending-58f8995468-cxvtf
I0205 12:12:24.849956       1 scheduler.go:602] [GetControllerMetricInfo] Obtendo o nome do controlador para o pod: default/onepending-58f8995468-cxvtf
I0205 12:12:24.849960       1 types.go:749] [ControllerName] Verificando as anotações do pod default/onepending-58f8995468-cxvtf
I0205 12:12:24.849964       1 types.go:767] [ControllerName] Anotação 'controller' encontrada para o pod default/onepending-58f8995468-cxvtf: onepending-controller
I0205 12:12:24.849969       1 scheduler.go:605] [GetControllerMetricInfo] Métricas do controlador definidas para o pod: default/onepending-58f8995468-cxvtf
I0205 12:12:24.849975       1 scheduler.go:97] [HigherPrecedence] Métricas para onepending-58f8995468-7xcqr: QoS = 9.190174, Importância = 0.80
I0205 12:12:24.849983       1 scheduler.go:98] [HigherPrecedence] Métricas para onepending-58f8995468-cxvtf: QoS = -46.245376, Importância = 0.80
I0205 12:12:24.849988       1 scheduler.go:109] [HigherPrecedence] Decisão final: onepending-58f8995468-7xcqr tem precedência sobre onepending-58f8995468-cxvtf? false
I0205 12:12:24.849998       1 postFilter.go:179] [Preempt] Verificando pods de menor precedência no nó minikube que precisam ter o campo NominatedNodeName limpo
I0205 12:12:24.850017       1 postFilter.go:189] [Preempt] Finalizado para o nó minikube. Pod default/onepending-58f8995468-7xcqr deve ser alocado agora.
I0205 12:12:24.850021       1 postFilter.go:49] [PostFilter] Nó nominado para o pod default/onepending-58f8995468-7xcqr: minikube
I0205 12:12:24.858319       1 scheduler.go:252] [OnUpdatePod] Iniciando processamento de atualização de pod
I0205 12:12:24.858363       1 scheduler.go:256] [OnUpdatePod] Pod atualizado detectado: default/onepending-58f8995468-7xcqr, Anotações: map[acceptablePreemptionOverhead:0.05 controller:onepending-controller qosMeasuring:independent slo:0.8]
I0205 12:12:24.858376       1 scheduler.go:259] [OnUpdatePod] Comparando estado no Informer e estado real no cluster para o pod default/onepending-58f8995468-7xcqr
I0205 12:12:24.861728       1 scheduler.go:69] Estado no Informer: map[acceptablePreemptionOverhead:0.05 controller:onepending-controller qosMeasuring:independent slo:0.8]
I0205 12:12:24.861757       1 scheduler.go:70] Estado real no cluster: map[acceptablePreemptionOverhead:0.05 controller:onepending-controller qosMeasuring:independent slo:0.8]
I0205 12:12:24.861764       1 scheduler.go:269] [OnUpdatePod] Atualizando informações de métricas para o pod default/onepending-58f8995468-7xcqr
I0205 12:12:24.861769       1 types.go:749] [ControllerName] Verificando as anotações do pod default/onepending-58f8995468-7xcqr
I0205 12:12:24.861773       1 types.go:767] [ControllerName] Anotação 'controller' encontrada para o pod default/onepending-58f8995468-7xcqr: onepending-controller
I0205 12:12:24.861781       1 scheduler.go:271] [OnUpdatePod] Atualizando 'LastStatus' do pod default/onepending-58f8995468-7xcqr nas métricas
I0205 12:12:24.861786       1 scheduler.go:273] [OnUpdatePod] Métrica atualizada para o pod default/onepending-58f8995468-7xcqr
I0205 12:12:24.861795       1 scheduler.go:277] [OnUpdatePod] Finalizando processamento de atualização de pod para default/onepending-58f8995468-7xcqr
I0205 12:12:33.025096       1 postFilter.go:29] [PostFilter] PostFilter chamado para pod: default/onepending-58f8995468-cxvtf
I0205 12:12:33.025118       1 postFilter.go:76] Comparando pod original com o atualizado...
I0205 12:12:33.025124       1 postFilter.go:83] Successfully retrieved updated pod default/onepending-58f8995468-cxvtf from lister
I0205 12:12:33.027216       1 postFilter.go:226] [compareNodeResources] Recursos calculados no nó minikube: CPU = 850 mCPU, Memória = 387973120 bytes
I0205 12:12:33.027233       1 postFilter.go:227] [compareNodeResources] Recursos do snapshot no nó minikube: CPU = 850 mCPU, Memória = 387973120 bytes
I0205 12:12:33.027238       1 postFilter.go:233] [compareNodeResources] Recursos de CPU do nó minikube estão sincronizados: 850 mCPU
I0205 12:12:33.027243       1 postFilter.go:239] [compareNodeResources] Recursos de memória do nó minikube estão sincronizados: 387973120 bytes
I0205 12:12:33.027347       1 postFilter.go:147] [PREEMPT CALL] The node minikube  was chosen to allocate pod onepending-58f8995468-cxvtf
I0205 12:12:33.027366       1 postFilter.go:151] [Preempt] Iniciando a remoção dos pods preemptados no nó minikube para alocar o pod default/onepending-58f8995468-cxvtf. Total de vítimas: 0
I0205 12:12:33.027378       1 postFilter.go:172] [Preempt] Total de pods preemptados no nó minikube: 0
W0205 12:12:33.027397       1 scheduler.go:78] [HigherPrecedence] Tentativa de comparar o pod onepending-58f8995468-cxvtf consigo mesmo. Retornando false.
I0205 12:12:33.027409       1 scheduler.go:83] [HigherPrecedence] Calculando precedência entre onepending-58f8995468-cxvtf e onepending-58f8995468-7xcqr
I0205 12:12:33.027413       1 scheduler.go:116] [WaitForPodsOnCache] Verificando se o pod onepending-58f8995468-cxvtf está no cache...
I0205 12:12:33.027417       1 scheduler.go:597] [GetControllerMetricInfo] Iniciando para o pod: default/onepending-58f8995468-cxvtf
I0205 12:12:33.027421       1 scheduler.go:602] [GetControllerMetricInfo] Obtendo o nome do controlador para o pod: default/onepending-58f8995468-cxvtf
I0205 12:12:33.027425       1 types.go:749] [ControllerName] Verificando as anotações do pod default/onepending-58f8995468-cxvtf
I0205 12:12:33.027429       1 types.go:767] [ControllerName] Anotação 'controller' encontrada para o pod default/onepending-58f8995468-cxvtf: onepending-controller
I0205 12:12:33.027434       1 scheduler.go:605] [GetControllerMetricInfo] Métricas do controlador definidas para o pod: default/onepending-58f8995468-cxvtf
I0205 12:12:33.028962       1 scheduler.go:69] Estado no Informer: map[acceptablePreemptionOverhead:0.05 controller:onepending-controller qosMeasuring:independent slo:0.8]
I0205 12:12:33.028985       1 scheduler.go:70] Estado real no cluster: map[acceptablePreemptionOverhead:0.05 controller:onepending-controller qosMeasuring:independent slo:0.8]
I0205 12:12:33.028991       1 scheduler.go:138] [WaitForPodsOnCache] Pod onepending-58f8995468-cxvtf encontrado no cache.
I0205 12:12:33.028995       1 scheduler.go:116] [WaitForPodsOnCache] Verificando se o pod onepending-58f8995468-7xcqr está no cache...
I0205 12:12:33.028998       1 scheduler.go:597] [GetControllerMetricInfo] Iniciando para o pod: default/onepending-58f8995468-7xcqr
I0205 12:12:33.029001       1 scheduler.go:602] [GetControllerMetricInfo] Obtendo o nome do controlador para o pod: default/onepending-58f8995468-7xcqr
I0205 12:12:33.029006       1 types.go:749] [ControllerName] Verificando as anotações do pod default/onepending-58f8995468-7xcqr
I0205 12:12:33.029009       1 types.go:767] [ControllerName] Anotação 'controller' encontrada para o pod default/onepending-58f8995468-7xcqr: onepending-controller
I0205 12:12:33.029013       1 scheduler.go:605] [GetControllerMetricInfo] Métricas do controlador definidas para o pod: default/onepending-58f8995468-7xcqr
I0205 12:12:33.030378       1 scheduler.go:69] Estado no Informer: map[acceptablePreemptionOverhead:0.05 controller:onepending-controller qosMeasuring:independent slo:0.8]
I0205 12:12:33.030405       1 scheduler.go:70] Estado real no cluster: map[acceptablePreemptionOverhead:0.05 controller:onepending-controller qosMeasuring:independent slo:0.8]
I0205 12:12:33.030411       1 scheduler.go:138] [WaitForPodsOnCache] Pod onepending-58f8995468-7xcqr encontrado no cache.
I0205 12:12:33.030414       1 scheduler.go:597] [GetControllerMetricInfo] Iniciando para o pod: default/onepending-58f8995468-cxvtf
I0205 12:12:33.030419       1 scheduler.go:602] [GetControllerMetricInfo] Obtendo o nome do controlador para o pod: default/onepending-58f8995468-cxvtf
I0205 12:12:33.030423       1 types.go:749] [ControllerName] Verificando as anotações do pod default/onepending-58f8995468-cxvtf
I0205 12:12:33.030428       1 types.go:767] [ControllerName] Anotação 'controller' encontrada para o pod default/onepending-58f8995468-cxvtf: onepending-controller
I0205 12:12:33.030433       1 scheduler.go:605] [GetControllerMetricInfo] Métricas do controlador definidas para o pod: default/onepending-58f8995468-cxvtf
I0205 12:12:33.030441       1 scheduler.go:597] [GetControllerMetricInfo] Iniciando para o pod: default/onepending-58f8995468-7xcqr
I0205 12:12:33.030446       1 scheduler.go:602] [GetControllerMetricInfo] Obtendo o nome do controlador para o pod: default/onepending-58f8995468-7xcqr
I0205 12:12:33.030449       1 types.go:749] [ControllerName] Verificando as anotações do pod default/onepending-58f8995468-7xcqr
I0205 12:12:33.030454       1 types.go:767] [ControllerName] Anotação 'controller' encontrada para o pod default/onepending-58f8995468-7xcqr: onepending-controller
I0205 12:12:33.030459       1 scheduler.go:605] [GetControllerMetricInfo] Métricas do controlador definidas para o pod: default/onepending-58f8995468-7xcqr
I0205 12:12:33.030468       1 scheduler.go:97] [HigherPrecedence] Métricas para onepending-58f8995468-cxvtf: QoS = -54.427407, Importância = 0.80
I0205 12:12:33.030488       1 scheduler.go:98] [HigherPrecedence] Métricas para onepending-58f8995468-7xcqr: QoS = 1.008142, Importância = 0.80
I0205 12:12:33.030494       1 scheduler.go:109] [HigherPrecedence] Decisão final: onepending-58f8995468-cxvtf tem precedência sobre onepending-58f8995468-7xcqr? true
I0205 12:12:33.030506       1 postFilter.go:179] [Preempt] Verificando pods de menor precedência no nó minikube que precisam ter o campo NominatedNodeName limpo
I0205 12:12:33.030516       1 postFilter.go:181] [Preempt] Limpando o campo NominatedNodeName do pod default/onepending-58f8995468-7xcqr
I0205 12:12:33.035070       1 scheduler.go:252] [OnUpdatePod] Iniciando processamento de atualização de pod
I0205 12:12:33.035106       1 scheduler.go:256] [OnUpdatePod] Pod atualizado detectado: default/onepending-58f8995468-7xcqr, Anotações: map[acceptablePreemptionOverhead:0.05 controller:onepending-controller qosMeasuring:independent slo:0.8]
I0205 12:12:33.035121       1 scheduler.go:259] [OnUpdatePod] Comparando estado no Informer e estado real no cluster para o pod default/onepending-58f8995468-7xcqr
I0205 12:12:33.035137       1 postFilter.go:189] [Preempt] Finalizado para o nó minikube. Pod default/onepending-58f8995468-cxvtf deve ser alocado agora.
I0205 12:12:33.035149       1 postFilter.go:49] [PostFilter] Nó nominado para o pod default/onepending-58f8995468-cxvtf: minikube
I0205 12:12:33.036828       1 scheduler.go:69] Estado no Informer: map[acceptablePreemptionOverhead:0.05 controller:onepending-controller qosMeasuring:independent slo:0.8]
I0205 12:12:33.036855       1 scheduler.go:70] Estado real no cluster: map[acceptablePreemptionOverhead:0.05 controller:onepending-controller qosMeasuring:independent slo:0.8]
I0205 12:12:33.036862       1 scheduler.go:269] [OnUpdatePod] Atualizando informações de métricas para o pod default/onepending-58f8995468-7xcqr
I0205 12:12:33.036867       1 types.go:749] [ControllerName] Verificando as anotações do pod default/onepending-58f8995468-7xcqr
I0205 12:12:33.036871       1 types.go:767] [ControllerName] Anotação 'controller' encontrada para o pod default/onepending-58f8995468-7xcqr: onepending-controller
I0205 12:12:33.036877       1 scheduler.go:271] [OnUpdatePod] Atualizando 'LastStatus' do pod default/onepending-58f8995468-7xcqr nas métricas
I0205 12:12:33.036889       1 scheduler.go:273] [OnUpdatePod] Métrica atualizada para o pod default/onepending-58f8995468-7xcqr
I0205 12:12:33.036896       1 scheduler.go:277] [OnUpdatePod] Finalizando processamento de atualização de pod para default/onepending-58f8995468-7xcqr
I0205 12:12:54.817247       1 scheduler.go:53] [QueueSort] Comparando prioridade de onepending-58f8995468-cxvtf com onepending-58f8995468-7xcqr
I0205 12:12:54.817272       1 scheduler.go:83] [HigherPrecedence] Calculando precedência entre onepending-58f8995468-cxvtf e onepending-58f8995468-7xcqr
I0205 12:12:54.817276       1 scheduler.go:116] [WaitForPodsOnCache] Verificando se o pod onepending-58f8995468-cxvtf está no cache...
I0205 12:12:54.817281       1 scheduler.go:597] [GetControllerMetricInfo] Iniciando para o pod: default/onepending-58f8995468-cxvtf
I0205 12:12:54.817285       1 scheduler.go:602] [GetControllerMetricInfo] Obtendo o nome do controlador para o pod: default/onepending-58f8995468-cxvtf
I0205 12:12:54.817289       1 types.go:749] [ControllerName] Verificando as anotações do pod default/onepending-58f8995468-cxvtf
I0205 12:12:54.817293       1 types.go:767] [ControllerName] Anotação 'controller' encontrada para o pod default/onepending-58f8995468-cxvtf: onepending-controller
I0205 12:12:54.817298       1 scheduler.go:605] [GetControllerMetricInfo] Métricas do controlador definidas para o pod: default/onepending-58f8995468-cxvtf
I0205 12:12:54.819261       1 scheduler.go:69] Estado no Informer: map[acceptablePreemptionOverhead:0.05 controller:onepending-controller qosMeasuring:independent slo:0.8]
I0205 12:12:54.819287       1 scheduler.go:70] Estado real no cluster: map[acceptablePreemptionOverhead:0.05 controller:onepending-controller qosMeasuring:independent slo:0.8]
I0205 12:12:54.819293       1 scheduler.go:138] [WaitForPodsOnCache] Pod onepending-58f8995468-cxvtf encontrado no cache.
I0205 12:12:54.819296       1 scheduler.go:116] [WaitForPodsOnCache] Verificando se o pod onepending-58f8995468-7xcqr está no cache...
I0205 12:12:54.819300       1 scheduler.go:597] [GetControllerMetricInfo] Iniciando para o pod: default/onepending-58f8995468-7xcqr
I0205 12:12:54.819304       1 scheduler.go:602] [GetControllerMetricInfo] Obtendo o nome do controlador para o pod: default/onepending-58f8995468-7xcqr
I0205 12:12:54.819307       1 types.go:749] [ControllerName] Verificando as anotações do pod default/onepending-58f8995468-7xcqr
I0205 12:12:54.819311       1 types.go:767] [ControllerName] Anotação 'controller' encontrada para o pod default/onepending-58f8995468-7xcqr: onepending-controller
I0205 12:12:54.819315       1 scheduler.go:605] [GetControllerMetricInfo] Métricas do controlador definidas para o pod: default/onepending-58f8995468-7xcqr
I0205 12:12:54.821153       1 scheduler.go:69] Estado no Informer: map[acceptablePreemptionOverhead:0.05 controller:onepending-controller qosMeasuring:independent slo:0.8]
I0205 12:12:54.821193       1 scheduler.go:70] Estado real no cluster: map[acceptablePreemptionOverhead:0.05 controller:onepending-controller qosMeasuring:independent slo:0.8]
I0205 12:12:54.821202       1 scheduler.go:138] [WaitForPodsOnCache] Pod onepending-58f8995468-7xcqr encontrado no cache.
I0205 12:12:54.821206       1 scheduler.go:597] [GetControllerMetricInfo] Iniciando para o pod: default/onepending-58f8995468-cxvtf
I0205 12:12:54.821210       1 scheduler.go:602] [GetControllerMetricInfo] Obtendo o nome do controlador para o pod: default/onepending-58f8995468-cxvtf
I0205 12:12:54.821213       1 types.go:749] [ControllerName] Verificando as anotações do pod default/onepending-58f8995468-cxvtf
I0205 12:12:54.821218       1 types.go:767] [ControllerName] Anotação 'controller' encontrada para o pod default/onepending-58f8995468-cxvtf: onepending-controller
I0205 12:12:54.821222       1 scheduler.go:605] [GetControllerMetricInfo] Métricas do controlador definidas para o pod: default/onepending-58f8995468-cxvtf
I0205 12:12:54.821228       1 scheduler.go:597] [GetControllerMetricInfo] Iniciando para o pod: default/onepending-58f8995468-7xcqr
I0205 12:12:54.821235       1 scheduler.go:602] [GetControllerMetricInfo] Obtendo o nome do controlador para o pod: default/onepending-58f8995468-7xcqr
I0205 12:12:54.821238       1 types.go:749] [ControllerName] Verificando as anotações do pod default/onepending-58f8995468-7xcqr
I0205 12:12:54.821241       1 types.go:767] [ControllerName] Anotação 'controller' encontrada para o pod default/onepending-58f8995468-7xcqr: onepending-controller
I0205 12:12:54.821245       1 scheduler.go:605] [GetControllerMetricInfo] Métricas do controlador definidas para o pod: default/onepending-58f8995468-7xcqr
I0205 12:12:54.821251       1 scheduler.go:97] [HigherPrecedence] Métricas para onepending-58f8995468-cxvtf: QoS = -76.217269, Importância = 0.80
I0205 12:12:54.821258       1 scheduler.go:98] [HigherPrecedence] Métricas para onepending-58f8995468-7xcqr: QoS = -20.781719, Importância = 0.80
I0205 12:12:54.821263       1 scheduler.go:109] [HigherPrecedence] Decisão final: onepending-58f8995468-cxvtf tem precedência sobre onepending-58f8995468-7xcqr? true
I0205 12:12:54.821268       1 scheduler.go:59] [QueueSort] Precedência determinada: onepending-58f8995468-cxvtf tem precedência sobre onepending-58f8995468-7xcqr? true
I0205 12:12:54.821422       1 scheduler.go:145] [Reserve] resources reserved at node minikube for pod onepending-58f8995468-cxvtf_default at 2025-02-05 12:12:54.821419412 +0000 UTC m=+361.139422963
I0205 12:12:54.821440       1 types.go:749] [ControllerName] Verificando as anotações do pod default/onepending-58f8995468-cxvtf
I0205 12:12:54.821444       1 types.go:767] [ControllerName] Anotação 'controller' encontrada para o pod default/onepending-58f8995468-cxvtf: onepending-controller
I0205 12:12:54.821448       1 scheduler.go:147] [Reserve] Status de alocação atual para o pod onepending-58f8995468-cxvtf_default: 
I0205 12:12:54.821452       1 scheduler.go:149] [Reserve] Status de alocação atualizado para o pod onepending-58f8995468-cxvtf_default: allocating
I0205 12:12:54.821516       1 postFilter.go:29] [PostFilter] PostFilter chamado para pod: default/onepending-58f8995468-7xcqr
I0205 12:12:54.821530       1 postFilter.go:76] Comparando pod original com o atualizado...
I0205 12:12:54.821535       1 postFilter.go:83] Successfully retrieved updated pod default/onepending-58f8995468-7xcqr from lister
I0205 12:12:54.821579       1 scheduler.go:173] [PreBind] Validando o pod onepending-58f8995468-cxvtf antes de vincular ao node minikube
I0205 12:12:54.823305       1 postFilter.go:226] [compareNodeResources] Recursos calculados no nó minikube: CPU = 8850 mCPU, Memória = 387973120 bytes
I0205 12:12:54.823326       1 postFilter.go:227] [compareNodeResources] Recursos do snapshot no nó minikube: CPU = 8850 mCPU, Memória = 387973120 bytes
I0205 12:12:54.823331       1 postFilter.go:233] [compareNodeResources] Recursos de CPU do nó minikube estão sincronizados: 8850 mCPU
I0205 12:12:54.823335       1 postFilter.go:239] [compareNodeResources] Recursos de memória do nó minikube estão sincronizados: 387973120 bytes
I0205 12:12:54.823408       1 scheduler.go:597] [GetControllerMetricInfo] Iniciando para o pod: default/onepending-58f8995468-cxvtf
I0205 12:12:54.823422       1 scheduler.go:602] [GetControllerMetricInfo] Obtendo o nome do controlador para o pod: default/onepending-58f8995468-cxvtf
I0205 12:12:54.823425       1 types.go:749] [ControllerName] Verificando as anotações do pod default/onepending-58f8995468-cxvtf
I0205 12:12:54.823429       1 types.go:767] [ControllerName] Anotação 'controller' encontrada para o pod default/onepending-58f8995468-cxvtf: onepending-controller
I0205 12:12:54.823433       1 scheduler.go:605] [GetControllerMetricInfo] Métricas do controlador definidas para o pod: default/onepending-58f8995468-cxvtf
I0205 12:12:54.823437       1 scheduler.go:83] [HigherPrecedence] Calculando precedência entre onepending-58f8995468-7xcqr e onepending-58f8995468-cxvtf
I0205 12:12:54.823440       1 scheduler.go:116] [WaitForPodsOnCache] Verificando se o pod onepending-58f8995468-7xcqr está no cache...
I0205 12:12:54.823443       1 scheduler.go:597] [GetControllerMetricInfo] Iniciando para o pod: default/onepending-58f8995468-7xcqr
I0205 12:12:54.823446       1 scheduler.go:602] [GetControllerMetricInfo] Obtendo o nome do controlador para o pod: default/onepending-58f8995468-7xcqr
I0205 12:12:54.823449       1 types.go:749] [ControllerName] Verificando as anotações do pod default/onepending-58f8995468-7xcqr
I0205 12:12:54.823452       1 types.go:767] [ControllerName] Anotação 'controller' encontrada para o pod default/onepending-58f8995468-7xcqr: onepending-controller
I0205 12:12:54.823456       1 scheduler.go:605] [GetControllerMetricInfo] Métricas do controlador definidas para o pod: default/onepending-58f8995468-7xcqr
I0205 12:12:54.826717       1 scheduler.go:181] [PostBind] Chamado para pod onepending-58f8995468-cxvtf
I0205 12:12:54.826735       1 scheduler.go:199] [PostBind] Pod onepending-58f8995468-cxvtf - Início do binding: 2025-02-05 12:12:54.821596165 +0000 UTC m=+361.139599716, Fim do binding: 2025-02-05 12:12:54.826732542 +0000 UTC m=+361.144736103
I0205 12:12:54.826786       1 scheduler.go:69] Estado no Informer: map[acceptablePreemptionOverhead:0.05 controller:onepending-controller qosMeasuring:independent slo:0.8]
I0205 12:12:54.826800       1 scheduler.go:70] Estado real no cluster: map[acceptablePreemptionOverhead:0.05 controller:onepending-controller qosMeasuring:independent slo:0.8]
I0205 12:12:54.826808       1 scheduler.go:138] [WaitForPodsOnCache] Pod onepending-58f8995468-7xcqr encontrado no cache.
I0205 12:12:54.826812       1 scheduler.go:116] [WaitForPodsOnCache] Verificando se o pod onepending-58f8995468-cxvtf está no cache...
I0205 12:12:54.826817       1 scheduler.go:597] [GetControllerMetricInfo] Iniciando para o pod: default/onepending-58f8995468-cxvtf
I0205 12:12:54.826868       1 types.go:749] [ControllerName] Verificando as anotações do pod default/onepending-58f8995468-cxvtf
I0205 12:12:54.826885       1 types.go:767] [ControllerName] Anotação 'controller' encontrada para o pod default/onepending-58f8995468-cxvtf: onepending-controller
I0205 12:12:54.826892       1 scheduler.go:206] [PostBind] Métricas atualizadas para o pod onepending-58f8995468-cxvtf
I0205 12:12:54.826899       1 scheduler.go:252] [OnUpdatePod] Iniciando processamento de atualização de pod
I0205 12:12:54.826975       1 scheduler.go:256] [OnUpdatePod] Pod atualizado detectado: default/onepending-58f8995468-cxvtf, Anotações: map[acceptablePreemptionOverhead:0.05 controller:onepending-controller qosMeasuring:independent slo:0.8]
I0205 12:12:54.827001       1 scheduler.go:259] [OnUpdatePod] Comparando estado no Informer e estado real no cluster para o pod default/onepending-58f8995468-cxvtf
I0205 12:12:54.826908       1 scheduler.go:602] [GetControllerMetricInfo] Obtendo o nome do controlador para o pod: default/onepending-58f8995468-cxvtf
I0205 12:12:54.827146       1 types.go:749] [ControllerName] Verificando as anotações do pod default/onepending-58f8995468-cxvtf
I0205 12:12:54.827291       1 types.go:767] [ControllerName] Anotação 'controller' encontrada para o pod default/onepending-58f8995468-cxvtf: onepending-controller
I0205 12:12:54.827300       1 scheduler.go:605] [GetControllerMetricInfo] Métricas do controlador definidas para o pod: default/onepending-58f8995468-cxvtf
I0205 12:12:54.828751       1 scheduler.go:69] Estado no Informer: map[acceptablePreemptionOverhead:0.05 controller:onepending-controller qosMeasuring:independent slo:0.8]
I0205 12:12:54.828776       1 scheduler.go:70] Estado real no cluster: map[acceptablePreemptionOverhead:0.05 controller:onepending-controller qosMeasuring:independent slo:0.8]
I0205 12:12:54.828784       1 scheduler.go:269] [OnUpdatePod] Atualizando informações de métricas para o pod default/onepending-58f8995468-cxvtf
I0205 12:12:54.829734       1 scheduler.go:69] Estado no Informer: map[acceptablePreemptionOverhead:0.05 controller:onepending-controller qosMeasuring:independent slo:0.8]
I0205 12:12:54.829762       1 scheduler.go:70] Estado real no cluster: map[acceptablePreemptionOverhead:0.05 controller:onepending-controller qosMeasuring:independent slo:0.8]
I0205 12:12:54.829784       1 scheduler.go:138] [WaitForPodsOnCache] Pod onepending-58f8995468-cxvtf encontrado no cache.
I0205 12:12:54.829789       1 scheduler.go:597] [GetControllerMetricInfo] Iniciando para o pod: default/onepending-58f8995468-7xcqr
I0205 12:12:54.829798       1 types.go:749] [ControllerName] Verificando as anotações do pod default/onepending-58f8995468-cxvtf
I0205 12:12:54.829803       1 types.go:767] [ControllerName] Anotação 'controller' encontrada para o pod default/onepending-58f8995468-cxvtf: onepending-controller
I0205 12:12:54.829809       1 scheduler.go:271] [OnUpdatePod] Atualizando 'LastStatus' do pod default/onepending-58f8995468-cxvtf nas métricas
I0205 12:12:54.829814       1 scheduler.go:273] [OnUpdatePod] Métrica atualizada para o pod default/onepending-58f8995468-cxvtf
I0205 12:12:54.829832       1 scheduler.go:277] [OnUpdatePod] Finalizando processamento de atualização de pod para default/onepending-58f8995468-cxvtf
I0205 12:12:54.829845       1 scheduler.go:602] [GetControllerMetricInfo] Obtendo o nome do controlador para o pod: default/onepending-58f8995468-7xcqr
I0205 12:12:54.829848       1 types.go:749] [ControllerName] Verificando as anotações do pod default/onepending-58f8995468-7xcqr
I0205 12:12:54.829852       1 types.go:767] [ControllerName] Anotação 'controller' encontrada para o pod default/onepending-58f8995468-7xcqr: onepending-controller
I0205 12:12:54.829856       1 scheduler.go:605] [GetControllerMetricInfo] Métricas do controlador definidas para o pod: default/onepending-58f8995468-7xcqr
I0205 12:12:54.829863       1 scheduler.go:597] [GetControllerMetricInfo] Iniciando para o pod: default/onepending-58f8995468-cxvtf
I0205 12:12:54.829867       1 scheduler.go:602] [GetControllerMetricInfo] Obtendo o nome do controlador para o pod: default/onepending-58f8995468-cxvtf
I0205 12:12:54.829871       1 types.go:749] [ControllerName] Verificando as anotações do pod default/onepending-58f8995468-cxvtf
I0205 12:12:54.829875       1 types.go:767] [ControllerName] Anotação 'controller' encontrada para o pod default/onepending-58f8995468-cxvtf: onepending-controller
I0205 12:12:54.829880       1 scheduler.go:605] [GetControllerMetricInfo] Métricas do controlador definidas para o pod: default/onepending-58f8995468-cxvtf
I0205 12:12:54.829889       1 scheduler.go:97] [HigherPrecedence] Métricas para onepending-58f8995468-7xcqr: QoS = -20.787885, Importância = 0.80
I0205 12:12:54.829905       1 scheduler.go:98] [HigherPrecedence] Métricas para onepending-58f8995468-cxvtf: QoS = -73.832693, Importância = 0.80
I0205 12:12:54.829911       1 scheduler.go:109] [HigherPrecedence] Decisão final: onepending-58f8995468-7xcqr tem precedência sobre onepending-58f8995468-cxvtf? false
I0205 12:12:54.829950       1 postFilter.go:144] [PREEMPT CALL] No node was chosen to allocate pod onepending-58f8995468-7xcqr
W0205 12:12:54.829965       1 postFilter.go:45] [PostFilter] Nenhum nó nominado após a preempção para o pod: default/onepending-58f8995468-7xcqr
I0205 12:12:54.836875       1 scheduler.go:252] [OnUpdatePod] Iniciando processamento de atualização de pod
I0205 12:12:54.836943       1 scheduler.go:256] [OnUpdatePod] Pod atualizado detectado: default/onepending-58f8995468-cxvtf, Anotações: map[acceptablePreemptionOverhead:0.05 controller:onepending-controller qosMeasuring:independent slo:0.8]
I0205 12:12:54.836959       1 scheduler.go:259] [OnUpdatePod] Comparando estado no Informer e estado real no cluster para o pod default/onepending-58f8995468-cxvtf
I0205 12:12:54.838686       1 scheduler.go:69] Estado no Informer: map[acceptablePreemptionOverhead:0.05 controller:onepending-controller qosMeasuring:independent slo:0.8]
I0205 12:12:54.838709       1 scheduler.go:70] Estado real no cluster: map[acceptablePreemptionOverhead:0.05 controller:onepending-controller qosMeasuring:independent slo:0.8]
I0205 12:12:54.838718       1 scheduler.go:269] [OnUpdatePod] Atualizando informações de métricas para o pod default/onepending-58f8995468-cxvtf
I0205 12:12:54.838723       1 types.go:749] [ControllerName] Verificando as anotações do pod default/onepending-58f8995468-cxvtf
I0205 12:12:54.838727       1 types.go:767] [ControllerName] Anotação 'controller' encontrada para o pod default/onepending-58f8995468-cxvtf: onepending-controller
I0205 12:12:54.838733       1 scheduler.go:271] [OnUpdatePod] Atualizando 'LastStatus' do pod default/onepending-58f8995468-cxvtf nas métricas
I0205 12:12:54.838736       1 scheduler.go:273] [OnUpdatePod] Métrica atualizada para o pod default/onepending-58f8995468-cxvtf
I0205 12:12:54.838743       1 scheduler.go:277] [OnUpdatePod] Finalizando processamento de atualização de pod para default/onepending-58f8995468-cxvtf
I0205 12:12:56.362064       1 scheduler.go:252] [OnUpdatePod] Iniciando processamento de atualização de pod
I0205 12:12:56.362125       1 scheduler.go:256] [OnUpdatePod] Pod atualizado detectado: default/onepending-58f8995468-cxvtf, Anotações: map[acceptablePreemptionOverhead:0.05 controller:onepending-controller qosMeasuring:independent slo:0.8]
I0205 12:12:56.362142       1 scheduler.go:259] [OnUpdatePod] Comparando estado no Informer e estado real no cluster para o pod default/onepending-58f8995468-cxvtf
I0205 12:12:56.364024       1 scheduler.go:69] Estado no Informer: map[acceptablePreemptionOverhead:0.05 controller:onepending-controller qosMeasuring:independent slo:0.8]
I0205 12:12:56.364040       1 scheduler.go:70] Estado real no cluster: map[acceptablePreemptionOverhead:0.05 controller:onepending-controller qosMeasuring:independent slo:0.8]
I0205 12:12:56.364048       1 scheduler.go:269] [OnUpdatePod] Atualizando informações de métricas para o pod default/onepending-58f8995468-cxvtf
I0205 12:12:56.364053       1 types.go:749] [ControllerName] Verificando as anotações do pod default/onepending-58f8995468-cxvtf
I0205 12:12:56.364058       1 types.go:767] [ControllerName] Anotação 'controller' encontrada para o pod default/onepending-58f8995468-cxvtf: onepending-controller
I0205 12:12:56.364065       1 scheduler.go:271] [OnUpdatePod] Atualizando 'LastStatus' do pod default/onepending-58f8995468-cxvtf nas métricas
I0205 12:12:56.364098       1 scheduler.go:273] [OnUpdatePod] Métrica atualizada para o pod default/onepending-58f8995468-cxvtf
I0205 12:12:56.364107       1 scheduler.go:277] [OnUpdatePod] Finalizando processamento de atualização de pod para default/onepending-58f8995468-cxvtf
I0205 12:12:57.036957       1 postFilter.go:29] [PostFilter] PostFilter chamado para pod: default/onepending-58f8995468-7xcqr
I0205 12:12:57.036981       1 postFilter.go:76] Comparando pod original com o atualizado...
I0205 12:12:57.036987       1 postFilter.go:83] Successfully retrieved updated pod default/onepending-58f8995468-7xcqr from lister
I0205 12:12:57.038734       1 postFilter.go:226] [compareNodeResources] Recursos calculados no nó minikube: CPU = 8850 mCPU, Memória = 387973120 bytes
I0205 12:12:57.038752       1 postFilter.go:227] [compareNodeResources] Recursos do snapshot no nó minikube: CPU = 8850 mCPU, Memória = 387973120 bytes
I0205 12:12:57.038757       1 postFilter.go:233] [compareNodeResources] Recursos de CPU do nó minikube estão sincronizados: 8850 mCPU
I0205 12:12:57.038761       1 postFilter.go:239] [compareNodeResources] Recursos de memória do nó minikube estão sincronizados: 387973120 bytes
I0205 12:12:57.038847       1 scheduler.go:597] [GetControllerMetricInfo] Iniciando para o pod: default/onepending-58f8995468-cxvtf
I0205 12:12:57.038862       1 scheduler.go:602] [GetControllerMetricInfo] Obtendo o nome do controlador para o pod: default/onepending-58f8995468-cxvtf
I0205 12:12:57.038867       1 types.go:749] [ControllerName] Verificando as anotações do pod default/onepending-58f8995468-cxvtf
I0205 12:12:57.038871       1 types.go:767] [ControllerName] Anotação 'controller' encontrada para o pod default/onepending-58f8995468-cxvtf: onepending-controller
I0205 12:12:57.038876       1 scheduler.go:605] [GetControllerMetricInfo] Métricas do controlador definidas para o pod: default/onepending-58f8995468-cxvtf
I0205 12:12:57.038881       1 scheduler.go:83] [HigherPrecedence] Calculando precedência entre onepending-58f8995468-7xcqr e onepending-58f8995468-cxvtf
I0205 12:12:57.038886       1 scheduler.go:116] [WaitForPodsOnCache] Verificando se o pod onepending-58f8995468-7xcqr está no cache...
I0205 12:12:57.038890       1 scheduler.go:597] [GetControllerMetricInfo] Iniciando para o pod: default/onepending-58f8995468-7xcqr
I0205 12:12:57.038896       1 scheduler.go:602] [GetControllerMetricInfo] Obtendo o nome do controlador para o pod: default/onepending-58f8995468-7xcqr
I0205 12:12:57.038903       1 types.go:749] [ControllerName] Verificando as anotações do pod default/onepending-58f8995468-7xcqr
I0205 12:12:57.038908       1 types.go:767] [ControllerName] Anotação 'controller' encontrada para o pod default/onepending-58f8995468-7xcqr: onepending-controller
I0205 12:12:57.038917       1 scheduler.go:605] [GetControllerMetricInfo] Métricas do controlador definidas para o pod: default/onepending-58f8995468-7xcqr
I0205 12:12:57.040723       1 scheduler.go:69] Estado no Informer: map[acceptablePreemptionOverhead:0.05 controller:onepending-controller qosMeasuring:independent slo:0.8]
I0205 12:12:57.040746       1 scheduler.go:70] Estado real no cluster: map[acceptablePreemptionOverhead:0.05 controller:onepending-controller qosMeasuring:independent slo:0.8]
I0205 12:12:57.040752       1 scheduler.go:138] [WaitForPodsOnCache] Pod onepending-58f8995468-7xcqr encontrado no cache.
I0205 12:12:57.040756       1 scheduler.go:116] [WaitForPodsOnCache] Verificando se o pod onepending-58f8995468-cxvtf está no cache...
I0205 12:12:57.040759       1 scheduler.go:597] [GetControllerMetricInfo] Iniciando para o pod: default/onepending-58f8995468-cxvtf
I0205 12:12:57.040763       1 scheduler.go:602] [GetControllerMetricInfo] Obtendo o nome do controlador para o pod: default/onepending-58f8995468-cxvtf
I0205 12:12:57.040766       1 types.go:749] [ControllerName] Verificando as anotações do pod default/onepending-58f8995468-cxvtf
I0205 12:12:57.040769       1 types.go:767] [ControllerName] Anotação 'controller' encontrada para o pod default/onepending-58f8995468-cxvtf: onepending-controller
I0205 12:12:57.040773       1 scheduler.go:605] [GetControllerMetricInfo] Métricas do controlador definidas para o pod: default/onepending-58f8995468-cxvtf
I0205 12:12:57.042024       1 scheduler.go:69] Estado no Informer: map[acceptablePreemptionOverhead:0.05 controller:onepending-controller qosMeasuring:independent slo:0.8]
I0205 12:12:57.042051       1 scheduler.go:70] Estado real no cluster: map[acceptablePreemptionOverhead:0.05 controller:onepending-controller qosMeasuring:independent slo:0.8]
I0205 12:12:57.042057       1 scheduler.go:138] [WaitForPodsOnCache] Pod onepending-58f8995468-cxvtf encontrado no cache.
I0205 12:12:57.042061       1 scheduler.go:597] [GetControllerMetricInfo] Iniciando para o pod: default/onepending-58f8995468-7xcqr
I0205 12:12:57.042065       1 scheduler.go:602] [GetControllerMetricInfo] Obtendo o nome do controlador para o pod: default/onepending-58f8995468-7xcqr
I0205 12:12:57.042068       1 types.go:749] [ControllerName] Verificando as anotações do pod default/onepending-58f8995468-7xcqr
I0205 12:12:57.042072       1 types.go:767] [ControllerName] Anotação 'controller' encontrada para o pod default/onepending-58f8995468-7xcqr: onepending-controller
I0205 12:12:57.042076       1 scheduler.go:605] [GetControllerMetricInfo] Métricas do controlador definidas para o pod: default/onepending-58f8995468-7xcqr
I0205 12:12:57.042082       1 scheduler.go:597] [GetControllerMetricInfo] Iniciando para o pod: default/onepending-58f8995468-cxvtf
I0205 12:12:57.042087       1 scheduler.go:602] [GetControllerMetricInfo] Obtendo o nome do controlador para o pod: default/onepending-58f8995468-cxvtf
I0205 12:12:57.042091       1 types.go:749] [ControllerName] Verificando as anotações do pod default/onepending-58f8995468-cxvtf
I0205 12:12:57.042095       1 types.go:767] [ControllerName] Anotação 'controller' encontrada para o pod default/onepending-58f8995468-cxvtf: onepending-controller
I0205 12:12:57.042100       1 scheduler.go:605] [GetControllerMetricInfo] Métricas do controlador definidas para o pod: default/onepending-58f8995468-cxvtf
I0205 12:12:57.042108       1 scheduler.go:97] [HigherPrecedence] Métricas para onepending-58f8995468-7xcqr: QoS = -23.003329, Importância = 0.80
I0205 12:12:57.042126       1 scheduler.go:98] [HigherPrecedence] Métricas para onepending-58f8995468-cxvtf: QoS = -73.278832, Importância = 0.80
I0205 12:12:57.042133       1 scheduler.go:109] [HigherPrecedence] Decisão final: onepending-58f8995468-7xcqr tem precedência sobre onepending-58f8995468-cxvtf? false
I0205 12:12:57.042157       1 postFilter.go:144] [PREEMPT CALL] No node was chosen to allocate pod onepending-58f8995468-7xcqr
W0205 12:12:57.042204       1 postFilter.go:45] [PostFilter] Nenhum nó nominado após a preempção para o pod: default/onepending-58f8995468-7xcqr
I0205 12:13:24.821930       1 postFilter.go:29] [PostFilter] PostFilter chamado para pod: default/onepending-58f8995468-7xcqr
I0205 12:13:24.821954       1 postFilter.go:76] Comparando pod original com o atualizado...
I0205 12:13:24.821960       1 postFilter.go:83] Successfully retrieved updated pod default/onepending-58f8995468-7xcqr from lister
I0205 12:13:24.824132       1 postFilter.go:226] [compareNodeResources] Recursos calculados no nó minikube: CPU = 8850 mCPU, Memória = 387973120 bytes
I0205 12:13:24.824155       1 postFilter.go:227] [compareNodeResources] Recursos do snapshot no nó minikube: CPU = 8850 mCPU, Memória = 387973120 bytes
I0205 12:13:24.824162       1 postFilter.go:233] [compareNodeResources] Recursos de CPU do nó minikube estão sincronizados: 8850 mCPU
I0205 12:13:24.824169       1 postFilter.go:239] [compareNodeResources] Recursos de memória do nó minikube estão sincronizados: 387973120 bytes
I0205 12:13:24.824280       1 scheduler.go:597] [GetControllerMetricInfo] Iniciando para o pod: default/onepending-58f8995468-cxvtf
I0205 12:13:24.824300       1 scheduler.go:602] [GetControllerMetricInfo] Obtendo o nome do controlador para o pod: default/onepending-58f8995468-cxvtf
I0205 12:13:24.824306       1 types.go:749] [ControllerName] Verificando as anotações do pod default/onepending-58f8995468-cxvtf
I0205 12:13:24.824311       1 types.go:767] [ControllerName] Anotação 'controller' encontrada para o pod default/onepending-58f8995468-cxvtf: onepending-controller
I0205 12:13:24.824317       1 scheduler.go:605] [GetControllerMetricInfo] Métricas do controlador definidas para o pod: default/onepending-58f8995468-cxvtf
I0205 12:13:24.824322       1 scheduler.go:83] [HigherPrecedence] Calculando precedência entre onepending-58f8995468-7xcqr e onepending-58f8995468-cxvtf
I0205 12:13:24.824328       1 scheduler.go:116] [WaitForPodsOnCache] Verificando se o pod onepending-58f8995468-7xcqr está no cache...
I0205 12:13:24.824331       1 scheduler.go:597] [GetControllerMetricInfo] Iniciando para o pod: default/onepending-58f8995468-7xcqr
I0205 12:13:24.824334       1 scheduler.go:602] [GetControllerMetricInfo] Obtendo o nome do controlador para o pod: default/onepending-58f8995468-7xcqr
I0205 12:13:24.824338       1 types.go:749] [ControllerName] Verificando as anotações do pod default/onepending-58f8995468-7xcqr
I0205 12:13:24.824342       1 types.go:767] [ControllerName] Anotação 'controller' encontrada para o pod default/onepending-58f8995468-7xcqr: onepending-controller
I0205 12:13:24.824346       1 scheduler.go:605] [GetControllerMetricInfo] Métricas do controlador definidas para o pod: default/onepending-58f8995468-7xcqr
I0205 12:13:24.826144       1 scheduler.go:69] Estado no Informer: map[acceptablePreemptionOverhead:0.05 controller:onepending-controller qosMeasuring:independent slo:0.8]
I0205 12:13:24.826170       1 scheduler.go:70] Estado real no cluster: map[acceptablePreemptionOverhead:0.05 controller:onepending-controller qosMeasuring:independent slo:0.8]
I0205 12:13:24.826213       1 scheduler.go:138] [WaitForPodsOnCache] Pod onepending-58f8995468-7xcqr encontrado no cache.
I0205 12:13:24.826218       1 scheduler.go:116] [WaitForPodsOnCache] Verificando se o pod onepending-58f8995468-cxvtf está no cache...
I0205 12:13:24.826223       1 scheduler.go:597] [GetControllerMetricInfo] Iniciando para o pod: default/onepending-58f8995468-cxvtf
I0205 12:13:24.826227       1 scheduler.go:602] [GetControllerMetricInfo] Obtendo o nome do controlador para o pod: default/onepending-58f8995468-cxvtf
I0205 12:13:24.826232       1 types.go:749] [ControllerName] Verificando as anotações do pod default/onepending-58f8995468-cxvtf
I0205 12:13:24.826237       1 types.go:767] [ControllerName] Anotação 'controller' encontrada para o pod default/onepending-58f8995468-cxvtf: onepending-controller
I0205 12:13:24.826243       1 scheduler.go:605] [GetControllerMetricInfo] Métricas do controlador definidas para o pod: default/onepending-58f8995468-cxvtf
I0205 12:13:24.827790       1 scheduler.go:69] Estado no Informer: map[acceptablePreemptionOverhead:0.05 controller:onepending-controller qosMeasuring:independent slo:0.8]
I0205 12:13:24.827814       1 scheduler.go:70] Estado real no cluster: map[acceptablePreemptionOverhead:0.05 controller:onepending-controller qosMeasuring:independent slo:0.8]
I0205 12:13:24.827821       1 scheduler.go:138] [WaitForPodsOnCache] Pod onepending-58f8995468-cxvtf encontrado no cache.
I0205 12:13:24.827826       1 scheduler.go:597] [GetControllerMetricInfo] Iniciando para o pod: default/onepending-58f8995468-7xcqr
I0205 12:13:24.827831       1 scheduler.go:602] [GetControllerMetricInfo] Obtendo o nome do controlador para o pod: default/onepending-58f8995468-7xcqr
I0205 12:13:24.827835       1 types.go:749] [ControllerName] Verificando as anotações do pod default/onepending-58f8995468-7xcqr
I0205 12:13:24.827840       1 types.go:767] [ControllerName] Anotação 'controller' encontrada para o pod default/onepending-58f8995468-7xcqr: onepending-controller
I0205 12:13:24.827846       1 scheduler.go:605] [GetControllerMetricInfo] Métricas do controlador definidas para o pod: default/onepending-58f8995468-7xcqr
I0205 12:13:24.827854       1 scheduler.go:597] [GetControllerMetricInfo] Iniciando para o pod: default/onepending-58f8995468-cxvtf
I0205 12:13:24.827859       1 scheduler.go:602] [GetControllerMetricInfo] Obtendo o nome do controlador para o pod: default/onepending-58f8995468-cxvtf
I0205 12:13:24.827864       1 types.go:749] [ControllerName] Verificando as anotações do pod default/onepending-58f8995468-cxvtf
I0205 12:13:24.827869       1 types.go:767] [ControllerName] Anotação 'controller' encontrada para o pod default/onepending-58f8995468-cxvtf: onepending-controller
I0205 12:13:24.827874       1 scheduler.go:605] [GetControllerMetricInfo] Métricas do controlador definidas para o pod: default/onepending-58f8995468-cxvtf
I0205 12:13:24.827882       1 scheduler.go:97] [HigherPrecedence] Métricas para onepending-58f8995468-7xcqr: QoS = -50.788770, Importância = 0.80
I0205 12:13:24.827891       1 scheduler.go:98] [HigherPrecedence] Métricas para onepending-58f8995468-cxvtf: QoS = -66.332472, Importância = 0.80
I0205 12:13:24.827897       1 scheduler.go:109] [HigherPrecedence] Decisão final: onepending-58f8995468-7xcqr tem precedência sobre onepending-58f8995468-cxvtf? false
I0205 12:13:24.827932       1 postFilter.go:144] [PREEMPT CALL] No node was chosen to allocate pod onepending-58f8995468-7xcqr
W0205 12:13:24.827945       1 postFilter.go:45] [PostFilter] Nenhum nó nominado após a preempção para o pod: default/onepending-58f8995468-7xcqr
I0205 12:13:54.822446       1 postFilter.go:29] [PostFilter] PostFilter chamado para pod: default/onepending-58f8995468-7xcqr
I0205 12:13:54.822471       1 postFilter.go:76] Comparando pod original com o atualizado...
I0205 12:13:54.822478       1 postFilter.go:83] Successfully retrieved updated pod default/onepending-58f8995468-7xcqr from lister
I0205 12:13:54.824591       1 postFilter.go:226] [compareNodeResources] Recursos calculados no nó minikube: CPU = 8850 mCPU, Memória = 387973120 bytes
I0205 12:13:54.824616       1 postFilter.go:227] [compareNodeResources] Recursos do snapshot no nó minikube: CPU = 8850 mCPU, Memória = 387973120 bytes
I0205 12:13:54.824623       1 postFilter.go:233] [compareNodeResources] Recursos de CPU do nó minikube estão sincronizados: 8850 mCPU
I0205 12:13:54.824629       1 postFilter.go:239] [compareNodeResources] Recursos de memória do nó minikube estão sincronizados: 387973120 bytes
I0205 12:13:54.824750       1 scheduler.go:597] [GetControllerMetricInfo] Iniciando para o pod: default/onepending-58f8995468-cxvtf
I0205 12:13:54.824767       1 scheduler.go:602] [GetControllerMetricInfo] Obtendo o nome do controlador para o pod: default/onepending-58f8995468-cxvtf
I0205 12:13:54.824771       1 types.go:749] [ControllerName] Verificando as anotações do pod default/onepending-58f8995468-cxvtf
I0205 12:13:54.824775       1 types.go:767] [ControllerName] Anotação 'controller' encontrada para o pod default/onepending-58f8995468-cxvtf: onepending-controller
I0205 12:13:54.824779       1 scheduler.go:605] [GetControllerMetricInfo] Métricas do controlador definidas para o pod: default/onepending-58f8995468-cxvtf
I0205 12:13:54.824784       1 scheduler.go:83] [HigherPrecedence] Calculando precedência entre onepending-58f8995468-7xcqr e onepending-58f8995468-cxvtf
I0205 12:13:54.824787       1 scheduler.go:116] [WaitForPodsOnCache] Verificando se o pod onepending-58f8995468-7xcqr está no cache...
I0205 12:13:54.824790       1 scheduler.go:597] [GetControllerMetricInfo] Iniciando para o pod: default/onepending-58f8995468-7xcqr
I0205 12:13:54.824794       1 scheduler.go:602] [GetControllerMetricInfo] Obtendo o nome do controlador para o pod: default/onepending-58f8995468-7xcqr
I0205 12:13:54.824797       1 types.go:749] [ControllerName] Verificando as anotações do pod default/onepending-58f8995468-7xcqr
I0205 12:13:54.824800       1 types.go:767] [ControllerName] Anotação 'controller' encontrada para o pod default/onepending-58f8995468-7xcqr: onepending-controller
I0205 12:13:54.824804       1 scheduler.go:605] [GetControllerMetricInfo] Métricas do controlador definidas para o pod: default/onepending-58f8995468-7xcqr
I0205 12:13:54.826720       1 scheduler.go:69] Estado no Informer: map[acceptablePreemptionOverhead:0.05 controller:onepending-controller qosMeasuring:independent slo:0.8]
I0205 12:13:54.826742       1 scheduler.go:70] Estado real no cluster: map[acceptablePreemptionOverhead:0.05 controller:onepending-controller qosMeasuring:independent slo:0.8]
I0205 12:13:54.826748       1 scheduler.go:138] [WaitForPodsOnCache] Pod onepending-58f8995468-7xcqr encontrado no cache.
I0205 12:13:54.826751       1 scheduler.go:116] [WaitForPodsOnCache] Verificando se o pod onepending-58f8995468-cxvtf está no cache...
I0205 12:13:54.826754       1 scheduler.go:597] [GetControllerMetricInfo] Iniciando para o pod: default/onepending-58f8995468-cxvtf
I0205 12:13:54.826758       1 scheduler.go:602] [GetControllerMetricInfo] Obtendo o nome do controlador para o pod: default/onepending-58f8995468-cxvtf
I0205 12:13:54.826761       1 types.go:749] [ControllerName] Verificando as anotações do pod default/onepending-58f8995468-cxvtf
I0205 12:13:54.826765       1 types.go:767] [ControllerName] Anotação 'controller' encontrada para o pod default/onepending-58f8995468-cxvtf: onepending-controller
I0205 12:13:54.826768       1 scheduler.go:605] [GetControllerMetricInfo] Métricas do controlador definidas para o pod: default/onepending-58f8995468-cxvtf
I0205 12:13:54.828256       1 scheduler.go:69] Estado no Informer: map[acceptablePreemptionOverhead:0.05 controller:onepending-controller qosMeasuring:independent slo:0.8]
I0205 12:13:54.828293       1 scheduler.go:70] Estado real no cluster: map[acceptablePreemptionOverhead:0.05 controller:onepending-controller qosMeasuring:independent slo:0.8]
I0205 12:13:54.828299       1 scheduler.go:138] [WaitForPodsOnCache] Pod onepending-58f8995468-cxvtf encontrado no cache.
I0205 12:13:54.828304       1 scheduler.go:597] [GetControllerMetricInfo] Iniciando para o pod: default/onepending-58f8995468-7xcqr
I0205 12:13:54.828308       1 scheduler.go:602] [GetControllerMetricInfo] Obtendo o nome do controlador para o pod: default/onepending-58f8995468-7xcqr
I0205 12:13:54.828313       1 types.go:749] [ControllerName] Verificando as anotações do pod default/onepending-58f8995468-7xcqr
I0205 12:13:54.828317       1 types.go:767] [ControllerName] Anotação 'controller' encontrada para o pod default/onepending-58f8995468-7xcqr: onepending-controller
I0205 12:13:54.828322       1 scheduler.go:605] [GetControllerMetricInfo] Métricas do controlador definidas para o pod: default/onepending-58f8995468-7xcqr
I0205 12:13:54.828331       1 scheduler.go:597] [GetControllerMetricInfo] Iniciando para o pod: default/onepending-58f8995468-cxvtf
I0205 12:13:54.828342       1 scheduler.go:602] [GetControllerMetricInfo] Obtendo o nome do controlador para o pod: default/onepending-58f8995468-cxvtf
I0205 12:13:54.828345       1 types.go:749] [ControllerName] Verificando as anotações do pod default/onepending-58f8995468-cxvtf
I0205 12:13:54.828351       1 types.go:767] [ControllerName] Anotação 'controller' encontrada para o pod default/onepending-58f8995468-cxvtf: onepending-controller
I0205 12:13:54.828355       1 scheduler.go:605] [GetControllerMetricInfo] Métricas do controlador definidas para o pod: default/onepending-58f8995468-cxvtf
I0205 12:13:54.828362       1 scheduler.go:97] [HigherPrecedence] Métricas para onepending-58f8995468-7xcqr: QoS = -80.789232, Importância = 0.80
I0205 12:13:54.828377       1 scheduler.go:98] [HigherPrecedence] Métricas para onepending-58f8995468-cxvtf: QoS = -58.832357, Importância = 0.80
I0205 12:13:54.828382       1 scheduler.go:109] [HigherPrecedence] Decisão final: onepending-58f8995468-7xcqr tem precedência sobre onepending-58f8995468-cxvtf? true
I0205 12:13:54.828387       1 types.go:749] [ControllerName] Verificando as anotações do pod default/onepending-58f8995468-7xcqr
I0205 12:13:54.828390       1 types.go:767] [ControllerName] Anotação 'controller' encontrada para o pod default/onepending-58f8995468-7xcqr: onepending-controller
I0205 12:13:54.828395       1 types.go:749] [ControllerName] Verificando as anotações do pod default/onepending-58f8995468-cxvtf
I0205 12:13:54.828398       1 types.go:767] [ControllerName] Anotação 'controller' encontrada para o pod default/onepending-58f8995468-cxvtf: onepending-controller
I0205 12:13:54.828402       1 scheduler.go:597] [GetControllerMetricInfo] Iniciando para o pod: default/onepending-58f8995468-cxvtf
I0205 12:13:54.828406       1 scheduler.go:602] [GetControllerMetricInfo] Obtendo o nome do controlador para o pod: default/onepending-58f8995468-cxvtf
I0205 12:13:54.828410       1 types.go:749] [ControllerName] Verificando as anotações do pod default/onepending-58f8995468-cxvtf
I0205 12:13:54.828413       1 types.go:767] [ControllerName] Anotação 'controller' encontrada para o pod default/onepending-58f8995468-cxvtf: onepending-controller
I0205 12:13:54.828418       1 scheduler.go:605] [GetControllerMetricInfo] Métricas do controlador definidas para o pod: default/onepending-58f8995468-cxvtf
I0205 12:13:54.828422       1 scheduler.go:597] [GetControllerMetricInfo] Iniciando para o pod: default/onepending-58f8995468-cxvtf
I0205 12:13:54.828425       1 scheduler.go:602] [GetControllerMetricInfo] Obtendo o nome do controlador para o pod: default/onepending-58f8995468-cxvtf
I0205 12:13:54.828428       1 types.go:749] [ControllerName] Verificando as anotações do pod default/onepending-58f8995468-cxvtf
I0205 12:13:54.828431       1 types.go:767] [ControllerName] Anotação 'controller' encontrada para o pod default/onepending-58f8995468-cxvtf: onepending-controller
I0205 12:13:54.828435       1 scheduler.go:605] [GetControllerMetricInfo] Métricas do controlador definidas para o pod: default/onepending-58f8995468-cxvtf
I0205 12:13:54.828439       1 types.go:749] [ControllerName] Verificando as anotações do pod default/onepending-58f8995468-cxvtf
I0205 12:13:54.828443       1 types.go:767] [ControllerName] Anotação 'controller' encontrada para o pod default/onepending-58f8995468-cxvtf: onepending-controller
I0205 12:13:54.828498       1 scheduler.go:597] [GetControllerMetricInfo] Iniciando para o pod: default/onepending-58f8995468-cxvtf
I0205 12:13:54.828512       1 scheduler.go:602] [GetControllerMetricInfo] Obtendo o nome do controlador para o pod: default/onepending-58f8995468-cxvtf
I0205 12:13:54.828514       1 types.go:749] [ControllerName] Verificando as anotações do pod default/onepending-58f8995468-cxvtf
I0205 12:13:54.828518       1 types.go:767] [ControllerName] Anotação 'controller' encontrada para o pod default/onepending-58f8995468-cxvtf: onepending-controller
I0205 12:13:54.828521       1 scheduler.go:605] [GetControllerMetricInfo] Métricas do controlador definidas para o pod: default/onepending-58f8995468-cxvtf
I0205 12:13:54.828527       1 scheduler.go:597] [GetControllerMetricInfo] Iniciando para o pod: default/onepending-58f8995468-cxvtf
I0205 12:13:54.828530       1 scheduler.go:602] [GetControllerMetricInfo] Obtendo o nome do controlador para o pod: default/onepending-58f8995468-cxvtf
I0205 12:13:54.828533       1 types.go:749] [ControllerName] Verificando as anotações do pod default/onepending-58f8995468-cxvtf
I0205 12:13:54.828536       1 types.go:767] [ControllerName] Anotação 'controller' encontrada para o pod default/onepending-58f8995468-cxvtf: onepending-controller
I0205 12:13:54.828540       1 scheduler.go:605] [GetControllerMetricInfo] Métricas do controlador definidas para o pod: default/onepending-58f8995468-cxvtf
I0205 12:13:54.828551       1 postFilter.go:147] [PREEMPT CALL] The node minikube  was chosen to allocate pod onepending-58f8995468-7xcqr
I0205 12:13:54.828557       1 postFilter.go:151] [Preempt] Iniciando a remoção dos pods preemptados no nó minikube para alocar o pod default/onepending-58f8995468-7xcqr. Total de vítimas: 1
I0205 12:13:54.828565       1 postFilter.go:155] [Preempt] Tentando remover o pod default/onepending-58f8995468-cxvtf no nó minikube
I0205 12:13:54.834806       1 scheduler.go:252] [OnUpdatePod] Iniciando processamento de atualização de pod
I0205 12:13:54.834842       1 scheduler.go:256] [OnUpdatePod] Pod atualizado detectado: default/onepending-58f8995468-cxvtf, Anotações: map[acceptablePreemptionOverhead:0.05 controller:onepending-controller qosMeasuring:independent slo:0.8]
I0205 12:13:54.834855       1 scheduler.go:259] [OnUpdatePod] Comparando estado no Informer e estado real no cluster para o pod default/onepending-58f8995468-cxvtf
I0205 12:13:54.837144       1 scheduler.go:69] Estado no Informer: map[acceptablePreemptionOverhead:0.05 controller:onepending-controller qosMeasuring:independent slo:0.8]
I0205 12:13:54.837216       1 scheduler.go:70] Estado real no cluster: map[acceptablePreemptionOverhead:0.05 controller:onepending-controller qosMeasuring:independent slo:0.8]
I0205 12:13:54.837228       1 scheduler.go:269] [OnUpdatePod] Atualizando informações de métricas para o pod default/onepending-58f8995468-cxvtf
I0205 12:13:54.837234       1 types.go:749] [ControllerName] Verificando as anotações do pod default/onepending-58f8995468-cxvtf
I0205 12:13:54.837242       1 types.go:767] [ControllerName] Anotação 'controller' encontrada para o pod default/onepending-58f8995468-cxvtf: onepending-controller
I0205 12:13:54.837250       1 scheduler.go:271] [OnUpdatePod] Atualizando 'LastStatus' do pod default/onepending-58f8995468-cxvtf nas métricas
I0205 12:13:54.837254       1 scheduler.go:273] [OnUpdatePod] Métrica atualizada para o pod default/onepending-58f8995468-cxvtf
I0205 12:13:54.837280       1 scheduler.go:277] [OnUpdatePod] Finalizando processamento de atualização de pod para default/onepending-58f8995468-cxvtf
I0205 12:13:54.837296       1 types.go:749] [ControllerName] Verificando as anotações do pod default/onepending-58f8995468-cxvtf
I0205 12:13:54.837305       1 types.go:767] [ControllerName] Anotação 'controller' encontrada para o pod default/onepending-58f8995468-cxvtf: onepending-controller
I0205 12:13:54.837316       1 types.go:532] [QoS DEBUG] effectiveRunning: 60.010575 | discardedRunning: 0.000000 | waiting: 73.821596 | binding: 0.005136 | denominator: 133.837308
I0205 12:13:54.837336       1 types.go:538] [QoS DEBUG] QoS calculado: 0.448385
I0205 12:13:54.838492       1 postFilter.go:161] [Preempt] Pod default/onepending-58f8995468-cxvtf removido com sucesso no nó minikube
I0205 12:13:54.838525       1 postFilter.go:167] onepending-58f8995468-cxvtf_default preempted by onepending-58f8995468-7xcqr_default on node minikube
I0205 12:13:54.838563       1 postFilter.go:172] [Preempt] Total de pods preemptados no nó minikube: 1
I0205 12:13:54.838577       1 postFilter.go:179] [Preempt] Verificando pods de menor precedência no nó minikube que precisam ter o campo NominatedNodeName limpo
I0205 12:13:54.838588       1 postFilter.go:189] [Preempt] Finalizado para o nó minikube. Pod default/onepending-58f8995468-7xcqr deve ser alocado agora.
I0205 12:13:54.838605       1 postFilter.go:49] [PostFilter] Nó nominado para o pod default/onepending-58f8995468-7xcqr: minikube
I0205 12:13:54.838607       1 scheduler.go:282] [OnDeletePod] Iniciando a execução do OnDeletePod
I0205 12:13:54.838663       1 scheduler.go:291] [OnDeletePod] DeepCopy realizado para o pod default/onepending-58f8995468-cxvtf
I0205 12:13:54.839005       1 scheduler.go:298] [OnDeletePod] Pod deletado detectado: default/onepending-58f8995468-cxvtf
I0205 12:13:54.839078       1 scheduler.go:300] [OnDeletePod] Atualizando métricas do pod default/onepending-58f8995468-cxvtf
I0205 12:13:54.839094       1 types.go:749] [ControllerName] Verificando as anotações do pod default/onepending-58f8995468-cxvtf
I0205 12:13:54.839099       1 types.go:767] [ControllerName] Anotação 'controller' encontrada para o pod default/onepending-58f8995468-cxvtf: onepending-controller
I0205 12:13:54.839107       1 scheduler.go:302] [OnDeletePod] Verificando o estado do pod default/onepending-58f8995468-cxvtf nas métricas
I0205 12:13:54.839112       1 scheduler.go:312] [OnDeletePod] EndTime atualizado para o pod default/onepending-58f8995468-cxvtf: 2025-02-05 12:13:54.839109797 +0000 UTC m=+421.157113358
I0205 12:13:54.839125       1 scheduler.go:316] [OnDeletePod] Finalizando a execução do OnDeletePod para o pod default/onepending-58f8995468-cxvtf
I0205 12:13:54.847461       1 scheduler.go:252] [OnUpdatePod] Iniciando processamento de atualização de pod
I0205 12:13:54.847522       1 scheduler.go:256] [OnUpdatePod] Pod atualizado detectado: default/onepending-58f8995468-7xcqr, Anotações: map[acceptablePreemptionOverhead:0.05 controller:onepending-controller qosMeasuring:independent slo:0.8]
I0205 12:13:54.847542       1 scheduler.go:259] [OnUpdatePod] Comparando estado no Informer e estado real no cluster para o pod default/onepending-58f8995468-7xcqr
I0205 12:13:54.850440       1 postFilter.go:29] [PostFilter] PostFilter chamado para pod: default/onepending-58f8995468-vx5mn
I0205 12:13:54.850466       1 postFilter.go:76] Comparando pod original com o atualizado...
I0205 12:13:54.850474       1 postFilter.go:83] Successfully retrieved updated pod default/onepending-58f8995468-vx5mn from lister
I0205 12:13:54.850436       1 scheduler.go:69] Estado no Informer: map[acceptablePreemptionOverhead:0.05 controller:onepending-controller qosMeasuring:independent slo:0.8]
I0205 12:13:54.850628       1 scheduler.go:70] Estado real no cluster: map[acceptablePreemptionOverhead:0.05 controller:onepending-controller qosMeasuring:independent slo:0.8]
I0205 12:13:54.850639       1 scheduler.go:269] [OnUpdatePod] Atualizando informações de métricas para o pod default/onepending-58f8995468-7xcqr
I0205 12:13:54.850645       1 types.go:749] [ControllerName] Verificando as anotações do pod default/onepending-58f8995468-7xcqr
I0205 12:13:54.850650       1 types.go:767] [ControllerName] Anotação 'controller' encontrada para o pod default/onepending-58f8995468-7xcqr: onepending-controller
I0205 12:13:54.850657       1 scheduler.go:271] [OnUpdatePod] Atualizando 'LastStatus' do pod default/onepending-58f8995468-7xcqr nas métricas
I0205 12:13:54.850661       1 scheduler.go:273] [OnUpdatePod] Métrica atualizada para o pod default/onepending-58f8995468-7xcqr
I0205 12:13:54.850669       1 scheduler.go:277] [OnUpdatePod] Finalizando processamento de atualização de pod para default/onepending-58f8995468-7xcqr
I0205 12:13:54.850688       1 scheduler.go:214] [OnAddPod] Pod adicionado: default/onepending-58f8995468-vx5mn, Anotações: map[acceptablePreemptionOverhead:0.05 controller:onepending-controller qosMeasuring:independent slo:0.8]
I0205 12:13:54.852647       1 scheduler.go:69] Estado no Informer: map[acceptablePreemptionOverhead:0.05 controller:onepending-controller qosMeasuring:independent slo:0.8]
I0205 12:13:54.852677       1 scheduler.go:70] Estado real no cluster: map[acceptablePreemptionOverhead:0.05 controller:onepending-controller qosMeasuring:independent slo:0.8]
I0205 12:13:54.852749       1 postFilter.go:226] [compareNodeResources] Recursos calculados no nó minikube: CPU = 850 mCPU, Memória = 387973120 bytes
I0205 12:13:54.852770       1 postFilter.go:227] [compareNodeResources] Recursos do snapshot no nó minikube: CPU = 850 mCPU, Memória = 387973120 bytes
I0205 12:13:54.852777       1 postFilter.go:233] [compareNodeResources] Recursos de CPU do nó minikube estão sincronizados: 850 mCPU
I0205 12:13:54.852784       1 postFilter.go:239] [compareNodeResources] Recursos de memória do nó minikube estão sincronizados: 387973120 bytes
I0205 12:13:54.852864       1 scheduler.go:225] [OnAddPod] Adicionando pod default/onepending-58f8995468-vx5mn com os seguintes detalhes:
I0205 12:13:54.852889       1 types.go:749] [ControllerName] Verificando as anotações do pod default/onepending-58f8995468-vx5mn
I0205 12:13:54.852894       1 types.go:767] [ControllerName] Anotação 'controller' encontrada para o pod default/onepending-58f8995468-vx5mn: onepending-controller
I0205 12:13:54.852901       1 scheduler.go:234] [OnAddPod] Atualizando métricas para o pod default/onepending-58f8995468-vx5mn
I0205 12:13:54.852904       1 types.go:749] [ControllerName] Verificando as anotações do pod default/onepending-58f8995468-vx5mn
I0205 12:13:54.852915       1 types.go:767] [ControllerName] Anotação 'controller' encontrada para o pod default/onepending-58f8995468-vx5mn: onepending-controller
I0205 12:13:54.852924       1 scheduler.go:247] [OnAddPod] Pod default/onepending-58f8995468-vx5mn adicionado com sucesso
I0205 12:13:54.852974       1 postFilter.go:147] [PREEMPT CALL] The node minikube  was chosen to allocate pod onepending-58f8995468-vx5mn
I0205 12:13:54.852994       1 postFilter.go:151] [Preempt] Iniciando a remoção dos pods preemptados no nó minikube para alocar o pod default/onepending-58f8995468-vx5mn. Total de vítimas: 0
I0205 12:13:54.853007       1 postFilter.go:172] [Preempt] Total de pods preemptados no nó minikube: 0
I0205 12:13:54.853041       1 scheduler.go:83] [HigherPrecedence] Calculando precedência entre onepending-58f8995468-vx5mn e onepending-58f8995468-7xcqr
I0205 12:13:54.853057       1 scheduler.go:116] [WaitForPodsOnCache] Verificando se o pod onepending-58f8995468-vx5mn está no cache...
I0205 12:13:54.853062       1 scheduler.go:597] [GetControllerMetricInfo] Iniciando para o pod: default/onepending-58f8995468-vx5mn
I0205 12:13:54.853067       1 scheduler.go:602] [GetControllerMetricInfo] Obtendo o nome do controlador para o pod: default/onepending-58f8995468-vx5mn
I0205 12:13:54.853071       1 types.go:749] [ControllerName] Verificando as anotações do pod default/onepending-58f8995468-vx5mn
I0205 12:13:54.853076       1 types.go:767] [ControllerName] Anotação 'controller' encontrada para o pod default/onepending-58f8995468-vx5mn: onepending-controller
I0205 12:13:54.853081       1 scheduler.go:605] [GetControllerMetricInfo] Métricas do controlador definidas para o pod: default/onepending-58f8995468-vx5mn
I0205 12:13:54.857486       1 scheduler.go:69] Estado no Informer: map[acceptablePreemptionOverhead:0.05 controller:onepending-controller qosMeasuring:independent slo:0.8]
I0205 12:13:54.857524       1 scheduler.go:70] Estado real no cluster: map[acceptablePreemptionOverhead:0.05 controller:onepending-controller qosMeasuring:independent slo:0.8]
I0205 12:13:54.857532       1 scheduler.go:138] [WaitForPodsOnCache] Pod onepending-58f8995468-vx5mn encontrado no cache.
I0205 12:13:54.857537       1 scheduler.go:116] [WaitForPodsOnCache] Verificando se o pod onepending-58f8995468-7xcqr está no cache...
I0205 12:13:54.857542       1 scheduler.go:597] [GetControllerMetricInfo] Iniciando para o pod: default/onepending-58f8995468-7xcqr
I0205 12:13:54.857547       1 scheduler.go:602] [GetControllerMetricInfo] Obtendo o nome do controlador para o pod: default/onepending-58f8995468-7xcqr
I0205 12:13:54.857560       1 types.go:749] [ControllerName] Verificando as anotações do pod default/onepending-58f8995468-7xcqr
I0205 12:13:54.857566       1 types.go:767] [ControllerName] Anotação 'controller' encontrada para o pod default/onepending-58f8995468-7xcqr: onepending-controller
I0205 12:13:54.857571       1 scheduler.go:605] [GetControllerMetricInfo] Métricas do controlador definidas para o pod: default/onepending-58f8995468-7xcqr
I0205 12:13:54.859274       1 scheduler.go:69] Estado no Informer: map[acceptablePreemptionOverhead:0.05 controller:onepending-controller qosMeasuring:independent slo:0.8]
I0205 12:13:54.859302       1 scheduler.go:70] Estado real no cluster: map[acceptablePreemptionOverhead:0.05 controller:onepending-controller qosMeasuring:independent slo:0.8]
I0205 12:13:54.859309       1 scheduler.go:138] [WaitForPodsOnCache] Pod onepending-58f8995468-7xcqr encontrado no cache.
I0205 12:13:54.859314       1 scheduler.go:597] [GetControllerMetricInfo] Iniciando para o pod: default/onepending-58f8995468-vx5mn
I0205 12:13:54.859318       1 scheduler.go:602] [GetControllerMetricInfo] Obtendo o nome do controlador para o pod: default/onepending-58f8995468-vx5mn
I0205 12:13:54.859323       1 types.go:749] [ControllerName] Verificando as anotações do pod default/onepending-58f8995468-vx5mn
I0205 12:13:54.859327       1 types.go:767] [ControllerName] Anotação 'controller' encontrada para o pod default/onepending-58f8995468-vx5mn: onepending-controller
I0205 12:13:54.859331       1 scheduler.go:605] [GetControllerMetricInfo] Métricas do controlador definidas para o pod: default/onepending-58f8995468-vx5mn
I0205 12:13:54.859339       1 scheduler.go:597] [GetControllerMetricInfo] Iniciando para o pod: default/onepending-58f8995468-7xcqr
I0205 12:13:54.859343       1 scheduler.go:602] [GetControllerMetricInfo] Obtendo o nome do controlador para o pod: default/onepending-58f8995468-7xcqr
I0205 12:13:54.859347       1 types.go:749] [ControllerName] Verificando as anotações do pod default/onepending-58f8995468-7xcqr
I0205 12:13:54.859351       1 types.go:767] [ControllerName] Anotação 'controller' encontrada para o pod default/onepending-58f8995468-7xcqr: onepending-controller
I0205 12:13:54.859356       1 scheduler.go:605] [GetControllerMetricInfo] Métricas do controlador definidas para o pod: default/onepending-58f8995468-7xcqr
I0205 12:13:54.859365       1 scheduler.go:97] [HigherPrecedence] Métricas para onepending-58f8995468-vx5mn: QoS = -59.679245, Importância = 0.80
I0205 12:13:54.859383       1 scheduler.go:98] [HigherPrecedence] Métricas para onepending-58f8995468-7xcqr: QoS = -80.817489, Importância = 0.80
I0205 12:13:54.859389       1 scheduler.go:109] [HigherPrecedence] Decisão final: onepending-58f8995468-vx5mn tem precedência sobre onepending-58f8995468-7xcqr? false
I0205 12:13:54.859402       1 postFilter.go:179] [Preempt] Verificando pods de menor precedência no nó minikube que precisam ter o campo NominatedNodeName limpo
I0205 12:13:54.859422       1 postFilter.go:189] [Preempt] Finalizado para o nó minikube. Pod default/onepending-58f8995468-vx5mn deve ser alocado agora.
I0205 12:13:54.859428       1 postFilter.go:49] [PostFilter] Nó nominado para o pod default/onepending-58f8995468-vx5mn: minikube
I0205 12:13:54.867874       1 scheduler.go:252] [OnUpdatePod] Iniciando processamento de atualização de pod
I0205 12:13:54.867912       1 scheduler.go:256] [OnUpdatePod] Pod atualizado detectado: default/onepending-58f8995468-vx5mn, Anotações: map[acceptablePreemptionOverhead:0.05 controller:onepending-controller qosMeasuring:independent slo:0.8]
I0205 12:13:54.867926       1 scheduler.go:259] [OnUpdatePod] Comparando estado no Informer e estado real no cluster para o pod default/onepending-58f8995468-vx5mn
I0205 12:13:54.870979       1 scheduler.go:69] Estado no Informer: map[acceptablePreemptionOverhead:0.05 controller:onepending-controller qosMeasuring:independent slo:0.8]
I0205 12:13:54.871008       1 scheduler.go:70] Estado real no cluster: map[acceptablePreemptionOverhead:0.05 controller:onepending-controller qosMeasuring:independent slo:0.8]
I0205 12:13:54.871016       1 scheduler.go:269] [OnUpdatePod] Atualizando informações de métricas para o pod default/onepending-58f8995468-vx5mn
I0205 12:13:54.871021       1 types.go:749] [ControllerName] Verificando as anotações do pod default/onepending-58f8995468-vx5mn
I0205 12:13:54.871025       1 types.go:767] [ControllerName] Anotação 'controller' encontrada para o pod default/onepending-58f8995468-vx5mn: onepending-controller
I0205 12:13:54.871032       1 scheduler.go:271] [OnUpdatePod] Atualizando 'LastStatus' do pod default/onepending-58f8995468-vx5mn nas métricas
I0205 12:13:54.871035       1 scheduler.go:273] [OnUpdatePod] Métrica atualizada para o pod default/onepending-58f8995468-vx5mn
I0205 12:13:54.871042       1 scheduler.go:277] [OnUpdatePod] Finalizando processamento de atualização de pod para default/onepending-58f8995468-vx5mn
I0205 12:14:05.080024       1 postFilter.go:29] [PostFilter] PostFilter chamado para pod: default/onepending-58f8995468-7xcqr
I0205 12:14:05.080056       1 postFilter.go:76] Comparando pod original com o atualizado...
I0205 12:14:05.080062       1 postFilter.go:83] Successfully retrieved updated pod default/onepending-58f8995468-7xcqr from lister
I0205 12:14:05.082245       1 postFilter.go:226] [compareNodeResources] Recursos calculados no nó minikube: CPU = 850 mCPU, Memória = 387973120 bytes
I0205 12:14:05.082271       1 postFilter.go:227] [compareNodeResources] Recursos do snapshot no nó minikube: CPU = 850 mCPU, Memória = 387973120 bytes
I0205 12:14:05.082276       1 postFilter.go:233] [compareNodeResources] Recursos de CPU do nó minikube estão sincronizados: 850 mCPU
I0205 12:14:05.082281       1 postFilter.go:239] [compareNodeResources] Recursos de memória do nó minikube estão sincronizados: 387973120 bytes
I0205 12:14:05.082388       1 postFilter.go:147] [PREEMPT CALL] The node minikube  was chosen to allocate pod onepending-58f8995468-7xcqr
I0205 12:14:05.082403       1 postFilter.go:151] [Preempt] Iniciando a remoção dos pods preemptados no nó minikube para alocar o pod default/onepending-58f8995468-7xcqr. Total de vítimas: 0
I0205 12:14:05.082413       1 postFilter.go:172] [Preempt] Total de pods preemptados no nó minikube: 0
W0205 12:14:05.082442       1 scheduler.go:78] [HigherPrecedence] Tentativa de comparar o pod onepending-58f8995468-7xcqr consigo mesmo. Retornando false.
I0205 12:14:05.082452       1 scheduler.go:83] [HigherPrecedence] Calculando precedência entre onepending-58f8995468-7xcqr e onepending-58f8995468-vx5mn
I0205 12:14:05.082456       1 scheduler.go:116] [WaitForPodsOnCache] Verificando se o pod onepending-58f8995468-7xcqr está no cache...
I0205 12:14:05.082460       1 scheduler.go:597] [GetControllerMetricInfo] Iniciando para o pod: default/onepending-58f8995468-7xcqr
I0205 12:14:05.082464       1 scheduler.go:602] [GetControllerMetricInfo] Obtendo o nome do controlador para o pod: default/onepending-58f8995468-7xcqr
I0205 12:14:05.082468       1 types.go:749] [ControllerName] Verificando as anotações do pod default/onepending-58f8995468-7xcqr
I0205 12:14:05.082472       1 types.go:767] [ControllerName] Anotação 'controller' encontrada para o pod default/onepending-58f8995468-7xcqr: onepending-controller
I0205 12:14:05.082477       1 scheduler.go:605] [GetControllerMetricInfo] Métricas do controlador definidas para o pod: default/onepending-58f8995468-7xcqr
I0205 12:14:05.083983       1 scheduler.go:69] Estado no Informer: map[acceptablePreemptionOverhead:0.05 controller:onepending-controller qosMeasuring:independent slo:0.8]
I0205 12:14:05.084009       1 scheduler.go:70] Estado real no cluster: map[acceptablePreemptionOverhead:0.05 controller:onepending-controller qosMeasuring:independent slo:0.8]
I0205 12:14:05.084014       1 scheduler.go:138] [WaitForPodsOnCache] Pod onepending-58f8995468-7xcqr encontrado no cache.
I0205 12:14:05.084018       1 scheduler.go:116] [WaitForPodsOnCache] Verificando se o pod onepending-58f8995468-vx5mn está no cache...
I0205 12:14:05.084021       1 scheduler.go:597] [GetControllerMetricInfo] Iniciando para o pod: default/onepending-58f8995468-vx5mn
I0205 12:14:05.084025       1 scheduler.go:602] [GetControllerMetricInfo] Obtendo o nome do controlador para o pod: default/onepending-58f8995468-vx5mn
I0205 12:14:05.084028       1 types.go:749] [ControllerName] Verificando as anotações do pod default/onepending-58f8995468-vx5mn
I0205 12:14:05.084032       1 types.go:767] [ControllerName] Anotação 'controller' encontrada para o pod default/onepending-58f8995468-vx5mn: onepending-controller
I0205 12:14:05.084036       1 scheduler.go:605] [GetControllerMetricInfo] Métricas do controlador definidas para o pod: default/onepending-58f8995468-vx5mn
I0205 12:14:05.085774       1 scheduler.go:69] Estado no Informer: map[acceptablePreemptionOverhead:0.05 controller:onepending-controller qosMeasuring:independent slo:0.8]
I0205 12:14:05.085795       1 scheduler.go:70] Estado real no cluster: map[acceptablePreemptionOverhead:0.05 controller:onepending-controller qosMeasuring:independent slo:0.8]
I0205 12:14:05.085801       1 scheduler.go:138] [WaitForPodsOnCache] Pod onepending-58f8995468-vx5mn encontrado no cache.
I0205 12:14:05.085805       1 scheduler.go:597] [GetControllerMetricInfo] Iniciando para o pod: default/onepending-58f8995468-7xcqr
I0205 12:14:05.085809       1 scheduler.go:602] [GetControllerMetricInfo] Obtendo o nome do controlador para o pod: default/onepending-58f8995468-7xcqr
I0205 12:14:05.085812       1 types.go:749] [ControllerName] Verificando as anotações do pod default/onepending-58f8995468-7xcqr
I0205 12:14:05.085816       1 types.go:767] [ControllerName] Anotação 'controller' encontrada para o pod default/onepending-58f8995468-7xcqr: onepending-controller
I0205 12:14:05.085820       1 scheduler.go:605] [GetControllerMetricInfo] Métricas do controlador definidas para o pod: default/onepending-58f8995468-7xcqr
I0205 12:14:05.085826       1 scheduler.go:597] [GetControllerMetricInfo] Iniciando para o pod: default/onepending-58f8995468-vx5mn
I0205 12:14:05.085830       1 scheduler.go:602] [GetControllerMetricInfo] Obtendo o nome do controlador para o pod: default/onepending-58f8995468-vx5mn
I0205 12:14:05.085833       1 types.go:749] [ControllerName] Verificando as anotações do pod default/onepending-58f8995468-vx5mn
I0205 12:14:05.085836       1 types.go:767] [ControllerName] Anotação 'controller' encontrada para o pod default/onepending-58f8995468-vx5mn: onepending-controller
I0205 12:14:05.085840       1 scheduler.go:605] [GetControllerMetricInfo] Métricas do controlador definidas para o pod: default/onepending-58f8995468-vx5mn
I0205 12:14:05.085847       1 scheduler.go:97] [HigherPrecedence] Métricas para onepending-58f8995468-7xcqr: QoS = -91.046901, Importância = 0.80
I0205 12:14:05.085861       1 scheduler.go:98] [HigherPrecedence] Métricas para onepending-58f8995468-vx5mn: QoS = -69.908657, Importância = 0.80
I0205 12:14:05.085866       1 scheduler.go:109] [HigherPrecedence] Decisão final: onepending-58f8995468-7xcqr tem precedência sobre onepending-58f8995468-vx5mn? true
I0205 12:14:05.085875       1 postFilter.go:179] [Preempt] Verificando pods de menor precedência no nó minikube que precisam ter o campo NominatedNodeName limpo
I0205 12:14:05.085886       1 postFilter.go:181] [Preempt] Limpando o campo NominatedNodeName do pod default/onepending-58f8995468-vx5mn
I0205 12:14:05.093569       1 scheduler.go:252] [OnUpdatePod] Iniciando processamento de atualização de pod
I0205 12:14:05.093633       1 scheduler.go:256] [OnUpdatePod] Pod atualizado detectado: default/onepending-58f8995468-vx5mn, Anotações: map[acceptablePreemptionOverhead:0.05 controller:onepending-controller qosMeasuring:independent slo:0.8]
I0205 12:14:05.093652       1 scheduler.go:259] [OnUpdatePod] Comparando estado no Informer e estado real no cluster para o pod default/onepending-58f8995468-vx5mn
I0205 12:14:05.093700       1 postFilter.go:189] [Preempt] Finalizado para o nó minikube. Pod default/onepending-58f8995468-7xcqr deve ser alocado agora.
I0205 12:14:05.093727       1 postFilter.go:49] [PostFilter] Nó nominado para o pod default/onepending-58f8995468-7xcqr: minikube
I0205 12:14:05.095492       1 scheduler.go:69] Estado no Informer: map[acceptablePreemptionOverhead:0.05 controller:onepending-controller qosMeasuring:independent slo:0.8]
I0205 12:14:05.095521       1 scheduler.go:70] Estado real no cluster: map[acceptablePreemptionOverhead:0.05 controller:onepending-controller qosMeasuring:independent slo:0.8]
I0205 12:14:05.095529       1 scheduler.go:269] [OnUpdatePod] Atualizando informações de métricas para o pod default/onepending-58f8995468-vx5mn
I0205 12:14:05.095534       1 types.go:749] [ControllerName] Verificando as anotações do pod default/onepending-58f8995468-vx5mn
I0205 12:14:05.095539       1 types.go:767] [ControllerName] Anotação 'controller' encontrada para o pod default/onepending-58f8995468-vx5mn: onepending-controller
I0205 12:14:05.095545       1 scheduler.go:271] [OnUpdatePod] Atualizando 'LastStatus' do pod default/onepending-58f8995468-vx5mn nas métricas
I0205 12:14:05.095548       1 scheduler.go:273] [OnUpdatePod] Métrica atualizada para o pod default/onepending-58f8995468-vx5mn
I0205 12:14:05.095554       1 scheduler.go:277] [OnUpdatePod] Finalizando processamento de atualização de pod para default/onepending-58f8995468-vx5mn
I0205 12:14:24.822999       1 scheduler.go:53] [QueueSort] Comparando prioridade de onepending-58f8995468-vx5mn com onepending-58f8995468-7xcqr
I0205 12:14:24.823027       1 scheduler.go:83] [HigherPrecedence] Calculando precedência entre onepending-58f8995468-vx5mn e onepending-58f8995468-7xcqr
I0205 12:14:24.823033       1 scheduler.go:116] [WaitForPodsOnCache] Verificando se o pod onepending-58f8995468-vx5mn está no cache...
I0205 12:14:24.823038       1 scheduler.go:597] [GetControllerMetricInfo] Iniciando para o pod: default/onepending-58f8995468-vx5mn
I0205 12:14:24.823043       1 scheduler.go:602] [GetControllerMetricInfo] Obtendo o nome do controlador para o pod: default/onepending-58f8995468-vx5mn
I0205 12:14:24.823048       1 types.go:749] [ControllerName] Verificando as anotações do pod default/onepending-58f8995468-vx5mn
I0205 12:14:24.823056       1 types.go:767] [ControllerName] Anotação 'controller' encontrada para o pod default/onepending-58f8995468-vx5mn: onepending-controller
I0205 12:14:24.823062       1 scheduler.go:605] [GetControllerMetricInfo] Métricas do controlador definidas para o pod: default/onepending-58f8995468-vx5mn
I0205 12:14:24.825451       1 scheduler.go:69] Estado no Informer: map[acceptablePreemptionOverhead:0.05 controller:onepending-controller qosMeasuring:independent slo:0.8]
I0205 12:14:24.825542       1 scheduler.go:70] Estado real no cluster: map[acceptablePreemptionOverhead:0.05 controller:onepending-controller qosMeasuring:independent slo:0.8]
I0205 12:14:24.825555       1 scheduler.go:138] [WaitForPodsOnCache] Pod onepending-58f8995468-vx5mn encontrado no cache.
I0205 12:14:24.825559       1 scheduler.go:116] [WaitForPodsOnCache] Verificando se o pod onepending-58f8995468-7xcqr está no cache...
I0205 12:14:24.825564       1 scheduler.go:597] [GetControllerMetricInfo] Iniciando para o pod: default/onepending-58f8995468-7xcqr
I0205 12:14:24.825569       1 scheduler.go:602] [GetControllerMetricInfo] Obtendo o nome do controlador para o pod: default/onepending-58f8995468-7xcqr
I0205 12:14:24.825573       1 types.go:749] [ControllerName] Verificando as anotações do pod default/onepending-58f8995468-7xcqr
I0205 12:14:24.825579       1 types.go:767] [ControllerName] Anotação 'controller' encontrada para o pod default/onepending-58f8995468-7xcqr: onepending-controller
I0205 12:14:24.825585       1 scheduler.go:605] [GetControllerMetricInfo] Métricas do controlador definidas para o pod: default/onepending-58f8995468-7xcqr
I0205 12:14:24.827348       1 scheduler.go:69] Estado no Informer: map[acceptablePreemptionOverhead:0.05 controller:onepending-controller qosMeasuring:independent slo:0.8]
I0205 12:14:24.827373       1 scheduler.go:70] Estado real no cluster: map[acceptablePreemptionOverhead:0.05 controller:onepending-controller qosMeasuring:independent slo:0.8]
I0205 12:14:24.827381       1 scheduler.go:138] [WaitForPodsOnCache] Pod onepending-58f8995468-7xcqr encontrado no cache.
I0205 12:14:24.827385       1 scheduler.go:597] [GetControllerMetricInfo] Iniciando para o pod: default/onepending-58f8995468-vx5mn
I0205 12:14:24.827390       1 scheduler.go:602] [GetControllerMetricInfo] Obtendo o nome do controlador para o pod: default/onepending-58f8995468-vx5mn
I0205 12:14:24.827395       1 types.go:749] [ControllerName] Verificando as anotações do pod default/onepending-58f8995468-vx5mn
I0205 12:14:24.827401       1 types.go:767] [ControllerName] Anotação 'controller' encontrada para o pod default/onepending-58f8995468-vx5mn: onepending-controller
I0205 12:14:24.827406       1 scheduler.go:605] [GetControllerMetricInfo] Métricas do controlador definidas para o pod: default/onepending-58f8995468-vx5mn
I0205 12:14:24.827415       1 scheduler.go:597] [GetControllerMetricInfo] Iniciando para o pod: default/onepending-58f8995468-7xcqr
I0205 12:14:24.827430       1 scheduler.go:602] [GetControllerMetricInfo] Obtendo o nome do controlador para o pod: default/onepending-58f8995468-7xcqr
I0205 12:14:24.827434       1 types.go:749] [ControllerName] Verificando as anotações do pod default/onepending-58f8995468-7xcqr
I0205 12:14:24.827438       1 types.go:767] [ControllerName] Anotação 'controller' encontrada para o pod default/onepending-58f8995468-7xcqr: onepending-controller
I0205 12:14:24.827443       1 scheduler.go:605] [GetControllerMetricInfo] Métricas do controlador definidas para o pod: default/onepending-58f8995468-7xcqr
I0205 12:14:24.827453       1 scheduler.go:97] [HigherPrecedence] Métricas para onepending-58f8995468-vx5mn: QoS = -89.649230, Importância = 0.80
I0205 12:14:24.827472       1 scheduler.go:98] [HigherPrecedence] Métricas para onepending-58f8995468-7xcqr: QoS = -110.787474, Importância = 0.80
I0205 12:14:24.827480       1 scheduler.go:109] [HigherPrecedence] Decisão final: onepending-58f8995468-vx5mn tem precedência sobre onepending-58f8995468-7xcqr? false
I0205 12:14:24.827489       1 scheduler.go:59] [QueueSort] Precedência determinada: onepending-58f8995468-vx5mn tem precedência sobre onepending-58f8995468-7xcqr? false
I0205 12:14:24.827687       1 scheduler.go:145] [Reserve] resources reserved at node minikube for pod onepending-58f8995468-7xcqr_default at 2025-02-05 12:14:24.827683349 +0000 UTC m=+451.145686910
I0205 12:14:24.827708       1 types.go:749] [ControllerName] Verificando as anotações do pod default/onepending-58f8995468-7xcqr
I0205 12:14:24.827714       1 types.go:767] [ControllerName] Anotação 'controller' encontrada para o pod default/onepending-58f8995468-7xcqr: onepending-controller
I0205 12:14:24.827719       1 scheduler.go:147] [Reserve] Status de alocação atual para o pod onepending-58f8995468-7xcqr_default: 
I0205 12:14:24.827722       1 scheduler.go:149] [Reserve] Status de alocação atualizado para o pod onepending-58f8995468-7xcqr_default: allocating
I0205 12:14:24.827789       1 postFilter.go:29] [PostFilter] PostFilter chamado para pod: default/onepending-58f8995468-vx5mn
I0205 12:14:24.827811       1 postFilter.go:76] Comparando pod original com o atualizado...
I0205 12:14:24.827818       1 postFilter.go:83] Successfully retrieved updated pod default/onepending-58f8995468-vx5mn from lister
I0205 12:14:24.827891       1 scheduler.go:173] [PreBind] Validando o pod onepending-58f8995468-7xcqr antes de vincular ao node minikube
I0205 12:14:24.829425       1 postFilter.go:226] [compareNodeResources] Recursos calculados no nó minikube: CPU = 8850 mCPU, Memória = 387973120 bytes
I0205 12:14:24.829477       1 postFilter.go:227] [compareNodeResources] Recursos do snapshot no nó minikube: CPU = 8850 mCPU, Memória = 387973120 bytes
I0205 12:14:24.829484       1 postFilter.go:233] [compareNodeResources] Recursos de CPU do nó minikube estão sincronizados: 8850 mCPU
I0205 12:14:24.829491       1 postFilter.go:239] [compareNodeResources] Recursos de memória do nó minikube estão sincronizados: 387973120 bytes
I0205 12:14:24.829589       1 scheduler.go:597] [GetControllerMetricInfo] Iniciando para o pod: default/onepending-58f8995468-7xcqr
I0205 12:14:24.829607       1 scheduler.go:602] [GetControllerMetricInfo] Obtendo o nome do controlador para o pod: default/onepending-58f8995468-7xcqr
I0205 12:14:24.829610       1 types.go:749] [ControllerName] Verificando as anotações do pod default/onepending-58f8995468-7xcqr
I0205 12:14:24.829615       1 types.go:767] [ControllerName] Anotação 'controller' encontrada para o pod default/onepending-58f8995468-7xcqr: onepending-controller
I0205 12:14:24.829620       1 scheduler.go:605] [GetControllerMetricInfo] Métricas do controlador definidas para o pod: default/onepending-58f8995468-7xcqr
I0205 12:14:24.829625       1 scheduler.go:83] [HigherPrecedence] Calculando precedência entre onepending-58f8995468-vx5mn e onepending-58f8995468-7xcqr
I0205 12:14:24.829630       1 scheduler.go:116] [WaitForPodsOnCache] Verificando se o pod onepending-58f8995468-vx5mn está no cache...
I0205 12:14:24.829634       1 scheduler.go:597] [GetControllerMetricInfo] Iniciando para o pod: default/onepending-58f8995468-vx5mn
I0205 12:14:24.829638       1 scheduler.go:602] [GetControllerMetricInfo] Obtendo o nome do controlador para o pod: default/onepending-58f8995468-vx5mn
I0205 12:14:24.829642       1 types.go:749] [ControllerName] Verificando as anotações do pod default/onepending-58f8995468-vx5mn
I0205 12:14:24.829646       1 types.go:767] [ControllerName] Anotação 'controller' encontrada para o pod default/onepending-58f8995468-vx5mn: onepending-controller
I0205 12:14:24.829651       1 scheduler.go:605] [GetControllerMetricInfo] Métricas do controlador definidas para o pod: default/onepending-58f8995468-vx5mn
I0205 12:14:24.833123       1 scheduler.go:181] [PostBind] Chamado para pod onepending-58f8995468-7xcqr
I0205 12:14:24.833155       1 scheduler.go:199] [PostBind] Pod onepending-58f8995468-7xcqr - Início do binding: 2025-02-05 12:14:24.827907342 +0000 UTC m=+451.145910903, Fim do binding: 2025-02-05 12:14:24.833151552 +0000 UTC m=+451.151155113
I0205 12:14:24.833267       1 scheduler.go:252] [OnUpdatePod] Iniciando processamento de atualização de pod
I0205 12:14:24.833364       1 scheduler.go:256] [OnUpdatePod] Pod atualizado detectado: default/onepending-58f8995468-7xcqr, Anotações: map[acceptablePreemptionOverhead:0.05 controller:onepending-controller qosMeasuring:independent slo:0.8]
I0205 12:14:24.833403       1 scheduler.go:259] [OnUpdatePod] Comparando estado no Informer e estado real no cluster para o pod default/onepending-58f8995468-7xcqr
I0205 12:14:24.833413       1 scheduler.go:69] Estado no Informer: map[acceptablePreemptionOverhead:0.05 controller:onepending-controller qosMeasuring:independent slo:0.8]
I0205 12:14:24.833441       1 scheduler.go:70] Estado real no cluster: map[acceptablePreemptionOverhead:0.05 controller:onepending-controller qosMeasuring:independent slo:0.8]
I0205 12:14:24.833466       1 scheduler.go:138] [WaitForPodsOnCache] Pod onepending-58f8995468-vx5mn encontrado no cache.
I0205 12:14:24.833480       1 scheduler.go:116] [WaitForPodsOnCache] Verificando se o pod onepending-58f8995468-7xcqr está no cache...
I0205 12:14:24.833486       1 scheduler.go:597] [GetControllerMetricInfo] Iniciando para o pod: default/onepending-58f8995468-7xcqr
I0205 12:14:24.833496       1 types.go:749] [ControllerName] Verificando as anotações do pod default/onepending-58f8995468-7xcqr
I0205 12:14:24.833503       1 types.go:767] [ControllerName] Anotação 'controller' encontrada para o pod default/onepending-58f8995468-7xcqr: onepending-controller
I0205 12:14:24.833513       1 scheduler.go:206] [PostBind] Métricas atualizadas para o pod onepending-58f8995468-7xcqr
I0205 12:14:24.833559       1 scheduler.go:602] [GetControllerMetricInfo] Obtendo o nome do controlador para o pod: default/onepending-58f8995468-7xcqr
I0205 12:14:24.833574       1 types.go:749] [ControllerName] Verificando as anotações do pod default/onepending-58f8995468-7xcqr
I0205 12:14:24.833579       1 types.go:767] [ControllerName] Anotação 'controller' encontrada para o pod default/onepending-58f8995468-7xcqr: onepending-controller
I0205 12:14:24.833584       1 scheduler.go:605] [GetControllerMetricInfo] Métricas do controlador definidas para o pod: default/onepending-58f8995468-7xcqr
I0205 12:14:24.835522       1 scheduler.go:69] Estado no Informer: map[acceptablePreemptionOverhead:0.05 controller:onepending-controller qosMeasuring:independent slo:0.8]
I0205 12:14:24.835558       1 scheduler.go:70] Estado real no cluster: map[acceptablePreemptionOverhead:0.05 controller:onepending-controller qosMeasuring:independent slo:0.8]
I0205 12:14:24.835569       1 scheduler.go:269] [OnUpdatePod] Atualizando informações de métricas para o pod default/onepending-58f8995468-7xcqr
I0205 12:14:24.835658       1 scheduler.go:69] Estado no Informer: map[acceptablePreemptionOverhead:0.05 controller:onepending-controller qosMeasuring:independent slo:0.8]
I0205 12:14:24.835685       1 scheduler.go:70] Estado real no cluster: map[acceptablePreemptionOverhead:0.05 controller:onepending-controller qosMeasuring:independent slo:0.8]
I0205 12:14:24.835707       1 scheduler.go:138] [WaitForPodsOnCache] Pod onepending-58f8995468-7xcqr encontrado no cache.
I0205 12:14:24.835722       1 scheduler.go:597] [GetControllerMetricInfo] Iniciando para o pod: default/onepending-58f8995468-vx5mn
I0205 12:14:24.835744       1 types.go:749] [ControllerName] Verificando as anotações do pod default/onepending-58f8995468-7xcqr
I0205 12:14:24.835752       1 types.go:767] [ControllerName] Anotação 'controller' encontrada para o pod default/onepending-58f8995468-7xcqr: onepending-controller
I0205 12:14:24.835760       1 scheduler.go:271] [OnUpdatePod] Atualizando 'LastStatus' do pod default/onepending-58f8995468-7xcqr nas métricas
I0205 12:14:24.835765       1 scheduler.go:273] [OnUpdatePod] Métrica atualizada para o pod default/onepending-58f8995468-7xcqr
I0205 12:14:24.835773       1 scheduler.go:277] [OnUpdatePod] Finalizando processamento de atualização de pod para default/onepending-58f8995468-7xcqr
I0205 12:14:24.835806       1 scheduler.go:602] [GetControllerMetricInfo] Obtendo o nome do controlador para o pod: default/onepending-58f8995468-vx5mn
I0205 12:14:24.835831       1 types.go:749] [ControllerName] Verificando as anotações do pod default/onepending-58f8995468-vx5mn
I0205 12:14:24.835855       1 types.go:767] [ControllerName] Anotação 'controller' encontrada para o pod default/onepending-58f8995468-vx5mn: onepending-controller
I0205 12:14:24.835862       1 scheduler.go:605] [GetControllerMetricInfo] Métricas do controlador definidas para o pod: default/onepending-58f8995468-vx5mn
I0205 12:14:24.835874       1 scheduler.go:597] [GetControllerMetricInfo] Iniciando para o pod: default/onepending-58f8995468-7xcqr
I0205 12:14:24.835890       1 scheduler.go:602] [GetControllerMetricInfo] Obtendo o nome do controlador para o pod: default/onepending-58f8995468-7xcqr
I0205 12:14:24.835894       1 types.go:749] [ControllerName] Verificando as anotações do pod default/onepending-58f8995468-7xcqr
I0205 12:14:24.835899       1 types.go:767] [ControllerName] Anotação 'controller' encontrada para o pod default/onepending-58f8995468-7xcqr: onepending-controller
I0205 12:14:24.835903       1 scheduler.go:605] [GetControllerMetricInfo] Métricas do controlador definidas para o pod: default/onepending-58f8995468-7xcqr
I0205 12:14:24.835913       1 scheduler.go:97] [HigherPrecedence] Métricas para onepending-58f8995468-vx5mn: QoS = -89.655830, Importância = 0.80
I0205 12:14:24.835922       1 scheduler.go:98] [HigherPrecedence] Métricas para onepending-58f8995468-7xcqr: QoS = -110.801106, Importância = 0.80
I0205 12:14:24.835928       1 scheduler.go:109] [HigherPrecedence] Decisão final: onepending-58f8995468-vx5mn tem precedência sobre onepending-58f8995468-7xcqr? false
I0205 12:14:24.835973       1 postFilter.go:144] [PREEMPT CALL] No node was chosen to allocate pod onepending-58f8995468-vx5mn
W0205 12:14:24.835988       1 postFilter.go:45] [PostFilter] Nenhum nó nominado após a preempção para o pod: default/onepending-58f8995468-vx5mn
I0205 12:14:24.842874       1 scheduler.go:252] [OnUpdatePod] Iniciando processamento de atualização de pod
I0205 12:14:24.842927       1 scheduler.go:256] [OnUpdatePod] Pod atualizado detectado: default/onepending-58f8995468-7xcqr, Anotações: map[acceptablePreemptionOverhead:0.05 controller:onepending-controller qosMeasuring:independent slo:0.8]
I0205 12:14:24.842944       1 scheduler.go:259] [OnUpdatePod] Comparando estado no Informer e estado real no cluster para o pod default/onepending-58f8995468-7xcqr
I0205 12:14:24.844998       1 scheduler.go:69] Estado no Informer: map[acceptablePreemptionOverhead:0.05 controller:onepending-controller qosMeasuring:independent slo:0.8]
I0205 12:14:24.845042       1 scheduler.go:70] Estado real no cluster: map[acceptablePreemptionOverhead:0.05 controller:onepending-controller qosMeasuring:independent slo:0.8]
I0205 12:14:24.845050       1 scheduler.go:269] [OnUpdatePod] Atualizando informações de métricas para o pod default/onepending-58f8995468-7xcqr
I0205 12:14:24.845055       1 types.go:749] [ControllerName] Verificando as anotações do pod default/onepending-58f8995468-7xcqr
I0205 12:14:24.845060       1 types.go:767] [ControllerName] Anotação 'controller' encontrada para o pod default/onepending-58f8995468-7xcqr: onepending-controller
I0205 12:14:24.845067       1 scheduler.go:271] [OnUpdatePod] Atualizando 'LastStatus' do pod default/onepending-58f8995468-7xcqr nas métricas
I0205 12:14:24.845071       1 scheduler.go:273] [OnUpdatePod] Métrica atualizada para o pod default/onepending-58f8995468-7xcqr
I0205 12:14:24.845078       1 scheduler.go:277] [OnUpdatePod] Finalizando processamento de atualização de pod para default/onepending-58f8995468-7xcqr
I0205 12:14:25.777469       1 scheduler.go:252] [OnUpdatePod] Iniciando processamento de atualização de pod
I0205 12:14:25.777531       1 scheduler.go:256] [OnUpdatePod] Pod atualizado detectado: default/onepending-58f8995468-7xcqr, Anotações: map[acceptablePreemptionOverhead:0.05 controller:onepending-controller qosMeasuring:independent slo:0.8]
I0205 12:14:25.777548       1 scheduler.go:259] [OnUpdatePod] Comparando estado no Informer e estado real no cluster para o pod default/onepending-58f8995468-7xcqr
I0205 12:14:25.781213       1 scheduler.go:69] Estado no Informer: map[acceptablePreemptionOverhead:0.05 controller:onepending-controller qosMeasuring:independent slo:0.8]
I0205 12:14:25.781245       1 scheduler.go:70] Estado real no cluster: map[acceptablePreemptionOverhead:0.05 controller:onepending-controller qosMeasuring:independent slo:0.8]
I0205 12:14:25.781253       1 scheduler.go:269] [OnUpdatePod] Atualizando informações de métricas para o pod default/onepending-58f8995468-7xcqr
I0205 12:14:25.781259       1 types.go:749] [ControllerName] Verificando as anotações do pod default/onepending-58f8995468-7xcqr
I0205 12:14:25.781263       1 types.go:767] [ControllerName] Anotação 'controller' encontrada para o pod default/onepending-58f8995468-7xcqr: onepending-controller
I0205 12:14:25.781270       1 scheduler.go:271] [OnUpdatePod] Atualizando 'LastStatus' do pod default/onepending-58f8995468-7xcqr nas métricas
I0205 12:14:25.781273       1 scheduler.go:273] [OnUpdatePod] Métrica atualizada para o pod default/onepending-58f8995468-7xcqr
I0205 12:14:25.781280       1 scheduler.go:277] [OnUpdatePod] Finalizando processamento de atualização de pod para default/onepending-58f8995468-7xcqr
I0205 12:14:27.093439       1 postFilter.go:29] [PostFilter] PostFilter chamado para pod: default/onepending-58f8995468-vx5mn
I0205 12:14:27.093465       1 postFilter.go:76] Comparando pod original com o atualizado...
I0205 12:14:27.093474       1 postFilter.go:83] Successfully retrieved updated pod default/onepending-58f8995468-vx5mn from lister
I0205 12:14:27.095485       1 postFilter.go:226] [compareNodeResources] Recursos calculados no nó minikube: CPU = 8850 mCPU, Memória = 387973120 bytes
I0205 12:14:27.095507       1 postFilter.go:227] [compareNodeResources] Recursos do snapshot no nó minikube: CPU = 8850 mCPU, Memória = 387973120 bytes
I0205 12:14:27.095513       1 postFilter.go:233] [compareNodeResources] Recursos de CPU do nó minikube estão sincronizados: 8850 mCPU
I0205 12:14:27.095519       1 postFilter.go:239] [compareNodeResources] Recursos de memória do nó minikube estão sincronizados: 387973120 bytes
I0205 12:14:27.095613       1 scheduler.go:597] [GetControllerMetricInfo] Iniciando para o pod: default/onepending-58f8995468-7xcqr
I0205 12:14:27.095629       1 scheduler.go:602] [GetControllerMetricInfo] Obtendo o nome do controlador para o pod: default/onepending-58f8995468-7xcqr
I0205 12:14:27.095634       1 types.go:749] [ControllerName] Verificando as anotações do pod default/onepending-58f8995468-7xcqr
I0205 12:14:27.095638       1 types.go:767] [ControllerName] Anotação 'controller' encontrada para o pod default/onepending-58f8995468-7xcqr: onepending-controller
I0205 12:14:27.095644       1 scheduler.go:605] [GetControllerMetricInfo] Métricas do controlador definidas para o pod: default/onepending-58f8995468-7xcqr
I0205 12:14:27.095648       1 scheduler.go:83] [HigherPrecedence] Calculando precedência entre onepending-58f8995468-vx5mn e onepending-58f8995468-7xcqr
I0205 12:14:27.095652       1 scheduler.go:116] [WaitForPodsOnCache] Verificando se o pod onepending-58f8995468-vx5mn está no cache...
I0205 12:14:27.095656       1 scheduler.go:597] [GetControllerMetricInfo] Iniciando para o pod: default/onepending-58f8995468-vx5mn
I0205 12:14:27.095660       1 scheduler.go:602] [GetControllerMetricInfo] Obtendo o nome do controlador para o pod: default/onepending-58f8995468-vx5mn
I0205 12:14:27.095664       1 types.go:749] [ControllerName] Verificando as anotações do pod default/onepending-58f8995468-vx5mn
I0205 12:14:27.095668       1 types.go:767] [ControllerName] Anotação 'controller' encontrada para o pod default/onepending-58f8995468-vx5mn: onepending-controller
I0205 12:14:27.095673       1 scheduler.go:605] [GetControllerMetricInfo] Métricas do controlador definidas para o pod: default/onepending-58f8995468-vx5mn
I0205 12:14:27.097499       1 scheduler.go:69] Estado no Informer: map[acceptablePreemptionOverhead:0.05 controller:onepending-controller qosMeasuring:independent slo:0.8]
I0205 12:14:27.097526       1 scheduler.go:70] Estado real no cluster: map[acceptablePreemptionOverhead:0.05 controller:onepending-controller qosMeasuring:independent slo:0.8]
I0205 12:14:27.097534       1 scheduler.go:138] [WaitForPodsOnCache] Pod onepending-58f8995468-vx5mn encontrado no cache.
I0205 12:14:27.097538       1 scheduler.go:116] [WaitForPodsOnCache] Verificando se o pod onepending-58f8995468-7xcqr está no cache...
I0205 12:14:27.097543       1 scheduler.go:597] [GetControllerMetricInfo] Iniciando para o pod: default/onepending-58f8995468-7xcqr
I0205 12:14:27.097547       1 scheduler.go:602] [GetControllerMetricInfo] Obtendo o nome do controlador para o pod: default/onepending-58f8995468-7xcqr
I0205 12:14:27.097552       1 types.go:749] [ControllerName] Verificando as anotações do pod default/onepending-58f8995468-7xcqr
I0205 12:14:27.097558       1 types.go:767] [ControllerName] Anotação 'controller' encontrada para o pod default/onepending-58f8995468-7xcqr: onepending-controller
I0205 12:14:27.097564       1 scheduler.go:605] [GetControllerMetricInfo] Métricas do controlador definidas para o pod: default/onepending-58f8995468-7xcqr
I0205 12:14:27.099392       1 scheduler.go:69] Estado no Informer: map[acceptablePreemptionOverhead:0.05 controller:onepending-controller qosMeasuring:independent slo:0.8]
I0205 12:14:27.099425       1 scheduler.go:70] Estado real no cluster: map[acceptablePreemptionOverhead:0.05 controller:onepending-controller qosMeasuring:independent slo:0.8]
I0205 12:14:27.099432       1 scheduler.go:138] [WaitForPodsOnCache] Pod onepending-58f8995468-7xcqr encontrado no cache.
I0205 12:14:27.099437       1 scheduler.go:597] [GetControllerMetricInfo] Iniciando para o pod: default/onepending-58f8995468-vx5mn
I0205 12:14:27.099441       1 scheduler.go:602] [GetControllerMetricInfo] Obtendo o nome do controlador para o pod: default/onepending-58f8995468-vx5mn
I0205 12:14:27.099446       1 types.go:749] [ControllerName] Verificando as anotações do pod default/onepending-58f8995468-vx5mn
I0205 12:14:27.099450       1 types.go:767] [ControllerName] Anotação 'controller' encontrada para o pod default/onepending-58f8995468-vx5mn: onepending-controller
I0205 12:14:27.099455       1 scheduler.go:605] [GetControllerMetricInfo] Métricas do controlador definidas para o pod: default/onepending-58f8995468-vx5mn
I0205 12:14:27.099464       1 scheduler.go:597] [GetControllerMetricInfo] Iniciando para o pod: default/onepending-58f8995468-7xcqr
I0205 12:14:27.099468       1 scheduler.go:602] [GetControllerMetricInfo] Obtendo o nome do controlador para o pod: default/onepending-58f8995468-7xcqr
I0205 12:14:27.099471       1 types.go:749] [ControllerName] Verificando as anotações do pod default/onepending-58f8995468-7xcqr
I0205 12:14:27.099475       1 types.go:767] [ControllerName] Anotação 'controller' encontrada para o pod default/onepending-58f8995468-7xcqr: onepending-controller
I0205 12:14:27.099478       1 scheduler.go:605] [GetControllerMetricInfo] Métricas do controlador definidas para o pod: default/onepending-58f8995468-7xcqr
I0205 12:14:27.099487       1 scheduler.go:97] [HigherPrecedence] Métricas para onepending-58f8995468-vx5mn: QoS = -91.921853, Importância = 0.80
I0205 12:14:27.099502       1 scheduler.go:98] [HigherPrecedence] Métricas para onepending-58f8995468-7xcqr: QoS = -110.234600, Importância = 0.80
I0205 12:14:27.099507       1 scheduler.go:109] [HigherPrecedence] Decisão final: onepending-58f8995468-vx5mn tem precedência sobre onepending-58f8995468-7xcqr? false
I0205 12:14:27.099543       1 postFilter.go:144] [PREEMPT CALL] No node was chosen to allocate pod onepending-58f8995468-vx5mn
W0205 12:14:27.099557       1 postFilter.go:45] [PostFilter] Nenhum nó nominado após a preempção para o pod: default/onepending-58f8995468-vx5mn
