I0124 13:45:35.841175       1 serving.go:386] Generated self-signed cert in-memory
W0124 13:45:35.842662       1 client_config.go:659] Neither --kubeconfig nor --master was specified.  Using the inClusterConfig.  This might not work.
I0124 13:45:36.174620       1 scheduler.go:218] [OnAddPod] Pod adicionado: kube-system/coredns-6f6b679f8f-j8ddm, Anotações: map[]
I0124 13:45:36.179035       1 scheduler.go:70] Estado no Informer: map[]
I0124 13:45:36.179074       1 scheduler.go:71] Estado real no cluster: map[]
I0124 13:45:36.179084       1 scheduler.go:224] [OnAddPod] Ignorando pod kube-system/coredns-6f6b679f8f-j8ddm pois pertence ao namespace kube-system
I0124 13:45:36.179105       1 scheduler.go:218] [OnAddPod] Pod adicionado: kube-system/custom-scheduler-868c6bbc7d-xwwmw, Anotações: map[]
I0124 13:45:36.183972       1 scheduler.go:70] Estado no Informer: map[]
I0124 13:45:36.184312       1 scheduler.go:71] Estado real no cluster: map[]
I0124 13:45:36.184642       1 scheduler.go:224] [OnAddPod] Ignorando pod kube-system/custom-scheduler-868c6bbc7d-xwwmw pois pertence ao namespace kube-system
I0124 13:45:36.184984       1 scheduler.go:218] [OnAddPod] Pod adicionado: kube-system/etcd-minikube, Anotações: map[kubeadm.kubernetes.io/etcd.advertise-client-urls:https://192.168.39.253:2379 kubernetes.io/config.hash:83b49ae0e8ec1d939c80919a7e7e502b kubernetes.io/config.mirror:83b49ae0e8ec1d939c80919a7e7e502b kubernetes.io/config.seen:2025-01-23T13:21:10.529429156Z kubernetes.io/config.source:file]
I0124 13:45:36.189709       1 scheduler.go:70] Estado no Informer: map[kubeadm.kubernetes.io/etcd.advertise-client-urls:https://192.168.39.253:2379 kubernetes.io/config.hash:83b49ae0e8ec1d939c80919a7e7e502b kubernetes.io/config.mirror:83b49ae0e8ec1d939c80919a7e7e502b kubernetes.io/config.seen:2025-01-23T13:21:10.529429156Z kubernetes.io/config.source:file]
I0124 13:45:36.190122       1 scheduler.go:71] Estado real no cluster: map[kubeadm.kubernetes.io/etcd.advertise-client-urls:https://192.168.39.253:2379 kubernetes.io/config.hash:83b49ae0e8ec1d939c80919a7e7e502b kubernetes.io/config.mirror:83b49ae0e8ec1d939c80919a7e7e502b kubernetes.io/config.seen:2025-01-23T13:21:10.529429156Z kubernetes.io/config.source:file]
I0124 13:45:36.190384       1 scheduler.go:224] [OnAddPod] Ignorando pod kube-system/etcd-minikube pois pertence ao namespace kube-system
I0124 13:45:36.190833       1 scheduler.go:218] [OnAddPod] Pod adicionado: kube-system/kube-apiserver-minikube, Anotações: map[kubeadm.kubernetes.io/kube-apiserver.advertise-address.endpoint:192.168.39.253:8443 kubernetes.io/config.hash:c85c19863b26fc8fc8ebf5568d420510 kubernetes.io/config.mirror:c85c19863b26fc8fc8ebf5568d420510 kubernetes.io/config.seen:2025-01-23T13:21:10.529440623Z kubernetes.io/config.source:file]
I0124 13:45:36.194578       1 scheduler.go:70] Estado no Informer: map[kubeadm.kubernetes.io/kube-apiserver.advertise-address.endpoint:192.168.39.253:8443 kubernetes.io/config.hash:c85c19863b26fc8fc8ebf5568d420510 kubernetes.io/config.mirror:c85c19863b26fc8fc8ebf5568d420510 kubernetes.io/config.seen:2025-01-23T13:21:10.529440623Z kubernetes.io/config.source:file]
I0124 13:45:36.195031       1 scheduler.go:71] Estado real no cluster: map[kubeadm.kubernetes.io/kube-apiserver.advertise-address.endpoint:192.168.39.253:8443 kubernetes.io/config.hash:c85c19863b26fc8fc8ebf5568d420510 kubernetes.io/config.mirror:c85c19863b26fc8fc8ebf5568d420510 kubernetes.io/config.seen:2025-01-23T13:21:10.529440623Z kubernetes.io/config.source:file]
I0124 13:45:36.195398       1 scheduler.go:224] [OnAddPod] Ignorando pod kube-system/kube-apiserver-minikube pois pertence ao namespace kube-system
I0124 13:45:36.195727       1 scheduler.go:218] [OnAddPod] Pod adicionado: kube-system/kube-controller-manager-minikube, Anotações: map[kubernetes.io/config.hash:6e07439efa4d6dab7ea55fed1a35452a kubernetes.io/config.mirror:6e07439efa4d6dab7ea55fed1a35452a kubernetes.io/config.seen:2025-01-23T13:21:10.529446212Z kubernetes.io/config.source:file]
I0124 13:45:36.199492       1 scheduler.go:70] Estado no Informer: map[kubernetes.io/config.hash:6e07439efa4d6dab7ea55fed1a35452a kubernetes.io/config.mirror:6e07439efa4d6dab7ea55fed1a35452a kubernetes.io/config.seen:2025-01-23T13:21:10.529446212Z kubernetes.io/config.source:file]
I0124 13:45:36.199587       1 scheduler.go:71] Estado real no cluster: map[kubernetes.io/config.hash:6e07439efa4d6dab7ea55fed1a35452a kubernetes.io/config.mirror:6e07439efa4d6dab7ea55fed1a35452a kubernetes.io/config.seen:2025-01-23T13:21:10.529446212Z kubernetes.io/config.source:file]
I0124 13:45:36.199737       1 scheduler.go:224] [OnAddPod] Ignorando pod kube-system/kube-controller-manager-minikube pois pertence ao namespace kube-system
I0124 13:45:36.199926       1 scheduler.go:218] [OnAddPod] Pod adicionado: kube-system/kube-proxy-4x8nj, Anotações: map[]
I0124 13:45:36.202990       1 scheduler.go:70] Estado no Informer: map[]
I0124 13:45:36.203410       1 scheduler.go:71] Estado real no cluster: map[]
I0124 13:45:36.203540       1 scheduler.go:224] [OnAddPod] Ignorando pod kube-system/kube-proxy-4x8nj pois pertence ao namespace kube-system
I0124 13:45:36.203925       1 scheduler.go:218] [OnAddPod] Pod adicionado: kube-system/kube-scheduler-minikube, Anotações: map[kubernetes.io/config.hash:e039200acb850c82bb901653cc38ff6e kubernetes.io/config.mirror:e039200acb850c82bb901653cc38ff6e kubernetes.io/config.seen:2025-01-23T13:21:10.529450432Z kubernetes.io/config.source:file]
I0124 13:45:36.206566       1 scheduler.go:70] Estado no Informer: map[kubernetes.io/config.hash:e039200acb850c82bb901653cc38ff6e kubernetes.io/config.mirror:e039200acb850c82bb901653cc38ff6e kubernetes.io/config.seen:2025-01-23T13:21:10.529450432Z kubernetes.io/config.source:file]
I0124 13:45:36.206904       1 scheduler.go:71] Estado real no cluster: map[kubernetes.io/config.hash:e039200acb850c82bb901653cc38ff6e kubernetes.io/config.mirror:e039200acb850c82bb901653cc38ff6e kubernetes.io/config.seen:2025-01-23T13:21:10.529450432Z kubernetes.io/config.source:file]
I0124 13:45:36.207018       1 scheduler.go:224] [OnAddPod] Ignorando pod kube-system/kube-scheduler-minikube pois pertence ao namespace kube-system
I0124 13:45:36.207148       1 scheduler.go:218] [OnAddPod] Pod adicionado: kube-system/storage-provisioner, Anotações: map[kubectl.kubernetes.io/last-applied-configuration:{"apiVersion":"v1","kind":"Pod","metadata":{"annotations":{},"labels":{"addonmanager.kubernetes.io/mode":"Reconcile","integration-test":"storage-provisioner"},"name":"storage-provisioner","namespace":"kube-system"},"spec":{"containers":[{"command":["/storage-provisioner"],"image":"gcr.io/k8s-minikube/storage-provisioner:v5","imagePullPolicy":"IfNotPresent","name":"storage-provisioner","volumeMounts":[{"mountPath":"/tmp","name":"tmp"}]}],"hostNetwork":true,"serviceAccountName":"storage-provisioner","volumes":[{"hostPath":{"path":"/tmp","type":"Directory"},"name":"tmp"}]}}
]
I0124 13:45:36.210139       1 scheduler.go:70] Estado no Informer: map[kubectl.kubernetes.io/last-applied-configuration:{"apiVersion":"v1","kind":"Pod","metadata":{"annotations":{},"labels":{"addonmanager.kubernetes.io/mode":"Reconcile","integration-test":"storage-provisioner"},"name":"storage-provisioner","namespace":"kube-system"},"spec":{"containers":[{"command":["/storage-provisioner"],"image":"gcr.io/k8s-minikube/storage-provisioner:v5","imagePullPolicy":"IfNotPresent","name":"storage-provisioner","volumeMounts":[{"mountPath":"/tmp","name":"tmp"}]}],"hostNetwork":true,"serviceAccountName":"storage-provisioner","volumes":[{"hostPath":{"path":"/tmp","type":"Directory"},"name":"tmp"}]}}
]
I0124 13:45:36.210506       1 scheduler.go:71] Estado real no cluster: map[kubectl.kubernetes.io/last-applied-configuration:{"apiVersion":"v1","kind":"Pod","metadata":{"annotations":{},"labels":{"addonmanager.kubernetes.io/mode":"Reconcile","integration-test":"storage-provisioner"},"name":"storage-provisioner","namespace":"kube-system"},"spec":{"containers":[{"command":["/storage-provisioner"],"image":"gcr.io/k8s-minikube/storage-provisioner:v5","imagePullPolicy":"IfNotPresent","name":"storage-provisioner","volumeMounts":[{"mountPath":"/tmp","name":"tmp"}]}],"hostNetwork":true,"serviceAccountName":"storage-provisioner","volumes":[{"hostPath":{"path":"/tmp","type":"Directory"},"name":"tmp"}]}}
]
I0124 13:45:36.210655       1 scheduler.go:224] [OnAddPod] Ignorando pod kube-system/storage-provisioner pois pertence ao namespace kube-system
I0124 13:45:36.263478       1 scheduler.go:662] PodInformer sincronizado com sucesso
I0124 13:45:36.276659       1 server.go:167] "Starting Kubernetes Scheduler" version="v0.0.0-master+$Format:%H$"
I0124 13:45:36.276707       1 server.go:169] "Golang settings" GOGC="" GOMAXPROCS="" GOTRACEBACK=""
I0124 13:45:36.290943       1 requestheader_controller.go:172] Starting RequestHeaderAuthRequestController
I0124 13:45:36.291040       1 shared_informer.go:313] Waiting for caches to sync for RequestHeaderAuthRequestController
I0124 13:45:36.291144       1 configmap_cafile_content.go:205] "Starting controller" name="client-ca::kube-system::extension-apiserver-authentication::client-ca-file"
I0124 13:45:36.291230       1 shared_informer.go:313] Waiting for caches to sync for client-ca::kube-system::extension-apiserver-authentication::client-ca-file
I0124 13:45:36.291249       1 configmap_cafile_content.go:205] "Starting controller" name="client-ca::kube-system::extension-apiserver-authentication::requestheader-client-ca-file"
I0124 13:45:36.291257       1 shared_informer.go:313] Waiting for caches to sync for client-ca::kube-system::extension-apiserver-authentication::requestheader-client-ca-file
I0124 13:45:36.292350       1 secure_serving.go:213] Serving securely on [::]:10259
I0124 13:45:36.292778       1 tlsconfig.go:243] "Starting DynamicServingCertificateController"
I0124 13:45:36.391553       1 shared_informer.go:320] Caches are synced for client-ca::kube-system::extension-apiserver-authentication::requestheader-client-ca-file
I0124 13:45:36.391761       1 shared_informer.go:320] Caches are synced for client-ca::kube-system::extension-apiserver-authentication::client-ca-file
I0124 13:45:36.393060       1 leaderelection.go:254] attempting to acquire leader lease kube-system/kube-scheduler...
I0124 13:45:36.393658       1 shared_informer.go:320] Caches are synced for RequestHeaderAuthRequestController
I0124 13:45:54.640163       1 leaderelection.go:268] successfully acquired lease kube-system/kube-scheduler
I0124 13:46:54.486540       1 scheduler.go:146] [Reserve] resources reserved at node minikube for pod test-deployment2-59c6b78cd5-dbnl2_default at 2025-01-24 13:46:54.486485203 +0000 UTC m=+79.303419347
I0124 13:46:54.486682       1 types.go:743] [ControllerName] Verificando as anotações do pod default/test-deployment2-59c6b78cd5-dbnl2
I0124 13:46:54.486692       1 types.go:761] [ControllerName] Anotação 'controller' encontrada para o pod default/test-deployment2-59c6b78cd5-dbnl2: test-controller2
I0124 13:46:54.501470       1 scheduler.go:218] [OnAddPod] Pod adicionado: default/test-deployment2-59c6b78cd5-dbnl2, Anotações: map[controller:test-controller2]
I0124 13:46:54.567238       1 scheduler.go:148] [Reserve] Status de alocação atual para o pod test-deployment2-59c6b78cd5-dbnl2_default: 
I0124 13:46:54.574063       1 scheduler.go:150] [Reserve] Status de alocação atualizado para o pod test-deployment2-59c6b78cd5-dbnl2_default: allocating
I0124 13:46:54.574380       1 scheduler.go:174] [PreBind] Validando o pod test-deployment2-59c6b78cd5-dbnl2 antes de vincular ao node minikube
I0124 13:46:54.583103       1 scheduler.go:70] Estado no Informer: map[controller:test-controller2]
I0124 13:46:54.587670       1 scheduler.go:71] Estado real no cluster: map[controller:test-controller2]
I0124 13:46:54.595542       1 scheduler.go:229] [OnAddPod] Adicionando pod default/test-deployment2-59c6b78cd5-dbnl2 com os seguintes detalhes:
I0124 13:46:54.596266       1 types.go:743] [ControllerName] Verificando as anotações do pod default/test-deployment2-59c6b78cd5-dbnl2
I0124 13:46:54.596587       1 types.go:761] [ControllerName] Anotação 'controller' encontrada para o pod default/test-deployment2-59c6b78cd5-dbnl2: test-controller2
I0124 13:46:54.597698       1 scheduler.go:238] [OnAddPod] Atualizando métricas para o pod default/test-deployment2-59c6b78cd5-dbnl2
I0124 13:46:54.606288       1 types.go:743] [ControllerName] Verificando as anotações do pod default/test-deployment2-59c6b78cd5-dbnl2
I0124 13:46:54.606672       1 types.go:761] [ControllerName] Anotação 'controller' encontrada para o pod default/test-deployment2-59c6b78cd5-dbnl2: test-controller2
I0124 13:46:54.609272       1 scheduler.go:251] [OnAddPod] Pod default/test-deployment2-59c6b78cd5-dbnl2 adicionado com sucesso
I0124 13:46:54.621489       1 scheduler.go:182] [PostBind] Chamado para pod test-deployment2-59c6b78cd5-dbnl2
I0124 13:46:54.625284       1 scheduler.go:200] [PostBind] Pod test-deployment2-59c6b78cd5-dbnl2 - Início do binding: 2025-01-24 13:46:54.574389971 +0000 UTC m=+79.391324480, Fim do binding: 2025-01-24 13:46:54.625277633 +0000 UTC m=+79.442211755
I0124 13:46:54.625499       1 types.go:743] [ControllerName] Verificando as anotações do pod default/test-deployment2-59c6b78cd5-dbnl2
I0124 13:46:54.625693       1 types.go:761] [ControllerName] Anotação 'controller' encontrada para o pod default/test-deployment2-59c6b78cd5-dbnl2: test-controller2
I0124 13:46:54.625830       1 scheduler.go:207] [PostBind] Métricas atualizadas para o pod test-deployment2-59c6b78cd5-dbnl2
I0124 13:46:54.625078       1 scheduler.go:258] [OnUpdatePod] Iniciando processamento de atualização de pod
I0124 13:46:54.629827       1 scheduler.go:262] [OnUpdatePod] Pod atualizado detectado: default/test-deployment2-59c6b78cd5-dbnl2, Anotações: map[controller:test-controller2]
I0124 13:46:54.629998       1 scheduler.go:265] [OnUpdatePod] Comparando estado no Informer e estado real no cluster para o pod default/test-deployment2-59c6b78cd5-dbnl2
I0124 13:46:54.669231       1 scheduler.go:70] Estado no Informer: map[controller:test-controller2]
I0124 13:46:54.671316       1 scheduler.go:71] Estado real no cluster: map[controller:test-controller2]
I0124 13:46:54.671438       1 scheduler.go:275] [OnUpdatePod] Atualizando informações de métricas para o pod default/test-deployment2-59c6b78cd5-dbnl2
I0124 13:46:54.671494       1 types.go:743] [ControllerName] Verificando as anotações do pod default/test-deployment2-59c6b78cd5-dbnl2
I0124 13:46:54.671513       1 types.go:761] [ControllerName] Anotação 'controller' encontrada para o pod default/test-deployment2-59c6b78cd5-dbnl2: test-controller2
I0124 13:46:54.671531       1 scheduler.go:277] [OnUpdatePod] Atualizando 'LastStatus' do pod default/test-deployment2-59c6b78cd5-dbnl2 nas métricas
I0124 13:46:54.671558       1 scheduler.go:279] [OnUpdatePod] Métrica atualizada para o pod default/test-deployment2-59c6b78cd5-dbnl2
I0124 13:46:54.671578       1 scheduler.go:283] [OnUpdatePod] Finalizando processamento de atualização de pod para default/test-deployment2-59c6b78cd5-dbnl2
I0124 13:46:54.693912       1 scheduler.go:258] [OnUpdatePod] Iniciando processamento de atualização de pod
I0124 13:46:54.694038       1 scheduler.go:262] [OnUpdatePod] Pod atualizado detectado: default/test-deployment2-59c6b78cd5-dbnl2, Anotações: map[controller:test-controller2]
I0124 13:46:54.695263       1 scheduler.go:265] [OnUpdatePod] Comparando estado no Informer e estado real no cluster para o pod default/test-deployment2-59c6b78cd5-dbnl2
I0124 13:46:54.703566       1 scheduler.go:70] Estado no Informer: map[controller:test-controller2]
I0124 13:46:54.703690       1 scheduler.go:71] Estado real no cluster: map[controller:test-controller2]
I0124 13:46:54.703717       1 scheduler.go:275] [OnUpdatePod] Atualizando informações de métricas para o pod default/test-deployment2-59c6b78cd5-dbnl2
I0124 13:46:54.703772       1 types.go:743] [ControllerName] Verificando as anotações do pod default/test-deployment2-59c6b78cd5-dbnl2
I0124 13:46:54.703794       1 types.go:761] [ControllerName] Anotação 'controller' encontrada para o pod default/test-deployment2-59c6b78cd5-dbnl2: test-controller2
I0124 13:46:54.704398       1 scheduler.go:277] [OnUpdatePod] Atualizando 'LastStatus' do pod default/test-deployment2-59c6b78cd5-dbnl2 nas métricas
I0124 13:46:54.704819       1 scheduler.go:279] [OnUpdatePod] Métrica atualizada para o pod default/test-deployment2-59c6b78cd5-dbnl2
I0124 13:46:54.704955       1 scheduler.go:283] [OnUpdatePod] Finalizando processamento de atualização de pod para default/test-deployment2-59c6b78cd5-dbnl2
I0124 13:46:58.737430       1 scheduler.go:258] [OnUpdatePod] Iniciando processamento de atualização de pod
I0124 13:46:58.737540       1 scheduler.go:262] [OnUpdatePod] Pod atualizado detectado: default/test-deployment2-59c6b78cd5-dbnl2, Anotações: map[controller:test-controller2]
I0124 13:46:58.737573       1 scheduler.go:265] [OnUpdatePod] Comparando estado no Informer e estado real no cluster para o pod default/test-deployment2-59c6b78cd5-dbnl2
I0124 13:46:58.755087       1 scheduler.go:70] Estado no Informer: map[controller:test-controller2]
I0124 13:46:58.755274       1 scheduler.go:71] Estado real no cluster: map[controller:test-controller2]
I0124 13:46:58.755425       1 scheduler.go:275] [OnUpdatePod] Atualizando informações de métricas para o pod default/test-deployment2-59c6b78cd5-dbnl2
I0124 13:46:58.755680       1 types.go:743] [ControllerName] Verificando as anotações do pod default/test-deployment2-59c6b78cd5-dbnl2
I0124 13:46:58.755986       1 types.go:761] [ControllerName] Anotação 'controller' encontrada para o pod default/test-deployment2-59c6b78cd5-dbnl2: test-controller2
I0124 13:46:58.758251       1 scheduler.go:277] [OnUpdatePod] Atualizando 'LastStatus' do pod default/test-deployment2-59c6b78cd5-dbnl2 nas métricas
I0124 13:46:58.759294       1 scheduler.go:279] [OnUpdatePod] Métrica atualizada para o pod default/test-deployment2-59c6b78cd5-dbnl2
I0124 13:46:58.759487       1 scheduler.go:283] [OnUpdatePod] Finalizando processamento de atualização de pod para default/test-deployment2-59c6b78cd5-dbnl2
I0124 13:48:27.308165       1 postFilter.go:29] [PostFilter] PostFilter chamado para pod: default/test-deployment3-6c95cffb97-585vw
I0124 13:48:27.308221       1 scheduler.go:218] [OnAddPod] Pod adicionado: default/test-deployment3-6c95cffb97-585vw, Anotações: map[controller:test-controller3]
I0124 13:48:27.377834       1 scheduler.go:70] Estado no Informer: map[controller:test-controller3]
I0124 13:48:27.378251       1 scheduler.go:71] Estado real no cluster: map[controller:test-controller3]
I0124 13:48:27.388306       1 scheduler.go:229] [OnAddPod] Adicionando pod default/test-deployment3-6c95cffb97-585vw com os seguintes detalhes:
I0124 13:48:27.393637       1 types.go:743] [ControllerName] Verificando as anotações do pod default/test-deployment3-6c95cffb97-585vw
I0124 13:48:27.395262       1 types.go:761] [ControllerName] Anotação 'controller' encontrada para o pod default/test-deployment3-6c95cffb97-585vw: test-controller3
I0124 13:48:27.419056       1 scheduler.go:238] [OnAddPod] Atualizando métricas para o pod default/test-deployment3-6c95cffb97-585vw
I0124 13:48:27.419100       1 types.go:743] [ControllerName] Verificando as anotações do pod default/test-deployment3-6c95cffb97-585vw
I0124 13:48:27.419109       1 types.go:761] [ControllerName] Anotação 'controller' encontrada para o pod default/test-deployment3-6c95cffb97-585vw: test-controller3
I0124 13:48:27.419212       1 scheduler.go:251] [OnAddPod] Pod default/test-deployment3-6c95cffb97-585vw adicionado com sucesso
I0124 13:48:27.420470       1 postFilter.go:79] Comparando pod original com o atualizado...
I0124 13:48:27.420589       1 postFilter.go:86] Successfully retrieved updated pod default/test-deployment3-6c95cffb97-585vw from lister
I0124 13:48:27.431429       1 postFilter.go:229] [compareNodeResources] Recursos calculados no nó minikube: CPU = 1750 mCPU, Memória = 178257920 bytes
I0124 13:48:27.431499       1 postFilter.go:230] [compareNodeResources] Recursos do snapshot no nó minikube: CPU = 1750 mCPU, Memória = 178257920 bytes
I0124 13:48:27.431509       1 postFilter.go:236] [compareNodeResources] Recursos de CPU do nó minikube estão sincronizados: 1750 mCPU
I0124 13:48:27.431540       1 postFilter.go:242] [compareNodeResources] Recursos de memória do nó minikube estão sincronizados: 178257920 bytes
I0124 13:48:27.435618       1 scheduler.go:606] [GetControllerMetricInfo] Iniciando para o pod: default/test-deployment2-59c6b78cd5-dbnl2
I0124 13:48:27.435672       1 scheduler.go:611] [GetControllerMetricInfo] Obtendo o nome do controlador para o pod: default/test-deployment2-59c6b78cd5-dbnl2
I0124 13:48:27.435693       1 types.go:743] [ControllerName] Verificando as anotações do pod default/test-deployment2-59c6b78cd5-dbnl2
I0124 13:48:27.435767       1 types.go:761] [ControllerName] Anotação 'controller' encontrada para o pod default/test-deployment2-59c6b78cd5-dbnl2: test-controller2
I0124 13:48:27.436969       1 scheduler.go:614] [GetControllerMetricInfo] Métricas do controlador definidas para o pod: default/test-deployment2-59c6b78cd5-dbnl2
I0124 13:48:27.437086       1 scheduler.go:84] [HigherPrecedence] Calculando precedência entre test-deployment3-6c95cffb97-585vw e test-deployment2-59c6b78cd5-dbnl2
I0124 13:48:27.437206       1 scheduler.go:117] [WaitForPodsOnCache] Verificando se o pod test-deployment3-6c95cffb97-585vw está no cache...
I0124 13:48:27.437241       1 scheduler.go:606] [GetControllerMetricInfo] Iniciando para o pod: default/test-deployment3-6c95cffb97-585vw
I0124 13:48:27.437352       1 scheduler.go:611] [GetControllerMetricInfo] Obtendo o nome do controlador para o pod: default/test-deployment3-6c95cffb97-585vw
I0124 13:48:27.437495       1 types.go:743] [ControllerName] Verificando as anotações do pod default/test-deployment3-6c95cffb97-585vw
I0124 13:48:27.437529       1 types.go:761] [ControllerName] Anotação 'controller' encontrada para o pod default/test-deployment3-6c95cffb97-585vw: test-controller3
I0124 13:48:27.437581       1 scheduler.go:614] [GetControllerMetricInfo] Métricas do controlador definidas para o pod: default/test-deployment3-6c95cffb97-585vw
I0124 13:48:27.442730       1 scheduler.go:70] Estado no Informer: map[controller:test-controller3]
I0124 13:48:27.442752       1 scheduler.go:71] Estado real no cluster: map[controller:test-controller3]
I0124 13:48:27.442759       1 scheduler.go:139] [WaitForPodsOnCache] Pod test-deployment3-6c95cffb97-585vw encontrado no cache.
I0124 13:48:27.442765       1 scheduler.go:117] [WaitForPodsOnCache] Verificando se o pod test-deployment2-59c6b78cd5-dbnl2 está no cache...
I0124 13:48:27.442771       1 scheduler.go:606] [GetControllerMetricInfo] Iniciando para o pod: default/test-deployment2-59c6b78cd5-dbnl2
I0124 13:48:27.442788       1 scheduler.go:611] [GetControllerMetricInfo] Obtendo o nome do controlador para o pod: default/test-deployment2-59c6b78cd5-dbnl2
I0124 13:48:27.442794       1 types.go:743] [ControllerName] Verificando as anotações do pod default/test-deployment2-59c6b78cd5-dbnl2
I0124 13:48:27.442800       1 types.go:761] [ControllerName] Anotação 'controller' encontrada para o pod default/test-deployment2-59c6b78cd5-dbnl2: test-controller2
I0124 13:48:27.442807       1 scheduler.go:614] [GetControllerMetricInfo] Métricas do controlador definidas para o pod: default/test-deployment2-59c6b78cd5-dbnl2
I0124 13:48:27.445400       1 scheduler.go:70] Estado no Informer: map[controller:test-controller2]
I0124 13:48:27.446399       1 scheduler.go:71] Estado real no cluster: map[controller:test-controller2]
I0124 13:48:27.446410       1 scheduler.go:139] [WaitForPodsOnCache] Pod test-deployment2-59c6b78cd5-dbnl2 encontrado no cache.
I0124 13:48:27.446417       1 scheduler.go:606] [GetControllerMetricInfo] Iniciando para o pod: default/test-deployment3-6c95cffb97-585vw
I0124 13:48:27.446423       1 scheduler.go:611] [GetControllerMetricInfo] Obtendo o nome do controlador para o pod: default/test-deployment3-6c95cffb97-585vw
I0124 13:48:27.446428       1 types.go:743] [ControllerName] Verificando as anotações do pod default/test-deployment3-6c95cffb97-585vw
I0124 13:48:27.446435       1 types.go:761] [ControllerName] Anotação 'controller' encontrada para o pod default/test-deployment3-6c95cffb97-585vw: test-controller3
I0124 13:48:27.446468       1 scheduler.go:614] [GetControllerMetricInfo] Métricas do controlador definidas para o pod: default/test-deployment3-6c95cffb97-585vw
I0124 13:48:27.446478       1 scheduler.go:606] [GetControllerMetricInfo] Iniciando para o pod: default/test-deployment2-59c6b78cd5-dbnl2
I0124 13:48:27.446483       1 scheduler.go:611] [GetControllerMetricInfo] Obtendo o nome do controlador para o pod: default/test-deployment2-59c6b78cd5-dbnl2
I0124 13:48:27.446487       1 types.go:743] [ControllerName] Verificando as anotações do pod default/test-deployment2-59c6b78cd5-dbnl2
I0124 13:48:27.446493       1 types.go:761] [ControllerName] Anotação 'controller' encontrada para o pod default/test-deployment2-59c6b78cd5-dbnl2: test-controller2
I0124 13:48:27.446498       1 scheduler.go:614] [GetControllerMetricInfo] Métricas do controlador definidas para o pod: default/test-deployment2-59c6b78cd5-dbnl2
I0124 13:48:27.446512       1 scheduler.go:98] [HigherPrecedence] Métricas para test-deployment3-6c95cffb97-585vw: QoS = -2.837080, Importância = 0.80
I0124 13:48:27.446565       1 scheduler.go:99] [HigherPrecedence] Métricas para test-deployment2-59c6b78cd5-dbnl2: QoS = 22.526786, Importância = 0.80
I0124 13:48:27.446616       1 scheduler.go:110] [HigherPrecedence] Decisão final: test-deployment3-6c95cffb97-585vw tem precedência sobre test-deployment2-59c6b78cd5-dbnl2? true
I0124 13:48:27.446622       1 types.go:743] [ControllerName] Verificando as anotações do pod default/test-deployment3-6c95cffb97-585vw
I0124 13:48:27.446630       1 types.go:761] [ControllerName] Anotação 'controller' encontrada para o pod default/test-deployment3-6c95cffb97-585vw: test-controller3
I0124 13:48:27.446634       1 types.go:743] [ControllerName] Verificando as anotações do pod default/test-deployment2-59c6b78cd5-dbnl2
I0124 13:48:27.446640       1 types.go:761] [ControllerName] Anotação 'controller' encontrada para o pod default/test-deployment2-59c6b78cd5-dbnl2: test-controller2
I0124 13:48:27.446645       1 scheduler.go:606] [GetControllerMetricInfo] Iniciando para o pod: default/test-deployment2-59c6b78cd5-dbnl2
I0124 13:48:27.446650       1 scheduler.go:611] [GetControllerMetricInfo] Obtendo o nome do controlador para o pod: default/test-deployment2-59c6b78cd5-dbnl2
I0124 13:48:27.446655       1 types.go:743] [ControllerName] Verificando as anotações do pod default/test-deployment2-59c6b78cd5-dbnl2
I0124 13:48:27.446660       1 types.go:761] [ControllerName] Anotação 'controller' encontrada para o pod default/test-deployment2-59c6b78cd5-dbnl2: test-controller2
I0124 13:48:27.446667       1 scheduler.go:614] [GetControllerMetricInfo] Métricas do controlador definidas para o pod: default/test-deployment2-59c6b78cd5-dbnl2
I0124 13:48:27.446672       1 scheduler.go:606] [GetControllerMetricInfo] Iniciando para o pod: default/test-deployment2-59c6b78cd5-dbnl2
I0124 13:48:27.446678       1 scheduler.go:611] [GetControllerMetricInfo] Obtendo o nome do controlador para o pod: default/test-deployment2-59c6b78cd5-dbnl2
I0124 13:48:27.446707       1 types.go:743] [ControllerName] Verificando as anotações do pod default/test-deployment2-59c6b78cd5-dbnl2
I0124 13:48:27.446714       1 types.go:761] [ControllerName] Anotação 'controller' encontrada para o pod default/test-deployment2-59c6b78cd5-dbnl2: test-controller2
I0124 13:48:27.446731       1 scheduler.go:614] [GetControllerMetricInfo] Métricas do controlador definidas para o pod: default/test-deployment2-59c6b78cd5-dbnl2
I0124 13:48:27.447103       1 types.go:743] [ControllerName] Verificando as anotações do pod default/test-deployment2-59c6b78cd5-dbnl2
I0124 13:48:27.447584       1 types.go:761] [ControllerName] Anotação 'controller' encontrada para o pod default/test-deployment2-59c6b78cd5-dbnl2: test-controller2
I0124 13:48:27.447729       1 scheduler.go:606] [GetControllerMetricInfo] Iniciando para o pod: default/test-deployment2-59c6b78cd5-dbnl2
I0124 13:48:27.447764       1 scheduler.go:611] [GetControllerMetricInfo] Obtendo o nome do controlador para o pod: default/test-deployment2-59c6b78cd5-dbnl2
I0124 13:48:27.447771       1 types.go:743] [ControllerName] Verificando as anotações do pod default/test-deployment2-59c6b78cd5-dbnl2
I0124 13:48:27.447776       1 types.go:761] [ControllerName] Anotação 'controller' encontrada para o pod default/test-deployment2-59c6b78cd5-dbnl2: test-controller2
I0124 13:48:27.447782       1 scheduler.go:614] [GetControllerMetricInfo] Métricas do controlador definidas para o pod: default/test-deployment2-59c6b78cd5-dbnl2
I0124 13:48:27.447791       1 scheduler.go:606] [GetControllerMetricInfo] Iniciando para o pod: default/test-deployment2-59c6b78cd5-dbnl2
I0124 13:48:27.447821       1 scheduler.go:611] [GetControllerMetricInfo] Obtendo o nome do controlador para o pod: default/test-deployment2-59c6b78cd5-dbnl2
I0124 13:48:27.447923       1 types.go:743] [ControllerName] Verificando as anotações do pod default/test-deployment2-59c6b78cd5-dbnl2
I0124 13:48:27.447955       1 types.go:761] [ControllerName] Anotação 'controller' encontrada para o pod default/test-deployment2-59c6b78cd5-dbnl2: test-controller2
I0124 13:48:27.447986       1 scheduler.go:614] [GetControllerMetricInfo] Métricas do controlador definidas para o pod: default/test-deployment2-59c6b78cd5-dbnl2
I0124 13:48:27.448006       1 postFilter.go:150] [PREEMPT CALL] The node minikube  was chosen to allocate pod test-deployment3-6c95cffb97-585vw
I0124 13:48:27.448047       1 postFilter.go:154] [Preempt] Iniciando a remoção dos pods preemptados no nó minikube para alocar o pod default/test-deployment3-6c95cffb97-585vw. Total de vítimas: 1
I0124 13:48:27.448069       1 postFilter.go:158] [Preempt] Tentando remover o pod default/test-deployment2-59c6b78cd5-dbnl2 no nó minikube
I0124 13:48:27.470607       1 postFilter.go:164] [Preempt] Pod default/test-deployment2-59c6b78cd5-dbnl2 removido com sucesso no nó minikube
I0124 13:48:27.470634       1 postFilter.go:170] test-deployment2-59c6b78cd5-dbnl2_default preempted by test-deployment3-6c95cffb97-585vw_default on node minikube
I0124 13:48:27.470679       1 postFilter.go:175] [Preempt] Total de pods preemptados no nó minikube: 1
I0124 13:48:27.470714       1 postFilter.go:182] [Preempt] Verificando pods de menor precedência no nó minikube que precisam ter o campo NominatedNodeName limpo
I0124 13:48:27.470726       1 postFilter.go:192] [Preempt] Finalizado para o nó minikube. Pod default/test-deployment3-6c95cffb97-585vw deve ser alocado agora.
I0124 13:48:27.470733       1 postFilter.go:52] [PostFilter] Nó nominado para o pod default/test-deployment3-6c95cffb97-585vw: minikube
I0124 13:48:27.476708       1 scheduler.go:258] [OnUpdatePod] Iniciando processamento de atualização de pod
I0124 13:48:27.477080       1 scheduler.go:262] [OnUpdatePod] Pod atualizado detectado: default/test-deployment2-59c6b78cd5-dbnl2, Anotações: map[controller:test-controller2]
I0124 13:48:27.477270       1 scheduler.go:265] [OnUpdatePod] Comparando estado no Informer e estado real no cluster para o pod default/test-deployment2-59c6b78cd5-dbnl2
I0124 13:48:27.768600       1 postFilter.go:29] [PostFilter] PostFilter chamado para pod: default/test-deployment2-59c6b78cd5-4pw59
I0124 13:48:27.769039       1 scheduler.go:70] Estado no Informer: map[controller:test-controller2]
I0124 13:48:27.776284       1 scheduler.go:71] Estado real no cluster: map[controller:test-controller2]
I0124 13:48:27.776301       1 scheduler.go:275] [OnUpdatePod] Atualizando informações de métricas para o pod default/test-deployment2-59c6b78cd5-dbnl2
I0124 13:48:27.776410       1 types.go:743] [ControllerName] Verificando as anotações do pod default/test-deployment2-59c6b78cd5-dbnl2
I0124 13:48:27.776425       1 types.go:761] [ControllerName] Anotação 'controller' encontrada para o pod default/test-deployment2-59c6b78cd5-dbnl2: test-controller2
I0124 13:48:27.776537       1 scheduler.go:277] [OnUpdatePod] Atualizando 'LastStatus' do pod default/test-deployment2-59c6b78cd5-dbnl2 nas métricas
I0124 13:48:27.776546       1 scheduler.go:279] [OnUpdatePod] Métrica atualizada para o pod default/test-deployment2-59c6b78cd5-dbnl2
I0124 13:48:27.776678       1 scheduler.go:283] [OnUpdatePod] Finalizando processamento de atualização de pod para default/test-deployment2-59c6b78cd5-dbnl2
I0124 13:48:27.776827       1 scheduler.go:218] [OnAddPod] Pod adicionado: default/test-deployment2-59c6b78cd5-4pw59, Anotações: map[controller:test-controller2]
I0124 13:48:27.780237       1 types.go:743] [ControllerName] Verificando as anotações do pod default/test-deployment2-59c6b78cd5-dbnl2
I0124 13:48:27.780361       1 types.go:761] [ControllerName] Anotação 'controller' encontrada para o pod default/test-deployment2-59c6b78cd5-dbnl2: test-controller2
I0124 13:48:28.047220       1 scheduler.go:70] Estado no Informer: map[controller:test-controller2]
I0124 13:48:28.047324       1 scheduler.go:71] Estado real no cluster: map[controller:test-controller2]
I0124 13:48:28.047756       1 scheduler.go:229] [OnAddPod] Adicionando pod default/test-deployment2-59c6b78cd5-4pw59 com os seguintes detalhes:
I0124 13:48:28.047840       1 types.go:743] [ControllerName] Verificando as anotações do pod default/test-deployment2-59c6b78cd5-4pw59
I0124 13:48:28.075509       1 types.go:761] [ControllerName] Anotação 'controller' encontrada para o pod default/test-deployment2-59c6b78cd5-4pw59: test-controller2
I0124 13:48:28.075531       1 scheduler.go:238] [OnAddPod] Atualizando métricas para o pod default/test-deployment2-59c6b78cd5-4pw59
I0124 13:48:28.075540       1 types.go:743] [ControllerName] Verificando as anotações do pod default/test-deployment2-59c6b78cd5-4pw59
I0124 13:48:28.075552       1 types.go:761] [ControllerName] Anotação 'controller' encontrada para o pod default/test-deployment2-59c6b78cd5-4pw59: test-controller2
I0124 13:48:28.075573       1 scheduler.go:251] [OnAddPod] Pod default/test-deployment2-59c6b78cd5-4pw59 adicionado com sucesso
I0124 13:48:28.075599       1 postFilter.go:79] Comparando pod original com o atualizado...
I0124 13:48:28.075611       1 postFilter.go:86] Successfully retrieved updated pod default/test-deployment2-59c6b78cd5-4pw59 from lister
I0124 13:48:28.252240       1 postFilter.go:229] [compareNodeResources] Recursos calculados no nó minikube: CPU = 1750 mCPU, Memória = 178257920 bytes
I0124 13:48:28.256018       1 postFilter.go:230] [compareNodeResources] Recursos do snapshot no nó minikube: CPU = 1750 mCPU, Memória = 178257920 bytes
I0124 13:48:28.257461       1 postFilter.go:236] [compareNodeResources] Recursos de CPU do nó minikube estão sincronizados: 1750 mCPU
I0124 13:48:28.257620       1 postFilter.go:242] [compareNodeResources] Recursos de memória do nó minikube estão sincronizados: 178257920 bytes
I0124 13:48:28.260985       1 scheduler.go:606] [GetControllerMetricInfo] Iniciando para o pod: default/test-deployment2-59c6b78cd5-dbnl2
I0124 13:48:28.261269       1 scheduler.go:611] [GetControllerMetricInfo] Obtendo o nome do controlador para o pod: default/test-deployment2-59c6b78cd5-dbnl2
I0124 13:48:28.261448       1 types.go:743] [ControllerName] Verificando as anotações do pod default/test-deployment2-59c6b78cd5-dbnl2
I0124 13:48:28.261609       1 types.go:761] [ControllerName] Anotação 'controller' encontrada para o pod default/test-deployment2-59c6b78cd5-dbnl2: test-controller2
I0124 13:48:28.268059       1 scheduler.go:614] [GetControllerMetricInfo] Métricas do controlador definidas para o pod: default/test-deployment2-59c6b78cd5-dbnl2
I0124 13:48:28.268080       1 scheduler.go:84] [HigherPrecedence] Calculando precedência entre test-deployment2-59c6b78cd5-4pw59 e test-deployment2-59c6b78cd5-dbnl2
I0124 13:48:28.268087       1 scheduler.go:117] [WaitForPodsOnCache] Verificando se o pod test-deployment2-59c6b78cd5-4pw59 está no cache...
I0124 13:48:28.268092       1 scheduler.go:606] [GetControllerMetricInfo] Iniciando para o pod: default/test-deployment2-59c6b78cd5-4pw59
I0124 13:48:28.268098       1 scheduler.go:611] [GetControllerMetricInfo] Obtendo o nome do controlador para o pod: default/test-deployment2-59c6b78cd5-4pw59
I0124 13:48:28.268104       1 types.go:743] [ControllerName] Verificando as anotações do pod default/test-deployment2-59c6b78cd5-4pw59
I0124 13:48:28.268112       1 types.go:761] [ControllerName] Anotação 'controller' encontrada para o pod default/test-deployment2-59c6b78cd5-4pw59: test-controller2
I0124 13:48:28.268118       1 scheduler.go:614] [GetControllerMetricInfo] Métricas do controlador definidas para o pod: default/test-deployment2-59c6b78cd5-4pw59
I0124 13:48:28.282364       1 scheduler.go:70] Estado no Informer: map[controller:test-controller2]
I0124 13:48:28.282490       1 scheduler.go:71] Estado real no cluster: map[controller:test-controller2]
I0124 13:48:28.282505       1 scheduler.go:139] [WaitForPodsOnCache] Pod test-deployment2-59c6b78cd5-4pw59 encontrado no cache.
I0124 13:48:28.282511       1 scheduler.go:117] [WaitForPodsOnCache] Verificando se o pod test-deployment2-59c6b78cd5-dbnl2 está no cache...
I0124 13:48:28.282517       1 scheduler.go:606] [GetControllerMetricInfo] Iniciando para o pod: default/test-deployment2-59c6b78cd5-dbnl2
I0124 13:48:28.282522       1 scheduler.go:611] [GetControllerMetricInfo] Obtendo o nome do controlador para o pod: default/test-deployment2-59c6b78cd5-dbnl2
I0124 13:48:28.282528       1 types.go:743] [ControllerName] Verificando as anotações do pod default/test-deployment2-59c6b78cd5-dbnl2
I0124 13:48:28.282600       1 types.go:761] [ControllerName] Anotação 'controller' encontrada para o pod default/test-deployment2-59c6b78cd5-dbnl2: test-controller2
I0124 13:48:28.282630       1 scheduler.go:614] [GetControllerMetricInfo] Métricas do controlador definidas para o pod: default/test-deployment2-59c6b78cd5-dbnl2
I0124 13:48:28.297742       1 scheduler.go:70] Estado no Informer: map[controller:test-controller2]
I0124 13:48:28.298100       1 scheduler.go:71] Estado real no cluster: map[controller:test-controller2]
I0124 13:48:28.298226       1 scheduler.go:139] [WaitForPodsOnCache] Pod test-deployment2-59c6b78cd5-dbnl2 encontrado no cache.
I0124 13:48:28.298343       1 scheduler.go:606] [GetControllerMetricInfo] Iniciando para o pod: default/test-deployment2-59c6b78cd5-4pw59
I0124 13:48:28.298467       1 scheduler.go:611] [GetControllerMetricInfo] Obtendo o nome do controlador para o pod: default/test-deployment2-59c6b78cd5-4pw59
I0124 13:48:28.298579       1 types.go:743] [ControllerName] Verificando as anotações do pod default/test-deployment2-59c6b78cd5-4pw59
I0124 13:48:28.298691       1 types.go:761] [ControllerName] Anotação 'controller' encontrada para o pod default/test-deployment2-59c6b78cd5-4pw59: test-controller2
I0124 13:48:28.298787       1 scheduler.go:614] [GetControllerMetricInfo] Métricas do controlador definidas para o pod: default/test-deployment2-59c6b78cd5-4pw59
I0124 13:48:28.298923       1 scheduler.go:606] [GetControllerMetricInfo] Iniciando para o pod: default/test-deployment2-59c6b78cd5-dbnl2
I0124 13:48:28.299039       1 scheduler.go:611] [GetControllerMetricInfo] Obtendo o nome do controlador para o pod: default/test-deployment2-59c6b78cd5-dbnl2
I0124 13:48:28.299150       1 types.go:743] [ControllerName] Verificando as anotações do pod default/test-deployment2-59c6b78cd5-dbnl2
I0124 13:48:28.299192       1 types.go:761] [ControllerName] Anotação 'controller' encontrada para o pod default/test-deployment2-59c6b78cd5-dbnl2: test-controller2
I0124 13:48:28.299301       1 scheduler.go:614] [GetControllerMetricInfo] Métricas do controlador definidas para o pod: default/test-deployment2-59c6b78cd5-dbnl2
I0124 13:48:28.299420       1 scheduler.go:98] [HigherPrecedence] Métricas para test-deployment2-59c6b78cd5-4pw59: QoS = 21.491904, Importância = 0.80
I0124 13:48:28.299544       1 scheduler.go:99] [HigherPrecedence] Métricas para test-deployment2-59c6b78cd5-dbnl2: QoS = 9.537822, Importância = 0.80
I0124 13:48:28.299661       1 scheduler.go:110] [HigherPrecedence] Decisão final: test-deployment2-59c6b78cd5-4pw59 tem precedência sobre test-deployment2-59c6b78cd5-dbnl2? false
I0124 13:48:28.299906       1 postFilter.go:147] [PREEMPT CALL] No node was chosen to allocate pod test-deployment2-59c6b78cd5-4pw59
W0124 13:48:28.300089       1 postFilter.go:48] [PostFilter] Nenhum nó nominado após a preempção para o pod: default/test-deployment2-59c6b78cd5-4pw59
I0124 13:48:28.300471       1 scheduler.go:258] [OnUpdatePod] Iniciando processamento de atualização de pod
I0124 13:48:28.304465       1 scheduler.go:262] [OnUpdatePod] Pod atualizado detectado: default/test-deployment3-6c95cffb97-585vw, Anotações: map[controller:test-controller3]
I0124 13:48:28.304610       1 scheduler.go:265] [OnUpdatePod] Comparando estado no Informer e estado real no cluster para o pod default/test-deployment3-6c95cffb97-585vw
I0124 13:48:28.339080       1 scheduler.go:70] Estado no Informer: map[controller:test-controller3]
I0124 13:48:28.340603       1 scheduler.go:71] Estado real no cluster: map[controller:test-controller3]
I0124 13:48:28.340831       1 scheduler.go:275] [OnUpdatePod] Atualizando informações de métricas para o pod default/test-deployment3-6c95cffb97-585vw
I0124 13:48:28.341083       1 types.go:743] [ControllerName] Verificando as anotações do pod default/test-deployment3-6c95cffb97-585vw
I0124 13:48:28.341200       1 types.go:761] [ControllerName] Anotação 'controller' encontrada para o pod default/test-deployment3-6c95cffb97-585vw: test-controller3
I0124 13:48:28.341343       1 scheduler.go:277] [OnUpdatePod] Atualizando 'LastStatus' do pod default/test-deployment3-6c95cffb97-585vw nas métricas
I0124 13:48:28.341443       1 scheduler.go:279] [OnUpdatePod] Métrica atualizada para o pod default/test-deployment3-6c95cffb97-585vw
I0124 13:48:28.341573       1 scheduler.go:283] [OnUpdatePod] Finalizando processamento de atualização de pod para default/test-deployment3-6c95cffb97-585vw
I0124 13:48:28.735554       1 scheduler.go:258] [OnUpdatePod] Iniciando processamento de atualização de pod
I0124 13:48:28.735671       1 scheduler.go:262] [OnUpdatePod] Pod atualizado detectado: default/test-deployment2-59c6b78cd5-4pw59, Anotações: map[controller:test-controller2]
I0124 13:48:28.735700       1 scheduler.go:265] [OnUpdatePod] Comparando estado no Informer e estado real no cluster para o pod default/test-deployment2-59c6b78cd5-4pw59
I0124 13:48:28.757395       1 scheduler.go:70] Estado no Informer: map[controller:test-controller2]
I0124 13:48:28.757441       1 scheduler.go:71] Estado real no cluster: map[controller:test-controller2]
I0124 13:48:28.757458       1 scheduler.go:275] [OnUpdatePod] Atualizando informações de métricas para o pod default/test-deployment2-59c6b78cd5-4pw59
I0124 13:48:28.757470       1 types.go:743] [ControllerName] Verificando as anotações do pod default/test-deployment2-59c6b78cd5-4pw59
I0124 13:48:28.757482       1 types.go:761] [ControllerName] Anotação 'controller' encontrada para o pod default/test-deployment2-59c6b78cd5-4pw59: test-controller2
I0124 13:48:28.758945       1 scheduler.go:277] [OnUpdatePod] Atualizando 'LastStatus' do pod default/test-deployment2-59c6b78cd5-4pw59 nas métricas
I0124 13:48:28.760718       1 scheduler.go:279] [OnUpdatePod] Métrica atualizada para o pod default/test-deployment2-59c6b78cd5-4pw59
I0124 13:48:28.761253       1 scheduler.go:283] [OnUpdatePod] Finalizando processamento de atualização de pod para default/test-deployment2-59c6b78cd5-4pw59
I0124 13:48:29.514384       1 scheduler.go:291] [OnDeletePod] Iniciando a execução do OnDeletePod
I0124 13:48:29.514453       1 scheduler.go:300] [OnDeletePod] DeepCopy realizado para o pod default/test-deployment2-59c6b78cd5-dbnl2
I0124 13:48:29.516063       1 scheduler.go:307] [OnDeletePod] Pod deletado detectado: default/test-deployment2-59c6b78cd5-dbnl2
I0124 13:48:29.516120       1 scheduler.go:309] [OnDeletePod] Atualizando métricas do pod default/test-deployment2-59c6b78cd5-dbnl2
I0124 13:48:29.516134       1 types.go:743] [ControllerName] Verificando as anotações do pod default/test-deployment2-59c6b78cd5-dbnl2
I0124 13:48:29.516142       1 types.go:761] [ControllerName] Anotação 'controller' encontrada para o pod default/test-deployment2-59c6b78cd5-dbnl2: test-controller2
I0124 13:48:29.516154       1 scheduler.go:311] [OnDeletePod] Verificando o estado do pod default/test-deployment2-59c6b78cd5-dbnl2 nas métricas
I0124 13:48:29.516163       1 scheduler.go:321] [OnDeletePod] EndTime atualizado para o pod default/test-deployment2-59c6b78cd5-dbnl2: 2025-01-24 13:48:29.516157663 +0000 UTC m=+174.333091798
I0124 13:48:29.516182       1 scheduler.go:325] [OnDeletePod] Finalizando a execução do OnDeletePod para o pod default/test-deployment2-59c6b78cd5-dbnl2
I0124 13:48:29.516331       1 scheduler.go:54] [QueueSort] Comparando prioridade de test-deployment2-59c6b78cd5-4pw59 com test-deployment3-6c95cffb97-585vw
I0124 13:48:29.516340       1 scheduler.go:84] [HigherPrecedence] Calculando precedência entre test-deployment2-59c6b78cd5-4pw59 e test-deployment3-6c95cffb97-585vw
I0124 13:48:29.516347       1 scheduler.go:117] [WaitForPodsOnCache] Verificando se o pod test-deployment2-59c6b78cd5-4pw59 está no cache...
I0124 13:48:29.516353       1 scheduler.go:606] [GetControllerMetricInfo] Iniciando para o pod: default/test-deployment2-59c6b78cd5-4pw59
I0124 13:48:29.516359       1 scheduler.go:611] [GetControllerMetricInfo] Obtendo o nome do controlador para o pod: default/test-deployment2-59c6b78cd5-4pw59
I0124 13:48:29.516364       1 types.go:743] [ControllerName] Verificando as anotações do pod default/test-deployment2-59c6b78cd5-4pw59
I0124 13:48:29.516371       1 types.go:761] [ControllerName] Anotação 'controller' encontrada para o pod default/test-deployment2-59c6b78cd5-4pw59: test-controller2
I0124 13:48:29.516377       1 scheduler.go:614] [GetControllerMetricInfo] Métricas do controlador definidas para o pod: default/test-deployment2-59c6b78cd5-4pw59
I0124 13:48:29.532983       1 scheduler.go:70] Estado no Informer: map[controller:test-controller2]
I0124 13:48:29.533015       1 scheduler.go:71] Estado real no cluster: map[controller:test-controller2]
I0124 13:48:29.533023       1 scheduler.go:139] [WaitForPodsOnCache] Pod test-deployment2-59c6b78cd5-4pw59 encontrado no cache.
I0124 13:48:29.533029       1 scheduler.go:117] [WaitForPodsOnCache] Verificando se o pod test-deployment3-6c95cffb97-585vw está no cache...
I0124 13:48:29.533036       1 scheduler.go:606] [GetControllerMetricInfo] Iniciando para o pod: default/test-deployment3-6c95cffb97-585vw
I0124 13:48:29.533041       1 scheduler.go:611] [GetControllerMetricInfo] Obtendo o nome do controlador para o pod: default/test-deployment3-6c95cffb97-585vw
I0124 13:48:29.533048       1 types.go:743] [ControllerName] Verificando as anotações do pod default/test-deployment3-6c95cffb97-585vw
I0124 13:48:29.533055       1 types.go:761] [ControllerName] Anotação 'controller' encontrada para o pod default/test-deployment3-6c95cffb97-585vw: test-controller3
I0124 13:48:29.533061       1 scheduler.go:614] [GetControllerMetricInfo] Métricas do controlador definidas para o pod: default/test-deployment3-6c95cffb97-585vw
I0124 13:48:29.538805       1 scheduler.go:70] Estado no Informer: map[controller:test-controller3]
I0124 13:48:29.539025       1 scheduler.go:71] Estado real no cluster: map[controller:test-controller3]
I0124 13:48:29.539114       1 scheduler.go:139] [WaitForPodsOnCache] Pod test-deployment3-6c95cffb97-585vw encontrado no cache.
I0124 13:48:29.539133       1 scheduler.go:606] [GetControllerMetricInfo] Iniciando para o pod: default/test-deployment2-59c6b78cd5-4pw59
I0124 13:48:29.539144       1 scheduler.go:611] [GetControllerMetricInfo] Obtendo o nome do controlador para o pod: default/test-deployment2-59c6b78cd5-4pw59
I0124 13:48:29.539214       1 types.go:743] [ControllerName] Verificando as anotações do pod default/test-deployment2-59c6b78cd5-4pw59
I0124 13:48:29.539232       1 types.go:761] [ControllerName] Anotação 'controller' encontrada para o pod default/test-deployment2-59c6b78cd5-4pw59: test-controller2
I0124 13:48:29.539253       1 scheduler.go:614] [GetControllerMetricInfo] Métricas do controlador definidas para o pod: default/test-deployment2-59c6b78cd5-4pw59
I0124 13:48:29.539268       1 scheduler.go:606] [GetControllerMetricInfo] Iniciando para o pod: default/test-deployment3-6c95cffb97-585vw
I0124 13:48:29.539336       1 scheduler.go:611] [GetControllerMetricInfo] Obtendo o nome do controlador para o pod: default/test-deployment3-6c95cffb97-585vw
I0124 13:48:29.539350       1 types.go:743] [ControllerName] Verificando as anotações do pod default/test-deployment3-6c95cffb97-585vw
I0124 13:48:29.539367       1 types.go:761] [ControllerName] Anotação 'controller' encontrada para o pod default/test-deployment3-6c95cffb97-585vw: test-controller3
I0124 13:48:29.539383       1 scheduler.go:614] [GetControllerMetricInfo] Métricas do controlador definidas para o pod: default/test-deployment3-6c95cffb97-585vw
I0124 13:48:29.539461       1 scheduler.go:98] [HigherPrecedence] Métricas para test-deployment2-59c6b78cd5-4pw59: QoS = 20.555663, Importância = 0.80
I0124 13:48:29.539486       1 scheduler.go:99] [HigherPrecedence] Métricas para test-deployment3-6c95cffb97-585vw: QoS = -4.916336, Importância = 0.80
I0124 13:48:29.539556       1 scheduler.go:110] [HigherPrecedence] Decisão final: test-deployment2-59c6b78cd5-4pw59 tem precedência sobre test-deployment3-6c95cffb97-585vw? false
I0124 13:48:29.539576       1 scheduler.go:60] [QueueSort] Precedência determinada: test-deployment2-59c6b78cd5-4pw59 tem precedência sobre test-deployment3-6c95cffb97-585vw? false
I0124 13:48:29.540470       1 scheduler.go:146] [Reserve] resources reserved at node minikube for pod test-deployment3-6c95cffb97-585vw_default at 2025-01-24 13:48:29.54046188 +0000 UTC m=+174.357395762
I0124 13:48:29.540564       1 types.go:743] [ControllerName] Verificando as anotações do pod default/test-deployment3-6c95cffb97-585vw
I0124 13:48:29.540581       1 types.go:761] [ControllerName] Anotação 'controller' encontrada para o pod default/test-deployment3-6c95cffb97-585vw: test-controller3
I0124 13:48:29.540600       1 scheduler.go:148] [Reserve] Status de alocação atual para o pod test-deployment3-6c95cffb97-585vw_default: 
I0124 13:48:29.540627       1 scheduler.go:150] [Reserve] Status de alocação atualizado para o pod test-deployment3-6c95cffb97-585vw_default: allocating
I0124 13:48:29.541077       1 postFilter.go:29] [PostFilter] PostFilter chamado para pod: default/test-deployment2-59c6b78cd5-4pw59
I0124 13:48:29.541153       1 postFilter.go:79] Comparando pod original com o atualizado...
I0124 13:48:29.541173       1 postFilter.go:86] Successfully retrieved updated pod default/test-deployment2-59c6b78cd5-4pw59 from lister
I0124 13:48:29.541585       1 scheduler.go:174] [PreBind] Validando o pod test-deployment3-6c95cffb97-585vw antes de vincular ao node minikube
I0124 13:48:29.550643       1 postFilter.go:229] [compareNodeResources] Recursos calculados no nó minikube: CPU = 1750 mCPU, Memória = 178257920 bytes
I0124 13:48:29.550729       1 postFilter.go:230] [compareNodeResources] Recursos do snapshot no nó minikube: CPU = 1750 mCPU, Memória = 178257920 bytes
I0124 13:48:29.550753       1 postFilter.go:236] [compareNodeResources] Recursos de CPU do nó minikube estão sincronizados: 1750 mCPU
I0124 13:48:29.550770       1 postFilter.go:242] [compareNodeResources] Recursos de memória do nó minikube estão sincronizados: 178257920 bytes
I0124 13:48:29.562984       1 scheduler.go:606] [GetControllerMetricInfo] Iniciando para o pod: default/test-deployment3-6c95cffb97-585vw
I0124 13:48:29.563798       1 scheduler.go:611] [GetControllerMetricInfo] Obtendo o nome do controlador para o pod: default/test-deployment3-6c95cffb97-585vw
I0124 13:48:29.563971       1 types.go:743] [ControllerName] Verificando as anotações do pod default/test-deployment3-6c95cffb97-585vw
I0124 13:48:29.564045       1 types.go:761] [ControllerName] Anotação 'controller' encontrada para o pod default/test-deployment3-6c95cffb97-585vw: test-controller3
I0124 13:48:29.564119       1 scheduler.go:614] [GetControllerMetricInfo] Métricas do controlador definidas para o pod: default/test-deployment3-6c95cffb97-585vw
I0124 13:48:29.564143       1 scheduler.go:84] [HigherPrecedence] Calculando precedência entre test-deployment2-59c6b78cd5-4pw59 e test-deployment3-6c95cffb97-585vw
I0124 13:48:29.564208       1 scheduler.go:117] [WaitForPodsOnCache] Verificando se o pod test-deployment2-59c6b78cd5-4pw59 está no cache...
I0124 13:48:29.564223       1 scheduler.go:606] [GetControllerMetricInfo] Iniciando para o pod: default/test-deployment2-59c6b78cd5-4pw59
I0124 13:48:29.564239       1 scheduler.go:611] [GetControllerMetricInfo] Obtendo o nome do controlador para o pod: default/test-deployment2-59c6b78cd5-4pw59
I0124 13:48:29.564250       1 types.go:743] [ControllerName] Verificando as anotações do pod default/test-deployment2-59c6b78cd5-4pw59
I0124 13:48:29.564315       1 types.go:761] [ControllerName] Anotação 'controller' encontrada para o pod default/test-deployment2-59c6b78cd5-4pw59: test-controller2
I0124 13:48:29.564332       1 scheduler.go:614] [GetControllerMetricInfo] Métricas do controlador definidas para o pod: default/test-deployment2-59c6b78cd5-4pw59
I0124 13:48:29.597800       1 scheduler.go:182] [PostBind] Chamado para pod test-deployment3-6c95cffb97-585vw
I0124 13:48:29.598686       1 scheduler.go:200] [PostBind] Pod test-deployment3-6c95cffb97-585vw - Início do binding: 2025-01-24 13:48:29.543022101 +0000 UTC m=+174.359955983, Fim do binding: 2025-01-24 13:48:29.598676205 +0000 UTC m=+174.415610426
I0124 13:48:29.602588       1 scheduler.go:70] Estado no Informer: map[controller:test-controller2]
I0124 13:48:29.603735       1 scheduler.go:71] Estado real no cluster: map[controller:test-controller2]
I0124 13:48:29.604324       1 scheduler.go:139] [WaitForPodsOnCache] Pod test-deployment2-59c6b78cd5-4pw59 encontrado no cache.
I0124 13:48:29.604579       1 scheduler.go:117] [WaitForPodsOnCache] Verificando se o pod test-deployment3-6c95cffb97-585vw está no cache...
I0124 13:48:29.604592       1 scheduler.go:606] [GetControllerMetricInfo] Iniciando para o pod: default/test-deployment3-6c95cffb97-585vw
I0124 13:48:29.604755       1 types.go:743] [ControllerName] Verificando as anotações do pod default/test-deployment3-6c95cffb97-585vw
I0124 13:48:29.604975       1 types.go:761] [ControllerName] Anotação 'controller' encontrada para o pod default/test-deployment3-6c95cffb97-585vw: test-controller3
I0124 13:48:29.605135       1 scheduler.go:207] [PostBind] Métricas atualizadas para o pod test-deployment3-6c95cffb97-585vw
I0124 13:48:29.605570       1 scheduler.go:611] [GetControllerMetricInfo] Obtendo o nome do controlador para o pod: default/test-deployment3-6c95cffb97-585vw
I0124 13:48:29.605758       1 types.go:743] [ControllerName] Verificando as anotações do pod default/test-deployment3-6c95cffb97-585vw
I0124 13:48:29.606152       1 types.go:761] [ControllerName] Anotação 'controller' encontrada para o pod default/test-deployment3-6c95cffb97-585vw: test-controller3
I0124 13:48:29.606308       1 scheduler.go:614] [GetControllerMetricInfo] Métricas do controlador definidas para o pod: default/test-deployment3-6c95cffb97-585vw
I0124 13:48:29.680432       1 scheduler.go:70] Estado no Informer: map[controller:test-controller3]
I0124 13:48:29.685664       1 scheduler.go:71] Estado real no cluster: map[controller:test-controller3]
I0124 13:48:29.685697       1 scheduler.go:139] [WaitForPodsOnCache] Pod test-deployment3-6c95cffb97-585vw encontrado no cache.
I0124 13:48:29.685709       1 scheduler.go:606] [GetControllerMetricInfo] Iniciando para o pod: default/test-deployment2-59c6b78cd5-4pw59
I0124 13:48:29.685718       1 scheduler.go:611] [GetControllerMetricInfo] Obtendo o nome do controlador para o pod: default/test-deployment2-59c6b78cd5-4pw59
I0124 13:48:29.685727       1 types.go:743] [ControllerName] Verificando as anotações do pod default/test-deployment2-59c6b78cd5-4pw59
I0124 13:48:29.685737       1 types.go:761] [ControllerName] Anotação 'controller' encontrada para o pod default/test-deployment2-59c6b78cd5-4pw59: test-controller2
I0124 13:48:29.685748       1 scheduler.go:614] [GetControllerMetricInfo] Métricas do controlador definidas para o pod: default/test-deployment2-59c6b78cd5-4pw59
I0124 13:48:29.685762       1 scheduler.go:606] [GetControllerMetricInfo] Iniciando para o pod: default/test-deployment3-6c95cffb97-585vw
I0124 13:48:29.685770       1 scheduler.go:611] [GetControllerMetricInfo] Obtendo o nome do controlador para o pod: default/test-deployment3-6c95cffb97-585vw
I0124 13:48:29.685777       1 types.go:743] [ControllerName] Verificando as anotações do pod default/test-deployment3-6c95cffb97-585vw
I0124 13:48:29.685784       1 types.go:761] [ControllerName] Anotação 'controller' encontrada para o pod default/test-deployment3-6c95cffb97-585vw: test-controller3
I0124 13:48:29.685792       1 scheduler.go:614] [GetControllerMetricInfo] Métricas do controlador definidas para o pod: default/test-deployment3-6c95cffb97-585vw
I0124 13:48:29.685810       1 scheduler.go:98] [HigherPrecedence] Métricas para test-deployment2-59c6b78cd5-4pw59: QoS = 20.507865, Importância = 0.80
I0124 13:48:29.685825       1 scheduler.go:99] [HigherPrecedence] Métricas para test-deployment3-6c95cffb97-585vw: QoS = -2.662967, Importância = 0.80
I0124 13:48:29.685908       1 scheduler.go:110] [HigherPrecedence] Decisão final: test-deployment2-59c6b78cd5-4pw59 tem precedência sobre test-deployment3-6c95cffb97-585vw? false
I0124 13:48:29.692116       1 postFilter.go:147] [PREEMPT CALL] No node was chosen to allocate pod test-deployment2-59c6b78cd5-4pw59
W0124 13:48:29.692168       1 postFilter.go:48] [PostFilter] Nenhum nó nominado após a preempção para o pod: default/test-deployment2-59c6b78cd5-4pw59
I0124 13:48:29.699693       1 scheduler.go:258] [OnUpdatePod] Iniciando processamento de atualização de pod
I0124 13:48:29.699827       1 scheduler.go:262] [OnUpdatePod] Pod atualizado detectado: default/test-deployment3-6c95cffb97-585vw, Anotações: map[controller:test-controller3]
I0124 13:48:29.699923       1 scheduler.go:265] [OnUpdatePod] Comparando estado no Informer e estado real no cluster para o pod default/test-deployment3-6c95cffb97-585vw
I0124 13:48:30.222550       1 scheduler.go:70] Estado no Informer: map[controller:test-controller3]
I0124 13:48:30.222685       1 scheduler.go:71] Estado real no cluster: map[controller:test-controller3]
I0124 13:48:30.222708       1 scheduler.go:275] [OnUpdatePod] Atualizando informações de métricas para o pod default/test-deployment3-6c95cffb97-585vw
I0124 13:48:30.222721       1 types.go:743] [ControllerName] Verificando as anotações do pod default/test-deployment3-6c95cffb97-585vw
I0124 13:48:30.222733       1 types.go:761] [ControllerName] Anotação 'controller' encontrada para o pod default/test-deployment3-6c95cffb97-585vw: test-controller3
I0124 13:48:30.222752       1 scheduler.go:277] [OnUpdatePod] Atualizando 'LastStatus' do pod default/test-deployment3-6c95cffb97-585vw nas métricas
I0124 13:48:30.222815       1 scheduler.go:279] [OnUpdatePod] Métrica atualizada para o pod default/test-deployment3-6c95cffb97-585vw
I0124 13:48:30.222831       1 scheduler.go:283] [OnUpdatePod] Finalizando processamento de atualização de pod para default/test-deployment3-6c95cffb97-585vw
I0124 13:48:30.229301       1 scheduler.go:258] [OnUpdatePod] Iniciando processamento de atualização de pod
I0124 13:48:30.232280       1 scheduler.go:262] [OnUpdatePod] Pod atualizado detectado: default/test-deployment3-6c95cffb97-585vw, Anotações: map[controller:test-controller3]
I0124 13:48:30.232449       1 scheduler.go:265] [OnUpdatePod] Comparando estado no Informer e estado real no cluster para o pod default/test-deployment3-6c95cffb97-585vw
I0124 13:48:30.255148       1 scheduler.go:70] Estado no Informer: map[controller:test-controller3]
I0124 13:48:30.255970       1 scheduler.go:71] Estado real no cluster: map[controller:test-controller3]
I0124 13:48:30.256044       1 scheduler.go:275] [OnUpdatePod] Atualizando informações de métricas para o pod default/test-deployment3-6c95cffb97-585vw
I0124 13:48:30.256059       1 types.go:743] [ControllerName] Verificando as anotações do pod default/test-deployment3-6c95cffb97-585vw
I0124 13:48:30.256070       1 types.go:761] [ControllerName] Anotação 'controller' encontrada para o pod default/test-deployment3-6c95cffb97-585vw: test-controller3
I0124 13:48:30.256084       1 scheduler.go:277] [OnUpdatePod] Atualizando 'LastStatus' do pod default/test-deployment3-6c95cffb97-585vw nas métricas
I0124 13:48:30.256109       1 scheduler.go:279] [OnUpdatePod] Métrica atualizada para o pod default/test-deployment3-6c95cffb97-585vw
I0124 13:48:30.256125       1 scheduler.go:283] [OnUpdatePod] Finalizando processamento de atualização de pod para default/test-deployment3-6c95cffb97-585vw
I0124 13:48:31.774929       1 postFilter.go:29] [PostFilter] PostFilter chamado para pod: default/test-deployment2-59c6b78cd5-4pw59
I0124 13:48:31.775122       1 postFilter.go:79] Comparando pod original com o atualizado...
I0124 13:48:31.775160       1 postFilter.go:86] Successfully retrieved updated pod default/test-deployment2-59c6b78cd5-4pw59 from lister
I0124 13:48:31.798818       1 postFilter.go:229] [compareNodeResources] Recursos calculados no nó minikube: CPU = 1750 mCPU, Memória = 178257920 bytes
I0124 13:48:31.799105       1 postFilter.go:230] [compareNodeResources] Recursos do snapshot no nó minikube: CPU = 1750 mCPU, Memória = 178257920 bytes
I0124 13:48:31.799119       1 postFilter.go:236] [compareNodeResources] Recursos de CPU do nó minikube estão sincronizados: 1750 mCPU
I0124 13:48:31.799127       1 postFilter.go:242] [compareNodeResources] Recursos de memória do nó minikube estão sincronizados: 178257920 bytes
I0124 13:48:31.804475       1 scheduler.go:606] [GetControllerMetricInfo] Iniciando para o pod: default/test-deployment3-6c95cffb97-585vw
I0124 13:48:31.804661       1 scheduler.go:611] [GetControllerMetricInfo] Obtendo o nome do controlador para o pod: default/test-deployment3-6c95cffb97-585vw
I0124 13:48:31.804810       1 types.go:743] [ControllerName] Verificando as anotações do pod default/test-deployment3-6c95cffb97-585vw
I0124 13:48:31.804950       1 types.go:761] [ControllerName] Anotação 'controller' encontrada para o pod default/test-deployment3-6c95cffb97-585vw: test-controller3
I0124 13:48:31.804961       1 scheduler.go:614] [GetControllerMetricInfo] Métricas do controlador definidas para o pod: default/test-deployment3-6c95cffb97-585vw
I0124 13:48:31.804970       1 scheduler.go:84] [HigherPrecedence] Calculando precedência entre test-deployment2-59c6b78cd5-4pw59 e test-deployment3-6c95cffb97-585vw
I0124 13:48:31.804976       1 scheduler.go:117] [WaitForPodsOnCache] Verificando se o pod test-deployment2-59c6b78cd5-4pw59 está no cache...
I0124 13:48:31.804982       1 scheduler.go:606] [GetControllerMetricInfo] Iniciando para o pod: default/test-deployment2-59c6b78cd5-4pw59
I0124 13:48:31.805207       1 scheduler.go:611] [GetControllerMetricInfo] Obtendo o nome do controlador para o pod: default/test-deployment2-59c6b78cd5-4pw59
I0124 13:48:31.805339       1 types.go:743] [ControllerName] Verificando as anotações do pod default/test-deployment2-59c6b78cd5-4pw59
I0124 13:48:31.805482       1 types.go:761] [ControllerName] Anotação 'controller' encontrada para o pod default/test-deployment2-59c6b78cd5-4pw59: test-controller2
I0124 13:48:31.805609       1 scheduler.go:614] [GetControllerMetricInfo] Métricas do controlador definidas para o pod: default/test-deployment2-59c6b78cd5-4pw59
I0124 13:48:32.051763       1 scheduler.go:70] Estado no Informer: map[controller:test-controller2]
I0124 13:48:32.051990       1 scheduler.go:71] Estado real no cluster: map[controller:test-controller2]
I0124 13:48:32.052013       1 scheduler.go:139] [WaitForPodsOnCache] Pod test-deployment2-59c6b78cd5-4pw59 encontrado no cache.
I0124 13:48:32.052026       1 scheduler.go:117] [WaitForPodsOnCache] Verificando se o pod test-deployment3-6c95cffb97-585vw está no cache...
I0124 13:48:32.052039       1 scheduler.go:606] [GetControllerMetricInfo] Iniciando para o pod: default/test-deployment3-6c95cffb97-585vw
I0124 13:48:32.052672       1 scheduler.go:611] [GetControllerMetricInfo] Obtendo o nome do controlador para o pod: default/test-deployment3-6c95cffb97-585vw
I0124 13:48:32.052754       1 types.go:743] [ControllerName] Verificando as anotações do pod default/test-deployment3-6c95cffb97-585vw
I0124 13:48:32.052772       1 types.go:761] [ControllerName] Anotação 'controller' encontrada para o pod default/test-deployment3-6c95cffb97-585vw: test-controller3
I0124 13:48:32.054134       1 scheduler.go:614] [GetControllerMetricInfo] Métricas do controlador definidas para o pod: default/test-deployment3-6c95cffb97-585vw
I0124 13:48:32.077659       1 scheduler.go:70] Estado no Informer: map[controller:test-controller3]
I0124 13:48:32.077751       1 scheduler.go:71] Estado real no cluster: map[controller:test-controller3]
I0124 13:48:32.077769       1 scheduler.go:139] [WaitForPodsOnCache] Pod test-deployment3-6c95cffb97-585vw encontrado no cache.
I0124 13:48:32.077792       1 scheduler.go:606] [GetControllerMetricInfo] Iniciando para o pod: default/test-deployment2-59c6b78cd5-4pw59
I0124 13:48:32.077804       1 scheduler.go:611] [GetControllerMetricInfo] Obtendo o nome do controlador para o pod: default/test-deployment2-59c6b78cd5-4pw59
I0124 13:48:32.077814       1 types.go:743] [ControllerName] Verificando as anotações do pod default/test-deployment2-59c6b78cd5-4pw59
I0124 13:48:32.077825       1 types.go:761] [ControllerName] Anotação 'controller' encontrada para o pod default/test-deployment2-59c6b78cd5-4pw59: test-controller2
I0124 13:48:32.077839       1 scheduler.go:614] [GetControllerMetricInfo] Métricas do controlador definidas para o pod: default/test-deployment2-59c6b78cd5-4pw59
I0124 13:48:32.079690       1 scheduler.go:606] [GetControllerMetricInfo] Iniciando para o pod: default/test-deployment3-6c95cffb97-585vw
I0124 13:48:32.079757       1 scheduler.go:611] [GetControllerMetricInfo] Obtendo o nome do controlador para o pod: default/test-deployment3-6c95cffb97-585vw
I0124 13:48:32.079769       1 types.go:743] [ControllerName] Verificando as anotações do pod default/test-deployment3-6c95cffb97-585vw
I0124 13:48:32.079779       1 types.go:761] [ControllerName] Anotação 'controller' encontrada para o pod default/test-deployment3-6c95cffb97-585vw: test-controller3
I0124 13:48:32.079790       1 scheduler.go:614] [GetControllerMetricInfo] Métricas do controlador definidas para o pod: default/test-deployment3-6c95cffb97-585vw
I0124 13:48:32.079811       1 scheduler.go:98] [HigherPrecedence] Métricas para test-deployment2-59c6b78cd5-4pw59: QoS = 18.267033, Importância = 0.80
I0124 13:48:32.079828       1 scheduler.go:99] [HigherPrecedence] Métricas para test-deployment3-6c95cffb97-585vw: QoS = -2.102759, Importância = 0.80
I0124 13:48:32.079932       1 scheduler.go:110] [HigherPrecedence] Decisão final: test-deployment2-59c6b78cd5-4pw59 tem precedência sobre test-deployment3-6c95cffb97-585vw? false
I0124 13:48:32.080505       1 postFilter.go:147] [PREEMPT CALL] No node was chosen to allocate pod test-deployment2-59c6b78cd5-4pw59
W0124 13:48:32.080570       1 postFilter.go:48] [PostFilter] Nenhum nó nominado após a preempção para o pod: default/test-deployment2-59c6b78cd5-4pw59
I0124 13:48:33.824457       1 scheduler.go:258] [OnUpdatePod] Iniciando processamento de atualização de pod
I0124 13:48:33.830626       1 scheduler.go:262] [OnUpdatePod] Pod atualizado detectado: default/test-deployment3-6c95cffb97-585vw, Anotações: map[controller:test-controller3]
I0124 13:48:33.830794       1 scheduler.go:265] [OnUpdatePod] Comparando estado no Informer e estado real no cluster para o pod default/test-deployment3-6c95cffb97-585vw
I0124 13:48:33.868726       1 scheduler.go:70] Estado no Informer: map[controller:test-controller3]
I0124 13:48:33.868791       1 scheduler.go:71] Estado real no cluster: map[controller:test-controller3]
I0124 13:48:33.868808       1 scheduler.go:275] [OnUpdatePod] Atualizando informações de métricas para o pod default/test-deployment3-6c95cffb97-585vw
I0124 13:48:33.869061       1 types.go:743] [ControllerName] Verificando as anotações do pod default/test-deployment3-6c95cffb97-585vw
I0124 13:48:33.872254       1 types.go:761] [ControllerName] Anotação 'controller' encontrada para o pod default/test-deployment3-6c95cffb97-585vw: test-controller3
I0124 13:48:33.872420       1 scheduler.go:277] [OnUpdatePod] Atualizando 'LastStatus' do pod default/test-deployment3-6c95cffb97-585vw nas métricas
I0124 13:48:33.872563       1 scheduler.go:279] [OnUpdatePod] Métrica atualizada para o pod default/test-deployment3-6c95cffb97-585vw
I0124 13:48:33.872731       1 scheduler.go:283] [OnUpdatePod] Finalizando processamento de atualização de pod para default/test-deployment3-6c95cffb97-585vw
I0124 13:53:54.665634       1 postFilter.go:29] [PostFilter] PostFilter chamado para pod: default/test-deployment2-59c6b78cd5-4pw59
I0124 13:53:54.667352       1 postFilter.go:79] Comparando pod original com o atualizado...
I0124 13:53:54.668317       1 postFilter.go:86] Successfully retrieved updated pod default/test-deployment2-59c6b78cd5-4pw59 from lister
I0124 13:53:54.677323       1 postFilter.go:229] [compareNodeResources] Recursos calculados no nó minikube: CPU = 1750 mCPU, Memória = 178257920 bytes
I0124 13:53:54.677458       1 postFilter.go:230] [compareNodeResources] Recursos do snapshot no nó minikube: CPU = 1750 mCPU, Memória = 178257920 bytes
I0124 13:53:54.677480       1 postFilter.go:236] [compareNodeResources] Recursos de CPU do nó minikube estão sincronizados: 1750 mCPU
I0124 13:53:54.677516       1 postFilter.go:242] [compareNodeResources] Recursos de memória do nó minikube estão sincronizados: 178257920 bytes
I0124 13:53:54.679301       1 scheduler.go:606] [GetControllerMetricInfo] Iniciando para o pod: default/test-deployment3-6c95cffb97-585vw
I0124 13:53:54.679393       1 scheduler.go:611] [GetControllerMetricInfo] Obtendo o nome do controlador para o pod: default/test-deployment3-6c95cffb97-585vw
I0124 13:53:54.679470       1 types.go:743] [ControllerName] Verificando as anotações do pod default/test-deployment3-6c95cffb97-585vw
I0124 13:53:54.679506       1 types.go:761] [ControllerName] Anotação 'controller' encontrada para o pod default/test-deployment3-6c95cffb97-585vw: test-controller3
I0124 13:53:54.679565       1 scheduler.go:614] [GetControllerMetricInfo] Métricas do controlador definidas para o pod: default/test-deployment3-6c95cffb97-585vw
I0124 13:53:54.679583       1 scheduler.go:84] [HigherPrecedence] Calculando precedência entre test-deployment2-59c6b78cd5-4pw59 e test-deployment3-6c95cffb97-585vw
I0124 13:53:54.679616       1 scheduler.go:117] [WaitForPodsOnCache] Verificando se o pod test-deployment2-59c6b78cd5-4pw59 está no cache...
I0124 13:53:54.679647       1 scheduler.go:606] [GetControllerMetricInfo] Iniciando para o pod: default/test-deployment2-59c6b78cd5-4pw59
I0124 13:53:54.679659       1 scheduler.go:611] [GetControllerMetricInfo] Obtendo o nome do controlador para o pod: default/test-deployment2-59c6b78cd5-4pw59
I0124 13:53:54.679669       1 types.go:743] [ControllerName] Verificando as anotações do pod default/test-deployment2-59c6b78cd5-4pw59
I0124 13:53:54.679682       1 types.go:761] [ControllerName] Anotação 'controller' encontrada para o pod default/test-deployment2-59c6b78cd5-4pw59: test-controller2
I0124 13:53:54.679695       1 scheduler.go:614] [GetControllerMetricInfo] Métricas do controlador definidas para o pod: default/test-deployment2-59c6b78cd5-4pw59
I0124 13:53:54.688043       1 scheduler.go:70] Estado no Informer: map[controller:test-controller2]
I0124 13:53:54.688253       1 scheduler.go:71] Estado real no cluster: map[controller:test-controller2]
I0124 13:53:54.688278       1 scheduler.go:139] [WaitForPodsOnCache] Pod test-deployment2-59c6b78cd5-4pw59 encontrado no cache.
I0124 13:53:54.688292       1 scheduler.go:117] [WaitForPodsOnCache] Verificando se o pod test-deployment3-6c95cffb97-585vw está no cache...
I0124 13:53:54.688305       1 scheduler.go:606] [GetControllerMetricInfo] Iniciando para o pod: default/test-deployment3-6c95cffb97-585vw
I0124 13:53:54.688345       1 scheduler.go:611] [GetControllerMetricInfo] Obtendo o nome do controlador para o pod: default/test-deployment3-6c95cffb97-585vw
I0124 13:53:54.688699       1 types.go:743] [ControllerName] Verificando as anotações do pod default/test-deployment3-6c95cffb97-585vw
I0124 13:53:54.689096       1 types.go:761] [ControllerName] Anotação 'controller' encontrada para o pod default/test-deployment3-6c95cffb97-585vw: test-controller3
I0124 13:53:54.689181       1 scheduler.go:614] [GetControllerMetricInfo] Métricas do controlador definidas para o pod: default/test-deployment3-6c95cffb97-585vw
I0124 13:53:54.696795       1 scheduler.go:70] Estado no Informer: map[controller:test-controller3]
I0124 13:53:54.696840       1 scheduler.go:71] Estado real no cluster: map[controller:test-controller3]
I0124 13:53:54.697967       1 scheduler.go:139] [WaitForPodsOnCache] Pod test-deployment3-6c95cffb97-585vw encontrado no cache.
I0124 13:53:54.698049       1 scheduler.go:606] [GetControllerMetricInfo] Iniciando para o pod: default/test-deployment2-59c6b78cd5-4pw59
I0124 13:53:54.698067       1 scheduler.go:611] [GetControllerMetricInfo] Obtendo o nome do controlador para o pod: default/test-deployment2-59c6b78cd5-4pw59
I0124 13:53:54.698104       1 types.go:743] [ControllerName] Verificando as anotações do pod default/test-deployment2-59c6b78cd5-4pw59
I0124 13:53:54.698120       1 types.go:761] [ControllerName] Anotação 'controller' encontrada para o pod default/test-deployment2-59c6b78cd5-4pw59: test-controller2
I0124 13:53:54.698134       1 scheduler.go:614] [GetControllerMetricInfo] Métricas do controlador definidas para o pod: default/test-deployment2-59c6b78cd5-4pw59
I0124 13:53:54.698156       1 scheduler.go:606] [GetControllerMetricInfo] Iniciando para o pod: default/test-deployment3-6c95cffb97-585vw
I0124 13:53:54.698169       1 scheduler.go:611] [GetControllerMetricInfo] Obtendo o nome do controlador para o pod: default/test-deployment3-6c95cffb97-585vw
I0124 13:53:54.698180       1 types.go:743] [ControllerName] Verificando as anotações do pod default/test-deployment3-6c95cffb97-585vw
I0124 13:53:54.698214       1 types.go:761] [ControllerName] Anotação 'controller' encontrada para o pod default/test-deployment3-6c95cffb97-585vw: test-controller3
I0124 13:53:54.698288       1 scheduler.go:614] [GetControllerMetricInfo] Métricas do controlador definidas para o pod: default/test-deployment3-6c95cffb97-585vw
I0124 13:53:54.698322       1 scheduler.go:98] [HigherPrecedence] Métricas para test-deployment2-59c6b78cd5-4pw59: QoS = -304.607576, Importância = 0.80
I0124 13:53:54.698348       1 scheduler.go:99] [HigherPrecedence] Métricas para test-deployment3-6c95cffb97-585vw: QoS = 78.615894, Importância = 0.80
I0124 13:53:54.698409       1 scheduler.go:110] [HigherPrecedence] Decisão final: test-deployment2-59c6b78cd5-4pw59 tem precedência sobre test-deployment3-6c95cffb97-585vw? true
I0124 13:53:54.698487       1 types.go:743] [ControllerName] Verificando as anotações do pod default/test-deployment2-59c6b78cd5-4pw59
I0124 13:53:54.698504       1 types.go:761] [ControllerName] Anotação 'controller' encontrada para o pod default/test-deployment2-59c6b78cd5-4pw59: test-controller2
I0124 13:53:54.698719       1 types.go:743] [ControllerName] Verificando as anotações do pod default/test-deployment3-6c95cffb97-585vw
I0124 13:53:54.698735       1 types.go:761] [ControllerName] Anotação 'controller' encontrada para o pod default/test-deployment3-6c95cffb97-585vw: test-controller3
I0124 13:53:54.698747       1 scheduler.go:606] [GetControllerMetricInfo] Iniciando para o pod: default/test-deployment3-6c95cffb97-585vw
I0124 13:53:54.698759       1 scheduler.go:611] [GetControllerMetricInfo] Obtendo o nome do controlador para o pod: default/test-deployment3-6c95cffb97-585vw
I0124 13:53:54.698767       1 types.go:743] [ControllerName] Verificando as anotações do pod default/test-deployment3-6c95cffb97-585vw
I0124 13:53:54.699135       1 types.go:761] [ControllerName] Anotação 'controller' encontrada para o pod default/test-deployment3-6c95cffb97-585vw: test-controller3
I0124 13:53:54.699208       1 scheduler.go:614] [GetControllerMetricInfo] Métricas do controlador definidas para o pod: default/test-deployment3-6c95cffb97-585vw
I0124 13:53:54.699222       1 scheduler.go:606] [GetControllerMetricInfo] Iniciando para o pod: default/test-deployment3-6c95cffb97-585vw
I0124 13:53:54.699233       1 scheduler.go:611] [GetControllerMetricInfo] Obtendo o nome do controlador para o pod: default/test-deployment3-6c95cffb97-585vw
I0124 13:53:54.699242       1 types.go:743] [ControllerName] Verificando as anotações do pod default/test-deployment3-6c95cffb97-585vw
I0124 13:53:54.699253       1 types.go:761] [ControllerName] Anotação 'controller' encontrada para o pod default/test-deployment3-6c95cffb97-585vw: test-controller3
I0124 13:53:54.699264       1 scheduler.go:614] [GetControllerMetricInfo] Métricas do controlador definidas para o pod: default/test-deployment3-6c95cffb97-585vw
I0124 13:53:54.699278       1 types.go:743] [ControllerName] Verificando as anotações do pod default/test-deployment3-6c95cffb97-585vw
I0124 13:53:54.699288       1 types.go:761] [ControllerName] Anotação 'controller' encontrada para o pod default/test-deployment3-6c95cffb97-585vw: test-controller3
I0124 13:53:54.699692       1 scheduler.go:606] [GetControllerMetricInfo] Iniciando para o pod: default/test-deployment3-6c95cffb97-585vw
I0124 13:53:54.699765       1 scheduler.go:611] [GetControllerMetricInfo] Obtendo o nome do controlador para o pod: default/test-deployment3-6c95cffb97-585vw
I0124 13:53:54.699778       1 types.go:743] [ControllerName] Verificando as anotações do pod default/test-deployment3-6c95cffb97-585vw
I0124 13:53:54.699789       1 types.go:761] [ControllerName] Anotação 'controller' encontrada para o pod default/test-deployment3-6c95cffb97-585vw: test-controller3
I0124 13:53:54.699801       1 scheduler.go:614] [GetControllerMetricInfo] Métricas do controlador definidas para o pod: default/test-deployment3-6c95cffb97-585vw
I0124 13:53:54.699817       1 scheduler.go:606] [GetControllerMetricInfo] Iniciando para o pod: default/test-deployment3-6c95cffb97-585vw
I0124 13:53:54.699827       1 scheduler.go:611] [GetControllerMetricInfo] Obtendo o nome do controlador para o pod: default/test-deployment3-6c95cffb97-585vw
I0124 13:53:54.699836       1 types.go:743] [ControllerName] Verificando as anotações do pod default/test-deployment3-6c95cffb97-585vw
I0124 13:53:54.700314       1 types.go:761] [ControllerName] Anotação 'controller' encontrada para o pod default/test-deployment3-6c95cffb97-585vw: test-controller3
I0124 13:53:54.700337       1 scheduler.go:614] [GetControllerMetricInfo] Métricas do controlador definidas para o pod: default/test-deployment3-6c95cffb97-585vw
I0124 13:53:54.700370       1 postFilter.go:150] [PREEMPT CALL] The node minikube  was chosen to allocate pod test-deployment2-59c6b78cd5-4pw59
I0124 13:53:54.700415       1 postFilter.go:154] [Preempt] Iniciando a remoção dos pods preemptados no nó minikube para alocar o pod default/test-deployment2-59c6b78cd5-4pw59. Total de vítimas: 1
I0124 13:53:54.700611       1 postFilter.go:158] [Preempt] Tentando remover o pod default/test-deployment3-6c95cffb97-585vw no nó minikube
I0124 13:53:54.754426       1 postFilter.go:164] [Preempt] Pod default/test-deployment3-6c95cffb97-585vw removido com sucesso no nó minikube
I0124 13:53:54.754473       1 postFilter.go:170] test-deployment3-6c95cffb97-585vw_default preempted by test-deployment2-59c6b78cd5-4pw59_default on node minikube
I0124 13:53:54.754526       1 postFilter.go:175] [Preempt] Total de pods preemptados no nó minikube: 1
I0124 13:53:54.754559       1 postFilter.go:182] [Preempt] Verificando pods de menor precedência no nó minikube que precisam ter o campo NominatedNodeName limpo
I0124 13:53:54.754576       1 postFilter.go:192] [Preempt] Finalizado para o nó minikube. Pod default/test-deployment2-59c6b78cd5-4pw59 deve ser alocado agora.
I0124 13:53:54.754586       1 postFilter.go:52] [PostFilter] Nó nominado para o pod default/test-deployment2-59c6b78cd5-4pw59: minikube
I0124 13:53:54.755272       1 scheduler.go:258] [OnUpdatePod] Iniciando processamento de atualização de pod
I0124 13:53:54.755344       1 scheduler.go:262] [OnUpdatePod] Pod atualizado detectado: default/test-deployment3-6c95cffb97-585vw, Anotações: map[controller:test-controller3]
I0124 13:53:54.755366       1 scheduler.go:265] [OnUpdatePod] Comparando estado no Informer e estado real no cluster para o pod default/test-deployment3-6c95cffb97-585vw
I0124 13:53:54.789758       1 scheduler.go:70] Estado no Informer: map[controller:test-controller3]
I0124 13:53:54.790271       1 scheduler.go:71] Estado real no cluster: map[controller:test-controller3]
I0124 13:53:54.790568       1 scheduler.go:275] [OnUpdatePod] Atualizando informações de métricas para o pod default/test-deployment3-6c95cffb97-585vw
I0124 13:53:54.790723       1 types.go:743] [ControllerName] Verificando as anotações do pod default/test-deployment3-6c95cffb97-585vw
I0124 13:53:54.791089       1 types.go:761] [ControllerName] Anotação 'controller' encontrada para o pod default/test-deployment3-6c95cffb97-585vw: test-controller3
I0124 13:53:54.791347       1 scheduler.go:277] [OnUpdatePod] Atualizando 'LastStatus' do pod default/test-deployment3-6c95cffb97-585vw nas métricas
I0124 13:53:54.791431       1 scheduler.go:279] [OnUpdatePod] Métrica atualizada para o pod default/test-deployment3-6c95cffb97-585vw
I0124 13:53:54.791695       1 scheduler.go:283] [OnUpdatePod] Finalizando processamento de atualização de pod para default/test-deployment3-6c95cffb97-585vw
I0124 13:53:54.792002       1 scheduler.go:258] [OnUpdatePod] Iniciando processamento de atualização de pod
I0124 13:53:54.792161       1 scheduler.go:262] [OnUpdatePod] Pod atualizado detectado: default/test-deployment2-59c6b78cd5-4pw59, Anotações: map[controller:test-controller2]
I0124 13:53:54.792304       1 scheduler.go:265] [OnUpdatePod] Comparando estado no Informer e estado real no cluster para o pod default/test-deployment2-59c6b78cd5-4pw59
I0124 13:53:54.792938       1 types.go:743] [ControllerName] Verificando as anotações do pod default/test-deployment3-6c95cffb97-585vw
I0124 13:53:54.796382       1 types.go:761] [ControllerName] Anotação 'controller' encontrada para o pod default/test-deployment3-6c95cffb97-585vw: test-controller3
I0124 13:53:54.829413       1 scheduler.go:70] Estado no Informer: map[controller:test-controller2]
I0124 13:53:54.829523       1 scheduler.go:71] Estado real no cluster: map[controller:test-controller2]
I0124 13:53:54.829536       1 scheduler.go:275] [OnUpdatePod] Atualizando informações de métricas para o pod default/test-deployment2-59c6b78cd5-4pw59
I0124 13:53:54.829604       1 types.go:743] [ControllerName] Verificando as anotações do pod default/test-deployment2-59c6b78cd5-4pw59
I0124 13:53:54.829611       1 types.go:761] [ControllerName] Anotação 'controller' encontrada para o pod default/test-deployment2-59c6b78cd5-4pw59: test-controller2
I0124 13:53:54.829619       1 scheduler.go:277] [OnUpdatePod] Atualizando 'LastStatus' do pod default/test-deployment2-59c6b78cd5-4pw59 nas métricas
I0124 13:53:54.829624       1 scheduler.go:279] [OnUpdatePod] Métrica atualizada para o pod default/test-deployment2-59c6b78cd5-4pw59
I0124 13:53:54.829644       1 scheduler.go:283] [OnUpdatePod] Finalizando processamento de atualização de pod para default/test-deployment2-59c6b78cd5-4pw59
I0124 13:53:54.848140       1 postFilter.go:29] [PostFilter] PostFilter chamado para pod: default/test-deployment3-6c95cffb97-d2xv7
I0124 13:53:54.848433       1 postFilter.go:79] Comparando pod original com o atualizado...
I0124 13:53:54.848672       1 postFilter.go:86] Successfully retrieved updated pod default/test-deployment3-6c95cffb97-d2xv7 from lister
I0124 13:53:54.917163       1 postFilter.go:229] [compareNodeResources] Recursos calculados no nó minikube: CPU = 1750 mCPU, Memória = 178257920 bytes
I0124 13:53:54.917208       1 postFilter.go:230] [compareNodeResources] Recursos do snapshot no nó minikube: CPU = 1750 mCPU, Memória = 178257920 bytes
I0124 13:53:54.917216       1 postFilter.go:236] [compareNodeResources] Recursos de CPU do nó minikube estão sincronizados: 1750 mCPU
I0124 13:53:54.917222       1 postFilter.go:242] [compareNodeResources] Recursos de memória do nó minikube estão sincronizados: 178257920 bytes
I0124 13:53:54.917743       1 scheduler.go:606] [GetControllerMetricInfo] Iniciando para o pod: default/test-deployment3-6c95cffb97-585vw
I0124 13:53:54.917807       1 scheduler.go:611] [GetControllerMetricInfo] Obtendo o nome do controlador para o pod: default/test-deployment3-6c95cffb97-585vw
I0124 13:53:54.917813       1 types.go:743] [ControllerName] Verificando as anotações do pod default/test-deployment3-6c95cffb97-585vw
I0124 13:53:54.917819       1 types.go:761] [ControllerName] Anotação 'controller' encontrada para o pod default/test-deployment3-6c95cffb97-585vw: test-controller3
I0124 13:53:54.917825       1 scheduler.go:614] [GetControllerMetricInfo] Métricas do controlador definidas para o pod: default/test-deployment3-6c95cffb97-585vw
I0124 13:53:54.917832       1 scheduler.go:84] [HigherPrecedence] Calculando precedência entre test-deployment3-6c95cffb97-d2xv7 e test-deployment3-6c95cffb97-585vw
I0124 13:53:54.917920       1 scheduler.go:117] [WaitForPodsOnCache] Verificando se o pod test-deployment3-6c95cffb97-d2xv7 está no cache...
I0124 13:53:54.917928       1 scheduler.go:606] [GetControllerMetricInfo] Iniciando para o pod: default/test-deployment3-6c95cffb97-d2xv7
I0124 13:53:54.917933       1 scheduler.go:611] [GetControllerMetricInfo] Obtendo o nome do controlador para o pod: default/test-deployment3-6c95cffb97-d2xv7
I0124 13:53:54.917936       1 types.go:743] [ControllerName] Verificando as anotações do pod default/test-deployment3-6c95cffb97-d2xv7
I0124 13:53:54.917941       1 types.go:761] [ControllerName] Anotação 'controller' encontrada para o pod default/test-deployment3-6c95cffb97-d2xv7: test-controller3
I0124 13:53:54.917946       1 scheduler.go:614] [GetControllerMetricInfo] Métricas do controlador definidas para o pod: default/test-deployment3-6c95cffb97-d2xv7
W0124 13:53:54.917962       1 scheduler.go:125] [cacheMiss] Métricas não encontradas para o pod: default/test-deployment3-6c95cffb97-d2xv7
I0124 13:53:55.261111       1 scheduler.go:70] Estado no Informer: map[controller:test-controller3]
I0124 13:53:55.261187       1 scheduler.go:71] Estado real no cluster: map[controller:test-controller3]
W0124 13:53:55.261202       1 scheduler.go:135] [WaitForPodsOnCache] Pod test-deployment3-6c95cffb97-d2xv7 não encontrado no cache. Tentando novamente...
I0124 13:53:55.361730       1 scheduler.go:606] [GetControllerMetricInfo] Iniciando para o pod: default/test-deployment3-6c95cffb97-d2xv7
I0124 13:53:55.361985       1 scheduler.go:611] [GetControllerMetricInfo] Obtendo o nome do controlador para o pod: default/test-deployment3-6c95cffb97-d2xv7
I0124 13:53:55.362100       1 types.go:743] [ControllerName] Verificando as anotações do pod default/test-deployment3-6c95cffb97-d2xv7
I0124 13:53:55.362115       1 types.go:761] [ControllerName] Anotação 'controller' encontrada para o pod default/test-deployment3-6c95cffb97-d2xv7: test-controller3
I0124 13:53:55.362128       1 scheduler.go:614] [GetControllerMetricInfo] Métricas do controlador definidas para o pod: default/test-deployment3-6c95cffb97-d2xv7
W0124 13:53:55.362145       1 scheduler.go:125] [cacheMiss] Métricas não encontradas para o pod: default/test-deployment3-6c95cffb97-d2xv7
I0124 13:53:55.839217       1 scheduler.go:70] Estado no Informer: map[controller:test-controller3]
I0124 13:53:55.839281       1 scheduler.go:71] Estado real no cluster: map[controller:test-controller3]
W0124 13:53:55.839291       1 scheduler.go:135] [WaitForPodsOnCache] Pod test-deployment3-6c95cffb97-d2xv7 não encontrado no cache. Tentando novamente...
I0124 13:53:55.939561       1 scheduler.go:606] [GetControllerMetricInfo] Iniciando para o pod: default/test-deployment3-6c95cffb97-d2xv7
I0124 13:53:55.939634       1 scheduler.go:611] [GetControllerMetricInfo] Obtendo o nome do controlador para o pod: default/test-deployment3-6c95cffb97-d2xv7
I0124 13:53:55.939646       1 types.go:743] [ControllerName] Verificando as anotações do pod default/test-deployment3-6c95cffb97-d2xv7
I0124 13:53:55.939658       1 types.go:761] [ControllerName] Anotação 'controller' encontrada para o pod default/test-deployment3-6c95cffb97-d2xv7: test-controller3
I0124 13:53:55.939668       1 scheduler.go:614] [GetControllerMetricInfo] Métricas do controlador definidas para o pod: default/test-deployment3-6c95cffb97-d2xv7
W0124 13:53:55.939683       1 scheduler.go:125] [cacheMiss] Métricas não encontradas para o pod: default/test-deployment3-6c95cffb97-d2xv7
I0124 13:53:55.978945       1 scheduler.go:70] Estado no Informer: map[controller:test-controller3]
I0124 13:53:55.978981       1 scheduler.go:71] Estado real no cluster: map[controller:test-controller3]
W0124 13:53:55.978999       1 scheduler.go:135] [WaitForPodsOnCache] Pod test-deployment3-6c95cffb97-d2xv7 não encontrado no cache. Tentando novamente...
I0124 13:53:56.079238       1 scheduler.go:606] [GetControllerMetricInfo] Iniciando para o pod: default/test-deployment3-6c95cffb97-d2xv7
I0124 13:53:56.079303       1 scheduler.go:611] [GetControllerMetricInfo] Obtendo o nome do controlador para o pod: default/test-deployment3-6c95cffb97-d2xv7
I0124 13:53:56.079313       1 types.go:743] [ControllerName] Verificando as anotações do pod default/test-deployment3-6c95cffb97-d2xv7
I0124 13:53:56.079325       1 types.go:761] [ControllerName] Anotação 'controller' encontrada para o pod default/test-deployment3-6c95cffb97-d2xv7: test-controller3
I0124 13:53:56.079335       1 scheduler.go:614] [GetControllerMetricInfo] Métricas do controlador definidas para o pod: default/test-deployment3-6c95cffb97-d2xv7
W0124 13:53:56.079350       1 scheduler.go:125] [cacheMiss] Métricas não encontradas para o pod: default/test-deployment3-6c95cffb97-d2xv7
I0124 13:53:56.420824       1 scheduler.go:70] Estado no Informer: map[controller:test-controller3]
I0124 13:53:56.427319       1 scheduler.go:71] Estado real no cluster: map[controller:test-controller3]
W0124 13:53:56.427348       1 scheduler.go:135] [WaitForPodsOnCache] Pod test-deployment3-6c95cffb97-d2xv7 não encontrado no cache. Tentando novamente...
I0124 13:53:56.528000       1 scheduler.go:606] [GetControllerMetricInfo] Iniciando para o pod: default/test-deployment3-6c95cffb97-d2xv7
I0124 13:53:56.528721       1 scheduler.go:611] [GetControllerMetricInfo] Obtendo o nome do controlador para o pod: default/test-deployment3-6c95cffb97-d2xv7
I0124 13:53:56.529069       1 types.go:743] [ControllerName] Verificando as anotações do pod default/test-deployment3-6c95cffb97-d2xv7
I0124 13:53:56.529149       1 types.go:761] [ControllerName] Anotação 'controller' encontrada para o pod default/test-deployment3-6c95cffb97-d2xv7: test-controller3
I0124 13:53:56.529388       1 scheduler.go:614] [GetControllerMetricInfo] Métricas do controlador definidas para o pod: default/test-deployment3-6c95cffb97-d2xv7
W0124 13:53:56.529511       1 scheduler.go:125] [cacheMiss] Métricas não encontradas para o pod: default/test-deployment3-6c95cffb97-d2xv7
I0124 13:53:56.544038       1 scheduler.go:70] Estado no Informer: map[controller:test-controller3]
I0124 13:53:56.544531       1 scheduler.go:71] Estado real no cluster: map[controller:test-controller3]
W0124 13:53:56.544800       1 scheduler.go:135] [WaitForPodsOnCache] Pod test-deployment3-6c95cffb97-d2xv7 não encontrado no cache. Tentando novamente...
I0124 13:53:56.645754       1 scheduler.go:606] [GetControllerMetricInfo] Iniciando para o pod: default/test-deployment3-6c95cffb97-d2xv7
I0124 13:53:56.646532       1 scheduler.go:611] [GetControllerMetricInfo] Obtendo o nome do controlador para o pod: default/test-deployment3-6c95cffb97-d2xv7
I0124 13:53:56.646835       1 types.go:743] [ControllerName] Verificando as anotações do pod default/test-deployment3-6c95cffb97-d2xv7
I0124 13:53:56.647180       1 types.go:761] [ControllerName] Anotação 'controller' encontrada para o pod default/test-deployment3-6c95cffb97-d2xv7: test-controller3
I0124 13:53:56.647296       1 scheduler.go:614] [GetControllerMetricInfo] Métricas do controlador definidas para o pod: default/test-deployment3-6c95cffb97-d2xv7
W0124 13:53:56.647391       1 scheduler.go:125] [cacheMiss] Métricas não encontradas para o pod: default/test-deployment3-6c95cffb97-d2xv7
I0124 13:53:56.654604       1 scheduler.go:70] Estado no Informer: map[controller:test-controller3]
I0124 13:53:56.655027       1 scheduler.go:71] Estado real no cluster: map[controller:test-controller3]
W0124 13:53:56.655368       1 scheduler.go:135] [WaitForPodsOnCache] Pod test-deployment3-6c95cffb97-d2xv7 não encontrado no cache. Tentando novamente...
I0124 13:53:56.756143       1 scheduler.go:606] [GetControllerMetricInfo] Iniciando para o pod: default/test-deployment3-6c95cffb97-d2xv7
I0124 13:53:56.756275       1 scheduler.go:611] [GetControllerMetricInfo] Obtendo o nome do controlador para o pod: default/test-deployment3-6c95cffb97-d2xv7
I0124 13:53:56.756293       1 types.go:743] [ControllerName] Verificando as anotações do pod default/test-deployment3-6c95cffb97-d2xv7
I0124 13:53:56.756311       1 types.go:761] [ControllerName] Anotação 'controller' encontrada para o pod default/test-deployment3-6c95cffb97-d2xv7: test-controller3
I0124 13:53:56.756327       1 scheduler.go:614] [GetControllerMetricInfo] Métricas do controlador definidas para o pod: default/test-deployment3-6c95cffb97-d2xv7
W0124 13:53:56.756356       1 scheduler.go:125] [cacheMiss] Métricas não encontradas para o pod: default/test-deployment3-6c95cffb97-d2xv7
I0124 13:53:56.767382       1 scheduler.go:70] Estado no Informer: map[controller:test-controller3]
I0124 13:53:56.768380       1 scheduler.go:71] Estado real no cluster: map[controller:test-controller3]
W0124 13:53:56.768412       1 scheduler.go:135] [WaitForPodsOnCache] Pod test-deployment3-6c95cffb97-d2xv7 não encontrado no cache. Tentando novamente...
I0124 13:53:56.870091       1 scheduler.go:606] [GetControllerMetricInfo] Iniciando para o pod: default/test-deployment3-6c95cffb97-d2xv7
I0124 13:53:56.873431       1 scheduler.go:611] [GetControllerMetricInfo] Obtendo o nome do controlador para o pod: default/test-deployment3-6c95cffb97-d2xv7
I0124 13:53:56.873803       1 types.go:743] [ControllerName] Verificando as anotações do pod default/test-deployment3-6c95cffb97-d2xv7
I0124 13:53:56.874020       1 types.go:761] [ControllerName] Anotação 'controller' encontrada para o pod default/test-deployment3-6c95cffb97-d2xv7: test-controller3
I0124 13:53:56.874376       1 scheduler.go:614] [GetControllerMetricInfo] Métricas do controlador definidas para o pod: default/test-deployment3-6c95cffb97-d2xv7
W0124 13:53:56.874590       1 scheduler.go:125] [cacheMiss] Métricas não encontradas para o pod: default/test-deployment3-6c95cffb97-d2xv7
I0124 13:53:56.884583       1 scheduler.go:70] Estado no Informer: map[controller:test-controller3]
I0124 13:53:56.884986       1 scheduler.go:71] Estado real no cluster: map[controller:test-controller3]
W0124 13:53:56.885312       1 scheduler.go:135] [WaitForPodsOnCache] Pod test-deployment3-6c95cffb97-d2xv7 não encontrado no cache. Tentando novamente...
I0124 13:53:56.989654       1 scheduler.go:606] [GetControllerMetricInfo] Iniciando para o pod: default/test-deployment3-6c95cffb97-d2xv7
I0124 13:53:56.990159       1 scheduler.go:611] [GetControllerMetricInfo] Obtendo o nome do controlador para o pod: default/test-deployment3-6c95cffb97-d2xv7
I0124 13:53:56.990599       1 types.go:743] [ControllerName] Verificando as anotações do pod default/test-deployment3-6c95cffb97-d2xv7
I0124 13:53:56.991138       1 types.go:761] [ControllerName] Anotação 'controller' encontrada para o pod default/test-deployment3-6c95cffb97-d2xv7: test-controller3
I0124 13:53:56.991359       1 scheduler.go:614] [GetControllerMetricInfo] Métricas do controlador definidas para o pod: default/test-deployment3-6c95cffb97-d2xv7
W0124 13:53:56.991577       1 scheduler.go:125] [cacheMiss] Métricas não encontradas para o pod: default/test-deployment3-6c95cffb97-d2xv7
I0124 13:53:57.014374       1 scheduler.go:70] Estado no Informer: map[controller:test-controller3]
I0124 13:53:57.014448       1 scheduler.go:71] Estado real no cluster: map[controller:test-controller3]
W0124 13:53:57.014462       1 scheduler.go:135] [WaitForPodsOnCache] Pod test-deployment3-6c95cffb97-d2xv7 não encontrado no cache. Tentando novamente...
I0124 13:53:57.115025       1 scheduler.go:606] [GetControllerMetricInfo] Iniciando para o pod: default/test-deployment3-6c95cffb97-d2xv7
I0124 13:53:57.115442       1 scheduler.go:611] [GetControllerMetricInfo] Obtendo o nome do controlador para o pod: default/test-deployment3-6c95cffb97-d2xv7
I0124 13:53:57.115687       1 types.go:743] [ControllerName] Verificando as anotações do pod default/test-deployment3-6c95cffb97-d2xv7
I0124 13:53:57.115763       1 types.go:761] [ControllerName] Anotação 'controller' encontrada para o pod default/test-deployment3-6c95cffb97-d2xv7: test-controller3
I0124 13:53:57.116067       1 scheduler.go:614] [GetControllerMetricInfo] Métricas do controlador definidas para o pod: default/test-deployment3-6c95cffb97-d2xv7
W0124 13:53:57.116132       1 scheduler.go:125] [cacheMiss] Métricas não encontradas para o pod: default/test-deployment3-6c95cffb97-d2xv7
I0124 13:53:57.121602       1 scheduler.go:70] Estado no Informer: map[controller:test-controller3]
I0124 13:53:57.121696       1 scheduler.go:71] Estado real no cluster: map[controller:test-controller3]
W0124 13:53:57.121718       1 scheduler.go:135] [WaitForPodsOnCache] Pod test-deployment3-6c95cffb97-d2xv7 não encontrado no cache. Tentando novamente...
I0124 13:53:57.228759       1 scheduler.go:606] [GetControllerMetricInfo] Iniciando para o pod: default/test-deployment3-6c95cffb97-d2xv7
I0124 13:53:57.229591       1 scheduler.go:611] [GetControllerMetricInfo] Obtendo o nome do controlador para o pod: default/test-deployment3-6c95cffb97-d2xv7
I0124 13:53:57.230409       1 types.go:743] [ControllerName] Verificando as anotações do pod default/test-deployment3-6c95cffb97-d2xv7
I0124 13:53:57.230787       1 types.go:761] [ControllerName] Anotação 'controller' encontrada para o pod default/test-deployment3-6c95cffb97-d2xv7: test-controller3
I0124 13:53:57.231145       1 scheduler.go:614] [GetControllerMetricInfo] Métricas do controlador definidas para o pod: default/test-deployment3-6c95cffb97-d2xv7
W0124 13:53:57.232740       1 scheduler.go:125] [cacheMiss] Métricas não encontradas para o pod: default/test-deployment3-6c95cffb97-d2xv7
I0124 13:53:57.241211       1 scheduler.go:70] Estado no Informer: map[controller:test-controller3]
I0124 13:53:57.241308       1 scheduler.go:71] Estado real no cluster: map[controller:test-controller3]
W0124 13:53:57.241331       1 scheduler.go:135] [WaitForPodsOnCache] Pod test-deployment3-6c95cffb97-d2xv7 não encontrado no cache. Tentando novamente...
I0124 13:53:57.343278       1 scheduler.go:606] [GetControllerMetricInfo] Iniciando para o pod: default/test-deployment3-6c95cffb97-d2xv7
I0124 13:53:57.345581       1 scheduler.go:611] [GetControllerMetricInfo] Obtendo o nome do controlador para o pod: default/test-deployment3-6c95cffb97-d2xv7
I0124 13:53:57.346116       1 types.go:743] [ControllerName] Verificando as anotações do pod default/test-deployment3-6c95cffb97-d2xv7
I0124 13:53:57.346768       1 types.go:761] [ControllerName] Anotação 'controller' encontrada para o pod default/test-deployment3-6c95cffb97-d2xv7: test-controller3
I0124 13:53:57.347147       1 scheduler.go:614] [GetControllerMetricInfo] Métricas do controlador definidas para o pod: default/test-deployment3-6c95cffb97-d2xv7
W0124 13:53:57.347206       1 scheduler.go:125] [cacheMiss] Métricas não encontradas para o pod: default/test-deployment3-6c95cffb97-d2xv7
I0124 13:53:57.354524       1 scheduler.go:70] Estado no Informer: map[controller:test-controller3]
I0124 13:53:57.354629       1 scheduler.go:71] Estado real no cluster: map[controller:test-controller3]
W0124 13:53:57.354652       1 scheduler.go:135] [WaitForPodsOnCache] Pod test-deployment3-6c95cffb97-d2xv7 não encontrado no cache. Tentando novamente...
I0124 13:53:57.455738       1 scheduler.go:606] [GetControllerMetricInfo] Iniciando para o pod: default/test-deployment3-6c95cffb97-d2xv7
I0124 13:53:57.456345       1 scheduler.go:611] [GetControllerMetricInfo] Obtendo o nome do controlador para o pod: default/test-deployment3-6c95cffb97-d2xv7
I0124 13:53:57.456527       1 types.go:743] [ControllerName] Verificando as anotações do pod default/test-deployment3-6c95cffb97-d2xv7
I0124 13:53:57.456577       1 types.go:761] [ControllerName] Anotação 'controller' encontrada para o pod default/test-deployment3-6c95cffb97-d2xv7: test-controller3
I0124 13:53:57.456618       1 scheduler.go:614] [GetControllerMetricInfo] Métricas do controlador definidas para o pod: default/test-deployment3-6c95cffb97-d2xv7
W0124 13:53:57.456661       1 scheduler.go:125] [cacheMiss] Métricas não encontradas para o pod: default/test-deployment3-6c95cffb97-d2xv7
I0124 13:53:57.465456       1 scheduler.go:70] Estado no Informer: map[controller:test-controller3]
I0124 13:53:57.465562       1 scheduler.go:71] Estado real no cluster: map[controller:test-controller3]
W0124 13:53:57.465584       1 scheduler.go:135] [WaitForPodsOnCache] Pod test-deployment3-6c95cffb97-d2xv7 não encontrado no cache. Tentando novamente...
I0124 13:53:57.566585       1 scheduler.go:606] [GetControllerMetricInfo] Iniciando para o pod: default/test-deployment3-6c95cffb97-d2xv7
I0124 13:53:57.566761       1 scheduler.go:611] [GetControllerMetricInfo] Obtendo o nome do controlador para o pod: default/test-deployment3-6c95cffb97-d2xv7
I0124 13:53:57.566808       1 types.go:743] [ControllerName] Verificando as anotações do pod default/test-deployment3-6c95cffb97-d2xv7
I0124 13:53:57.566965       1 types.go:761] [ControllerName] Anotação 'controller' encontrada para o pod default/test-deployment3-6c95cffb97-d2xv7: test-controller3
I0124 13:53:57.567177       1 scheduler.go:614] [GetControllerMetricInfo] Métricas do controlador definidas para o pod: default/test-deployment3-6c95cffb97-d2xv7
W0124 13:53:57.567304       1 scheduler.go:125] [cacheMiss] Métricas não encontradas para o pod: default/test-deployment3-6c95cffb97-d2xv7
I0124 13:53:57.574583       1 scheduler.go:70] Estado no Informer: map[controller:test-controller3]
I0124 13:53:57.574629       1 scheduler.go:71] Estado real no cluster: map[controller:test-controller3]
W0124 13:53:57.574647       1 scheduler.go:135] [WaitForPodsOnCache] Pod test-deployment3-6c95cffb97-d2xv7 não encontrado no cache. Tentando novamente...
I0124 13:53:57.676050       1 scheduler.go:606] [GetControllerMetricInfo] Iniciando para o pod: default/test-deployment3-6c95cffb97-d2xv7
I0124 13:53:57.676144       1 scheduler.go:611] [GetControllerMetricInfo] Obtendo o nome do controlador para o pod: default/test-deployment3-6c95cffb97-d2xv7
I0124 13:53:57.676162       1 types.go:743] [ControllerName] Verificando as anotações do pod default/test-deployment3-6c95cffb97-d2xv7
I0124 13:53:57.676256       1 types.go:761] [ControllerName] Anotação 'controller' encontrada para o pod default/test-deployment3-6c95cffb97-d2xv7: test-controller3
I0124 13:53:57.676274       1 scheduler.go:614] [GetControllerMetricInfo] Métricas do controlador definidas para o pod: default/test-deployment3-6c95cffb97-d2xv7
W0124 13:53:57.676294       1 scheduler.go:125] [cacheMiss] Métricas não encontradas para o pod: default/test-deployment3-6c95cffb97-d2xv7
I0124 13:53:57.685624       1 scheduler.go:70] Estado no Informer: map[controller:test-controller3]
I0124 13:53:57.685670       1 scheduler.go:71] Estado real no cluster: map[controller:test-controller3]
W0124 13:53:57.685687       1 scheduler.go:135] [WaitForPodsOnCache] Pod test-deployment3-6c95cffb97-d2xv7 não encontrado no cache. Tentando novamente...
I0124 13:53:57.790723       1 scheduler.go:606] [GetControllerMetricInfo] Iniciando para o pod: default/test-deployment3-6c95cffb97-d2xv7
I0124 13:53:57.790767       1 scheduler.go:611] [GetControllerMetricInfo] Obtendo o nome do controlador para o pod: default/test-deployment3-6c95cffb97-d2xv7
I0124 13:53:57.790781       1 types.go:743] [ControllerName] Verificando as anotações do pod default/test-deployment3-6c95cffb97-d2xv7
I0124 13:53:57.790797       1 types.go:761] [ControllerName] Anotação 'controller' encontrada para o pod default/test-deployment3-6c95cffb97-d2xv7: test-controller3
I0124 13:53:57.790812       1 scheduler.go:614] [GetControllerMetricInfo] Métricas do controlador definidas para o pod: default/test-deployment3-6c95cffb97-d2xv7
W0124 13:53:57.790831       1 scheduler.go:125] [cacheMiss] Métricas não encontradas para o pod: default/test-deployment3-6c95cffb97-d2xv7
I0124 13:53:57.804424       1 scheduler.go:70] Estado no Informer: map[controller:test-controller3]
I0124 13:53:57.805469       1 scheduler.go:71] Estado real no cluster: map[controller:test-controller3]
W0124 13:53:57.805759       1 scheduler.go:135] [WaitForPodsOnCache] Pod test-deployment3-6c95cffb97-d2xv7 não encontrado no cache. Tentando novamente...
I0124 13:53:57.906643       1 scheduler.go:606] [GetControllerMetricInfo] Iniciando para o pod: default/test-deployment3-6c95cffb97-d2xv7
I0124 13:53:57.906735       1 scheduler.go:611] [GetControllerMetricInfo] Obtendo o nome do controlador para o pod: default/test-deployment3-6c95cffb97-d2xv7
I0124 13:53:57.906750       1 types.go:743] [ControllerName] Verificando as anotações do pod default/test-deployment3-6c95cffb97-d2xv7
I0124 13:53:57.906766       1 types.go:761] [ControllerName] Anotação 'controller' encontrada para o pod default/test-deployment3-6c95cffb97-d2xv7: test-controller3
I0124 13:53:57.906824       1 scheduler.go:614] [GetControllerMetricInfo] Métricas do controlador definidas para o pod: default/test-deployment3-6c95cffb97-d2xv7
W0124 13:53:57.906956       1 scheduler.go:125] [cacheMiss] Métricas não encontradas para o pod: default/test-deployment3-6c95cffb97-d2xv7
I0124 13:53:58.250230       1 scheduler.go:70] Estado no Informer: map[controller:test-controller3]
I0124 13:53:58.250284       1 scheduler.go:71] Estado real no cluster: map[controller:test-controller3]
W0124 13:53:58.250296       1 scheduler.go:135] [WaitForPodsOnCache] Pod test-deployment3-6c95cffb97-d2xv7 não encontrado no cache. Tentando novamente...
I0124 13:53:58.351403       1 scheduler.go:606] [GetControllerMetricInfo] Iniciando para o pod: default/test-deployment3-6c95cffb97-d2xv7
I0124 13:53:58.351596       1 scheduler.go:611] [GetControllerMetricInfo] Obtendo o nome do controlador para o pod: default/test-deployment3-6c95cffb97-d2xv7
I0124 13:53:58.351641       1 types.go:743] [ControllerName] Verificando as anotações do pod default/test-deployment3-6c95cffb97-d2xv7
I0124 13:53:58.351682       1 types.go:761] [ControllerName] Anotação 'controller' encontrada para o pod default/test-deployment3-6c95cffb97-d2xv7: test-controller3
I0124 13:53:58.351722       1 scheduler.go:614] [GetControllerMetricInfo] Métricas do controlador definidas para o pod: default/test-deployment3-6c95cffb97-d2xv7
W0124 13:53:58.351767       1 scheduler.go:125] [cacheMiss] Métricas não encontradas para o pod: default/test-deployment3-6c95cffb97-d2xv7
I0124 13:53:58.370051       1 scheduler.go:70] Estado no Informer: map[controller:test-controller3]
I0124 13:53:58.370173       1 scheduler.go:71] Estado real no cluster: map[controller:test-controller3]
W0124 13:53:58.370206       1 scheduler.go:135] [WaitForPodsOnCache] Pod test-deployment3-6c95cffb97-d2xv7 não encontrado no cache. Tentando novamente...
I0124 13:53:58.471408       1 scheduler.go:606] [GetControllerMetricInfo] Iniciando para o pod: default/test-deployment3-6c95cffb97-d2xv7
I0124 13:53:58.471514       1 scheduler.go:611] [GetControllerMetricInfo] Obtendo o nome do controlador para o pod: default/test-deployment3-6c95cffb97-d2xv7
I0124 13:53:58.471532       1 types.go:743] [ControllerName] Verificando as anotações do pod default/test-deployment3-6c95cffb97-d2xv7
I0124 13:53:58.471563       1 types.go:761] [ControllerName] Anotação 'controller' encontrada para o pod default/test-deployment3-6c95cffb97-d2xv7: test-controller3
I0124 13:53:58.471568       1 scheduler.go:614] [GetControllerMetricInfo] Métricas do controlador definidas para o pod: default/test-deployment3-6c95cffb97-d2xv7
W0124 13:53:58.471588       1 scheduler.go:125] [cacheMiss] Métricas não encontradas para o pod: default/test-deployment3-6c95cffb97-d2xv7
I0124 13:53:58.489151       1 scheduler.go:70] Estado no Informer: map[controller:test-controller3]
I0124 13:53:58.489343       1 scheduler.go:71] Estado real no cluster: map[controller:test-controller3]
W0124 13:53:58.489399       1 scheduler.go:135] [WaitForPodsOnCache] Pod test-deployment3-6c95cffb97-d2xv7 não encontrado no cache. Tentando novamente...
I0124 13:53:58.591283       1 scheduler.go:606] [GetControllerMetricInfo] Iniciando para o pod: default/test-deployment3-6c95cffb97-d2xv7
I0124 13:53:58.591541       1 scheduler.go:611] [GetControllerMetricInfo] Obtendo o nome do controlador para o pod: default/test-deployment3-6c95cffb97-d2xv7
I0124 13:53:58.591590       1 types.go:743] [ControllerName] Verificando as anotações do pod default/test-deployment3-6c95cffb97-d2xv7
I0124 13:53:58.591634       1 types.go:761] [ControllerName] Anotação 'controller' encontrada para o pod default/test-deployment3-6c95cffb97-d2xv7: test-controller3
I0124 13:53:58.591760       1 scheduler.go:614] [GetControllerMetricInfo] Métricas do controlador definidas para o pod: default/test-deployment3-6c95cffb97-d2xv7
W0124 13:53:58.592320       1 scheduler.go:125] [cacheMiss] Métricas não encontradas para o pod: default/test-deployment3-6c95cffb97-d2xv7
I0124 13:53:58.599754       1 scheduler.go:70] Estado no Informer: map[controller:test-controller3]
I0124 13:53:58.600054       1 scheduler.go:71] Estado real no cluster: map[controller:test-controller3]
W0124 13:53:58.600131       1 scheduler.go:135] [WaitForPodsOnCache] Pod test-deployment3-6c95cffb97-d2xv7 não encontrado no cache. Tentando novamente...
I0124 13:53:58.700539       1 scheduler.go:606] [GetControllerMetricInfo] Iniciando para o pod: default/test-deployment3-6c95cffb97-d2xv7
I0124 13:53:58.701142       1 scheduler.go:611] [GetControllerMetricInfo] Obtendo o nome do controlador para o pod: default/test-deployment3-6c95cffb97-d2xv7
I0124 13:53:58.701224       1 types.go:743] [ControllerName] Verificando as anotações do pod default/test-deployment3-6c95cffb97-d2xv7
I0124 13:53:58.701244       1 types.go:761] [ControllerName] Anotação 'controller' encontrada para o pod default/test-deployment3-6c95cffb97-d2xv7: test-controller3
I0124 13:53:58.701289       1 scheduler.go:614] [GetControllerMetricInfo] Métricas do controlador definidas para o pod: default/test-deployment3-6c95cffb97-d2xv7
W0124 13:53:58.701689       1 scheduler.go:125] [cacheMiss] Métricas não encontradas para o pod: default/test-deployment3-6c95cffb97-d2xv7
I0124 13:53:58.709497       1 scheduler.go:70] Estado no Informer: map[controller:test-controller3]
I0124 13:53:58.709676       1 scheduler.go:71] Estado real no cluster: map[controller:test-controller3]
W0124 13:53:58.709728       1 scheduler.go:135] [WaitForPodsOnCache] Pod test-deployment3-6c95cffb97-d2xv7 não encontrado no cache. Tentando novamente...
I0124 13:53:58.810385       1 scheduler.go:606] [GetControllerMetricInfo] Iniciando para o pod: default/test-deployment3-6c95cffb97-d2xv7
I0124 13:53:58.810593       1 scheduler.go:611] [GetControllerMetricInfo] Obtendo o nome do controlador para o pod: default/test-deployment3-6c95cffb97-d2xv7
I0124 13:53:58.810612       1 types.go:743] [ControllerName] Verificando as anotações do pod default/test-deployment3-6c95cffb97-d2xv7
I0124 13:53:58.810627       1 types.go:761] [ControllerName] Anotação 'controller' encontrada para o pod default/test-deployment3-6c95cffb97-d2xv7: test-controller3
I0124 13:53:58.810643       1 scheduler.go:614] [GetControllerMetricInfo] Métricas do controlador definidas para o pod: default/test-deployment3-6c95cffb97-d2xv7
W0124 13:53:58.811379       1 scheduler.go:125] [cacheMiss] Métricas não encontradas para o pod: default/test-deployment3-6c95cffb97-d2xv7
I0124 13:53:58.820407       1 scheduler.go:70] Estado no Informer: map[controller:test-controller3]
I0124 13:53:58.820585       1 scheduler.go:71] Estado real no cluster: map[controller:test-controller3]
W0124 13:53:58.820637       1 scheduler.go:135] [WaitForPodsOnCache] Pod test-deployment3-6c95cffb97-d2xv7 não encontrado no cache. Tentando novamente...
I0124 13:53:58.921689       1 scheduler.go:606] [GetControllerMetricInfo] Iniciando para o pod: default/test-deployment3-6c95cffb97-d2xv7
I0124 13:53:58.921733       1 scheduler.go:611] [GetControllerMetricInfo] Obtendo o nome do controlador para o pod: default/test-deployment3-6c95cffb97-d2xv7
I0124 13:53:58.921746       1 types.go:743] [ControllerName] Verificando as anotações do pod default/test-deployment3-6c95cffb97-d2xv7
I0124 13:53:58.921760       1 types.go:761] [ControllerName] Anotação 'controller' encontrada para o pod default/test-deployment3-6c95cffb97-d2xv7: test-controller3
I0124 13:53:58.921775       1 scheduler.go:614] [GetControllerMetricInfo] Métricas do controlador definidas para o pod: default/test-deployment3-6c95cffb97-d2xv7
W0124 13:53:58.921792       1 scheduler.go:125] [cacheMiss] Métricas não encontradas para o pod: default/test-deployment3-6c95cffb97-d2xv7
I0124 13:53:58.931823       1 scheduler.go:70] Estado no Informer: map[controller:test-controller3]
I0124 13:53:58.932015       1 scheduler.go:71] Estado real no cluster: map[controller:test-controller3]
W0124 13:53:58.932032       1 scheduler.go:135] [WaitForPodsOnCache] Pod test-deployment3-6c95cffb97-d2xv7 não encontrado no cache. Tentando novamente...
I0124 13:53:59.033049       1 scheduler.go:606] [GetControllerMetricInfo] Iniciando para o pod: default/test-deployment3-6c95cffb97-d2xv7
I0124 13:53:59.033174       1 scheduler.go:611] [GetControllerMetricInfo] Obtendo o nome do controlador para o pod: default/test-deployment3-6c95cffb97-d2xv7
I0124 13:53:59.033205       1 types.go:743] [ControllerName] Verificando as anotações do pod default/test-deployment3-6c95cffb97-d2xv7
I0124 13:53:59.033227       1 types.go:761] [ControllerName] Anotação 'controller' encontrada para o pod default/test-deployment3-6c95cffb97-d2xv7: test-controller3
I0124 13:53:59.033244       1 scheduler.go:614] [GetControllerMetricInfo] Métricas do controlador definidas para o pod: default/test-deployment3-6c95cffb97-d2xv7
W0124 13:53:59.033664       1 scheduler.go:125] [cacheMiss] Métricas não encontradas para o pod: default/test-deployment3-6c95cffb97-d2xv7
I0124 13:53:59.040693       1 scheduler.go:70] Estado no Informer: map[controller:test-controller3]
I0124 13:53:59.041648       1 scheduler.go:71] Estado real no cluster: map[controller:test-controller3]
W0124 13:53:59.041815       1 scheduler.go:135] [WaitForPodsOnCache] Pod test-deployment3-6c95cffb97-d2xv7 não encontrado no cache. Tentando novamente...
I0124 13:53:59.142539       1 scheduler.go:606] [GetControllerMetricInfo] Iniciando para o pod: default/test-deployment3-6c95cffb97-d2xv7
I0124 13:53:59.142653       1 scheduler.go:611] [GetControllerMetricInfo] Obtendo o nome do controlador para o pod: default/test-deployment3-6c95cffb97-d2xv7
I0124 13:53:59.142671       1 types.go:743] [ControllerName] Verificando as anotações do pod default/test-deployment3-6c95cffb97-d2xv7
I0124 13:53:59.142687       1 types.go:761] [ControllerName] Anotação 'controller' encontrada para o pod default/test-deployment3-6c95cffb97-d2xv7: test-controller3
I0124 13:53:59.142704       1 scheduler.go:614] [GetControllerMetricInfo] Métricas do controlador definidas para o pod: default/test-deployment3-6c95cffb97-d2xv7
W0124 13:53:59.142725       1 scheduler.go:125] [cacheMiss] Métricas não encontradas para o pod: default/test-deployment3-6c95cffb97-d2xv7
I0124 13:53:59.150140       1 scheduler.go:70] Estado no Informer: map[controller:test-controller3]
I0124 13:53:59.150247       1 scheduler.go:71] Estado real no cluster: map[controller:test-controller3]
W0124 13:53:59.150297       1 scheduler.go:135] [WaitForPodsOnCache] Pod test-deployment3-6c95cffb97-d2xv7 não encontrado no cache. Tentando novamente...
I0124 13:53:59.251017       1 scheduler.go:606] [GetControllerMetricInfo] Iniciando para o pod: default/test-deployment3-6c95cffb97-d2xv7
I0124 13:53:59.251069       1 scheduler.go:611] [GetControllerMetricInfo] Obtendo o nome do controlador para o pod: default/test-deployment3-6c95cffb97-d2xv7
I0124 13:53:59.251086       1 types.go:743] [ControllerName] Verificando as anotações do pod default/test-deployment3-6c95cffb97-d2xv7
I0124 13:53:59.251105       1 types.go:761] [ControllerName] Anotação 'controller' encontrada para o pod default/test-deployment3-6c95cffb97-d2xv7: test-controller3
I0124 13:53:59.251121       1 scheduler.go:614] [GetControllerMetricInfo] Métricas do controlador definidas para o pod: default/test-deployment3-6c95cffb97-d2xv7
W0124 13:53:59.251188       1 scheduler.go:125] [cacheMiss] Métricas não encontradas para o pod: default/test-deployment3-6c95cffb97-d2xv7
I0124 13:53:59.260128       1 scheduler.go:70] Estado no Informer: map[controller:test-controller3]
I0124 13:53:59.260453       1 scheduler.go:71] Estado real no cluster: map[controller:test-controller3]
W0124 13:53:59.261261       1 scheduler.go:135] [WaitForPodsOnCache] Pod test-deployment3-6c95cffb97-d2xv7 não encontrado no cache. Tentando novamente...
I0124 13:53:59.364325       1 scheduler.go:606] [GetControllerMetricInfo] Iniciando para o pod: default/test-deployment3-6c95cffb97-d2xv7
I0124 13:53:59.365481       1 scheduler.go:611] [GetControllerMetricInfo] Obtendo o nome do controlador para o pod: default/test-deployment3-6c95cffb97-d2xv7
I0124 13:53:59.366223       1 types.go:743] [ControllerName] Verificando as anotações do pod default/test-deployment3-6c95cffb97-d2xv7
I0124 13:53:59.366790       1 types.go:761] [ControllerName] Anotação 'controller' encontrada para o pod default/test-deployment3-6c95cffb97-d2xv7: test-controller3
I0124 13:53:59.367187       1 scheduler.go:614] [GetControllerMetricInfo] Métricas do controlador definidas para o pod: default/test-deployment3-6c95cffb97-d2xv7
W0124 13:53:59.367772       1 scheduler.go:125] [cacheMiss] Métricas não encontradas para o pod: default/test-deployment3-6c95cffb97-d2xv7
I0124 13:53:59.381226       1 scheduler.go:70] Estado no Informer: map[controller:test-controller3]
I0124 13:53:59.381765       1 scheduler.go:71] Estado real no cluster: map[controller:test-controller3]
W0124 13:53:59.382472       1 scheduler.go:135] [WaitForPodsOnCache] Pod test-deployment3-6c95cffb97-d2xv7 não encontrado no cache. Tentando novamente...
I0124 13:53:59.483791       1 scheduler.go:606] [GetControllerMetricInfo] Iniciando para o pod: default/test-deployment3-6c95cffb97-d2xv7
I0124 13:53:59.483963       1 scheduler.go:611] [GetControllerMetricInfo] Obtendo o nome do controlador para o pod: default/test-deployment3-6c95cffb97-d2xv7
I0124 13:53:59.483985       1 types.go:743] [ControllerName] Verificando as anotações do pod default/test-deployment3-6c95cffb97-d2xv7
I0124 13:53:59.484014       1 types.go:761] [ControllerName] Anotação 'controller' encontrada para o pod default/test-deployment3-6c95cffb97-d2xv7: test-controller3
I0124 13:53:59.484032       1 scheduler.go:614] [GetControllerMetricInfo] Métricas do controlador definidas para o pod: default/test-deployment3-6c95cffb97-d2xv7
W0124 13:53:59.484054       1 scheduler.go:125] [cacheMiss] Métricas não encontradas para o pod: default/test-deployment3-6c95cffb97-d2xv7
I0124 13:53:59.493237       1 scheduler.go:70] Estado no Informer: map[controller:test-controller3]
I0124 13:53:59.494588       1 scheduler.go:71] Estado real no cluster: map[controller:test-controller3]
W0124 13:53:59.495181       1 scheduler.go:135] [WaitForPodsOnCache] Pod test-deployment3-6c95cffb97-d2xv7 não encontrado no cache. Tentando novamente...
I0124 13:53:59.597232       1 scheduler.go:606] [GetControllerMetricInfo] Iniciando para o pod: default/test-deployment3-6c95cffb97-d2xv7
I0124 13:53:59.597675       1 scheduler.go:611] [GetControllerMetricInfo] Obtendo o nome do controlador para o pod: default/test-deployment3-6c95cffb97-d2xv7
I0124 13:53:59.598699       1 types.go:743] [ControllerName] Verificando as anotações do pod default/test-deployment3-6c95cffb97-d2xv7
I0124 13:53:59.598985       1 types.go:761] [ControllerName] Anotação 'controller' encontrada para o pod default/test-deployment3-6c95cffb97-d2xv7: test-controller3
I0124 13:53:59.599283       1 scheduler.go:614] [GetControllerMetricInfo] Métricas do controlador definidas para o pod: default/test-deployment3-6c95cffb97-d2xv7
W0124 13:53:59.599481       1 scheduler.go:125] [cacheMiss] Métricas não encontradas para o pod: default/test-deployment3-6c95cffb97-d2xv7
I0124 13:53:59.611370       1 scheduler.go:70] Estado no Informer: map[controller:test-controller3]
I0124 13:53:59.612521       1 scheduler.go:71] Estado real no cluster: map[controller:test-controller3]
W0124 13:53:59.613365       1 scheduler.go:135] [WaitForPodsOnCache] Pod test-deployment3-6c95cffb97-d2xv7 não encontrado no cache. Tentando novamente...
I0124 13:53:59.714552       1 scheduler.go:606] [GetControllerMetricInfo] Iniciando para o pod: default/test-deployment3-6c95cffb97-d2xv7
I0124 13:53:59.714604       1 scheduler.go:611] [GetControllerMetricInfo] Obtendo o nome do controlador para o pod: default/test-deployment3-6c95cffb97-d2xv7
I0124 13:53:59.714620       1 types.go:743] [ControllerName] Verificando as anotações do pod default/test-deployment3-6c95cffb97-d2xv7
I0124 13:53:59.714639       1 types.go:761] [ControllerName] Anotação 'controller' encontrada para o pod default/test-deployment3-6c95cffb97-d2xv7: test-controller3
I0124 13:53:59.714654       1 scheduler.go:614] [GetControllerMetricInfo] Métricas do controlador definidas para o pod: default/test-deployment3-6c95cffb97-d2xv7
W0124 13:53:59.714675       1 scheduler.go:125] [cacheMiss] Métricas não encontradas para o pod: default/test-deployment3-6c95cffb97-d2xv7
I0124 13:53:59.722514       1 scheduler.go:70] Estado no Informer: map[controller:test-controller3]
I0124 13:53:59.723512       1 scheduler.go:71] Estado real no cluster: map[controller:test-controller3]
W0124 13:53:59.724452       1 scheduler.go:135] [WaitForPodsOnCache] Pod test-deployment3-6c95cffb97-d2xv7 não encontrado no cache. Tentando novamente...
I0124 13:53:59.826101       1 scheduler.go:606] [GetControllerMetricInfo] Iniciando para o pod: default/test-deployment3-6c95cffb97-d2xv7
I0124 13:53:59.826634       1 scheduler.go:611] [GetControllerMetricInfo] Obtendo o nome do controlador para o pod: default/test-deployment3-6c95cffb97-d2xv7
I0124 13:53:59.827005       1 types.go:743] [ControllerName] Verificando as anotações do pod default/test-deployment3-6c95cffb97-d2xv7
I0124 13:53:59.827384       1 types.go:761] [ControllerName] Anotação 'controller' encontrada para o pod default/test-deployment3-6c95cffb97-d2xv7: test-controller3
I0124 13:53:59.827808       1 scheduler.go:614] [GetControllerMetricInfo] Métricas do controlador definidas para o pod: default/test-deployment3-6c95cffb97-d2xv7
W0124 13:53:59.828332       1 scheduler.go:125] [cacheMiss] Métricas não encontradas para o pod: default/test-deployment3-6c95cffb97-d2xv7
I0124 13:53:59.842822       1 scheduler.go:70] Estado no Informer: map[controller:test-controller3]
I0124 13:53:59.843569       1 scheduler.go:71] Estado real no cluster: map[controller:test-controller3]
W0124 13:53:59.844254       1 scheduler.go:135] [WaitForPodsOnCache] Pod test-deployment3-6c95cffb97-d2xv7 não encontrado no cache. Tentando novamente...
I0124 13:53:59.947406       1 scheduler.go:606] [GetControllerMetricInfo] Iniciando para o pod: default/test-deployment3-6c95cffb97-d2xv7
I0124 13:53:59.947973       1 scheduler.go:611] [GetControllerMetricInfo] Obtendo o nome do controlador para o pod: default/test-deployment3-6c95cffb97-d2xv7
I0124 13:53:59.948493       1 types.go:743] [ControllerName] Verificando as anotações do pod default/test-deployment3-6c95cffb97-d2xv7
I0124 13:53:59.949088       1 types.go:761] [ControllerName] Anotação 'controller' encontrada para o pod default/test-deployment3-6c95cffb97-d2xv7: test-controller3
I0124 13:53:59.949671       1 scheduler.go:614] [GetControllerMetricInfo] Métricas do controlador definidas para o pod: default/test-deployment3-6c95cffb97-d2xv7
W0124 13:53:59.950167       1 scheduler.go:125] [cacheMiss] Métricas não encontradas para o pod: default/test-deployment3-6c95cffb97-d2xv7
I0124 13:53:59.959515       1 scheduler.go:70] Estado no Informer: map[controller:test-controller3]
I0124 13:53:59.960019       1 scheduler.go:71] Estado real no cluster: map[controller:test-controller3]
W0124 13:53:59.960381       1 scheduler.go:135] [WaitForPodsOnCache] Pod test-deployment3-6c95cffb97-d2xv7 não encontrado no cache. Tentando novamente...
I0124 13:54:00.060651       1 scheduler.go:606] [GetControllerMetricInfo] Iniciando para o pod: default/test-deployment3-6c95cffb97-d2xv7
I0124 13:54:00.061012       1 scheduler.go:611] [GetControllerMetricInfo] Obtendo o nome do controlador para o pod: default/test-deployment3-6c95cffb97-d2xv7
I0124 13:54:00.061070       1 types.go:743] [ControllerName] Verificando as anotações do pod default/test-deployment3-6c95cffb97-d2xv7
I0124 13:54:00.061123       1 types.go:761] [ControllerName] Anotação 'controller' encontrada para o pod default/test-deployment3-6c95cffb97-d2xv7: test-controller3
I0124 13:54:00.061174       1 scheduler.go:614] [GetControllerMetricInfo] Métricas do controlador definidas para o pod: default/test-deployment3-6c95cffb97-d2xv7
W0124 13:54:00.061445       1 scheduler.go:125] [cacheMiss] Métricas não encontradas para o pod: default/test-deployment3-6c95cffb97-d2xv7
I0124 13:54:00.072505       1 scheduler.go:70] Estado no Informer: map[controller:test-controller3]
I0124 13:54:00.072734       1 scheduler.go:71] Estado real no cluster: map[controller:test-controller3]
W0124 13:54:00.072795       1 scheduler.go:135] [WaitForPodsOnCache] Pod test-deployment3-6c95cffb97-d2xv7 não encontrado no cache. Tentando novamente...
I0124 13:54:00.173806       1 scheduler.go:606] [GetControllerMetricInfo] Iniciando para o pod: default/test-deployment3-6c95cffb97-d2xv7
I0124 13:54:00.174155       1 scheduler.go:611] [GetControllerMetricInfo] Obtendo o nome do controlador para o pod: default/test-deployment3-6c95cffb97-d2xv7
I0124 13:54:00.174212       1 types.go:743] [ControllerName] Verificando as anotações do pod default/test-deployment3-6c95cffb97-d2xv7
I0124 13:54:00.174263       1 types.go:761] [ControllerName] Anotação 'controller' encontrada para o pod default/test-deployment3-6c95cffb97-d2xv7: test-controller3
I0124 13:54:00.174350       1 scheduler.go:614] [GetControllerMetricInfo] Métricas do controlador definidas para o pod: default/test-deployment3-6c95cffb97-d2xv7
W0124 13:54:00.174830       1 scheduler.go:125] [cacheMiss] Métricas não encontradas para o pod: default/test-deployment3-6c95cffb97-d2xv7
I0124 13:54:00.183671       1 scheduler.go:70] Estado no Informer: map[controller:test-controller3]
I0124 13:54:00.183721       1 scheduler.go:71] Estado real no cluster: map[controller:test-controller3]
W0124 13:54:00.183738       1 scheduler.go:135] [WaitForPodsOnCache] Pod test-deployment3-6c95cffb97-d2xv7 não encontrado no cache. Tentando novamente...
I0124 13:54:00.284672       1 scheduler.go:606] [GetControllerMetricInfo] Iniciando para o pod: default/test-deployment3-6c95cffb97-d2xv7
I0124 13:54:00.284781       1 scheduler.go:611] [GetControllerMetricInfo] Obtendo o nome do controlador para o pod: default/test-deployment3-6c95cffb97-d2xv7
I0124 13:54:00.284801       1 types.go:743] [ControllerName] Verificando as anotações do pod default/test-deployment3-6c95cffb97-d2xv7
I0124 13:54:00.284829       1 types.go:761] [ControllerName] Anotação 'controller' encontrada para o pod default/test-deployment3-6c95cffb97-d2xv7: test-controller3
I0124 13:54:00.284919       1 scheduler.go:614] [GetControllerMetricInfo] Métricas do controlador definidas para o pod: default/test-deployment3-6c95cffb97-d2xv7
W0124 13:54:00.284944       1 scheduler.go:125] [cacheMiss] Métricas não encontradas para o pod: default/test-deployment3-6c95cffb97-d2xv7
I0124 13:54:00.291519       1 scheduler.go:70] Estado no Informer: map[controller:test-controller3]
I0124 13:54:00.291757       1 scheduler.go:71] Estado real no cluster: map[controller:test-controller3]
W0124 13:54:00.291912       1 scheduler.go:135] [WaitForPodsOnCache] Pod test-deployment3-6c95cffb97-d2xv7 não encontrado no cache. Tentando novamente...
I0124 13:54:00.393619       1 scheduler.go:606] [GetControllerMetricInfo] Iniciando para o pod: default/test-deployment3-6c95cffb97-d2xv7
I0124 13:54:00.394494       1 scheduler.go:611] [GetControllerMetricInfo] Obtendo o nome do controlador para o pod: default/test-deployment3-6c95cffb97-d2xv7
I0124 13:54:00.394924       1 types.go:743] [ControllerName] Verificando as anotações do pod default/test-deployment3-6c95cffb97-d2xv7
I0124 13:54:00.395461       1 types.go:761] [ControllerName] Anotação 'controller' encontrada para o pod default/test-deployment3-6c95cffb97-d2xv7: test-controller3
I0124 13:54:00.395810       1 scheduler.go:614] [GetControllerMetricInfo] Métricas do controlador definidas para o pod: default/test-deployment3-6c95cffb97-d2xv7
W0124 13:54:00.396364       1 scheduler.go:125] [cacheMiss] Métricas não encontradas para o pod: default/test-deployment3-6c95cffb97-d2xv7
I0124 13:54:00.429714       1 scheduler.go:70] Estado no Informer: map[controller:test-controller3]
I0124 13:54:00.435406       1 scheduler.go:71] Estado real no cluster: map[controller:test-controller3]
W0124 13:54:00.436012       1 scheduler.go:135] [WaitForPodsOnCache] Pod test-deployment3-6c95cffb97-d2xv7 não encontrado no cache. Tentando novamente...
I0124 13:54:00.537120       1 scheduler.go:606] [GetControllerMetricInfo] Iniciando para o pod: default/test-deployment3-6c95cffb97-d2xv7
I0124 13:54:00.537787       1 scheduler.go:611] [GetControllerMetricInfo] Obtendo o nome do controlador para o pod: default/test-deployment3-6c95cffb97-d2xv7
I0124 13:54:00.538523       1 types.go:743] [ControllerName] Verificando as anotações do pod default/test-deployment3-6c95cffb97-d2xv7
I0124 13:54:00.538672       1 types.go:761] [ControllerName] Anotação 'controller' encontrada para o pod default/test-deployment3-6c95cffb97-d2xv7: test-controller3
I0124 13:54:00.538722       1 scheduler.go:614] [GetControllerMetricInfo] Métricas do controlador definidas para o pod: default/test-deployment3-6c95cffb97-d2xv7
W0124 13:54:00.538776       1 scheduler.go:125] [cacheMiss] Métricas não encontradas para o pod: default/test-deployment3-6c95cffb97-d2xv7
I0124 13:54:00.548108       1 scheduler.go:70] Estado no Informer: map[controller:test-controller3]
I0124 13:54:00.549011       1 scheduler.go:71] Estado real no cluster: map[controller:test-controller3]
W0124 13:54:00.549172       1 scheduler.go:135] [WaitForPodsOnCache] Pod test-deployment3-6c95cffb97-d2xv7 não encontrado no cache. Tentando novamente...
I0124 13:54:00.650568       1 scheduler.go:606] [GetControllerMetricInfo] Iniciando para o pod: default/test-deployment3-6c95cffb97-d2xv7
I0124 13:54:00.651318       1 scheduler.go:611] [GetControllerMetricInfo] Obtendo o nome do controlador para o pod: default/test-deployment3-6c95cffb97-d2xv7
I0124 13:54:00.651638       1 types.go:743] [ControllerName] Verificando as anotações do pod default/test-deployment3-6c95cffb97-d2xv7
I0124 13:54:00.652053       1 types.go:761] [ControllerName] Anotação 'controller' encontrada para o pod default/test-deployment3-6c95cffb97-d2xv7: test-controller3
I0124 13:54:00.652476       1 scheduler.go:614] [GetControllerMetricInfo] Métricas do controlador definidas para o pod: default/test-deployment3-6c95cffb97-d2xv7
W0124 13:54:00.652652       1 scheduler.go:125] [cacheMiss] Métricas não encontradas para o pod: default/test-deployment3-6c95cffb97-d2xv7
I0124 13:54:00.660558       1 scheduler.go:70] Estado no Informer: map[controller:test-controller3]
I0124 13:54:00.660773       1 scheduler.go:71] Estado real no cluster: map[controller:test-controller3]
W0124 13:54:00.660959       1 scheduler.go:135] [WaitForPodsOnCache] Pod test-deployment3-6c95cffb97-d2xv7 não encontrado no cache. Tentando novamente...
I0124 13:54:00.762163       1 scheduler.go:606] [GetControllerMetricInfo] Iniciando para o pod: default/test-deployment3-6c95cffb97-d2xv7
I0124 13:54:00.762290       1 scheduler.go:611] [GetControllerMetricInfo] Obtendo o nome do controlador para o pod: default/test-deployment3-6c95cffb97-d2xv7
I0124 13:54:00.762324       1 types.go:743] [ControllerName] Verificando as anotações do pod default/test-deployment3-6c95cffb97-d2xv7
I0124 13:54:00.762340       1 types.go:761] [ControllerName] Anotação 'controller' encontrada para o pod default/test-deployment3-6c95cffb97-d2xv7: test-controller3
I0124 13:54:00.762353       1 scheduler.go:614] [GetControllerMetricInfo] Métricas do controlador definidas para o pod: default/test-deployment3-6c95cffb97-d2xv7
W0124 13:54:00.762369       1 scheduler.go:125] [cacheMiss] Métricas não encontradas para o pod: default/test-deployment3-6c95cffb97-d2xv7
I0124 13:54:00.768269       1 scheduler.go:70] Estado no Informer: map[controller:test-controller3]
I0124 13:54:00.768640       1 scheduler.go:71] Estado real no cluster: map[controller:test-controller3]
W0124 13:54:00.768993       1 scheduler.go:135] [WaitForPodsOnCache] Pod test-deployment3-6c95cffb97-d2xv7 não encontrado no cache. Tentando novamente...
I0124 13:54:00.869832       1 scheduler.go:606] [GetControllerMetricInfo] Iniciando para o pod: default/test-deployment3-6c95cffb97-d2xv7
I0124 13:54:00.870122       1 scheduler.go:611] [GetControllerMetricInfo] Obtendo o nome do controlador para o pod: default/test-deployment3-6c95cffb97-d2xv7
I0124 13:54:00.870297       1 types.go:743] [ControllerName] Verificando as anotações do pod default/test-deployment3-6c95cffb97-d2xv7
I0124 13:54:00.870696       1 types.go:761] [ControllerName] Anotação 'controller' encontrada para o pod default/test-deployment3-6c95cffb97-d2xv7: test-controller3
I0124 13:54:00.870797       1 scheduler.go:614] [GetControllerMetricInfo] Métricas do controlador definidas para o pod: default/test-deployment3-6c95cffb97-d2xv7
W0124 13:54:00.870923       1 scheduler.go:125] [cacheMiss] Métricas não encontradas para o pod: default/test-deployment3-6c95cffb97-d2xv7
I0124 13:54:00.876988       1 scheduler.go:70] Estado no Informer: map[controller:test-controller3]
I0124 13:54:00.877160       1 scheduler.go:71] Estado real no cluster: map[controller:test-controller3]
W0124 13:54:00.877328       1 scheduler.go:135] [WaitForPodsOnCache] Pod test-deployment3-6c95cffb97-d2xv7 não encontrado no cache. Tentando novamente...
I0124 13:54:00.978241       1 scheduler.go:606] [GetControllerMetricInfo] Iniciando para o pod: default/test-deployment3-6c95cffb97-d2xv7
I0124 13:54:00.978348       1 scheduler.go:611] [GetControllerMetricInfo] Obtendo o nome do controlador para o pod: default/test-deployment3-6c95cffb97-d2xv7
I0124 13:54:00.978376       1 types.go:743] [ControllerName] Verificando as anotações do pod default/test-deployment3-6c95cffb97-d2xv7
I0124 13:54:00.978406       1 types.go:761] [ControllerName] Anotação 'controller' encontrada para o pod default/test-deployment3-6c95cffb97-d2xv7: test-controller3
I0124 13:54:00.978435       1 scheduler.go:614] [GetControllerMetricInfo] Métricas do controlador definidas para o pod: default/test-deployment3-6c95cffb97-d2xv7
W0124 13:54:00.978468       1 scheduler.go:125] [cacheMiss] Métricas não encontradas para o pod: default/test-deployment3-6c95cffb97-d2xv7
I0124 13:54:00.990001       1 scheduler.go:70] Estado no Informer: map[controller:test-controller3]
I0124 13:54:00.991331       1 scheduler.go:71] Estado real no cluster: map[controller:test-controller3]
W0124 13:54:00.991983       1 scheduler.go:135] [WaitForPodsOnCache] Pod test-deployment3-6c95cffb97-d2xv7 não encontrado no cache. Tentando novamente...
I0124 13:54:01.094023       1 scheduler.go:606] [GetControllerMetricInfo] Iniciando para o pod: default/test-deployment3-6c95cffb97-d2xv7
I0124 13:54:01.094541       1 scheduler.go:611] [GetControllerMetricInfo] Obtendo o nome do controlador para o pod: default/test-deployment3-6c95cffb97-d2xv7
I0124 13:54:01.095013       1 types.go:743] [ControllerName] Verificando as anotações do pod default/test-deployment3-6c95cffb97-d2xv7
I0124 13:54:01.096420       1 types.go:761] [ControllerName] Anotação 'controller' encontrada para o pod default/test-deployment3-6c95cffb97-d2xv7: test-controller3
I0124 13:54:01.097251       1 scheduler.go:614] [GetControllerMetricInfo] Métricas do controlador definidas para o pod: default/test-deployment3-6c95cffb97-d2xv7
W0124 13:54:01.097489       1 scheduler.go:125] [cacheMiss] Métricas não encontradas para o pod: default/test-deployment3-6c95cffb97-d2xv7
I0124 13:54:01.107751       1 scheduler.go:70] Estado no Informer: map[controller:test-controller3]
I0124 13:54:01.107957       1 scheduler.go:71] Estado real no cluster: map[controller:test-controller3]
W0124 13:54:01.107982       1 scheduler.go:135] [WaitForPodsOnCache] Pod test-deployment3-6c95cffb97-d2xv7 não encontrado no cache. Tentando novamente...
I0124 13:54:01.208285       1 scheduler.go:606] [GetControllerMetricInfo] Iniciando para o pod: default/test-deployment3-6c95cffb97-d2xv7
I0124 13:54:01.209102       1 scheduler.go:611] [GetControllerMetricInfo] Obtendo o nome do controlador para o pod: default/test-deployment3-6c95cffb97-d2xv7
I0124 13:54:01.209311       1 types.go:743] [ControllerName] Verificando as anotações do pod default/test-deployment3-6c95cffb97-d2xv7
I0124 13:54:01.209644       1 types.go:761] [ControllerName] Anotação 'controller' encontrada para o pod default/test-deployment3-6c95cffb97-d2xv7: test-controller3
I0124 13:54:01.210193       1 scheduler.go:614] [GetControllerMetricInfo] Métricas do controlador definidas para o pod: default/test-deployment3-6c95cffb97-d2xv7
W0124 13:54:01.210550       1 scheduler.go:125] [cacheMiss] Métricas não encontradas para o pod: default/test-deployment3-6c95cffb97-d2xv7
I0124 13:54:01.219187       1 scheduler.go:70] Estado no Informer: map[controller:test-controller3]
I0124 13:54:01.219228       1 scheduler.go:71] Estado real no cluster: map[controller:test-controller3]
W0124 13:54:01.219245       1 scheduler.go:135] [WaitForPodsOnCache] Pod test-deployment3-6c95cffb97-d2xv7 não encontrado no cache. Tentando novamente...
I0124 13:54:01.320307       1 scheduler.go:606] [GetControllerMetricInfo] Iniciando para o pod: default/test-deployment3-6c95cffb97-d2xv7
I0124 13:54:01.320522       1 scheduler.go:611] [GetControllerMetricInfo] Obtendo o nome do controlador para o pod: default/test-deployment3-6c95cffb97-d2xv7
I0124 13:54:01.320747       1 types.go:743] [ControllerName] Verificando as anotações do pod default/test-deployment3-6c95cffb97-d2xv7
I0124 13:54:01.321064       1 types.go:761] [ControllerName] Anotação 'controller' encontrada para o pod default/test-deployment3-6c95cffb97-d2xv7: test-controller3
I0124 13:54:01.321170       1 scheduler.go:614] [GetControllerMetricInfo] Métricas do controlador definidas para o pod: default/test-deployment3-6c95cffb97-d2xv7
W0124 13:54:01.321385       1 scheduler.go:125] [cacheMiss] Métricas não encontradas para o pod: default/test-deployment3-6c95cffb97-d2xv7
I0124 13:54:01.330012       1 scheduler.go:70] Estado no Informer: map[controller:test-controller3]
I0124 13:54:01.330120       1 scheduler.go:71] Estado real no cluster: map[controller:test-controller3]
W0124 13:54:01.330144       1 scheduler.go:135] [WaitForPodsOnCache] Pod test-deployment3-6c95cffb97-d2xv7 não encontrado no cache. Tentando novamente...
I0124 13:54:01.430563       1 scheduler.go:606] [GetControllerMetricInfo] Iniciando para o pod: default/test-deployment3-6c95cffb97-d2xv7
I0124 13:54:01.430675       1 scheduler.go:611] [GetControllerMetricInfo] Obtendo o nome do controlador para o pod: default/test-deployment3-6c95cffb97-d2xv7
I0124 13:54:01.430694       1 types.go:743] [ControllerName] Verificando as anotações do pod default/test-deployment3-6c95cffb97-d2xv7
I0124 13:54:01.430712       1 types.go:761] [ControllerName] Anotação 'controller' encontrada para o pod default/test-deployment3-6c95cffb97-d2xv7: test-controller3
I0124 13:54:01.430728       1 scheduler.go:614] [GetControllerMetricInfo] Métricas do controlador definidas para o pod: default/test-deployment3-6c95cffb97-d2xv7
W0124 13:54:01.430750       1 scheduler.go:125] [cacheMiss] Métricas não encontradas para o pod: default/test-deployment3-6c95cffb97-d2xv7
I0124 13:54:01.438826       1 scheduler.go:70] Estado no Informer: map[controller:test-controller3]
I0124 13:54:01.439234       1 scheduler.go:71] Estado real no cluster: map[controller:test-controller3]
W0124 13:54:01.439952       1 scheduler.go:135] [WaitForPodsOnCache] Pod test-deployment3-6c95cffb97-d2xv7 não encontrado no cache. Tentando novamente...
I0124 13:54:01.541002       1 scheduler.go:606] [GetControllerMetricInfo] Iniciando para o pod: default/test-deployment3-6c95cffb97-d2xv7
I0124 13:54:01.541605       1 scheduler.go:611] [GetControllerMetricInfo] Obtendo o nome do controlador para o pod: default/test-deployment3-6c95cffb97-d2xv7
I0124 13:54:01.542192       1 types.go:743] [ControllerName] Verificando as anotações do pod default/test-deployment3-6c95cffb97-d2xv7
I0124 13:54:01.542832       1 types.go:761] [ControllerName] Anotação 'controller' encontrada para o pod default/test-deployment3-6c95cffb97-d2xv7: test-controller3
I0124 13:54:01.543069       1 scheduler.go:614] [GetControllerMetricInfo] Métricas do controlador definidas para o pod: default/test-deployment3-6c95cffb97-d2xv7
W0124 13:54:01.543536       1 scheduler.go:125] [cacheMiss] Métricas não encontradas para o pod: default/test-deployment3-6c95cffb97-d2xv7
I0124 13:54:01.552053       1 scheduler.go:70] Estado no Informer: map[controller:test-controller3]
I0124 13:54:01.552613       1 scheduler.go:71] Estado real no cluster: map[controller:test-controller3]
W0124 13:54:01.553299       1 scheduler.go:135] [WaitForPodsOnCache] Pod test-deployment3-6c95cffb97-d2xv7 não encontrado no cache. Tentando novamente...
I0124 13:54:01.654104       1 scheduler.go:606] [GetControllerMetricInfo] Iniciando para o pod: default/test-deployment3-6c95cffb97-d2xv7
I0124 13:54:01.654243       1 scheduler.go:611] [GetControllerMetricInfo] Obtendo o nome do controlador para o pod: default/test-deployment3-6c95cffb97-d2xv7
I0124 13:54:01.654267       1 types.go:743] [ControllerName] Verificando as anotações do pod default/test-deployment3-6c95cffb97-d2xv7
I0124 13:54:01.654291       1 types.go:761] [ControllerName] Anotação 'controller' encontrada para o pod default/test-deployment3-6c95cffb97-d2xv7: test-controller3
I0124 13:54:01.654341       1 scheduler.go:614] [GetControllerMetricInfo] Métricas do controlador definidas para o pod: default/test-deployment3-6c95cffb97-d2xv7
W0124 13:54:01.654370       1 scheduler.go:125] [cacheMiss] Métricas não encontradas para o pod: default/test-deployment3-6c95cffb97-d2xv7
I0124 13:54:01.663090       1 scheduler.go:70] Estado no Informer: map[controller:test-controller3]
I0124 13:54:01.663186       1 scheduler.go:71] Estado real no cluster: map[controller:test-controller3]
W0124 13:54:01.663208       1 scheduler.go:135] [WaitForPodsOnCache] Pod test-deployment3-6c95cffb97-d2xv7 não encontrado no cache. Tentando novamente...
I0124 13:54:01.763442       1 scheduler.go:606] [GetControllerMetricInfo] Iniciando para o pod: default/test-deployment3-6c95cffb97-d2xv7
I0124 13:54:01.763560       1 scheduler.go:611] [GetControllerMetricInfo] Obtendo o nome do controlador para o pod: default/test-deployment3-6c95cffb97-d2xv7
I0124 13:54:01.763579       1 types.go:743] [ControllerName] Verificando as anotações do pod default/test-deployment3-6c95cffb97-d2xv7
I0124 13:54:01.763597       1 types.go:761] [ControllerName] Anotação 'controller' encontrada para o pod default/test-deployment3-6c95cffb97-d2xv7: test-controller3
I0124 13:54:01.763613       1 scheduler.go:614] [GetControllerMetricInfo] Métricas do controlador definidas para o pod: default/test-deployment3-6c95cffb97-d2xv7
W0124 13:54:01.763634       1 scheduler.go:125] [cacheMiss] Métricas não encontradas para o pod: default/test-deployment3-6c95cffb97-d2xv7
I0124 13:54:01.770777       1 scheduler.go:70] Estado no Informer: map[controller:test-controller3]
I0124 13:54:01.770995       1 scheduler.go:71] Estado real no cluster: map[controller:test-controller3]
W0124 13:54:01.771018       1 scheduler.go:135] [WaitForPodsOnCache] Pod test-deployment3-6c95cffb97-d2xv7 não encontrado no cache. Tentando novamente...
I0124 13:54:01.871105       1 scheduler.go:606] [GetControllerMetricInfo] Iniciando para o pod: default/test-deployment3-6c95cffb97-d2xv7
I0124 13:54:01.871211       1 scheduler.go:611] [GetControllerMetricInfo] Obtendo o nome do controlador para o pod: default/test-deployment3-6c95cffb97-d2xv7
I0124 13:54:01.871227       1 types.go:743] [ControllerName] Verificando as anotações do pod default/test-deployment3-6c95cffb97-d2xv7
I0124 13:54:01.871242       1 types.go:761] [ControllerName] Anotação 'controller' encontrada para o pod default/test-deployment3-6c95cffb97-d2xv7: test-controller3
I0124 13:54:01.871258       1 scheduler.go:614] [GetControllerMetricInfo] Métricas do controlador definidas para o pod: default/test-deployment3-6c95cffb97-d2xv7
W0124 13:54:01.871278       1 scheduler.go:125] [cacheMiss] Métricas não encontradas para o pod: default/test-deployment3-6c95cffb97-d2xv7
I0124 13:54:01.878744       1 scheduler.go:70] Estado no Informer: map[controller:test-controller3]
I0124 13:54:01.878948       1 scheduler.go:71] Estado real no cluster: map[controller:test-controller3]
W0124 13:54:01.878973       1 scheduler.go:135] [WaitForPodsOnCache] Pod test-deployment3-6c95cffb97-d2xv7 não encontrado no cache. Tentando novamente...
I0124 13:54:01.980555       1 scheduler.go:606] [GetControllerMetricInfo] Iniciando para o pod: default/test-deployment3-6c95cffb97-d2xv7
I0124 13:54:01.981516       1 scheduler.go:611] [GetControllerMetricInfo] Obtendo o nome do controlador para o pod: default/test-deployment3-6c95cffb97-d2xv7
I0124 13:54:01.982044       1 types.go:743] [ControllerName] Verificando as anotações do pod default/test-deployment3-6c95cffb97-d2xv7
I0124 13:54:01.982642       1 types.go:761] [ControllerName] Anotação 'controller' encontrada para o pod default/test-deployment3-6c95cffb97-d2xv7: test-controller3
I0124 13:54:01.982825       1 scheduler.go:614] [GetControllerMetricInfo] Métricas do controlador definidas para o pod: default/test-deployment3-6c95cffb97-d2xv7
W0124 13:54:01.983062       1 scheduler.go:125] [cacheMiss] Métricas não encontradas para o pod: default/test-deployment3-6c95cffb97-d2xv7
I0124 13:54:01.993377       1 scheduler.go:70] Estado no Informer: map[controller:test-controller3]
I0124 13:54:01.993546       1 scheduler.go:71] Estado real no cluster: map[controller:test-controller3]
W0124 13:54:01.993837       1 scheduler.go:135] [WaitForPodsOnCache] Pod test-deployment3-6c95cffb97-d2xv7 não encontrado no cache. Tentando novamente...
I0124 13:54:02.095346       1 scheduler.go:606] [GetControllerMetricInfo] Iniciando para o pod: default/test-deployment3-6c95cffb97-d2xv7
I0124 13:54:02.095827       1 scheduler.go:611] [GetControllerMetricInfo] Obtendo o nome do controlador para o pod: default/test-deployment3-6c95cffb97-d2xv7
I0124 13:54:02.096597       1 types.go:743] [ControllerName] Verificando as anotações do pod default/test-deployment3-6c95cffb97-d2xv7
I0124 13:54:02.097275       1 types.go:761] [ControllerName] Anotação 'controller' encontrada para o pod default/test-deployment3-6c95cffb97-d2xv7: test-controller3
I0124 13:54:02.097741       1 scheduler.go:614] [GetControllerMetricInfo] Métricas do controlador definidas para o pod: default/test-deployment3-6c95cffb97-d2xv7
W0124 13:54:02.098356       1 scheduler.go:125] [cacheMiss] Métricas não encontradas para o pod: default/test-deployment3-6c95cffb97-d2xv7
I0124 13:54:02.114759       1 scheduler.go:70] Estado no Informer: map[controller:test-controller3]
I0124 13:54:02.114972       1 scheduler.go:71] Estado real no cluster: map[controller:test-controller3]
W0124 13:54:02.115001       1 scheduler.go:135] [WaitForPodsOnCache] Pod test-deployment3-6c95cffb97-d2xv7 não encontrado no cache. Tentando novamente...
I0124 13:54:02.215350       1 scheduler.go:606] [GetControllerMetricInfo] Iniciando para o pod: default/test-deployment3-6c95cffb97-d2xv7
I0124 13:54:02.215476       1 scheduler.go:611] [GetControllerMetricInfo] Obtendo o nome do controlador para o pod: default/test-deployment3-6c95cffb97-d2xv7
I0124 13:54:02.215501       1 types.go:743] [ControllerName] Verificando as anotações do pod default/test-deployment3-6c95cffb97-d2xv7
I0124 13:54:02.215523       1 types.go:761] [ControllerName] Anotação 'controller' encontrada para o pod default/test-deployment3-6c95cffb97-d2xv7: test-controller3
I0124 13:54:02.215539       1 scheduler.go:614] [GetControllerMetricInfo] Métricas do controlador definidas para o pod: default/test-deployment3-6c95cffb97-d2xv7
W0124 13:54:02.215559       1 scheduler.go:125] [cacheMiss] Métricas não encontradas para o pod: default/test-deployment3-6c95cffb97-d2xv7
I0124 13:54:02.222565       1 scheduler.go:70] Estado no Informer: map[controller:test-controller3]
I0124 13:54:02.223014       1 scheduler.go:71] Estado real no cluster: map[controller:test-controller3]
W0124 13:54:02.223150       1 scheduler.go:135] [WaitForPodsOnCache] Pod test-deployment3-6c95cffb97-d2xv7 não encontrado no cache. Tentando novamente...
I0124 13:54:02.326022       1 scheduler.go:606] [GetControllerMetricInfo] Iniciando para o pod: default/test-deployment3-6c95cffb97-d2xv7
I0124 13:54:02.330980       1 scheduler.go:611] [GetControllerMetricInfo] Obtendo o nome do controlador para o pod: default/test-deployment3-6c95cffb97-d2xv7
I0124 13:54:02.333135       1 types.go:743] [ControllerName] Verificando as anotações do pod default/test-deployment3-6c95cffb97-d2xv7
I0124 13:54:02.333334       1 types.go:761] [ControllerName] Anotação 'controller' encontrada para o pod default/test-deployment3-6c95cffb97-d2xv7: test-controller3
I0124 13:54:02.333614       1 scheduler.go:614] [GetControllerMetricInfo] Métricas do controlador definidas para o pod: default/test-deployment3-6c95cffb97-d2xv7
W0124 13:54:02.333946       1 scheduler.go:125] [cacheMiss] Métricas não encontradas para o pod: default/test-deployment3-6c95cffb97-d2xv7
I0124 13:54:02.343315       1 scheduler.go:70] Estado no Informer: map[controller:test-controller3]
I0124 13:54:02.343708       1 scheduler.go:71] Estado real no cluster: map[controller:test-controller3]
W0124 13:54:02.343981       1 scheduler.go:135] [WaitForPodsOnCache] Pod test-deployment3-6c95cffb97-d2xv7 não encontrado no cache. Tentando novamente...
I0124 13:54:02.445077       1 scheduler.go:606] [GetControllerMetricInfo] Iniciando para o pod: default/test-deployment3-6c95cffb97-d2xv7
I0124 13:54:02.445187       1 scheduler.go:611] [GetControllerMetricInfo] Obtendo o nome do controlador para o pod: default/test-deployment3-6c95cffb97-d2xv7
I0124 13:54:02.445206       1 types.go:743] [ControllerName] Verificando as anotações do pod default/test-deployment3-6c95cffb97-d2xv7
I0124 13:54:02.445223       1 types.go:761] [ControllerName] Anotação 'controller' encontrada para o pod default/test-deployment3-6c95cffb97-d2xv7: test-controller3
I0124 13:54:02.445240       1 scheduler.go:614] [GetControllerMetricInfo] Métricas do controlador definidas para o pod: default/test-deployment3-6c95cffb97-d2xv7
W0124 13:54:02.445261       1 scheduler.go:125] [cacheMiss] Métricas não encontradas para o pod: default/test-deployment3-6c95cffb97-d2xv7
I0124 13:54:02.471536       1 scheduler.go:70] Estado no Informer: map[controller:test-controller3]
I0124 13:54:02.471622       1 scheduler.go:71] Estado real no cluster: map[controller:test-controller3]
W0124 13:54:02.471640       1 scheduler.go:135] [WaitForPodsOnCache] Pod test-deployment3-6c95cffb97-d2xv7 não encontrado no cache. Tentando novamente...
I0124 13:54:02.572099       1 scheduler.go:606] [GetControllerMetricInfo] Iniciando para o pod: default/test-deployment3-6c95cffb97-d2xv7
I0124 13:54:02.572317       1 scheduler.go:611] [GetControllerMetricInfo] Obtendo o nome do controlador para o pod: default/test-deployment3-6c95cffb97-d2xv7
I0124 13:54:02.572338       1 types.go:743] [ControllerName] Verificando as anotações do pod default/test-deployment3-6c95cffb97-d2xv7
I0124 13:54:02.572353       1 types.go:761] [ControllerName] Anotação 'controller' encontrada para o pod default/test-deployment3-6c95cffb97-d2xv7: test-controller3
I0124 13:54:02.572368       1 scheduler.go:614] [GetControllerMetricInfo] Métricas do controlador definidas para o pod: default/test-deployment3-6c95cffb97-d2xv7
W0124 13:54:02.572389       1 scheduler.go:125] [cacheMiss] Métricas não encontradas para o pod: default/test-deployment3-6c95cffb97-d2xv7
I0124 13:54:02.582833       1 scheduler.go:70] Estado no Informer: map[controller:test-controller3]
I0124 13:54:02.583320       1 scheduler.go:71] Estado real no cluster: map[controller:test-controller3]
W0124 13:54:02.583443       1 scheduler.go:135] [WaitForPodsOnCache] Pod test-deployment3-6c95cffb97-d2xv7 não encontrado no cache. Tentando novamente...
I0124 13:54:02.684759       1 scheduler.go:606] [GetControllerMetricInfo] Iniciando para o pod: default/test-deployment3-6c95cffb97-d2xv7
I0124 13:54:02.684810       1 scheduler.go:611] [GetControllerMetricInfo] Obtendo o nome do controlador para o pod: default/test-deployment3-6c95cffb97-d2xv7
I0124 13:54:02.684824       1 types.go:743] [ControllerName] Verificando as anotações do pod default/test-deployment3-6c95cffb97-d2xv7
I0124 13:54:02.684840       1 types.go:761] [ControllerName] Anotação 'controller' encontrada para o pod default/test-deployment3-6c95cffb97-d2xv7: test-controller3
I0124 13:54:02.684979       1 scheduler.go:614] [GetControllerMetricInfo] Métricas do controlador definidas para o pod: default/test-deployment3-6c95cffb97-d2xv7
W0124 13:54:02.685002       1 scheduler.go:125] [cacheMiss] Métricas não encontradas para o pod: default/test-deployment3-6c95cffb97-d2xv7
I0124 13:54:02.691825       1 scheduler.go:70] Estado no Informer: map[controller:test-controller3]
I0124 13:54:02.692429       1 scheduler.go:71] Estado real no cluster: map[controller:test-controller3]
W0124 13:54:02.692722       1 scheduler.go:135] [WaitForPodsOnCache] Pod test-deployment3-6c95cffb97-d2xv7 não encontrado no cache. Tentando novamente...
I0124 13:54:02.794103       1 scheduler.go:606] [GetControllerMetricInfo] Iniciando para o pod: default/test-deployment3-6c95cffb97-d2xv7
I0124 13:54:02.794212       1 scheduler.go:611] [GetControllerMetricInfo] Obtendo o nome do controlador para o pod: default/test-deployment3-6c95cffb97-d2xv7
I0124 13:54:02.794231       1 types.go:743] [ControllerName] Verificando as anotações do pod default/test-deployment3-6c95cffb97-d2xv7
I0124 13:54:02.794249       1 types.go:761] [ControllerName] Anotação 'controller' encontrada para o pod default/test-deployment3-6c95cffb97-d2xv7: test-controller3
I0124 13:54:02.794266       1 scheduler.go:614] [GetControllerMetricInfo] Métricas do controlador definidas para o pod: default/test-deployment3-6c95cffb97-d2xv7
W0124 13:54:02.794287       1 scheduler.go:125] [cacheMiss] Métricas não encontradas para o pod: default/test-deployment3-6c95cffb97-d2xv7
I0124 13:54:02.802310       1 scheduler.go:70] Estado no Informer: map[controller:test-controller3]
I0124 13:54:02.802519       1 scheduler.go:71] Estado real no cluster: map[controller:test-controller3]
W0124 13:54:02.803370       1 scheduler.go:135] [WaitForPodsOnCache] Pod test-deployment3-6c95cffb97-d2xv7 não encontrado no cache. Tentando novamente...
I0124 13:54:02.904645       1 scheduler.go:606] [GetControllerMetricInfo] Iniciando para o pod: default/test-deployment3-6c95cffb97-d2xv7
I0124 13:54:02.904793       1 scheduler.go:611] [GetControllerMetricInfo] Obtendo o nome do controlador para o pod: default/test-deployment3-6c95cffb97-d2xv7
I0124 13:54:02.904813       1 types.go:743] [ControllerName] Verificando as anotações do pod default/test-deployment3-6c95cffb97-d2xv7
I0124 13:54:02.904830       1 types.go:761] [ControllerName] Anotação 'controller' encontrada para o pod default/test-deployment3-6c95cffb97-d2xv7: test-controller3
I0124 13:54:02.904952       1 scheduler.go:614] [GetControllerMetricInfo] Métricas do controlador definidas para o pod: default/test-deployment3-6c95cffb97-d2xv7
W0124 13:54:02.904979       1 scheduler.go:125] [cacheMiss] Métricas não encontradas para o pod: default/test-deployment3-6c95cffb97-d2xv7
I0124 13:54:02.913528       1 scheduler.go:70] Estado no Informer: map[controller:test-controller3]
I0124 13:54:02.913634       1 scheduler.go:71] Estado real no cluster: map[controller:test-controller3]
W0124 13:54:02.913657       1 scheduler.go:135] [WaitForPodsOnCache] Pod test-deployment3-6c95cffb97-d2xv7 não encontrado no cache. Tentando novamente...
I0124 13:54:03.014272       1 scheduler.go:606] [GetControllerMetricInfo] Iniciando para o pod: default/test-deployment3-6c95cffb97-d2xv7
I0124 13:54:03.014320       1 scheduler.go:611] [GetControllerMetricInfo] Obtendo o nome do controlador para o pod: default/test-deployment3-6c95cffb97-d2xv7
I0124 13:54:03.014336       1 types.go:743] [ControllerName] Verificando as anotações do pod default/test-deployment3-6c95cffb97-d2xv7
I0124 13:54:03.014379       1 types.go:761] [ControllerName] Anotação 'controller' encontrada para o pod default/test-deployment3-6c95cffb97-d2xv7: test-controller3
I0124 13:54:03.014395       1 scheduler.go:614] [GetControllerMetricInfo] Métricas do controlador definidas para o pod: default/test-deployment3-6c95cffb97-d2xv7
W0124 13:54:03.014415       1 scheduler.go:125] [cacheMiss] Métricas não encontradas para o pod: default/test-deployment3-6c95cffb97-d2xv7
I0124 13:54:03.024795       1 scheduler.go:70] Estado no Informer: map[controller:test-controller3]
I0124 13:54:03.025046       1 scheduler.go:71] Estado real no cluster: map[controller:test-controller3]
W0124 13:54:03.025136       1 scheduler.go:135] [WaitForPodsOnCache] Pod test-deployment3-6c95cffb97-d2xv7 não encontrado no cache. Tentando novamente...
I0124 13:54:03.126257       1 scheduler.go:606] [GetControllerMetricInfo] Iniciando para o pod: default/test-deployment3-6c95cffb97-d2xv7
I0124 13:54:03.126384       1 scheduler.go:611] [GetControllerMetricInfo] Obtendo o nome do controlador para o pod: default/test-deployment3-6c95cffb97-d2xv7
I0124 13:54:03.126403       1 types.go:743] [ControllerName] Verificando as anotações do pod default/test-deployment3-6c95cffb97-d2xv7
I0124 13:54:03.126418       1 types.go:761] [ControllerName] Anotação 'controller' encontrada para o pod default/test-deployment3-6c95cffb97-d2xv7: test-controller3
I0124 13:54:03.126435       1 scheduler.go:614] [GetControllerMetricInfo] Métricas do controlador definidas para o pod: default/test-deployment3-6c95cffb97-d2xv7
W0124 13:54:03.126455       1 scheduler.go:125] [cacheMiss] Métricas não encontradas para o pod: default/test-deployment3-6c95cffb97-d2xv7
I0124 13:54:03.133654       1 scheduler.go:70] Estado no Informer: map[controller:test-controller3]
I0124 13:54:03.133758       1 scheduler.go:71] Estado real no cluster: map[controller:test-controller3]
W0124 13:54:03.133779       1 scheduler.go:135] [WaitForPodsOnCache] Pod test-deployment3-6c95cffb97-d2xv7 não encontrado no cache. Tentando novamente...
I0124 13:54:03.234989       1 scheduler.go:606] [GetControllerMetricInfo] Iniciando para o pod: default/test-deployment3-6c95cffb97-d2xv7
I0124 13:54:03.235486       1 scheduler.go:611] [GetControllerMetricInfo] Obtendo o nome do controlador para o pod: default/test-deployment3-6c95cffb97-d2xv7
I0124 13:54:03.236335       1 types.go:743] [ControllerName] Verificando as anotações do pod default/test-deployment3-6c95cffb97-d2xv7
I0124 13:54:03.237011       1 types.go:761] [ControllerName] Anotação 'controller' encontrada para o pod default/test-deployment3-6c95cffb97-d2xv7: test-controller3
I0124 13:54:03.237688       1 scheduler.go:614] [GetControllerMetricInfo] Métricas do controlador definidas para o pod: default/test-deployment3-6c95cffb97-d2xv7
W0124 13:54:03.238157       1 scheduler.go:125] [cacheMiss] Métricas não encontradas para o pod: default/test-deployment3-6c95cffb97-d2xv7
I0124 13:54:03.247837       1 scheduler.go:70] Estado no Informer: map[controller:test-controller3]
I0124 13:54:03.248681       1 scheduler.go:71] Estado real no cluster: map[controller:test-controller3]
W0124 13:54:03.248836       1 scheduler.go:135] [WaitForPodsOnCache] Pod test-deployment3-6c95cffb97-d2xv7 não encontrado no cache. Tentando novamente...
I0124 13:54:03.350088       1 scheduler.go:606] [GetControllerMetricInfo] Iniciando para o pod: default/test-deployment3-6c95cffb97-d2xv7
I0124 13:54:03.350273       1 scheduler.go:611] [GetControllerMetricInfo] Obtendo o nome do controlador para o pod: default/test-deployment3-6c95cffb97-d2xv7
I0124 13:54:03.350321       1 types.go:743] [ControllerName] Verificando as anotações do pod default/test-deployment3-6c95cffb97-d2xv7
I0124 13:54:03.350415       1 types.go:761] [ControllerName] Anotação 'controller' encontrada para o pod default/test-deployment3-6c95cffb97-d2xv7: test-controller3
I0124 13:54:03.350458       1 scheduler.go:614] [GetControllerMetricInfo] Métricas do controlador definidas para o pod: default/test-deployment3-6c95cffb97-d2xv7
W0124 13:54:03.350500       1 scheduler.go:125] [cacheMiss] Métricas não encontradas para o pod: default/test-deployment3-6c95cffb97-d2xv7
I0124 13:54:03.358446       1 scheduler.go:70] Estado no Informer: map[controller:test-controller3]
I0124 13:54:03.358559       1 scheduler.go:71] Estado real no cluster: map[controller:test-controller3]
W0124 13:54:03.358581       1 scheduler.go:135] [WaitForPodsOnCache] Pod test-deployment3-6c95cffb97-d2xv7 não encontrado no cache. Tentando novamente...
I0124 13:54:03.459467       1 scheduler.go:606] [GetControllerMetricInfo] Iniciando para o pod: default/test-deployment3-6c95cffb97-d2xv7
I0124 13:54:03.460059       1 scheduler.go:611] [GetControllerMetricInfo] Obtendo o nome do controlador para o pod: default/test-deployment3-6c95cffb97-d2xv7
I0124 13:54:03.460479       1 types.go:743] [ControllerName] Verificando as anotações do pod default/test-deployment3-6c95cffb97-d2xv7
I0124 13:54:03.460522       1 types.go:761] [ControllerName] Anotação 'controller' encontrada para o pod default/test-deployment3-6c95cffb97-d2xv7: test-controller3
I0124 13:54:03.460643       1 scheduler.go:614] [GetControllerMetricInfo] Métricas do controlador definidas para o pod: default/test-deployment3-6c95cffb97-d2xv7
W0124 13:54:03.461131       1 scheduler.go:125] [cacheMiss] Métricas não encontradas para o pod: default/test-deployment3-6c95cffb97-d2xv7
I0124 13:54:03.469647       1 scheduler.go:70] Estado no Informer: map[controller:test-controller3]
I0124 13:54:03.469759       1 scheduler.go:71] Estado real no cluster: map[controller:test-controller3]
W0124 13:54:03.469782       1 scheduler.go:135] [WaitForPodsOnCache] Pod test-deployment3-6c95cffb97-d2xv7 não encontrado no cache. Tentando novamente...
I0124 13:54:03.570098       1 scheduler.go:606] [GetControllerMetricInfo] Iniciando para o pod: default/test-deployment3-6c95cffb97-d2xv7
I0124 13:54:03.574284       1 scheduler.go:611] [GetControllerMetricInfo] Obtendo o nome do controlador para o pod: default/test-deployment3-6c95cffb97-d2xv7
I0124 13:54:03.575766       1 types.go:743] [ControllerName] Verificando as anotações do pod default/test-deployment3-6c95cffb97-d2xv7
I0124 13:54:03.577048       1 types.go:761] [ControllerName] Anotação 'controller' encontrada para o pod default/test-deployment3-6c95cffb97-d2xv7: test-controller3
I0124 13:54:03.577155       1 scheduler.go:614] [GetControllerMetricInfo] Métricas do controlador definidas para o pod: default/test-deployment3-6c95cffb97-d2xv7
W0124 13:54:03.577185       1 scheduler.go:125] [cacheMiss] Métricas não encontradas para o pod: default/test-deployment3-6c95cffb97-d2xv7
I0124 13:54:03.592286       1 scheduler.go:70] Estado no Informer: map[controller:test-controller3]
I0124 13:54:03.592478       1 scheduler.go:71] Estado real no cluster: map[controller:test-controller3]
W0124 13:54:03.592643       1 scheduler.go:135] [WaitForPodsOnCache] Pod test-deployment3-6c95cffb97-d2xv7 não encontrado no cache. Tentando novamente...
I0124 13:54:03.694046       1 scheduler.go:606] [GetControllerMetricInfo] Iniciando para o pod: default/test-deployment3-6c95cffb97-d2xv7
I0124 13:54:03.695047       1 scheduler.go:611] [GetControllerMetricInfo] Obtendo o nome do controlador para o pod: default/test-deployment3-6c95cffb97-d2xv7
I0124 13:54:03.695240       1 types.go:743] [ControllerName] Verificando as anotações do pod default/test-deployment3-6c95cffb97-d2xv7
I0124 13:54:03.695298       1 types.go:761] [ControllerName] Anotação 'controller' encontrada para o pod default/test-deployment3-6c95cffb97-d2xv7: test-controller3
I0124 13:54:03.695315       1 scheduler.go:614] [GetControllerMetricInfo] Métricas do controlador definidas para o pod: default/test-deployment3-6c95cffb97-d2xv7
W0124 13:54:03.695361       1 scheduler.go:125] [cacheMiss] Métricas não encontradas para o pod: default/test-deployment3-6c95cffb97-d2xv7
I0124 13:54:03.702287       1 scheduler.go:70] Estado no Informer: map[controller:test-controller3]
I0124 13:54:03.702475       1 scheduler.go:71] Estado real no cluster: map[controller:test-controller3]
W0124 13:54:03.702526       1 scheduler.go:135] [WaitForPodsOnCache] Pod test-deployment3-6c95cffb97-d2xv7 não encontrado no cache. Tentando novamente...
I0124 13:54:03.803246       1 scheduler.go:606] [GetControllerMetricInfo] Iniciando para o pod: default/test-deployment3-6c95cffb97-d2xv7
I0124 13:54:03.803289       1 scheduler.go:611] [GetControllerMetricInfo] Obtendo o nome do controlador para o pod: default/test-deployment3-6c95cffb97-d2xv7
I0124 13:54:03.803302       1 types.go:743] [ControllerName] Verificando as anotações do pod default/test-deployment3-6c95cffb97-d2xv7
I0124 13:54:03.803355       1 types.go:761] [ControllerName] Anotação 'controller' encontrada para o pod default/test-deployment3-6c95cffb97-d2xv7: test-controller3
I0124 13:54:03.803371       1 scheduler.go:614] [GetControllerMetricInfo] Métricas do controlador definidas para o pod: default/test-deployment3-6c95cffb97-d2xv7
W0124 13:54:03.803390       1 scheduler.go:125] [cacheMiss] Métricas não encontradas para o pod: default/test-deployment3-6c95cffb97-d2xv7
I0124 13:54:03.813139       1 scheduler.go:70] Estado no Informer: map[controller:test-controller3]
I0124 13:54:03.814053       1 scheduler.go:71] Estado real no cluster: map[controller:test-controller3]
W0124 13:54:03.814571       1 scheduler.go:135] [WaitForPodsOnCache] Pod test-deployment3-6c95cffb97-d2xv7 não encontrado no cache. Tentando novamente...
I0124 13:54:03.916410       1 scheduler.go:606] [GetControllerMetricInfo] Iniciando para o pod: default/test-deployment3-6c95cffb97-d2xv7
I0124 13:54:03.916506       1 scheduler.go:611] [GetControllerMetricInfo] Obtendo o nome do controlador para o pod: default/test-deployment3-6c95cffb97-d2xv7
I0124 13:54:03.916525       1 types.go:743] [ControllerName] Verificando as anotações do pod default/test-deployment3-6c95cffb97-d2xv7
I0124 13:54:03.916541       1 types.go:761] [ControllerName] Anotação 'controller' encontrada para o pod default/test-deployment3-6c95cffb97-d2xv7: test-controller3
I0124 13:54:03.916592       1 scheduler.go:614] [GetControllerMetricInfo] Métricas do controlador definidas para o pod: default/test-deployment3-6c95cffb97-d2xv7
W0124 13:54:03.916646       1 scheduler.go:125] [cacheMiss] Métricas não encontradas para o pod: default/test-deployment3-6c95cffb97-d2xv7
I0124 13:54:03.926164       1 scheduler.go:70] Estado no Informer: map[controller:test-controller3]
I0124 13:54:03.926411       1 scheduler.go:71] Estado real no cluster: map[controller:test-controller3]
W0124 13:54:03.926466       1 scheduler.go:135] [WaitForPodsOnCache] Pod test-deployment3-6c95cffb97-d2xv7 não encontrado no cache. Tentando novamente...
I0124 13:54:04.027272       1 scheduler.go:606] [GetControllerMetricInfo] Iniciando para o pod: default/test-deployment3-6c95cffb97-d2xv7
I0124 13:54:04.027523       1 scheduler.go:611] [GetControllerMetricInfo] Obtendo o nome do controlador para o pod: default/test-deployment3-6c95cffb97-d2xv7
I0124 13:54:04.027572       1 types.go:743] [ControllerName] Verificando as anotações do pod default/test-deployment3-6c95cffb97-d2xv7
I0124 13:54:04.027613       1 types.go:761] [ControllerName] Anotação 'controller' encontrada para o pod default/test-deployment3-6c95cffb97-d2xv7: test-controller3
I0124 13:54:04.027652       1 scheduler.go:614] [GetControllerMetricInfo] Métricas do controlador definidas para o pod: default/test-deployment3-6c95cffb97-d2xv7
W0124 13:54:04.027761       1 scheduler.go:125] [cacheMiss] Métricas não encontradas para o pod: default/test-deployment3-6c95cffb97-d2xv7
I0124 13:54:04.173071       1 scheduler.go:70] Estado no Informer: map[controller:test-controller3]
I0124 13:54:04.173408       1 scheduler.go:71] Estado real no cluster: map[controller:test-controller3]
W0124 13:54:04.173490       1 scheduler.go:135] [WaitForPodsOnCache] Pod test-deployment3-6c95cffb97-d2xv7 não encontrado no cache. Tentando novamente...
I0124 13:54:04.274317       1 scheduler.go:606] [GetControllerMetricInfo] Iniciando para o pod: default/test-deployment3-6c95cffb97-d2xv7
I0124 13:54:04.274599       1 scheduler.go:611] [GetControllerMetricInfo] Obtendo o nome do controlador para o pod: default/test-deployment3-6c95cffb97-d2xv7
I0124 13:54:04.274649       1 types.go:743] [ControllerName] Verificando as anotações do pod default/test-deployment3-6c95cffb97-d2xv7
I0124 13:54:04.274691       1 types.go:761] [ControllerName] Anotação 'controller' encontrada para o pod default/test-deployment3-6c95cffb97-d2xv7: test-controller3
I0124 13:54:04.274790       1 scheduler.go:614] [GetControllerMetricInfo] Métricas do controlador definidas para o pod: default/test-deployment3-6c95cffb97-d2xv7
W0124 13:54:04.275561       1 scheduler.go:125] [cacheMiss] Métricas não encontradas para o pod: default/test-deployment3-6c95cffb97-d2xv7
I0124 13:54:04.286556       1 scheduler.go:70] Estado no Informer: map[controller:test-controller3]
I0124 13:54:04.287167       1 scheduler.go:71] Estado real no cluster: map[controller:test-controller3]
W0124 13:54:04.287681       1 scheduler.go:135] [WaitForPodsOnCache] Pod test-deployment3-6c95cffb97-d2xv7 não encontrado no cache. Tentando novamente...
I0124 13:54:04.389688       1 scheduler.go:606] [GetControllerMetricInfo] Iniciando para o pod: default/test-deployment3-6c95cffb97-d2xv7
I0124 13:54:04.390952       1 scheduler.go:611] [GetControllerMetricInfo] Obtendo o nome do controlador para o pod: default/test-deployment3-6c95cffb97-d2xv7
I0124 13:54:04.391085       1 types.go:743] [ControllerName] Verificando as anotações do pod default/test-deployment3-6c95cffb97-d2xv7
I0124 13:54:04.391134       1 types.go:761] [ControllerName] Anotação 'controller' encontrada para o pod default/test-deployment3-6c95cffb97-d2xv7: test-controller3
I0124 13:54:04.391175       1 scheduler.go:614] [GetControllerMetricInfo] Métricas do controlador definidas para o pod: default/test-deployment3-6c95cffb97-d2xv7
W0124 13:54:04.391240       1 scheduler.go:125] [cacheMiss] Métricas não encontradas para o pod: default/test-deployment3-6c95cffb97-d2xv7
I0124 13:54:04.400552       1 scheduler.go:70] Estado no Informer: map[controller:test-controller3]
I0124 13:54:04.400660       1 scheduler.go:71] Estado real no cluster: map[controller:test-controller3]
W0124 13:54:04.400682       1 scheduler.go:135] [WaitForPodsOnCache] Pod test-deployment3-6c95cffb97-d2xv7 não encontrado no cache. Tentando novamente...
I0124 13:54:04.501824       1 scheduler.go:606] [GetControllerMetricInfo] Iniciando para o pod: default/test-deployment3-6c95cffb97-d2xv7
I0124 13:54:04.503031       1 scheduler.go:611] [GetControllerMetricInfo] Obtendo o nome do controlador para o pod: default/test-deployment3-6c95cffb97-d2xv7
I0124 13:54:04.503225       1 types.go:743] [ControllerName] Verificando as anotações do pod default/test-deployment3-6c95cffb97-d2xv7
I0124 13:54:04.503320       1 types.go:761] [ControllerName] Anotação 'controller' encontrada para o pod default/test-deployment3-6c95cffb97-d2xv7: test-controller3
I0124 13:54:04.503380       1 scheduler.go:614] [GetControllerMetricInfo] Métricas do controlador definidas para o pod: default/test-deployment3-6c95cffb97-d2xv7
W0124 13:54:04.503840       1 scheduler.go:125] [cacheMiss] Métricas não encontradas para o pod: default/test-deployment3-6c95cffb97-d2xv7
I0124 13:54:04.511693       1 scheduler.go:70] Estado no Informer: map[controller:test-controller3]
I0124 13:54:04.511789       1 scheduler.go:71] Estado real no cluster: map[controller:test-controller3]
W0124 13:54:04.511809       1 scheduler.go:135] [WaitForPodsOnCache] Pod test-deployment3-6c95cffb97-d2xv7 não encontrado no cache. Tentando novamente...
I0124 13:54:04.613245       1 scheduler.go:606] [GetControllerMetricInfo] Iniciando para o pod: default/test-deployment3-6c95cffb97-d2xv7
I0124 13:54:04.613620       1 scheduler.go:611] [GetControllerMetricInfo] Obtendo o nome do controlador para o pod: default/test-deployment3-6c95cffb97-d2xv7
I0124 13:54:04.614598       1 types.go:743] [ControllerName] Verificando as anotações do pod default/test-deployment3-6c95cffb97-d2xv7
I0124 13:54:04.614804       1 types.go:761] [ControllerName] Anotação 'controller' encontrada para o pod default/test-deployment3-6c95cffb97-d2xv7: test-controller3
I0124 13:54:04.615022       1 scheduler.go:614] [GetControllerMetricInfo] Métricas do controlador definidas para o pod: default/test-deployment3-6c95cffb97-d2xv7
W0124 13:54:04.615367       1 scheduler.go:125] [cacheMiss] Métricas não encontradas para o pod: default/test-deployment3-6c95cffb97-d2xv7
I0124 13:54:04.623283       1 scheduler.go:70] Estado no Informer: map[controller:test-controller3]
I0124 13:54:04.624036       1 scheduler.go:71] Estado real no cluster: map[controller:test-controller3]
W0124 13:54:04.624805       1 scheduler.go:135] [WaitForPodsOnCache] Pod test-deployment3-6c95cffb97-d2xv7 não encontrado no cache. Tentando novamente...
I0124 13:54:04.725778       1 scheduler.go:606] [GetControllerMetricInfo] Iniciando para o pod: default/test-deployment3-6c95cffb97-d2xv7
I0124 13:54:04.726937       1 scheduler.go:611] [GetControllerMetricInfo] Obtendo o nome do controlador para o pod: default/test-deployment3-6c95cffb97-d2xv7
I0124 13:54:04.727048       1 types.go:743] [ControllerName] Verificando as anotações do pod default/test-deployment3-6c95cffb97-d2xv7
I0124 13:54:04.727069       1 types.go:761] [ControllerName] Anotação 'controller' encontrada para o pod default/test-deployment3-6c95cffb97-d2xv7: test-controller3
I0124 13:54:04.727088       1 scheduler.go:614] [GetControllerMetricInfo] Métricas do controlador definidas para o pod: default/test-deployment3-6c95cffb97-d2xv7
W0124 13:54:04.727107       1 scheduler.go:125] [cacheMiss] Métricas não encontradas para o pod: default/test-deployment3-6c95cffb97-d2xv7
I0124 13:54:04.737570       1 scheduler.go:70] Estado no Informer: map[controller:test-controller3]
I0124 13:54:04.738819       1 scheduler.go:71] Estado real no cluster: map[controller:test-controller3]
W0124 13:54:04.740368       1 scheduler.go:135] [WaitForPodsOnCache] Pod test-deployment3-6c95cffb97-d2xv7 não encontrado no cache. Tentando novamente...
I0124 13:54:04.841738       1 scheduler.go:606] [GetControllerMetricInfo] Iniciando para o pod: default/test-deployment3-6c95cffb97-d2xv7
I0124 13:54:04.842552       1 scheduler.go:611] [GetControllerMetricInfo] Obtendo o nome do controlador para o pod: default/test-deployment3-6c95cffb97-d2xv7
I0124 13:54:04.842814       1 types.go:743] [ControllerName] Verificando as anotações do pod default/test-deployment3-6c95cffb97-d2xv7
I0124 13:54:04.843171       1 types.go:761] [ControllerName] Anotação 'controller' encontrada para o pod default/test-deployment3-6c95cffb97-d2xv7: test-controller3
I0124 13:54:04.843604       1 scheduler.go:614] [GetControllerMetricInfo] Métricas do controlador definidas para o pod: default/test-deployment3-6c95cffb97-d2xv7
W0124 13:54:04.844410       1 scheduler.go:125] [cacheMiss] Métricas não encontradas para o pod: default/test-deployment3-6c95cffb97-d2xv7
I0124 13:54:04.852337       1 scheduler.go:70] Estado no Informer: map[controller:test-controller3]
I0124 13:54:04.852633       1 scheduler.go:71] Estado real no cluster: map[controller:test-controller3]
W0124 13:54:04.852992       1 scheduler.go:135] [WaitForPodsOnCache] Pod test-deployment3-6c95cffb97-d2xv7 não encontrado no cache. Tentando novamente...
I0124 13:54:04.953792       1 scheduler.go:606] [GetControllerMetricInfo] Iniciando para o pod: default/test-deployment3-6c95cffb97-d2xv7
I0124 13:54:04.954529       1 scheduler.go:611] [GetControllerMetricInfo] Obtendo o nome do controlador para o pod: default/test-deployment3-6c95cffb97-d2xv7
I0124 13:54:04.955223       1 types.go:743] [ControllerName] Verificando as anotações do pod default/test-deployment3-6c95cffb97-d2xv7
I0124 13:54:04.955339       1 types.go:761] [ControllerName] Anotação 'controller' encontrada para o pod default/test-deployment3-6c95cffb97-d2xv7: test-controller3
I0124 13:54:04.955364       1 scheduler.go:614] [GetControllerMetricInfo] Métricas do controlador definidas para o pod: default/test-deployment3-6c95cffb97-d2xv7
W0124 13:54:04.955385       1 scheduler.go:125] [cacheMiss] Métricas não encontradas para o pod: default/test-deployment3-6c95cffb97-d2xv7
I0124 13:54:04.989334       1 scheduler.go:70] Estado no Informer: map[controller:test-controller3]
I0124 13:54:04.989438       1 scheduler.go:71] Estado real no cluster: map[controller:test-controller3]
W0124 13:54:04.989460       1 scheduler.go:135] [WaitForPodsOnCache] Pod test-deployment3-6c95cffb97-d2xv7 não encontrado no cache. Tentando novamente...
I0124 13:54:05.089774       1 scheduler.go:606] [GetControllerMetricInfo] Iniciando para o pod: default/test-deployment3-6c95cffb97-d2xv7
I0124 13:54:05.089974       1 scheduler.go:611] [GetControllerMetricInfo] Obtendo o nome do controlador para o pod: default/test-deployment3-6c95cffb97-d2xv7
I0124 13:54:05.090022       1 types.go:743] [ControllerName] Verificando as anotações do pod default/test-deployment3-6c95cffb97-d2xv7
I0124 13:54:05.090040       1 types.go:761] [ControllerName] Anotação 'controller' encontrada para o pod default/test-deployment3-6c95cffb97-d2xv7: test-controller3
I0124 13:54:05.090055       1 scheduler.go:614] [GetControllerMetricInfo] Métricas do controlador definidas para o pod: default/test-deployment3-6c95cffb97-d2xv7
W0124 13:54:05.090073       1 scheduler.go:125] [cacheMiss] Métricas não encontradas para o pod: default/test-deployment3-6c95cffb97-d2xv7
I0124 13:54:05.107746       1 scheduler.go:70] Estado no Informer: map[controller:test-controller3]
I0124 13:54:05.107947       1 scheduler.go:71] Estado real no cluster: map[controller:test-controller3]
W0124 13:54:05.107971       1 scheduler.go:135] [WaitForPodsOnCache] Pod test-deployment3-6c95cffb97-d2xv7 não encontrado no cache. Tentando novamente...
I0124 13:54:05.208421       1 scheduler.go:606] [GetControllerMetricInfo] Iniciando para o pod: default/test-deployment3-6c95cffb97-d2xv7
I0124 13:54:05.208518       1 scheduler.go:611] [GetControllerMetricInfo] Obtendo o nome do controlador para o pod: default/test-deployment3-6c95cffb97-d2xv7
I0124 13:54:05.208536       1 types.go:743] [ControllerName] Verificando as anotações do pod default/test-deployment3-6c95cffb97-d2xv7
I0124 13:54:05.208552       1 types.go:761] [ControllerName] Anotação 'controller' encontrada para o pod default/test-deployment3-6c95cffb97-d2xv7: test-controller3
I0124 13:54:05.208568       1 scheduler.go:614] [GetControllerMetricInfo] Métricas do controlador definidas para o pod: default/test-deployment3-6c95cffb97-d2xv7
W0124 13:54:05.209577       1 scheduler.go:125] [cacheMiss] Métricas não encontradas para o pod: default/test-deployment3-6c95cffb97-d2xv7
I0124 13:54:05.217569       1 scheduler.go:70] Estado no Informer: map[controller:test-controller3]
I0124 13:54:05.218586       1 scheduler.go:71] Estado real no cluster: map[controller:test-controller3]
W0124 13:54:05.218953       1 scheduler.go:135] [WaitForPodsOnCache] Pod test-deployment3-6c95cffb97-d2xv7 não encontrado no cache. Tentando novamente...
I0124 13:54:05.322347       1 scheduler.go:606] [GetControllerMetricInfo] Iniciando para o pod: default/test-deployment3-6c95cffb97-d2xv7
I0124 13:54:05.322471       1 scheduler.go:611] [GetControllerMetricInfo] Obtendo o nome do controlador para o pod: default/test-deployment3-6c95cffb97-d2xv7
I0124 13:54:05.322488       1 types.go:743] [ControllerName] Verificando as anotações do pod default/test-deployment3-6c95cffb97-d2xv7
I0124 13:54:05.322502       1 types.go:761] [ControllerName] Anotação 'controller' encontrada para o pod default/test-deployment3-6c95cffb97-d2xv7: test-controller3
I0124 13:54:05.322574       1 scheduler.go:614] [GetControllerMetricInfo] Métricas do controlador definidas para o pod: default/test-deployment3-6c95cffb97-d2xv7
W0124 13:54:05.322594       1 scheduler.go:125] [cacheMiss] Métricas não encontradas para o pod: default/test-deployment3-6c95cffb97-d2xv7
I0124 13:54:05.344598       1 scheduler.go:70] Estado no Informer: map[controller:test-controller3]
I0124 13:54:05.348630       1 scheduler.go:71] Estado real no cluster: map[controller:test-controller3]
W0124 13:54:05.348813       1 scheduler.go:135] [WaitForPodsOnCache] Pod test-deployment3-6c95cffb97-d2xv7 não encontrado no cache. Tentando novamente...
I0124 13:54:05.449819       1 scheduler.go:606] [GetControllerMetricInfo] Iniciando para o pod: default/test-deployment3-6c95cffb97-d2xv7
I0124 13:54:05.450235       1 scheduler.go:611] [GetControllerMetricInfo] Obtendo o nome do controlador para o pod: default/test-deployment3-6c95cffb97-d2xv7
I0124 13:54:05.450491       1 types.go:743] [ControllerName] Verificando as anotações do pod default/test-deployment3-6c95cffb97-d2xv7
I0124 13:54:05.450957       1 types.go:761] [ControllerName] Anotação 'controller' encontrada para o pod default/test-deployment3-6c95cffb97-d2xv7: test-controller3
I0124 13:54:05.451142       1 scheduler.go:614] [GetControllerMetricInfo] Métricas do controlador definidas para o pod: default/test-deployment3-6c95cffb97-d2xv7
W0124 13:54:05.451402       1 scheduler.go:125] [cacheMiss] Métricas não encontradas para o pod: default/test-deployment3-6c95cffb97-d2xv7
I0124 13:54:05.460989       1 scheduler.go:70] Estado no Informer: map[controller:test-controller3]
I0124 13:54:05.461335       1 scheduler.go:71] Estado real no cluster: map[controller:test-controller3]
W0124 13:54:05.461359       1 scheduler.go:135] [WaitForPodsOnCache] Pod test-deployment3-6c95cffb97-d2xv7 não encontrado no cache. Tentando novamente...
I0124 13:54:05.562118       1 scheduler.go:606] [GetControllerMetricInfo] Iniciando para o pod: default/test-deployment3-6c95cffb97-d2xv7
I0124 13:54:05.562485       1 scheduler.go:611] [GetControllerMetricInfo] Obtendo o nome do controlador para o pod: default/test-deployment3-6c95cffb97-d2xv7
I0124 13:54:05.562631       1 types.go:743] [ControllerName] Verificando as anotações do pod default/test-deployment3-6c95cffb97-d2xv7
I0124 13:54:05.562718       1 types.go:761] [ControllerName] Anotação 'controller' encontrada para o pod default/test-deployment3-6c95cffb97-d2xv7: test-controller3
I0124 13:54:05.562745       1 scheduler.go:614] [GetControllerMetricInfo] Métricas do controlador definidas para o pod: default/test-deployment3-6c95cffb97-d2xv7
W0124 13:54:05.562944       1 scheduler.go:125] [cacheMiss] Métricas não encontradas para o pod: default/test-deployment3-6c95cffb97-d2xv7
I0124 13:54:05.571291       1 scheduler.go:70] Estado no Informer: map[controller:test-controller3]
I0124 13:54:05.571489       1 scheduler.go:71] Estado real no cluster: map[controller:test-controller3]
W0124 13:54:05.571602       1 scheduler.go:135] [WaitForPodsOnCache] Pod test-deployment3-6c95cffb97-d2xv7 não encontrado no cache. Tentando novamente...
I0124 13:54:05.671819       1 scheduler.go:606] [GetControllerMetricInfo] Iniciando para o pod: default/test-deployment3-6c95cffb97-d2xv7
I0124 13:54:05.671912       1 scheduler.go:611] [GetControllerMetricInfo] Obtendo o nome do controlador para o pod: default/test-deployment3-6c95cffb97-d2xv7
I0124 13:54:05.671923       1 types.go:743] [ControllerName] Verificando as anotações do pod default/test-deployment3-6c95cffb97-d2xv7
I0124 13:54:05.671933       1 types.go:761] [ControllerName] Anotação 'controller' encontrada para o pod default/test-deployment3-6c95cffb97-d2xv7: test-controller3
I0124 13:54:05.671942       1 scheduler.go:614] [GetControllerMetricInfo] Métricas do controlador definidas para o pod: default/test-deployment3-6c95cffb97-d2xv7
W0124 13:54:05.671954       1 scheduler.go:125] [cacheMiss] Métricas não encontradas para o pod: default/test-deployment3-6c95cffb97-d2xv7
I0124 13:54:05.679124       1 scheduler.go:70] Estado no Informer: map[controller:test-controller3]
I0124 13:54:05.679597       1 scheduler.go:71] Estado real no cluster: map[controller:test-controller3]
W0124 13:54:05.679952       1 scheduler.go:135] [WaitForPodsOnCache] Pod test-deployment3-6c95cffb97-d2xv7 não encontrado no cache. Tentando novamente...
I0124 13:54:05.781276       1 scheduler.go:606] [GetControllerMetricInfo] Iniciando para o pod: default/test-deployment3-6c95cffb97-d2xv7
I0124 13:54:05.781751       1 scheduler.go:611] [GetControllerMetricInfo] Obtendo o nome do controlador para o pod: default/test-deployment3-6c95cffb97-d2xv7
I0124 13:54:05.782057       1 types.go:743] [ControllerName] Verificando as anotações do pod default/test-deployment3-6c95cffb97-d2xv7
I0124 13:54:05.782269       1 types.go:761] [ControllerName] Anotação 'controller' encontrada para o pod default/test-deployment3-6c95cffb97-d2xv7: test-controller3
I0124 13:54:05.782544       1 scheduler.go:614] [GetControllerMetricInfo] Métricas do controlador definidas para o pod: default/test-deployment3-6c95cffb97-d2xv7
W0124 13:54:05.782975       1 scheduler.go:125] [cacheMiss] Métricas não encontradas para o pod: default/test-deployment3-6c95cffb97-d2xv7
I0124 13:54:05.787744       1 scheduler.go:70] Estado no Informer: map[controller:test-controller3]
I0124 13:54:05.788307       1 scheduler.go:71] Estado real no cluster: map[controller:test-controller3]
W0124 13:54:05.789245       1 scheduler.go:135] [WaitForPodsOnCache] Pod test-deployment3-6c95cffb97-d2xv7 não encontrado no cache. Tentando novamente...
I0124 13:54:05.891402       1 scheduler.go:606] [GetControllerMetricInfo] Iniciando para o pod: default/test-deployment3-6c95cffb97-d2xv7
I0124 13:54:05.891455       1 scheduler.go:611] [GetControllerMetricInfo] Obtendo o nome do controlador para o pod: default/test-deployment3-6c95cffb97-d2xv7
I0124 13:54:05.891470       1 types.go:743] [ControllerName] Verificando as anotações do pod default/test-deployment3-6c95cffb97-d2xv7
I0124 13:54:05.891489       1 types.go:761] [ControllerName] Anotação 'controller' encontrada para o pod default/test-deployment3-6c95cffb97-d2xv7: test-controller3
I0124 13:54:05.891504       1 scheduler.go:614] [GetControllerMetricInfo] Métricas do controlador definidas para o pod: default/test-deployment3-6c95cffb97-d2xv7
W0124 13:54:05.891614       1 scheduler.go:125] [cacheMiss] Métricas não encontradas para o pod: default/test-deployment3-6c95cffb97-d2xv7
I0124 13:54:05.901260       1 scheduler.go:70] Estado no Informer: map[controller:test-controller3]
I0124 13:54:05.901495       1 scheduler.go:71] Estado real no cluster: map[controller:test-controller3]
W0124 13:54:05.901545       1 scheduler.go:135] [WaitForPodsOnCache] Pod test-deployment3-6c95cffb97-d2xv7 não encontrado no cache. Tentando novamente...
I0124 13:54:06.002448       1 scheduler.go:606] [GetControllerMetricInfo] Iniciando para o pod: default/test-deployment3-6c95cffb97-d2xv7
I0124 13:54:06.002703       1 scheduler.go:611] [GetControllerMetricInfo] Obtendo o nome do controlador para o pod: default/test-deployment3-6c95cffb97-d2xv7
I0124 13:54:06.003023       1 types.go:743] [ControllerName] Verificando as anotações do pod default/test-deployment3-6c95cffb97-d2xv7
I0124 13:54:06.003602       1 types.go:761] [ControllerName] Anotação 'controller' encontrada para o pod default/test-deployment3-6c95cffb97-d2xv7: test-controller3
I0124 13:54:06.003828       1 scheduler.go:614] [GetControllerMetricInfo] Métricas do controlador definidas para o pod: default/test-deployment3-6c95cffb97-d2xv7
W0124 13:54:06.004381       1 scheduler.go:125] [cacheMiss] Métricas não encontradas para o pod: default/test-deployment3-6c95cffb97-d2xv7
I0124 13:54:06.022813       1 scheduler.go:70] Estado no Informer: map[controller:test-controller3]
I0124 13:54:06.023177       1 scheduler.go:71] Estado real no cluster: map[controller:test-controller3]
W0124 13:54:06.023355       1 scheduler.go:135] [WaitForPodsOnCache] Pod test-deployment3-6c95cffb97-d2xv7 não encontrado no cache. Tentando novamente...
I0124 13:54:06.124448       1 scheduler.go:606] [GetControllerMetricInfo] Iniciando para o pod: default/test-deployment3-6c95cffb97-d2xv7
I0124 13:54:06.124501       1 scheduler.go:611] [GetControllerMetricInfo] Obtendo o nome do controlador para o pod: default/test-deployment3-6c95cffb97-d2xv7
I0124 13:54:06.124516       1 types.go:743] [ControllerName] Verificando as anotações do pod default/test-deployment3-6c95cffb97-d2xv7
I0124 13:54:06.124533       1 types.go:761] [ControllerName] Anotação 'controller' encontrada para o pod default/test-deployment3-6c95cffb97-d2xv7: test-controller3
I0124 13:54:06.124548       1 scheduler.go:614] [GetControllerMetricInfo] Métricas do controlador definidas para o pod: default/test-deployment3-6c95cffb97-d2xv7
W0124 13:54:06.125472       1 scheduler.go:125] [cacheMiss] Métricas não encontradas para o pod: default/test-deployment3-6c95cffb97-d2xv7
I0124 13:54:06.131836       1 scheduler.go:70] Estado no Informer: map[controller:test-controller3]
I0124 13:54:06.132243       1 scheduler.go:71] Estado real no cluster: map[controller:test-controller3]
W0124 13:54:06.132295       1 scheduler.go:135] [WaitForPodsOnCache] Pod test-deployment3-6c95cffb97-d2xv7 não encontrado no cache. Tentando novamente...
I0124 13:54:06.232972       1 scheduler.go:606] [GetControllerMetricInfo] Iniciando para o pod: default/test-deployment3-6c95cffb97-d2xv7
I0124 13:54:06.233159       1 scheduler.go:611] [GetControllerMetricInfo] Obtendo o nome do controlador para o pod: default/test-deployment3-6c95cffb97-d2xv7
I0124 13:54:06.233242       1 types.go:743] [ControllerName] Verificando as anotações do pod default/test-deployment3-6c95cffb97-d2xv7
I0124 13:54:06.233284       1 types.go:761] [ControllerName] Anotação 'controller' encontrada para o pod default/test-deployment3-6c95cffb97-d2xv7: test-controller3
I0124 13:54:06.233319       1 scheduler.go:614] [GetControllerMetricInfo] Métricas do controlador definidas para o pod: default/test-deployment3-6c95cffb97-d2xv7
W0124 13:54:06.233340       1 scheduler.go:125] [cacheMiss] Métricas não encontradas para o pod: default/test-deployment3-6c95cffb97-d2xv7
I0124 13:54:06.240032       1 scheduler.go:70] Estado no Informer: map[controller:test-controller3]
I0124 13:54:06.240204       1 scheduler.go:71] Estado real no cluster: map[controller:test-controller3]
W0124 13:54:06.240229       1 scheduler.go:135] [WaitForPodsOnCache] Pod test-deployment3-6c95cffb97-d2xv7 não encontrado no cache. Tentando novamente...
I0124 13:54:06.341113       1 scheduler.go:606] [GetControllerMetricInfo] Iniciando para o pod: default/test-deployment3-6c95cffb97-d2xv7
I0124 13:54:06.341505       1 scheduler.go:611] [GetControllerMetricInfo] Obtendo o nome do controlador para o pod: default/test-deployment3-6c95cffb97-d2xv7
I0124 13:54:06.341732       1 types.go:743] [ControllerName] Verificando as anotações do pod default/test-deployment3-6c95cffb97-d2xv7
I0124 13:54:06.342116       1 types.go:761] [ControllerName] Anotação 'controller' encontrada para o pod default/test-deployment3-6c95cffb97-d2xv7: test-controller3
I0124 13:54:06.342214       1 scheduler.go:614] [GetControllerMetricInfo] Métricas do controlador definidas para o pod: default/test-deployment3-6c95cffb97-d2xv7
W0124 13:54:06.342543       1 scheduler.go:125] [cacheMiss] Métricas não encontradas para o pod: default/test-deployment3-6c95cffb97-d2xv7
I0124 13:54:06.358130       1 scheduler.go:70] Estado no Informer: map[controller:test-controller3]
I0124 13:54:06.358181       1 scheduler.go:71] Estado real no cluster: map[controller:test-controller3]
W0124 13:54:06.358199       1 scheduler.go:135] [WaitForPodsOnCache] Pod test-deployment3-6c95cffb97-d2xv7 não encontrado no cache. Tentando novamente...
I0124 13:54:06.458732       1 scheduler.go:606] [GetControllerMetricInfo] Iniciando para o pod: default/test-deployment3-6c95cffb97-d2xv7
I0124 13:54:06.459102       1 scheduler.go:611] [GetControllerMetricInfo] Obtendo o nome do controlador para o pod: default/test-deployment3-6c95cffb97-d2xv7
I0124 13:54:06.459150       1 types.go:743] [ControllerName] Verificando as anotações do pod default/test-deployment3-6c95cffb97-d2xv7
I0124 13:54:06.459191       1 types.go:761] [ControllerName] Anotação 'controller' encontrada para o pod default/test-deployment3-6c95cffb97-d2xv7: test-controller3
I0124 13:54:06.459231       1 scheduler.go:614] [GetControllerMetricInfo] Métricas do controlador definidas para o pod: default/test-deployment3-6c95cffb97-d2xv7
W0124 13:54:06.459276       1 scheduler.go:125] [cacheMiss] Métricas não encontradas para o pod: default/test-deployment3-6c95cffb97-d2xv7
I0124 13:54:06.466610       1 scheduler.go:70] Estado no Informer: map[controller:test-controller3]
I0124 13:54:06.466787       1 scheduler.go:71] Estado real no cluster: map[controller:test-controller3]
W0124 13:54:06.466810       1 scheduler.go:135] [WaitForPodsOnCache] Pod test-deployment3-6c95cffb97-d2xv7 não encontrado no cache. Tentando novamente...
I0124 13:54:06.567588       1 scheduler.go:606] [GetControllerMetricInfo] Iniciando para o pod: default/test-deployment3-6c95cffb97-d2xv7
I0124 13:54:06.567718       1 scheduler.go:611] [GetControllerMetricInfo] Obtendo o nome do controlador para o pod: default/test-deployment3-6c95cffb97-d2xv7
I0124 13:54:06.567738       1 types.go:743] [ControllerName] Verificando as anotações do pod default/test-deployment3-6c95cffb97-d2xv7
I0124 13:54:06.567755       1 types.go:761] [ControllerName] Anotação 'controller' encontrada para o pod default/test-deployment3-6c95cffb97-d2xv7: test-controller3
I0124 13:54:06.567771       1 scheduler.go:614] [GetControllerMetricInfo] Métricas do controlador definidas para o pod: default/test-deployment3-6c95cffb97-d2xv7
W0124 13:54:06.567834       1 scheduler.go:125] [cacheMiss] Métricas não encontradas para o pod: default/test-deployment3-6c95cffb97-d2xv7
I0124 13:54:06.593761       1 scheduler.go:70] Estado no Informer: map[controller:test-controller3]
I0124 13:54:06.594839       1 scheduler.go:71] Estado real no cluster: map[controller:test-controller3]
W0124 13:54:06.595104       1 scheduler.go:135] [WaitForPodsOnCache] Pod test-deployment3-6c95cffb97-d2xv7 não encontrado no cache. Tentando novamente...
I0124 13:54:06.696231       1 scheduler.go:606] [GetControllerMetricInfo] Iniciando para o pod: default/test-deployment3-6c95cffb97-d2xv7
I0124 13:54:06.696479       1 scheduler.go:611] [GetControllerMetricInfo] Obtendo o nome do controlador para o pod: default/test-deployment3-6c95cffb97-d2xv7
I0124 13:54:06.696526       1 types.go:743] [ControllerName] Verificando as anotações do pod default/test-deployment3-6c95cffb97-d2xv7
I0124 13:54:06.696631       1 types.go:761] [ControllerName] Anotação 'controller' encontrada para o pod default/test-deployment3-6c95cffb97-d2xv7: test-controller3
I0124 13:54:06.697039       1 scheduler.go:614] [GetControllerMetricInfo] Métricas do controlador definidas para o pod: default/test-deployment3-6c95cffb97-d2xv7
W0124 13:54:06.697308       1 scheduler.go:125] [cacheMiss] Métricas não encontradas para o pod: default/test-deployment3-6c95cffb97-d2xv7
I0124 13:54:06.704561       1 scheduler.go:70] Estado no Informer: map[controller:test-controller3]
I0124 13:54:06.704667       1 scheduler.go:71] Estado real no cluster: map[controller:test-controller3]
W0124 13:54:06.704689       1 scheduler.go:135] [WaitForPodsOnCache] Pod test-deployment3-6c95cffb97-d2xv7 não encontrado no cache. Tentando novamente...
I0124 13:54:06.805981       1 scheduler.go:606] [GetControllerMetricInfo] Iniciando para o pod: default/test-deployment3-6c95cffb97-d2xv7
I0124 13:54:06.806026       1 scheduler.go:611] [GetControllerMetricInfo] Obtendo o nome do controlador para o pod: default/test-deployment3-6c95cffb97-d2xv7
I0124 13:54:06.806039       1 types.go:743] [ControllerName] Verificando as anotações do pod default/test-deployment3-6c95cffb97-d2xv7
I0124 13:54:06.806055       1 types.go:761] [ControllerName] Anotação 'controller' encontrada para o pod default/test-deployment3-6c95cffb97-d2xv7: test-controller3
I0124 13:54:06.806071       1 scheduler.go:614] [GetControllerMetricInfo] Métricas do controlador definidas para o pod: default/test-deployment3-6c95cffb97-d2xv7
W0124 13:54:06.806092       1 scheduler.go:125] [cacheMiss] Métricas não encontradas para o pod: default/test-deployment3-6c95cffb97-d2xv7
I0124 13:54:06.818668       1 scheduler.go:70] Estado no Informer: map[controller:test-controller3]
I0124 13:54:06.819221       1 scheduler.go:71] Estado real no cluster: map[controller:test-controller3]
W0124 13:54:06.819971       1 scheduler.go:135] [WaitForPodsOnCache] Pod test-deployment3-6c95cffb97-d2xv7 não encontrado no cache. Tentando novamente...
I0124 13:54:06.921250       1 scheduler.go:606] [GetControllerMetricInfo] Iniciando para o pod: default/test-deployment3-6c95cffb97-d2xv7
I0124 13:54:06.921446       1 scheduler.go:611] [GetControllerMetricInfo] Obtendo o nome do controlador para o pod: default/test-deployment3-6c95cffb97-d2xv7
I0124 13:54:06.922001       1 types.go:743] [ControllerName] Verificando as anotações do pod default/test-deployment3-6c95cffb97-d2xv7
I0124 13:54:06.922484       1 types.go:761] [ControllerName] Anotação 'controller' encontrada para o pod default/test-deployment3-6c95cffb97-d2xv7: test-controller3
I0124 13:54:06.922826       1 scheduler.go:614] [GetControllerMetricInfo] Métricas do controlador definidas para o pod: default/test-deployment3-6c95cffb97-d2xv7
W0124 13:54:06.923251       1 scheduler.go:125] [cacheMiss] Métricas não encontradas para o pod: default/test-deployment3-6c95cffb97-d2xv7
I0124 13:54:06.931042       1 scheduler.go:70] Estado no Informer: map[controller:test-controller3]
I0124 13:54:06.931086       1 scheduler.go:71] Estado real no cluster: map[controller:test-controller3]
W0124 13:54:06.931102       1 scheduler.go:135] [WaitForPodsOnCache] Pod test-deployment3-6c95cffb97-d2xv7 não encontrado no cache. Tentando novamente...
I0124 13:54:07.031832       1 scheduler.go:606] [GetControllerMetricInfo] Iniciando para o pod: default/test-deployment3-6c95cffb97-d2xv7
I0124 13:54:07.032320       1 scheduler.go:611] [GetControllerMetricInfo] Obtendo o nome do controlador para o pod: default/test-deployment3-6c95cffb97-d2xv7
I0124 13:54:07.032486       1 types.go:743] [ControllerName] Verificando as anotações do pod default/test-deployment3-6c95cffb97-d2xv7
I0124 13:54:07.032698       1 types.go:761] [ControllerName] Anotação 'controller' encontrada para o pod default/test-deployment3-6c95cffb97-d2xv7: test-controller3
I0124 13:54:07.032802       1 scheduler.go:614] [GetControllerMetricInfo] Métricas do controlador definidas para o pod: default/test-deployment3-6c95cffb97-d2xv7
W0124 13:54:07.033023       1 scheduler.go:125] [cacheMiss] Métricas não encontradas para o pod: default/test-deployment3-6c95cffb97-d2xv7
I0124 13:54:07.048060       1 scheduler.go:70] Estado no Informer: map[controller:test-controller3]
I0124 13:54:07.048240       1 scheduler.go:71] Estado real no cluster: map[controller:test-controller3]
W0124 13:54:07.048503       1 scheduler.go:135] [WaitForPodsOnCache] Pod test-deployment3-6c95cffb97-d2xv7 não encontrado no cache. Tentando novamente...
I0124 13:54:07.149014       1 scheduler.go:606] [GetControllerMetricInfo] Iniciando para o pod: default/test-deployment3-6c95cffb97-d2xv7
I0124 13:54:07.149337       1 scheduler.go:611] [GetControllerMetricInfo] Obtendo o nome do controlador para o pod: default/test-deployment3-6c95cffb97-d2xv7
I0124 13:54:07.149487       1 types.go:743] [ControllerName] Verificando as anotações do pod default/test-deployment3-6c95cffb97-d2xv7
I0124 13:54:07.149586       1 types.go:761] [ControllerName] Anotação 'controller' encontrada para o pod default/test-deployment3-6c95cffb97-d2xv7: test-controller3
I0124 13:54:07.149776       1 scheduler.go:614] [GetControllerMetricInfo] Métricas do controlador definidas para o pod: default/test-deployment3-6c95cffb97-d2xv7
W0124 13:54:07.149833       1 scheduler.go:125] [cacheMiss] Métricas não encontradas para o pod: default/test-deployment3-6c95cffb97-d2xv7
I0124 13:54:07.158685       1 scheduler.go:70] Estado no Informer: map[controller:test-controller3]
I0124 13:54:07.159605       1 scheduler.go:71] Estado real no cluster: map[controller:test-controller3]
W0124 13:54:07.160475       1 scheduler.go:135] [WaitForPodsOnCache] Pod test-deployment3-6c95cffb97-d2xv7 não encontrado no cache. Tentando novamente...
I0124 13:54:07.261658       1 scheduler.go:606] [GetControllerMetricInfo] Iniciando para o pod: default/test-deployment3-6c95cffb97-d2xv7
I0124 13:54:07.262438       1 scheduler.go:611] [GetControllerMetricInfo] Obtendo o nome do controlador para o pod: default/test-deployment3-6c95cffb97-d2xv7
I0124 13:54:07.263013       1 types.go:743] [ControllerName] Verificando as anotações do pod default/test-deployment3-6c95cffb97-d2xv7
I0124 13:54:07.263511       1 types.go:761] [ControllerName] Anotação 'controller' encontrada para o pod default/test-deployment3-6c95cffb97-d2xv7: test-controller3
I0124 13:54:07.264013       1 scheduler.go:614] [GetControllerMetricInfo] Métricas do controlador definidas para o pod: default/test-deployment3-6c95cffb97-d2xv7
W0124 13:54:07.264547       1 scheduler.go:125] [cacheMiss] Métricas não encontradas para o pod: default/test-deployment3-6c95cffb97-d2xv7
I0124 13:54:07.277226       1 scheduler.go:70] Estado no Informer: map[controller:test-controller3]
I0124 13:54:07.277603       1 scheduler.go:71] Estado real no cluster: map[controller:test-controller3]
W0124 13:54:07.277752       1 scheduler.go:135] [WaitForPodsOnCache] Pod test-deployment3-6c95cffb97-d2xv7 não encontrado no cache. Tentando novamente...
I0124 13:54:07.378518       1 scheduler.go:606] [GetControllerMetricInfo] Iniciando para o pod: default/test-deployment3-6c95cffb97-d2xv7
I0124 13:54:07.378626       1 scheduler.go:611] [GetControllerMetricInfo] Obtendo o nome do controlador para o pod: default/test-deployment3-6c95cffb97-d2xv7
I0124 13:54:07.378643       1 types.go:743] [ControllerName] Verificando as anotações do pod default/test-deployment3-6c95cffb97-d2xv7
I0124 13:54:07.378662       1 types.go:761] [ControllerName] Anotação 'controller' encontrada para o pod default/test-deployment3-6c95cffb97-d2xv7: test-controller3
I0124 13:54:07.378679       1 scheduler.go:614] [GetControllerMetricInfo] Métricas do controlador definidas para o pod: default/test-deployment3-6c95cffb97-d2xv7
W0124 13:54:07.378700       1 scheduler.go:125] [cacheMiss] Métricas não encontradas para o pod: default/test-deployment3-6c95cffb97-d2xv7
I0124 13:54:07.392818       1 scheduler.go:70] Estado no Informer: map[controller:test-controller3]
I0124 13:54:07.393247       1 scheduler.go:71] Estado real no cluster: map[controller:test-controller3]
W0124 13:54:07.393811       1 scheduler.go:135] [WaitForPodsOnCache] Pod test-deployment3-6c95cffb97-d2xv7 não encontrado no cache. Tentando novamente...
I0124 13:54:07.495423       1 scheduler.go:606] [GetControllerMetricInfo] Iniciando para o pod: default/test-deployment3-6c95cffb97-d2xv7
I0124 13:54:07.495534       1 scheduler.go:611] [GetControllerMetricInfo] Obtendo o nome do controlador para o pod: default/test-deployment3-6c95cffb97-d2xv7
I0124 13:54:07.496438       1 types.go:743] [ControllerName] Verificando as anotações do pod default/test-deployment3-6c95cffb97-d2xv7
I0124 13:54:07.496807       1 types.go:761] [ControllerName] Anotação 'controller' encontrada para o pod default/test-deployment3-6c95cffb97-d2xv7: test-controller3
I0124 13:54:07.497052       1 scheduler.go:614] [GetControllerMetricInfo] Métricas do controlador definidas para o pod: default/test-deployment3-6c95cffb97-d2xv7
W0124 13:54:07.497341       1 scheduler.go:125] [cacheMiss] Métricas não encontradas para o pod: default/test-deployment3-6c95cffb97-d2xv7
I0124 13:54:07.505308       1 scheduler.go:70] Estado no Informer: map[controller:test-controller3]
I0124 13:54:07.505730       1 scheduler.go:71] Estado real no cluster: map[controller:test-controller3]
W0124 13:54:07.506480       1 scheduler.go:135] [WaitForPodsOnCache] Pod test-deployment3-6c95cffb97-d2xv7 não encontrado no cache. Tentando novamente...
I0124 13:54:07.607009       1 scheduler.go:606] [GetControllerMetricInfo] Iniciando para o pod: default/test-deployment3-6c95cffb97-d2xv7
I0124 13:54:07.607291       1 scheduler.go:611] [GetControllerMetricInfo] Obtendo o nome do controlador para o pod: default/test-deployment3-6c95cffb97-d2xv7
I0124 13:54:07.607528       1 types.go:743] [ControllerName] Verificando as anotações do pod default/test-deployment3-6c95cffb97-d2xv7
I0124 13:54:07.608258       1 types.go:761] [ControllerName] Anotação 'controller' encontrada para o pod default/test-deployment3-6c95cffb97-d2xv7: test-controller3
I0124 13:54:07.608737       1 scheduler.go:614] [GetControllerMetricInfo] Métricas do controlador definidas para o pod: default/test-deployment3-6c95cffb97-d2xv7
W0124 13:54:07.609661       1 scheduler.go:125] [cacheMiss] Métricas não encontradas para o pod: default/test-deployment3-6c95cffb97-d2xv7
I0124 13:54:07.620068       1 scheduler.go:70] Estado no Informer: map[controller:test-controller3]
I0124 13:54:07.620834       1 scheduler.go:71] Estado real no cluster: map[controller:test-controller3]
W0124 13:54:07.621309       1 scheduler.go:135] [WaitForPodsOnCache] Pod test-deployment3-6c95cffb97-d2xv7 não encontrado no cache. Tentando novamente...
I0124 13:54:07.722576       1 scheduler.go:606] [GetControllerMetricInfo] Iniciando para o pod: default/test-deployment3-6c95cffb97-d2xv7
I0124 13:54:07.722663       1 scheduler.go:611] [GetControllerMetricInfo] Obtendo o nome do controlador para o pod: default/test-deployment3-6c95cffb97-d2xv7
I0124 13:54:07.722679       1 types.go:743] [ControllerName] Verificando as anotações do pod default/test-deployment3-6c95cffb97-d2xv7
I0124 13:54:07.722695       1 types.go:761] [ControllerName] Anotação 'controller' encontrada para o pod default/test-deployment3-6c95cffb97-d2xv7: test-controller3
I0124 13:54:07.722712       1 scheduler.go:614] [GetControllerMetricInfo] Métricas do controlador definidas para o pod: default/test-deployment3-6c95cffb97-d2xv7
W0124 13:54:07.722732       1 scheduler.go:125] [cacheMiss] Métricas não encontradas para o pod: default/test-deployment3-6c95cffb97-d2xv7
I0124 13:54:07.730833       1 scheduler.go:70] Estado no Informer: map[controller:test-controller3]
I0124 13:54:07.731272       1 scheduler.go:71] Estado real no cluster: map[controller:test-controller3]
W0124 13:54:07.731697       1 scheduler.go:135] [WaitForPodsOnCache] Pod test-deployment3-6c95cffb97-d2xv7 não encontrado no cache. Tentando novamente...
I0124 13:54:07.833789       1 scheduler.go:606] [GetControllerMetricInfo] Iniciando para o pod: default/test-deployment3-6c95cffb97-d2xv7
I0124 13:54:07.834744       1 scheduler.go:611] [GetControllerMetricInfo] Obtendo o nome do controlador para o pod: default/test-deployment3-6c95cffb97-d2xv7
I0124 13:54:07.835523       1 types.go:743] [ControllerName] Verificando as anotações do pod default/test-deployment3-6c95cffb97-d2xv7
I0124 13:54:07.835547       1 types.go:761] [ControllerName] Anotação 'controller' encontrada para o pod default/test-deployment3-6c95cffb97-d2xv7: test-controller3
I0124 13:54:07.835564       1 scheduler.go:614] [GetControllerMetricInfo] Métricas do controlador definidas para o pod: default/test-deployment3-6c95cffb97-d2xv7
W0124 13:54:07.836005       1 scheduler.go:125] [cacheMiss] Métricas não encontradas para o pod: default/test-deployment3-6c95cffb97-d2xv7
I0124 13:54:07.844289       1 scheduler.go:70] Estado no Informer: map[controller:test-controller3]
I0124 13:54:07.844389       1 scheduler.go:71] Estado real no cluster: map[controller:test-controller3]
W0124 13:54:07.844410       1 scheduler.go:135] [WaitForPodsOnCache] Pod test-deployment3-6c95cffb97-d2xv7 não encontrado no cache. Tentando novamente...
I0124 13:54:07.944560       1 scheduler.go:606] [GetControllerMetricInfo] Iniciando para o pod: default/test-deployment3-6c95cffb97-d2xv7
I0124 13:54:07.945243       1 scheduler.go:611] [GetControllerMetricInfo] Obtendo o nome do controlador para o pod: default/test-deployment3-6c95cffb97-d2xv7
I0124 13:54:07.945586       1 types.go:743] [ControllerName] Verificando as anotações do pod default/test-deployment3-6c95cffb97-d2xv7
I0124 13:54:07.946137       1 types.go:761] [ControllerName] Anotação 'controller' encontrada para o pod default/test-deployment3-6c95cffb97-d2xv7: test-controller3
I0124 13:54:07.946566       1 scheduler.go:614] [GetControllerMetricInfo] Métricas do controlador definidas para o pod: default/test-deployment3-6c95cffb97-d2xv7
W0124 13:54:07.947254       1 scheduler.go:125] [cacheMiss] Métricas não encontradas para o pod: default/test-deployment3-6c95cffb97-d2xv7
I0124 13:54:07.953089       1 scheduler.go:70] Estado no Informer: map[controller:test-controller3]
I0124 13:54:07.953566       1 scheduler.go:71] Estado real no cluster: map[controller:test-controller3]
W0124 13:54:07.953809       1 scheduler.go:135] [WaitForPodsOnCache] Pod test-deployment3-6c95cffb97-d2xv7 não encontrado no cache. Tentando novamente...
I0124 13:54:08.069696       1 scheduler.go:606] [GetControllerMetricInfo] Iniciando para o pod: default/test-deployment3-6c95cffb97-d2xv7
I0124 13:54:08.070822       1 scheduler.go:611] [GetControllerMetricInfo] Obtendo o nome do controlador para o pod: default/test-deployment3-6c95cffb97-d2xv7
I0124 13:54:08.075119       1 types.go:743] [ControllerName] Verificando as anotações do pod default/test-deployment3-6c95cffb97-d2xv7
I0124 13:54:08.075316       1 types.go:761] [ControllerName] Anotação 'controller' encontrada para o pod default/test-deployment3-6c95cffb97-d2xv7: test-controller3
I0124 13:54:08.075335       1 scheduler.go:614] [GetControllerMetricInfo] Métricas do controlador definidas para o pod: default/test-deployment3-6c95cffb97-d2xv7
W0124 13:54:08.075352       1 scheduler.go:125] [cacheMiss] Métricas não encontradas para o pod: default/test-deployment3-6c95cffb97-d2xv7
I0124 13:54:08.088231       1 scheduler.go:70] Estado no Informer: map[controller:test-controller3]
I0124 13:54:08.088370       1 scheduler.go:71] Estado real no cluster: map[controller:test-controller3]
W0124 13:54:08.092919       1 scheduler.go:135] [WaitForPodsOnCache] Pod test-deployment3-6c95cffb97-d2xv7 não encontrado no cache. Tentando novamente...
I0124 13:54:08.194566       1 scheduler.go:606] [GetControllerMetricInfo] Iniciando para o pod: default/test-deployment3-6c95cffb97-d2xv7
I0124 13:54:08.194968       1 scheduler.go:611] [GetControllerMetricInfo] Obtendo o nome do controlador para o pod: default/test-deployment3-6c95cffb97-d2xv7
I0124 13:54:08.194987       1 types.go:743] [ControllerName] Verificando as anotações do pod default/test-deployment3-6c95cffb97-d2xv7
I0124 13:54:08.195006       1 types.go:761] [ControllerName] Anotação 'controller' encontrada para o pod default/test-deployment3-6c95cffb97-d2xv7: test-controller3
I0124 13:54:08.195023       1 scheduler.go:614] [GetControllerMetricInfo] Métricas do controlador definidas para o pod: default/test-deployment3-6c95cffb97-d2xv7
W0124 13:54:08.195047       1 scheduler.go:125] [cacheMiss] Métricas não encontradas para o pod: default/test-deployment3-6c95cffb97-d2xv7
I0124 13:54:08.205504       1 scheduler.go:70] Estado no Informer: map[controller:test-controller3]
I0124 13:54:08.206098       1 scheduler.go:71] Estado real no cluster: map[controller:test-controller3]
W0124 13:54:08.206223       1 scheduler.go:135] [WaitForPodsOnCache] Pod test-deployment3-6c95cffb97-d2xv7 não encontrado no cache. Tentando novamente...
I0124 13:54:08.307366       1 scheduler.go:606] [GetControllerMetricInfo] Iniciando para o pod: default/test-deployment3-6c95cffb97-d2xv7
I0124 13:54:08.307765       1 scheduler.go:611] [GetControllerMetricInfo] Obtendo o nome do controlador para o pod: default/test-deployment3-6c95cffb97-d2xv7
I0124 13:54:08.307778       1 types.go:743] [ControllerName] Verificando as anotações do pod default/test-deployment3-6c95cffb97-d2xv7
I0124 13:54:08.307790       1 types.go:761] [ControllerName] Anotação 'controller' encontrada para o pod default/test-deployment3-6c95cffb97-d2xv7: test-controller3
I0124 13:54:08.308264       1 scheduler.go:614] [GetControllerMetricInfo] Métricas do controlador definidas para o pod: default/test-deployment3-6c95cffb97-d2xv7
W0124 13:54:08.308406       1 scheduler.go:125] [cacheMiss] Métricas não encontradas para o pod: default/test-deployment3-6c95cffb97-d2xv7
I0124 13:54:08.336275       1 scheduler.go:70] Estado no Informer: map[controller:test-controller3]
I0124 13:54:08.336338       1 scheduler.go:71] Estado real no cluster: map[controller:test-controller3]
W0124 13:54:08.336348       1 scheduler.go:135] [WaitForPodsOnCache] Pod test-deployment3-6c95cffb97-d2xv7 não encontrado no cache. Tentando novamente...
I0124 13:54:08.437161       1 scheduler.go:606] [GetControllerMetricInfo] Iniciando para o pod: default/test-deployment3-6c95cffb97-d2xv7
I0124 13:54:08.437286       1 scheduler.go:611] [GetControllerMetricInfo] Obtendo o nome do controlador para o pod: default/test-deployment3-6c95cffb97-d2xv7
I0124 13:54:08.437321       1 types.go:743] [ControllerName] Verificando as anotações do pod default/test-deployment3-6c95cffb97-d2xv7
I0124 13:54:08.437354       1 types.go:761] [ControllerName] Anotação 'controller' encontrada para o pod default/test-deployment3-6c95cffb97-d2xv7: test-controller3
I0124 13:54:08.437384       1 scheduler.go:614] [GetControllerMetricInfo] Métricas do controlador definidas para o pod: default/test-deployment3-6c95cffb97-d2xv7
W0124 13:54:08.437419       1 scheduler.go:125] [cacheMiss] Métricas não encontradas para o pod: default/test-deployment3-6c95cffb97-d2xv7
I0124 13:54:08.444385       1 scheduler.go:70] Estado no Informer: map[controller:test-controller3]
I0124 13:54:08.444642       1 scheduler.go:71] Estado real no cluster: map[controller:test-controller3]
W0124 13:54:08.445099       1 scheduler.go:135] [WaitForPodsOnCache] Pod test-deployment3-6c95cffb97-d2xv7 não encontrado no cache. Tentando novamente...
I0124 13:54:08.549476       1 scheduler.go:606] [GetControllerMetricInfo] Iniciando para o pod: default/test-deployment3-6c95cffb97-d2xv7
I0124 13:54:08.549576       1 scheduler.go:611] [GetControllerMetricInfo] Obtendo o nome do controlador para o pod: default/test-deployment3-6c95cffb97-d2xv7
I0124 13:54:08.549594       1 types.go:743] [ControllerName] Verificando as anotações do pod default/test-deployment3-6c95cffb97-d2xv7
I0124 13:54:08.549612       1 types.go:761] [ControllerName] Anotação 'controller' encontrada para o pod default/test-deployment3-6c95cffb97-d2xv7: test-controller3
I0124 13:54:08.550203       1 scheduler.go:614] [GetControllerMetricInfo] Métricas do controlador definidas para o pod: default/test-deployment3-6c95cffb97-d2xv7
W0124 13:54:08.550239       1 scheduler.go:125] [cacheMiss] Métricas não encontradas para o pod: default/test-deployment3-6c95cffb97-d2xv7
I0124 13:54:08.561012       1 scheduler.go:70] Estado no Informer: map[controller:test-controller3]
I0124 13:54:08.561430       1 scheduler.go:71] Estado real no cluster: map[controller:test-controller3]
W0124 13:54:08.562026       1 scheduler.go:135] [WaitForPodsOnCache] Pod test-deployment3-6c95cffb97-d2xv7 não encontrado no cache. Tentando novamente...
I0124 13:54:08.662815       1 scheduler.go:606] [GetControllerMetricInfo] Iniciando para o pod: default/test-deployment3-6c95cffb97-d2xv7
I0124 13:54:08.663804       1 scheduler.go:611] [GetControllerMetricInfo] Obtendo o nome do controlador para o pod: default/test-deployment3-6c95cffb97-d2xv7
I0124 13:54:08.663978       1 types.go:743] [ControllerName] Verificando as anotações do pod default/test-deployment3-6c95cffb97-d2xv7
I0124 13:54:08.664555       1 types.go:761] [ControllerName] Anotação 'controller' encontrada para o pod default/test-deployment3-6c95cffb97-d2xv7: test-controller3
I0124 13:54:08.664642       1 scheduler.go:614] [GetControllerMetricInfo] Métricas do controlador definidas para o pod: default/test-deployment3-6c95cffb97-d2xv7
W0124 13:54:08.664691       1 scheduler.go:125] [cacheMiss] Métricas não encontradas para o pod: default/test-deployment3-6c95cffb97-d2xv7
I0124 13:54:08.671502       1 scheduler.go:70] Estado no Informer: map[controller:test-controller3]
I0124 13:54:08.671612       1 scheduler.go:71] Estado real no cluster: map[controller:test-controller3]
W0124 13:54:08.671633       1 scheduler.go:135] [WaitForPodsOnCache] Pod test-deployment3-6c95cffb97-d2xv7 não encontrado no cache. Tentando novamente...
I0124 13:54:08.772630       1 scheduler.go:606] [GetControllerMetricInfo] Iniciando para o pod: default/test-deployment3-6c95cffb97-d2xv7
I0124 13:54:08.772728       1 scheduler.go:611] [GetControllerMetricInfo] Obtendo o nome do controlador para o pod: default/test-deployment3-6c95cffb97-d2xv7
I0124 13:54:08.772745       1 types.go:743] [ControllerName] Verificando as anotações do pod default/test-deployment3-6c95cffb97-d2xv7
I0124 13:54:08.772766       1 types.go:761] [ControllerName] Anotação 'controller' encontrada para o pod default/test-deployment3-6c95cffb97-d2xv7: test-controller3
I0124 13:54:08.772791       1 scheduler.go:614] [GetControllerMetricInfo] Métricas do controlador definidas para o pod: default/test-deployment3-6c95cffb97-d2xv7
W0124 13:54:08.772817       1 scheduler.go:125] [cacheMiss] Métricas não encontradas para o pod: default/test-deployment3-6c95cffb97-d2xv7
I0124 13:54:08.790376       1 scheduler.go:70] Estado no Informer: map[controller:test-controller3]
I0124 13:54:08.800295       1 scheduler.go:71] Estado real no cluster: map[controller:test-controller3]
W0124 13:54:08.800601       1 scheduler.go:135] [WaitForPodsOnCache] Pod test-deployment3-6c95cffb97-d2xv7 não encontrado no cache. Tentando novamente...
I0124 13:54:08.902181       1 scheduler.go:606] [GetControllerMetricInfo] Iniciando para o pod: default/test-deployment3-6c95cffb97-d2xv7
I0124 13:54:08.902278       1 scheduler.go:611] [GetControllerMetricInfo] Obtendo o nome do controlador para o pod: default/test-deployment3-6c95cffb97-d2xv7
I0124 13:54:08.902295       1 types.go:743] [ControllerName] Verificando as anotações do pod default/test-deployment3-6c95cffb97-d2xv7
I0124 13:54:08.902312       1 types.go:761] [ControllerName] Anotação 'controller' encontrada para o pod default/test-deployment3-6c95cffb97-d2xv7: test-controller3
I0124 13:54:08.902328       1 scheduler.go:614] [GetControllerMetricInfo] Métricas do controlador definidas para o pod: default/test-deployment3-6c95cffb97-d2xv7
W0124 13:54:08.902347       1 scheduler.go:125] [cacheMiss] Métricas não encontradas para o pod: default/test-deployment3-6c95cffb97-d2xv7
I0124 13:54:08.911278       1 scheduler.go:70] Estado no Informer: map[controller:test-controller3]
I0124 13:54:08.911374       1 scheduler.go:71] Estado real no cluster: map[controller:test-controller3]
W0124 13:54:08.911396       1 scheduler.go:135] [WaitForPodsOnCache] Pod test-deployment3-6c95cffb97-d2xv7 não encontrado no cache. Tentando novamente...
I0124 13:54:09.011626       1 scheduler.go:606] [GetControllerMetricInfo] Iniciando para o pod: default/test-deployment3-6c95cffb97-d2xv7
I0124 13:54:09.011750       1 scheduler.go:611] [GetControllerMetricInfo] Obtendo o nome do controlador para o pod: default/test-deployment3-6c95cffb97-d2xv7
I0124 13:54:09.011769       1 types.go:743] [ControllerName] Verificando as anotações do pod default/test-deployment3-6c95cffb97-d2xv7
I0124 13:54:09.011785       1 types.go:761] [ControllerName] Anotação 'controller' encontrada para o pod default/test-deployment3-6c95cffb97-d2xv7: test-controller3
I0124 13:54:09.011800       1 scheduler.go:614] [GetControllerMetricInfo] Métricas do controlador definidas para o pod: default/test-deployment3-6c95cffb97-d2xv7
W0124 13:54:09.011820       1 scheduler.go:125] [cacheMiss] Métricas não encontradas para o pod: default/test-deployment3-6c95cffb97-d2xv7
I0124 13:54:09.018518       1 scheduler.go:70] Estado no Informer: map[controller:test-controller3]
I0124 13:54:09.021453       1 scheduler.go:71] Estado real no cluster: map[controller:test-controller3]
W0124 13:54:09.021553       1 scheduler.go:135] [WaitForPodsOnCache] Pod test-deployment3-6c95cffb97-d2xv7 não encontrado no cache. Tentando novamente...
I0124 13:54:09.122513       1 scheduler.go:606] [GetControllerMetricInfo] Iniciando para o pod: default/test-deployment3-6c95cffb97-d2xv7
I0124 13:54:09.122623       1 scheduler.go:611] [GetControllerMetricInfo] Obtendo o nome do controlador para o pod: default/test-deployment3-6c95cffb97-d2xv7
I0124 13:54:09.122641       1 types.go:743] [ControllerName] Verificando as anotações do pod default/test-deployment3-6c95cffb97-d2xv7
I0124 13:54:09.122658       1 types.go:761] [ControllerName] Anotação 'controller' encontrada para o pod default/test-deployment3-6c95cffb97-d2xv7: test-controller3
I0124 13:54:09.122674       1 scheduler.go:614] [GetControllerMetricInfo] Métricas do controlador definidas para o pod: default/test-deployment3-6c95cffb97-d2xv7
W0124 13:54:09.122701       1 scheduler.go:125] [cacheMiss] Métricas não encontradas para o pod: default/test-deployment3-6c95cffb97-d2xv7
I0124 13:54:09.131050       1 scheduler.go:70] Estado no Informer: map[controller:test-controller3]
I0124 13:54:09.131625       1 scheduler.go:71] Estado real no cluster: map[controller:test-controller3]
W0124 13:54:09.132260       1 scheduler.go:135] [WaitForPodsOnCache] Pod test-deployment3-6c95cffb97-d2xv7 não encontrado no cache. Tentando novamente...
I0124 13:54:09.233629       1 scheduler.go:606] [GetControllerMetricInfo] Iniciando para o pod: default/test-deployment3-6c95cffb97-d2xv7
I0124 13:54:09.233832       1 scheduler.go:611] [GetControllerMetricInfo] Obtendo o nome do controlador para o pod: default/test-deployment3-6c95cffb97-d2xv7
I0124 13:54:09.234458       1 types.go:743] [ControllerName] Verificando as anotações do pod default/test-deployment3-6c95cffb97-d2xv7
I0124 13:54:09.235704       1 types.go:761] [ControllerName] Anotação 'controller' encontrada para o pod default/test-deployment3-6c95cffb97-d2xv7: test-controller3
I0124 13:54:09.236732       1 scheduler.go:614] [GetControllerMetricInfo] Métricas do controlador definidas para o pod: default/test-deployment3-6c95cffb97-d2xv7
W0124 13:54:09.237840       1 scheduler.go:125] [cacheMiss] Métricas não encontradas para o pod: default/test-deployment3-6c95cffb97-d2xv7
I0124 13:54:09.245282       1 scheduler.go:70] Estado no Informer: map[controller:test-controller3]
I0124 13:54:09.246044       1 scheduler.go:71] Estado real no cluster: map[controller:test-controller3]
W0124 13:54:09.246613       1 scheduler.go:135] [WaitForPodsOnCache] Pod test-deployment3-6c95cffb97-d2xv7 não encontrado no cache. Tentando novamente...
I0124 13:54:09.348319       1 scheduler.go:606] [GetControllerMetricInfo] Iniciando para o pod: default/test-deployment3-6c95cffb97-d2xv7
I0124 13:54:09.349055       1 scheduler.go:611] [GetControllerMetricInfo] Obtendo o nome do controlador para o pod: default/test-deployment3-6c95cffb97-d2xv7
I0124 13:54:09.350028       1 types.go:743] [ControllerName] Verificando as anotações do pod default/test-deployment3-6c95cffb97-d2xv7
I0124 13:54:09.350153       1 types.go:761] [ControllerName] Anotação 'controller' encontrada para o pod default/test-deployment3-6c95cffb97-d2xv7: test-controller3
I0124 13:54:09.350791       1 scheduler.go:614] [GetControllerMetricInfo] Métricas do controlador definidas para o pod: default/test-deployment3-6c95cffb97-d2xv7
W0124 13:54:09.351200       1 scheduler.go:125] [cacheMiss] Métricas não encontradas para o pod: default/test-deployment3-6c95cffb97-d2xv7
I0124 13:54:09.358554       1 scheduler.go:70] Estado no Informer: map[controller:test-controller3]
I0124 13:54:09.358776       1 scheduler.go:71] Estado real no cluster: map[controller:test-controller3]
W0124 13:54:09.359637       1 scheduler.go:135] [WaitForPodsOnCache] Pod test-deployment3-6c95cffb97-d2xv7 não encontrado no cache. Tentando novamente...
I0124 13:54:09.461798       1 scheduler.go:606] [GetControllerMetricInfo] Iniciando para o pod: default/test-deployment3-6c95cffb97-d2xv7
I0124 13:54:09.462203       1 scheduler.go:611] [GetControllerMetricInfo] Obtendo o nome do controlador para o pod: default/test-deployment3-6c95cffb97-d2xv7
I0124 13:54:09.462998       1 types.go:743] [ControllerName] Verificando as anotações do pod default/test-deployment3-6c95cffb97-d2xv7
I0124 13:54:09.463497       1 types.go:761] [ControllerName] Anotação 'controller' encontrada para o pod default/test-deployment3-6c95cffb97-d2xv7: test-controller3
I0124 13:54:09.463685       1 scheduler.go:614] [GetControllerMetricInfo] Métricas do controlador definidas para o pod: default/test-deployment3-6c95cffb97-d2xv7
W0124 13:54:09.464257       1 scheduler.go:125] [cacheMiss] Métricas não encontradas para o pod: default/test-deployment3-6c95cffb97-d2xv7
I0124 13:54:09.473246       1 scheduler.go:70] Estado no Informer: map[controller:test-controller3]
I0124 13:54:09.473491       1 scheduler.go:71] Estado real no cluster: map[controller:test-controller3]
W0124 13:54:09.474045       1 scheduler.go:135] [WaitForPodsOnCache] Pod test-deployment3-6c95cffb97-d2xv7 não encontrado no cache. Tentando novamente...
I0124 13:54:09.575356       1 scheduler.go:606] [GetControllerMetricInfo] Iniciando para o pod: default/test-deployment3-6c95cffb97-d2xv7
I0124 13:54:09.575453       1 scheduler.go:611] [GetControllerMetricInfo] Obtendo o nome do controlador para o pod: default/test-deployment3-6c95cffb97-d2xv7
I0124 13:54:09.575471       1 types.go:743] [ControllerName] Verificando as anotações do pod default/test-deployment3-6c95cffb97-d2xv7
I0124 13:54:09.575487       1 types.go:761] [ControllerName] Anotação 'controller' encontrada para o pod default/test-deployment3-6c95cffb97-d2xv7: test-controller3
I0124 13:54:09.575503       1 scheduler.go:614] [GetControllerMetricInfo] Métricas do controlador definidas para o pod: default/test-deployment3-6c95cffb97-d2xv7
W0124 13:54:09.575523       1 scheduler.go:125] [cacheMiss] Métricas não encontradas para o pod: default/test-deployment3-6c95cffb97-d2xv7
I0124 13:54:09.583426       1 scheduler.go:70] Estado no Informer: map[controller:test-controller3]
I0124 13:54:09.584065       1 scheduler.go:71] Estado real no cluster: map[controller:test-controller3]
W0124 13:54:09.584776       1 scheduler.go:135] [WaitForPodsOnCache] Pod test-deployment3-6c95cffb97-d2xv7 não encontrado no cache. Tentando novamente...
I0124 13:54:09.686016       1 scheduler.go:606] [GetControllerMetricInfo] Iniciando para o pod: default/test-deployment3-6c95cffb97-d2xv7
I0124 13:54:09.686114       1 scheduler.go:611] [GetControllerMetricInfo] Obtendo o nome do controlador para o pod: default/test-deployment3-6c95cffb97-d2xv7
I0124 13:54:09.686131       1 types.go:743] [ControllerName] Verificando as anotações do pod default/test-deployment3-6c95cffb97-d2xv7
I0124 13:54:09.686148       1 types.go:761] [ControllerName] Anotação 'controller' encontrada para o pod default/test-deployment3-6c95cffb97-d2xv7: test-controller3
I0124 13:54:09.686164       1 scheduler.go:614] [GetControllerMetricInfo] Métricas do controlador definidas para o pod: default/test-deployment3-6c95cffb97-d2xv7
W0124 13:54:09.686184       1 scheduler.go:125] [cacheMiss] Métricas não encontradas para o pod: default/test-deployment3-6c95cffb97-d2xv7
I0124 13:54:09.926467       1 scheduler.go:70] Estado no Informer: map[controller:test-controller3]
I0124 13:54:09.926583       1 scheduler.go:71] Estado real no cluster: map[controller:test-controller3]
W0124 13:54:09.926607       1 scheduler.go:135] [WaitForPodsOnCache] Pod test-deployment3-6c95cffb97-d2xv7 não encontrado no cache. Tentando novamente...
I0124 13:54:10.027483       1 scheduler.go:606] [GetControllerMetricInfo] Iniciando para o pod: default/test-deployment3-6c95cffb97-d2xv7
I0124 13:54:10.027595       1 scheduler.go:611] [GetControllerMetricInfo] Obtendo o nome do controlador para o pod: default/test-deployment3-6c95cffb97-d2xv7
I0124 13:54:10.027614       1 types.go:743] [ControllerName] Verificando as anotações do pod default/test-deployment3-6c95cffb97-d2xv7
I0124 13:54:10.027632       1 types.go:761] [ControllerName] Anotação 'controller' encontrada para o pod default/test-deployment3-6c95cffb97-d2xv7: test-controller3
I0124 13:54:10.027649       1 scheduler.go:614] [GetControllerMetricInfo] Métricas do controlador definidas para o pod: default/test-deployment3-6c95cffb97-d2xv7
W0124 13:54:10.027670       1 scheduler.go:125] [cacheMiss] Métricas não encontradas para o pod: default/test-deployment3-6c95cffb97-d2xv7
I0124 13:54:10.038817       1 scheduler.go:70] Estado no Informer: map[controller:test-controller3]
I0124 13:54:10.039037       1 scheduler.go:71] Estado real no cluster: map[controller:test-controller3]
W0124 13:54:10.039059       1 scheduler.go:135] [WaitForPodsOnCache] Pod test-deployment3-6c95cffb97-d2xv7 não encontrado no cache. Tentando novamente...
I0124 13:54:10.139457       1 scheduler.go:606] [GetControllerMetricInfo] Iniciando para o pod: default/test-deployment3-6c95cffb97-d2xv7
I0124 13:54:10.140374       1 scheduler.go:611] [GetControllerMetricInfo] Obtendo o nome do controlador para o pod: default/test-deployment3-6c95cffb97-d2xv7
I0124 13:54:10.140707       1 types.go:743] [ControllerName] Verificando as anotações do pod default/test-deployment3-6c95cffb97-d2xv7
I0124 13:54:10.140810       1 types.go:761] [ControllerName] Anotação 'controller' encontrada para o pod default/test-deployment3-6c95cffb97-d2xv7: test-controller3
I0124 13:54:10.140962       1 scheduler.go:614] [GetControllerMetricInfo] Métricas do controlador definidas para o pod: default/test-deployment3-6c95cffb97-d2xv7
W0124 13:54:10.141722       1 scheduler.go:125] [cacheMiss] Métricas não encontradas para o pod: default/test-deployment3-6c95cffb97-d2xv7
I0124 13:54:10.149028       1 scheduler.go:70] Estado no Informer: map[controller:test-controller3]
I0124 13:54:10.149109       1 scheduler.go:71] Estado real no cluster: map[controller:test-controller3]
W0124 13:54:10.149125       1 scheduler.go:135] [WaitForPodsOnCache] Pod test-deployment3-6c95cffb97-d2xv7 não encontrado no cache. Tentando novamente...
I0124 13:54:10.249973       1 scheduler.go:606] [GetControllerMetricInfo] Iniciando para o pod: default/test-deployment3-6c95cffb97-d2xv7
I0124 13:54:10.250596       1 scheduler.go:611] [GetControllerMetricInfo] Obtendo o nome do controlador para o pod: default/test-deployment3-6c95cffb97-d2xv7
I0124 13:54:10.250781       1 types.go:743] [ControllerName] Verificando as anotações do pod default/test-deployment3-6c95cffb97-d2xv7
I0124 13:54:10.250974       1 types.go:761] [ControllerName] Anotação 'controller' encontrada para o pod default/test-deployment3-6c95cffb97-d2xv7: test-controller3
I0124 13:54:10.251279       1 scheduler.go:614] [GetControllerMetricInfo] Métricas do controlador definidas para o pod: default/test-deployment3-6c95cffb97-d2xv7
W0124 13:54:10.251752       1 scheduler.go:125] [cacheMiss] Métricas não encontradas para o pod: default/test-deployment3-6c95cffb97-d2xv7
I0124 13:54:10.260513       1 scheduler.go:70] Estado no Informer: map[controller:test-controller3]
I0124 13:54:10.260748       1 scheduler.go:71] Estado real no cluster: map[controller:test-controller3]
W0124 13:54:10.260771       1 scheduler.go:135] [WaitForPodsOnCache] Pod test-deployment3-6c95cffb97-d2xv7 não encontrado no cache. Tentando novamente...
I0124 13:54:10.362207       1 scheduler.go:606] [GetControllerMetricInfo] Iniciando para o pod: default/test-deployment3-6c95cffb97-d2xv7
I0124 13:54:10.362336       1 scheduler.go:611] [GetControllerMetricInfo] Obtendo o nome do controlador para o pod: default/test-deployment3-6c95cffb97-d2xv7
I0124 13:54:10.362356       1 types.go:743] [ControllerName] Verificando as anotações do pod default/test-deployment3-6c95cffb97-d2xv7
I0124 13:54:10.362373       1 types.go:761] [ControllerName] Anotação 'controller' encontrada para o pod default/test-deployment3-6c95cffb97-d2xv7: test-controller3
I0124 13:54:10.362783       1 scheduler.go:614] [GetControllerMetricInfo] Métricas do controlador definidas para o pod: default/test-deployment3-6c95cffb97-d2xv7
W0124 13:54:10.362977       1 scheduler.go:125] [cacheMiss] Métricas não encontradas para o pod: default/test-deployment3-6c95cffb97-d2xv7
I0124 13:54:10.370835       1 scheduler.go:70] Estado no Informer: map[controller:test-controller3]
I0124 13:54:10.371064       1 scheduler.go:71] Estado real no cluster: map[controller:test-controller3]
W0124 13:54:10.371084       1 scheduler.go:135] [WaitForPodsOnCache] Pod test-deployment3-6c95cffb97-d2xv7 não encontrado no cache. Tentando novamente...
I0124 13:54:10.471713       1 scheduler.go:606] [GetControllerMetricInfo] Iniciando para o pod: default/test-deployment3-6c95cffb97-d2xv7
I0124 13:54:10.471823       1 scheduler.go:611] [GetControllerMetricInfo] Obtendo o nome do controlador para o pod: default/test-deployment3-6c95cffb97-d2xv7
I0124 13:54:10.471841       1 types.go:743] [ControllerName] Verificando as anotações do pod default/test-deployment3-6c95cffb97-d2xv7
I0124 13:54:10.472801       1 types.go:761] [ControllerName] Anotação 'controller' encontrada para o pod default/test-deployment3-6c95cffb97-d2xv7: test-controller3
I0124 13:54:10.472820       1 scheduler.go:614] [GetControllerMetricInfo] Métricas do controlador definidas para o pod: default/test-deployment3-6c95cffb97-d2xv7
W0124 13:54:10.472977       1 scheduler.go:125] [cacheMiss] Métricas não encontradas para o pod: default/test-deployment3-6c95cffb97-d2xv7
I0124 13:54:10.483355       1 scheduler.go:70] Estado no Informer: map[controller:test-controller3]
I0124 13:54:10.483460       1 scheduler.go:71] Estado real no cluster: map[controller:test-controller3]
W0124 13:54:10.483483       1 scheduler.go:135] [WaitForPodsOnCache] Pod test-deployment3-6c95cffb97-d2xv7 não encontrado no cache. Tentando novamente...
I0124 13:54:10.584578       1 scheduler.go:606] [GetControllerMetricInfo] Iniciando para o pod: default/test-deployment3-6c95cffb97-d2xv7
I0124 13:54:10.585331       1 scheduler.go:611] [GetControllerMetricInfo] Obtendo o nome do controlador para o pod: default/test-deployment3-6c95cffb97-d2xv7
I0124 13:54:10.585574       1 types.go:743] [ControllerName] Verificando as anotações do pod default/test-deployment3-6c95cffb97-d2xv7
I0124 13:54:10.585963       1 types.go:761] [ControllerName] Anotação 'controller' encontrada para o pod default/test-deployment3-6c95cffb97-d2xv7: test-controller3
I0124 13:54:10.586215       1 scheduler.go:614] [GetControllerMetricInfo] Métricas do controlador definidas para o pod: default/test-deployment3-6c95cffb97-d2xv7
W0124 13:54:10.586806       1 scheduler.go:125] [cacheMiss] Métricas não encontradas para o pod: default/test-deployment3-6c95cffb97-d2xv7
I0124 13:54:10.603548       1 scheduler.go:70] Estado no Informer: map[controller:test-controller3]
I0124 13:54:10.603682       1 scheduler.go:71] Estado real no cluster: map[controller:test-controller3]
W0124 13:54:10.603704       1 scheduler.go:135] [WaitForPodsOnCache] Pod test-deployment3-6c95cffb97-d2xv7 não encontrado no cache. Tentando novamente...
I0124 13:54:10.704621       1 scheduler.go:606] [GetControllerMetricInfo] Iniciando para o pod: default/test-deployment3-6c95cffb97-d2xv7
I0124 13:54:10.704665       1 scheduler.go:611] [GetControllerMetricInfo] Obtendo o nome do controlador para o pod: default/test-deployment3-6c95cffb97-d2xv7
I0124 13:54:10.704680       1 types.go:743] [ControllerName] Verificando as anotações do pod default/test-deployment3-6c95cffb97-d2xv7
I0124 13:54:10.704696       1 types.go:761] [ControllerName] Anotação 'controller' encontrada para o pod default/test-deployment3-6c95cffb97-d2xv7: test-controller3
I0124 13:54:10.704711       1 scheduler.go:614] [GetControllerMetricInfo] Métricas do controlador definidas para o pod: default/test-deployment3-6c95cffb97-d2xv7
W0124 13:54:10.704730       1 scheduler.go:125] [cacheMiss] Métricas não encontradas para o pod: default/test-deployment3-6c95cffb97-d2xv7
I0124 13:54:10.722353       1 scheduler.go:70] Estado no Informer: map[controller:test-controller3]
I0124 13:54:10.722399       1 scheduler.go:71] Estado real no cluster: map[controller:test-controller3]
W0124 13:54:10.722414       1 scheduler.go:135] [WaitForPodsOnCache] Pod test-deployment3-6c95cffb97-d2xv7 não encontrado no cache. Tentando novamente...
I0124 13:54:10.823200       1 scheduler.go:606] [GetControllerMetricInfo] Iniciando para o pod: default/test-deployment3-6c95cffb97-d2xv7
I0124 13:54:10.823243       1 scheduler.go:611] [GetControllerMetricInfo] Obtendo o nome do controlador para o pod: default/test-deployment3-6c95cffb97-d2xv7
I0124 13:54:10.823257       1 types.go:743] [ControllerName] Verificando as anotações do pod default/test-deployment3-6c95cffb97-d2xv7
I0124 13:54:10.823272       1 types.go:761] [ControllerName] Anotação 'controller' encontrada para o pod default/test-deployment3-6c95cffb97-d2xv7: test-controller3
I0124 13:54:10.823321       1 scheduler.go:614] [GetControllerMetricInfo] Métricas do controlador definidas para o pod: default/test-deployment3-6c95cffb97-d2xv7
W0124 13:54:10.823340       1 scheduler.go:125] [cacheMiss] Métricas não encontradas para o pod: default/test-deployment3-6c95cffb97-d2xv7
I0124 13:54:10.832757       1 scheduler.go:70] Estado no Informer: map[controller:test-controller3]
I0124 13:54:10.833649       1 scheduler.go:71] Estado real no cluster: map[controller:test-controller3]
W0124 13:54:10.834210       1 scheduler.go:135] [WaitForPodsOnCache] Pod test-deployment3-6c95cffb97-d2xv7 não encontrado no cache. Tentando novamente...
I0124 13:54:10.935707       1 scheduler.go:606] [GetControllerMetricInfo] Iniciando para o pod: default/test-deployment3-6c95cffb97-d2xv7
I0124 13:54:10.936942       1 scheduler.go:611] [GetControllerMetricInfo] Obtendo o nome do controlador para o pod: default/test-deployment3-6c95cffb97-d2xv7
I0124 13:54:10.937356       1 types.go:743] [ControllerName] Verificando as anotações do pod default/test-deployment3-6c95cffb97-d2xv7
I0124 13:54:10.937678       1 types.go:761] [ControllerName] Anotação 'controller' encontrada para o pod default/test-deployment3-6c95cffb97-d2xv7: test-controller3
I0124 13:54:10.938120       1 scheduler.go:614] [GetControllerMetricInfo] Métricas do controlador definidas para o pod: default/test-deployment3-6c95cffb97-d2xv7
W0124 13:54:10.938558       1 scheduler.go:125] [cacheMiss] Métricas não encontradas para o pod: default/test-deployment3-6c95cffb97-d2xv7
I0124 13:54:10.947696       1 scheduler.go:70] Estado no Informer: map[controller:test-controller3]
I0124 13:54:10.947744       1 scheduler.go:71] Estado real no cluster: map[controller:test-controller3]
W0124 13:54:10.947761       1 scheduler.go:135] [WaitForPodsOnCache] Pod test-deployment3-6c95cffb97-d2xv7 não encontrado no cache. Tentando novamente...
I0124 13:54:11.048764       1 scheduler.go:606] [GetControllerMetricInfo] Iniciando para o pod: default/test-deployment3-6c95cffb97-d2xv7
I0124 13:54:11.049498       1 scheduler.go:611] [GetControllerMetricInfo] Obtendo o nome do controlador para o pod: default/test-deployment3-6c95cffb97-d2xv7
I0124 13:54:11.049535       1 types.go:743] [ControllerName] Verificando as anotações do pod default/test-deployment3-6c95cffb97-d2xv7
I0124 13:54:11.049552       1 types.go:761] [ControllerName] Anotação 'controller' encontrada para o pod default/test-deployment3-6c95cffb97-d2xv7: test-controller3
I0124 13:54:11.049568       1 scheduler.go:614] [GetControllerMetricInfo] Métricas do controlador definidas para o pod: default/test-deployment3-6c95cffb97-d2xv7
W0124 13:54:11.049589       1 scheduler.go:125] [cacheMiss] Métricas não encontradas para o pod: default/test-deployment3-6c95cffb97-d2xv7
I0124 13:54:11.055186       1 scheduler.go:70] Estado no Informer: map[controller:test-controller3]
I0124 13:54:11.055296       1 scheduler.go:71] Estado real no cluster: map[controller:test-controller3]
W0124 13:54:11.055317       1 scheduler.go:135] [WaitForPodsOnCache] Pod test-deployment3-6c95cffb97-d2xv7 não encontrado no cache. Tentando novamente...
I0124 13:54:11.155947       1 scheduler.go:606] [GetControllerMetricInfo] Iniciando para o pod: default/test-deployment3-6c95cffb97-d2xv7
I0124 13:54:11.156022       1 scheduler.go:611] [GetControllerMetricInfo] Obtendo o nome do controlador para o pod: default/test-deployment3-6c95cffb97-d2xv7
I0124 13:54:11.156035       1 types.go:743] [ControllerName] Verificando as anotações do pod default/test-deployment3-6c95cffb97-d2xv7
I0124 13:54:11.156078       1 types.go:761] [ControllerName] Anotação 'controller' encontrada para o pod default/test-deployment3-6c95cffb97-d2xv7: test-controller3
I0124 13:54:11.156090       1 scheduler.go:614] [GetControllerMetricInfo] Métricas do controlador definidas para o pod: default/test-deployment3-6c95cffb97-d2xv7
W0124 13:54:11.156153       1 scheduler.go:125] [cacheMiss] Métricas não encontradas para o pod: default/test-deployment3-6c95cffb97-d2xv7
I0124 13:54:11.162957       1 scheduler.go:70] Estado no Informer: map[controller:test-controller3]
I0124 13:54:11.163179       1 scheduler.go:71] Estado real no cluster: map[controller:test-controller3]
W0124 13:54:11.163508       1 scheduler.go:135] [WaitForPodsOnCache] Pod test-deployment3-6c95cffb97-d2xv7 não encontrado no cache. Tentando novamente...
I0124 13:54:11.264493       1 scheduler.go:606] [GetControllerMetricInfo] Iniciando para o pod: default/test-deployment3-6c95cffb97-d2xv7
I0124 13:54:11.265219       1 scheduler.go:611] [GetControllerMetricInfo] Obtendo o nome do controlador para o pod: default/test-deployment3-6c95cffb97-d2xv7
I0124 13:54:11.265578       1 types.go:743] [ControllerName] Verificando as anotações do pod default/test-deployment3-6c95cffb97-d2xv7
I0124 13:54:11.265975       1 types.go:761] [ControllerName] Anotação 'controller' encontrada para o pod default/test-deployment3-6c95cffb97-d2xv7: test-controller3
I0124 13:54:11.266571       1 scheduler.go:614] [GetControllerMetricInfo] Métricas do controlador definidas para o pod: default/test-deployment3-6c95cffb97-d2xv7
W0124 13:54:11.266772       1 scheduler.go:125] [cacheMiss] Métricas não encontradas para o pod: default/test-deployment3-6c95cffb97-d2xv7
I0124 13:54:11.273541       1 scheduler.go:70] Estado no Informer: map[controller:test-controller3]
I0124 13:54:11.274071       1 scheduler.go:71] Estado real no cluster: map[controller:test-controller3]
W0124 13:54:11.274769       1 scheduler.go:135] [WaitForPodsOnCache] Pod test-deployment3-6c95cffb97-d2xv7 não encontrado no cache. Tentando novamente...
I0124 13:54:11.376800       1 scheduler.go:606] [GetControllerMetricInfo] Iniciando para o pod: default/test-deployment3-6c95cffb97-d2xv7
I0124 13:54:11.376976       1 scheduler.go:611] [GetControllerMetricInfo] Obtendo o nome do controlador para o pod: default/test-deployment3-6c95cffb97-d2xv7
I0124 13:54:11.376996       1 types.go:743] [ControllerName] Verificando as anotações do pod default/test-deployment3-6c95cffb97-d2xv7
I0124 13:54:11.377013       1 types.go:761] [ControllerName] Anotação 'controller' encontrada para o pod default/test-deployment3-6c95cffb97-d2xv7: test-controller3
I0124 13:54:11.377029       1 scheduler.go:614] [GetControllerMetricInfo] Métricas do controlador definidas para o pod: default/test-deployment3-6c95cffb97-d2xv7
W0124 13:54:11.377048       1 scheduler.go:125] [cacheMiss] Métricas não encontradas para o pod: default/test-deployment3-6c95cffb97-d2xv7
I0124 13:54:11.384417       1 scheduler.go:70] Estado no Informer: map[controller:test-controller3]
I0124 13:54:11.384657       1 scheduler.go:71] Estado real no cluster: map[controller:test-controller3]
W0124 13:54:11.385656       1 scheduler.go:135] [WaitForPodsOnCache] Pod test-deployment3-6c95cffb97-d2xv7 não encontrado no cache. Tentando novamente...
I0124 13:54:11.487163       1 scheduler.go:606] [GetControllerMetricInfo] Iniciando para o pod: default/test-deployment3-6c95cffb97-d2xv7
I0124 13:54:11.487955       1 scheduler.go:611] [GetControllerMetricInfo] Obtendo o nome do controlador para o pod: default/test-deployment3-6c95cffb97-d2xv7
I0124 13:54:11.488648       1 types.go:743] [ControllerName] Verificando as anotações do pod default/test-deployment3-6c95cffb97-d2xv7
I0124 13:54:11.488755       1 types.go:761] [ControllerName] Anotação 'controller' encontrada para o pod default/test-deployment3-6c95cffb97-d2xv7: test-controller3
I0124 13:54:11.488778       1 scheduler.go:614] [GetControllerMetricInfo] Métricas do controlador definidas para o pod: default/test-deployment3-6c95cffb97-d2xv7
W0124 13:54:11.488797       1 scheduler.go:125] [cacheMiss] Métricas não encontradas para o pod: default/test-deployment3-6c95cffb97-d2xv7
I0124 13:54:11.496336       1 scheduler.go:70] Estado no Informer: map[controller:test-controller3]
I0124 13:54:11.497182       1 scheduler.go:71] Estado real no cluster: map[controller:test-controller3]
W0124 13:54:11.497388       1 scheduler.go:135] [WaitForPodsOnCache] Pod test-deployment3-6c95cffb97-d2xv7 não encontrado no cache. Tentando novamente...
I0124 13:54:11.598640       1 scheduler.go:606] [GetControllerMetricInfo] Iniciando para o pod: default/test-deployment3-6c95cffb97-d2xv7
I0124 13:54:11.598827       1 scheduler.go:611] [GetControllerMetricInfo] Obtendo o nome do controlador para o pod: default/test-deployment3-6c95cffb97-d2xv7
I0124 13:54:11.599529       1 types.go:743] [ControllerName] Verificando as anotações do pod default/test-deployment3-6c95cffb97-d2xv7
I0124 13:54:11.600289       1 types.go:761] [ControllerName] Anotação 'controller' encontrada para o pod default/test-deployment3-6c95cffb97-d2xv7: test-controller3
I0124 13:54:11.601068       1 scheduler.go:614] [GetControllerMetricInfo] Métricas do controlador definidas para o pod: default/test-deployment3-6c95cffb97-d2xv7
W0124 13:54:11.601554       1 scheduler.go:125] [cacheMiss] Métricas não encontradas para o pod: default/test-deployment3-6c95cffb97-d2xv7
I0124 13:54:11.610776       1 scheduler.go:70] Estado no Informer: map[controller:test-controller3]
I0124 13:54:11.611402       1 scheduler.go:71] Estado real no cluster: map[controller:test-controller3]
W0124 13:54:11.611805       1 scheduler.go:135] [WaitForPodsOnCache] Pod test-deployment3-6c95cffb97-d2xv7 não encontrado no cache. Tentando novamente...
I0124 13:54:11.713109       1 scheduler.go:606] [GetControllerMetricInfo] Iniciando para o pod: default/test-deployment3-6c95cffb97-d2xv7
I0124 13:54:11.713207       1 scheduler.go:611] [GetControllerMetricInfo] Obtendo o nome do controlador para o pod: default/test-deployment3-6c95cffb97-d2xv7
I0124 13:54:11.713225       1 types.go:743] [ControllerName] Verificando as anotações do pod default/test-deployment3-6c95cffb97-d2xv7
I0124 13:54:11.713241       1 types.go:761] [ControllerName] Anotação 'controller' encontrada para o pod default/test-deployment3-6c95cffb97-d2xv7: test-controller3
I0124 13:54:11.713257       1 scheduler.go:614] [GetControllerMetricInfo] Métricas do controlador definidas para o pod: default/test-deployment3-6c95cffb97-d2xv7
W0124 13:54:11.713316       1 scheduler.go:125] [cacheMiss] Métricas não encontradas para o pod: default/test-deployment3-6c95cffb97-d2xv7
I0124 13:54:11.721266       1 scheduler.go:70] Estado no Informer: map[controller:test-controller3]
I0124 13:54:11.722108       1 scheduler.go:71] Estado real no cluster: map[controller:test-controller3]
W0124 13:54:11.722817       1 scheduler.go:135] [WaitForPodsOnCache] Pod test-deployment3-6c95cffb97-d2xv7 não encontrado no cache. Tentando novamente...
I0124 13:54:11.824329       1 scheduler.go:606] [GetControllerMetricInfo] Iniciando para o pod: default/test-deployment3-6c95cffb97-d2xv7
I0124 13:54:11.825258       1 scheduler.go:611] [GetControllerMetricInfo] Obtendo o nome do controlador para o pod: default/test-deployment3-6c95cffb97-d2xv7
I0124 13:54:11.825835       1 types.go:743] [ControllerName] Verificando as anotações do pod default/test-deployment3-6c95cffb97-d2xv7
I0124 13:54:11.826641       1 types.go:761] [ControllerName] Anotação 'controller' encontrada para o pod default/test-deployment3-6c95cffb97-d2xv7: test-controller3
I0124 13:54:11.827350       1 scheduler.go:614] [GetControllerMetricInfo] Métricas do controlador definidas para o pod: default/test-deployment3-6c95cffb97-d2xv7
W0124 13:54:11.827965       1 scheduler.go:125] [cacheMiss] Métricas não encontradas para o pod: default/test-deployment3-6c95cffb97-d2xv7
I0124 13:54:11.837749       1 scheduler.go:70] Estado no Informer: map[controller:test-controller3]
I0124 13:54:11.838225       1 scheduler.go:71] Estado real no cluster: map[controller:test-controller3]
W0124 13:54:11.838311       1 scheduler.go:135] [WaitForPodsOnCache] Pod test-deployment3-6c95cffb97-d2xv7 não encontrado no cache. Tentando novamente...
I0124 13:54:11.939651       1 scheduler.go:606] [GetControllerMetricInfo] Iniciando para o pod: default/test-deployment3-6c95cffb97-d2xv7
I0124 13:54:11.939700       1 scheduler.go:611] [GetControllerMetricInfo] Obtendo o nome do controlador para o pod: default/test-deployment3-6c95cffb97-d2xv7
I0124 13:54:11.939715       1 types.go:743] [ControllerName] Verificando as anotações do pod default/test-deployment3-6c95cffb97-d2xv7
I0124 13:54:11.939731       1 types.go:761] [ControllerName] Anotação 'controller' encontrada para o pod default/test-deployment3-6c95cffb97-d2xv7: test-controller3
I0124 13:54:11.939746       1 scheduler.go:614] [GetControllerMetricInfo] Métricas do controlador definidas para o pod: default/test-deployment3-6c95cffb97-d2xv7
W0124 13:54:11.939765       1 scheduler.go:125] [cacheMiss] Métricas não encontradas para o pod: default/test-deployment3-6c95cffb97-d2xv7
I0124 13:54:11.947168       1 scheduler.go:70] Estado no Informer: map[controller:test-controller3]
I0124 13:54:11.947344       1 scheduler.go:71] Estado real no cluster: map[controller:test-controller3]
W0124 13:54:11.947396       1 scheduler.go:135] [WaitForPodsOnCache] Pod test-deployment3-6c95cffb97-d2xv7 não encontrado no cache. Tentando novamente...
I0124 13:54:12.048751       1 scheduler.go:606] [GetControllerMetricInfo] Iniciando para o pod: default/test-deployment3-6c95cffb97-d2xv7
I0124 13:54:12.049284       1 scheduler.go:611] [GetControllerMetricInfo] Obtendo o nome do controlador para o pod: default/test-deployment3-6c95cffb97-d2xv7
I0124 13:54:12.049512       1 types.go:743] [ControllerName] Verificando as anotações do pod default/test-deployment3-6c95cffb97-d2xv7
I0124 13:54:12.049588       1 types.go:761] [ControllerName] Anotação 'controller' encontrada para o pod default/test-deployment3-6c95cffb97-d2xv7: test-controller3
I0124 13:54:12.049732       1 scheduler.go:614] [GetControllerMetricInfo] Métricas do controlador definidas para o pod: default/test-deployment3-6c95cffb97-d2xv7
W0124 13:54:12.049802       1 scheduler.go:125] [cacheMiss] Métricas não encontradas para o pod: default/test-deployment3-6c95cffb97-d2xv7
I0124 13:54:12.059472       1 scheduler.go:70] Estado no Informer: map[controller:test-controller3]
I0124 13:54:12.059580       1 scheduler.go:71] Estado real no cluster: map[controller:test-controller3]
W0124 13:54:12.059603       1 scheduler.go:135] [WaitForPodsOnCache] Pod test-deployment3-6c95cffb97-d2xv7 não encontrado no cache. Tentando novamente...
I0124 13:54:12.160356       1 scheduler.go:606] [GetControllerMetricInfo] Iniciando para o pod: default/test-deployment3-6c95cffb97-d2xv7
I0124 13:54:12.160453       1 scheduler.go:611] [GetControllerMetricInfo] Obtendo o nome do controlador para o pod: default/test-deployment3-6c95cffb97-d2xv7
I0124 13:54:12.160468       1 types.go:743] [ControllerName] Verificando as anotações do pod default/test-deployment3-6c95cffb97-d2xv7
I0124 13:54:12.160483       1 types.go:761] [ControllerName] Anotação 'controller' encontrada para o pod default/test-deployment3-6c95cffb97-d2xv7: test-controller3
I0124 13:54:12.160497       1 scheduler.go:614] [GetControllerMetricInfo] Métricas do controlador definidas para o pod: default/test-deployment3-6c95cffb97-d2xv7
W0124 13:54:12.160514       1 scheduler.go:125] [cacheMiss] Métricas não encontradas para o pod: default/test-deployment3-6c95cffb97-d2xv7
I0124 13:54:12.221469       1 scheduler.go:70] Estado no Informer: map[controller:test-controller3]
I0124 13:54:12.221579       1 scheduler.go:71] Estado real no cluster: map[controller:test-controller3]
W0124 13:54:12.221602       1 scheduler.go:135] [WaitForPodsOnCache] Pod test-deployment3-6c95cffb97-d2xv7 não encontrado no cache. Tentando novamente...
I0124 13:54:12.324175       1 scheduler.go:606] [GetControllerMetricInfo] Iniciando para o pod: default/test-deployment3-6c95cffb97-d2xv7
I0124 13:54:12.332727       1 scheduler.go:611] [GetControllerMetricInfo] Obtendo o nome do controlador para o pod: default/test-deployment3-6c95cffb97-d2xv7
I0124 13:54:12.332933       1 types.go:743] [ControllerName] Verificando as anotações do pod default/test-deployment3-6c95cffb97-d2xv7
I0124 13:54:12.332979       1 types.go:761] [ControllerName] Anotação 'controller' encontrada para o pod default/test-deployment3-6c95cffb97-d2xv7: test-controller3
I0124 13:54:12.333018       1 scheduler.go:614] [GetControllerMetricInfo] Métricas do controlador definidas para o pod: default/test-deployment3-6c95cffb97-d2xv7
W0124 13:54:12.333061       1 scheduler.go:125] [cacheMiss] Métricas não encontradas para o pod: default/test-deployment3-6c95cffb97-d2xv7
I0124 13:54:12.340485       1 scheduler.go:70] Estado no Informer: map[controller:test-controller3]
I0124 13:54:12.340584       1 scheduler.go:71] Estado real no cluster: map[controller:test-controller3]
W0124 13:54:12.340634       1 scheduler.go:135] [WaitForPodsOnCache] Pod test-deployment3-6c95cffb97-d2xv7 não encontrado no cache. Tentando novamente...
I0124 13:54:12.442048       1 scheduler.go:606] [GetControllerMetricInfo] Iniciando para o pod: default/test-deployment3-6c95cffb97-d2xv7
I0124 13:54:12.442324       1 scheduler.go:611] [GetControllerMetricInfo] Obtendo o nome do controlador para o pod: default/test-deployment3-6c95cffb97-d2xv7
I0124 13:54:12.442399       1 types.go:743] [ControllerName] Verificando as anotações do pod default/test-deployment3-6c95cffb97-d2xv7
I0124 13:54:12.442504       1 types.go:761] [ControllerName] Anotação 'controller' encontrada para o pod default/test-deployment3-6c95cffb97-d2xv7: test-controller3
I0124 13:54:12.443098       1 scheduler.go:614] [GetControllerMetricInfo] Métricas do controlador definidas para o pod: default/test-deployment3-6c95cffb97-d2xv7
W0124 13:54:12.443287       1 scheduler.go:125] [cacheMiss] Métricas não encontradas para o pod: default/test-deployment3-6c95cffb97-d2xv7
I0124 13:54:12.454439       1 scheduler.go:70] Estado no Informer: map[controller:test-controller3]
I0124 13:54:12.454678       1 scheduler.go:71] Estado real no cluster: map[controller:test-controller3]
W0124 13:54:12.454740       1 scheduler.go:135] [WaitForPodsOnCache] Pod test-deployment3-6c95cffb97-d2xv7 não encontrado no cache. Tentando novamente...
I0124 13:54:12.556172       1 scheduler.go:606] [GetControllerMetricInfo] Iniciando para o pod: default/test-deployment3-6c95cffb97-d2xv7
I0124 13:54:12.556220       1 scheduler.go:611] [GetControllerMetricInfo] Obtendo o nome do controlador para o pod: default/test-deployment3-6c95cffb97-d2xv7
I0124 13:54:12.556235       1 types.go:743] [ControllerName] Verificando as anotações do pod default/test-deployment3-6c95cffb97-d2xv7
I0124 13:54:12.556252       1 types.go:761] [ControllerName] Anotação 'controller' encontrada para o pod default/test-deployment3-6c95cffb97-d2xv7: test-controller3
I0124 13:54:12.556982       1 scheduler.go:614] [GetControllerMetricInfo] Métricas do controlador definidas para o pod: default/test-deployment3-6c95cffb97-d2xv7
W0124 13:54:12.557072       1 scheduler.go:125] [cacheMiss] Métricas não encontradas para o pod: default/test-deployment3-6c95cffb97-d2xv7
I0124 13:54:12.567229       1 scheduler.go:70] Estado no Informer: map[controller:test-controller3]
I0124 13:54:12.567330       1 scheduler.go:71] Estado real no cluster: map[controller:test-controller3]
W0124 13:54:12.567352       1 scheduler.go:135] [WaitForPodsOnCache] Pod test-deployment3-6c95cffb97-d2xv7 não encontrado no cache. Tentando novamente...
I0124 13:54:12.667436       1 scheduler.go:606] [GetControllerMetricInfo] Iniciando para o pod: default/test-deployment3-6c95cffb97-d2xv7
I0124 13:54:12.667544       1 scheduler.go:611] [GetControllerMetricInfo] Obtendo o nome do controlador para o pod: default/test-deployment3-6c95cffb97-d2xv7
I0124 13:54:12.667561       1 types.go:743] [ControllerName] Verificando as anotações do pod default/test-deployment3-6c95cffb97-d2xv7
I0124 13:54:12.667579       1 types.go:761] [ControllerName] Anotação 'controller' encontrada para o pod default/test-deployment3-6c95cffb97-d2xv7: test-controller3
I0124 13:54:12.667595       1 scheduler.go:614] [GetControllerMetricInfo] Métricas do controlador definidas para o pod: default/test-deployment3-6c95cffb97-d2xv7
W0124 13:54:12.667614       1 scheduler.go:125] [cacheMiss] Métricas não encontradas para o pod: default/test-deployment3-6c95cffb97-d2xv7
I0124 13:54:12.860837       1 scheduler.go:70] Estado no Informer: map[controller:test-controller3]
I0124 13:54:12.861569       1 scheduler.go:71] Estado real no cluster: map[controller:test-controller3]
W0124 13:54:12.861807       1 scheduler.go:135] [WaitForPodsOnCache] Pod test-deployment3-6c95cffb97-d2xv7 não encontrado no cache. Tentando novamente...
I0124 13:54:12.962653       1 scheduler.go:606] [GetControllerMetricInfo] Iniciando para o pod: default/test-deployment3-6c95cffb97-d2xv7
I0124 13:54:12.963314       1 scheduler.go:611] [GetControllerMetricInfo] Obtendo o nome do controlador para o pod: default/test-deployment3-6c95cffb97-d2xv7
I0124 13:54:12.963398       1 types.go:743] [ControllerName] Verificando as anotações do pod default/test-deployment3-6c95cffb97-d2xv7
I0124 13:54:12.963418       1 types.go:761] [ControllerName] Anotação 'controller' encontrada para o pod default/test-deployment3-6c95cffb97-d2xv7: test-controller3
I0124 13:54:12.963434       1 scheduler.go:614] [GetControllerMetricInfo] Métricas do controlador definidas para o pod: default/test-deployment3-6c95cffb97-d2xv7
W0124 13:54:12.963453       1 scheduler.go:125] [cacheMiss] Métricas não encontradas para o pod: default/test-deployment3-6c95cffb97-d2xv7
I0124 13:54:12.991315       1 scheduler.go:70] Estado no Informer: map[controller:test-controller3]
I0124 13:54:12.991424       1 scheduler.go:71] Estado real no cluster: map[controller:test-controller3]
W0124 13:54:12.991446       1 scheduler.go:135] [WaitForPodsOnCache] Pod test-deployment3-6c95cffb97-d2xv7 não encontrado no cache. Tentando novamente...
I0124 13:54:13.092251       1 scheduler.go:606] [GetControllerMetricInfo] Iniciando para o pod: default/test-deployment3-6c95cffb97-d2xv7
I0124 13:54:13.093434       1 scheduler.go:611] [GetControllerMetricInfo] Obtendo o nome do controlador para o pod: default/test-deployment3-6c95cffb97-d2xv7
I0124 13:54:13.093954       1 types.go:743] [ControllerName] Verificando as anotações do pod default/test-deployment3-6c95cffb97-d2xv7
I0124 13:54:13.095180       1 types.go:761] [ControllerName] Anotação 'controller' encontrada para o pod default/test-deployment3-6c95cffb97-d2xv7: test-controller3
I0124 13:54:13.096018       1 scheduler.go:614] [GetControllerMetricInfo] Métricas do controlador definidas para o pod: default/test-deployment3-6c95cffb97-d2xv7
W0124 13:54:13.097016       1 scheduler.go:125] [cacheMiss] Métricas não encontradas para o pod: default/test-deployment3-6c95cffb97-d2xv7
I0124 13:54:13.111284       1 scheduler.go:70] Estado no Informer: map[controller:test-controller3]
I0124 13:54:13.111388       1 scheduler.go:71] Estado real no cluster: map[controller:test-controller3]
W0124 13:54:13.111410       1 scheduler.go:135] [WaitForPodsOnCache] Pod test-deployment3-6c95cffb97-d2xv7 não encontrado no cache. Tentando novamente...
I0124 13:54:13.212071       1 scheduler.go:606] [GetControllerMetricInfo] Iniciando para o pod: default/test-deployment3-6c95cffb97-d2xv7
I0124 13:54:13.212224       1 scheduler.go:611] [GetControllerMetricInfo] Obtendo o nome do controlador para o pod: default/test-deployment3-6c95cffb97-d2xv7
I0124 13:54:13.212314       1 types.go:743] [ControllerName] Verificando as anotações do pod default/test-deployment3-6c95cffb97-d2xv7
I0124 13:54:13.212331       1 types.go:761] [ControllerName] Anotação 'controller' encontrada para o pod default/test-deployment3-6c95cffb97-d2xv7: test-controller3
I0124 13:54:13.212385       1 scheduler.go:614] [GetControllerMetricInfo] Métricas do controlador definidas para o pod: default/test-deployment3-6c95cffb97-d2xv7
W0124 13:54:13.212407       1 scheduler.go:125] [cacheMiss] Métricas não encontradas para o pod: default/test-deployment3-6c95cffb97-d2xv7
I0124 13:54:13.221818       1 scheduler.go:70] Estado no Informer: map[controller:test-controller3]
I0124 13:54:13.222016       1 scheduler.go:71] Estado real no cluster: map[controller:test-controller3]
W0124 13:54:13.222055       1 scheduler.go:135] [WaitForPodsOnCache] Pod test-deployment3-6c95cffb97-d2xv7 não encontrado no cache. Tentando novamente...
I0124 13:54:13.323060       1 scheduler.go:606] [GetControllerMetricInfo] Iniciando para o pod: default/test-deployment3-6c95cffb97-d2xv7
I0124 13:54:13.323451       1 scheduler.go:611] [GetControllerMetricInfo] Obtendo o nome do controlador para o pod: default/test-deployment3-6c95cffb97-d2xv7
I0124 13:54:13.323995       1 types.go:743] [ControllerName] Verificando as anotações do pod default/test-deployment3-6c95cffb97-d2xv7
I0124 13:54:13.324387       1 types.go:761] [ControllerName] Anotação 'controller' encontrada para o pod default/test-deployment3-6c95cffb97-d2xv7: test-controller3
I0124 13:54:13.324512       1 scheduler.go:614] [GetControllerMetricInfo] Métricas do controlador definidas para o pod: default/test-deployment3-6c95cffb97-d2xv7
W0124 13:54:13.324647       1 scheduler.go:125] [cacheMiss] Métricas não encontradas para o pod: default/test-deployment3-6c95cffb97-d2xv7
I0124 13:54:13.332201       1 scheduler.go:70] Estado no Informer: map[controller:test-controller3]
I0124 13:54:13.332242       1 scheduler.go:71] Estado real no cluster: map[controller:test-controller3]
W0124 13:54:13.332258       1 scheduler.go:135] [WaitForPodsOnCache] Pod test-deployment3-6c95cffb97-d2xv7 não encontrado no cache. Tentando novamente...
I0124 13:54:13.433492       1 scheduler.go:606] [GetControllerMetricInfo] Iniciando para o pod: default/test-deployment3-6c95cffb97-d2xv7
I0124 13:54:13.433586       1 scheduler.go:611] [GetControllerMetricInfo] Obtendo o nome do controlador para o pod: default/test-deployment3-6c95cffb97-d2xv7
I0124 13:54:13.433604       1 types.go:743] [ControllerName] Verificando as anotações do pod default/test-deployment3-6c95cffb97-d2xv7
I0124 13:54:13.433621       1 types.go:761] [ControllerName] Anotação 'controller' encontrada para o pod default/test-deployment3-6c95cffb97-d2xv7: test-controller3
I0124 13:54:13.433638       1 scheduler.go:614] [GetControllerMetricInfo] Métricas do controlador definidas para o pod: default/test-deployment3-6c95cffb97-d2xv7
W0124 13:54:13.433753       1 scheduler.go:125] [cacheMiss] Métricas não encontradas para o pod: default/test-deployment3-6c95cffb97-d2xv7
I0124 13:54:13.442182       1 scheduler.go:70] Estado no Informer: map[controller:test-controller3]
I0124 13:54:13.442614       1 scheduler.go:71] Estado real no cluster: map[controller:test-controller3]
W0124 13:54:13.442755       1 scheduler.go:135] [WaitForPodsOnCache] Pod test-deployment3-6c95cffb97-d2xv7 não encontrado no cache. Tentando novamente...
I0124 13:54:13.544007       1 scheduler.go:606] [GetControllerMetricInfo] Iniciando para o pod: default/test-deployment3-6c95cffb97-d2xv7
I0124 13:54:13.544174       1 scheduler.go:611] [GetControllerMetricInfo] Obtendo o nome do controlador para o pod: default/test-deployment3-6c95cffb97-d2xv7
I0124 13:54:13.544194       1 types.go:743] [ControllerName] Verificando as anotações do pod default/test-deployment3-6c95cffb97-d2xv7
I0124 13:54:13.544210       1 types.go:761] [ControllerName] Anotação 'controller' encontrada para o pod default/test-deployment3-6c95cffb97-d2xv7: test-controller3
I0124 13:54:13.544307       1 scheduler.go:614] [GetControllerMetricInfo] Métricas do controlador definidas para o pod: default/test-deployment3-6c95cffb97-d2xv7
W0124 13:54:13.544759       1 scheduler.go:125] [cacheMiss] Métricas não encontradas para o pod: default/test-deployment3-6c95cffb97-d2xv7
I0124 13:54:13.550430       1 scheduler.go:70] Estado no Informer: map[controller:test-controller3]
I0124 13:54:13.550653       1 scheduler.go:71] Estado real no cluster: map[controller:test-controller3]
W0124 13:54:13.550731       1 scheduler.go:135] [WaitForPodsOnCache] Pod test-deployment3-6c95cffb97-d2xv7 não encontrado no cache. Tentando novamente...
I0124 13:54:13.651959       1 scheduler.go:606] [GetControllerMetricInfo] Iniciando para o pod: default/test-deployment3-6c95cffb97-d2xv7
I0124 13:54:13.652049       1 scheduler.go:611] [GetControllerMetricInfo] Obtendo o nome do controlador para o pod: default/test-deployment3-6c95cffb97-d2xv7
I0124 13:54:13.652067       1 types.go:743] [ControllerName] Verificando as anotações do pod default/test-deployment3-6c95cffb97-d2xv7
I0124 13:54:13.652082       1 types.go:761] [ControllerName] Anotação 'controller' encontrada para o pod default/test-deployment3-6c95cffb97-d2xv7: test-controller3
I0124 13:54:13.652170       1 scheduler.go:614] [GetControllerMetricInfo] Métricas do controlador definidas para o pod: default/test-deployment3-6c95cffb97-d2xv7
W0124 13:54:13.652192       1 scheduler.go:125] [cacheMiss] Métricas não encontradas para o pod: default/test-deployment3-6c95cffb97-d2xv7
I0124 13:54:13.659315       1 scheduler.go:70] Estado no Informer: map[controller:test-controller3]
I0124 13:54:13.659353       1 scheduler.go:71] Estado real no cluster: map[controller:test-controller3]
W0124 13:54:13.659369       1 scheduler.go:135] [WaitForPodsOnCache] Pod test-deployment3-6c95cffb97-d2xv7 não encontrado no cache. Tentando novamente...
I0124 13:54:13.760008       1 scheduler.go:606] [GetControllerMetricInfo] Iniciando para o pod: default/test-deployment3-6c95cffb97-d2xv7
I0124 13:54:13.760462       1 scheduler.go:611] [GetControllerMetricInfo] Obtendo o nome do controlador para o pod: default/test-deployment3-6c95cffb97-d2xv7
I0124 13:54:13.760987       1 types.go:743] [ControllerName] Verificando as anotações do pod default/test-deployment3-6c95cffb97-d2xv7
I0124 13:54:13.761210       1 types.go:761] [ControllerName] Anotação 'controller' encontrada para o pod default/test-deployment3-6c95cffb97-d2xv7: test-controller3
I0124 13:54:13.761348       1 scheduler.go:614] [GetControllerMetricInfo] Métricas do controlador definidas para o pod: default/test-deployment3-6c95cffb97-d2xv7
W0124 13:54:13.761461       1 scheduler.go:125] [cacheMiss] Métricas não encontradas para o pod: default/test-deployment3-6c95cffb97-d2xv7
I0124 13:54:13.768530       1 scheduler.go:70] Estado no Informer: map[controller:test-controller3]
I0124 13:54:13.768625       1 scheduler.go:71] Estado real no cluster: map[controller:test-controller3]
W0124 13:54:13.768646       1 scheduler.go:135] [WaitForPodsOnCache] Pod test-deployment3-6c95cffb97-d2xv7 não encontrado no cache. Tentando novamente...
I0124 13:54:13.868911       1 scheduler.go:606] [GetControllerMetricInfo] Iniciando para o pod: default/test-deployment3-6c95cffb97-d2xv7
I0124 13:54:13.869007       1 scheduler.go:611] [GetControllerMetricInfo] Obtendo o nome do controlador para o pod: default/test-deployment3-6c95cffb97-d2xv7
I0124 13:54:13.869025       1 types.go:743] [ControllerName] Verificando as anotações do pod default/test-deployment3-6c95cffb97-d2xv7
I0124 13:54:13.869042       1 types.go:761] [ControllerName] Anotação 'controller' encontrada para o pod default/test-deployment3-6c95cffb97-d2xv7: test-controller3
I0124 13:54:13.869058       1 scheduler.go:614] [GetControllerMetricInfo] Métricas do controlador definidas para o pod: default/test-deployment3-6c95cffb97-d2xv7
W0124 13:54:13.869077       1 scheduler.go:125] [cacheMiss] Métricas não encontradas para o pod: default/test-deployment3-6c95cffb97-d2xv7
I0124 13:54:13.878712       1 scheduler.go:70] Estado no Informer: map[controller:test-controller3]
I0124 13:54:13.879216       1 scheduler.go:71] Estado real no cluster: map[controller:test-controller3]
W0124 13:54:13.879524       1 scheduler.go:135] [WaitForPodsOnCache] Pod test-deployment3-6c95cffb97-d2xv7 não encontrado no cache. Tentando novamente...
I0124 13:54:13.980275       1 scheduler.go:606] [GetControllerMetricInfo] Iniciando para o pod: default/test-deployment3-6c95cffb97-d2xv7
I0124 13:54:13.980689       1 scheduler.go:611] [GetControllerMetricInfo] Obtendo o nome do controlador para o pod: default/test-deployment3-6c95cffb97-d2xv7
I0124 13:54:13.981140       1 types.go:743] [ControllerName] Verificando as anotações do pod default/test-deployment3-6c95cffb97-d2xv7
I0124 13:54:13.981352       1 types.go:761] [ControllerName] Anotação 'controller' encontrada para o pod default/test-deployment3-6c95cffb97-d2xv7: test-controller3
I0124 13:54:13.981523       1 scheduler.go:614] [GetControllerMetricInfo] Métricas do controlador definidas para o pod: default/test-deployment3-6c95cffb97-d2xv7
W0124 13:54:13.981725       1 scheduler.go:125] [cacheMiss] Métricas não encontradas para o pod: default/test-deployment3-6c95cffb97-d2xv7
I0124 13:54:13.991060       1 scheduler.go:70] Estado no Informer: map[controller:test-controller3]
I0124 13:54:13.991457       1 scheduler.go:71] Estado real no cluster: map[controller:test-controller3]
W0124 13:54:13.991720       1 scheduler.go:135] [WaitForPodsOnCache] Pod test-deployment3-6c95cffb97-d2xv7 não encontrado no cache. Tentando novamente...
I0124 13:54:14.093623       1 scheduler.go:606] [GetControllerMetricInfo] Iniciando para o pod: default/test-deployment3-6c95cffb97-d2xv7
I0124 13:54:14.093673       1 scheduler.go:611] [GetControllerMetricInfo] Obtendo o nome do controlador para o pod: default/test-deployment3-6c95cffb97-d2xv7
I0124 13:54:14.093704       1 types.go:743] [ControllerName] Verificando as anotações do pod default/test-deployment3-6c95cffb97-d2xv7
I0124 13:54:14.093720       1 types.go:761] [ControllerName] Anotação 'controller' encontrada para o pod default/test-deployment3-6c95cffb97-d2xv7: test-controller3
I0124 13:54:14.093735       1 scheduler.go:614] [GetControllerMetricInfo] Métricas do controlador definidas para o pod: default/test-deployment3-6c95cffb97-d2xv7
W0124 13:54:14.093755       1 scheduler.go:125] [cacheMiss] Métricas não encontradas para o pod: default/test-deployment3-6c95cffb97-d2xv7
I0124 13:54:14.101599       1 scheduler.go:70] Estado no Informer: map[controller:test-controller3]
I0124 13:54:14.103772       1 scheduler.go:71] Estado real no cluster: map[controller:test-controller3]
W0124 13:54:14.104309       1 scheduler.go:135] [WaitForPodsOnCache] Pod test-deployment3-6c95cffb97-d2xv7 não encontrado no cache. Tentando novamente...
I0124 13:54:14.205642       1 scheduler.go:606] [GetControllerMetricInfo] Iniciando para o pod: default/test-deployment3-6c95cffb97-d2xv7
I0124 13:54:14.205733       1 scheduler.go:611] [GetControllerMetricInfo] Obtendo o nome do controlador para o pod: default/test-deployment3-6c95cffb97-d2xv7
I0124 13:54:14.205747       1 types.go:743] [ControllerName] Verificando as anotações do pod default/test-deployment3-6c95cffb97-d2xv7
I0124 13:54:14.205764       1 types.go:761] [ControllerName] Anotação 'controller' encontrada para o pod default/test-deployment3-6c95cffb97-d2xv7: test-controller3
I0124 13:54:14.205779       1 scheduler.go:614] [GetControllerMetricInfo] Métricas do controlador definidas para o pod: default/test-deployment3-6c95cffb97-d2xv7
W0124 13:54:14.205799       1 scheduler.go:125] [cacheMiss] Métricas não encontradas para o pod: default/test-deployment3-6c95cffb97-d2xv7
I0124 13:54:14.213256       1 scheduler.go:70] Estado no Informer: map[controller:test-controller3]
I0124 13:54:14.214071       1 scheduler.go:71] Estado real no cluster: map[controller:test-controller3]
W0124 13:54:14.214592       1 scheduler.go:135] [WaitForPodsOnCache] Pod test-deployment3-6c95cffb97-d2xv7 não encontrado no cache. Tentando novamente...
I0124 13:54:14.316239       1 scheduler.go:606] [GetControllerMetricInfo] Iniciando para o pod: default/test-deployment3-6c95cffb97-d2xv7
I0124 13:54:14.316817       1 scheduler.go:611] [GetControllerMetricInfo] Obtendo o nome do controlador para o pod: default/test-deployment3-6c95cffb97-d2xv7
I0124 13:54:14.317356       1 types.go:743] [ControllerName] Verificando as anotações do pod default/test-deployment3-6c95cffb97-d2xv7
I0124 13:54:14.317770       1 types.go:761] [ControllerName] Anotação 'controller' encontrada para o pod default/test-deployment3-6c95cffb97-d2xv7: test-controller3
I0124 13:54:14.318475       1 scheduler.go:614] [GetControllerMetricInfo] Métricas do controlador definidas para o pod: default/test-deployment3-6c95cffb97-d2xv7
W0124 13:54:14.318999       1 scheduler.go:125] [cacheMiss] Métricas não encontradas para o pod: default/test-deployment3-6c95cffb97-d2xv7
I0124 13:54:14.330662       1 scheduler.go:70] Estado no Informer: map[controller:test-controller3]
I0124 13:54:14.331172       1 scheduler.go:71] Estado real no cluster: map[controller:test-controller3]
W0124 13:54:14.332262       1 scheduler.go:135] [WaitForPodsOnCache] Pod test-deployment3-6c95cffb97-d2xv7 não encontrado no cache. Tentando novamente...
I0124 13:54:14.434405       1 scheduler.go:606] [GetControllerMetricInfo] Iniciando para o pod: default/test-deployment3-6c95cffb97-d2xv7
I0124 13:54:14.435815       1 scheduler.go:611] [GetControllerMetricInfo] Obtendo o nome do controlador para o pod: default/test-deployment3-6c95cffb97-d2xv7
I0124 13:54:14.436691       1 types.go:743] [ControllerName] Verificando as anotações do pod default/test-deployment3-6c95cffb97-d2xv7
I0124 13:54:14.437577       1 types.go:761] [ControllerName] Anotação 'controller' encontrada para o pod default/test-deployment3-6c95cffb97-d2xv7: test-controller3
I0124 13:54:14.438353       1 scheduler.go:614] [GetControllerMetricInfo] Métricas do controlador definidas para o pod: default/test-deployment3-6c95cffb97-d2xv7
W0124 13:54:14.438512       1 scheduler.go:125] [cacheMiss] Métricas não encontradas para o pod: default/test-deployment3-6c95cffb97-d2xv7
I0124 13:54:14.450309       1 scheduler.go:70] Estado no Informer: map[controller:test-controller3]
I0124 13:54:14.451031       1 scheduler.go:71] Estado real no cluster: map[controller:test-controller3]
W0124 13:54:14.452038       1 scheduler.go:135] [WaitForPodsOnCache] Pod test-deployment3-6c95cffb97-d2xv7 não encontrado no cache. Tentando novamente...
I0124 13:54:14.553832       1 scheduler.go:606] [GetControllerMetricInfo] Iniciando para o pod: default/test-deployment3-6c95cffb97-d2xv7
I0124 13:54:14.555680       1 scheduler.go:611] [GetControllerMetricInfo] Obtendo o nome do controlador para o pod: default/test-deployment3-6c95cffb97-d2xv7
I0124 13:54:14.556320       1 types.go:743] [ControllerName] Verificando as anotações do pod default/test-deployment3-6c95cffb97-d2xv7
I0124 13:54:14.556966       1 types.go:761] [ControllerName] Anotação 'controller' encontrada para o pod default/test-deployment3-6c95cffb97-d2xv7: test-controller3
I0124 13:54:14.557413       1 scheduler.go:614] [GetControllerMetricInfo] Métricas do controlador definidas para o pod: default/test-deployment3-6c95cffb97-d2xv7
W0124 13:54:14.558186       1 scheduler.go:125] [cacheMiss] Métricas não encontradas para o pod: default/test-deployment3-6c95cffb97-d2xv7
I0124 13:54:14.565769       1 scheduler.go:70] Estado no Informer: map[controller:test-controller3]
I0124 13:54:14.565815       1 scheduler.go:71] Estado real no cluster: map[controller:test-controller3]
W0124 13:54:14.565830       1 scheduler.go:135] [WaitForPodsOnCache] Pod test-deployment3-6c95cffb97-d2xv7 não encontrado no cache. Tentando novamente...
I0124 13:54:14.666707       1 scheduler.go:606] [GetControllerMetricInfo] Iniciando para o pod: default/test-deployment3-6c95cffb97-d2xv7
I0124 13:54:14.667054       1 scheduler.go:611] [GetControllerMetricInfo] Obtendo o nome do controlador para o pod: default/test-deployment3-6c95cffb97-d2xv7
I0124 13:54:14.667224       1 types.go:743] [ControllerName] Verificando as anotações do pod default/test-deployment3-6c95cffb97-d2xv7
I0124 13:54:14.667244       1 types.go:761] [ControllerName] Anotação 'controller' encontrada para o pod default/test-deployment3-6c95cffb97-d2xv7: test-controller3
I0124 13:54:14.667261       1 scheduler.go:614] [GetControllerMetricInfo] Métricas do controlador definidas para o pod: default/test-deployment3-6c95cffb97-d2xv7
W0124 13:54:14.667281       1 scheduler.go:125] [cacheMiss] Métricas não encontradas para o pod: default/test-deployment3-6c95cffb97-d2xv7
I0124 13:54:14.674274       1 scheduler.go:70] Estado no Informer: map[controller:test-controller3]
I0124 13:54:14.674779       1 scheduler.go:71] Estado real no cluster: map[controller:test-controller3]
W0124 13:54:14.675257       1 scheduler.go:135] [WaitForPodsOnCache] Pod test-deployment3-6c95cffb97-d2xv7 não encontrado no cache. Tentando novamente...
I0124 13:54:14.776051       1 scheduler.go:606] [GetControllerMetricInfo] Iniciando para o pod: default/test-deployment3-6c95cffb97-d2xv7
I0124 13:54:14.776195       1 scheduler.go:611] [GetControllerMetricInfo] Obtendo o nome do controlador para o pod: default/test-deployment3-6c95cffb97-d2xv7
I0124 13:54:14.776214       1 types.go:743] [ControllerName] Verificando as anotações do pod default/test-deployment3-6c95cffb97-d2xv7
I0124 13:54:14.776230       1 types.go:761] [ControllerName] Anotação 'controller' encontrada para o pod default/test-deployment3-6c95cffb97-d2xv7: test-controller3
I0124 13:54:14.776304       1 scheduler.go:614] [GetControllerMetricInfo] Métricas do controlador definidas para o pod: default/test-deployment3-6c95cffb97-d2xv7
W0124 13:54:14.776324       1 scheduler.go:125] [cacheMiss] Métricas não encontradas para o pod: default/test-deployment3-6c95cffb97-d2xv7
I0124 13:54:14.783463       1 scheduler.go:70] Estado no Informer: map[controller:test-controller3]
I0124 13:54:14.784038       1 scheduler.go:71] Estado real no cluster: map[controller:test-controller3]
W0124 13:54:14.784336       1 scheduler.go:135] [WaitForPodsOnCache] Pod test-deployment3-6c95cffb97-d2xv7 não encontrado no cache. Tentando novamente...
I0124 13:54:14.885045       1 scheduler.go:606] [GetControllerMetricInfo] Iniciando para o pod: default/test-deployment3-6c95cffb97-d2xv7
I0124 13:54:14.885294       1 scheduler.go:611] [GetControllerMetricInfo] Obtendo o nome do controlador para o pod: default/test-deployment3-6c95cffb97-d2xv7
I0124 13:54:14.885641       1 types.go:743] [ControllerName] Verificando as anotações do pod default/test-deployment3-6c95cffb97-d2xv7
I0124 13:54:14.886229       1 types.go:761] [ControllerName] Anotação 'controller' encontrada para o pod default/test-deployment3-6c95cffb97-d2xv7: test-controller3
I0124 13:54:14.886364       1 scheduler.go:614] [GetControllerMetricInfo] Métricas do controlador definidas para o pod: default/test-deployment3-6c95cffb97-d2xv7
W0124 13:54:14.886970       1 scheduler.go:125] [cacheMiss] Métricas não encontradas para o pod: default/test-deployment3-6c95cffb97-d2xv7
I0124 13:54:14.895212       1 scheduler.go:70] Estado no Informer: map[controller:test-controller3]
I0124 13:54:14.895620       1 scheduler.go:71] Estado real no cluster: map[controller:test-controller3]
W0124 13:54:14.895998       1 scheduler.go:135] [WaitForPodsOnCache] Pod test-deployment3-6c95cffb97-d2xv7 não encontrado no cache. Tentando novamente...
I0124 13:54:14.997270       1 scheduler.go:606] [GetControllerMetricInfo] Iniciando para o pod: default/test-deployment3-6c95cffb97-d2xv7
I0124 13:54:14.997326       1 scheduler.go:611] [GetControllerMetricInfo] Obtendo o nome do controlador para o pod: default/test-deployment3-6c95cffb97-d2xv7
I0124 13:54:14.997341       1 types.go:743] [ControllerName] Verificando as anotações do pod default/test-deployment3-6c95cffb97-d2xv7
I0124 13:54:14.997358       1 types.go:761] [ControllerName] Anotação 'controller' encontrada para o pod default/test-deployment3-6c95cffb97-d2xv7: test-controller3
I0124 13:54:14.997374       1 scheduler.go:614] [GetControllerMetricInfo] Métricas do controlador definidas para o pod: default/test-deployment3-6c95cffb97-d2xv7
W0124 13:54:14.997404       1 scheduler.go:125] [cacheMiss] Métricas não encontradas para o pod: default/test-deployment3-6c95cffb97-d2xv7
I0124 13:54:15.006373       1 scheduler.go:70] Estado no Informer: map[controller:test-controller3]
I0124 13:54:15.006991       1 scheduler.go:71] Estado real no cluster: map[controller:test-controller3]
W0124 13:54:15.007472       1 scheduler.go:135] [WaitForPodsOnCache] Pod test-deployment3-6c95cffb97-d2xv7 não encontrado no cache. Tentando novamente...
I0124 13:54:15.109175       1 scheduler.go:606] [GetControllerMetricInfo] Iniciando para o pod: default/test-deployment3-6c95cffb97-d2xv7
I0124 13:54:15.109274       1 scheduler.go:611] [GetControllerMetricInfo] Obtendo o nome do controlador para o pod: default/test-deployment3-6c95cffb97-d2xv7
I0124 13:54:15.109292       1 types.go:743] [ControllerName] Verificando as anotações do pod default/test-deployment3-6c95cffb97-d2xv7
I0124 13:54:15.109316       1 types.go:761] [ControllerName] Anotação 'controller' encontrada para o pod default/test-deployment3-6c95cffb97-d2xv7: test-controller3
I0124 13:54:15.109333       1 scheduler.go:614] [GetControllerMetricInfo] Métricas do controlador definidas para o pod: default/test-deployment3-6c95cffb97-d2xv7
W0124 13:54:15.109446       1 scheduler.go:125] [cacheMiss] Métricas não encontradas para o pod: default/test-deployment3-6c95cffb97-d2xv7
I0124 13:54:15.117065       1 scheduler.go:70] Estado no Informer: map[controller:test-controller3]
I0124 13:54:15.117166       1 scheduler.go:71] Estado real no cluster: map[controller:test-controller3]
W0124 13:54:15.117190       1 scheduler.go:135] [WaitForPodsOnCache] Pod test-deployment3-6c95cffb97-d2xv7 não encontrado no cache. Tentando novamente...
I0124 13:54:15.218036       1 scheduler.go:606] [GetControllerMetricInfo] Iniciando para o pod: default/test-deployment3-6c95cffb97-d2xv7
I0124 13:54:15.218088       1 scheduler.go:611] [GetControllerMetricInfo] Obtendo o nome do controlador para o pod: default/test-deployment3-6c95cffb97-d2xv7
I0124 13:54:15.218103       1 types.go:743] [ControllerName] Verificando as anotações do pod default/test-deployment3-6c95cffb97-d2xv7
I0124 13:54:15.218120       1 types.go:761] [ControllerName] Anotação 'controller' encontrada para o pod default/test-deployment3-6c95cffb97-d2xv7: test-controller3
I0124 13:54:15.218135       1 scheduler.go:614] [GetControllerMetricInfo] Métricas do controlador definidas para o pod: default/test-deployment3-6c95cffb97-d2xv7
W0124 13:54:15.218156       1 scheduler.go:125] [cacheMiss] Métricas não encontradas para o pod: default/test-deployment3-6c95cffb97-d2xv7
I0124 13:54:15.225436       1 scheduler.go:70] Estado no Informer: map[controller:test-controller3]
I0124 13:54:15.225482       1 scheduler.go:71] Estado real no cluster: map[controller:test-controller3]
W0124 13:54:15.225528       1 scheduler.go:135] [WaitForPodsOnCache] Pod test-deployment3-6c95cffb97-d2xv7 não encontrado no cache. Tentando novamente...
I0124 13:54:15.328514       1 scheduler.go:606] [GetControllerMetricInfo] Iniciando para o pod: default/test-deployment3-6c95cffb97-d2xv7
I0124 13:54:15.328815       1 scheduler.go:611] [GetControllerMetricInfo] Obtendo o nome do controlador para o pod: default/test-deployment3-6c95cffb97-d2xv7
I0124 13:54:15.329040       1 types.go:743] [ControllerName] Verificando as anotações do pod default/test-deployment3-6c95cffb97-d2xv7
I0124 13:54:15.329564       1 types.go:761] [ControllerName] Anotação 'controller' encontrada para o pod default/test-deployment3-6c95cffb97-d2xv7: test-controller3
I0124 13:54:15.329959       1 scheduler.go:614] [GetControllerMetricInfo] Métricas do controlador definidas para o pod: default/test-deployment3-6c95cffb97-d2xv7
W0124 13:54:15.330198       1 scheduler.go:125] [cacheMiss] Métricas não encontradas para o pod: default/test-deployment3-6c95cffb97-d2xv7
I0124 13:54:15.336457       1 scheduler.go:70] Estado no Informer: map[controller:test-controller3]
I0124 13:54:15.336570       1 scheduler.go:71] Estado real no cluster: map[controller:test-controller3]
W0124 13:54:15.336594       1 scheduler.go:135] [WaitForPodsOnCache] Pod test-deployment3-6c95cffb97-d2xv7 não encontrado no cache. Tentando novamente...
I0124 13:54:15.437610       1 scheduler.go:606] [GetControllerMetricInfo] Iniciando para o pod: default/test-deployment3-6c95cffb97-d2xv7
I0124 13:54:15.437803       1 scheduler.go:611] [GetControllerMetricInfo] Obtendo o nome do controlador para o pod: default/test-deployment3-6c95cffb97-d2xv7
I0124 13:54:15.437966       1 types.go:743] [ControllerName] Verificando as anotações do pod default/test-deployment3-6c95cffb97-d2xv7
I0124 13:54:15.438082       1 types.go:761] [ControllerName] Anotação 'controller' encontrada para o pod default/test-deployment3-6c95cffb97-d2xv7: test-controller3
I0124 13:54:15.438344       1 scheduler.go:614] [GetControllerMetricInfo] Métricas do controlador definidas para o pod: default/test-deployment3-6c95cffb97-d2xv7
W0124 13:54:15.438796       1 scheduler.go:125] [cacheMiss] Métricas não encontradas para o pod: default/test-deployment3-6c95cffb97-d2xv7
I0124 13:54:15.446741       1 scheduler.go:70] Estado no Informer: map[controller:test-controller3]
I0124 13:54:15.447611       1 scheduler.go:71] Estado real no cluster: map[controller:test-controller3]
W0124 13:54:15.447815       1 scheduler.go:135] [WaitForPodsOnCache] Pod test-deployment3-6c95cffb97-d2xv7 não encontrado no cache. Tentando novamente...
I0124 13:54:15.548969       1 scheduler.go:606] [GetControllerMetricInfo] Iniciando para o pod: default/test-deployment3-6c95cffb97-d2xv7
I0124 13:54:15.549091       1 scheduler.go:611] [GetControllerMetricInfo] Obtendo o nome do controlador para o pod: default/test-deployment3-6c95cffb97-d2xv7
I0124 13:54:15.549110       1 types.go:743] [ControllerName] Verificando as anotações do pod default/test-deployment3-6c95cffb97-d2xv7
I0124 13:54:15.549127       1 types.go:761] [ControllerName] Anotação 'controller' encontrada para o pod default/test-deployment3-6c95cffb97-d2xv7: test-controller3
I0124 13:54:15.549144       1 scheduler.go:614] [GetControllerMetricInfo] Métricas do controlador definidas para o pod: default/test-deployment3-6c95cffb97-d2xv7
W0124 13:54:15.549167       1 scheduler.go:125] [cacheMiss] Métricas não encontradas para o pod: default/test-deployment3-6c95cffb97-d2xv7
I0124 13:54:15.557610       1 scheduler.go:70] Estado no Informer: map[controller:test-controller3]
I0124 13:54:15.557732       1 scheduler.go:71] Estado real no cluster: map[controller:test-controller3]
W0124 13:54:15.557766       1 scheduler.go:135] [WaitForPodsOnCache] Pod test-deployment3-6c95cffb97-d2xv7 não encontrado no cache. Tentando novamente...
I0124 13:54:15.658729       1 scheduler.go:606] [GetControllerMetricInfo] Iniciando para o pod: default/test-deployment3-6c95cffb97-d2xv7
I0124 13:54:15.659476       1 scheduler.go:611] [GetControllerMetricInfo] Obtendo o nome do controlador para o pod: default/test-deployment3-6c95cffb97-d2xv7
I0124 13:54:15.659668       1 types.go:743] [ControllerName] Verificando as anotações do pod default/test-deployment3-6c95cffb97-d2xv7
I0124 13:54:15.659717       1 types.go:761] [ControllerName] Anotação 'controller' encontrada para o pod default/test-deployment3-6c95cffb97-d2xv7: test-controller3
I0124 13:54:15.660022       1 scheduler.go:614] [GetControllerMetricInfo] Métricas do controlador definidas para o pod: default/test-deployment3-6c95cffb97-d2xv7
W0124 13:54:15.661009       1 scheduler.go:125] [cacheMiss] Métricas não encontradas para o pod: default/test-deployment3-6c95cffb97-d2xv7
I0124 13:54:15.669207       1 scheduler.go:70] Estado no Informer: map[controller:test-controller3]
I0124 13:54:15.669700       1 scheduler.go:71] Estado real no cluster: map[controller:test-controller3]
W0124 13:54:15.670122       1 scheduler.go:135] [WaitForPodsOnCache] Pod test-deployment3-6c95cffb97-d2xv7 não encontrado no cache. Tentando novamente...
I0124 13:54:15.771286       1 scheduler.go:606] [GetControllerMetricInfo] Iniciando para o pod: default/test-deployment3-6c95cffb97-d2xv7
I0124 13:54:15.771344       1 scheduler.go:611] [GetControllerMetricInfo] Obtendo o nome do controlador para o pod: default/test-deployment3-6c95cffb97-d2xv7
I0124 13:54:15.771370       1 types.go:743] [ControllerName] Verificando as anotações do pod default/test-deployment3-6c95cffb97-d2xv7
I0124 13:54:15.771389       1 types.go:761] [ControllerName] Anotação 'controller' encontrada para o pod default/test-deployment3-6c95cffb97-d2xv7: test-controller3
I0124 13:54:15.772286       1 scheduler.go:614] [GetControllerMetricInfo] Métricas do controlador definidas para o pod: default/test-deployment3-6c95cffb97-d2xv7
W0124 13:54:15.772328       1 scheduler.go:125] [cacheMiss] Métricas não encontradas para o pod: default/test-deployment3-6c95cffb97-d2xv7
I0124 13:54:15.779533       1 scheduler.go:70] Estado no Informer: map[controller:test-controller3]
I0124 13:54:15.780036       1 scheduler.go:71] Estado real no cluster: map[controller:test-controller3]
W0124 13:54:15.780420       1 scheduler.go:135] [WaitForPodsOnCache] Pod test-deployment3-6c95cffb97-d2xv7 não encontrado no cache. Tentando novamente...
I0124 13:54:15.880709       1 scheduler.go:606] [GetControllerMetricInfo] Iniciando para o pod: default/test-deployment3-6c95cffb97-d2xv7
I0124 13:54:15.880760       1 scheduler.go:611] [GetControllerMetricInfo] Obtendo o nome do controlador para o pod: default/test-deployment3-6c95cffb97-d2xv7
I0124 13:54:15.880776       1 types.go:743] [ControllerName] Verificando as anotações do pod default/test-deployment3-6c95cffb97-d2xv7
I0124 13:54:15.880793       1 types.go:761] [ControllerName] Anotação 'controller' encontrada para o pod default/test-deployment3-6c95cffb97-d2xv7: test-controller3
I0124 13:54:15.880809       1 scheduler.go:614] [GetControllerMetricInfo] Métricas do controlador definidas para o pod: default/test-deployment3-6c95cffb97-d2xv7
W0124 13:54:15.881479       1 scheduler.go:125] [cacheMiss] Métricas não encontradas para o pod: default/test-deployment3-6c95cffb97-d2xv7
I0124 13:54:15.888815       1 scheduler.go:70] Estado no Informer: map[controller:test-controller3]
I0124 13:54:15.889752       1 scheduler.go:71] Estado real no cluster: map[controller:test-controller3]
W0124 13:54:15.890432       1 scheduler.go:135] [WaitForPodsOnCache] Pod test-deployment3-6c95cffb97-d2xv7 não encontrado no cache. Tentando novamente...
I0124 13:54:15.993208       1 scheduler.go:606] [GetControllerMetricInfo] Iniciando para o pod: default/test-deployment3-6c95cffb97-d2xv7
I0124 13:54:15.993256       1 scheduler.go:611] [GetControllerMetricInfo] Obtendo o nome do controlador para o pod: default/test-deployment3-6c95cffb97-d2xv7
I0124 13:54:15.993270       1 types.go:743] [ControllerName] Verificando as anotações do pod default/test-deployment3-6c95cffb97-d2xv7
I0124 13:54:15.993286       1 types.go:761] [ControllerName] Anotação 'controller' encontrada para o pod default/test-deployment3-6c95cffb97-d2xv7: test-controller3
I0124 13:54:15.993301       1 scheduler.go:614] [GetControllerMetricInfo] Métricas do controlador definidas para o pod: default/test-deployment3-6c95cffb97-d2xv7
W0124 13:54:15.993321       1 scheduler.go:125] [cacheMiss] Métricas não encontradas para o pod: default/test-deployment3-6c95cffb97-d2xv7
I0124 13:54:16.005774       1 scheduler.go:70] Estado no Informer: map[controller:test-controller3]
I0124 13:54:16.006570       1 scheduler.go:71] Estado real no cluster: map[controller:test-controller3]
W0124 13:54:16.006979       1 scheduler.go:135] [WaitForPodsOnCache] Pod test-deployment3-6c95cffb97-d2xv7 não encontrado no cache. Tentando novamente...
I0124 13:54:16.107348       1 scheduler.go:606] [GetControllerMetricInfo] Iniciando para o pod: default/test-deployment3-6c95cffb97-d2xv7
I0124 13:54:16.111838       1 scheduler.go:611] [GetControllerMetricInfo] Obtendo o nome do controlador para o pod: default/test-deployment3-6c95cffb97-d2xv7
I0124 13:54:16.112375       1 types.go:743] [ControllerName] Verificando as anotações do pod default/test-deployment3-6c95cffb97-d2xv7
I0124 13:54:16.112482       1 types.go:761] [ControllerName] Anotação 'controller' encontrada para o pod default/test-deployment3-6c95cffb97-d2xv7: test-controller3
I0124 13:54:16.112505       1 scheduler.go:614] [GetControllerMetricInfo] Métricas do controlador definidas para o pod: default/test-deployment3-6c95cffb97-d2xv7
W0124 13:54:16.112575       1 scheduler.go:125] [cacheMiss] Métricas não encontradas para o pod: default/test-deployment3-6c95cffb97-d2xv7
I0124 13:54:16.119803       1 scheduler.go:70] Estado no Informer: map[controller:test-controller3]
I0124 13:54:16.120310       1 scheduler.go:71] Estado real no cluster: map[controller:test-controller3]
W0124 13:54:16.120768       1 scheduler.go:135] [WaitForPodsOnCache] Pod test-deployment3-6c95cffb97-d2xv7 não encontrado no cache. Tentando novamente...
I0124 13:54:16.222108       1 scheduler.go:606] [GetControllerMetricInfo] Iniciando para o pod: default/test-deployment3-6c95cffb97-d2xv7
I0124 13:54:16.222384       1 scheduler.go:611] [GetControllerMetricInfo] Obtendo o nome do controlador para o pod: default/test-deployment3-6c95cffb97-d2xv7
I0124 13:54:16.222398       1 types.go:743] [ControllerName] Verificando as anotações do pod default/test-deployment3-6c95cffb97-d2xv7
I0124 13:54:16.222509       1 types.go:761] [ControllerName] Anotação 'controller' encontrada para o pod default/test-deployment3-6c95cffb97-d2xv7: test-controller3
I0124 13:54:16.222525       1 scheduler.go:614] [GetControllerMetricInfo] Métricas do controlador definidas para o pod: default/test-deployment3-6c95cffb97-d2xv7
W0124 13:54:16.222656       1 scheduler.go:125] [cacheMiss] Métricas não encontradas para o pod: default/test-deployment3-6c95cffb97-d2xv7
I0124 13:54:16.230066       1 scheduler.go:70] Estado no Informer: map[controller:test-controller3]
I0124 13:54:16.230177       1 scheduler.go:71] Estado real no cluster: map[controller:test-controller3]
W0124 13:54:16.230195       1 scheduler.go:135] [WaitForPodsOnCache] Pod test-deployment3-6c95cffb97-d2xv7 não encontrado no cache. Tentando novamente...
I0124 13:54:16.330753       1 scheduler.go:606] [GetControllerMetricInfo] Iniciando para o pod: default/test-deployment3-6c95cffb97-d2xv7
I0124 13:54:16.330937       1 scheduler.go:611] [GetControllerMetricInfo] Obtendo o nome do controlador para o pod: default/test-deployment3-6c95cffb97-d2xv7
I0124 13:54:16.330948       1 types.go:743] [ControllerName] Verificando as anotações do pod default/test-deployment3-6c95cffb97-d2xv7
I0124 13:54:16.330956       1 types.go:761] [ControllerName] Anotação 'controller' encontrada para o pod default/test-deployment3-6c95cffb97-d2xv7: test-controller3
I0124 13:54:16.330964       1 scheduler.go:614] [GetControllerMetricInfo] Métricas do controlador definidas para o pod: default/test-deployment3-6c95cffb97-d2xv7
W0124 13:54:16.330977       1 scheduler.go:125] [cacheMiss] Métricas não encontradas para o pod: default/test-deployment3-6c95cffb97-d2xv7
I0124 13:54:16.348432       1 scheduler.go:70] Estado no Informer: map[controller:test-controller3]
I0124 13:54:16.348486       1 scheduler.go:71] Estado real no cluster: map[controller:test-controller3]
W0124 13:54:16.348503       1 scheduler.go:135] [WaitForPodsOnCache] Pod test-deployment3-6c95cffb97-d2xv7 não encontrado no cache. Tentando novamente...
I0124 13:54:16.449474       1 scheduler.go:606] [GetControllerMetricInfo] Iniciando para o pod: default/test-deployment3-6c95cffb97-d2xv7
I0124 13:54:16.449635       1 scheduler.go:611] [GetControllerMetricInfo] Obtendo o nome do controlador para o pod: default/test-deployment3-6c95cffb97-d2xv7
I0124 13:54:16.450474       1 types.go:743] [ControllerName] Verificando as anotações do pod default/test-deployment3-6c95cffb97-d2xv7
I0124 13:54:16.450601       1 types.go:761] [ControllerName] Anotação 'controller' encontrada para o pod default/test-deployment3-6c95cffb97-d2xv7: test-controller3
I0124 13:54:16.450634       1 scheduler.go:614] [GetControllerMetricInfo] Métricas do controlador definidas para o pod: default/test-deployment3-6c95cffb97-d2xv7
W0124 13:54:16.450669       1 scheduler.go:125] [cacheMiss] Métricas não encontradas para o pod: default/test-deployment3-6c95cffb97-d2xv7
I0124 13:54:16.459424       1 scheduler.go:70] Estado no Informer: map[controller:test-controller3]
I0124 13:54:16.459576       1 scheduler.go:71] Estado real no cluster: map[controller:test-controller3]
W0124 13:54:16.460635       1 scheduler.go:135] [WaitForPodsOnCache] Pod test-deployment3-6c95cffb97-d2xv7 não encontrado no cache. Tentando novamente...
I0124 13:54:16.561397       1 scheduler.go:606] [GetControllerMetricInfo] Iniciando para o pod: default/test-deployment3-6c95cffb97-d2xv7
I0124 13:54:16.561533       1 scheduler.go:611] [GetControllerMetricInfo] Obtendo o nome do controlador para o pod: default/test-deployment3-6c95cffb97-d2xv7
I0124 13:54:16.561552       1 types.go:743] [ControllerName] Verificando as anotações do pod default/test-deployment3-6c95cffb97-d2xv7
I0124 13:54:16.561569       1 types.go:761] [ControllerName] Anotação 'controller' encontrada para o pod default/test-deployment3-6c95cffb97-d2xv7: test-controller3
I0124 13:54:16.561598       1 scheduler.go:614] [GetControllerMetricInfo] Métricas do controlador definidas para o pod: default/test-deployment3-6c95cffb97-d2xv7
W0124 13:54:16.562471       1 scheduler.go:125] [cacheMiss] Métricas não encontradas para o pod: default/test-deployment3-6c95cffb97-d2xv7
I0124 13:54:16.571234       1 scheduler.go:70] Estado no Informer: map[controller:test-controller3]
I0124 13:54:16.571367       1 scheduler.go:71] Estado real no cluster: map[controller:test-controller3]
W0124 13:54:16.571401       1 scheduler.go:135] [WaitForPodsOnCache] Pod test-deployment3-6c95cffb97-d2xv7 não encontrado no cache. Tentando novamente...
I0124 13:54:16.672166       1 scheduler.go:606] [GetControllerMetricInfo] Iniciando para o pod: default/test-deployment3-6c95cffb97-d2xv7
I0124 13:54:16.673061       1 scheduler.go:611] [GetControllerMetricInfo] Obtendo o nome do controlador para o pod: default/test-deployment3-6c95cffb97-d2xv7
I0124 13:54:16.673463       1 types.go:743] [ControllerName] Verificando as anotações do pod default/test-deployment3-6c95cffb97-d2xv7
I0124 13:54:16.673689       1 types.go:761] [ControllerName] Anotação 'controller' encontrada para o pod default/test-deployment3-6c95cffb97-d2xv7: test-controller3
I0124 13:54:16.673994       1 scheduler.go:614] [GetControllerMetricInfo] Métricas do controlador definidas para o pod: default/test-deployment3-6c95cffb97-d2xv7
W0124 13:54:16.674122       1 scheduler.go:125] [cacheMiss] Métricas não encontradas para o pod: default/test-deployment3-6c95cffb97-d2xv7
I0124 13:54:16.690813       1 scheduler.go:70] Estado no Informer: map[controller:test-controller3]
I0124 13:54:16.691229       1 scheduler.go:71] Estado real no cluster: map[controller:test-controller3]
W0124 13:54:16.691445       1 scheduler.go:135] [WaitForPodsOnCache] Pod test-deployment3-6c95cffb97-d2xv7 não encontrado no cache. Tentando novamente...
I0124 13:54:16.792442       1 scheduler.go:606] [GetControllerMetricInfo] Iniciando para o pod: default/test-deployment3-6c95cffb97-d2xv7
I0124 13:54:16.792670       1 scheduler.go:611] [GetControllerMetricInfo] Obtendo o nome do controlador para o pod: default/test-deployment3-6c95cffb97-d2xv7
I0124 13:54:16.792790       1 types.go:743] [ControllerName] Verificando as anotações do pod default/test-deployment3-6c95cffb97-d2xv7
I0124 13:54:16.793766       1 types.go:761] [ControllerName] Anotação 'controller' encontrada para o pod default/test-deployment3-6c95cffb97-d2xv7: test-controller3
I0124 13:54:16.794425       1 scheduler.go:614] [GetControllerMetricInfo] Métricas do controlador definidas para o pod: default/test-deployment3-6c95cffb97-d2xv7
W0124 13:54:16.794949       1 scheduler.go:125] [cacheMiss] Métricas não encontradas para o pod: default/test-deployment3-6c95cffb97-d2xv7
I0124 13:54:16.802698       1 scheduler.go:70] Estado no Informer: map[controller:test-controller3]
I0124 13:54:16.803218       1 scheduler.go:71] Estado real no cluster: map[controller:test-controller3]
W0124 13:54:16.803508       1 scheduler.go:135] [WaitForPodsOnCache] Pod test-deployment3-6c95cffb97-d2xv7 não encontrado no cache. Tentando novamente...
I0124 13:54:16.905564       1 scheduler.go:606] [GetControllerMetricInfo] Iniciando para o pod: default/test-deployment3-6c95cffb97-d2xv7
I0124 13:54:16.905671       1 scheduler.go:611] [GetControllerMetricInfo] Obtendo o nome do controlador para o pod: default/test-deployment3-6c95cffb97-d2xv7
I0124 13:54:16.905696       1 types.go:743] [ControllerName] Verificando as anotações do pod default/test-deployment3-6c95cffb97-d2xv7
I0124 13:54:16.905722       1 types.go:761] [ControllerName] Anotação 'controller' encontrada para o pod default/test-deployment3-6c95cffb97-d2xv7: test-controller3
I0124 13:54:16.905746       1 scheduler.go:614] [GetControllerMetricInfo] Métricas do controlador definidas para o pod: default/test-deployment3-6c95cffb97-d2xv7
W0124 13:54:16.905766       1 scheduler.go:125] [cacheMiss] Métricas não encontradas para o pod: default/test-deployment3-6c95cffb97-d2xv7
I0124 13:54:16.913558       1 scheduler.go:70] Estado no Informer: map[controller:test-controller3]
I0124 13:54:16.914086       1 scheduler.go:71] Estado real no cluster: map[controller:test-controller3]
W0124 13:54:16.914566       1 scheduler.go:135] [WaitForPodsOnCache] Pod test-deployment3-6c95cffb97-d2xv7 não encontrado no cache. Tentando novamente...
I0124 13:54:17.015711       1 scheduler.go:606] [GetControllerMetricInfo] Iniciando para o pod: default/test-deployment3-6c95cffb97-d2xv7
I0124 13:54:17.015761       1 scheduler.go:611] [GetControllerMetricInfo] Obtendo o nome do controlador para o pod: default/test-deployment3-6c95cffb97-d2xv7
I0124 13:54:17.015776       1 types.go:743] [ControllerName] Verificando as anotações do pod default/test-deployment3-6c95cffb97-d2xv7
I0124 13:54:17.015793       1 types.go:761] [ControllerName] Anotação 'controller' encontrada para o pod default/test-deployment3-6c95cffb97-d2xv7: test-controller3
I0124 13:54:17.015810       1 scheduler.go:614] [GetControllerMetricInfo] Métricas do controlador definidas para o pod: default/test-deployment3-6c95cffb97-d2xv7
W0124 13:54:17.015829       1 scheduler.go:125] [cacheMiss] Métricas não encontradas para o pod: default/test-deployment3-6c95cffb97-d2xv7
I0124 13:54:17.027142       1 scheduler.go:70] Estado no Informer: map[controller:test-controller3]
I0124 13:54:17.027728       1 scheduler.go:71] Estado real no cluster: map[controller:test-controller3]
W0124 13:54:17.028233       1 scheduler.go:135] [WaitForPodsOnCache] Pod test-deployment3-6c95cffb97-d2xv7 não encontrado no cache. Tentando novamente...
I0124 13:54:17.129348       1 scheduler.go:606] [GetControllerMetricInfo] Iniciando para o pod: default/test-deployment3-6c95cffb97-d2xv7
I0124 13:54:17.130115       1 scheduler.go:611] [GetControllerMetricInfo] Obtendo o nome do controlador para o pod: default/test-deployment3-6c95cffb97-d2xv7
I0124 13:54:17.130208       1 types.go:743] [ControllerName] Verificando as anotações do pod default/test-deployment3-6c95cffb97-d2xv7
I0124 13:54:17.130231       1 types.go:761] [ControllerName] Anotação 'controller' encontrada para o pod default/test-deployment3-6c95cffb97-d2xv7: test-controller3
I0124 13:54:17.130253       1 scheduler.go:614] [GetControllerMetricInfo] Métricas do controlador definidas para o pod: default/test-deployment3-6c95cffb97-d2xv7
W0124 13:54:17.130288       1 scheduler.go:125] [cacheMiss] Métricas não encontradas para o pod: default/test-deployment3-6c95cffb97-d2xv7
I0124 13:54:17.138311       1 scheduler.go:70] Estado no Informer: map[controller:test-controller3]
I0124 13:54:17.138357       1 scheduler.go:71] Estado real no cluster: map[controller:test-controller3]
W0124 13:54:17.138376       1 scheduler.go:135] [WaitForPodsOnCache] Pod test-deployment3-6c95cffb97-d2xv7 não encontrado no cache. Tentando novamente...
I0124 13:54:17.239309       1 scheduler.go:606] [GetControllerMetricInfo] Iniciando para o pod: default/test-deployment3-6c95cffb97-d2xv7
I0124 13:54:17.239476       1 scheduler.go:611] [GetControllerMetricInfo] Obtendo o nome do controlador para o pod: default/test-deployment3-6c95cffb97-d2xv7
I0124 13:54:17.239498       1 types.go:743] [ControllerName] Verificando as anotações do pod default/test-deployment3-6c95cffb97-d2xv7
I0124 13:54:17.239516       1 types.go:761] [ControllerName] Anotação 'controller' encontrada para o pod default/test-deployment3-6c95cffb97-d2xv7: test-controller3
I0124 13:54:17.239533       1 scheduler.go:614] [GetControllerMetricInfo] Métricas do controlador definidas para o pod: default/test-deployment3-6c95cffb97-d2xv7
W0124 13:54:17.239554       1 scheduler.go:125] [cacheMiss] Métricas não encontradas para o pod: default/test-deployment3-6c95cffb97-d2xv7
I0124 13:54:17.263152       1 scheduler.go:70] Estado no Informer: map[controller:test-controller3]
I0124 13:54:17.263723       1 scheduler.go:71] Estado real no cluster: map[controller:test-controller3]
W0124 13:54:17.263955       1 scheduler.go:135] [WaitForPodsOnCache] Pod test-deployment3-6c95cffb97-d2xv7 não encontrado no cache. Tentando novamente...
I0124 13:54:17.365054       1 scheduler.go:606] [GetControllerMetricInfo] Iniciando para o pod: default/test-deployment3-6c95cffb97-d2xv7
I0124 13:54:17.365640       1 scheduler.go:611] [GetControllerMetricInfo] Obtendo o nome do controlador para o pod: default/test-deployment3-6c95cffb97-d2xv7
I0124 13:54:17.366147       1 types.go:743] [ControllerName] Verificando as anotações do pod default/test-deployment3-6c95cffb97-d2xv7
I0124 13:54:17.366494       1 types.go:761] [ControllerName] Anotação 'controller' encontrada para o pod default/test-deployment3-6c95cffb97-d2xv7: test-controller3
I0124 13:54:17.367537       1 scheduler.go:614] [GetControllerMetricInfo] Métricas do controlador definidas para o pod: default/test-deployment3-6c95cffb97-d2xv7
W0124 13:54:17.368014       1 scheduler.go:125] [cacheMiss] Métricas não encontradas para o pod: default/test-deployment3-6c95cffb97-d2xv7
I0124 13:54:17.377045       1 scheduler.go:70] Estado no Informer: map[controller:test-controller3]
I0124 13:54:17.377541       1 scheduler.go:71] Estado real no cluster: map[controller:test-controller3]
W0124 13:54:17.378068       1 scheduler.go:135] [WaitForPodsOnCache] Pod test-deployment3-6c95cffb97-d2xv7 não encontrado no cache. Tentando novamente...
I0124 13:54:17.480013       1 scheduler.go:606] [GetControllerMetricInfo] Iniciando para o pod: default/test-deployment3-6c95cffb97-d2xv7
I0124 13:54:17.480745       1 scheduler.go:611] [GetControllerMetricInfo] Obtendo o nome do controlador para o pod: default/test-deployment3-6c95cffb97-d2xv7
I0124 13:54:17.481282       1 types.go:743] [ControllerName] Verificando as anotações do pod default/test-deployment3-6c95cffb97-d2xv7
I0124 13:54:17.482570       1 types.go:761] [ControllerName] Anotação 'controller' encontrada para o pod default/test-deployment3-6c95cffb97-d2xv7: test-controller3
I0124 13:54:17.482680       1 scheduler.go:614] [GetControllerMetricInfo] Métricas do controlador definidas para o pod: default/test-deployment3-6c95cffb97-d2xv7
W0124 13:54:17.482717       1 scheduler.go:125] [cacheMiss] Métricas não encontradas para o pod: default/test-deployment3-6c95cffb97-d2xv7
I0124 13:54:17.496348       1 scheduler.go:70] Estado no Informer: map[controller:test-controller3]
I0124 13:54:17.497438       1 scheduler.go:71] Estado real no cluster: map[controller:test-controller3]
W0124 13:54:17.498269       1 scheduler.go:135] [WaitForPodsOnCache] Pod test-deployment3-6c95cffb97-d2xv7 não encontrado no cache. Tentando novamente...
I0124 13:54:17.598722       1 scheduler.go:606] [GetControllerMetricInfo] Iniciando para o pod: default/test-deployment3-6c95cffb97-d2xv7
I0124 13:54:17.598772       1 scheduler.go:611] [GetControllerMetricInfo] Obtendo o nome do controlador para o pod: default/test-deployment3-6c95cffb97-d2xv7
I0124 13:54:17.598795       1 types.go:743] [ControllerName] Verificando as anotações do pod default/test-deployment3-6c95cffb97-d2xv7
I0124 13:54:17.598818       1 types.go:761] [ControllerName] Anotação 'controller' encontrada para o pod default/test-deployment3-6c95cffb97-d2xv7: test-controller3
I0124 13:54:17.598844       1 scheduler.go:614] [GetControllerMetricInfo] Métricas do controlador definidas para o pod: default/test-deployment3-6c95cffb97-d2xv7
W0124 13:54:17.600013       1 scheduler.go:125] [cacheMiss] Métricas não encontradas para o pod: default/test-deployment3-6c95cffb97-d2xv7
I0124 13:54:17.612697       1 scheduler.go:70] Estado no Informer: map[controller:test-controller3]
I0124 13:54:17.612823       1 scheduler.go:71] Estado real no cluster: map[controller:test-controller3]
W0124 13:54:17.612994       1 scheduler.go:135] [WaitForPodsOnCache] Pod test-deployment3-6c95cffb97-d2xv7 não encontrado no cache. Tentando novamente...
I0124 13:54:17.713587       1 scheduler.go:606] [GetControllerMetricInfo] Iniciando para o pod: default/test-deployment3-6c95cffb97-d2xv7
I0124 13:54:17.713701       1 scheduler.go:611] [GetControllerMetricInfo] Obtendo o nome do controlador para o pod: default/test-deployment3-6c95cffb97-d2xv7
I0124 13:54:17.713720       1 types.go:743] [ControllerName] Verificando as anotações do pod default/test-deployment3-6c95cffb97-d2xv7
I0124 13:54:17.713746       1 types.go:761] [ControllerName] Anotação 'controller' encontrada para o pod default/test-deployment3-6c95cffb97-d2xv7: test-controller3
I0124 13:54:17.713774       1 scheduler.go:614] [GetControllerMetricInfo] Métricas do controlador definidas para o pod: default/test-deployment3-6c95cffb97-d2xv7
W0124 13:54:17.713795       1 scheduler.go:125] [cacheMiss] Métricas não encontradas para o pod: default/test-deployment3-6c95cffb97-d2xv7
I0124 13:54:17.722426       1 scheduler.go:70] Estado no Informer: map[controller:test-controller3]
I0124 13:54:17.722534       1 scheduler.go:71] Estado real no cluster: map[controller:test-controller3]
W0124 13:54:17.722587       1 scheduler.go:135] [WaitForPodsOnCache] Pod test-deployment3-6c95cffb97-d2xv7 não encontrado no cache. Tentando novamente...
I0124 13:54:17.823398       1 scheduler.go:606] [GetControllerMetricInfo] Iniciando para o pod: default/test-deployment3-6c95cffb97-d2xv7
I0124 13:54:17.823529       1 scheduler.go:611] [GetControllerMetricInfo] Obtendo o nome do controlador para o pod: default/test-deployment3-6c95cffb97-d2xv7
I0124 13:54:17.823557       1 types.go:743] [ControllerName] Verificando as anotações do pod default/test-deployment3-6c95cffb97-d2xv7
I0124 13:54:17.823584       1 types.go:761] [ControllerName] Anotação 'controller' encontrada para o pod default/test-deployment3-6c95cffb97-d2xv7: test-controller3
I0124 13:54:17.823614       1 scheduler.go:614] [GetControllerMetricInfo] Métricas do controlador definidas para o pod: default/test-deployment3-6c95cffb97-d2xv7
W0124 13:54:17.824188       1 scheduler.go:125] [cacheMiss] Métricas não encontradas para o pod: default/test-deployment3-6c95cffb97-d2xv7
I0124 13:54:17.830677       1 scheduler.go:70] Estado no Informer: map[controller:test-controller3]
I0124 13:54:17.831265       1 scheduler.go:71] Estado real no cluster: map[controller:test-controller3]
W0124 13:54:17.831716       1 scheduler.go:135] [WaitForPodsOnCache] Pod test-deployment3-6c95cffb97-d2xv7 não encontrado no cache. Tentando novamente...
I0124 13:54:17.933612       1 scheduler.go:606] [GetControllerMetricInfo] Iniciando para o pod: default/test-deployment3-6c95cffb97-d2xv7
I0124 13:54:17.933722       1 scheduler.go:611] [GetControllerMetricInfo] Obtendo o nome do controlador para o pod: default/test-deployment3-6c95cffb97-d2xv7
I0124 13:54:17.933741       1 types.go:743] [ControllerName] Verificando as anotações do pod default/test-deployment3-6c95cffb97-d2xv7
I0124 13:54:17.933759       1 types.go:761] [ControllerName] Anotação 'controller' encontrada para o pod default/test-deployment3-6c95cffb97-d2xv7: test-controller3
I0124 13:54:17.933776       1 scheduler.go:614] [GetControllerMetricInfo] Métricas do controlador definidas para o pod: default/test-deployment3-6c95cffb97-d2xv7
W0124 13:54:17.933796       1 scheduler.go:125] [cacheMiss] Métricas não encontradas para o pod: default/test-deployment3-6c95cffb97-d2xv7
I0124 13:54:17.941514       1 scheduler.go:70] Estado no Informer: map[controller:test-controller3]
I0124 13:54:17.942077       1 scheduler.go:71] Estado real no cluster: map[controller:test-controller3]
W0124 13:54:17.942372       1 scheduler.go:135] [WaitForPodsOnCache] Pod test-deployment3-6c95cffb97-d2xv7 não encontrado no cache. Tentando novamente...
I0124 13:54:18.043756       1 scheduler.go:606] [GetControllerMetricInfo] Iniciando para o pod: default/test-deployment3-6c95cffb97-d2xv7
I0124 13:54:18.043820       1 scheduler.go:611] [GetControllerMetricInfo] Obtendo o nome do controlador para o pod: default/test-deployment3-6c95cffb97-d2xv7
I0124 13:54:18.043844       1 types.go:743] [ControllerName] Verificando as anotações do pod default/test-deployment3-6c95cffb97-d2xv7
I0124 13:54:18.044036       1 types.go:761] [ControllerName] Anotação 'controller' encontrada para o pod default/test-deployment3-6c95cffb97-d2xv7: test-controller3
I0124 13:54:18.044065       1 scheduler.go:614] [GetControllerMetricInfo] Métricas do controlador definidas para o pod: default/test-deployment3-6c95cffb97-d2xv7
W0124 13:54:18.044636       1 scheduler.go:125] [cacheMiss] Métricas não encontradas para o pod: default/test-deployment3-6c95cffb97-d2xv7
I0124 13:54:18.054787       1 scheduler.go:70] Estado no Informer: map[controller:test-controller3]
I0124 13:54:18.055138       1 scheduler.go:71] Estado real no cluster: map[controller:test-controller3]
W0124 13:54:18.056268       1 scheduler.go:135] [WaitForPodsOnCache] Pod test-deployment3-6c95cffb97-d2xv7 não encontrado no cache. Tentando novamente...
I0124 13:54:18.157081       1 scheduler.go:606] [GetControllerMetricInfo] Iniciando para o pod: default/test-deployment3-6c95cffb97-d2xv7
I0124 13:54:18.157831       1 scheduler.go:611] [GetControllerMetricInfo] Obtendo o nome do controlador para o pod: default/test-deployment3-6c95cffb97-d2xv7
I0124 13:54:18.158503       1 types.go:743] [ControllerName] Verificando as anotações do pod default/test-deployment3-6c95cffb97-d2xv7
I0124 13:54:18.159070       1 types.go:761] [ControllerName] Anotação 'controller' encontrada para o pod default/test-deployment3-6c95cffb97-d2xv7: test-controller3
I0124 13:54:18.159351       1 scheduler.go:614] [GetControllerMetricInfo] Métricas do controlador definidas para o pod: default/test-deployment3-6c95cffb97-d2xv7
W0124 13:54:18.159702       1 scheduler.go:125] [cacheMiss] Métricas não encontradas para o pod: default/test-deployment3-6c95cffb97-d2xv7
I0124 13:54:18.169545       1 scheduler.go:70] Estado no Informer: map[controller:test-controller3]
I0124 13:54:18.169665       1 scheduler.go:71] Estado real no cluster: map[controller:test-controller3]
W0124 13:54:18.169688       1 scheduler.go:135] [WaitForPodsOnCache] Pod test-deployment3-6c95cffb97-d2xv7 não encontrado no cache. Tentando novamente...
I0124 13:54:18.271042       1 scheduler.go:606] [GetControllerMetricInfo] Iniciando para o pod: default/test-deployment3-6c95cffb97-d2xv7
I0124 13:54:18.271154       1 scheduler.go:611] [GetControllerMetricInfo] Obtendo o nome do controlador para o pod: default/test-deployment3-6c95cffb97-d2xv7
I0124 13:54:18.271174       1 types.go:743] [ControllerName] Verificando as anotações do pod default/test-deployment3-6c95cffb97-d2xv7
I0124 13:54:18.271190       1 types.go:761] [ControllerName] Anotação 'controller' encontrada para o pod default/test-deployment3-6c95cffb97-d2xv7: test-controller3
I0124 13:54:18.271207       1 scheduler.go:614] [GetControllerMetricInfo] Métricas do controlador definidas para o pod: default/test-deployment3-6c95cffb97-d2xv7
W0124 13:54:18.271227       1 scheduler.go:125] [cacheMiss] Métricas não encontradas para o pod: default/test-deployment3-6c95cffb97-d2xv7
I0124 13:54:18.290797       1 scheduler.go:70] Estado no Informer: map[controller:test-controller3]
I0124 13:54:18.291466       1 scheduler.go:71] Estado real no cluster: map[controller:test-controller3]
W0124 13:54:18.292015       1 scheduler.go:135] [WaitForPodsOnCache] Pod test-deployment3-6c95cffb97-d2xv7 não encontrado no cache. Tentando novamente...
I0124 13:54:18.393040       1 scheduler.go:606] [GetControllerMetricInfo] Iniciando para o pod: default/test-deployment3-6c95cffb97-d2xv7
I0124 13:54:18.393160       1 scheduler.go:611] [GetControllerMetricInfo] Obtendo o nome do controlador para o pod: default/test-deployment3-6c95cffb97-d2xv7
I0124 13:54:18.393180       1 types.go:743] [ControllerName] Verificando as anotações do pod default/test-deployment3-6c95cffb97-d2xv7
I0124 13:54:18.393197       1 types.go:761] [ControllerName] Anotação 'controller' encontrada para o pod default/test-deployment3-6c95cffb97-d2xv7: test-controller3
I0124 13:54:18.393213       1 scheduler.go:614] [GetControllerMetricInfo] Métricas do controlador definidas para o pod: default/test-deployment3-6c95cffb97-d2xv7
W0124 13:54:18.393235       1 scheduler.go:125] [cacheMiss] Métricas não encontradas para o pod: default/test-deployment3-6c95cffb97-d2xv7
I0124 13:54:18.410552       1 scheduler.go:70] Estado no Informer: map[controller:test-controller3]
I0124 13:54:18.410663       1 scheduler.go:71] Estado real no cluster: map[controller:test-controller3]
W0124 13:54:18.410681       1 scheduler.go:135] [WaitForPodsOnCache] Pod test-deployment3-6c95cffb97-d2xv7 não encontrado no cache. Tentando novamente...
I0124 13:54:18.511407       1 scheduler.go:606] [GetControllerMetricInfo] Iniciando para o pod: default/test-deployment3-6c95cffb97-d2xv7
I0124 13:54:18.511523       1 scheduler.go:611] [GetControllerMetricInfo] Obtendo o nome do controlador para o pod: default/test-deployment3-6c95cffb97-d2xv7
I0124 13:54:18.511542       1 types.go:743] [ControllerName] Verificando as anotações do pod default/test-deployment3-6c95cffb97-d2xv7
I0124 13:54:18.511560       1 types.go:761] [ControllerName] Anotação 'controller' encontrada para o pod default/test-deployment3-6c95cffb97-d2xv7: test-controller3
I0124 13:54:18.511577       1 scheduler.go:614] [GetControllerMetricInfo] Métricas do controlador definidas para o pod: default/test-deployment3-6c95cffb97-d2xv7
W0124 13:54:18.511598       1 scheduler.go:125] [cacheMiss] Métricas não encontradas para o pod: default/test-deployment3-6c95cffb97-d2xv7
I0124 13:54:18.521272       1 scheduler.go:70] Estado no Informer: map[controller:test-controller3]
I0124 13:54:18.521324       1 scheduler.go:71] Estado real no cluster: map[controller:test-controller3]
W0124 13:54:18.521345       1 scheduler.go:135] [WaitForPodsOnCache] Pod test-deployment3-6c95cffb97-d2xv7 não encontrado no cache. Tentando novamente...
I0124 13:54:18.621560       1 scheduler.go:606] [GetControllerMetricInfo] Iniciando para o pod: default/test-deployment3-6c95cffb97-d2xv7
I0124 13:54:18.621820       1 scheduler.go:611] [GetControllerMetricInfo] Obtendo o nome do controlador para o pod: default/test-deployment3-6c95cffb97-d2xv7
I0124 13:54:18.622451       1 types.go:743] [ControllerName] Verificando as anotações do pod default/test-deployment3-6c95cffb97-d2xv7
I0124 13:54:18.623246       1 types.go:761] [ControllerName] Anotação 'controller' encontrada para o pod default/test-deployment3-6c95cffb97-d2xv7: test-controller3
I0124 13:54:18.623799       1 scheduler.go:614] [GetControllerMetricInfo] Métricas do controlador definidas para o pod: default/test-deployment3-6c95cffb97-d2xv7
W0124 13:54:18.624472       1 scheduler.go:125] [cacheMiss] Métricas não encontradas para o pod: default/test-deployment3-6c95cffb97-d2xv7
I0124 13:54:18.632407       1 scheduler.go:70] Estado no Informer: map[controller:test-controller3]
I0124 13:54:18.633010       1 scheduler.go:71] Estado real no cluster: map[controller:test-controller3]
W0124 13:54:18.633673       1 scheduler.go:135] [WaitForPodsOnCache] Pod test-deployment3-6c95cffb97-d2xv7 não encontrado no cache. Tentando novamente...
I0124 13:54:18.734528       1 scheduler.go:606] [GetControllerMetricInfo] Iniciando para o pod: default/test-deployment3-6c95cffb97-d2xv7
I0124 13:54:18.735093       1 scheduler.go:611] [GetControllerMetricInfo] Obtendo o nome do controlador para o pod: default/test-deployment3-6c95cffb97-d2xv7
I0124 13:54:18.735115       1 types.go:743] [ControllerName] Verificando as anotações do pod default/test-deployment3-6c95cffb97-d2xv7
I0124 13:54:18.735139       1 types.go:761] [ControllerName] Anotação 'controller' encontrada para o pod default/test-deployment3-6c95cffb97-d2xv7: test-controller3
I0124 13:54:18.735156       1 scheduler.go:614] [GetControllerMetricInfo] Métricas do controlador definidas para o pod: default/test-deployment3-6c95cffb97-d2xv7
W0124 13:54:18.735175       1 scheduler.go:125] [cacheMiss] Métricas não encontradas para o pod: default/test-deployment3-6c95cffb97-d2xv7
I0124 13:54:18.742029       1 scheduler.go:70] Estado no Informer: map[controller:test-controller3]
I0124 13:54:18.742784       1 scheduler.go:71] Estado real no cluster: map[controller:test-controller3]
W0124 13:54:18.743610       1 scheduler.go:135] [WaitForPodsOnCache] Pod test-deployment3-6c95cffb97-d2xv7 não encontrado no cache. Tentando novamente...
I0124 13:54:18.846240       1 scheduler.go:606] [GetControllerMetricInfo] Iniciando para o pod: default/test-deployment3-6c95cffb97-d2xv7
I0124 13:54:18.847225       1 scheduler.go:611] [GetControllerMetricInfo] Obtendo o nome do controlador para o pod: default/test-deployment3-6c95cffb97-d2xv7
I0124 13:54:18.848318       1 types.go:743] [ControllerName] Verificando as anotações do pod default/test-deployment3-6c95cffb97-d2xv7
I0124 13:54:18.848981       1 types.go:761] [ControllerName] Anotação 'controller' encontrada para o pod default/test-deployment3-6c95cffb97-d2xv7: test-controller3
I0124 13:54:18.849277       1 scheduler.go:614] [GetControllerMetricInfo] Métricas do controlador definidas para o pod: default/test-deployment3-6c95cffb97-d2xv7
W0124 13:54:18.849637       1 scheduler.go:125] [cacheMiss] Métricas não encontradas para o pod: default/test-deployment3-6c95cffb97-d2xv7
I0124 13:54:18.863777       1 scheduler.go:70] Estado no Informer: map[controller:test-controller3]
I0124 13:54:18.864298       1 scheduler.go:71] Estado real no cluster: map[controller:test-controller3]
W0124 13:54:18.864730       1 scheduler.go:135] [WaitForPodsOnCache] Pod test-deployment3-6c95cffb97-d2xv7 não encontrado no cache. Tentando novamente...
I0124 13:54:18.965962       1 scheduler.go:606] [GetControllerMetricInfo] Iniciando para o pod: default/test-deployment3-6c95cffb97-d2xv7
I0124 13:54:18.966061       1 scheduler.go:611] [GetControllerMetricInfo] Obtendo o nome do controlador para o pod: default/test-deployment3-6c95cffb97-d2xv7
I0124 13:54:18.966078       1 types.go:743] [ControllerName] Verificando as anotações do pod default/test-deployment3-6c95cffb97-d2xv7
I0124 13:54:18.966094       1 types.go:761] [ControllerName] Anotação 'controller' encontrada para o pod default/test-deployment3-6c95cffb97-d2xv7: test-controller3
I0124 13:54:18.966110       1 scheduler.go:614] [GetControllerMetricInfo] Métricas do controlador definidas para o pod: default/test-deployment3-6c95cffb97-d2xv7
W0124 13:54:18.966131       1 scheduler.go:125] [cacheMiss] Métricas não encontradas para o pod: default/test-deployment3-6c95cffb97-d2xv7
I0124 13:54:18.977136       1 scheduler.go:70] Estado no Informer: map[controller:test-controller3]
I0124 13:54:18.979414       1 scheduler.go:71] Estado real no cluster: map[controller:test-controller3]
W0124 13:54:18.979525       1 scheduler.go:135] [WaitForPodsOnCache] Pod test-deployment3-6c95cffb97-d2xv7 não encontrado no cache. Tentando novamente...
I0124 13:54:19.080628       1 scheduler.go:606] [GetControllerMetricInfo] Iniciando para o pod: default/test-deployment3-6c95cffb97-d2xv7
I0124 13:54:19.080728       1 scheduler.go:611] [GetControllerMetricInfo] Obtendo o nome do controlador para o pod: default/test-deployment3-6c95cffb97-d2xv7
I0124 13:54:19.080747       1 types.go:743] [ControllerName] Verificando as anotações do pod default/test-deployment3-6c95cffb97-d2xv7
I0124 13:54:19.080763       1 types.go:761] [ControllerName] Anotação 'controller' encontrada para o pod default/test-deployment3-6c95cffb97-d2xv7: test-controller3
I0124 13:54:19.080779       1 scheduler.go:614] [GetControllerMetricInfo] Métricas do controlador definidas para o pod: default/test-deployment3-6c95cffb97-d2xv7
W0124 13:54:19.080799       1 scheduler.go:125] [cacheMiss] Métricas não encontradas para o pod: default/test-deployment3-6c95cffb97-d2xv7
I0124 13:54:19.102135       1 scheduler.go:70] Estado no Informer: map[controller:test-controller3]
I0124 13:54:19.102996       1 scheduler.go:71] Estado real no cluster: map[controller:test-controller3]
W0124 13:54:19.103644       1 scheduler.go:135] [WaitForPodsOnCache] Pod test-deployment3-6c95cffb97-d2xv7 não encontrado no cache. Tentando novamente...
I0124 13:54:19.205010       1 scheduler.go:606] [GetControllerMetricInfo] Iniciando para o pod: default/test-deployment3-6c95cffb97-d2xv7
I0124 13:54:19.205581       1 scheduler.go:611] [GetControllerMetricInfo] Obtendo o nome do controlador para o pod: default/test-deployment3-6c95cffb97-d2xv7
I0124 13:54:19.205712       1 types.go:743] [ControllerName] Verificando as anotações do pod default/test-deployment3-6c95cffb97-d2xv7
I0124 13:54:19.206447       1 types.go:761] [ControllerName] Anotação 'controller' encontrada para o pod default/test-deployment3-6c95cffb97-d2xv7: test-controller3
I0124 13:54:19.206662       1 scheduler.go:614] [GetControllerMetricInfo] Métricas do controlador definidas para o pod: default/test-deployment3-6c95cffb97-d2xv7
W0124 13:54:19.207254       1 scheduler.go:125] [cacheMiss] Métricas não encontradas para o pod: default/test-deployment3-6c95cffb97-d2xv7
I0124 13:54:19.214747       1 scheduler.go:70] Estado no Informer: map[controller:test-controller3]
I0124 13:54:19.215353       1 scheduler.go:71] Estado real no cluster: map[controller:test-controller3]
W0124 13:54:19.215676       1 scheduler.go:135] [WaitForPodsOnCache] Pod test-deployment3-6c95cffb97-d2xv7 não encontrado no cache. Tentando novamente...
I0124 13:54:19.318473       1 scheduler.go:606] [GetControllerMetricInfo] Iniciando para o pod: default/test-deployment3-6c95cffb97-d2xv7
I0124 13:54:19.318525       1 scheduler.go:611] [GetControllerMetricInfo] Obtendo o nome do controlador para o pod: default/test-deployment3-6c95cffb97-d2xv7
I0124 13:54:19.318541       1 types.go:743] [ControllerName] Verificando as anotações do pod default/test-deployment3-6c95cffb97-d2xv7
I0124 13:54:19.318593       1 types.go:761] [ControllerName] Anotação 'controller' encontrada para o pod default/test-deployment3-6c95cffb97-d2xv7: test-controller3
I0124 13:54:19.318613       1 scheduler.go:614] [GetControllerMetricInfo] Métricas do controlador definidas para o pod: default/test-deployment3-6c95cffb97-d2xv7
W0124 13:54:19.318633       1 scheduler.go:125] [cacheMiss] Métricas não encontradas para o pod: default/test-deployment3-6c95cffb97-d2xv7
I0124 13:54:19.331636       1 scheduler.go:70] Estado no Informer: map[controller:test-controller3]
I0124 13:54:19.331736       1 scheduler.go:71] Estado real no cluster: map[controller:test-controller3]
W0124 13:54:19.331759       1 scheduler.go:135] [WaitForPodsOnCache] Pod test-deployment3-6c95cffb97-d2xv7 não encontrado no cache. Tentando novamente...
I0124 13:54:19.432210       1 scheduler.go:606] [GetControllerMetricInfo] Iniciando para o pod: default/test-deployment3-6c95cffb97-d2xv7
I0124 13:54:19.432298       1 scheduler.go:611] [GetControllerMetricInfo] Obtendo o nome do controlador para o pod: default/test-deployment3-6c95cffb97-d2xv7
I0124 13:54:19.432315       1 types.go:743] [ControllerName] Verificando as anotações do pod default/test-deployment3-6c95cffb97-d2xv7
I0124 13:54:19.432330       1 types.go:761] [ControllerName] Anotação 'controller' encontrada para o pod default/test-deployment3-6c95cffb97-d2xv7: test-controller3
I0124 13:54:19.432346       1 scheduler.go:614] [GetControllerMetricInfo] Métricas do controlador definidas para o pod: default/test-deployment3-6c95cffb97-d2xv7
W0124 13:54:19.432366       1 scheduler.go:125] [cacheMiss] Métricas não encontradas para o pod: default/test-deployment3-6c95cffb97-d2xv7
I0124 13:54:19.441960       1 scheduler.go:70] Estado no Informer: map[controller:test-controller3]
I0124 13:54:19.442055       1 scheduler.go:71] Estado real no cluster: map[controller:test-controller3]
W0124 13:54:19.442077       1 scheduler.go:135] [WaitForPodsOnCache] Pod test-deployment3-6c95cffb97-d2xv7 não encontrado no cache. Tentando novamente...
I0124 13:54:19.543269       1 scheduler.go:606] [GetControllerMetricInfo] Iniciando para o pod: default/test-deployment3-6c95cffb97-d2xv7
I0124 13:54:19.544016       1 scheduler.go:611] [GetControllerMetricInfo] Obtendo o nome do controlador para o pod: default/test-deployment3-6c95cffb97-d2xv7
I0124 13:54:19.544604       1 types.go:743] [ControllerName] Verificando as anotações do pod default/test-deployment3-6c95cffb97-d2xv7
I0124 13:54:19.545185       1 types.go:761] [ControllerName] Anotação 'controller' encontrada para o pod default/test-deployment3-6c95cffb97-d2xv7: test-controller3
I0124 13:54:19.545482       1 scheduler.go:614] [GetControllerMetricInfo] Métricas do controlador definidas para o pod: default/test-deployment3-6c95cffb97-d2xv7
W0124 13:54:19.545819       1 scheduler.go:125] [cacheMiss] Métricas não encontradas para o pod: default/test-deployment3-6c95cffb97-d2xv7
I0124 13:54:19.553317       1 scheduler.go:70] Estado no Informer: map[controller:test-controller3]
I0124 13:54:19.553417       1 scheduler.go:71] Estado real no cluster: map[controller:test-controller3]
W0124 13:54:19.553438       1 scheduler.go:135] [WaitForPodsOnCache] Pod test-deployment3-6c95cffb97-d2xv7 não encontrado no cache. Tentando novamente...
I0124 13:54:19.654513       1 scheduler.go:606] [GetControllerMetricInfo] Iniciando para o pod: default/test-deployment3-6c95cffb97-d2xv7
I0124 13:54:19.655345       1 scheduler.go:611] [GetControllerMetricInfo] Obtendo o nome do controlador para o pod: default/test-deployment3-6c95cffb97-d2xv7
I0124 13:54:19.655498       1 types.go:743] [ControllerName] Verificando as anotações do pod default/test-deployment3-6c95cffb97-d2xv7
I0124 13:54:19.655552       1 types.go:761] [ControllerName] Anotação 'controller' encontrada para o pod default/test-deployment3-6c95cffb97-d2xv7: test-controller3
I0124 13:54:19.655605       1 scheduler.go:614] [GetControllerMetricInfo] Métricas do controlador definidas para o pod: default/test-deployment3-6c95cffb97-d2xv7
W0124 13:54:19.655686       1 scheduler.go:125] [cacheMiss] Métricas não encontradas para o pod: default/test-deployment3-6c95cffb97-d2xv7
I0124 13:54:19.663162       1 scheduler.go:70] Estado no Informer: map[controller:test-controller3]
I0124 13:54:19.663775       1 scheduler.go:71] Estado real no cluster: map[controller:test-controller3]
W0124 13:54:19.664234       1 scheduler.go:135] [WaitForPodsOnCache] Pod test-deployment3-6c95cffb97-d2xv7 não encontrado no cache. Tentando novamente...
I0124 13:54:19.765260       1 scheduler.go:606] [GetControllerMetricInfo] Iniciando para o pod: default/test-deployment3-6c95cffb97-d2xv7
I0124 13:54:19.765315       1 scheduler.go:611] [GetControllerMetricInfo] Obtendo o nome do controlador para o pod: default/test-deployment3-6c95cffb97-d2xv7
I0124 13:54:19.765330       1 types.go:743] [ControllerName] Verificando as anotações do pod default/test-deployment3-6c95cffb97-d2xv7
I0124 13:54:19.765345       1 types.go:761] [ControllerName] Anotação 'controller' encontrada para o pod default/test-deployment3-6c95cffb97-d2xv7: test-controller3
I0124 13:54:19.765361       1 scheduler.go:614] [GetControllerMetricInfo] Métricas do controlador definidas para o pod: default/test-deployment3-6c95cffb97-d2xv7
W0124 13:54:19.765400       1 scheduler.go:125] [cacheMiss] Métricas não encontradas para o pod: default/test-deployment3-6c95cffb97-d2xv7
I0124 13:54:19.774452       1 scheduler.go:70] Estado no Informer: map[controller:test-controller3]
I0124 13:54:19.774707       1 scheduler.go:71] Estado real no cluster: map[controller:test-controller3]
W0124 13:54:19.774728       1 scheduler.go:135] [WaitForPodsOnCache] Pod test-deployment3-6c95cffb97-d2xv7 não encontrado no cache. Tentando novamente...
I0124 13:54:19.875712       1 scheduler.go:606] [GetControllerMetricInfo] Iniciando para o pod: default/test-deployment3-6c95cffb97-d2xv7
I0124 13:54:19.875975       1 scheduler.go:611] [GetControllerMetricInfo] Obtendo o nome do controlador para o pod: default/test-deployment3-6c95cffb97-d2xv7
I0124 13:54:19.876036       1 types.go:743] [ControllerName] Verificando as anotações do pod default/test-deployment3-6c95cffb97-d2xv7
I0124 13:54:19.876440       1 types.go:761] [ControllerName] Anotação 'controller' encontrada para o pod default/test-deployment3-6c95cffb97-d2xv7: test-controller3
I0124 13:54:19.876608       1 scheduler.go:614] [GetControllerMetricInfo] Métricas do controlador definidas para o pod: default/test-deployment3-6c95cffb97-d2xv7
W0124 13:54:19.876695       1 scheduler.go:125] [cacheMiss] Métricas não encontradas para o pod: default/test-deployment3-6c95cffb97-d2xv7
I0124 13:54:19.885324       1 scheduler.go:70] Estado no Informer: map[controller:test-controller3]
I0124 13:54:19.885423       1 scheduler.go:71] Estado real no cluster: map[controller:test-controller3]
W0124 13:54:19.885444       1 scheduler.go:135] [WaitForPodsOnCache] Pod test-deployment3-6c95cffb97-d2xv7 não encontrado no cache. Tentando novamente...
I0124 13:54:19.985931       1 scheduler.go:606] [GetControllerMetricInfo] Iniciando para o pod: default/test-deployment3-6c95cffb97-d2xv7
I0124 13:54:19.986022       1 scheduler.go:611] [GetControllerMetricInfo] Obtendo o nome do controlador para o pod: default/test-deployment3-6c95cffb97-d2xv7
I0124 13:54:19.986041       1 types.go:743] [ControllerName] Verificando as anotações do pod default/test-deployment3-6c95cffb97-d2xv7
I0124 13:54:19.986057       1 types.go:761] [ControllerName] Anotação 'controller' encontrada para o pod default/test-deployment3-6c95cffb97-d2xv7: test-controller3
I0124 13:54:19.986073       1 scheduler.go:614] [GetControllerMetricInfo] Métricas do controlador definidas para o pod: default/test-deployment3-6c95cffb97-d2xv7
W0124 13:54:19.986092       1 scheduler.go:125] [cacheMiss] Métricas não encontradas para o pod: default/test-deployment3-6c95cffb97-d2xv7
I0124 13:54:19.995322       1 scheduler.go:70] Estado no Informer: map[controller:test-controller3]
I0124 13:54:19.995424       1 scheduler.go:71] Estado real no cluster: map[controller:test-controller3]
W0124 13:54:19.995446       1 scheduler.go:135] [WaitForPodsOnCache] Pod test-deployment3-6c95cffb97-d2xv7 não encontrado no cache. Tentando novamente...
I0124 13:54:20.111148       1 scheduler.go:606] [GetControllerMetricInfo] Iniciando para o pod: default/test-deployment3-6c95cffb97-d2xv7
I0124 13:54:20.111258       1 scheduler.go:611] [GetControllerMetricInfo] Obtendo o nome do controlador para o pod: default/test-deployment3-6c95cffb97-d2xv7
I0124 13:54:20.111276       1 types.go:743] [ControllerName] Verificando as anotações do pod default/test-deployment3-6c95cffb97-d2xv7
I0124 13:54:20.111810       1 types.go:761] [ControllerName] Anotação 'controller' encontrada para o pod default/test-deployment3-6c95cffb97-d2xv7: test-controller3
I0124 13:54:20.112019       1 scheduler.go:614] [GetControllerMetricInfo] Métricas do controlador definidas para o pod: default/test-deployment3-6c95cffb97-d2xv7
W0124 13:54:20.112531       1 scheduler.go:125] [cacheMiss] Métricas não encontradas para o pod: default/test-deployment3-6c95cffb97-d2xv7
I0124 13:54:20.119217       1 scheduler.go:70] Estado no Informer: map[controller:test-controller3]
I0124 13:54:20.119300       1 scheduler.go:71] Estado real no cluster: map[controller:test-controller3]
W0124 13:54:20.119318       1 scheduler.go:135] [WaitForPodsOnCache] Pod test-deployment3-6c95cffb97-d2xv7 não encontrado no cache. Tentando novamente...
I0124 13:54:20.220027       1 scheduler.go:606] [GetControllerMetricInfo] Iniciando para o pod: default/test-deployment3-6c95cffb97-d2xv7
I0124 13:54:20.220150       1 scheduler.go:611] [GetControllerMetricInfo] Obtendo o nome do controlador para o pod: default/test-deployment3-6c95cffb97-d2xv7
I0124 13:54:20.220173       1 types.go:743] [ControllerName] Verificando as anotações do pod default/test-deployment3-6c95cffb97-d2xv7
I0124 13:54:20.220194       1 types.go:761] [ControllerName] Anotação 'controller' encontrada para o pod default/test-deployment3-6c95cffb97-d2xv7: test-controller3
I0124 13:54:20.220216       1 scheduler.go:614] [GetControllerMetricInfo] Métricas do controlador definidas para o pod: default/test-deployment3-6c95cffb97-d2xv7
W0124 13:54:20.220240       1 scheduler.go:125] [cacheMiss] Métricas não encontradas para o pod: default/test-deployment3-6c95cffb97-d2xv7
I0124 13:54:20.238152       1 scheduler.go:70] Estado no Informer: map[controller:test-controller3]
I0124 13:54:20.239656       1 scheduler.go:71] Estado real no cluster: map[controller:test-controller3]
W0124 13:54:20.240646       1 scheduler.go:135] [WaitForPodsOnCache] Pod test-deployment3-6c95cffb97-d2xv7 não encontrado no cache. Tentando novamente...
I0124 13:54:20.341123       1 scheduler.go:606] [GetControllerMetricInfo] Iniciando para o pod: default/test-deployment3-6c95cffb97-d2xv7
I0124 13:54:20.341165       1 scheduler.go:611] [GetControllerMetricInfo] Obtendo o nome do controlador para o pod: default/test-deployment3-6c95cffb97-d2xv7
I0124 13:54:20.341181       1 types.go:743] [ControllerName] Verificando as anotações do pod default/test-deployment3-6c95cffb97-d2xv7
I0124 13:54:20.341196       1 types.go:761] [ControllerName] Anotação 'controller' encontrada para o pod default/test-deployment3-6c95cffb97-d2xv7: test-controller3
I0124 13:54:20.341211       1 scheduler.go:614] [GetControllerMetricInfo] Métricas do controlador definidas para o pod: default/test-deployment3-6c95cffb97-d2xv7
W0124 13:54:20.341231       1 scheduler.go:125] [cacheMiss] Métricas não encontradas para o pod: default/test-deployment3-6c95cffb97-d2xv7
I0124 13:54:20.366798       1 scheduler.go:70] Estado no Informer: map[controller:test-controller3]
I0124 13:54:20.367274       1 scheduler.go:71] Estado real no cluster: map[controller:test-controller3]
W0124 13:54:20.367614       1 scheduler.go:135] [WaitForPodsOnCache] Pod test-deployment3-6c95cffb97-d2xv7 não encontrado no cache. Tentando novamente...
I0124 13:54:20.469239       1 scheduler.go:606] [GetControllerMetricInfo] Iniciando para o pod: default/test-deployment3-6c95cffb97-d2xv7
I0124 13:54:20.469351       1 scheduler.go:611] [GetControllerMetricInfo] Obtendo o nome do controlador para o pod: default/test-deployment3-6c95cffb97-d2xv7
I0124 13:54:20.469369       1 types.go:743] [ControllerName] Verificando as anotações do pod default/test-deployment3-6c95cffb97-d2xv7
I0124 13:54:20.469388       1 types.go:761] [ControllerName] Anotação 'controller' encontrada para o pod default/test-deployment3-6c95cffb97-d2xv7: test-controller3
I0124 13:54:20.469404       1 scheduler.go:614] [GetControllerMetricInfo] Métricas do controlador definidas para o pod: default/test-deployment3-6c95cffb97-d2xv7
W0124 13:54:20.469425       1 scheduler.go:125] [cacheMiss] Métricas não encontradas para o pod: default/test-deployment3-6c95cffb97-d2xv7
I0124 13:54:20.477571       1 scheduler.go:70] Estado no Informer: map[controller:test-controller3]
I0124 13:54:20.478415       1 scheduler.go:71] Estado real no cluster: map[controller:test-controller3]
W0124 13:54:20.479215       1 scheduler.go:135] [WaitForPodsOnCache] Pod test-deployment3-6c95cffb97-d2xv7 não encontrado no cache. Tentando novamente...
I0124 13:54:20.580333       1 scheduler.go:606] [GetControllerMetricInfo] Iniciando para o pod: default/test-deployment3-6c95cffb97-d2xv7
I0124 13:54:20.581552       1 scheduler.go:611] [GetControllerMetricInfo] Obtendo o nome do controlador para o pod: default/test-deployment3-6c95cffb97-d2xv7
I0124 13:54:20.581945       1 types.go:743] [ControllerName] Verificando as anotações do pod default/test-deployment3-6c95cffb97-d2xv7
I0124 13:54:20.582390       1 types.go:761] [ControllerName] Anotação 'controller' encontrada para o pod default/test-deployment3-6c95cffb97-d2xv7: test-controller3
I0124 13:54:20.582939       1 scheduler.go:614] [GetControllerMetricInfo] Métricas do controlador definidas para o pod: default/test-deployment3-6c95cffb97-d2xv7
W0124 13:54:20.583366       1 scheduler.go:125] [cacheMiss] Métricas não encontradas para o pod: default/test-deployment3-6c95cffb97-d2xv7
I0124 13:54:20.591981       1 scheduler.go:70] Estado no Informer: map[controller:test-controller3]
I0124 13:54:20.592329       1 scheduler.go:71] Estado real no cluster: map[controller:test-controller3]
W0124 13:54:20.592353       1 scheduler.go:135] [WaitForPodsOnCache] Pod test-deployment3-6c95cffb97-d2xv7 não encontrado no cache. Tentando novamente...
I0124 13:54:20.693253       1 scheduler.go:606] [GetControllerMetricInfo] Iniciando para o pod: default/test-deployment3-6c95cffb97-d2xv7
I0124 13:54:20.693767       1 scheduler.go:611] [GetControllerMetricInfo] Obtendo o nome do controlador para o pod: default/test-deployment3-6c95cffb97-d2xv7
I0124 13:54:20.694193       1 types.go:743] [ControllerName] Verificando as anotações do pod default/test-deployment3-6c95cffb97-d2xv7
I0124 13:54:20.694556       1 types.go:761] [ControllerName] Anotação 'controller' encontrada para o pod default/test-deployment3-6c95cffb97-d2xv7: test-controller3
I0124 13:54:20.694836       1 scheduler.go:614] [GetControllerMetricInfo] Métricas do controlador definidas para o pod: default/test-deployment3-6c95cffb97-d2xv7
W0124 13:54:20.695399       1 scheduler.go:125] [cacheMiss] Métricas não encontradas para o pod: default/test-deployment3-6c95cffb97-d2xv7
I0124 13:54:20.717073       1 scheduler.go:70] Estado no Informer: map[controller:test-controller3]
I0124 13:54:20.717259       1 scheduler.go:71] Estado real no cluster: map[controller:test-controller3]
W0124 13:54:20.717444       1 scheduler.go:135] [WaitForPodsOnCache] Pod test-deployment3-6c95cffb97-d2xv7 não encontrado no cache. Tentando novamente...
I0124 13:54:20.817961       1 scheduler.go:606] [GetControllerMetricInfo] Iniciando para o pod: default/test-deployment3-6c95cffb97-d2xv7
I0124 13:54:20.818292       1 scheduler.go:611] [GetControllerMetricInfo] Obtendo o nome do controlador para o pod: default/test-deployment3-6c95cffb97-d2xv7
I0124 13:54:20.818520       1 types.go:743] [ControllerName] Verificando as anotações do pod default/test-deployment3-6c95cffb97-d2xv7
I0124 13:54:20.818672       1 types.go:761] [ControllerName] Anotação 'controller' encontrada para o pod default/test-deployment3-6c95cffb97-d2xv7: test-controller3
I0124 13:54:20.818798       1 scheduler.go:614] [GetControllerMetricInfo] Métricas do controlador definidas para o pod: default/test-deployment3-6c95cffb97-d2xv7
W0124 13:54:20.819061       1 scheduler.go:125] [cacheMiss] Métricas não encontradas para o pod: default/test-deployment3-6c95cffb97-d2xv7
I0124 13:54:20.825466       1 scheduler.go:70] Estado no Informer: map[controller:test-controller3]
I0124 13:54:20.825565       1 scheduler.go:71] Estado real no cluster: map[controller:test-controller3]
W0124 13:54:20.825588       1 scheduler.go:135] [WaitForPodsOnCache] Pod test-deployment3-6c95cffb97-d2xv7 não encontrado no cache. Tentando novamente...
I0124 13:54:20.926061       1 scheduler.go:606] [GetControllerMetricInfo] Iniciando para o pod: default/test-deployment3-6c95cffb97-d2xv7
I0124 13:54:20.927513       1 scheduler.go:611] [GetControllerMetricInfo] Obtendo o nome do controlador para o pod: default/test-deployment3-6c95cffb97-d2xv7
I0124 13:54:20.928398       1 types.go:743] [ControllerName] Verificando as anotações do pod default/test-deployment3-6c95cffb97-d2xv7
I0124 13:54:20.929098       1 types.go:761] [ControllerName] Anotação 'controller' encontrada para o pod default/test-deployment3-6c95cffb97-d2xv7: test-controller3
I0124 13:54:20.929779       1 scheduler.go:614] [GetControllerMetricInfo] Métricas do controlador definidas para o pod: default/test-deployment3-6c95cffb97-d2xv7
W0124 13:54:20.930632       1 scheduler.go:125] [cacheMiss] Métricas não encontradas para o pod: default/test-deployment3-6c95cffb97-d2xv7
I0124 13:54:20.939281       1 scheduler.go:70] Estado no Informer: map[controller:test-controller3]
I0124 13:54:20.939324       1 scheduler.go:71] Estado real no cluster: map[controller:test-controller3]
W0124 13:54:20.939341       1 scheduler.go:135] [WaitForPodsOnCache] Pod test-deployment3-6c95cffb97-d2xv7 não encontrado no cache. Tentando novamente...
I0124 13:54:21.040586       1 scheduler.go:606] [GetControllerMetricInfo] Iniciando para o pod: default/test-deployment3-6c95cffb97-d2xv7
I0124 13:54:21.040743       1 scheduler.go:611] [GetControllerMetricInfo] Obtendo o nome do controlador para o pod: default/test-deployment3-6c95cffb97-d2xv7
I0124 13:54:21.040758       1 types.go:743] [ControllerName] Verificando as anotações do pod default/test-deployment3-6c95cffb97-d2xv7
I0124 13:54:21.040770       1 types.go:761] [ControllerName] Anotação 'controller' encontrada para o pod default/test-deployment3-6c95cffb97-d2xv7: test-controller3
I0124 13:54:21.040783       1 scheduler.go:614] [GetControllerMetricInfo] Métricas do controlador definidas para o pod: default/test-deployment3-6c95cffb97-d2xv7
W0124 13:54:21.040800       1 scheduler.go:125] [cacheMiss] Métricas não encontradas para o pod: default/test-deployment3-6c95cffb97-d2xv7
I0124 13:54:21.050010       1 scheduler.go:70] Estado no Informer: map[controller:test-controller3]
I0124 13:54:21.050081       1 scheduler.go:71] Estado real no cluster: map[controller:test-controller3]
W0124 13:54:21.050097       1 scheduler.go:135] [WaitForPodsOnCache] Pod test-deployment3-6c95cffb97-d2xv7 não encontrado no cache. Tentando novamente...
I0124 13:54:21.150649       1 scheduler.go:606] [GetControllerMetricInfo] Iniciando para o pod: default/test-deployment3-6c95cffb97-d2xv7
I0124 13:54:21.151136       1 scheduler.go:611] [GetControllerMetricInfo] Obtendo o nome do controlador para o pod: default/test-deployment3-6c95cffb97-d2xv7
I0124 13:54:21.151284       1 types.go:743] [ControllerName] Verificando as anotações do pod default/test-deployment3-6c95cffb97-d2xv7
I0124 13:54:21.151379       1 types.go:761] [ControllerName] Anotação 'controller' encontrada para o pod default/test-deployment3-6c95cffb97-d2xv7: test-controller3
I0124 13:54:21.151637       1 scheduler.go:614] [GetControllerMetricInfo] Métricas do controlador definidas para o pod: default/test-deployment3-6c95cffb97-d2xv7
W0124 13:54:21.151739       1 scheduler.go:125] [cacheMiss] Métricas não encontradas para o pod: default/test-deployment3-6c95cffb97-d2xv7
I0124 13:54:21.159609       1 scheduler.go:70] Estado no Informer: map[controller:test-controller3]
I0124 13:54:21.159649       1 scheduler.go:71] Estado real no cluster: map[controller:test-controller3]
W0124 13:54:21.159666       1 scheduler.go:135] [WaitForPodsOnCache] Pod test-deployment3-6c95cffb97-d2xv7 não encontrado no cache. Tentando novamente...
I0124 13:54:21.260750       1 scheduler.go:606] [GetControllerMetricInfo] Iniciando para o pod: default/test-deployment3-6c95cffb97-d2xv7
I0124 13:54:21.261318       1 scheduler.go:611] [GetControllerMetricInfo] Obtendo o nome do controlador para o pod: default/test-deployment3-6c95cffb97-d2xv7
I0124 13:54:21.261519       1 types.go:743] [ControllerName] Verificando as anotações do pod default/test-deployment3-6c95cffb97-d2xv7
I0124 13:54:21.261633       1 types.go:761] [ControllerName] Anotação 'controller' encontrada para o pod default/test-deployment3-6c95cffb97-d2xv7: test-controller3
I0124 13:54:21.261729       1 scheduler.go:614] [GetControllerMetricInfo] Métricas do controlador definidas para o pod: default/test-deployment3-6c95cffb97-d2xv7
W0124 13:54:21.261953       1 scheduler.go:125] [cacheMiss] Métricas não encontradas para o pod: default/test-deployment3-6c95cffb97-d2xv7
I0124 13:54:21.268785       1 scheduler.go:70] Estado no Informer: map[controller:test-controller3]
I0124 13:54:21.269373       1 scheduler.go:71] Estado real no cluster: map[controller:test-controller3]
W0124 13:54:21.269466       1 scheduler.go:135] [WaitForPodsOnCache] Pod test-deployment3-6c95cffb97-d2xv7 não encontrado no cache. Tentando novamente...
I0124 13:54:21.370666       1 scheduler.go:606] [GetControllerMetricInfo] Iniciando para o pod: default/test-deployment3-6c95cffb97-d2xv7
I0124 13:54:21.371111       1 scheduler.go:611] [GetControllerMetricInfo] Obtendo o nome do controlador para o pod: default/test-deployment3-6c95cffb97-d2xv7
I0124 13:54:21.371234       1 types.go:743] [ControllerName] Verificando as anotações do pod default/test-deployment3-6c95cffb97-d2xv7
I0124 13:54:21.371526       1 types.go:761] [ControllerName] Anotação 'controller' encontrada para o pod default/test-deployment3-6c95cffb97-d2xv7: test-controller3
I0124 13:54:21.371726       1 scheduler.go:614] [GetControllerMetricInfo] Métricas do controlador definidas para o pod: default/test-deployment3-6c95cffb97-d2xv7
W0124 13:54:21.371799       1 scheduler.go:125] [cacheMiss] Métricas não encontradas para o pod: default/test-deployment3-6c95cffb97-d2xv7
I0124 13:54:21.384703       1 scheduler.go:70] Estado no Informer: map[controller:test-controller3]
I0124 13:54:21.384804       1 scheduler.go:71] Estado real no cluster: map[controller:test-controller3]
W0124 13:54:21.384825       1 scheduler.go:135] [WaitForPodsOnCache] Pod test-deployment3-6c95cffb97-d2xv7 não encontrado no cache. Tentando novamente...
I0124 13:54:21.485984       1 scheduler.go:606] [GetControllerMetricInfo] Iniciando para o pod: default/test-deployment3-6c95cffb97-d2xv7
I0124 13:54:21.486510       1 scheduler.go:611] [GetControllerMetricInfo] Obtendo o nome do controlador para o pod: default/test-deployment3-6c95cffb97-d2xv7
I0124 13:54:21.486802       1 types.go:743] [ControllerName] Verificando as anotações do pod default/test-deployment3-6c95cffb97-d2xv7
I0124 13:54:21.487039       1 types.go:761] [ControllerName] Anotação 'controller' encontrada para o pod default/test-deployment3-6c95cffb97-d2xv7: test-controller3
I0124 13:54:21.487173       1 scheduler.go:614] [GetControllerMetricInfo] Métricas do controlador definidas para o pod: default/test-deployment3-6c95cffb97-d2xv7
W0124 13:54:21.487239       1 scheduler.go:125] [cacheMiss] Métricas não encontradas para o pod: default/test-deployment3-6c95cffb97-d2xv7
I0124 13:54:21.496613       1 scheduler.go:70] Estado no Informer: map[controller:test-controller3]
I0124 13:54:21.496721       1 scheduler.go:71] Estado real no cluster: map[controller:test-controller3]
W0124 13:54:21.496743       1 scheduler.go:135] [WaitForPodsOnCache] Pod test-deployment3-6c95cffb97-d2xv7 não encontrado no cache. Tentando novamente...
I0124 13:54:21.597175       1 scheduler.go:606] [GetControllerMetricInfo] Iniciando para o pod: default/test-deployment3-6c95cffb97-d2xv7
I0124 13:54:21.597279       1 scheduler.go:611] [GetControllerMetricInfo] Obtendo o nome do controlador para o pod: default/test-deployment3-6c95cffb97-d2xv7
I0124 13:54:21.597310       1 types.go:743] [ControllerName] Verificando as anotações do pod default/test-deployment3-6c95cffb97-d2xv7
I0124 13:54:21.597328       1 types.go:761] [ControllerName] Anotação 'controller' encontrada para o pod default/test-deployment3-6c95cffb97-d2xv7: test-controller3
I0124 13:54:21.597344       1 scheduler.go:614] [GetControllerMetricInfo] Métricas do controlador definidas para o pod: default/test-deployment3-6c95cffb97-d2xv7
W0124 13:54:21.597365       1 scheduler.go:125] [cacheMiss] Métricas não encontradas para o pod: default/test-deployment3-6c95cffb97-d2xv7
I0124 13:54:21.606397       1 scheduler.go:70] Estado no Informer: map[controller:test-controller3]
I0124 13:54:21.606574       1 scheduler.go:71] Estado real no cluster: map[controller:test-controller3]
W0124 13:54:21.607217       1 scheduler.go:135] [WaitForPodsOnCache] Pod test-deployment3-6c95cffb97-d2xv7 não encontrado no cache. Tentando novamente...
I0124 13:54:21.709551       1 scheduler.go:606] [GetControllerMetricInfo] Iniciando para o pod: default/test-deployment3-6c95cffb97-d2xv7
I0124 13:54:21.709662       1 scheduler.go:611] [GetControllerMetricInfo] Obtendo o nome do controlador para o pod: default/test-deployment3-6c95cffb97-d2xv7
I0124 13:54:21.709681       1 types.go:743] [ControllerName] Verificando as anotações do pod default/test-deployment3-6c95cffb97-d2xv7
I0124 13:54:21.709699       1 types.go:761] [ControllerName] Anotação 'controller' encontrada para o pod default/test-deployment3-6c95cffb97-d2xv7: test-controller3
I0124 13:54:21.710027       1 scheduler.go:614] [GetControllerMetricInfo] Métricas do controlador definidas para o pod: default/test-deployment3-6c95cffb97-d2xv7
W0124 13:54:21.710501       1 scheduler.go:125] [cacheMiss] Métricas não encontradas para o pod: default/test-deployment3-6c95cffb97-d2xv7
I0124 13:54:21.718365       1 scheduler.go:70] Estado no Informer: map[controller:test-controller3]
I0124 13:54:21.718410       1 scheduler.go:71] Estado real no cluster: map[controller:test-controller3]
W0124 13:54:21.718420       1 scheduler.go:135] [WaitForPodsOnCache] Pod test-deployment3-6c95cffb97-d2xv7 não encontrado no cache. Tentando novamente...
I0124 13:54:21.819675       1 scheduler.go:606] [GetControllerMetricInfo] Iniciando para o pod: default/test-deployment3-6c95cffb97-d2xv7
I0124 13:54:21.819780       1 scheduler.go:611] [GetControllerMetricInfo] Obtendo o nome do controlador para o pod: default/test-deployment3-6c95cffb97-d2xv7
I0124 13:54:21.819798       1 types.go:743] [ControllerName] Verificando as anotações do pod default/test-deployment3-6c95cffb97-d2xv7
I0124 13:54:21.819822       1 types.go:761] [ControllerName] Anotação 'controller' encontrada para o pod default/test-deployment3-6c95cffb97-d2xv7: test-controller3
I0124 13:54:21.819839       1 scheduler.go:614] [GetControllerMetricInfo] Métricas do controlador definidas para o pod: default/test-deployment3-6c95cffb97-d2xv7
W0124 13:54:21.820028       1 scheduler.go:125] [cacheMiss] Métricas não encontradas para o pod: default/test-deployment3-6c95cffb97-d2xv7
I0124 13:54:21.827301       1 scheduler.go:70] Estado no Informer: map[controller:test-controller3]
I0124 13:54:21.828007       1 scheduler.go:71] Estado real no cluster: map[controller:test-controller3]
W0124 13:54:21.828162       1 scheduler.go:135] [WaitForPodsOnCache] Pod test-deployment3-6c95cffb97-d2xv7 não encontrado no cache. Tentando novamente...
I0124 13:54:21.928738       1 scheduler.go:606] [GetControllerMetricInfo] Iniciando para o pod: default/test-deployment3-6c95cffb97-d2xv7
I0124 13:54:21.929328       1 scheduler.go:611] [GetControllerMetricInfo] Obtendo o nome do controlador para o pod: default/test-deployment3-6c95cffb97-d2xv7
I0124 13:54:21.929995       1 types.go:743] [ControllerName] Verificando as anotações do pod default/test-deployment3-6c95cffb97-d2xv7
I0124 13:54:21.930459       1 types.go:761] [ControllerName] Anotação 'controller' encontrada para o pod default/test-deployment3-6c95cffb97-d2xv7: test-controller3
I0124 13:54:21.930789       1 scheduler.go:614] [GetControllerMetricInfo] Métricas do controlador definidas para o pod: default/test-deployment3-6c95cffb97-d2xv7
W0124 13:54:21.931161       1 scheduler.go:125] [cacheMiss] Métricas não encontradas para o pod: default/test-deployment3-6c95cffb97-d2xv7
I0124 13:54:21.938335       1 scheduler.go:70] Estado no Informer: map[controller:test-controller3]
I0124 13:54:21.938822       1 scheduler.go:71] Estado real no cluster: map[controller:test-controller3]
W0124 13:54:21.939294       1 scheduler.go:135] [WaitForPodsOnCache] Pod test-deployment3-6c95cffb97-d2xv7 não encontrado no cache. Tentando novamente...
I0124 13:54:22.040487       1 scheduler.go:606] [GetControllerMetricInfo] Iniciando para o pod: default/test-deployment3-6c95cffb97-d2xv7
I0124 13:54:22.040578       1 scheduler.go:611] [GetControllerMetricInfo] Obtendo o nome do controlador para o pod: default/test-deployment3-6c95cffb97-d2xv7
I0124 13:54:22.040595       1 types.go:743] [ControllerName] Verificando as anotações do pod default/test-deployment3-6c95cffb97-d2xv7
I0124 13:54:22.040611       1 types.go:761] [ControllerName] Anotação 'controller' encontrada para o pod default/test-deployment3-6c95cffb97-d2xv7: test-controller3
I0124 13:54:22.040626       1 scheduler.go:614] [GetControllerMetricInfo] Métricas do controlador definidas para o pod: default/test-deployment3-6c95cffb97-d2xv7
W0124 13:54:22.040652       1 scheduler.go:125] [cacheMiss] Métricas não encontradas para o pod: default/test-deployment3-6c95cffb97-d2xv7
I0124 13:54:22.047454       1 scheduler.go:70] Estado no Informer: map[controller:test-controller3]
I0124 13:54:22.048034       1 scheduler.go:71] Estado real no cluster: map[controller:test-controller3]
W0124 13:54:22.050494       1 scheduler.go:135] [WaitForPodsOnCache] Pod test-deployment3-6c95cffb97-d2xv7 não encontrado no cache. Tentando novamente...
I0124 13:54:22.152143       1 scheduler.go:606] [GetControllerMetricInfo] Iniciando para o pod: default/test-deployment3-6c95cffb97-d2xv7
I0124 13:54:22.152192       1 scheduler.go:611] [GetControllerMetricInfo] Obtendo o nome do controlador para o pod: default/test-deployment3-6c95cffb97-d2xv7
I0124 13:54:22.152207       1 types.go:743] [ControllerName] Verificando as anotações do pod default/test-deployment3-6c95cffb97-d2xv7
I0124 13:54:22.152224       1 types.go:761] [ControllerName] Anotação 'controller' encontrada para o pod default/test-deployment3-6c95cffb97-d2xv7: test-controller3
I0124 13:54:22.152241       1 scheduler.go:614] [GetControllerMetricInfo] Métricas do controlador definidas para o pod: default/test-deployment3-6c95cffb97-d2xv7
W0124 13:54:22.152261       1 scheduler.go:125] [cacheMiss] Métricas não encontradas para o pod: default/test-deployment3-6c95cffb97-d2xv7
I0124 13:54:22.160156       1 scheduler.go:70] Estado no Informer: map[controller:test-controller3]
I0124 13:54:22.160685       1 scheduler.go:71] Estado real no cluster: map[controller:test-controller3]
W0124 13:54:22.161167       1 scheduler.go:135] [WaitForPodsOnCache] Pod test-deployment3-6c95cffb97-d2xv7 não encontrado no cache. Tentando novamente...
I0124 13:54:22.262819       1 scheduler.go:606] [GetControllerMetricInfo] Iniciando para o pod: default/test-deployment3-6c95cffb97-d2xv7
I0124 13:54:22.263018       1 scheduler.go:611] [GetControllerMetricInfo] Obtendo o nome do controlador para o pod: default/test-deployment3-6c95cffb97-d2xv7
I0124 13:54:22.263036       1 types.go:743] [ControllerName] Verificando as anotações do pod default/test-deployment3-6c95cffb97-d2xv7
I0124 13:54:22.263051       1 types.go:761] [ControllerName] Anotação 'controller' encontrada para o pod default/test-deployment3-6c95cffb97-d2xv7: test-controller3
I0124 13:54:22.263122       1 scheduler.go:614] [GetControllerMetricInfo] Métricas do controlador definidas para o pod: default/test-deployment3-6c95cffb97-d2xv7
W0124 13:54:22.263147       1 scheduler.go:125] [cacheMiss] Métricas não encontradas para o pod: default/test-deployment3-6c95cffb97-d2xv7
I0124 13:54:22.270378       1 scheduler.go:70] Estado no Informer: map[controller:test-controller3]
I0124 13:54:22.271108       1 scheduler.go:71] Estado real no cluster: map[controller:test-controller3]
W0124 13:54:22.271623       1 scheduler.go:135] [WaitForPodsOnCache] Pod test-deployment3-6c95cffb97-d2xv7 não encontrado no cache. Tentando novamente...
I0124 13:54:22.373267       1 scheduler.go:606] [GetControllerMetricInfo] Iniciando para o pod: default/test-deployment3-6c95cffb97-d2xv7
I0124 13:54:22.373310       1 scheduler.go:611] [GetControllerMetricInfo] Obtendo o nome do controlador para o pod: default/test-deployment3-6c95cffb97-d2xv7
I0124 13:54:22.373324       1 types.go:743] [ControllerName] Verificando as anotações do pod default/test-deployment3-6c95cffb97-d2xv7
I0124 13:54:22.373339       1 types.go:761] [ControllerName] Anotação 'controller' encontrada para o pod default/test-deployment3-6c95cffb97-d2xv7: test-controller3
I0124 13:54:22.373354       1 scheduler.go:614] [GetControllerMetricInfo] Métricas do controlador definidas para o pod: default/test-deployment3-6c95cffb97-d2xv7
W0124 13:54:22.373371       1 scheduler.go:125] [cacheMiss] Métricas não encontradas para o pod: default/test-deployment3-6c95cffb97-d2xv7
I0124 13:54:22.383541       1 scheduler.go:70] Estado no Informer: map[controller:test-controller3]
I0124 13:54:22.383997       1 scheduler.go:71] Estado real no cluster: map[controller:test-controller3]
W0124 13:54:22.384360       1 scheduler.go:135] [WaitForPodsOnCache] Pod test-deployment3-6c95cffb97-d2xv7 não encontrado no cache. Tentando novamente...
I0124 13:54:22.485167       1 scheduler.go:606] [GetControllerMetricInfo] Iniciando para o pod: default/test-deployment3-6c95cffb97-d2xv7
I0124 13:54:22.485650       1 scheduler.go:611] [GetControllerMetricInfo] Obtendo o nome do controlador para o pod: default/test-deployment3-6c95cffb97-d2xv7
I0124 13:54:22.486258       1 types.go:743] [ControllerName] Verificando as anotações do pod default/test-deployment3-6c95cffb97-d2xv7
I0124 13:54:22.486829       1 types.go:761] [ControllerName] Anotação 'controller' encontrada para o pod default/test-deployment3-6c95cffb97-d2xv7: test-controller3
I0124 13:54:22.487359       1 scheduler.go:614] [GetControllerMetricInfo] Métricas do controlador definidas para o pod: default/test-deployment3-6c95cffb97-d2xv7
W0124 13:54:22.487760       1 scheduler.go:125] [cacheMiss] Métricas não encontradas para o pod: default/test-deployment3-6c95cffb97-d2xv7
I0124 13:54:22.603493       1 scheduler.go:70] Estado no Informer: map[controller:test-controller3]
I0124 13:54:22.604309       1 scheduler.go:71] Estado real no cluster: map[controller:test-controller3]
W0124 13:54:22.604388       1 scheduler.go:135] [WaitForPodsOnCache] Pod test-deployment3-6c95cffb97-d2xv7 não encontrado no cache. Tentando novamente...
I0124 13:54:22.705276       1 scheduler.go:606] [GetControllerMetricInfo] Iniciando para o pod: default/test-deployment3-6c95cffb97-d2xv7
I0124 13:54:22.705399       1 scheduler.go:611] [GetControllerMetricInfo] Obtendo o nome do controlador para o pod: default/test-deployment3-6c95cffb97-d2xv7
I0124 13:54:22.705418       1 types.go:743] [ControllerName] Verificando as anotações do pod default/test-deployment3-6c95cffb97-d2xv7
I0124 13:54:22.705435       1 types.go:761] [ControllerName] Anotação 'controller' encontrada para o pod default/test-deployment3-6c95cffb97-d2xv7: test-controller3
I0124 13:54:22.706132       1 scheduler.go:614] [GetControllerMetricInfo] Métricas do controlador definidas para o pod: default/test-deployment3-6c95cffb97-d2xv7
W0124 13:54:22.706159       1 scheduler.go:125] [cacheMiss] Métricas não encontradas para o pod: default/test-deployment3-6c95cffb97-d2xv7
I0124 13:54:22.714108       1 scheduler.go:70] Estado no Informer: map[controller:test-controller3]
I0124 13:54:22.714777       1 scheduler.go:71] Estado real no cluster: map[controller:test-controller3]
W0124 13:54:22.715465       1 scheduler.go:135] [WaitForPodsOnCache] Pod test-deployment3-6c95cffb97-d2xv7 não encontrado no cache. Tentando novamente...
I0124 13:54:22.817129       1 scheduler.go:606] [GetControllerMetricInfo] Iniciando para o pod: default/test-deployment3-6c95cffb97-d2xv7
I0124 13:54:22.817565       1 scheduler.go:611] [GetControllerMetricInfo] Obtendo o nome do controlador para o pod: default/test-deployment3-6c95cffb97-d2xv7
I0124 13:54:22.817839       1 types.go:743] [ControllerName] Verificando as anotações do pod default/test-deployment3-6c95cffb97-d2xv7
I0124 13:54:22.818416       1 types.go:761] [ControllerName] Anotação 'controller' encontrada para o pod default/test-deployment3-6c95cffb97-d2xv7: test-controller3
I0124 13:54:22.819037       1 scheduler.go:614] [GetControllerMetricInfo] Métricas do controlador definidas para o pod: default/test-deployment3-6c95cffb97-d2xv7
W0124 13:54:22.819165       1 scheduler.go:125] [cacheMiss] Métricas não encontradas para o pod: default/test-deployment3-6c95cffb97-d2xv7
I0124 13:54:22.827555       1 scheduler.go:70] Estado no Informer: map[controller:test-controller3]
I0124 13:54:22.827739       1 scheduler.go:71] Estado real no cluster: map[controller:test-controller3]
W0124 13:54:22.827788       1 scheduler.go:135] [WaitForPodsOnCache] Pod test-deployment3-6c95cffb97-d2xv7 não encontrado no cache. Tentando novamente...
I0124 13:54:22.928277       1 scheduler.go:606] [GetControllerMetricInfo] Iniciando para o pod: default/test-deployment3-6c95cffb97-d2xv7
I0124 13:54:22.928484       1 scheduler.go:611] [GetControllerMetricInfo] Obtendo o nome do controlador para o pod: default/test-deployment3-6c95cffb97-d2xv7
I0124 13:54:22.928528       1 types.go:743] [ControllerName] Verificando as anotações do pod default/test-deployment3-6c95cffb97-d2xv7
I0124 13:54:22.928571       1 types.go:761] [ControllerName] Anotação 'controller' encontrada para o pod default/test-deployment3-6c95cffb97-d2xv7: test-controller3
I0124 13:54:22.928612       1 scheduler.go:614] [GetControllerMetricInfo] Métricas do controlador definidas para o pod: default/test-deployment3-6c95cffb97-d2xv7
W0124 13:54:22.928657       1 scheduler.go:125] [cacheMiss] Métricas não encontradas para o pod: default/test-deployment3-6c95cffb97-d2xv7
I0124 13:54:22.936778       1 scheduler.go:70] Estado no Informer: map[controller:test-controller3]
I0124 13:54:22.937343       1 scheduler.go:71] Estado real no cluster: map[controller:test-controller3]
W0124 13:54:22.937601       1 scheduler.go:135] [WaitForPodsOnCache] Pod test-deployment3-6c95cffb97-d2xv7 não encontrado no cache. Tentando novamente...
I0124 13:54:23.038234       1 scheduler.go:606] [GetControllerMetricInfo] Iniciando para o pod: default/test-deployment3-6c95cffb97-d2xv7
I0124 13:54:23.038352       1 scheduler.go:611] [GetControllerMetricInfo] Obtendo o nome do controlador para o pod: default/test-deployment3-6c95cffb97-d2xv7
I0124 13:54:23.038371       1 types.go:743] [ControllerName] Verificando as anotações do pod default/test-deployment3-6c95cffb97-d2xv7
I0124 13:54:23.038387       1 types.go:761] [ControllerName] Anotação 'controller' encontrada para o pod default/test-deployment3-6c95cffb97-d2xv7: test-controller3
I0124 13:54:23.039235       1 scheduler.go:614] [GetControllerMetricInfo] Métricas do controlador definidas para o pod: default/test-deployment3-6c95cffb97-d2xv7
W0124 13:54:23.039326       1 scheduler.go:125] [cacheMiss] Métricas não encontradas para o pod: default/test-deployment3-6c95cffb97-d2xv7
I0124 13:54:23.047692       1 scheduler.go:70] Estado no Informer: map[controller:test-controller3]
I0124 13:54:23.047809       1 scheduler.go:71] Estado real no cluster: map[controller:test-controller3]
W0124 13:54:23.047966       1 scheduler.go:135] [WaitForPodsOnCache] Pod test-deployment3-6c95cffb97-d2xv7 não encontrado no cache. Tentando novamente...
I0124 13:54:23.152831       1 scheduler.go:606] [GetControllerMetricInfo] Iniciando para o pod: default/test-deployment3-6c95cffb97-d2xv7
I0124 13:54:23.153365       1 scheduler.go:611] [GetControllerMetricInfo] Obtendo o nome do controlador para o pod: default/test-deployment3-6c95cffb97-d2xv7
I0124 13:54:23.153387       1 types.go:743] [ControllerName] Verificando as anotações do pod default/test-deployment3-6c95cffb97-d2xv7
I0124 13:54:23.153563       1 types.go:761] [ControllerName] Anotação 'controller' encontrada para o pod default/test-deployment3-6c95cffb97-d2xv7: test-controller3
I0124 13:54:23.153738       1 scheduler.go:614] [GetControllerMetricInfo] Métricas do controlador definidas para o pod: default/test-deployment3-6c95cffb97-d2xv7
W0124 13:54:23.154014       1 scheduler.go:125] [cacheMiss] Métricas não encontradas para o pod: default/test-deployment3-6c95cffb97-d2xv7
I0124 13:54:23.167551       1 scheduler.go:70] Estado no Informer: map[controller:test-controller3]
I0124 13:54:23.167652       1 scheduler.go:71] Estado real no cluster: map[controller:test-controller3]
W0124 13:54:23.167674       1 scheduler.go:135] [WaitForPodsOnCache] Pod test-deployment3-6c95cffb97-d2xv7 não encontrado no cache. Tentando novamente...
I0124 13:54:23.269004       1 scheduler.go:606] [GetControllerMetricInfo] Iniciando para o pod: default/test-deployment3-6c95cffb97-d2xv7
I0124 13:54:23.269454       1 scheduler.go:611] [GetControllerMetricInfo] Obtendo o nome do controlador para o pod: default/test-deployment3-6c95cffb97-d2xv7
I0124 13:54:23.269633       1 types.go:743] [ControllerName] Verificando as anotações do pod default/test-deployment3-6c95cffb97-d2xv7
I0124 13:54:23.269793       1 types.go:761] [ControllerName] Anotação 'controller' encontrada para o pod default/test-deployment3-6c95cffb97-d2xv7: test-controller3
I0124 13:54:23.269833       1 scheduler.go:614] [GetControllerMetricInfo] Métricas do controlador definidas para o pod: default/test-deployment3-6c95cffb97-d2xv7
W0124 13:54:23.270034       1 scheduler.go:125] [cacheMiss] Métricas não encontradas para o pod: default/test-deployment3-6c95cffb97-d2xv7
I0124 13:54:23.277544       1 scheduler.go:70] Estado no Informer: map[controller:test-controller3]
I0124 13:54:23.277588       1 scheduler.go:71] Estado real no cluster: map[controller:test-controller3]
W0124 13:54:23.277605       1 scheduler.go:135] [WaitForPodsOnCache] Pod test-deployment3-6c95cffb97-d2xv7 não encontrado no cache. Tentando novamente...
I0124 13:54:23.378089       1 scheduler.go:606] [GetControllerMetricInfo] Iniciando para o pod: default/test-deployment3-6c95cffb97-d2xv7
I0124 13:54:23.378118       1 scheduler.go:611] [GetControllerMetricInfo] Obtendo o nome do controlador para o pod: default/test-deployment3-6c95cffb97-d2xv7
I0124 13:54:23.378128       1 types.go:743] [ControllerName] Verificando as anotações do pod default/test-deployment3-6c95cffb97-d2xv7
I0124 13:54:23.378137       1 types.go:761] [ControllerName] Anotação 'controller' encontrada para o pod default/test-deployment3-6c95cffb97-d2xv7: test-controller3
I0124 13:54:23.378145       1 scheduler.go:614] [GetControllerMetricInfo] Métricas do controlador definidas para o pod: default/test-deployment3-6c95cffb97-d2xv7
W0124 13:54:23.378708       1 scheduler.go:125] [cacheMiss] Métricas não encontradas para o pod: default/test-deployment3-6c95cffb97-d2xv7
I0124 13:54:23.383952       1 scheduler.go:70] Estado no Informer: map[controller:test-controller3]
I0124 13:54:23.384117       1 scheduler.go:71] Estado real no cluster: map[controller:test-controller3]
W0124 13:54:23.384141       1 scheduler.go:135] [WaitForPodsOnCache] Pod test-deployment3-6c95cffb97-d2xv7 não encontrado no cache. Tentando novamente...
I0124 13:54:23.484944       1 scheduler.go:606] [GetControllerMetricInfo] Iniciando para o pod: default/test-deployment3-6c95cffb97-d2xv7
I0124 13:54:23.485012       1 scheduler.go:611] [GetControllerMetricInfo] Obtendo o nome do controlador para o pod: default/test-deployment3-6c95cffb97-d2xv7
I0124 13:54:23.485025       1 types.go:743] [ControllerName] Verificando as anotações do pod default/test-deployment3-6c95cffb97-d2xv7
I0124 13:54:23.485037       1 types.go:761] [ControllerName] Anotação 'controller' encontrada para o pod default/test-deployment3-6c95cffb97-d2xv7: test-controller3
I0124 13:54:23.485046       1 scheduler.go:614] [GetControllerMetricInfo] Métricas do controlador definidas para o pod: default/test-deployment3-6c95cffb97-d2xv7
W0124 13:54:23.485057       1 scheduler.go:125] [cacheMiss] Métricas não encontradas para o pod: default/test-deployment3-6c95cffb97-d2xv7
I0124 13:54:23.489280       1 scheduler.go:70] Estado no Informer: map[controller:test-controller3]
I0124 13:54:23.489339       1 scheduler.go:71] Estado real no cluster: map[controller:test-controller3]
W0124 13:54:23.489351       1 scheduler.go:135] [WaitForPodsOnCache] Pod test-deployment3-6c95cffb97-d2xv7 não encontrado no cache. Tentando novamente...
I0124 13:54:23.590274       1 scheduler.go:606] [GetControllerMetricInfo] Iniciando para o pod: default/test-deployment3-6c95cffb97-d2xv7
I0124 13:54:23.590511       1 scheduler.go:611] [GetControllerMetricInfo] Obtendo o nome do controlador para o pod: default/test-deployment3-6c95cffb97-d2xv7
I0124 13:54:23.590560       1 types.go:743] [ControllerName] Verificando as anotações do pod default/test-deployment3-6c95cffb97-d2xv7
I0124 13:54:23.590600       1 types.go:761] [ControllerName] Anotação 'controller' encontrada para o pod default/test-deployment3-6c95cffb97-d2xv7: test-controller3
I0124 13:54:23.590664       1 scheduler.go:614] [GetControllerMetricInfo] Métricas do controlador definidas para o pod: default/test-deployment3-6c95cffb97-d2xv7
W0124 13:54:23.590742       1 scheduler.go:125] [cacheMiss] Métricas não encontradas para o pod: default/test-deployment3-6c95cffb97-d2xv7
I0124 13:54:23.598151       1 scheduler.go:70] Estado no Informer: map[controller:test-controller3]
I0124 13:54:23.598246       1 scheduler.go:71] Estado real no cluster: map[controller:test-controller3]
W0124 13:54:23.598269       1 scheduler.go:135] [WaitForPodsOnCache] Pod test-deployment3-6c95cffb97-d2xv7 não encontrado no cache. Tentando novamente...
I0124 13:54:23.699310       1 scheduler.go:606] [GetControllerMetricInfo] Iniciando para o pod: default/test-deployment3-6c95cffb97-d2xv7
I0124 13:54:23.699359       1 scheduler.go:611] [GetControllerMetricInfo] Obtendo o nome do controlador para o pod: default/test-deployment3-6c95cffb97-d2xv7
I0124 13:54:23.699372       1 types.go:743] [ControllerName] Verificando as anotações do pod default/test-deployment3-6c95cffb97-d2xv7
I0124 13:54:23.699386       1 types.go:761] [ControllerName] Anotação 'controller' encontrada para o pod default/test-deployment3-6c95cffb97-d2xv7: test-controller3
I0124 13:54:23.699401       1 scheduler.go:614] [GetControllerMetricInfo] Métricas do controlador definidas para o pod: default/test-deployment3-6c95cffb97-d2xv7
W0124 13:54:23.699995       1 scheduler.go:125] [cacheMiss] Métricas não encontradas para o pod: default/test-deployment3-6c95cffb97-d2xv7
I0124 13:54:23.708978       1 scheduler.go:70] Estado no Informer: map[controller:test-controller3]
I0124 13:54:23.709085       1 scheduler.go:71] Estado real no cluster: map[controller:test-controller3]
W0124 13:54:23.709107       1 scheduler.go:135] [WaitForPodsOnCache] Pod test-deployment3-6c95cffb97-d2xv7 não encontrado no cache. Tentando novamente...
I0124 13:54:23.809756       1 scheduler.go:606] [GetControllerMetricInfo] Iniciando para o pod: default/test-deployment3-6c95cffb97-d2xv7
I0124 13:54:23.810160       1 scheduler.go:611] [GetControllerMetricInfo] Obtendo o nome do controlador para o pod: default/test-deployment3-6c95cffb97-d2xv7
I0124 13:54:23.810433       1 types.go:743] [ControllerName] Verificando as anotações do pod default/test-deployment3-6c95cffb97-d2xv7
I0124 13:54:23.810842       1 types.go:761] [ControllerName] Anotação 'controller' encontrada para o pod default/test-deployment3-6c95cffb97-d2xv7: test-controller3
I0124 13:54:23.811235       1 scheduler.go:614] [GetControllerMetricInfo] Métricas do controlador definidas para o pod: default/test-deployment3-6c95cffb97-d2xv7
W0124 13:54:23.811500       1 scheduler.go:125] [cacheMiss] Métricas não encontradas para o pod: default/test-deployment3-6c95cffb97-d2xv7
I0124 13:54:23.820289       1 scheduler.go:70] Estado no Informer: map[controller:test-controller3]
I0124 13:54:23.820329       1 scheduler.go:71] Estado real no cluster: map[controller:test-controller3]
W0124 13:54:23.820345       1 scheduler.go:135] [WaitForPodsOnCache] Pod test-deployment3-6c95cffb97-d2xv7 não encontrado no cache. Tentando novamente...
I0124 13:54:23.921400       1 scheduler.go:606] [GetControllerMetricInfo] Iniciando para o pod: default/test-deployment3-6c95cffb97-d2xv7
I0124 13:54:23.921641       1 scheduler.go:611] [GetControllerMetricInfo] Obtendo o nome do controlador para o pod: default/test-deployment3-6c95cffb97-d2xv7
I0124 13:54:23.921804       1 types.go:743] [ControllerName] Verificando as anotações do pod default/test-deployment3-6c95cffb97-d2xv7
I0124 13:54:23.922291       1 types.go:761] [ControllerName] Anotação 'controller' encontrada para o pod default/test-deployment3-6c95cffb97-d2xv7: test-controller3
I0124 13:54:23.922736       1 scheduler.go:614] [GetControllerMetricInfo] Métricas do controlador definidas para o pod: default/test-deployment3-6c95cffb97-d2xv7
W0124 13:54:23.923166       1 scheduler.go:125] [cacheMiss] Métricas não encontradas para o pod: default/test-deployment3-6c95cffb97-d2xv7
I0124 13:54:23.930575       1 scheduler.go:70] Estado no Informer: map[controller:test-controller3]
I0124 13:54:23.931052       1 scheduler.go:71] Estado real no cluster: map[controller:test-controller3]
W0124 13:54:23.931310       1 scheduler.go:135] [WaitForPodsOnCache] Pod test-deployment3-6c95cffb97-d2xv7 não encontrado no cache. Tentando novamente...
I0124 13:54:24.031970       1 scheduler.go:606] [GetControllerMetricInfo] Iniciando para o pod: default/test-deployment3-6c95cffb97-d2xv7
I0124 13:54:24.032374       1 scheduler.go:611] [GetControllerMetricInfo] Obtendo o nome do controlador para o pod: default/test-deployment3-6c95cffb97-d2xv7
I0124 13:54:24.032722       1 types.go:743] [ControllerName] Verificando as anotações do pod default/test-deployment3-6c95cffb97-d2xv7
I0124 13:54:24.033075       1 types.go:761] [ControllerName] Anotação 'controller' encontrada para o pod default/test-deployment3-6c95cffb97-d2xv7: test-controller3
I0124 13:54:24.033177       1 scheduler.go:614] [GetControllerMetricInfo] Métricas do controlador definidas para o pod: default/test-deployment3-6c95cffb97-d2xv7
W0124 13:54:24.033380       1 scheduler.go:125] [cacheMiss] Métricas não encontradas para o pod: default/test-deployment3-6c95cffb97-d2xv7
I0124 13:54:24.040758       1 scheduler.go:70] Estado no Informer: map[controller:test-controller3]
I0124 13:54:24.040965       1 scheduler.go:71] Estado real no cluster: map[controller:test-controller3]
W0124 13:54:24.040988       1 scheduler.go:135] [WaitForPodsOnCache] Pod test-deployment3-6c95cffb97-d2xv7 não encontrado no cache. Tentando novamente...
I0124 13:54:24.142033       1 scheduler.go:606] [GetControllerMetricInfo] Iniciando para o pod: default/test-deployment3-6c95cffb97-d2xv7
I0124 13:54:24.142446       1 scheduler.go:611] [GetControllerMetricInfo] Obtendo o nome do controlador para o pod: default/test-deployment3-6c95cffb97-d2xv7
I0124 13:54:24.142777       1 types.go:743] [ControllerName] Verificando as anotações do pod default/test-deployment3-6c95cffb97-d2xv7
I0124 13:54:24.143163       1 types.go:761] [ControllerName] Anotação 'controller' encontrada para o pod default/test-deployment3-6c95cffb97-d2xv7: test-controller3
I0124 13:54:24.143285       1 scheduler.go:614] [GetControllerMetricInfo] Métricas do controlador definidas para o pod: default/test-deployment3-6c95cffb97-d2xv7
W0124 13:54:24.143376       1 scheduler.go:125] [cacheMiss] Métricas não encontradas para o pod: default/test-deployment3-6c95cffb97-d2xv7
I0124 13:54:24.150231       1 scheduler.go:70] Estado no Informer: map[controller:test-controller3]
I0124 13:54:24.150333       1 scheduler.go:71] Estado real no cluster: map[controller:test-controller3]
W0124 13:54:24.150355       1 scheduler.go:135] [WaitForPodsOnCache] Pod test-deployment3-6c95cffb97-d2xv7 não encontrado no cache. Tentando novamente...
I0124 13:54:24.251519       1 scheduler.go:606] [GetControllerMetricInfo] Iniciando para o pod: default/test-deployment3-6c95cffb97-d2xv7
I0124 13:54:24.252021       1 scheduler.go:611] [GetControllerMetricInfo] Obtendo o nome do controlador para o pod: default/test-deployment3-6c95cffb97-d2xv7
I0124 13:54:24.252586       1 types.go:743] [ControllerName] Verificando as anotações do pod default/test-deployment3-6c95cffb97-d2xv7
I0124 13:54:24.252717       1 types.go:761] [ControllerName] Anotação 'controller' encontrada para o pod default/test-deployment3-6c95cffb97-d2xv7: test-controller3
I0124 13:54:24.253440       1 scheduler.go:614] [GetControllerMetricInfo] Métricas do controlador definidas para o pod: default/test-deployment3-6c95cffb97-d2xv7
W0124 13:54:24.253568       1 scheduler.go:125] [cacheMiss] Métricas não encontradas para o pod: default/test-deployment3-6c95cffb97-d2xv7
I0124 13:54:24.262512       1 scheduler.go:70] Estado no Informer: map[controller:test-controller3]
I0124 13:54:24.262619       1 scheduler.go:71] Estado real no cluster: map[controller:test-controller3]
W0124 13:54:24.262667       1 scheduler.go:135] [WaitForPodsOnCache] Pod test-deployment3-6c95cffb97-d2xv7 não encontrado no cache. Tentando novamente...
I0124 13:54:24.363041       1 scheduler.go:606] [GetControllerMetricInfo] Iniciando para o pod: default/test-deployment3-6c95cffb97-d2xv7
I0124 13:54:24.363484       1 scheduler.go:611] [GetControllerMetricInfo] Obtendo o nome do controlador para o pod: default/test-deployment3-6c95cffb97-d2xv7
I0124 13:54:24.363639       1 types.go:743] [ControllerName] Verificando as anotações do pod default/test-deployment3-6c95cffb97-d2xv7
I0124 13:54:24.363759       1 types.go:761] [ControllerName] Anotação 'controller' encontrada para o pod default/test-deployment3-6c95cffb97-d2xv7: test-controller3
I0124 13:54:24.363968       1 scheduler.go:614] [GetControllerMetricInfo] Métricas do controlador definidas para o pod: default/test-deployment3-6c95cffb97-d2xv7
W0124 13:54:24.364218       1 scheduler.go:125] [cacheMiss] Métricas não encontradas para o pod: default/test-deployment3-6c95cffb97-d2xv7
I0124 13:54:24.370343       1 scheduler.go:70] Estado no Informer: map[controller:test-controller3]
I0124 13:54:24.370443       1 scheduler.go:71] Estado real no cluster: map[controller:test-controller3]
W0124 13:54:24.370464       1 scheduler.go:135] [WaitForPodsOnCache] Pod test-deployment3-6c95cffb97-d2xv7 não encontrado no cache. Tentando novamente...
I0124 13:54:24.470812       1 scheduler.go:606] [GetControllerMetricInfo] Iniciando para o pod: default/test-deployment3-6c95cffb97-d2xv7
I0124 13:54:24.471036       1 scheduler.go:611] [GetControllerMetricInfo] Obtendo o nome do controlador para o pod: default/test-deployment3-6c95cffb97-d2xv7
I0124 13:54:24.471065       1 types.go:743] [ControllerName] Verificando as anotações do pod default/test-deployment3-6c95cffb97-d2xv7
I0124 13:54:24.471082       1 types.go:761] [ControllerName] Anotação 'controller' encontrada para o pod default/test-deployment3-6c95cffb97-d2xv7: test-controller3
I0124 13:54:24.471098       1 scheduler.go:614] [GetControllerMetricInfo] Métricas do controlador definidas para o pod: default/test-deployment3-6c95cffb97-d2xv7
W0124 13:54:24.471118       1 scheduler.go:125] [cacheMiss] Métricas não encontradas para o pod: default/test-deployment3-6c95cffb97-d2xv7
I0124 13:54:24.478727       1 scheduler.go:70] Estado no Informer: map[controller:test-controller3]
I0124 13:54:24.479517       1 scheduler.go:71] Estado real no cluster: map[controller:test-controller3]
W0124 13:54:24.479653       1 scheduler.go:135] [WaitForPodsOnCache] Pod test-deployment3-6c95cffb97-d2xv7 não encontrado no cache. Tentando novamente...
I0124 13:54:24.580518       1 scheduler.go:606] [GetControllerMetricInfo] Iniciando para o pod: default/test-deployment3-6c95cffb97-d2xv7
I0124 13:54:24.580620       1 scheduler.go:611] [GetControllerMetricInfo] Obtendo o nome do controlador para o pod: default/test-deployment3-6c95cffb97-d2xv7
I0124 13:54:24.580639       1 types.go:743] [ControllerName] Verificando as anotações do pod default/test-deployment3-6c95cffb97-d2xv7
I0124 13:54:24.580656       1 types.go:761] [ControllerName] Anotação 'controller' encontrada para o pod default/test-deployment3-6c95cffb97-d2xv7: test-controller3
I0124 13:54:24.580761       1 scheduler.go:614] [GetControllerMetricInfo] Métricas do controlador definidas para o pod: default/test-deployment3-6c95cffb97-d2xv7
W0124 13:54:24.581209       1 scheduler.go:125] [cacheMiss] Métricas não encontradas para o pod: default/test-deployment3-6c95cffb97-d2xv7
I0124 13:54:24.590243       1 scheduler.go:70] Estado no Informer: map[controller:test-controller3]
I0124 13:54:24.591009       1 scheduler.go:71] Estado real no cluster: map[controller:test-controller3]
W0124 13:54:24.591214       1 scheduler.go:135] [WaitForPodsOnCache] Pod test-deployment3-6c95cffb97-d2xv7 não encontrado no cache. Tentando novamente...
I0124 13:54:24.691842       1 scheduler.go:606] [GetControllerMetricInfo] Iniciando para o pod: default/test-deployment3-6c95cffb97-d2xv7
I0124 13:54:24.692561       1 scheduler.go:611] [GetControllerMetricInfo] Obtendo o nome do controlador para o pod: default/test-deployment3-6c95cffb97-d2xv7
I0124 13:54:24.692692       1 types.go:743] [ControllerName] Verificando as anotações do pod default/test-deployment3-6c95cffb97-d2xv7
I0124 13:54:24.692752       1 types.go:761] [ControllerName] Anotação 'controller' encontrada para o pod default/test-deployment3-6c95cffb97-d2xv7: test-controller3
I0124 13:54:24.692824       1 scheduler.go:614] [GetControllerMetricInfo] Métricas do controlador definidas para o pod: default/test-deployment3-6c95cffb97-d2xv7
W0124 13:54:24.693071       1 scheduler.go:125] [cacheMiss] Métricas não encontradas para o pod: default/test-deployment3-6c95cffb97-d2xv7
I0124 13:54:24.704511       1 scheduler.go:70] Estado no Informer: map[controller:test-controller3]
I0124 13:54:24.704742       1 scheduler.go:71] Estado real no cluster: map[controller:test-controller3]
W0124 13:54:24.704792       1 scheduler.go:135] [WaitForPodsOnCache] Pod test-deployment3-6c95cffb97-d2xv7 não encontrado no cache. Tentando novamente...
I0124 13:54:24.811354       1 scheduler.go:606] [GetControllerMetricInfo] Iniciando para o pod: default/test-deployment3-6c95cffb97-d2xv7
I0124 13:54:24.812483       1 scheduler.go:611] [GetControllerMetricInfo] Obtendo o nome do controlador para o pod: default/test-deployment3-6c95cffb97-d2xv7
I0124 13:54:24.812835       1 types.go:743] [ControllerName] Verificando as anotações do pod default/test-deployment3-6c95cffb97-d2xv7
I0124 13:54:24.815602       1 types.go:761] [ControllerName] Anotação 'controller' encontrada para o pod default/test-deployment3-6c95cffb97-d2xv7: test-controller3
I0124 13:54:24.817138       1 scheduler.go:614] [GetControllerMetricInfo] Métricas do controlador definidas para o pod: default/test-deployment3-6c95cffb97-d2xv7
W0124 13:54:24.817950       1 scheduler.go:125] [cacheMiss] Métricas não encontradas para o pod: default/test-deployment3-6c95cffb97-d2xv7
I0124 13:54:24.830086       1 scheduler.go:70] Estado no Informer: map[controller:test-controller3]
I0124 13:54:24.830286       1 scheduler.go:71] Estado real no cluster: map[controller:test-controller3]
W0124 13:54:24.830332       1 scheduler.go:135] [WaitForPodsOnCache] Pod test-deployment3-6c95cffb97-d2xv7 não encontrado no cache. Tentando novamente...
I0124 13:54:24.931762       1 scheduler.go:606] [GetControllerMetricInfo] Iniciando para o pod: default/test-deployment3-6c95cffb97-d2xv7
I0124 13:54:24.931965       1 scheduler.go:611] [GetControllerMetricInfo] Obtendo o nome do controlador para o pod: default/test-deployment3-6c95cffb97-d2xv7
I0124 13:54:24.931984       1 types.go:743] [ControllerName] Verificando as anotações do pod default/test-deployment3-6c95cffb97-d2xv7
I0124 13:54:24.932436       1 types.go:761] [ControllerName] Anotação 'controller' encontrada para o pod default/test-deployment3-6c95cffb97-d2xv7: test-controller3
I0124 13:54:24.932517       1 scheduler.go:614] [GetControllerMetricInfo] Métricas do controlador definidas para o pod: default/test-deployment3-6c95cffb97-d2xv7
W0124 13:54:24.932541       1 scheduler.go:125] [cacheMiss] Métricas não encontradas para o pod: default/test-deployment3-6c95cffb97-d2xv7
I0124 13:54:24.942348       1 scheduler.go:70] Estado no Informer: map[controller:test-controller3]
I0124 13:54:24.943303       1 scheduler.go:71] Estado real no cluster: map[controller:test-controller3]
W0124 13:54:24.943994       1 scheduler.go:135] [WaitForPodsOnCache] Pod test-deployment3-6c95cffb97-d2xv7 não encontrado no cache. Tentando novamente...
I0124 13:54:25.045083       1 scheduler.go:606] [GetControllerMetricInfo] Iniciando para o pod: default/test-deployment3-6c95cffb97-d2xv7
I0124 13:54:25.045184       1 scheduler.go:611] [GetControllerMetricInfo] Obtendo o nome do controlador para o pod: default/test-deployment3-6c95cffb97-d2xv7
I0124 13:54:25.045201       1 types.go:743] [ControllerName] Verificando as anotações do pod default/test-deployment3-6c95cffb97-d2xv7
I0124 13:54:25.045218       1 types.go:761] [ControllerName] Anotação 'controller' encontrada para o pod default/test-deployment3-6c95cffb97-d2xv7: test-controller3
I0124 13:54:25.045235       1 scheduler.go:614] [GetControllerMetricInfo] Métricas do controlador definidas para o pod: default/test-deployment3-6c95cffb97-d2xv7
W0124 13:54:25.045254       1 scheduler.go:125] [cacheMiss] Métricas não encontradas para o pod: default/test-deployment3-6c95cffb97-d2xv7
I0124 13:54:25.052220       1 scheduler.go:70] Estado no Informer: map[controller:test-controller3]
I0124 13:54:25.052643       1 scheduler.go:71] Estado real no cluster: map[controller:test-controller3]
W0124 13:54:25.053002       1 scheduler.go:135] [WaitForPodsOnCache] Pod test-deployment3-6c95cffb97-d2xv7 não encontrado no cache. Tentando novamente...
I0124 13:54:25.154311       1 scheduler.go:606] [GetControllerMetricInfo] Iniciando para o pod: default/test-deployment3-6c95cffb97-d2xv7
I0124 13:54:25.154378       1 scheduler.go:611] [GetControllerMetricInfo] Obtendo o nome do controlador para o pod: default/test-deployment3-6c95cffb97-d2xv7
I0124 13:54:25.154393       1 types.go:743] [ControllerName] Verificando as anotações do pod default/test-deployment3-6c95cffb97-d2xv7
I0124 13:54:25.154409       1 types.go:761] [ControllerName] Anotação 'controller' encontrada para o pod default/test-deployment3-6c95cffb97-d2xv7: test-controller3
I0124 13:54:25.154425       1 scheduler.go:614] [GetControllerMetricInfo] Métricas do controlador definidas para o pod: default/test-deployment3-6c95cffb97-d2xv7
W0124 13:54:25.154445       1 scheduler.go:125] [cacheMiss] Métricas não encontradas para o pod: default/test-deployment3-6c95cffb97-d2xv7
I0124 13:54:25.160614       1 scheduler.go:70] Estado no Informer: map[controller:test-controller3]
I0124 13:54:25.160726       1 scheduler.go:71] Estado real no cluster: map[controller:test-controller3]
W0124 13:54:25.160749       1 scheduler.go:135] [WaitForPodsOnCache] Pod test-deployment3-6c95cffb97-d2xv7 não encontrado no cache. Tentando novamente...
I0124 13:54:25.261755       1 scheduler.go:606] [GetControllerMetricInfo] Iniciando para o pod: default/test-deployment3-6c95cffb97-d2xv7
I0124 13:54:25.261970       1 scheduler.go:611] [GetControllerMetricInfo] Obtendo o nome do controlador para o pod: default/test-deployment3-6c95cffb97-d2xv7
I0124 13:54:25.261990       1 types.go:743] [ControllerName] Verificando as anotações do pod default/test-deployment3-6c95cffb97-d2xv7
I0124 13:54:25.262006       1 types.go:761] [ControllerName] Anotação 'controller' encontrada para o pod default/test-deployment3-6c95cffb97-d2xv7: test-controller3
I0124 13:54:25.262021       1 scheduler.go:614] [GetControllerMetricInfo] Métricas do controlador definidas para o pod: default/test-deployment3-6c95cffb97-d2xv7
W0124 13:54:25.262049       1 scheduler.go:125] [cacheMiss] Métricas não encontradas para o pod: default/test-deployment3-6c95cffb97-d2xv7
I0124 13:54:25.273453       1 scheduler.go:70] Estado no Informer: map[controller:test-controller3]
I0124 13:54:25.274493       1 scheduler.go:71] Estado real no cluster: map[controller:test-controller3]
W0124 13:54:25.275437       1 scheduler.go:135] [WaitForPodsOnCache] Pod test-deployment3-6c95cffb97-d2xv7 não encontrado no cache. Tentando novamente...
I0124 13:54:25.376447       1 scheduler.go:606] [GetControllerMetricInfo] Iniciando para o pod: default/test-deployment3-6c95cffb97-d2xv7
I0124 13:54:25.376512       1 scheduler.go:611] [GetControllerMetricInfo] Obtendo o nome do controlador para o pod: default/test-deployment3-6c95cffb97-d2xv7
I0124 13:54:25.376521       1 types.go:743] [ControllerName] Verificando as anotações do pod default/test-deployment3-6c95cffb97-d2xv7
