I0303 19:25:00.912597       1 serving.go:386] Generated self-signed cert in-memory
W0303 19:25:00.913304       1 client_config.go:667] Neither --kubeconfig nor --master was specified.  Using the inClusterConfig.  This might not work.
I0303 19:25:01.172963       1 server.go:166] "Starting Kubernetes Scheduler" version="v0.0.0-master+$Format:%H$"
I0303 19:25:01.172989       1 server.go:168] "Golang settings" GOGC="" GOMAXPROCS="" GOTRACEBACK=""
I0303 19:25:01.176408       1 requestheader_controller.go:180] Starting RequestHeaderAuthRequestController
I0303 19:25:01.176456       1 shared_informer.go:313] Waiting for caches to sync for RequestHeaderAuthRequestController
I0303 19:25:01.176522       1 configmap_cafile_content.go:205] "Starting controller" name="client-ca::kube-system::extension-apiserver-authentication::client-ca-file"
I0303 19:25:01.176543       1 shared_informer.go:313] Waiting for caches to sync for client-ca::kube-system::extension-apiserver-authentication::client-ca-file
I0303 19:25:01.176571       1 configmap_cafile_content.go:205] "Starting controller" name="client-ca::kube-system::extension-apiserver-authentication::requestheader-client-ca-file"
I0303 19:25:01.176593       1 secure_serving.go:213] Serving securely on [::]:10259
I0303 19:25:01.176663       1 tlsconfig.go:243] "Starting DynamicServingCertificateController"
I0303 19:25:01.176605       1 shared_informer.go:313] Waiting for caches to sync for client-ca::kube-system::extension-apiserver-authentication::requestheader-client-ca-file
I0303 19:25:01.276667       1 shared_informer.go:320] Caches are synced for RequestHeaderAuthRequestController
I0303 19:25:01.276775       1 shared_informer.go:320] Caches are synced for client-ca::kube-system::extension-apiserver-authentication::client-ca-file
I0303 19:25:01.276836       1 leaderelection.go:257] attempting to acquire leader lease kube-system/kube-scheduler...
I0303 19:25:01.278177       1 shared_informer.go:320] Caches are synced for client-ca::kube-system::extension-apiserver-authentication::requestheader-client-ca-file
I0303 19:25:01.281184       1 leaderelection.go:271] successfully acquired lease kube-system/kube-scheduler
I0303 19:26:19.263544       1 scheduler.go:150] [Reserve] resources reserved at node minikube for pod low-priority-pod_default at 2025-03-03 19:26:19.263536198 +0000 UTC m=+78.783825418
I0303 19:26:19.263577       1 types.go:751] [ControllerName] Verificando as anotações do pod default/low-priority-pod
I0303 19:26:19.263583       1 types.go:769] [ControllerName] Anotação 'controller' encontrada para o pod default/low-priority-pod: test-controller2
I0303 19:26:19.263591       1 scheduler.go:152] [Reserve] Status de alocação atual para o pod low-priority-pod_default: 
I0303 19:26:19.263596       1 scheduler.go:154] [Reserve] Status de alocação atualizado para o pod low-priority-pod_default: allocating
I0303 19:26:19.263639       1 scheduler.go:178] [PreBind] Validando o pod low-priority-pod antes de vincular ao node minikube
I0303 19:26:19.267792       1 scheduler.go:186] [PostBind] Chamado para pod low-priority-pod
I0303 19:26:19.267817       1 scheduler.go:204] [PostBind] Pod low-priority-pod - Início do binding: 2025-03-03 19:26:19.263651334 +0000 UTC m=+78.783940554, Fim do binding: 2025-03-03 19:26:19.26781398 +0000 UTC m=+78.788103200
I0303 19:26:19.267831       1 types.go:751] [ControllerName] Verificando as anotações do pod default/low-priority-pod
I0303 19:26:19.267836       1 types.go:769] [ControllerName] Anotação 'controller' encontrada para o pod default/low-priority-pod: test-controller2
I0303 19:26:19.267842       1 scheduler.go:211] [PostBind] Métricas atualizadas para o pod low-priority-pod
I0303 19:26:35.047167       1 default_preemption.go:25] "PostFilter called" pod="default/high-priority-pod"
I0303 19:26:35.047205       1 preemption.go:242] Lista de nós obtidaallNodes[&NodeInfo{Pods:[coredns-668d6bf9bc-tbzv9 custom-scheduler-8dcdbb8b5-glk8n etcd-minikube kube-apiserver-minikube kube-controller-manager-minikube kube-proxy-hqbh2 kube-scheduler-minikube storage-provisioner low-priority-pod], RequestedResource:&framework.Resource{MilliCPU:8750, Memory:459276288, EphemeralStorage:0, AllowedPodNumber:0, ScalarResources:map[v1.ResourceName]int64(nil)}, NonZeroRequest: &framework.Resource{MilliCPU:9050, Memory:1717567488, EphemeralStorage:0, AllowedPodNumber:0, ScalarResources:map[v1.ResourceName]int64(nil)}, UsedPort: framework.HostPortInfo{}, AllocatableResource:&framework.Resource{MilliCPU:16000, Memory:33260965888, EphemeralStorage:30083776512, AllowedPodNumber:110, ScalarResources:map[v1.ResourceName]int64{"hugepages-1Gi":0, "hugepages-2Mi":0}}}]
I0303 19:26:35.047298       1 preemption.go:306] "Starting candidate search for preemption" pod="default/high-priority-pod" totalNodes=1
I0303 19:26:35.047316       1 preemption.go:325] "Potential node for preemption identified" pod="default/high-priority-pod" node="minikube"
I0303 19:26:35.047323       1 preemption.go:338] "Calling DryRunPreemption" pod="default/high-priority-pod" numPotentialNodes=1
I0303 19:26:35.047434       1 preemption.go:347] "Preemption candidates found" pod="default/high-priority-pod" numCandidates=0
I0303 19:26:35.047448       1 preemption.go:249] Número de candidatos encontradoscount0
I0303 19:26:35.047453       1 preemption.go:250] Mapa de status dos nósnodeToStatusMap&{map[] 0xc000846f00}
I0303 19:26:35.047464       1 preemption.go:259] "No preemption candidate is found; preemption is not helpful for scheduling" pod="default/high-priority-pod"
I0303 19:26:35.047508       1 default_preemption.go:34] "Preemption failed or not needed" pod="default/high-priority-pod" status="0/1 nodes are available: 1 Preemption is not helpful for scheduling."
