I0210 17:14:29.437984       1 serving.go:386] Generated self-signed cert in-memory
W0210 17:14:29.438739       1 client_config.go:659] Neither --kubeconfig nor --master was specified.  Using the inClusterConfig.  This might not work.
I0210 17:14:29.693739       1 scheduler.go:214] [OnAddPod] Pod adicionado: kube-system/coredns-668d6bf9bc-d5rfg, Anotações: map[]
I0210 17:14:29.695483       1 scheduler.go:69] Estado no Informer: map[]
I0210 17:14:29.695501       1 scheduler.go:70] Estado real no cluster: map[]
I0210 17:14:29.695505       1 scheduler.go:220] [OnAddPod] Ignorando pod kube-system/coredns-668d6bf9bc-d5rfg pois pertence ao namespace kube-system
I0210 17:14:29.695530       1 scheduler.go:214] [OnAddPod] Pod adicionado: kube-system/custom-scheduler-8dcdbb8b5-v7qlj, Anotações: map[]
I0210 17:14:29.696995       1 scheduler.go:69] Estado no Informer: map[]
I0210 17:14:29.697018       1 scheduler.go:70] Estado real no cluster: map[]
I0210 17:14:29.697023       1 scheduler.go:220] [OnAddPod] Ignorando pod kube-system/custom-scheduler-8dcdbb8b5-v7qlj pois pertence ao namespace kube-system
I0210 17:14:29.697062       1 scheduler.go:214] [OnAddPod] Pod adicionado: kube-system/etcd-minikube, Anotações: map[kubeadm.kubernetes.io/etcd.advertise-client-urls:https://192.168.49.2:2379 kubernetes.io/config.hash:2b4b75c2a289008e0b381891e9683040 kubernetes.io/config.mirror:2b4b75c2a289008e0b381891e9683040 kubernetes.io/config.seen:2025-02-04T15:54:51.518019519Z kubernetes.io/config.source:file]
I0210 17:14:29.698461       1 scheduler.go:69] Estado no Informer: map[kubeadm.kubernetes.io/etcd.advertise-client-urls:https://192.168.49.2:2379 kubernetes.io/config.hash:2b4b75c2a289008e0b381891e9683040 kubernetes.io/config.mirror:2b4b75c2a289008e0b381891e9683040 kubernetes.io/config.seen:2025-02-04T15:54:51.518019519Z kubernetes.io/config.source:file]
I0210 17:14:29.698485       1 scheduler.go:70] Estado real no cluster: map[kubeadm.kubernetes.io/etcd.advertise-client-urls:https://192.168.49.2:2379 kubernetes.io/config.hash:2b4b75c2a289008e0b381891e9683040 kubernetes.io/config.mirror:2b4b75c2a289008e0b381891e9683040 kubernetes.io/config.seen:2025-02-04T15:54:51.518019519Z kubernetes.io/config.source:file]
I0210 17:14:29.698493       1 scheduler.go:220] [OnAddPod] Ignorando pod kube-system/etcd-minikube pois pertence ao namespace kube-system
I0210 17:14:29.698522       1 scheduler.go:214] [OnAddPod] Pod adicionado: kube-system/kube-apiserver-minikube, Anotações: map[kubeadm.kubernetes.io/kube-apiserver.advertise-address.endpoint:192.168.49.2:8443 kubernetes.io/config.hash:d72d0a4cf4be077c9919d46b7358a5e8 kubernetes.io/config.mirror:d72d0a4cf4be077c9919d46b7358a5e8 kubernetes.io/config.seen:2025-02-04T15:54:55.687286899Z kubernetes.io/config.source:file]
I0210 17:14:29.699809       1 scheduler.go:69] Estado no Informer: map[kubeadm.kubernetes.io/kube-apiserver.advertise-address.endpoint:192.168.49.2:8443 kubernetes.io/config.hash:d72d0a4cf4be077c9919d46b7358a5e8 kubernetes.io/config.mirror:d72d0a4cf4be077c9919d46b7358a5e8 kubernetes.io/config.seen:2025-02-04T15:54:55.687286899Z kubernetes.io/config.source:file]
I0210 17:14:29.699832       1 scheduler.go:70] Estado real no cluster: map[kubeadm.kubernetes.io/kube-apiserver.advertise-address.endpoint:192.168.49.2:8443 kubernetes.io/config.hash:d72d0a4cf4be077c9919d46b7358a5e8 kubernetes.io/config.mirror:d72d0a4cf4be077c9919d46b7358a5e8 kubernetes.io/config.seen:2025-02-04T15:54:55.687286899Z kubernetes.io/config.source:file]
I0210 17:14:29.699839       1 scheduler.go:220] [OnAddPod] Ignorando pod kube-system/kube-apiserver-minikube pois pertence ao namespace kube-system
I0210 17:14:29.699890       1 scheduler.go:214] [OnAddPod] Pod adicionado: kube-system/kube-controller-manager-minikube, Anotações: map[kubernetes.io/config.hash:843c74f7b3bc7d7040a05c31708a6a30 kubernetes.io/config.mirror:843c74f7b3bc7d7040a05c31708a6a30 kubernetes.io/config.seen:2025-02-04T15:54:55.687288679Z kubernetes.io/config.source:file]
I0210 17:14:29.701330       1 scheduler.go:69] Estado no Informer: map[kubernetes.io/config.hash:843c74f7b3bc7d7040a05c31708a6a30 kubernetes.io/config.mirror:843c74f7b3bc7d7040a05c31708a6a30 kubernetes.io/config.seen:2025-02-04T15:54:55.687288679Z kubernetes.io/config.source:file]
I0210 17:14:29.701355       1 scheduler.go:70] Estado real no cluster: map[kubernetes.io/config.hash:843c74f7b3bc7d7040a05c31708a6a30 kubernetes.io/config.mirror:843c74f7b3bc7d7040a05c31708a6a30 kubernetes.io/config.seen:2025-02-04T15:54:55.687288679Z kubernetes.io/config.source:file]
I0210 17:14:29.701362       1 scheduler.go:220] [OnAddPod] Ignorando pod kube-system/kube-controller-manager-minikube pois pertence ao namespace kube-system
I0210 17:14:29.701401       1 scheduler.go:214] [OnAddPod] Pod adicionado: kube-system/kube-proxy-w2kkv, Anotações: map[]
I0210 17:14:29.702744       1 scheduler.go:69] Estado no Informer: map[]
I0210 17:14:29.702761       1 scheduler.go:70] Estado real no cluster: map[]
I0210 17:14:29.702765       1 scheduler.go:220] [OnAddPod] Ignorando pod kube-system/kube-proxy-w2kkv pois pertence ao namespace kube-system
I0210 17:14:29.702785       1 scheduler.go:214] [OnAddPod] Pod adicionado: kube-system/kube-scheduler-minikube, Anotações: map[kubernetes.io/config.hash:d14ce008bee3a1f3bd7cf547688f9dfe kubernetes.io/config.mirror:d14ce008bee3a1f3bd7cf547688f9dfe kubernetes.io/config.seen:2025-02-04T15:54:51.518024909Z kubernetes.io/config.source:file]
I0210 17:14:29.704154       1 scheduler.go:69] Estado no Informer: map[kubernetes.io/config.hash:d14ce008bee3a1f3bd7cf547688f9dfe kubernetes.io/config.mirror:d14ce008bee3a1f3bd7cf547688f9dfe kubernetes.io/config.seen:2025-02-04T15:54:51.518024909Z kubernetes.io/config.source:file]
I0210 17:14:29.704205       1 scheduler.go:70] Estado real no cluster: map[kubernetes.io/config.hash:d14ce008bee3a1f3bd7cf547688f9dfe kubernetes.io/config.mirror:d14ce008bee3a1f3bd7cf547688f9dfe kubernetes.io/config.seen:2025-02-04T15:54:51.518024909Z kubernetes.io/config.source:file]
I0210 17:14:29.704215       1 scheduler.go:220] [OnAddPod] Ignorando pod kube-system/kube-scheduler-minikube pois pertence ao namespace kube-system
I0210 17:14:29.704241       1 scheduler.go:214] [OnAddPod] Pod adicionado: kube-system/metrics-server-7fbb699795-m84df, Anotações: map[]
I0210 17:14:29.705692       1 scheduler.go:69] Estado no Informer: map[]
I0210 17:14:29.705712       1 scheduler.go:70] Estado real no cluster: map[]
I0210 17:14:29.705717       1 scheduler.go:220] [OnAddPod] Ignorando pod kube-system/metrics-server-7fbb699795-m84df pois pertence ao namespace kube-system
I0210 17:14:29.705739       1 scheduler.go:214] [OnAddPod] Pod adicionado: kube-system/storage-provisioner, Anotações: map[kubectl.kubernetes.io/last-applied-configuration:{"apiVersion":"v1","kind":"Pod","metadata":{"annotations":{},"labels":{"addonmanager.kubernetes.io/mode":"Reconcile","integration-test":"storage-provisioner"},"name":"storage-provisioner","namespace":"kube-system"},"spec":{"containers":[{"command":["/storage-provisioner"],"image":"gcr.io/k8s-minikube/storage-provisioner:v5","imagePullPolicy":"IfNotPresent","name":"storage-provisioner","volumeMounts":[{"mountPath":"/tmp","name":"tmp"}]}],"hostNetwork":true,"serviceAccountName":"storage-provisioner","volumes":[{"hostPath":{"path":"/tmp","type":"Directory"},"name":"tmp"}]}}
]
I0210 17:14:29.706882       1 scheduler.go:69] Estado no Informer: map[kubectl.kubernetes.io/last-applied-configuration:{"apiVersion":"v1","kind":"Pod","metadata":{"annotations":{},"labels":{"addonmanager.kubernetes.io/mode":"Reconcile","integration-test":"storage-provisioner"},"name":"storage-provisioner","namespace":"kube-system"},"spec":{"containers":[{"command":["/storage-provisioner"],"image":"gcr.io/k8s-minikube/storage-provisioner:v5","imagePullPolicy":"IfNotPresent","name":"storage-provisioner","volumeMounts":[{"mountPath":"/tmp","name":"tmp"}]}],"hostNetwork":true,"serviceAccountName":"storage-provisioner","volumes":[{"hostPath":{"path":"/tmp","type":"Directory"},"name":"tmp"}]}}
]
I0210 17:14:29.706902       1 scheduler.go:70] Estado real no cluster: map[kubectl.kubernetes.io/last-applied-configuration:{"apiVersion":"v1","kind":"Pod","metadata":{"annotations":{},"labels":{"addonmanager.kubernetes.io/mode":"Reconcile","integration-test":"storage-provisioner"},"name":"storage-provisioner","namespace":"kube-system"},"spec":{"containers":[{"command":["/storage-provisioner"],"image":"gcr.io/k8s-minikube/storage-provisioner:v5","imagePullPolicy":"IfNotPresent","name":"storage-provisioner","volumeMounts":[{"mountPath":"/tmp","name":"tmp"}]}],"hostNetwork":true,"serviceAccountName":"storage-provisioner","volumes":[{"hostPath":{"path":"/tmp","type":"Directory"},"name":"tmp"}]}}
]
I0210 17:14:29.706917       1 scheduler.go:220] [OnAddPod] Ignorando pod kube-system/storage-provisioner pois pertence ao namespace kube-system
I0210 17:14:29.791037       1 scheduler.go:653] PodInformer sincronizado com sucesso
I0210 17:14:29.794494       1 server.go:167] "Starting Kubernetes Scheduler" version="v0.0.0-master+$Format:%H$"
I0210 17:14:29.794529       1 server.go:169] "Golang settings" GOGC="" GOMAXPROCS="" GOTRACEBACK=""
I0210 17:14:29.798244       1 requestheader_controller.go:172] Starting RequestHeaderAuthRequestController
I0210 17:14:29.798261       1 configmap_cafile_content.go:205] "Starting controller" name="client-ca::kube-system::extension-apiserver-authentication::client-ca-file"
I0210 17:14:29.798275       1 shared_informer.go:313] Waiting for caches to sync for RequestHeaderAuthRequestController
I0210 17:14:29.798280       1 shared_informer.go:313] Waiting for caches to sync for client-ca::kube-system::extension-apiserver-authentication::client-ca-file
I0210 17:14:29.798296       1 configmap_cafile_content.go:205] "Starting controller" name="client-ca::kube-system::extension-apiserver-authentication::requestheader-client-ca-file"
I0210 17:14:29.798307       1 secure_serving.go:213] Serving securely on [::]:10259
I0210 17:14:29.798311       1 shared_informer.go:313] Waiting for caches to sync for client-ca::kube-system::extension-apiserver-authentication::requestheader-client-ca-file
I0210 17:14:29.798343       1 tlsconfig.go:243] "Starting DynamicServingCertificateController"
I0210 17:14:29.898753       1 shared_informer.go:320] Caches are synced for client-ca::kube-system::extension-apiserver-authentication::client-ca-file
I0210 17:14:29.898861       1 shared_informer.go:320] Caches are synced for client-ca::kube-system::extension-apiserver-authentication::requestheader-client-ca-file
I0210 17:14:29.898971       1 leaderelection.go:254] attempting to acquire leader lease kube-system/kube-scheduler...
I0210 17:14:29.898987       1 shared_informer.go:320] Caches are synced for RequestHeaderAuthRequestController
I0210 17:14:29.902546       1 leaderelection.go:268] successfully acquired lease kube-system/kube-scheduler
I0210 17:16:39.078341       1 scheduler.go:214] [OnAddPod] Pod adicionado: default/prod-deployment-average-1-9a2b81a4ad79-8447964868-22sfk, Anotações: map[acceptablePreemptionOverhead:0.05 controller:prod-deployment-average-1-9a2b81a4ad79 qosMeasuring:average slo:0.8]
I0210 17:16:39.078593       1 scheduler.go:145] [Reserve] resources reserved at node minikube for pod prod-deployment-average-1-9a2b81a4ad79-8447964868-22sfk_default at 2025-02-10 17:16:39.078584308 +0000 UTC m=+130.006321862
I0210 17:16:39.078630       1 types.go:751] [ControllerName] Verificando as anotações do pod default/prod-deployment-average-1-9a2b81a4ad79-8447964868-22sfk
I0210 17:16:39.078637       1 types.go:769] [ControllerName] Anotação 'controller' encontrada para o pod default/prod-deployment-average-1-9a2b81a4ad79-8447964868-22sfk: prod-deployment-average-1-9a2b81a4ad79
I0210 17:16:39.080240       1 scheduler.go:69] Estado no Informer: map[acceptablePreemptionOverhead:0.05 controller:prod-deployment-average-1-9a2b81a4ad79 qosMeasuring:average slo:0.8]
I0210 17:16:39.080273       1 scheduler.go:70] Estado real no cluster: map[acceptablePreemptionOverhead:0.05 controller:prod-deployment-average-1-9a2b81a4ad79 qosMeasuring:average slo:0.8]
I0210 17:16:39.080329       1 scheduler.go:147] [Reserve] Status de alocação atual para o pod prod-deployment-average-1-9a2b81a4ad79-8447964868-22sfk_default: 
I0210 17:16:39.080353       1 scheduler.go:149] [Reserve] Status de alocação atualizado para o pod prod-deployment-average-1-9a2b81a4ad79-8447964868-22sfk_default: allocating
I0210 17:16:39.080417       1 scheduler.go:173] [PreBind] Validando o pod prod-deployment-average-1-9a2b81a4ad79-8447964868-22sfk antes de vincular ao node minikube
I0210 17:16:39.080640       1 scheduler.go:225] [OnAddPod] Adicionando pod default/prod-deployment-average-1-9a2b81a4ad79-8447964868-22sfk com os seguintes detalhes:
I0210 17:16:39.080662       1 types.go:751] [ControllerName] Verificando as anotações do pod default/prod-deployment-average-1-9a2b81a4ad79-8447964868-22sfk
I0210 17:16:39.080670       1 types.go:769] [ControllerName] Anotação 'controller' encontrada para o pod default/prod-deployment-average-1-9a2b81a4ad79-8447964868-22sfk: prod-deployment-average-1-9a2b81a4ad79
I0210 17:16:39.080677       1 scheduler.go:234] [OnAddPod] Atualizando métricas para o pod default/prod-deployment-average-1-9a2b81a4ad79-8447964868-22sfk
I0210 17:16:39.080685       1 types.go:751] [ControllerName] Verificando as anotações do pod default/prod-deployment-average-1-9a2b81a4ad79-8447964868-22sfk
I0210 17:16:39.080689       1 types.go:769] [ControllerName] Anotação 'controller' encontrada para o pod default/prod-deployment-average-1-9a2b81a4ad79-8447964868-22sfk: prod-deployment-average-1-9a2b81a4ad79
I0210 17:16:39.080698       1 scheduler.go:247] [OnAddPod] Pod default/prod-deployment-average-1-9a2b81a4ad79-8447964868-22sfk adicionado com sucesso
I0210 17:16:39.086152       1 scheduler.go:181] [PostBind] Chamado para pod prod-deployment-average-1-9a2b81a4ad79-8447964868-22sfk
I0210 17:16:39.086206       1 scheduler.go:199] [PostBind] Pod prod-deployment-average-1-9a2b81a4ad79-8447964868-22sfk - Início do binding: 2025-02-10 17:16:39.080427576 +0000 UTC m=+130.008165130, Fim do binding: 2025-02-10 17:16:39.086202274 +0000 UTC m=+130.013939828
I0210 17:16:39.086222       1 types.go:751] [ControllerName] Verificando as anotações do pod default/prod-deployment-average-1-9a2b81a4ad79-8447964868-22sfk
I0210 17:16:39.086230       1 types.go:769] [ControllerName] Anotação 'controller' encontrada para o pod default/prod-deployment-average-1-9a2b81a4ad79-8447964868-22sfk: prod-deployment-average-1-9a2b81a4ad79
I0210 17:16:39.086238       1 scheduler.go:206] [PostBind] Métricas atualizadas para o pod prod-deployment-average-1-9a2b81a4ad79-8447964868-22sfk
I0210 17:16:39.086582       1 scheduler.go:252] [OnUpdatePod] Iniciando processamento de atualização de pod
I0210 17:16:39.086626       1 scheduler.go:256] [OnUpdatePod] Pod atualizado detectado: default/prod-deployment-average-1-9a2b81a4ad79-8447964868-22sfk, Anotações: map[acceptablePreemptionOverhead:0.05 controller:prod-deployment-average-1-9a2b81a4ad79 qosMeasuring:average slo:0.8]
I0210 17:16:39.086644       1 scheduler.go:259] [OnUpdatePod] Comparando estado no Informer e estado real no cluster para o pod default/prod-deployment-average-1-9a2b81a4ad79-8447964868-22sfk
I0210 17:16:39.089659       1 postFilter.go:29] [PostFilter] PostFilter chamado para pod: default/prod-deployment-average-2-77e788a61edf-5b7dd97cd5-zj78l
I0210 17:16:39.089686       1 postFilter.go:76] Comparando pod original com o atualizado...
I0210 17:16:39.089693       1 postFilter.go:83] Successfully retrieved updated pod default/prod-deployment-average-2-77e788a61edf-5b7dd97cd5-zj78l from lister
I0210 17:16:39.090689       1 scheduler.go:69] Estado no Informer: map[acceptablePreemptionOverhead:0.05 controller:prod-deployment-average-1-9a2b81a4ad79 qosMeasuring:average slo:0.8]
I0210 17:16:39.090731       1 scheduler.go:70] Estado real no cluster: map[acceptablePreemptionOverhead:0.05 controller:prod-deployment-average-1-9a2b81a4ad79 qosMeasuring:average slo:0.8]
I0210 17:16:39.090743       1 scheduler.go:269] [OnUpdatePod] Atualizando informações de métricas para o pod default/prod-deployment-average-1-9a2b81a4ad79-8447964868-22sfk
I0210 17:16:39.090749       1 types.go:751] [ControllerName] Verificando as anotações do pod default/prod-deployment-average-1-9a2b81a4ad79-8447964868-22sfk
I0210 17:16:39.090755       1 types.go:769] [ControllerName] Anotação 'controller' encontrada para o pod default/prod-deployment-average-1-9a2b81a4ad79-8447964868-22sfk: prod-deployment-average-1-9a2b81a4ad79
I0210 17:16:39.090764       1 scheduler.go:271] [OnUpdatePod] Atualizando 'LastStatus' do pod default/prod-deployment-average-1-9a2b81a4ad79-8447964868-22sfk nas métricas
I0210 17:16:39.090768       1 scheduler.go:273] [OnUpdatePod] Métrica atualizada para o pod default/prod-deployment-average-1-9a2b81a4ad79-8447964868-22sfk
I0210 17:16:39.090776       1 scheduler.go:277] [OnUpdatePod] Finalizando processamento de atualização de pod para default/prod-deployment-average-1-9a2b81a4ad79-8447964868-22sfk
I0210 17:16:39.090816       1 scheduler.go:214] [OnAddPod] Pod adicionado: default/prod-deployment-average-2-77e788a61edf-5b7dd97cd5-zj78l, Anotações: map[acceptablePreemptionOverhead:0.05 controller:prod-deployment-average-2-77e788a61edf qosMeasuring:average slo:0.8]
I0210 17:16:39.091864       1 postFilter.go:250] [compareNodeResources] Recursos calculados no nó minikube: CPU = 8850 mCPU, Memória = 490373120 bytes
I0210 17:16:39.091890       1 postFilter.go:251] [compareNodeResources] Recursos do snapshot no nó minikube: CPU = 8850 mCPU, Memória = 490373120 bytes
I0210 17:16:39.091897       1 postFilter.go:257] [compareNodeResources] Recursos de CPU do nó minikube estão sincronizados: 8850 mCPU
I0210 17:16:39.091942       1 postFilter.go:263] [compareNodeResources] Recursos de memória do nó minikube estão sincronizados: 490373120 bytes
I0210 17:16:39.091966       1 postFilter.go:104] [Preempt] Verificando se é necessário limpar NominatedNodeName do pod default/prod-deployment-average-2-77e788a61edf-5b7dd97cd5-zj78l antes de continuar.
I0210 17:16:39.092061       1 scheduler.go:597] [GetControllerMetricInfo] Iniciando para o pod: default/prod-deployment-average-1-9a2b81a4ad79-8447964868-22sfk
I0210 17:16:39.092093       1 scheduler.go:602] [GetControllerMetricInfo] Obtendo o nome do controlador para o pod: default/prod-deployment-average-1-9a2b81a4ad79-8447964868-22sfk
I0210 17:16:39.092099       1 types.go:751] [ControllerName] Verificando as anotações do pod default/prod-deployment-average-1-9a2b81a4ad79-8447964868-22sfk
I0210 17:16:39.092104       1 types.go:769] [ControllerName] Anotação 'controller' encontrada para o pod default/prod-deployment-average-1-9a2b81a4ad79-8447964868-22sfk: prod-deployment-average-1-9a2b81a4ad79
I0210 17:16:39.092109       1 scheduler.go:605] [GetControllerMetricInfo] Métricas do controlador definidas para o pod: default/prod-deployment-average-1-9a2b81a4ad79-8447964868-22sfk
I0210 17:16:39.092115       1 scheduler.go:83] [HigherPrecedence] Calculando precedência entre prod-deployment-average-2-77e788a61edf-5b7dd97cd5-zj78l e prod-deployment-average-1-9a2b81a4ad79-8447964868-22sfk
I0210 17:16:39.092119       1 scheduler.go:116] [WaitForPodsOnCache] Verificando se o pod prod-deployment-average-2-77e788a61edf-5b7dd97cd5-zj78l está no cache...
I0210 17:16:39.092123       1 scheduler.go:597] [GetControllerMetricInfo] Iniciando para o pod: default/prod-deployment-average-2-77e788a61edf-5b7dd97cd5-zj78l
I0210 17:16:39.092128       1 scheduler.go:602] [GetControllerMetricInfo] Obtendo o nome do controlador para o pod: default/prod-deployment-average-2-77e788a61edf-5b7dd97cd5-zj78l
I0210 17:16:39.092131       1 types.go:751] [ControllerName] Verificando as anotações do pod default/prod-deployment-average-2-77e788a61edf-5b7dd97cd5-zj78l
I0210 17:16:39.092136       1 types.go:769] [ControllerName] Anotação 'controller' encontrada para o pod default/prod-deployment-average-2-77e788a61edf-5b7dd97cd5-zj78l: prod-deployment-average-2-77e788a61edf
I0210 17:16:39.092141       1 scheduler.go:605] [GetControllerMetricInfo] Métricas do controlador definidas para o pod: default/prod-deployment-average-2-77e788a61edf-5b7dd97cd5-zj78l
W0210 17:16:39.092147       1 scheduler.go:124] [cacheMiss] Métricas não encontradas para o pod: default/prod-deployment-average-2-77e788a61edf-5b7dd97cd5-zj78l
I0210 17:16:39.092607       1 scheduler.go:69] Estado no Informer: map[acceptablePreemptionOverhead:0.05 controller:prod-deployment-average-2-77e788a61edf qosMeasuring:average slo:0.8]
I0210 17:16:39.092629       1 scheduler.go:70] Estado real no cluster: map[acceptablePreemptionOverhead:0.05 controller:prod-deployment-average-2-77e788a61edf qosMeasuring:average slo:0.8]
I0210 17:16:39.092803       1 scheduler.go:225] [OnAddPod] Adicionando pod default/prod-deployment-average-2-77e788a61edf-5b7dd97cd5-zj78l com os seguintes detalhes:
I0210 17:16:39.097568       1 scheduler.go:69] Estado no Informer: map[acceptablePreemptionOverhead:0.05 controller:prod-deployment-average-2-77e788a61edf qosMeasuring:average slo:0.8]
I0210 17:16:39.097597       1 scheduler.go:70] Estado real no cluster: map[acceptablePreemptionOverhead:0.05 controller:prod-deployment-average-2-77e788a61edf qosMeasuring:average slo:0.8]
W0210 17:16:39.097617       1 scheduler.go:134] [WaitForPodsOnCache] Pod prod-deployment-average-2-77e788a61edf-5b7dd97cd5-zj78l não encontrado no cache. Tentando novamente...
I0210 17:16:39.097637       1 types.go:751] [ControllerName] Verificando as anotações do pod default/prod-deployment-average-2-77e788a61edf-5b7dd97cd5-zj78l
I0210 17:16:39.097644       1 types.go:769] [ControllerName] Anotação 'controller' encontrada para o pod default/prod-deployment-average-2-77e788a61edf-5b7dd97cd5-zj78l: prod-deployment-average-2-77e788a61edf
I0210 17:16:39.099423       1 scheduler.go:234] [OnAddPod] Atualizando métricas para o pod default/prod-deployment-average-2-77e788a61edf-5b7dd97cd5-zj78l
I0210 17:16:39.099450       1 types.go:751] [ControllerName] Verificando as anotações do pod default/prod-deployment-average-2-77e788a61edf-5b7dd97cd5-zj78l
I0210 17:16:39.099457       1 types.go:769] [ControllerName] Anotação 'controller' encontrada para o pod default/prod-deployment-average-2-77e788a61edf-5b7dd97cd5-zj78l: prod-deployment-average-2-77e788a61edf
I0210 17:16:39.099471       1 scheduler.go:247] [OnAddPod] Pod default/prod-deployment-average-2-77e788a61edf-5b7dd97cd5-zj78l adicionado com sucesso
I0210 17:16:39.099490       1 scheduler.go:252] [OnUpdatePod] Iniciando processamento de atualização de pod
I0210 17:16:39.099517       1 scheduler.go:256] [OnUpdatePod] Pod atualizado detectado: default/prod-deployment-average-1-9a2b81a4ad79-8447964868-22sfk, Anotações: map[acceptablePreemptionOverhead:0.05 controller:prod-deployment-average-1-9a2b81a4ad79 qosMeasuring:average slo:0.8]
I0210 17:16:39.099543       1 scheduler.go:259] [OnUpdatePod] Comparando estado no Informer e estado real no cluster para o pod default/prod-deployment-average-1-9a2b81a4ad79-8447964868-22sfk
I0210 17:16:39.100993       1 scheduler.go:69] Estado no Informer: map[acceptablePreemptionOverhead:0.05 controller:prod-deployment-average-1-9a2b81a4ad79 qosMeasuring:average slo:0.8]
I0210 17:16:39.101014       1 scheduler.go:70] Estado real no cluster: map[acceptablePreemptionOverhead:0.05 controller:prod-deployment-average-1-9a2b81a4ad79 qosMeasuring:average slo:0.8]
I0210 17:16:39.101021       1 scheduler.go:269] [OnUpdatePod] Atualizando informações de métricas para o pod default/prod-deployment-average-1-9a2b81a4ad79-8447964868-22sfk
I0210 17:16:39.101024       1 types.go:751] [ControllerName] Verificando as anotações do pod default/prod-deployment-average-1-9a2b81a4ad79-8447964868-22sfk
I0210 17:16:39.101030       1 types.go:769] [ControllerName] Anotação 'controller' encontrada para o pod default/prod-deployment-average-1-9a2b81a4ad79-8447964868-22sfk: prod-deployment-average-1-9a2b81a4ad79
I0210 17:16:39.101036       1 scheduler.go:271] [OnUpdatePod] Atualizando 'LastStatus' do pod default/prod-deployment-average-1-9a2b81a4ad79-8447964868-22sfk nas métricas
I0210 17:16:39.101039       1 scheduler.go:273] [OnUpdatePod] Métrica atualizada para o pod default/prod-deployment-average-1-9a2b81a4ad79-8447964868-22sfk
I0210 17:16:39.101045       1 scheduler.go:277] [OnUpdatePod] Finalizando processamento de atualização de pod para default/prod-deployment-average-1-9a2b81a4ad79-8447964868-22sfk
I0210 17:16:39.198562       1 scheduler.go:597] [GetControllerMetricInfo] Iniciando para o pod: default/prod-deployment-average-2-77e788a61edf-5b7dd97cd5-zj78l
I0210 17:16:39.198591       1 scheduler.go:602] [GetControllerMetricInfo] Obtendo o nome do controlador para o pod: default/prod-deployment-average-2-77e788a61edf-5b7dd97cd5-zj78l
I0210 17:16:39.198599       1 types.go:751] [ControllerName] Verificando as anotações do pod default/prod-deployment-average-2-77e788a61edf-5b7dd97cd5-zj78l
I0210 17:16:39.198606       1 types.go:769] [ControllerName] Anotação 'controller' encontrada para o pod default/prod-deployment-average-2-77e788a61edf-5b7dd97cd5-zj78l: prod-deployment-average-2-77e788a61edf
I0210 17:16:39.198613       1 scheduler.go:605] [GetControllerMetricInfo] Métricas do controlador definidas para o pod: default/prod-deployment-average-2-77e788a61edf-5b7dd97cd5-zj78l
I0210 17:16:39.200106       1 scheduler.go:69] Estado no Informer: map[acceptablePreemptionOverhead:0.05 controller:prod-deployment-average-2-77e788a61edf qosMeasuring:average slo:0.8]
I0210 17:16:39.200130       1 scheduler.go:70] Estado real no cluster: map[acceptablePreemptionOverhead:0.05 controller:prod-deployment-average-2-77e788a61edf qosMeasuring:average slo:0.8]
I0210 17:16:39.200136       1 scheduler.go:138] [WaitForPodsOnCache] Pod prod-deployment-average-2-77e788a61edf-5b7dd97cd5-zj78l encontrado no cache.
I0210 17:16:39.200141       1 scheduler.go:116] [WaitForPodsOnCache] Verificando se o pod prod-deployment-average-1-9a2b81a4ad79-8447964868-22sfk está no cache...
I0210 17:16:39.200144       1 scheduler.go:597] [GetControllerMetricInfo] Iniciando para o pod: default/prod-deployment-average-1-9a2b81a4ad79-8447964868-22sfk
I0210 17:16:39.200148       1 scheduler.go:602] [GetControllerMetricInfo] Obtendo o nome do controlador para o pod: default/prod-deployment-average-1-9a2b81a4ad79-8447964868-22sfk
I0210 17:16:39.200151       1 types.go:751] [ControllerName] Verificando as anotações do pod default/prod-deployment-average-1-9a2b81a4ad79-8447964868-22sfk
I0210 17:16:39.200155       1 types.go:769] [ControllerName] Anotação 'controller' encontrada para o pod default/prod-deployment-average-1-9a2b81a4ad79-8447964868-22sfk: prod-deployment-average-1-9a2b81a4ad79
I0210 17:16:39.200160       1 scheduler.go:605] [GetControllerMetricInfo] Métricas do controlador definidas para o pod: default/prod-deployment-average-1-9a2b81a4ad79-8447964868-22sfk
I0210 17:16:39.201389       1 scheduler.go:69] Estado no Informer: map[acceptablePreemptionOverhead:0.05 controller:prod-deployment-average-1-9a2b81a4ad79 qosMeasuring:average slo:0.8]
I0210 17:16:39.201422       1 scheduler.go:70] Estado real no cluster: map[acceptablePreemptionOverhead:0.05 controller:prod-deployment-average-1-9a2b81a4ad79 qosMeasuring:average slo:0.8]
I0210 17:16:39.201429       1 scheduler.go:138] [WaitForPodsOnCache] Pod prod-deployment-average-1-9a2b81a4ad79-8447964868-22sfk encontrado no cache.
I0210 17:16:39.201434       1 scheduler.go:597] [GetControllerMetricInfo] Iniciando para o pod: default/prod-deployment-average-2-77e788a61edf-5b7dd97cd5-zj78l
I0210 17:16:39.201438       1 scheduler.go:602] [GetControllerMetricInfo] Obtendo o nome do controlador para o pod: default/prod-deployment-average-2-77e788a61edf-5b7dd97cd5-zj78l
I0210 17:16:39.201444       1 types.go:751] [ControllerName] Verificando as anotações do pod default/prod-deployment-average-2-77e788a61edf-5b7dd97cd5-zj78l
I0210 17:16:39.201448       1 types.go:769] [ControllerName] Anotação 'controller' encontrada para o pod default/prod-deployment-average-2-77e788a61edf-5b7dd97cd5-zj78l: prod-deployment-average-2-77e788a61edf
I0210 17:16:39.201453       1 scheduler.go:605] [GetControllerMetricInfo] Métricas do controlador definidas para o pod: default/prod-deployment-average-2-77e788a61edf-5b7dd97cd5-zj78l
I0210 17:16:39.201461       1 scheduler.go:597] [GetControllerMetricInfo] Iniciando para o pod: default/prod-deployment-average-1-9a2b81a4ad79-8447964868-22sfk
I0210 17:16:39.201467       1 scheduler.go:602] [GetControllerMetricInfo] Obtendo o nome do controlador para o pod: default/prod-deployment-average-1-9a2b81a4ad79-8447964868-22sfk
I0210 17:16:39.201470       1 types.go:751] [ControllerName] Verificando as anotações do pod default/prod-deployment-average-1-9a2b81a4ad79-8447964868-22sfk
I0210 17:16:39.201473       1 types.go:769] [ControllerName] Anotação 'controller' encontrada para o pod default/prod-deployment-average-1-9a2b81a4ad79-8447964868-22sfk: prod-deployment-average-1-9a2b81a4ad79
I0210 17:16:39.201477       1 scheduler.go:605] [GetControllerMetricInfo] Métricas do controlador definidas para o pod: default/prod-deployment-average-1-9a2b81a4ad79-8447964868-22sfk
I0210 17:16:39.201484       1 types.go:546] [QoSMetric] qosMeasuringApproach: average
I0210 17:16:39.201496       1 types.go:532] [QoS DEBUG] effectiveRunning: 0.000000 | discardedRunning: 0.000000 | waiting: 0.092112 | binding: 0.000000 | denominator: 0.092112
I0210 17:16:39.201503       1 types.go:538] [QoS DEBUG] QoS calculado: 0.000000
I0210 17:16:39.201509       1 types.go:611] [COMPUTE QoS METRIC - AVERAGE] The pod prod-deployment-average-2-77e788a61edf-5b7dd97cd5-zj78l: availability 0.000000 | runtime 0.000000 | pendingTime 0.092112 | nRunning: 0 | nWaiting: 1 | residualContr 0 | estimatedOverhead 2.400000 | QoSMetric -2.492112
I0210 17:16:39.201521       1 types.go:546] [QoSMetric] qosMeasuringApproach: average
I0210 17:16:39.201527       1 types.go:532] [QoS DEBUG] effectiveRunning: 0.005910 | discardedRunning: 0.000000 | waiting: 0.080428 | binding: 0.005775 | denominator: 0.092112
I0210 17:16:39.201532       1 types.go:538] [QoS DEBUG] QoS calculado: 0.064160
I0210 17:16:39.201536       1 types.go:611] [COMPUTE QoS METRIC - AVERAGE] The pod prod-deployment-average-1-9a2b81a4ad79-8447964868-22sfk: availability 0.064160 | runtime 0.005910 | pendingTime 0.080428 | nRunning: 1 | nWaiting: 0 | residualContr 1 | estimatedOverhead 0.005775 | QoSMetric -0.090499
I0210 17:16:39.201543       1 scheduler.go:97] [HigherPrecedence] Métricas para prod-deployment-average-2-77e788a61edf-5b7dd97cd5-zj78l: QoS = -2.492112, Importância = 0.80
I0210 17:16:39.201548       1 scheduler.go:98] [HigherPrecedence] Métricas para prod-deployment-average-1-9a2b81a4ad79-8447964868-22sfk: QoS = -0.090499, Importância = 0.80
I0210 17:16:39.201553       1 scheduler.go:109] [HigherPrecedence] Decisão final: prod-deployment-average-2-77e788a61edf-5b7dd97cd5-zj78l tem precedência sobre prod-deployment-average-1-9a2b81a4ad79-8447964868-22sfk? true
I0210 17:16:39.201561       1 types.go:751] [ControllerName] Verificando as anotações do pod default/prod-deployment-average-2-77e788a61edf-5b7dd97cd5-zj78l
I0210 17:16:39.201564       1 types.go:769] [ControllerName] Anotação 'controller' encontrada para o pod default/prod-deployment-average-2-77e788a61edf-5b7dd97cd5-zj78l: prod-deployment-average-2-77e788a61edf
I0210 17:16:39.201567       1 types.go:751] [ControllerName] Verificando as anotações do pod default/prod-deployment-average-1-9a2b81a4ad79-8447964868-22sfk
I0210 17:16:39.201570       1 types.go:769] [ControllerName] Anotação 'controller' encontrada para o pod default/prod-deployment-average-1-9a2b81a4ad79-8447964868-22sfk: prod-deployment-average-1-9a2b81a4ad79
I0210 17:16:39.201573       1 scheduler.go:597] [GetControllerMetricInfo] Iniciando para o pod: default/prod-deployment-average-1-9a2b81a4ad79-8447964868-22sfk
I0210 17:16:39.201577       1 scheduler.go:602] [GetControllerMetricInfo] Obtendo o nome do controlador para o pod: default/prod-deployment-average-1-9a2b81a4ad79-8447964868-22sfk
I0210 17:16:39.201579       1 types.go:751] [ControllerName] Verificando as anotações do pod default/prod-deployment-average-1-9a2b81a4ad79-8447964868-22sfk
I0210 17:16:39.201582       1 types.go:769] [ControllerName] Anotação 'controller' encontrada para o pod default/prod-deployment-average-1-9a2b81a4ad79-8447964868-22sfk: prod-deployment-average-1-9a2b81a4ad79
I0210 17:16:39.201586       1 scheduler.go:605] [GetControllerMetricInfo] Métricas do controlador definidas para o pod: default/prod-deployment-average-1-9a2b81a4ad79-8447964868-22sfk
I0210 17:16:39.201589       1 scheduler.go:597] [GetControllerMetricInfo] Iniciando para o pod: default/prod-deployment-average-1-9a2b81a4ad79-8447964868-22sfk
I0210 17:16:39.201592       1 scheduler.go:602] [GetControllerMetricInfo] Obtendo o nome do controlador para o pod: default/prod-deployment-average-1-9a2b81a4ad79-8447964868-22sfk
I0210 17:16:39.201595       1 types.go:751] [ControllerName] Verificando as anotações do pod default/prod-deployment-average-1-9a2b81a4ad79-8447964868-22sfk
I0210 17:16:39.201599       1 types.go:769] [ControllerName] Anotação 'controller' encontrada para o pod default/prod-deployment-average-1-9a2b81a4ad79-8447964868-22sfk: prod-deployment-average-1-9a2b81a4ad79
I0210 17:16:39.201603       1 scheduler.go:605] [GetControllerMetricInfo] Métricas do controlador definidas para o pod: default/prod-deployment-average-1-9a2b81a4ad79-8447964868-22sfk
I0210 17:16:39.201607       1 types.go:751] [ControllerName] Verificando as anotações do pod default/prod-deployment-average-1-9a2b81a4ad79-8447964868-22sfk
I0210 17:16:39.201610       1 types.go:769] [ControllerName] Anotação 'controller' encontrada para o pod default/prod-deployment-average-1-9a2b81a4ad79-8447964868-22sfk: prod-deployment-average-1-9a2b81a4ad79
I0210 17:16:39.201661       1 postFilter.go:154] [PREEMPT CALL] No node was chosen to allocate pod prod-deployment-average-2-77e788a61edf-5b7dd97cd5-zj78l
W0210 17:16:39.201673       1 postFilter.go:45] [PostFilter] Nenhum nó nominado após a preempção para o pod: default/prod-deployment-average-2-77e788a61edf-5b7dd97cd5-zj78l
I0210 17:16:39.207564       1 scheduler.go:252] [OnUpdatePod] Iniciando processamento de atualização de pod
I0210 17:16:39.207599       1 scheduler.go:256] [OnUpdatePod] Pod atualizado detectado: default/prod-deployment-average-2-77e788a61edf-5b7dd97cd5-zj78l, Anotações: map[acceptablePreemptionOverhead:0.05 controller:prod-deployment-average-2-77e788a61edf qosMeasuring:average slo:0.8]
I0210 17:16:39.207609       1 scheduler.go:259] [OnUpdatePod] Comparando estado no Informer e estado real no cluster para o pod default/prod-deployment-average-2-77e788a61edf-5b7dd97cd5-zj78l
I0210 17:16:39.208776       1 scheduler.go:69] Estado no Informer: map[acceptablePreemptionOverhead:0.05 controller:prod-deployment-average-2-77e788a61edf qosMeasuring:average slo:0.8]
I0210 17:16:39.208794       1 scheduler.go:70] Estado real no cluster: map[acceptablePreemptionOverhead:0.05 controller:prod-deployment-average-2-77e788a61edf qosMeasuring:average slo:0.8]
I0210 17:16:39.208801       1 scheduler.go:269] [OnUpdatePod] Atualizando informações de métricas para o pod default/prod-deployment-average-2-77e788a61edf-5b7dd97cd5-zj78l
I0210 17:16:39.208805       1 types.go:751] [ControllerName] Verificando as anotações do pod default/prod-deployment-average-2-77e788a61edf-5b7dd97cd5-zj78l
I0210 17:16:39.208809       1 types.go:769] [ControllerName] Anotação 'controller' encontrada para o pod default/prod-deployment-average-2-77e788a61edf-5b7dd97cd5-zj78l: prod-deployment-average-2-77e788a61edf
I0210 17:16:39.208815       1 scheduler.go:271] [OnUpdatePod] Atualizando 'LastStatus' do pod default/prod-deployment-average-2-77e788a61edf-5b7dd97cd5-zj78l nas métricas
I0210 17:16:39.208818       1 scheduler.go:273] [OnUpdatePod] Métrica atualizada para o pod default/prod-deployment-average-2-77e788a61edf-5b7dd97cd5-zj78l
I0210 17:16:39.208824       1 scheduler.go:277] [OnUpdatePod] Finalizando processamento de atualização de pod para default/prod-deployment-average-2-77e788a61edf-5b7dd97cd5-zj78l
I0210 17:16:40.035489       1 scheduler.go:252] [OnUpdatePod] Iniciando processamento de atualização de pod
I0210 17:16:40.035531       1 scheduler.go:256] [OnUpdatePod] Pod atualizado detectado: default/prod-deployment-average-1-9a2b81a4ad79-8447964868-22sfk, Anotações: map[acceptablePreemptionOverhead:0.05 controller:prod-deployment-average-1-9a2b81a4ad79 qosMeasuring:average slo:0.8]
I0210 17:16:40.035547       1 scheduler.go:259] [OnUpdatePod] Comparando estado no Informer e estado real no cluster para o pod default/prod-deployment-average-1-9a2b81a4ad79-8447964868-22sfk
I0210 17:16:40.037631       1 scheduler.go:69] Estado no Informer: map[acceptablePreemptionOverhead:0.05 controller:prod-deployment-average-1-9a2b81a4ad79 qosMeasuring:average slo:0.8]
I0210 17:16:40.037652       1 scheduler.go:70] Estado real no cluster: map[acceptablePreemptionOverhead:0.05 controller:prod-deployment-average-1-9a2b81a4ad79 qosMeasuring:average slo:0.8]
I0210 17:16:40.037659       1 scheduler.go:269] [OnUpdatePod] Atualizando informações de métricas para o pod default/prod-deployment-average-1-9a2b81a4ad79-8447964868-22sfk
I0210 17:16:40.037664       1 types.go:751] [ControllerName] Verificando as anotações do pod default/prod-deployment-average-1-9a2b81a4ad79-8447964868-22sfk
I0210 17:16:40.037668       1 types.go:769] [ControllerName] Anotação 'controller' encontrada para o pod default/prod-deployment-average-1-9a2b81a4ad79-8447964868-22sfk: prod-deployment-average-1-9a2b81a4ad79
I0210 17:16:40.037675       1 scheduler.go:271] [OnUpdatePod] Atualizando 'LastStatus' do pod default/prod-deployment-average-1-9a2b81a4ad79-8447964868-22sfk nas métricas
I0210 17:16:40.037678       1 scheduler.go:273] [OnUpdatePod] Métrica atualizada para o pod default/prod-deployment-average-1-9a2b81a4ad79-8447964868-22sfk
I0210 17:16:40.037684       1 scheduler.go:277] [OnUpdatePod] Finalizando processamento de atualização de pod para default/prod-deployment-average-1-9a2b81a4ad79-8447964868-22sfk
I0210 17:16:40.990915       1 postFilter.go:29] [PostFilter] PostFilter chamado para pod: default/prod-deployment-average-2-77e788a61edf-5b7dd97cd5-zj78l
I0210 17:16:40.990940       1 postFilter.go:76] Comparando pod original com o atualizado...
I0210 17:16:40.990946       1 postFilter.go:83] Successfully retrieved updated pod default/prod-deployment-average-2-77e788a61edf-5b7dd97cd5-zj78l from lister
I0210 17:16:40.993037       1 postFilter.go:250] [compareNodeResources] Recursos calculados no nó minikube: CPU = 8850 mCPU, Memória = 490373120 bytes
I0210 17:16:40.993055       1 postFilter.go:251] [compareNodeResources] Recursos do snapshot no nó minikube: CPU = 8850 mCPU, Memória = 490373120 bytes
I0210 17:16:40.993060       1 postFilter.go:257] [compareNodeResources] Recursos de CPU do nó minikube estão sincronizados: 8850 mCPU
I0210 17:16:40.993066       1 postFilter.go:263] [compareNodeResources] Recursos de memória do nó minikube estão sincronizados: 490373120 bytes
I0210 17:16:40.993084       1 postFilter.go:104] [Preempt] Verificando se é necessário limpar NominatedNodeName do pod default/prod-deployment-average-2-77e788a61edf-5b7dd97cd5-zj78l antes de continuar.
I0210 17:16:40.993171       1 scheduler.go:597] [GetControllerMetricInfo] Iniciando para o pod: default/prod-deployment-average-1-9a2b81a4ad79-8447964868-22sfk
I0210 17:16:40.993214       1 scheduler.go:602] [GetControllerMetricInfo] Obtendo o nome do controlador para o pod: default/prod-deployment-average-1-9a2b81a4ad79-8447964868-22sfk
I0210 17:16:40.993218       1 types.go:751] [ControllerName] Verificando as anotações do pod default/prod-deployment-average-1-9a2b81a4ad79-8447964868-22sfk
I0210 17:16:40.993223       1 types.go:769] [ControllerName] Anotação 'controller' encontrada para o pod default/prod-deployment-average-1-9a2b81a4ad79-8447964868-22sfk: prod-deployment-average-1-9a2b81a4ad79
I0210 17:16:40.993227       1 scheduler.go:605] [GetControllerMetricInfo] Métricas do controlador definidas para o pod: default/prod-deployment-average-1-9a2b81a4ad79-8447964868-22sfk
I0210 17:16:40.993231       1 scheduler.go:83] [HigherPrecedence] Calculando precedência entre prod-deployment-average-2-77e788a61edf-5b7dd97cd5-zj78l e prod-deployment-average-1-9a2b81a4ad79-8447964868-22sfk
I0210 17:16:40.993235       1 scheduler.go:116] [WaitForPodsOnCache] Verificando se o pod prod-deployment-average-2-77e788a61edf-5b7dd97cd5-zj78l está no cache...
I0210 17:16:40.993240       1 scheduler.go:597] [GetControllerMetricInfo] Iniciando para o pod: default/prod-deployment-average-2-77e788a61edf-5b7dd97cd5-zj78l
I0210 17:16:40.993244       1 scheduler.go:602] [GetControllerMetricInfo] Obtendo o nome do controlador para o pod: default/prod-deployment-average-2-77e788a61edf-5b7dd97cd5-zj78l
I0210 17:16:40.993248       1 types.go:751] [ControllerName] Verificando as anotações do pod default/prod-deployment-average-2-77e788a61edf-5b7dd97cd5-zj78l
I0210 17:16:40.993253       1 types.go:769] [ControllerName] Anotação 'controller' encontrada para o pod default/prod-deployment-average-2-77e788a61edf-5b7dd97cd5-zj78l: prod-deployment-average-2-77e788a61edf
I0210 17:16:40.993258       1 scheduler.go:605] [GetControllerMetricInfo] Métricas do controlador definidas para o pod: default/prod-deployment-average-2-77e788a61edf-5b7dd97cd5-zj78l
I0210 17:16:40.994556       1 scheduler.go:69] Estado no Informer: map[acceptablePreemptionOverhead:0.05 controller:prod-deployment-average-2-77e788a61edf qosMeasuring:average slo:0.8]
I0210 17:16:40.994586       1 scheduler.go:70] Estado real no cluster: map[acceptablePreemptionOverhead:0.05 controller:prod-deployment-average-2-77e788a61edf qosMeasuring:average slo:0.8]
I0210 17:16:40.994593       1 scheduler.go:138] [WaitForPodsOnCache] Pod prod-deployment-average-2-77e788a61edf-5b7dd97cd5-zj78l encontrado no cache.
I0210 17:16:40.994597       1 scheduler.go:116] [WaitForPodsOnCache] Verificando se o pod prod-deployment-average-1-9a2b81a4ad79-8447964868-22sfk está no cache...
I0210 17:16:40.994601       1 scheduler.go:597] [GetControllerMetricInfo] Iniciando para o pod: default/prod-deployment-average-1-9a2b81a4ad79-8447964868-22sfk
I0210 17:16:40.994604       1 scheduler.go:602] [GetControllerMetricInfo] Obtendo o nome do controlador para o pod: default/prod-deployment-average-1-9a2b81a4ad79-8447964868-22sfk
I0210 17:16:40.994608       1 types.go:751] [ControllerName] Verificando as anotações do pod default/prod-deployment-average-1-9a2b81a4ad79-8447964868-22sfk
I0210 17:16:40.994612       1 types.go:769] [ControllerName] Anotação 'controller' encontrada para o pod default/prod-deployment-average-1-9a2b81a4ad79-8447964868-22sfk: prod-deployment-average-1-9a2b81a4ad79
I0210 17:16:40.994616       1 scheduler.go:605] [GetControllerMetricInfo] Métricas do controlador definidas para o pod: default/prod-deployment-average-1-9a2b81a4ad79-8447964868-22sfk
I0210 17:16:40.995759       1 scheduler.go:69] Estado no Informer: map[acceptablePreemptionOverhead:0.05 controller:prod-deployment-average-1-9a2b81a4ad79 qosMeasuring:average slo:0.8]
I0210 17:16:40.995777       1 scheduler.go:70] Estado real no cluster: map[acceptablePreemptionOverhead:0.05 controller:prod-deployment-average-1-9a2b81a4ad79 qosMeasuring:average slo:0.8]
I0210 17:16:40.995783       1 scheduler.go:138] [WaitForPodsOnCache] Pod prod-deployment-average-1-9a2b81a4ad79-8447964868-22sfk encontrado no cache.
I0210 17:16:40.995787       1 scheduler.go:597] [GetControllerMetricInfo] Iniciando para o pod: default/prod-deployment-average-2-77e788a61edf-5b7dd97cd5-zj78l
I0210 17:16:40.995790       1 scheduler.go:602] [GetControllerMetricInfo] Obtendo o nome do controlador para o pod: default/prod-deployment-average-2-77e788a61edf-5b7dd97cd5-zj78l
I0210 17:16:40.995793       1 types.go:751] [ControllerName] Verificando as anotações do pod default/prod-deployment-average-2-77e788a61edf-5b7dd97cd5-zj78l
I0210 17:16:40.995797       1 types.go:769] [ControllerName] Anotação 'controller' encontrada para o pod default/prod-deployment-average-2-77e788a61edf-5b7dd97cd5-zj78l: prod-deployment-average-2-77e788a61edf
I0210 17:16:40.995801       1 scheduler.go:605] [GetControllerMetricInfo] Métricas do controlador definidas para o pod: default/prod-deployment-average-2-77e788a61edf-5b7dd97cd5-zj78l
I0210 17:16:40.995806       1 scheduler.go:597] [GetControllerMetricInfo] Iniciando para o pod: default/prod-deployment-average-1-9a2b81a4ad79-8447964868-22sfk
I0210 17:16:40.995810       1 scheduler.go:602] [GetControllerMetricInfo] Obtendo o nome do controlador para o pod: default/prod-deployment-average-1-9a2b81a4ad79-8447964868-22sfk
I0210 17:16:40.995813       1 types.go:751] [ControllerName] Verificando as anotações do pod default/prod-deployment-average-1-9a2b81a4ad79-8447964868-22sfk
I0210 17:16:40.995816       1 types.go:769] [ControllerName] Anotação 'controller' encontrada para o pod default/prod-deployment-average-1-9a2b81a4ad79-8447964868-22sfk: prod-deployment-average-1-9a2b81a4ad79
I0210 17:16:40.995819       1 scheduler.go:605] [GetControllerMetricInfo] Métricas do controlador definidas para o pod: default/prod-deployment-average-1-9a2b81a4ad79-8447964868-22sfk
I0210 17:16:40.995825       1 types.go:546] [QoSMetric] qosMeasuringApproach: average
I0210 17:16:40.995829       1 types.go:532] [QoS DEBUG] effectiveRunning: 0.000000 | discardedRunning: 0.000000 | waiting: 1.993229 | binding: 0.000000 | denominator: 1.993229
I0210 17:16:40.995841       1 types.go:538] [QoS DEBUG] QoS calculado: 0.000000
I0210 17:16:40.995846       1 types.go:611] [COMPUTE QoS METRIC - AVERAGE] The pod prod-deployment-average-2-77e788a61edf-5b7dd97cd5-zj78l: availability 0.000000 | runtime 0.000000 | pendingTime 1.993229 | nRunning: 0 | nWaiting: 1 | residualContr 0 | estimatedOverhead 2.400000 | QoSMetric -4.393229
I0210 17:16:40.995857       1 types.go:546] [QoSMetric] qosMeasuringApproach: average
I0210 17:16:40.995863       1 types.go:532] [QoS DEBUG] effectiveRunning: 1.907027 | discardedRunning: 0.000000 | waiting: 0.080428 | binding: 0.005775 | denominator: 1.993229
I0210 17:16:40.995870       1 types.go:538] [QoS DEBUG] QoS calculado: 0.956752
I0210 17:16:40.995876       1 types.go:611] [COMPUTE QoS METRIC - AVERAGE] The pod prod-deployment-average-1-9a2b81a4ad79-8447964868-22sfk: availability 0.956752 | runtime 1.907027 | pendingTime 0.080428 | nRunning: 1 | nWaiting: 0 | residualContr 0 | estimatedOverhead 0.005775 | QoSMetric 0.384780
I0210 17:16:40.995884       1 scheduler.go:97] [HigherPrecedence] Métricas para prod-deployment-average-2-77e788a61edf-5b7dd97cd5-zj78l: QoS = -4.393229, Importância = 0.80
I0210 17:16:40.995891       1 scheduler.go:98] [HigherPrecedence] Métricas para prod-deployment-average-1-9a2b81a4ad79-8447964868-22sfk: QoS = 0.384780, Importância = 0.80
I0210 17:16:40.995896       1 scheduler.go:109] [HigherPrecedence] Decisão final: prod-deployment-average-2-77e788a61edf-5b7dd97cd5-zj78l tem precedência sobre prod-deployment-average-1-9a2b81a4ad79-8447964868-22sfk? true
I0210 17:16:40.995901       1 types.go:751] [ControllerName] Verificando as anotações do pod default/prod-deployment-average-2-77e788a61edf-5b7dd97cd5-zj78l
I0210 17:16:40.995904       1 types.go:769] [ControllerName] Anotação 'controller' encontrada para o pod default/prod-deployment-average-2-77e788a61edf-5b7dd97cd5-zj78l: prod-deployment-average-2-77e788a61edf
I0210 17:16:40.995907       1 types.go:751] [ControllerName] Verificando as anotações do pod default/prod-deployment-average-1-9a2b81a4ad79-8447964868-22sfk
I0210 17:16:40.995910       1 types.go:769] [ControllerName] Anotação 'controller' encontrada para o pod default/prod-deployment-average-1-9a2b81a4ad79-8447964868-22sfk: prod-deployment-average-1-9a2b81a4ad79
I0210 17:16:40.995913       1 scheduler.go:597] [GetControllerMetricInfo] Iniciando para o pod: default/prod-deployment-average-1-9a2b81a4ad79-8447964868-22sfk
I0210 17:16:40.995917       1 scheduler.go:602] [GetControllerMetricInfo] Obtendo o nome do controlador para o pod: default/prod-deployment-average-1-9a2b81a4ad79-8447964868-22sfk
I0210 17:16:40.995920       1 types.go:751] [ControllerName] Verificando as anotações do pod default/prod-deployment-average-1-9a2b81a4ad79-8447964868-22sfk
I0210 17:16:40.995923       1 types.go:769] [ControllerName] Anotação 'controller' encontrada para o pod default/prod-deployment-average-1-9a2b81a4ad79-8447964868-22sfk: prod-deployment-average-1-9a2b81a4ad79
I0210 17:16:40.995926       1 scheduler.go:605] [GetControllerMetricInfo] Métricas do controlador definidas para o pod: default/prod-deployment-average-1-9a2b81a4ad79-8447964868-22sfk
I0210 17:16:40.995929       1 scheduler.go:597] [GetControllerMetricInfo] Iniciando para o pod: default/prod-deployment-average-1-9a2b81a4ad79-8447964868-22sfk
I0210 17:16:40.995933       1 scheduler.go:602] [GetControllerMetricInfo] Obtendo o nome do controlador para o pod: default/prod-deployment-average-1-9a2b81a4ad79-8447964868-22sfk
I0210 17:16:40.995936       1 types.go:751] [ControllerName] Verificando as anotações do pod default/prod-deployment-average-1-9a2b81a4ad79-8447964868-22sfk
I0210 17:16:40.995939       1 types.go:769] [ControllerName] Anotação 'controller' encontrada para o pod default/prod-deployment-average-1-9a2b81a4ad79-8447964868-22sfk: prod-deployment-average-1-9a2b81a4ad79
I0210 17:16:40.995942       1 scheduler.go:605] [GetControllerMetricInfo] Métricas do controlador definidas para o pod: default/prod-deployment-average-1-9a2b81a4ad79-8447964868-22sfk
I0210 17:16:40.995946       1 types.go:751] [ControllerName] Verificando as anotações do pod default/prod-deployment-average-1-9a2b81a4ad79-8447964868-22sfk
I0210 17:16:40.995950       1 types.go:769] [ControllerName] Anotação 'controller' encontrada para o pod default/prod-deployment-average-1-9a2b81a4ad79-8447964868-22sfk: prod-deployment-average-1-9a2b81a4ad79
I0210 17:16:40.995983       1 postFilter.go:154] [PREEMPT CALL] No node was chosen to allocate pod prod-deployment-average-2-77e788a61edf-5b7dd97cd5-zj78l
W0210 17:16:40.995996       1 postFilter.go:45] [PostFilter] Nenhum nó nominado após a preempção para o pod: default/prod-deployment-average-2-77e788a61edf-5b7dd97cd5-zj78l
I0210 17:16:59.905524       1 postFilter.go:29] [PostFilter] PostFilter chamado para pod: default/prod-deployment-average-2-77e788a61edf-5b7dd97cd5-zj78l
I0210 17:16:59.905548       1 postFilter.go:76] Comparando pod original com o atualizado...
I0210 17:16:59.905554       1 postFilter.go:83] Successfully retrieved updated pod default/prod-deployment-average-2-77e788a61edf-5b7dd97cd5-zj78l from lister
I0210 17:16:59.907540       1 postFilter.go:250] [compareNodeResources] Recursos calculados no nó minikube: CPU = 8850 mCPU, Memória = 490373120 bytes
I0210 17:16:59.907559       1 postFilter.go:251] [compareNodeResources] Recursos do snapshot no nó minikube: CPU = 8850 mCPU, Memória = 490373120 bytes
I0210 17:16:59.907565       1 postFilter.go:257] [compareNodeResources] Recursos de CPU do nó minikube estão sincronizados: 8850 mCPU
I0210 17:16:59.907569       1 postFilter.go:263] [compareNodeResources] Recursos de memória do nó minikube estão sincronizados: 490373120 bytes
I0210 17:16:59.907576       1 postFilter.go:104] [Preempt] Verificando se é necessário limpar NominatedNodeName do pod default/prod-deployment-average-2-77e788a61edf-5b7dd97cd5-zj78l antes de continuar.
I0210 17:16:59.907673       1 scheduler.go:597] [GetControllerMetricInfo] Iniciando para o pod: default/prod-deployment-average-1-9a2b81a4ad79-8447964868-22sfk
I0210 17:16:59.907690       1 scheduler.go:602] [GetControllerMetricInfo] Obtendo o nome do controlador para o pod: default/prod-deployment-average-1-9a2b81a4ad79-8447964868-22sfk
I0210 17:16:59.907695       1 types.go:751] [ControllerName] Verificando as anotações do pod default/prod-deployment-average-1-9a2b81a4ad79-8447964868-22sfk
I0210 17:16:59.907700       1 types.go:769] [ControllerName] Anotação 'controller' encontrada para o pod default/prod-deployment-average-1-9a2b81a4ad79-8447964868-22sfk: prod-deployment-average-1-9a2b81a4ad79
I0210 17:16:59.907707       1 scheduler.go:605] [GetControllerMetricInfo] Métricas do controlador definidas para o pod: default/prod-deployment-average-1-9a2b81a4ad79-8447964868-22sfk
I0210 17:16:59.907712       1 scheduler.go:83] [HigherPrecedence] Calculando precedência entre prod-deployment-average-2-77e788a61edf-5b7dd97cd5-zj78l e prod-deployment-average-1-9a2b81a4ad79-8447964868-22sfk
I0210 17:16:59.907717       1 scheduler.go:116] [WaitForPodsOnCache] Verificando se o pod prod-deployment-average-2-77e788a61edf-5b7dd97cd5-zj78l está no cache...
I0210 17:16:59.907722       1 scheduler.go:597] [GetControllerMetricInfo] Iniciando para o pod: default/prod-deployment-average-2-77e788a61edf-5b7dd97cd5-zj78l
I0210 17:16:59.907726       1 scheduler.go:602] [GetControllerMetricInfo] Obtendo o nome do controlador para o pod: default/prod-deployment-average-2-77e788a61edf-5b7dd97cd5-zj78l
I0210 17:16:59.907730       1 types.go:751] [ControllerName] Verificando as anotações do pod default/prod-deployment-average-2-77e788a61edf-5b7dd97cd5-zj78l
I0210 17:16:59.907735       1 types.go:769] [ControllerName] Anotação 'controller' encontrada para o pod default/prod-deployment-average-2-77e788a61edf-5b7dd97cd5-zj78l: prod-deployment-average-2-77e788a61edf
I0210 17:16:59.907739       1 scheduler.go:605] [GetControllerMetricInfo] Métricas do controlador definidas para o pod: default/prod-deployment-average-2-77e788a61edf-5b7dd97cd5-zj78l
I0210 17:16:59.909612       1 scheduler.go:69] Estado no Informer: map[acceptablePreemptionOverhead:0.05 controller:prod-deployment-average-2-77e788a61edf qosMeasuring:average slo:0.8]
I0210 17:16:59.909640       1 scheduler.go:70] Estado real no cluster: map[acceptablePreemptionOverhead:0.05 controller:prod-deployment-average-2-77e788a61edf qosMeasuring:average slo:0.8]
I0210 17:16:59.909647       1 scheduler.go:138] [WaitForPodsOnCache] Pod prod-deployment-average-2-77e788a61edf-5b7dd97cd5-zj78l encontrado no cache.
I0210 17:16:59.909651       1 scheduler.go:116] [WaitForPodsOnCache] Verificando se o pod prod-deployment-average-1-9a2b81a4ad79-8447964868-22sfk está no cache...
I0210 17:16:59.909655       1 scheduler.go:597] [GetControllerMetricInfo] Iniciando para o pod: default/prod-deployment-average-1-9a2b81a4ad79-8447964868-22sfk
I0210 17:16:59.909658       1 scheduler.go:602] [GetControllerMetricInfo] Obtendo o nome do controlador para o pod: default/prod-deployment-average-1-9a2b81a4ad79-8447964868-22sfk
I0210 17:16:59.909662       1 types.go:751] [ControllerName] Verificando as anotações do pod default/prod-deployment-average-1-9a2b81a4ad79-8447964868-22sfk
I0210 17:16:59.909666       1 types.go:769] [ControllerName] Anotação 'controller' encontrada para o pod default/prod-deployment-average-1-9a2b81a4ad79-8447964868-22sfk: prod-deployment-average-1-9a2b81a4ad79
I0210 17:16:59.909670       1 scheduler.go:605] [GetControllerMetricInfo] Métricas do controlador definidas para o pod: default/prod-deployment-average-1-9a2b81a4ad79-8447964868-22sfk
I0210 17:16:59.911307       1 scheduler.go:69] Estado no Informer: map[acceptablePreemptionOverhead:0.05 controller:prod-deployment-average-1-9a2b81a4ad79 qosMeasuring:average slo:0.8]
I0210 17:16:59.911339       1 scheduler.go:70] Estado real no cluster: map[acceptablePreemptionOverhead:0.05 controller:prod-deployment-average-1-9a2b81a4ad79 qosMeasuring:average slo:0.8]
I0210 17:16:59.911346       1 scheduler.go:138] [WaitForPodsOnCache] Pod prod-deployment-average-1-9a2b81a4ad79-8447964868-22sfk encontrado no cache.
I0210 17:16:59.911351       1 scheduler.go:597] [GetControllerMetricInfo] Iniciando para o pod: default/prod-deployment-average-2-77e788a61edf-5b7dd97cd5-zj78l
I0210 17:16:59.911355       1 scheduler.go:602] [GetControllerMetricInfo] Obtendo o nome do controlador para o pod: default/prod-deployment-average-2-77e788a61edf-5b7dd97cd5-zj78l
I0210 17:16:59.911360       1 types.go:751] [ControllerName] Verificando as anotações do pod default/prod-deployment-average-2-77e788a61edf-5b7dd97cd5-zj78l
I0210 17:16:59.911366       1 types.go:769] [ControllerName] Anotação 'controller' encontrada para o pod default/prod-deployment-average-2-77e788a61edf-5b7dd97cd5-zj78l: prod-deployment-average-2-77e788a61edf
I0210 17:16:59.911373       1 scheduler.go:605] [GetControllerMetricInfo] Métricas do controlador definidas para o pod: default/prod-deployment-average-2-77e788a61edf-5b7dd97cd5-zj78l
I0210 17:16:59.911382       1 scheduler.go:597] [GetControllerMetricInfo] Iniciando para o pod: default/prod-deployment-average-1-9a2b81a4ad79-8447964868-22sfk
I0210 17:16:59.911396       1 scheduler.go:602] [GetControllerMetricInfo] Obtendo o nome do controlador para o pod: default/prod-deployment-average-1-9a2b81a4ad79-8447964868-22sfk
I0210 17:16:59.911400       1 types.go:751] [ControllerName] Verificando as anotações do pod default/prod-deployment-average-1-9a2b81a4ad79-8447964868-22sfk
I0210 17:16:59.911405       1 types.go:769] [ControllerName] Anotação 'controller' encontrada para o pod default/prod-deployment-average-1-9a2b81a4ad79-8447964868-22sfk: prod-deployment-average-1-9a2b81a4ad79
I0210 17:16:59.911412       1 scheduler.go:605] [GetControllerMetricInfo] Métricas do controlador definidas para o pod: default/prod-deployment-average-1-9a2b81a4ad79-8447964868-22sfk
I0210 17:16:59.911419       1 types.go:546] [QoSMetric] qosMeasuringApproach: average
I0210 17:16:59.911432       1 types.go:532] [QoS DEBUG] effectiveRunning: 0.000000 | discardedRunning: 0.000000 | waiting: 20.907710 | binding: 0.000000 | denominator: 20.907710
I0210 17:16:59.911440       1 types.go:538] [QoS DEBUG] QoS calculado: 0.000000
I0210 17:16:59.911449       1 types.go:611] [COMPUTE QoS METRIC - AVERAGE] The pod prod-deployment-average-2-77e788a61edf-5b7dd97cd5-zj78l: availability 0.000000 | runtime 0.000000 | pendingTime 20.907710 | nRunning: 0 | nWaiting: 1 | residualContr 0 | estimatedOverhead 2.400000 | QoSMetric -23.307710
I0210 17:16:59.911456       1 types.go:546] [QoSMetric] qosMeasuringApproach: average
I0210 17:16:59.911465       1 types.go:532] [QoS DEBUG] effectiveRunning: 20.821508 | discardedRunning: 0.000000 | waiting: 0.080428 | binding: 0.005775 | denominator: 20.907710
I0210 17:16:59.911483       1 types.go:538] [QoS DEBUG] QoS calculado: 0.995877
I0210 17:16:59.911490       1 types.go:611] [COMPUTE QoS METRIC - AVERAGE] The pod prod-deployment-average-1-9a2b81a4ad79-8447964868-22sfk: availability 0.995877 | runtime 20.821508 | pendingTime 0.080428 | nRunning: 1 | nWaiting: 0 | residualContr 0 | estimatedOverhead 0.005775 | QoSMetric 5.113400
I0210 17:16:59.911498       1 scheduler.go:97] [HigherPrecedence] Métricas para prod-deployment-average-2-77e788a61edf-5b7dd97cd5-zj78l: QoS = -23.307710, Importância = 0.80
I0210 17:16:59.911512       1 scheduler.go:98] [HigherPrecedence] Métricas para prod-deployment-average-1-9a2b81a4ad79-8447964868-22sfk: QoS = 5.113400, Importância = 0.80
I0210 17:16:59.911519       1 scheduler.go:109] [HigherPrecedence] Decisão final: prod-deployment-average-2-77e788a61edf-5b7dd97cd5-zj78l tem precedência sobre prod-deployment-average-1-9a2b81a4ad79-8447964868-22sfk? true
I0210 17:16:59.911539       1 types.go:751] [ControllerName] Verificando as anotações do pod default/prod-deployment-average-2-77e788a61edf-5b7dd97cd5-zj78l
I0210 17:16:59.911542       1 types.go:769] [ControllerName] Anotação 'controller' encontrada para o pod default/prod-deployment-average-2-77e788a61edf-5b7dd97cd5-zj78l: prod-deployment-average-2-77e788a61edf
I0210 17:16:59.911545       1 types.go:751] [ControllerName] Verificando as anotações do pod default/prod-deployment-average-1-9a2b81a4ad79-8447964868-22sfk
I0210 17:16:59.911554       1 types.go:769] [ControllerName] Anotação 'controller' encontrada para o pod default/prod-deployment-average-1-9a2b81a4ad79-8447964868-22sfk: prod-deployment-average-1-9a2b81a4ad79
I0210 17:16:59.911558       1 scheduler.go:597] [GetControllerMetricInfo] Iniciando para o pod: default/prod-deployment-average-1-9a2b81a4ad79-8447964868-22sfk
I0210 17:16:59.911561       1 scheduler.go:602] [GetControllerMetricInfo] Obtendo o nome do controlador para o pod: default/prod-deployment-average-1-9a2b81a4ad79-8447964868-22sfk
I0210 17:16:59.911564       1 types.go:751] [ControllerName] Verificando as anotações do pod default/prod-deployment-average-1-9a2b81a4ad79-8447964868-22sfk
I0210 17:16:59.911567       1 types.go:769] [ControllerName] Anotação 'controller' encontrada para o pod default/prod-deployment-average-1-9a2b81a4ad79-8447964868-22sfk: prod-deployment-average-1-9a2b81a4ad79
I0210 17:16:59.911571       1 scheduler.go:605] [GetControllerMetricInfo] Métricas do controlador definidas para o pod: default/prod-deployment-average-1-9a2b81a4ad79-8447964868-22sfk
I0210 17:16:59.911574       1 scheduler.go:597] [GetControllerMetricInfo] Iniciando para o pod: default/prod-deployment-average-1-9a2b81a4ad79-8447964868-22sfk
I0210 17:16:59.911577       1 scheduler.go:602] [GetControllerMetricInfo] Obtendo o nome do controlador para o pod: default/prod-deployment-average-1-9a2b81a4ad79-8447964868-22sfk
I0210 17:16:59.911580       1 types.go:751] [ControllerName] Verificando as anotações do pod default/prod-deployment-average-1-9a2b81a4ad79-8447964868-22sfk
I0210 17:16:59.911584       1 types.go:769] [ControllerName] Anotação 'controller' encontrada para o pod default/prod-deployment-average-1-9a2b81a4ad79-8447964868-22sfk: prod-deployment-average-1-9a2b81a4ad79
I0210 17:16:59.911589       1 scheduler.go:605] [GetControllerMetricInfo] Métricas do controlador definidas para o pod: default/prod-deployment-average-1-9a2b81a4ad79-8447964868-22sfk
I0210 17:16:59.911594       1 types.go:751] [ControllerName] Verificando as anotações do pod default/prod-deployment-average-1-9a2b81a4ad79-8447964868-22sfk
I0210 17:16:59.911598       1 types.go:769] [ControllerName] Anotação 'controller' encontrada para o pod default/prod-deployment-average-1-9a2b81a4ad79-8447964868-22sfk: prod-deployment-average-1-9a2b81a4ad79
I0210 17:16:59.911640       1 postFilter.go:154] [PREEMPT CALL] No node was chosen to allocate pod prod-deployment-average-2-77e788a61edf-5b7dd97cd5-zj78l
W0210 17:16:59.911653       1 postFilter.go:45] [PostFilter] Nenhum nó nominado após a preempção para o pod: default/prod-deployment-average-2-77e788a61edf-5b7dd97cd5-zj78l
I0210 17:17:29.905993       1 postFilter.go:29] [PostFilter] PostFilter chamado para pod: default/prod-deployment-average-2-77e788a61edf-5b7dd97cd5-zj78l
I0210 17:17:29.906020       1 postFilter.go:76] Comparando pod original com o atualizado...
I0210 17:17:29.906028       1 postFilter.go:83] Successfully retrieved updated pod default/prod-deployment-average-2-77e788a61edf-5b7dd97cd5-zj78l from lister
I0210 17:17:29.907926       1 postFilter.go:250] [compareNodeResources] Recursos calculados no nó minikube: CPU = 8850 mCPU, Memória = 490373120 bytes
I0210 17:17:29.907947       1 postFilter.go:251] [compareNodeResources] Recursos do snapshot no nó minikube: CPU = 8850 mCPU, Memória = 490373120 bytes
I0210 17:17:29.907952       1 postFilter.go:257] [compareNodeResources] Recursos de CPU do nó minikube estão sincronizados: 8850 mCPU
I0210 17:17:29.907956       1 postFilter.go:263] [compareNodeResources] Recursos de memória do nó minikube estão sincronizados: 490373120 bytes
I0210 17:17:29.907964       1 postFilter.go:104] [Preempt] Verificando se é necessário limpar NominatedNodeName do pod default/prod-deployment-average-2-77e788a61edf-5b7dd97cd5-zj78l antes de continuar.
I0210 17:17:29.908044       1 scheduler.go:597] [GetControllerMetricInfo] Iniciando para o pod: default/prod-deployment-average-1-9a2b81a4ad79-8447964868-22sfk
I0210 17:17:29.908061       1 scheduler.go:602] [GetControllerMetricInfo] Obtendo o nome do controlador para o pod: default/prod-deployment-average-1-9a2b81a4ad79-8447964868-22sfk
I0210 17:17:29.908066       1 types.go:751] [ControllerName] Verificando as anotações do pod default/prod-deployment-average-1-9a2b81a4ad79-8447964868-22sfk
I0210 17:17:29.908071       1 types.go:769] [ControllerName] Anotação 'controller' encontrada para o pod default/prod-deployment-average-1-9a2b81a4ad79-8447964868-22sfk: prod-deployment-average-1-9a2b81a4ad79
I0210 17:17:29.908089       1 scheduler.go:605] [GetControllerMetricInfo] Métricas do controlador definidas para o pod: default/prod-deployment-average-1-9a2b81a4ad79-8447964868-22sfk
I0210 17:17:29.908094       1 scheduler.go:83] [HigherPrecedence] Calculando precedência entre prod-deployment-average-2-77e788a61edf-5b7dd97cd5-zj78l e prod-deployment-average-1-9a2b81a4ad79-8447964868-22sfk
I0210 17:17:29.908098       1 scheduler.go:116] [WaitForPodsOnCache] Verificando se o pod prod-deployment-average-2-77e788a61edf-5b7dd97cd5-zj78l está no cache...
I0210 17:17:29.908102       1 scheduler.go:597] [GetControllerMetricInfo] Iniciando para o pod: default/prod-deployment-average-2-77e788a61edf-5b7dd97cd5-zj78l
I0210 17:17:29.908106       1 scheduler.go:602] [GetControllerMetricInfo] Obtendo o nome do controlador para o pod: default/prod-deployment-average-2-77e788a61edf-5b7dd97cd5-zj78l
I0210 17:17:29.908109       1 types.go:751] [ControllerName] Verificando as anotações do pod default/prod-deployment-average-2-77e788a61edf-5b7dd97cd5-zj78l
I0210 17:17:29.908113       1 types.go:769] [ControllerName] Anotação 'controller' encontrada para o pod default/prod-deployment-average-2-77e788a61edf-5b7dd97cd5-zj78l: prod-deployment-average-2-77e788a61edf
I0210 17:17:29.908121       1 scheduler.go:605] [GetControllerMetricInfo] Métricas do controlador definidas para o pod: default/prod-deployment-average-2-77e788a61edf-5b7dd97cd5-zj78l
I0210 17:17:29.909738       1 scheduler.go:69] Estado no Informer: map[acceptablePreemptionOverhead:0.05 controller:prod-deployment-average-2-77e788a61edf qosMeasuring:average slo:0.8]
I0210 17:17:29.909766       1 scheduler.go:70] Estado real no cluster: map[acceptablePreemptionOverhead:0.05 controller:prod-deployment-average-2-77e788a61edf qosMeasuring:average slo:0.8]
I0210 17:17:29.909773       1 scheduler.go:138] [WaitForPodsOnCache] Pod prod-deployment-average-2-77e788a61edf-5b7dd97cd5-zj78l encontrado no cache.
I0210 17:17:29.909776       1 scheduler.go:116] [WaitForPodsOnCache] Verificando se o pod prod-deployment-average-1-9a2b81a4ad79-8447964868-22sfk está no cache...
I0210 17:17:29.909780       1 scheduler.go:597] [GetControllerMetricInfo] Iniciando para o pod: default/prod-deployment-average-1-9a2b81a4ad79-8447964868-22sfk
I0210 17:17:29.909783       1 scheduler.go:602] [GetControllerMetricInfo] Obtendo o nome do controlador para o pod: default/prod-deployment-average-1-9a2b81a4ad79-8447964868-22sfk
I0210 17:17:29.909786       1 types.go:751] [ControllerName] Verificando as anotações do pod default/prod-deployment-average-1-9a2b81a4ad79-8447964868-22sfk
I0210 17:17:29.909790       1 types.go:769] [ControllerName] Anotação 'controller' encontrada para o pod default/prod-deployment-average-1-9a2b81a4ad79-8447964868-22sfk: prod-deployment-average-1-9a2b81a4ad79
I0210 17:17:29.909794       1 scheduler.go:605] [GetControllerMetricInfo] Métricas do controlador definidas para o pod: default/prod-deployment-average-1-9a2b81a4ad79-8447964868-22sfk
I0210 17:17:29.911347       1 scheduler.go:69] Estado no Informer: map[acceptablePreemptionOverhead:0.05 controller:prod-deployment-average-1-9a2b81a4ad79 qosMeasuring:average slo:0.8]
I0210 17:17:29.911368       1 scheduler.go:70] Estado real no cluster: map[acceptablePreemptionOverhead:0.05 controller:prod-deployment-average-1-9a2b81a4ad79 qosMeasuring:average slo:0.8]
I0210 17:17:29.911373       1 scheduler.go:138] [WaitForPodsOnCache] Pod prod-deployment-average-1-9a2b81a4ad79-8447964868-22sfk encontrado no cache.
I0210 17:17:29.911377       1 scheduler.go:597] [GetControllerMetricInfo] Iniciando para o pod: default/prod-deployment-average-2-77e788a61edf-5b7dd97cd5-zj78l
I0210 17:17:29.911381       1 scheduler.go:602] [GetControllerMetricInfo] Obtendo o nome do controlador para o pod: default/prod-deployment-average-2-77e788a61edf-5b7dd97cd5-zj78l
I0210 17:17:29.911385       1 types.go:751] [ControllerName] Verificando as anotações do pod default/prod-deployment-average-2-77e788a61edf-5b7dd97cd5-zj78l
I0210 17:17:29.911389       1 types.go:769] [ControllerName] Anotação 'controller' encontrada para o pod default/prod-deployment-average-2-77e788a61edf-5b7dd97cd5-zj78l: prod-deployment-average-2-77e788a61edf
I0210 17:17:29.911393       1 scheduler.go:605] [GetControllerMetricInfo] Métricas do controlador definidas para o pod: default/prod-deployment-average-2-77e788a61edf-5b7dd97cd5-zj78l
I0210 17:17:29.911399       1 scheduler.go:597] [GetControllerMetricInfo] Iniciando para o pod: default/prod-deployment-average-1-9a2b81a4ad79-8447964868-22sfk
I0210 17:17:29.911403       1 scheduler.go:602] [GetControllerMetricInfo] Obtendo o nome do controlador para o pod: default/prod-deployment-average-1-9a2b81a4ad79-8447964868-22sfk
I0210 17:17:29.911405       1 types.go:751] [ControllerName] Verificando as anotações do pod default/prod-deployment-average-1-9a2b81a4ad79-8447964868-22sfk
I0210 17:17:29.911409       1 types.go:769] [ControllerName] Anotação 'controller' encontrada para o pod default/prod-deployment-average-1-9a2b81a4ad79-8447964868-22sfk: prod-deployment-average-1-9a2b81a4ad79
I0210 17:17:29.911412       1 scheduler.go:605] [GetControllerMetricInfo] Métricas do controlador definidas para o pod: default/prod-deployment-average-1-9a2b81a4ad79-8447964868-22sfk
I0210 17:17:29.911419       1 types.go:546] [QoSMetric] qosMeasuringApproach: average
I0210 17:17:29.911431       1 types.go:532] [QoS DEBUG] effectiveRunning: 0.000000 | discardedRunning: 0.000000 | waiting: 50.908092 | binding: 0.000000 | denominator: 50.908092
I0210 17:17:29.911439       1 types.go:538] [QoS DEBUG] QoS calculado: 0.000000
I0210 17:17:29.911444       1 types.go:611] [COMPUTE QoS METRIC - AVERAGE] The pod prod-deployment-average-2-77e788a61edf-5b7dd97cd5-zj78l: availability 0.000000 | runtime 0.000000 | pendingTime 50.908092 | nRunning: 0 | nWaiting: 1 | residualContr 0 | estimatedOverhead 2.400000 | QoSMetric -53.308092
I0210 17:17:29.911449       1 types.go:546] [QoSMetric] qosMeasuringApproach: average
I0210 17:17:29.911455       1 types.go:532] [QoS DEBUG] effectiveRunning: 50.821890 | discardedRunning: 0.000000 | waiting: 0.080428 | binding: 0.005775 | denominator: 50.908092
I0210 17:17:29.911467       1 types.go:538] [QoS DEBUG] QoS calculado: 0.998307
I0210 17:17:29.911472       1 types.go:611] [COMPUTE QoS METRIC - AVERAGE] The pod prod-deployment-average-1-9a2b81a4ad79-8447964868-22sfk: availability 0.998307 | runtime 50.821890 | pendingTime 0.080428 | nRunning: 1 | nWaiting: 0 | residualContr 0 | estimatedOverhead 0.005775 | QoSMetric 12.613495
I0210 17:17:29.911477       1 scheduler.go:97] [HigherPrecedence] Métricas para prod-deployment-average-2-77e788a61edf-5b7dd97cd5-zj78l: QoS = -53.308092, Importância = 0.80
I0210 17:17:29.911483       1 scheduler.go:98] [HigherPrecedence] Métricas para prod-deployment-average-1-9a2b81a4ad79-8447964868-22sfk: QoS = 12.613495, Importância = 0.80
I0210 17:17:29.911488       1 scheduler.go:109] [HigherPrecedence] Decisão final: prod-deployment-average-2-77e788a61edf-5b7dd97cd5-zj78l tem precedência sobre prod-deployment-average-1-9a2b81a4ad79-8447964868-22sfk? true
I0210 17:17:29.911499       1 types.go:751] [ControllerName] Verificando as anotações do pod default/prod-deployment-average-2-77e788a61edf-5b7dd97cd5-zj78l
I0210 17:17:29.911502       1 types.go:769] [ControllerName] Anotação 'controller' encontrada para o pod default/prod-deployment-average-2-77e788a61edf-5b7dd97cd5-zj78l: prod-deployment-average-2-77e788a61edf
I0210 17:17:29.911506       1 types.go:751] [ControllerName] Verificando as anotações do pod default/prod-deployment-average-1-9a2b81a4ad79-8447964868-22sfk
I0210 17:17:29.911509       1 types.go:769] [ControllerName] Anotação 'controller' encontrada para o pod default/prod-deployment-average-1-9a2b81a4ad79-8447964868-22sfk: prod-deployment-average-1-9a2b81a4ad79
I0210 17:17:29.911512       1 scheduler.go:597] [GetControllerMetricInfo] Iniciando para o pod: default/prod-deployment-average-1-9a2b81a4ad79-8447964868-22sfk
I0210 17:17:29.911516       1 scheduler.go:602] [GetControllerMetricInfo] Obtendo o nome do controlador para o pod: default/prod-deployment-average-1-9a2b81a4ad79-8447964868-22sfk
I0210 17:17:29.911521       1 types.go:751] [ControllerName] Verificando as anotações do pod default/prod-deployment-average-1-9a2b81a4ad79-8447964868-22sfk
I0210 17:17:29.911525       1 types.go:769] [ControllerName] Anotação 'controller' encontrada para o pod default/prod-deployment-average-1-9a2b81a4ad79-8447964868-22sfk: prod-deployment-average-1-9a2b81a4ad79
I0210 17:17:29.911530       1 scheduler.go:605] [GetControllerMetricInfo] Métricas do controlador definidas para o pod: default/prod-deployment-average-1-9a2b81a4ad79-8447964868-22sfk
I0210 17:17:29.911535       1 scheduler.go:597] [GetControllerMetricInfo] Iniciando para o pod: default/prod-deployment-average-1-9a2b81a4ad79-8447964868-22sfk
I0210 17:17:29.911540       1 scheduler.go:602] [GetControllerMetricInfo] Obtendo o nome do controlador para o pod: default/prod-deployment-average-1-9a2b81a4ad79-8447964868-22sfk
I0210 17:17:29.911554       1 types.go:751] [ControllerName] Verificando as anotações do pod default/prod-deployment-average-1-9a2b81a4ad79-8447964868-22sfk
I0210 17:17:29.911558       1 types.go:769] [ControllerName] Anotação 'controller' encontrada para o pod default/prod-deployment-average-1-9a2b81a4ad79-8447964868-22sfk: prod-deployment-average-1-9a2b81a4ad79
I0210 17:17:29.911562       1 scheduler.go:605] [GetControllerMetricInfo] Métricas do controlador definidas para o pod: default/prod-deployment-average-1-9a2b81a4ad79-8447964868-22sfk
I0210 17:17:29.911566       1 types.go:751] [ControllerName] Verificando as anotações do pod default/prod-deployment-average-1-9a2b81a4ad79-8447964868-22sfk
I0210 17:17:29.911569       1 types.go:769] [ControllerName] Anotação 'controller' encontrada para o pod default/prod-deployment-average-1-9a2b81a4ad79-8447964868-22sfk: prod-deployment-average-1-9a2b81a4ad79
I0210 17:17:29.911574       1 types.go:546] [QoSMetric] qosMeasuringApproach: average
I0210 17:17:29.911582       1 types.go:532] [QoS DEBUG] effectiveRunning: 50.825295 | discardedRunning: 0.000000 | waiting: 0.080428 | binding: 0.005775 | denominator: 50.911497
I0210 17:17:29.911587       1 types.go:538] [QoS DEBUG] QoS calculado: 0.998307
I0210 17:17:29.911593       1 types.go:611] [COMPUTE QoS METRIC - AVERAGE] The pod prod-deployment-average-1-9a2b81a4ad79-8447964868-22sfk: availability 0.998307 | runtime 50.825295 | pendingTime 0.080428 | nRunning: 1 | nWaiting: 0 | residualContr 0 | estimatedOverhead 0.005775 | QoSMetric 12.614347
I0210 17:17:29.911608       1 postFilter.go:676] [selectVictimsOnNode]
I0210 17:17:29.911652       1 scheduler.go:597] [GetControllerMetricInfo] Iniciando para o pod: default/prod-deployment-average-1-9a2b81a4ad79-8447964868-22sfk
I0210 17:17:29.911664       1 scheduler.go:602] [GetControllerMetricInfo] Obtendo o nome do controlador para o pod: default/prod-deployment-average-1-9a2b81a4ad79-8447964868-22sfk
I0210 17:17:29.911667       1 types.go:751] [ControllerName] Verificando as anotações do pod default/prod-deployment-average-1-9a2b81a4ad79-8447964868-22sfk
I0210 17:17:29.911671       1 types.go:769] [ControllerName] Anotação 'controller' encontrada para o pod default/prod-deployment-average-1-9a2b81a4ad79-8447964868-22sfk: prod-deployment-average-1-9a2b81a4ad79
I0210 17:17:29.911675       1 scheduler.go:605] [GetControllerMetricInfo] Métricas do controlador definidas para o pod: default/prod-deployment-average-1-9a2b81a4ad79-8447964868-22sfk
I0210 17:17:29.911679       1 types.go:546] [QoSMetric] qosMeasuringApproach: average
I0210 17:17:29.911683       1 types.go:532] [QoS DEBUG] effectiveRunning: 50.825448 | discardedRunning: 0.000000 | waiting: 0.080428 | binding: 0.005775 | denominator: 50.911650
I0210 17:17:29.911688       1 types.go:538] [QoS DEBUG] QoS calculado: 0.998307
I0210 17:17:29.911692       1 types.go:611] [COMPUTE QoS METRIC - AVERAGE] The pod prod-deployment-average-1-9a2b81a4ad79-8447964868-22sfk: availability 0.998307 | runtime 50.825448 | pendingTime 0.080428 | nRunning: 1 | nWaiting: 0 | residualContr 0 | estimatedOverhead 0.005775 | QoSMetric 12.614385
I0210 17:17:29.911707       1 scheduler.go:597] [GetControllerMetricInfo] Iniciando para o pod: default/prod-deployment-average-1-9a2b81a4ad79-8447964868-22sfk
I0210 17:17:29.911711       1 scheduler.go:602] [GetControllerMetricInfo] Obtendo o nome do controlador para o pod: default/prod-deployment-average-1-9a2b81a4ad79-8447964868-22sfk
I0210 17:17:29.911715       1 types.go:751] [ControllerName] Verificando as anotações do pod default/prod-deployment-average-1-9a2b81a4ad79-8447964868-22sfk
I0210 17:17:29.911719       1 types.go:769] [ControllerName] Anotação 'controller' encontrada para o pod default/prod-deployment-average-1-9a2b81a4ad79-8447964868-22sfk: prod-deployment-average-1-9a2b81a4ad79
I0210 17:17:29.911723       1 scheduler.go:605] [GetControllerMetricInfo] Métricas do controlador definidas para o pod: default/prod-deployment-average-1-9a2b81a4ad79-8447964868-22sfk
I0210 17:17:29.911734       1 postFilter.go:157] [PREEMPT CALL] The node minikube  was chosen to allocate pod prod-deployment-average-2-77e788a61edf-5b7dd97cd5-zj78l
I0210 17:17:29.911748       1 postFilter.go:161] [Preempt] Iniciando a remoção dos pods preemptados no nó minikube para alocar o pod default/prod-deployment-average-2-77e788a61edf-5b7dd97cd5-zj78l. Total de vítimas: 1
I0210 17:17:29.911755       1 postFilter.go:165] [Preempt] Tentando remover o pod default/prod-deployment-average-1-9a2b81a4ad79-8447964868-22sfk no nó minikube
I0210 17:17:29.917993       1 scheduler.go:252] [OnUpdatePod] Iniciando processamento de atualização de pod
I0210 17:17:29.918043       1 scheduler.go:256] [OnUpdatePod] Pod atualizado detectado: default/prod-deployment-average-1-9a2b81a4ad79-8447964868-22sfk, Anotações: map[acceptablePreemptionOverhead:0.05 controller:prod-deployment-average-1-9a2b81a4ad79 qosMeasuring:average slo:0.8]
I0210 17:17:29.918056       1 scheduler.go:259] [OnUpdatePod] Comparando estado no Informer e estado real no cluster para o pod default/prod-deployment-average-1-9a2b81a4ad79-8447964868-22sfk
I0210 17:17:29.920037       1 scheduler.go:69] Estado no Informer: map[acceptablePreemptionOverhead:0.05 controller:prod-deployment-average-1-9a2b81a4ad79 qosMeasuring:average slo:0.8]
I0210 17:17:29.920069       1 scheduler.go:70] Estado real no cluster: map[acceptablePreemptionOverhead:0.05 controller:prod-deployment-average-1-9a2b81a4ad79 qosMeasuring:average slo:0.8]
I0210 17:17:29.920091       1 scheduler.go:269] [OnUpdatePod] Atualizando informações de métricas para o pod default/prod-deployment-average-1-9a2b81a4ad79-8447964868-22sfk
I0210 17:17:29.920097       1 types.go:751] [ControllerName] Verificando as anotações do pod default/prod-deployment-average-1-9a2b81a4ad79-8447964868-22sfk
I0210 17:17:29.920103       1 types.go:769] [ControllerName] Anotação 'controller' encontrada para o pod default/prod-deployment-average-1-9a2b81a4ad79-8447964868-22sfk: prod-deployment-average-1-9a2b81a4ad79
I0210 17:17:29.920112       1 scheduler.go:271] [OnUpdatePod] Atualizando 'LastStatus' do pod default/prod-deployment-average-1-9a2b81a4ad79-8447964868-22sfk nas métricas
I0210 17:17:29.920116       1 scheduler.go:273] [OnUpdatePod] Métrica atualizada para o pod default/prod-deployment-average-1-9a2b81a4ad79-8447964868-22sfk
I0210 17:17:29.920137       1 scheduler.go:277] [OnUpdatePod] Finalizando processamento de atualização de pod para default/prod-deployment-average-1-9a2b81a4ad79-8447964868-22sfk
I0210 17:17:29.920152       1 types.go:751] [ControllerName] Verificando as anotações do pod default/prod-deployment-average-1-9a2b81a4ad79-8447964868-22sfk
I0210 17:17:29.920210       1 types.go:769] [ControllerName] Anotação 'controller' encontrada para o pod default/prod-deployment-average-1-9a2b81a4ad79-8447964868-22sfk: prod-deployment-average-1-9a2b81a4ad79
I0210 17:17:29.920222       1 types.go:532] [QoS DEBUG] effectiveRunning: 50.834012 | discardedRunning: 0.000000 | waiting: 0.080428 | binding: 0.005775 | denominator: 50.920214
I0210 17:17:29.920250       1 types.go:538] [QoS DEBUG] QoS calculado: 0.998307
I0210 17:17:29.920253       1 types.go:546] [QoSMetric] qosMeasuringApproach: average
I0210 17:17:29.920257       1 types.go:532] [QoS DEBUG] effectiveRunning: 50.834012 | discardedRunning: 0.000000 | waiting: 0.080428 | binding: 0.005775 | denominator: 50.920214
I0210 17:17:29.920261       1 types.go:538] [QoS DEBUG] QoS calculado: 0.998307
I0210 17:17:29.920274       1 types.go:611] [COMPUTE QoS METRIC - AVERAGE] The pod prod-deployment-average-1-9a2b81a4ad79-8447964868-22sfk: availability 0.998307 | runtime 50.834012 | pendingTime 0.080428 | nRunning: 0 | nWaiting: 0 | residualContr -1 | estimatedOverhead 0.005775 | QoSMetric 10.092066
I0210 17:17:29.924327       1 postFilter.go:171] [Preempt] Pod default/prod-deployment-average-1-9a2b81a4ad79-8447964868-22sfk removido com sucesso no nó minikube
I0210 17:17:29.924369       1 postFilter.go:177] prod-deployment-average-1-9a2b81a4ad79-8447964868-22sfk_default preempted by prod-deployment-average-2-77e788a61edf-5b7dd97cd5-zj78l_default on node minikube
I0210 17:17:29.924417       1 postFilter.go:182] [Preempt] Total de pods preemptados no nó minikube: 1
I0210 17:17:29.924433       1 postFilter.go:796] [getLowerPrecedenceNominatedPods] Nenhum pod nomeado encontrado para o nó: minikube
I0210 17:17:29.924444       1 postFilter.go:189] [Preempt] Verificando pods de menor precedência no nó minikube que precisam ter o campo NominatedNodeName limpo
I0210 17:17:29.924456       1 postFilter.go:194] [Preempt] Limpando NominatedNodeName dos pods de menor precedência no nó minikube para evitar conflito com o pod default/prod-deployment-average-2-77e788a61edf-5b7dd97cd5-zj78l.
I0210 17:17:29.924453       1 scheduler.go:282] [OnDeletePod] Iniciando a execução do OnDeletePod
I0210 17:17:29.924470       1 postFilter.go:199] [Preempt] NominatedNodeName dos pods de menor precedência no nó minikube removido com sucesso.
I0210 17:17:29.924483       1 postFilter.go:202] [Preempt] Finalizado para o nó minikube. Pod default/prod-deployment-average-2-77e788a61edf-5b7dd97cd5-zj78l deve ser alocado agora.
I0210 17:17:29.924545       1 postFilter.go:49] [PostFilter] Nó nominado para o pod default/prod-deployment-average-2-77e788a61edf-5b7dd97cd5-zj78l: minikube
I0210 17:17:29.924501       1 scheduler.go:291] [OnDeletePod] DeepCopy realizado para o pod default/prod-deployment-average-1-9a2b81a4ad79-8447964868-22sfk
I0210 17:17:29.924929       1 scheduler.go:298] [OnDeletePod] Pod deletado detectado: default/prod-deployment-average-1-9a2b81a4ad79-8447964868-22sfk
I0210 17:17:29.924957       1 scheduler.go:300] [OnDeletePod] Atualizando métricas do pod default/prod-deployment-average-1-9a2b81a4ad79-8447964868-22sfk
I0210 17:17:29.924964       1 types.go:751] [ControllerName] Verificando as anotações do pod default/prod-deployment-average-1-9a2b81a4ad79-8447964868-22sfk
I0210 17:17:29.924970       1 types.go:769] [ControllerName] Anotação 'controller' encontrada para o pod default/prod-deployment-average-1-9a2b81a4ad79-8447964868-22sfk: prod-deployment-average-1-9a2b81a4ad79
I0210 17:17:29.924981       1 scheduler.go:302] [OnDeletePod] Verificando o estado do pod default/prod-deployment-average-1-9a2b81a4ad79-8447964868-22sfk nas métricas
I0210 17:17:29.924985       1 scheduler.go:312] [OnDeletePod] EndTime atualizado para o pod default/prod-deployment-average-1-9a2b81a4ad79-8447964868-22sfk: 2025-02-10 17:17:29.924983095 +0000 UTC m=+180.852720649
I0210 17:17:29.924995       1 scheduler.go:316] [OnDeletePod] Finalizando a execução do OnDeletePod para o pod default/prod-deployment-average-1-9a2b81a4ad79-8447964868-22sfk
I0210 17:17:29.934212       1 scheduler.go:252] [OnUpdatePod] Iniciando processamento de atualização de pod
I0210 17:17:29.934351       1 scheduler.go:256] [OnUpdatePod] Pod atualizado detectado: default/prod-deployment-average-2-77e788a61edf-5b7dd97cd5-zj78l, Anotações: map[acceptablePreemptionOverhead:0.05 controller:prod-deployment-average-2-77e788a61edf qosMeasuring:average slo:0.8]
I0210 17:17:29.934381       1 scheduler.go:259] [OnUpdatePod] Comparando estado no Informer e estado real no cluster para o pod default/prod-deployment-average-2-77e788a61edf-5b7dd97cd5-zj78l
I0210 17:17:29.934388       1 postFilter.go:29] [PostFilter] PostFilter chamado para pod: default/prod-deployment-average-1-9a2b81a4ad79-8447964868-6npqb
I0210 17:17:29.934398       1 postFilter.go:76] Comparando pod original com o atualizado...
I0210 17:17:29.934412       1 postFilter.go:83] Successfully retrieved updated pod default/prod-deployment-average-1-9a2b81a4ad79-8447964868-6npqb from lister
I0210 17:17:29.936669       1 scheduler.go:69] Estado no Informer: map[acceptablePreemptionOverhead:0.05 controller:prod-deployment-average-2-77e788a61edf qosMeasuring:average slo:0.8]
I0210 17:17:29.936696       1 scheduler.go:70] Estado real no cluster: map[acceptablePreemptionOverhead:0.05 controller:prod-deployment-average-2-77e788a61edf qosMeasuring:average slo:0.8]
I0210 17:17:29.936704       1 scheduler.go:269] [OnUpdatePod] Atualizando informações de métricas para o pod default/prod-deployment-average-2-77e788a61edf-5b7dd97cd5-zj78l
I0210 17:17:29.936710       1 types.go:751] [ControllerName] Verificando as anotações do pod default/prod-deployment-average-2-77e788a61edf-5b7dd97cd5-zj78l
I0210 17:17:29.936715       1 types.go:769] [ControllerName] Anotação 'controller' encontrada para o pod default/prod-deployment-average-2-77e788a61edf-5b7dd97cd5-zj78l: prod-deployment-average-2-77e788a61edf
I0210 17:17:29.936716       1 postFilter.go:250] [compareNodeResources] Recursos calculados no nó minikube: CPU = 850 mCPU, Memória = 387973120 bytes
I0210 17:17:29.936723       1 scheduler.go:271] [OnUpdatePod] Atualizando 'LastStatus' do pod default/prod-deployment-average-2-77e788a61edf-5b7dd97cd5-zj78l nas métricas
I0210 17:17:29.936724       1 postFilter.go:251] [compareNodeResources] Recursos do snapshot no nó minikube: CPU = 850 mCPU, Memória = 387973120 bytes
I0210 17:17:29.936727       1 scheduler.go:273] [OnUpdatePod] Métrica atualizada para o pod default/prod-deployment-average-2-77e788a61edf-5b7dd97cd5-zj78l
I0210 17:17:29.936730       1 postFilter.go:257] [compareNodeResources] Recursos de CPU do nó minikube estão sincronizados: 850 mCPU
I0210 17:17:29.936735       1 scheduler.go:277] [OnUpdatePod] Finalizando processamento de atualização de pod para default/prod-deployment-average-2-77e788a61edf-5b7dd97cd5-zj78l
I0210 17:17:29.936736       1 postFilter.go:263] [compareNodeResources] Recursos de memória do nó minikube estão sincronizados: 387973120 bytes
I0210 17:17:29.936745       1 postFilter.go:104] [Preempt] Verificando se é necessário limpar NominatedNodeName do pod default/prod-deployment-average-1-9a2b81a4ad79-8447964868-6npqb antes de continuar.
I0210 17:17:29.936766       1 scheduler.go:214] [OnAddPod] Pod adicionado: default/prod-deployment-average-1-9a2b81a4ad79-8447964868-6npqb, Anotações: map[acceptablePreemptionOverhead:0.05 controller:prod-deployment-average-1-9a2b81a4ad79 qosMeasuring:average slo:0.8]
I0210 17:17:29.936878       1 postFilter.go:157] [PREEMPT CALL] The node minikube  was chosen to allocate pod prod-deployment-average-1-9a2b81a4ad79-8447964868-6npqb
I0210 17:17:29.936907       1 postFilter.go:161] [Preempt] Iniciando a remoção dos pods preemptados no nó minikube para alocar o pod default/prod-deployment-average-1-9a2b81a4ad79-8447964868-6npqb. Total de vítimas: 0
I0210 17:17:29.936923       1 postFilter.go:182] [Preempt] Total de pods preemptados no nó minikube: 0
I0210 17:17:29.936945       1 postFilter.go:801] [getLowerPrecedenceNominatedPods]Verificando pods nomeados para o nó: minikube
I0210 17:17:29.936949       1 postFilter.go:804] [getLowerPrecedenceNominatedPods]Comparando pod default/prod-deployment-average-1-9a2b81a4ad79-8447964868-6npqb com prioridade 824647247512 com pod default/prod-deployment-average-2-77e788a61edf-5b7dd97cd5-zj78l com prioridade 824649548040
I0210 17:17:29.936954       1 scheduler.go:83] [HigherPrecedence] Calculando precedência entre prod-deployment-average-1-9a2b81a4ad79-8447964868-6npqb e prod-deployment-average-2-77e788a61edf-5b7dd97cd5-zj78l
I0210 17:17:29.936959       1 scheduler.go:116] [WaitForPodsOnCache] Verificando se o pod prod-deployment-average-1-9a2b81a4ad79-8447964868-6npqb está no cache...
I0210 17:17:29.936963       1 scheduler.go:597] [GetControllerMetricInfo] Iniciando para o pod: default/prod-deployment-average-1-9a2b81a4ad79-8447964868-6npqb
I0210 17:17:29.936970       1 scheduler.go:602] [GetControllerMetricInfo] Obtendo o nome do controlador para o pod: default/prod-deployment-average-1-9a2b81a4ad79-8447964868-6npqb
I0210 17:17:29.936985       1 types.go:751] [ControllerName] Verificando as anotações do pod default/prod-deployment-average-1-9a2b81a4ad79-8447964868-6npqb
I0210 17:17:29.937000       1 types.go:769] [ControllerName] Anotação 'controller' encontrada para o pod default/prod-deployment-average-1-9a2b81a4ad79-8447964868-6npqb: prod-deployment-average-1-9a2b81a4ad79
I0210 17:17:29.937004       1 scheduler.go:605] [GetControllerMetricInfo] Métricas do controlador definidas para o pod: default/prod-deployment-average-1-9a2b81a4ad79-8447964868-6npqb
W0210 17:17:29.937009       1 scheduler.go:124] [cacheMiss] Métricas não encontradas para o pod: default/prod-deployment-average-1-9a2b81a4ad79-8447964868-6npqb
I0210 17:17:29.941617       1 scheduler.go:69] Estado no Informer: map[acceptablePreemptionOverhead:0.05 controller:prod-deployment-average-1-9a2b81a4ad79 qosMeasuring:average slo:0.8]
I0210 17:17:29.941653       1 scheduler.go:70] Estado real no cluster: map[acceptablePreemptionOverhead:0.05 controller:prod-deployment-average-1-9a2b81a4ad79 qosMeasuring:average slo:0.8]
I0210 17:17:29.941762       1 scheduler.go:69] Estado no Informer: map[acceptablePreemptionOverhead:0.05 controller:prod-deployment-average-1-9a2b81a4ad79 qosMeasuring:average slo:0.8]
I0210 17:17:29.941792       1 scheduler.go:70] Estado real no cluster: map[acceptablePreemptionOverhead:0.05 controller:prod-deployment-average-1-9a2b81a4ad79 qosMeasuring:average slo:0.8]
W0210 17:17:29.941801       1 scheduler.go:134] [WaitForPodsOnCache] Pod prod-deployment-average-1-9a2b81a4ad79-8447964868-6npqb não encontrado no cache. Tentando novamente...
I0210 17:17:29.941861       1 scheduler.go:225] [OnAddPod] Adicionando pod default/prod-deployment-average-1-9a2b81a4ad79-8447964868-6npqb com os seguintes detalhes:
I0210 17:17:29.941891       1 types.go:751] [ControllerName] Verificando as anotações do pod default/prod-deployment-average-1-9a2b81a4ad79-8447964868-6npqb
I0210 17:17:29.941899       1 types.go:769] [ControllerName] Anotação 'controller' encontrada para o pod default/prod-deployment-average-1-9a2b81a4ad79-8447964868-6npqb: prod-deployment-average-1-9a2b81a4ad79
I0210 17:17:29.941907       1 scheduler.go:234] [OnAddPod] Atualizando métricas para o pod default/prod-deployment-average-1-9a2b81a4ad79-8447964868-6npqb
I0210 17:17:29.941911       1 types.go:751] [ControllerName] Verificando as anotações do pod default/prod-deployment-average-1-9a2b81a4ad79-8447964868-6npqb
I0210 17:17:29.941916       1 types.go:769] [ControllerName] Anotação 'controller' encontrada para o pod default/prod-deployment-average-1-9a2b81a4ad79-8447964868-6npqb: prod-deployment-average-1-9a2b81a4ad79
I0210 17:17:29.941927       1 scheduler.go:247] [OnAddPod] Pod default/prod-deployment-average-1-9a2b81a4ad79-8447964868-6npqb adicionado com sucesso
I0210 17:17:30.042096       1 scheduler.go:597] [GetControllerMetricInfo] Iniciando para o pod: default/prod-deployment-average-1-9a2b81a4ad79-8447964868-6npqb
I0210 17:17:30.042121       1 scheduler.go:602] [GetControllerMetricInfo] Obtendo o nome do controlador para o pod: default/prod-deployment-average-1-9a2b81a4ad79-8447964868-6npqb
I0210 17:17:30.042127       1 types.go:751] [ControllerName] Verificando as anotações do pod default/prod-deployment-average-1-9a2b81a4ad79-8447964868-6npqb
I0210 17:17:30.042133       1 types.go:769] [ControllerName] Anotação 'controller' encontrada para o pod default/prod-deployment-average-1-9a2b81a4ad79-8447964868-6npqb: prod-deployment-average-1-9a2b81a4ad79
I0210 17:17:30.042139       1 scheduler.go:605] [GetControllerMetricInfo] Métricas do controlador definidas para o pod: default/prod-deployment-average-1-9a2b81a4ad79-8447964868-6npqb
I0210 17:17:30.044251       1 scheduler.go:69] Estado no Informer: map[acceptablePreemptionOverhead:0.05 controller:prod-deployment-average-1-9a2b81a4ad79 qosMeasuring:average slo:0.8]
I0210 17:17:30.044278       1 scheduler.go:70] Estado real no cluster: map[acceptablePreemptionOverhead:0.05 controller:prod-deployment-average-1-9a2b81a4ad79 qosMeasuring:average slo:0.8]
I0210 17:17:30.044287       1 scheduler.go:138] [WaitForPodsOnCache] Pod prod-deployment-average-1-9a2b81a4ad79-8447964868-6npqb encontrado no cache.
I0210 17:17:30.044291       1 scheduler.go:116] [WaitForPodsOnCache] Verificando se o pod prod-deployment-average-2-77e788a61edf-5b7dd97cd5-zj78l está no cache...
I0210 17:17:30.044296       1 scheduler.go:597] [GetControllerMetricInfo] Iniciando para o pod: default/prod-deployment-average-2-77e788a61edf-5b7dd97cd5-zj78l
I0210 17:17:30.044300       1 scheduler.go:602] [GetControllerMetricInfo] Obtendo o nome do controlador para o pod: default/prod-deployment-average-2-77e788a61edf-5b7dd97cd5-zj78l
I0210 17:17:30.044305       1 types.go:751] [ControllerName] Verificando as anotações do pod default/prod-deployment-average-2-77e788a61edf-5b7dd97cd5-zj78l
I0210 17:17:30.044309       1 types.go:769] [ControllerName] Anotação 'controller' encontrada para o pod default/prod-deployment-average-2-77e788a61edf-5b7dd97cd5-zj78l: prod-deployment-average-2-77e788a61edf
I0210 17:17:30.044314       1 scheduler.go:605] [GetControllerMetricInfo] Métricas do controlador definidas para o pod: default/prod-deployment-average-2-77e788a61edf-5b7dd97cd5-zj78l
I0210 17:17:30.045849       1 scheduler.go:69] Estado no Informer: map[acceptablePreemptionOverhead:0.05 controller:prod-deployment-average-2-77e788a61edf qosMeasuring:average slo:0.8]
I0210 17:17:30.045870       1 scheduler.go:70] Estado real no cluster: map[acceptablePreemptionOverhead:0.05 controller:prod-deployment-average-2-77e788a61edf qosMeasuring:average slo:0.8]
I0210 17:17:30.045877       1 scheduler.go:138] [WaitForPodsOnCache] Pod prod-deployment-average-2-77e788a61edf-5b7dd97cd5-zj78l encontrado no cache.
I0210 17:17:30.045882       1 scheduler.go:597] [GetControllerMetricInfo] Iniciando para o pod: default/prod-deployment-average-1-9a2b81a4ad79-8447964868-6npqb
I0210 17:17:30.045887       1 scheduler.go:602] [GetControllerMetricInfo] Obtendo o nome do controlador para o pod: default/prod-deployment-average-1-9a2b81a4ad79-8447964868-6npqb
I0210 17:17:30.045891       1 types.go:751] [ControllerName] Verificando as anotações do pod default/prod-deployment-average-1-9a2b81a4ad79-8447964868-6npqb
I0210 17:17:30.045896       1 types.go:769] [ControllerName] Anotação 'controller' encontrada para o pod default/prod-deployment-average-1-9a2b81a4ad79-8447964868-6npqb: prod-deployment-average-1-9a2b81a4ad79
I0210 17:17:30.045901       1 scheduler.go:605] [GetControllerMetricInfo] Métricas do controlador definidas para o pod: default/prod-deployment-average-1-9a2b81a4ad79-8447964868-6npqb
I0210 17:17:30.045909       1 scheduler.go:597] [GetControllerMetricInfo] Iniciando para o pod: default/prod-deployment-average-2-77e788a61edf-5b7dd97cd5-zj78l
I0210 17:17:30.045914       1 scheduler.go:602] [GetControllerMetricInfo] Obtendo o nome do controlador para o pod: default/prod-deployment-average-2-77e788a61edf-5b7dd97cd5-zj78l
I0210 17:17:30.045918       1 types.go:751] [ControllerName] Verificando as anotações do pod default/prod-deployment-average-2-77e788a61edf-5b7dd97cd5-zj78l
I0210 17:17:30.045922       1 types.go:769] [ControllerName] Anotação 'controller' encontrada para o pod default/prod-deployment-average-2-77e788a61edf-5b7dd97cd5-zj78l: prod-deployment-average-2-77e788a61edf
I0210 17:17:30.045927       1 scheduler.go:605] [GetControllerMetricInfo] Métricas do controlador definidas para o pod: default/prod-deployment-average-2-77e788a61edf-5b7dd97cd5-zj78l
I0210 17:17:30.045934       1 types.go:546] [QoSMetric] qosMeasuringApproach: average
I0210 17:17:30.045940       1 types.go:532] [QoS DEBUG] effectiveRunning: 50.838781 | discardedRunning: 0.000000 | waiting: 1.017381 | binding: 0.005775 | denominator: 51.861936
I0210 17:17:30.045960       1 types.go:538] [QoS DEBUG] QoS calculado: 0.980272
I0210 17:17:30.045967       1 types.go:611] [COMPUTE QoS METRIC - AVERAGE] The pod prod-deployment-average-1-9a2b81a4ad79-8447964868-6npqb: availability 0.980272 | runtime 50.838781 | pendingTime 1.017381 | nRunning: 0 | nWaiting: 1 | residualContr 0 | estimatedOverhead 0.002887 | QoSMetric 11.683653
I0210 17:17:30.045975       1 types.go:546] [QoSMetric] qosMeasuringApproach: average
I0210 17:17:30.045981       1 types.go:532] [QoS DEBUG] effectiveRunning: 0.000000 | discardedRunning: 0.000000 | waiting: 50.936953 | binding: 0.000000 | denominator: 50.936953
I0210 17:17:30.045988       1 types.go:538] [QoS DEBUG] QoS calculado: 0.000000
I0210 17:17:30.045993       1 types.go:611] [COMPUTE QoS METRIC - AVERAGE] The pod prod-deployment-average-2-77e788a61edf-5b7dd97cd5-zj78l: availability 0.000000 | runtime 0.000000 | pendingTime 50.936953 | nRunning: 0 | nWaiting: 1 | residualContr 0 | estimatedOverhead 2.400000 | QoSMetric -53.336953
I0210 17:17:30.046003       1 scheduler.go:97] [HigherPrecedence] Métricas para prod-deployment-average-1-9a2b81a4ad79-8447964868-6npqb: QoS = 11.683653, Importância = 0.80
I0210 17:17:30.046019       1 scheduler.go:98] [HigherPrecedence] Métricas para prod-deployment-average-2-77e788a61edf-5b7dd97cd5-zj78l: QoS = -53.336953, Importância = 0.80
I0210 17:17:30.046026       1 scheduler.go:109] [HigherPrecedence] Decisão final: prod-deployment-average-1-9a2b81a4ad79-8447964868-6npqb tem precedência sobre prod-deployment-average-2-77e788a61edf-5b7dd97cd5-zj78l? false
I0210 17:17:30.046038       1 postFilter.go:812] [getLowerPrecedenceNominatedPods]Pod default/prod-deployment-average-1-9a2b81a4ad79-8447964868-6npqb não tem maior precedência que default/prod-deployment-average-2-77e788a61edf-5b7dd97cd5-zj78l, ignorando.
I0210 17:17:30.046044       1 postFilter.go:817] [getLowerPrecedenceNominatedPods]Total de pods de menor precedência encontrados: 0
I0210 17:17:30.046059       1 postFilter.go:189] [Preempt] Verificando pods de menor precedência no nó minikube que precisam ter o campo NominatedNodeName limpo
I0210 17:17:30.046082       1 postFilter.go:194] [Preempt] Limpando NominatedNodeName dos pods de menor precedência no nó minikube para evitar conflito com o pod default/prod-deployment-average-1-9a2b81a4ad79-8447964868-6npqb.
I0210 17:17:30.046096       1 postFilter.go:199] [Preempt] NominatedNodeName dos pods de menor precedência no nó minikube removido com sucesso.
I0210 17:17:30.046108       1 postFilter.go:202] [Preempt] Finalizado para o nó minikube. Pod default/prod-deployment-average-1-9a2b81a4ad79-8447964868-6npqb deve ser alocado agora.
I0210 17:17:30.046135       1 postFilter.go:49] [PostFilter] Nó nominado para o pod default/prod-deployment-average-1-9a2b81a4ad79-8447964868-6npqb: minikube
I0210 17:17:30.052741       1 scheduler.go:252] [OnUpdatePod] Iniciando processamento de atualização de pod
I0210 17:17:30.052801       1 scheduler.go:256] [OnUpdatePod] Pod atualizado detectado: default/prod-deployment-average-1-9a2b81a4ad79-8447964868-6npqb, Anotações: map[acceptablePreemptionOverhead:0.05 controller:prod-deployment-average-1-9a2b81a4ad79 qosMeasuring:average slo:0.8]
I0210 17:17:30.052821       1 scheduler.go:259] [OnUpdatePod] Comparando estado no Informer e estado real no cluster para o pod default/prod-deployment-average-1-9a2b81a4ad79-8447964868-6npqb
I0210 17:17:30.054645       1 scheduler.go:69] Estado no Informer: map[acceptablePreemptionOverhead:0.05 controller:prod-deployment-average-1-9a2b81a4ad79 qosMeasuring:average slo:0.8]
I0210 17:17:30.054665       1 scheduler.go:70] Estado real no cluster: map[acceptablePreemptionOverhead:0.05 controller:prod-deployment-average-1-9a2b81a4ad79 qosMeasuring:average slo:0.8]
I0210 17:17:30.054673       1 scheduler.go:269] [OnUpdatePod] Atualizando informações de métricas para o pod default/prod-deployment-average-1-9a2b81a4ad79-8447964868-6npqb
I0210 17:17:30.054679       1 types.go:751] [ControllerName] Verificando as anotações do pod default/prod-deployment-average-1-9a2b81a4ad79-8447964868-6npqb
I0210 17:17:30.054684       1 types.go:769] [ControllerName] Anotação 'controller' encontrada para o pod default/prod-deployment-average-1-9a2b81a4ad79-8447964868-6npqb: prod-deployment-average-1-9a2b81a4ad79
I0210 17:17:30.054692       1 scheduler.go:271] [OnUpdatePod] Atualizando 'LastStatus' do pod default/prod-deployment-average-1-9a2b81a4ad79-8447964868-6npqb nas métricas
I0210 17:17:30.054697       1 scheduler.go:273] [OnUpdatePod] Métrica atualizada para o pod default/prod-deployment-average-1-9a2b81a4ad79-8447964868-6npqb
I0210 17:17:30.054705       1 scheduler.go:277] [OnUpdatePod] Finalizando processamento de atualização de pod para default/prod-deployment-average-1-9a2b81a4ad79-8447964868-6npqb
I0210 17:17:34.925216       1 postFilter.go:210] [Preempt] Status do pod default/prod-deployment-average-2-77e788a61edf-5b7dd97cd5-zj78l após preempção: Pending
I0210 17:17:35.046755       1 postFilter.go:210] [Preempt] Status do pod default/prod-deployment-average-1-9a2b81a4ad79-8447964868-6npqb após preempção: Pending
I0210 17:17:38.032400       1 postFilter.go:29] [PostFilter] PostFilter chamado para pod: default/prod-deployment-average-2-77e788a61edf-5b7dd97cd5-zj78l
I0210 17:17:38.032424       1 postFilter.go:76] Comparando pod original com o atualizado...
I0210 17:17:38.032430       1 postFilter.go:83] Successfully retrieved updated pod default/prod-deployment-average-2-77e788a61edf-5b7dd97cd5-zj78l from lister
I0210 17:17:38.034444       1 postFilter.go:250] [compareNodeResources] Recursos calculados no nó minikube: CPU = 850 mCPU, Memória = 387973120 bytes
I0210 17:17:38.034472       1 postFilter.go:251] [compareNodeResources] Recursos do snapshot no nó minikube: CPU = 850 mCPU, Memória = 387973120 bytes
I0210 17:17:38.034480       1 postFilter.go:257] [compareNodeResources] Recursos de CPU do nó minikube estão sincronizados: 850 mCPU
I0210 17:17:38.034486       1 postFilter.go:263] [compareNodeResources] Recursos de memória do nó minikube estão sincronizados: 387973120 bytes
I0210 17:17:38.034496       1 postFilter.go:104] [Preempt] Verificando se é necessário limpar NominatedNodeName do pod default/prod-deployment-average-2-77e788a61edf-5b7dd97cd5-zj78l antes de continuar.
I0210 17:17:38.034868       1 postFilter.go:157] [PREEMPT CALL] The node minikube  was chosen to allocate pod prod-deployment-average-2-77e788a61edf-5b7dd97cd5-zj78l
I0210 17:17:38.034896       1 postFilter.go:161] [Preempt] Iniciando a remoção dos pods preemptados no nó minikube para alocar o pod default/prod-deployment-average-2-77e788a61edf-5b7dd97cd5-zj78l. Total de vítimas: 0
I0210 17:17:38.034908       1 postFilter.go:182] [Preempt] Total de pods preemptados no nó minikube: 0
I0210 17:17:38.034959       1 postFilter.go:801] [getLowerPrecedenceNominatedPods]Verificando pods nomeados para o nó: minikube
I0210 17:17:38.034986       1 postFilter.go:804] [getLowerPrecedenceNominatedPods]Comparando pod default/prod-deployment-average-2-77e788a61edf-5b7dd97cd5-zj78l com prioridade 824647246984 com pod default/prod-deployment-average-2-77e788a61edf-5b7dd97cd5-zj78l com prioridade 0
W0210 17:17:38.035314       1 scheduler.go:78] [HigherPrecedence] Tentativa de comparar o pod prod-deployment-average-2-77e788a61edf-5b7dd97cd5-zj78l consigo mesmo. Retornando false.
I0210 17:17:38.035362       1 postFilter.go:812] [getLowerPrecedenceNominatedPods]Pod default/prod-deployment-average-2-77e788a61edf-5b7dd97cd5-zj78l não tem maior precedência que default/prod-deployment-average-2-77e788a61edf-5b7dd97cd5-zj78l, ignorando.
I0210 17:17:38.035371       1 postFilter.go:804] [getLowerPrecedenceNominatedPods]Comparando pod default/prod-deployment-average-2-77e788a61edf-5b7dd97cd5-zj78l com prioridade 824647246984 com pod default/prod-deployment-average-1-9a2b81a4ad79-8447964868-6npqb com prioridade 824648615336
I0210 17:17:38.035384       1 scheduler.go:83] [HigherPrecedence] Calculando precedência entre prod-deployment-average-2-77e788a61edf-5b7dd97cd5-zj78l e prod-deployment-average-1-9a2b81a4ad79-8447964868-6npqb
I0210 17:17:38.035390       1 scheduler.go:116] [WaitForPodsOnCache] Verificando se o pod prod-deployment-average-2-77e788a61edf-5b7dd97cd5-zj78l está no cache...
I0210 17:17:38.035395       1 scheduler.go:597] [GetControllerMetricInfo] Iniciando para o pod: default/prod-deployment-average-2-77e788a61edf-5b7dd97cd5-zj78l
I0210 17:17:38.035400       1 scheduler.go:602] [GetControllerMetricInfo] Obtendo o nome do controlador para o pod: default/prod-deployment-average-2-77e788a61edf-5b7dd97cd5-zj78l
I0210 17:17:38.035406       1 types.go:751] [ControllerName] Verificando as anotações do pod default/prod-deployment-average-2-77e788a61edf-5b7dd97cd5-zj78l
I0210 17:17:38.035412       1 types.go:769] [ControllerName] Anotação 'controller' encontrada para o pod default/prod-deployment-average-2-77e788a61edf-5b7dd97cd5-zj78l: prod-deployment-average-2-77e788a61edf
I0210 17:17:38.035423       1 scheduler.go:605] [GetControllerMetricInfo] Métricas do controlador definidas para o pod: default/prod-deployment-average-2-77e788a61edf-5b7dd97cd5-zj78l
I0210 17:17:38.037428       1 scheduler.go:69] Estado no Informer: map[acceptablePreemptionOverhead:0.05 controller:prod-deployment-average-2-77e788a61edf qosMeasuring:average slo:0.8]
I0210 17:17:38.037467       1 scheduler.go:70] Estado real no cluster: map[acceptablePreemptionOverhead:0.05 controller:prod-deployment-average-2-77e788a61edf qosMeasuring:average slo:0.8]
I0210 17:17:38.037476       1 scheduler.go:138] [WaitForPodsOnCache] Pod prod-deployment-average-2-77e788a61edf-5b7dd97cd5-zj78l encontrado no cache.
I0210 17:17:38.037480       1 scheduler.go:116] [WaitForPodsOnCache] Verificando se o pod prod-deployment-average-1-9a2b81a4ad79-8447964868-6npqb está no cache...
I0210 17:17:38.037485       1 scheduler.go:597] [GetControllerMetricInfo] Iniciando para o pod: default/prod-deployment-average-1-9a2b81a4ad79-8447964868-6npqb
I0210 17:17:38.037489       1 scheduler.go:602] [GetControllerMetricInfo] Obtendo o nome do controlador para o pod: default/prod-deployment-average-1-9a2b81a4ad79-8447964868-6npqb
I0210 17:17:38.037493       1 types.go:751] [ControllerName] Verificando as anotações do pod default/prod-deployment-average-1-9a2b81a4ad79-8447964868-6npqb
I0210 17:17:38.037499       1 types.go:769] [ControllerName] Anotação 'controller' encontrada para o pod default/prod-deployment-average-1-9a2b81a4ad79-8447964868-6npqb: prod-deployment-average-1-9a2b81a4ad79
I0210 17:17:38.037505       1 scheduler.go:605] [GetControllerMetricInfo] Métricas do controlador definidas para o pod: default/prod-deployment-average-1-9a2b81a4ad79-8447964868-6npqb
I0210 17:17:38.038968       1 scheduler.go:69] Estado no Informer: map[acceptablePreemptionOverhead:0.05 controller:prod-deployment-average-1-9a2b81a4ad79 qosMeasuring:average slo:0.8]
I0210 17:17:38.039005       1 scheduler.go:70] Estado real no cluster: map[acceptablePreemptionOverhead:0.05 controller:prod-deployment-average-1-9a2b81a4ad79 qosMeasuring:average slo:0.8]
I0210 17:17:38.039012       1 scheduler.go:138] [WaitForPodsOnCache] Pod prod-deployment-average-1-9a2b81a4ad79-8447964868-6npqb encontrado no cache.
I0210 17:17:38.039017       1 scheduler.go:597] [GetControllerMetricInfo] Iniciando para o pod: default/prod-deployment-average-2-77e788a61edf-5b7dd97cd5-zj78l
I0210 17:17:38.039021       1 scheduler.go:602] [GetControllerMetricInfo] Obtendo o nome do controlador para o pod: default/prod-deployment-average-2-77e788a61edf-5b7dd97cd5-zj78l
I0210 17:17:38.039025       1 types.go:751] [ControllerName] Verificando as anotações do pod default/prod-deployment-average-2-77e788a61edf-5b7dd97cd5-zj78l
I0210 17:17:38.039030       1 types.go:769] [ControllerName] Anotação 'controller' encontrada para o pod default/prod-deployment-average-2-77e788a61edf-5b7dd97cd5-zj78l: prod-deployment-average-2-77e788a61edf
I0210 17:17:38.039035       1 scheduler.go:605] [GetControllerMetricInfo] Métricas do controlador definidas para o pod: default/prod-deployment-average-2-77e788a61edf-5b7dd97cd5-zj78l
I0210 17:17:38.039042       1 scheduler.go:597] [GetControllerMetricInfo] Iniciando para o pod: default/prod-deployment-average-1-9a2b81a4ad79-8447964868-6npqb
I0210 17:17:38.039047       1 scheduler.go:602] [GetControllerMetricInfo] Obtendo o nome do controlador para o pod: default/prod-deployment-average-1-9a2b81a4ad79-8447964868-6npqb
I0210 17:17:38.039050       1 types.go:751] [ControllerName] Verificando as anotações do pod default/prod-deployment-average-1-9a2b81a4ad79-8447964868-6npqb
I0210 17:17:38.039054       1 types.go:769] [ControllerName] Anotação 'controller' encontrada para o pod default/prod-deployment-average-1-9a2b81a4ad79-8447964868-6npqb: prod-deployment-average-1-9a2b81a4ad79
I0210 17:17:38.039057       1 scheduler.go:605] [GetControllerMetricInfo] Métricas do controlador definidas para o pod: default/prod-deployment-average-1-9a2b81a4ad79-8447964868-6npqb
I0210 17:17:38.039065       1 types.go:546] [QoSMetric] qosMeasuringApproach: average
I0210 17:17:38.039079       1 types.go:532] [QoS DEBUG] effectiveRunning: 0.000000 | discardedRunning: 0.000000 | waiting: 59.035380 | binding: 0.000000 | denominator: 59.035380
I0210 17:17:38.039087       1 types.go:538] [QoS DEBUG] QoS calculado: 0.000000
I0210 17:17:38.039092       1 types.go:611] [COMPUTE QoS METRIC - AVERAGE] The pod prod-deployment-average-2-77e788a61edf-5b7dd97cd5-zj78l: availability 0.000000 | runtime 0.000000 | pendingTime 59.035380 | nRunning: 0 | nWaiting: 1 | residualContr 0 | estimatedOverhead 2.400000 | QoSMetric -61.435380
I0210 17:17:38.039106       1 types.go:546] [QoSMetric] qosMeasuringApproach: average
I0210 17:17:38.039111       1 types.go:532] [QoS DEBUG] effectiveRunning: 50.838781 | discardedRunning: 0.000000 | waiting: 9.115808 | binding: 0.005775 | denominator: 59.960363
I0210 17:17:38.039116       1 types.go:538] [QoS DEBUG] QoS calculado: 0.847873
I0210 17:17:38.039122       1 types.go:611] [COMPUTE QoS METRIC - AVERAGE] The pod prod-deployment-average-1-9a2b81a4ad79-8447964868-6npqb: availability 0.847873 | runtime 50.838781 | pendingTime 9.115808 | nRunning: 0 | nWaiting: 1 | residualContr 0 | estimatedOverhead 0.002887 | QoSMetric 3.585225
I0210 17:17:38.039136       1 scheduler.go:97] [HigherPrecedence] Métricas para prod-deployment-average-2-77e788a61edf-5b7dd97cd5-zj78l: QoS = -61.435380, Importância = 0.80
I0210 17:17:38.039142       1 scheduler.go:98] [HigherPrecedence] Métricas para prod-deployment-average-1-9a2b81a4ad79-8447964868-6npqb: QoS = 3.585225, Importância = 0.80
I0210 17:17:38.039147       1 scheduler.go:109] [HigherPrecedence] Decisão final: prod-deployment-average-2-77e788a61edf-5b7dd97cd5-zj78l tem precedência sobre prod-deployment-average-1-9a2b81a4ad79-8447964868-6npqb? true
I0210 17:17:38.039154       1 postFilter.go:808] [getLowerPrecedenceNominatedPods]Pod default/prod-deployment-average-2-77e788a61edf-5b7dd97cd5-zj78l tem maior precedência que default/prod-deployment-average-1-9a2b81a4ad79-8447964868-6npqb, adicionando à lista.
I0210 17:17:38.039160       1 postFilter.go:817] [getLowerPrecedenceNominatedPods]Total de pods de menor precedência encontrados: 1
I0210 17:17:38.039209       1 postFilter.go:189] [Preempt] Verificando pods de menor precedência no nó minikube que precisam ter o campo NominatedNodeName limpo
I0210 17:17:38.039228       1 postFilter.go:191] [Preempt] Limpando o campo NominatedNodeName do pod default/prod-deployment-average-1-9a2b81a4ad79-8447964868-6npqb
I0210 17:17:38.039237       1 postFilter.go:194] [Preempt] Limpando NominatedNodeName dos pods de menor precedência no nó minikube para evitar conflito com o pod default/prod-deployment-average-2-77e788a61edf-5b7dd97cd5-zj78l.
I0210 17:17:38.043908       1 postFilter.go:199] [Preempt] NominatedNodeName dos pods de menor precedência no nó minikube removido com sucesso.
I0210 17:17:38.043939       1 postFilter.go:202] [Preempt] Finalizado para o nó minikube. Pod default/prod-deployment-average-2-77e788a61edf-5b7dd97cd5-zj78l deve ser alocado agora.
I0210 17:17:38.043934       1 scheduler.go:252] [OnUpdatePod] Iniciando processamento de atualização de pod
I0210 17:17:38.043950       1 postFilter.go:49] [PostFilter] Nó nominado para o pod default/prod-deployment-average-2-77e788a61edf-5b7dd97cd5-zj78l: minikube
I0210 17:17:38.043972       1 scheduler.go:256] [OnUpdatePod] Pod atualizado detectado: default/prod-deployment-average-1-9a2b81a4ad79-8447964868-6npqb, Anotações: map[acceptablePreemptionOverhead:0.05 controller:prod-deployment-average-1-9a2b81a4ad79 qosMeasuring:average slo:0.8]
I0210 17:17:38.043988       1 scheduler.go:259] [OnUpdatePod] Comparando estado no Informer e estado real no cluster para o pod default/prod-deployment-average-1-9a2b81a4ad79-8447964868-6npqb
I0210 17:17:38.045827       1 scheduler.go:69] Estado no Informer: map[acceptablePreemptionOverhead:0.05 controller:prod-deployment-average-1-9a2b81a4ad79 qosMeasuring:average slo:0.8]
I0210 17:17:38.045863       1 scheduler.go:70] Estado real no cluster: map[acceptablePreemptionOverhead:0.05 controller:prod-deployment-average-1-9a2b81a4ad79 qosMeasuring:average slo:0.8]
I0210 17:17:38.045874       1 scheduler.go:269] [OnUpdatePod] Atualizando informações de métricas para o pod default/prod-deployment-average-1-9a2b81a4ad79-8447964868-6npqb
I0210 17:17:38.045880       1 types.go:751] [ControllerName] Verificando as anotações do pod default/prod-deployment-average-1-9a2b81a4ad79-8447964868-6npqb
I0210 17:17:38.045885       1 types.go:769] [ControllerName] Anotação 'controller' encontrada para o pod default/prod-deployment-average-1-9a2b81a4ad79-8447964868-6npqb: prod-deployment-average-1-9a2b81a4ad79
I0210 17:17:38.045891       1 scheduler.go:271] [OnUpdatePod] Atualizando 'LastStatus' do pod default/prod-deployment-average-1-9a2b81a4ad79-8447964868-6npqb nas métricas
I0210 17:17:38.045894       1 scheduler.go:273] [OnUpdatePod] Métrica atualizada para o pod default/prod-deployment-average-1-9a2b81a4ad79-8447964868-6npqb
I0210 17:17:38.045900       1 scheduler.go:277] [OnUpdatePod] Finalizando processamento de atualização de pod para default/prod-deployment-average-1-9a2b81a4ad79-8447964868-6npqb
I0210 17:17:43.044939       1 postFilter.go:210] [Preempt] Status do pod default/prod-deployment-average-2-77e788a61edf-5b7dd97cd5-zj78l após preempção: Pending
I0210 17:17:59.906406       1 scheduler.go:53] [QueueSort] Comparando prioridade de prod-deployment-average-2-77e788a61edf-5b7dd97cd5-zj78l com prod-deployment-average-1-9a2b81a4ad79-8447964868-6npqb
I0210 17:17:59.906429       1 scheduler.go:83] [HigherPrecedence] Calculando precedência entre prod-deployment-average-2-77e788a61edf-5b7dd97cd5-zj78l e prod-deployment-average-1-9a2b81a4ad79-8447964868-6npqb
I0210 17:17:59.906433       1 scheduler.go:116] [WaitForPodsOnCache] Verificando se o pod prod-deployment-average-2-77e788a61edf-5b7dd97cd5-zj78l está no cache...
I0210 17:17:59.906437       1 scheduler.go:597] [GetControllerMetricInfo] Iniciando para o pod: default/prod-deployment-average-2-77e788a61edf-5b7dd97cd5-zj78l
I0210 17:17:59.906444       1 scheduler.go:602] [GetControllerMetricInfo] Obtendo o nome do controlador para o pod: default/prod-deployment-average-2-77e788a61edf-5b7dd97cd5-zj78l
I0210 17:17:59.906448       1 types.go:751] [ControllerName] Verificando as anotações do pod default/prod-deployment-average-2-77e788a61edf-5b7dd97cd5-zj78l
I0210 17:17:59.906453       1 types.go:769] [ControllerName] Anotação 'controller' encontrada para o pod default/prod-deployment-average-2-77e788a61edf-5b7dd97cd5-zj78l: prod-deployment-average-2-77e788a61edf
I0210 17:17:59.906458       1 scheduler.go:605] [GetControllerMetricInfo] Métricas do controlador definidas para o pod: default/prod-deployment-average-2-77e788a61edf-5b7dd97cd5-zj78l
I0210 17:17:59.908422       1 scheduler.go:69] Estado no Informer: map[acceptablePreemptionOverhead:0.05 controller:prod-deployment-average-2-77e788a61edf qosMeasuring:average slo:0.8]
I0210 17:17:59.908447       1 scheduler.go:70] Estado real no cluster: map[acceptablePreemptionOverhead:0.05 controller:prod-deployment-average-2-77e788a61edf qosMeasuring:average slo:0.8]
I0210 17:17:59.908455       1 scheduler.go:138] [WaitForPodsOnCache] Pod prod-deployment-average-2-77e788a61edf-5b7dd97cd5-zj78l encontrado no cache.
I0210 17:17:59.908461       1 scheduler.go:116] [WaitForPodsOnCache] Verificando se o pod prod-deployment-average-1-9a2b81a4ad79-8447964868-6npqb está no cache...
I0210 17:17:59.908465       1 scheduler.go:597] [GetControllerMetricInfo] Iniciando para o pod: default/prod-deployment-average-1-9a2b81a4ad79-8447964868-6npqb
I0210 17:17:59.908470       1 scheduler.go:602] [GetControllerMetricInfo] Obtendo o nome do controlador para o pod: default/prod-deployment-average-1-9a2b81a4ad79-8447964868-6npqb
I0210 17:17:59.908474       1 types.go:751] [ControllerName] Verificando as anotações do pod default/prod-deployment-average-1-9a2b81a4ad79-8447964868-6npqb
I0210 17:17:59.908480       1 types.go:769] [ControllerName] Anotação 'controller' encontrada para o pod default/prod-deployment-average-1-9a2b81a4ad79-8447964868-6npqb: prod-deployment-average-1-9a2b81a4ad79
I0210 17:17:59.908485       1 scheduler.go:605] [GetControllerMetricInfo] Métricas do controlador definidas para o pod: default/prod-deployment-average-1-9a2b81a4ad79-8447964868-6npqb
I0210 17:17:59.910324       1 scheduler.go:69] Estado no Informer: map[acceptablePreemptionOverhead:0.05 controller:prod-deployment-average-1-9a2b81a4ad79 qosMeasuring:average slo:0.8]
I0210 17:17:59.910348       1 scheduler.go:70] Estado real no cluster: map[acceptablePreemptionOverhead:0.05 controller:prod-deployment-average-1-9a2b81a4ad79 qosMeasuring:average slo:0.8]
I0210 17:17:59.910354       1 scheduler.go:138] [WaitForPodsOnCache] Pod prod-deployment-average-1-9a2b81a4ad79-8447964868-6npqb encontrado no cache.
I0210 17:17:59.910358       1 scheduler.go:597] [GetControllerMetricInfo] Iniciando para o pod: default/prod-deployment-average-2-77e788a61edf-5b7dd97cd5-zj78l
I0210 17:17:59.910361       1 scheduler.go:602] [GetControllerMetricInfo] Obtendo o nome do controlador para o pod: default/prod-deployment-average-2-77e788a61edf-5b7dd97cd5-zj78l
I0210 17:17:59.910365       1 types.go:751] [ControllerName] Verificando as anotações do pod default/prod-deployment-average-2-77e788a61edf-5b7dd97cd5-zj78l
I0210 17:17:59.910369       1 types.go:769] [ControllerName] Anotação 'controller' encontrada para o pod default/prod-deployment-average-2-77e788a61edf-5b7dd97cd5-zj78l: prod-deployment-average-2-77e788a61edf
I0210 17:17:59.910373       1 scheduler.go:605] [GetControllerMetricInfo] Métricas do controlador definidas para o pod: default/prod-deployment-average-2-77e788a61edf-5b7dd97cd5-zj78l
I0210 17:17:59.910378       1 scheduler.go:597] [GetControllerMetricInfo] Iniciando para o pod: default/prod-deployment-average-1-9a2b81a4ad79-8447964868-6npqb
I0210 17:17:59.910382       1 scheduler.go:602] [GetControllerMetricInfo] Obtendo o nome do controlador para o pod: default/prod-deployment-average-1-9a2b81a4ad79-8447964868-6npqb
I0210 17:17:59.910384       1 types.go:751] [ControllerName] Verificando as anotações do pod default/prod-deployment-average-1-9a2b81a4ad79-8447964868-6npqb
I0210 17:17:59.910388       1 types.go:769] [ControllerName] Anotação 'controller' encontrada para o pod default/prod-deployment-average-1-9a2b81a4ad79-8447964868-6npqb: prod-deployment-average-1-9a2b81a4ad79
I0210 17:17:59.910391       1 scheduler.go:605] [GetControllerMetricInfo] Métricas do controlador definidas para o pod: default/prod-deployment-average-1-9a2b81a4ad79-8447964868-6npqb
I0210 17:17:59.910397       1 types.go:546] [QoSMetric] qosMeasuringApproach: average
I0210 17:17:59.910402       1 types.go:532] [QoS DEBUG] effectiveRunning: 0.000000 | discardedRunning: 0.000000 | waiting: 80.906427 | binding: 0.000000 | denominator: 80.906427
I0210 17:17:59.910416       1 types.go:538] [QoS DEBUG] QoS calculado: 0.000000
I0210 17:17:59.910421       1 types.go:611] [COMPUTE QoS METRIC - AVERAGE] The pod prod-deployment-average-2-77e788a61edf-5b7dd97cd5-zj78l: availability 0.000000 | runtime 0.000000 | pendingTime 80.906427 | nRunning: 0 | nWaiting: 1 | residualContr 0 | estimatedOverhead 2.400000 | QoSMetric -83.306427
I0210 17:17:59.910429       1 types.go:546] [QoSMetric] qosMeasuringApproach: average
I0210 17:17:59.910434       1 types.go:532] [QoS DEBUG] effectiveRunning: 50.838781 | discardedRunning: 0.000000 | waiting: 30.986854 | binding: 0.005775 | denominator: 81.831410
I0210 17:17:59.910441       1 types.go:538] [QoS DEBUG] QoS calculado: 0.621262
I0210 17:17:59.910445       1 types.go:611] [COMPUTE QoS METRIC - AVERAGE] The pod prod-deployment-average-1-9a2b81a4ad79-8447964868-6npqb: availability 0.621262 | runtime 50.838781 | pendingTime 30.986854 | nRunning: 0 | nWaiting: 1 | residualContr 0 | estimatedOverhead 0.002887 | QoSMetric -18.285821
I0210 17:17:59.910453       1 scheduler.go:97] [HigherPrecedence] Métricas para prod-deployment-average-2-77e788a61edf-5b7dd97cd5-zj78l: QoS = -83.306427, Importância = 0.80
I0210 17:17:59.910458       1 scheduler.go:98] [HigherPrecedence] Métricas para prod-deployment-average-1-9a2b81a4ad79-8447964868-6npqb: QoS = -18.285821, Importância = 0.80
I0210 17:17:59.910463       1 scheduler.go:109] [HigherPrecedence] Decisão final: prod-deployment-average-2-77e788a61edf-5b7dd97cd5-zj78l tem precedência sobre prod-deployment-average-1-9a2b81a4ad79-8447964868-6npqb? true
I0210 17:17:59.910468       1 scheduler.go:59] [QueueSort] Precedência determinada: prod-deployment-average-2-77e788a61edf-5b7dd97cd5-zj78l tem precedência sobre prod-deployment-average-1-9a2b81a4ad79-8447964868-6npqb? true
I0210 17:17:59.910631       1 scheduler.go:145] [Reserve] resources reserved at node minikube for pod prod-deployment-average-2-77e788a61edf-5b7dd97cd5-zj78l_default at 2025-02-10 17:17:59.910626551 +0000 UTC m=+210.838364105
I0210 17:17:59.910649       1 types.go:751] [ControllerName] Verificando as anotações do pod default/prod-deployment-average-2-77e788a61edf-5b7dd97cd5-zj78l
I0210 17:17:59.910652       1 types.go:769] [ControllerName] Anotação 'controller' encontrada para o pod default/prod-deployment-average-2-77e788a61edf-5b7dd97cd5-zj78l: prod-deployment-average-2-77e788a61edf
I0210 17:17:59.910657       1 scheduler.go:147] [Reserve] Status de alocação atual para o pod prod-deployment-average-2-77e788a61edf-5b7dd97cd5-zj78l_default: 
I0210 17:17:59.910660       1 scheduler.go:149] [Reserve] Status de alocação atualizado para o pod prod-deployment-average-2-77e788a61edf-5b7dd97cd5-zj78l_default: allocating
I0210 17:17:59.910716       1 postFilter.go:29] [PostFilter] PostFilter chamado para pod: default/prod-deployment-average-1-9a2b81a4ad79-8447964868-6npqb
I0210 17:17:59.910730       1 postFilter.go:76] Comparando pod original com o atualizado...
I0210 17:17:59.910735       1 postFilter.go:83] Successfully retrieved updated pod default/prod-deployment-average-1-9a2b81a4ad79-8447964868-6npqb from lister
I0210 17:17:59.910799       1 scheduler.go:173] [PreBind] Validando o pod prod-deployment-average-2-77e788a61edf-5b7dd97cd5-zj78l antes de vincular ao node minikube
I0210 17:17:59.912521       1 postFilter.go:250] [compareNodeResources] Recursos calculados no nó minikube: CPU = 8850 mCPU, Memória = 490373120 bytes
I0210 17:17:59.912542       1 postFilter.go:251] [compareNodeResources] Recursos do snapshot no nó minikube: CPU = 8850 mCPU, Memória = 490373120 bytes
I0210 17:17:59.912547       1 postFilter.go:257] [compareNodeResources] Recursos de CPU do nó minikube estão sincronizados: 8850 mCPU
I0210 17:17:59.912551       1 postFilter.go:263] [compareNodeResources] Recursos de memória do nó minikube estão sincronizados: 490373120 bytes
I0210 17:17:59.912558       1 postFilter.go:104] [Preempt] Verificando se é necessário limpar NominatedNodeName do pod default/prod-deployment-average-1-9a2b81a4ad79-8447964868-6npqb antes de continuar.
I0210 17:17:59.912640       1 scheduler.go:597] [GetControllerMetricInfo] Iniciando para o pod: default/prod-deployment-average-2-77e788a61edf-5b7dd97cd5-zj78l
I0210 17:17:59.912652       1 scheduler.go:602] [GetControllerMetricInfo] Obtendo o nome do controlador para o pod: default/prod-deployment-average-2-77e788a61edf-5b7dd97cd5-zj78l
I0210 17:17:59.912656       1 types.go:751] [ControllerName] Verificando as anotações do pod default/prod-deployment-average-2-77e788a61edf-5b7dd97cd5-zj78l
I0210 17:17:59.912660       1 types.go:769] [ControllerName] Anotação 'controller' encontrada para o pod default/prod-deployment-average-2-77e788a61edf-5b7dd97cd5-zj78l: prod-deployment-average-2-77e788a61edf
I0210 17:17:59.912665       1 scheduler.go:605] [GetControllerMetricInfo] Métricas do controlador definidas para o pod: default/prod-deployment-average-2-77e788a61edf-5b7dd97cd5-zj78l
I0210 17:17:59.912669       1 scheduler.go:83] [HigherPrecedence] Calculando precedência entre prod-deployment-average-1-9a2b81a4ad79-8447964868-6npqb e prod-deployment-average-2-77e788a61edf-5b7dd97cd5-zj78l
I0210 17:17:59.912673       1 scheduler.go:116] [WaitForPodsOnCache] Verificando se o pod prod-deployment-average-1-9a2b81a4ad79-8447964868-6npqb está no cache...
I0210 17:17:59.912676       1 scheduler.go:597] [GetControllerMetricInfo] Iniciando para o pod: default/prod-deployment-average-1-9a2b81a4ad79-8447964868-6npqb
I0210 17:17:59.912679       1 scheduler.go:602] [GetControllerMetricInfo] Obtendo o nome do controlador para o pod: default/prod-deployment-average-1-9a2b81a4ad79-8447964868-6npqb
I0210 17:17:59.912682       1 types.go:751] [ControllerName] Verificando as anotações do pod default/prod-deployment-average-1-9a2b81a4ad79-8447964868-6npqb
I0210 17:17:59.912685       1 types.go:769] [ControllerName] Anotação 'controller' encontrada para o pod default/prod-deployment-average-1-9a2b81a4ad79-8447964868-6npqb: prod-deployment-average-1-9a2b81a4ad79
I0210 17:17:59.912690       1 scheduler.go:605] [GetControllerMetricInfo] Métricas do controlador definidas para o pod: default/prod-deployment-average-1-9a2b81a4ad79-8447964868-6npqb
I0210 17:17:59.916363       1 scheduler.go:69] Estado no Informer: map[acceptablePreemptionOverhead:0.05 controller:prod-deployment-average-1-9a2b81a4ad79 qosMeasuring:average slo:0.8]
I0210 17:17:59.916391       1 scheduler.go:70] Estado real no cluster: map[acceptablePreemptionOverhead:0.05 controller:prod-deployment-average-1-9a2b81a4ad79 qosMeasuring:average slo:0.8]
I0210 17:17:59.916399       1 scheduler.go:138] [WaitForPodsOnCache] Pod prod-deployment-average-1-9a2b81a4ad79-8447964868-6npqb encontrado no cache.
I0210 17:17:59.916404       1 scheduler.go:116] [WaitForPodsOnCache] Verificando se o pod prod-deployment-average-2-77e788a61edf-5b7dd97cd5-zj78l está no cache...
I0210 17:17:59.916408       1 scheduler.go:597] [GetControllerMetricInfo] Iniciando para o pod: default/prod-deployment-average-2-77e788a61edf-5b7dd97cd5-zj78l
I0210 17:17:59.916412       1 scheduler.go:602] [GetControllerMetricInfo] Obtendo o nome do controlador para o pod: default/prod-deployment-average-2-77e788a61edf-5b7dd97cd5-zj78l
I0210 17:17:59.916412       1 scheduler.go:181] [PostBind] Chamado para pod prod-deployment-average-2-77e788a61edf-5b7dd97cd5-zj78l
I0210 17:17:59.916417       1 types.go:751] [ControllerName] Verificando as anotações do pod default/prod-deployment-average-2-77e788a61edf-5b7dd97cd5-zj78l
I0210 17:17:59.916423       1 types.go:769] [ControllerName] Anotação 'controller' encontrada para o pod default/prod-deployment-average-2-77e788a61edf-5b7dd97cd5-zj78l: prod-deployment-average-2-77e788a61edf
I0210 17:17:59.916427       1 scheduler.go:605] [GetControllerMetricInfo] Métricas do controlador definidas para o pod: default/prod-deployment-average-2-77e788a61edf-5b7dd97cd5-zj78l
I0210 17:17:59.916423       1 scheduler.go:199] [PostBind] Pod prod-deployment-average-2-77e788a61edf-5b7dd97cd5-zj78l - Início do binding: 2025-02-10 17:17:59.910820624 +0000 UTC m=+210.838558178, Fim do binding: 2025-02-10 17:17:59.916420199 +0000 UTC m=+210.844157753
I0210 17:17:59.916630       1 scheduler.go:252] [OnUpdatePod] Iniciando processamento de atualização de pod
I0210 17:17:59.916675       1 scheduler.go:256] [OnUpdatePod] Pod atualizado detectado: default/prod-deployment-average-2-77e788a61edf-5b7dd97cd5-zj78l, Anotações: map[acceptablePreemptionOverhead:0.05 controller:prod-deployment-average-2-77e788a61edf qosMeasuring:average slo:0.8]
I0210 17:17:59.916706       1 scheduler.go:259] [OnUpdatePod] Comparando estado no Informer e estado real no cluster para o pod default/prod-deployment-average-2-77e788a61edf-5b7dd97cd5-zj78l
I0210 17:17:59.918586       1 scheduler.go:69] Estado no Informer: map[acceptablePreemptionOverhead:0.05 controller:prod-deployment-average-2-77e788a61edf qosMeasuring:average slo:0.8]
I0210 17:17:59.918606       1 scheduler.go:70] Estado real no cluster: map[acceptablePreemptionOverhead:0.05 controller:prod-deployment-average-2-77e788a61edf qosMeasuring:average slo:0.8]
I0210 17:17:59.918616       1 scheduler.go:269] [OnUpdatePod] Atualizando informações de métricas para o pod default/prod-deployment-average-2-77e788a61edf-5b7dd97cd5-zj78l
I0210 17:17:59.918686       1 scheduler.go:69] Estado no Informer: map[acceptablePreemptionOverhead:0.05 controller:prod-deployment-average-2-77e788a61edf qosMeasuring:average slo:0.8]
I0210 17:17:59.918710       1 scheduler.go:70] Estado real no cluster: map[acceptablePreemptionOverhead:0.05 controller:prod-deployment-average-2-77e788a61edf qosMeasuring:average slo:0.8]
I0210 17:17:59.918729       1 scheduler.go:138] [WaitForPodsOnCache] Pod prod-deployment-average-2-77e788a61edf-5b7dd97cd5-zj78l encontrado no cache.
I0210 17:17:59.918742       1 scheduler.go:597] [GetControllerMetricInfo] Iniciando para o pod: default/prod-deployment-average-1-9a2b81a4ad79-8447964868-6npqb
I0210 17:17:59.918769       1 types.go:751] [ControllerName] Verificando as anotações do pod default/prod-deployment-average-2-77e788a61edf-5b7dd97cd5-zj78l
I0210 17:17:59.918787       1 types.go:769] [ControllerName] Anotação 'controller' encontrada para o pod default/prod-deployment-average-2-77e788a61edf-5b7dd97cd5-zj78l: prod-deployment-average-2-77e788a61edf
I0210 17:17:59.918794       1 scheduler.go:206] [PostBind] Métricas atualizadas para o pod prod-deployment-average-2-77e788a61edf-5b7dd97cd5-zj78l
I0210 17:17:59.918827       1 scheduler.go:602] [GetControllerMetricInfo] Obtendo o nome do controlador para o pod: default/prod-deployment-average-1-9a2b81a4ad79-8447964868-6npqb
I0210 17:17:59.918834       1 types.go:751] [ControllerName] Verificando as anotações do pod default/prod-deployment-average-1-9a2b81a4ad79-8447964868-6npqb
I0210 17:17:59.918838       1 types.go:769] [ControllerName] Anotação 'controller' encontrada para o pod default/prod-deployment-average-1-9a2b81a4ad79-8447964868-6npqb: prod-deployment-average-1-9a2b81a4ad79
I0210 17:17:59.918843       1 scheduler.go:605] [GetControllerMetricInfo] Métricas do controlador definidas para o pod: default/prod-deployment-average-1-9a2b81a4ad79-8447964868-6npqb
I0210 17:17:59.918861       1 types.go:751] [ControllerName] Verificando as anotações do pod default/prod-deployment-average-2-77e788a61edf-5b7dd97cd5-zj78l
I0210 17:17:59.918874       1 types.go:769] [ControllerName] Anotação 'controller' encontrada para o pod default/prod-deployment-average-2-77e788a61edf-5b7dd97cd5-zj78l: prod-deployment-average-2-77e788a61edf
I0210 17:17:59.918879       1 scheduler.go:271] [OnUpdatePod] Atualizando 'LastStatus' do pod default/prod-deployment-average-2-77e788a61edf-5b7dd97cd5-zj78l nas métricas
I0210 17:17:59.918883       1 scheduler.go:273] [OnUpdatePod] Métrica atualizada para o pod default/prod-deployment-average-2-77e788a61edf-5b7dd97cd5-zj78l
I0210 17:17:59.918898       1 scheduler.go:277] [OnUpdatePod] Finalizando processamento de atualização de pod para default/prod-deployment-average-2-77e788a61edf-5b7dd97cd5-zj78l
I0210 17:17:59.918915       1 scheduler.go:597] [GetControllerMetricInfo] Iniciando para o pod: default/prod-deployment-average-2-77e788a61edf-5b7dd97cd5-zj78l
I0210 17:17:59.918920       1 scheduler.go:602] [GetControllerMetricInfo] Obtendo o nome do controlador para o pod: default/prod-deployment-average-2-77e788a61edf-5b7dd97cd5-zj78l
I0210 17:17:59.918924       1 types.go:751] [ControllerName] Verificando as anotações do pod default/prod-deployment-average-2-77e788a61edf-5b7dd97cd5-zj78l
I0210 17:17:59.918928       1 types.go:769] [ControllerName] Anotação 'controller' encontrada para o pod default/prod-deployment-average-2-77e788a61edf-5b7dd97cd5-zj78l: prod-deployment-average-2-77e788a61edf
I0210 17:17:59.918933       1 scheduler.go:605] [GetControllerMetricInfo] Métricas do controlador definidas para o pod: default/prod-deployment-average-2-77e788a61edf-5b7dd97cd5-zj78l
I0210 17:17:59.918942       1 types.go:546] [QoSMetric] qosMeasuringApproach: average
I0210 17:17:59.918955       1 types.go:532] [QoS DEBUG] effectiveRunning: 50.838781 | discardedRunning: 0.000000 | waiting: 30.993095 | binding: 0.005775 | denominator: 81.837650
I0210 17:17:59.918964       1 types.go:538] [QoS DEBUG] QoS calculado: 0.621215
I0210 17:17:59.918971       1 types.go:611] [COMPUTE QoS METRIC - AVERAGE] The pod prod-deployment-average-1-9a2b81a4ad79-8447964868-6npqb: availability 0.621215 | runtime 50.838781 | pendingTime 30.993095 | nRunning: 0 | nWaiting: 1 | residualContr 0 | estimatedOverhead 0.002887 | QoSMetric -18.292062
I0210 17:17:59.918987       1 types.go:546] [QoSMetric] qosMeasuringApproach: average
I0210 17:17:59.918992       1 types.go:532] [QoS DEBUG] effectiveRunning: -0.003753 | discardedRunning: 0.000000 | waiting: 80.910821 | binding: 0.005600 | denominator: 80.912667
I0210 17:17:59.919000       1 types.go:538] [QoS DEBUG] QoS calculado: -0.000046
I0210 17:17:59.919005       1 types.go:611] [COMPUTE QoS METRIC - AVERAGE] The pod prod-deployment-average-2-77e788a61edf-5b7dd97cd5-zj78l: availability -0.000046 | runtime -0.003753 | pendingTime 80.910821 | nRunning: 1 | nWaiting: 0 | residualContr 1 | estimatedOverhead 0.005600 | QoSMetric -80.922958
I0210 17:17:59.919013       1 scheduler.go:97] [HigherPrecedence] Métricas para prod-deployment-average-1-9a2b81a4ad79-8447964868-6npqb: QoS = -18.292062, Importância = 0.80
I0210 17:17:59.919022       1 scheduler.go:98] [HigherPrecedence] Métricas para prod-deployment-average-2-77e788a61edf-5b7dd97cd5-zj78l: QoS = -80.922958, Importância = 0.80
I0210 17:17:59.919028       1 scheduler.go:109] [HigherPrecedence] Decisão final: prod-deployment-average-1-9a2b81a4ad79-8447964868-6npqb tem precedência sobre prod-deployment-average-2-77e788a61edf-5b7dd97cd5-zj78l? false
I0210 17:17:59.919068       1 postFilter.go:154] [PREEMPT CALL] No node was chosen to allocate pod prod-deployment-average-1-9a2b81a4ad79-8447964868-6npqb
W0210 17:17:59.919074       1 postFilter.go:45] [PostFilter] Nenhum nó nominado após a preempção para o pod: default/prod-deployment-average-1-9a2b81a4ad79-8447964868-6npqb
I0210 17:17:59.929318       1 scheduler.go:252] [OnUpdatePod] Iniciando processamento de atualização de pod
I0210 17:17:59.929373       1 scheduler.go:256] [OnUpdatePod] Pod atualizado detectado: default/prod-deployment-average-2-77e788a61edf-5b7dd97cd5-zj78l, Anotações: map[acceptablePreemptionOverhead:0.05 controller:prod-deployment-average-2-77e788a61edf qosMeasuring:average slo:0.8]
I0210 17:17:59.929392       1 scheduler.go:259] [OnUpdatePod] Comparando estado no Informer e estado real no cluster para o pod default/prod-deployment-average-2-77e788a61edf-5b7dd97cd5-zj78l
I0210 17:17:59.931649       1 scheduler.go:69] Estado no Informer: map[acceptablePreemptionOverhead:0.05 controller:prod-deployment-average-2-77e788a61edf qosMeasuring:average slo:0.8]
I0210 17:17:59.931672       1 scheduler.go:70] Estado real no cluster: map[acceptablePreemptionOverhead:0.05 controller:prod-deployment-average-2-77e788a61edf qosMeasuring:average slo:0.8]
I0210 17:17:59.931679       1 scheduler.go:269] [OnUpdatePod] Atualizando informações de métricas para o pod default/prod-deployment-average-2-77e788a61edf-5b7dd97cd5-zj78l
I0210 17:17:59.931684       1 types.go:751] [ControllerName] Verificando as anotações do pod default/prod-deployment-average-2-77e788a61edf-5b7dd97cd5-zj78l
I0210 17:17:59.931688       1 types.go:769] [ControllerName] Anotação 'controller' encontrada para o pod default/prod-deployment-average-2-77e788a61edf-5b7dd97cd5-zj78l: prod-deployment-average-2-77e788a61edf
I0210 17:17:59.931695       1 scheduler.go:271] [OnUpdatePod] Atualizando 'LastStatus' do pod default/prod-deployment-average-2-77e788a61edf-5b7dd97cd5-zj78l nas métricas
I0210 17:17:59.931698       1 scheduler.go:273] [OnUpdatePod] Métrica atualizada para o pod default/prod-deployment-average-2-77e788a61edf-5b7dd97cd5-zj78l
I0210 17:17:59.931704       1 scheduler.go:277] [OnUpdatePod] Finalizando processamento de atualização de pod para default/prod-deployment-average-2-77e788a61edf-5b7dd97cd5-zj78l
I0210 17:18:01.437577       1 scheduler.go:252] [OnUpdatePod] Iniciando processamento de atualização de pod
I0210 17:18:01.437632       1 scheduler.go:256] [OnUpdatePod] Pod atualizado detectado: default/prod-deployment-average-2-77e788a61edf-5b7dd97cd5-zj78l, Anotações: map[acceptablePreemptionOverhead:0.05 controller:prod-deployment-average-2-77e788a61edf qosMeasuring:average slo:0.8]
I0210 17:18:01.437648       1 scheduler.go:259] [OnUpdatePod] Comparando estado no Informer e estado real no cluster para o pod default/prod-deployment-average-2-77e788a61edf-5b7dd97cd5-zj78l
I0210 17:18:01.439720       1 scheduler.go:69] Estado no Informer: map[acceptablePreemptionOverhead:0.05 controller:prod-deployment-average-2-77e788a61edf qosMeasuring:average slo:0.8]
I0210 17:18:01.439753       1 scheduler.go:70] Estado real no cluster: map[acceptablePreemptionOverhead:0.05 controller:prod-deployment-average-2-77e788a61edf qosMeasuring:average slo:0.8]
I0210 17:18:01.439761       1 scheduler.go:269] [OnUpdatePod] Atualizando informações de métricas para o pod default/prod-deployment-average-2-77e788a61edf-5b7dd97cd5-zj78l
I0210 17:18:01.439767       1 types.go:751] [ControllerName] Verificando as anotações do pod default/prod-deployment-average-2-77e788a61edf-5b7dd97cd5-zj78l
I0210 17:18:01.439772       1 types.go:769] [ControllerName] Anotação 'controller' encontrada para o pod default/prod-deployment-average-2-77e788a61edf-5b7dd97cd5-zj78l: prod-deployment-average-2-77e788a61edf
I0210 17:18:01.439780       1 scheduler.go:271] [OnUpdatePod] Atualizando 'LastStatus' do pod default/prod-deployment-average-2-77e788a61edf-5b7dd97cd5-zj78l nas métricas
I0210 17:18:01.439783       1 scheduler.go:273] [OnUpdatePod] Métrica atualizada para o pod default/prod-deployment-average-2-77e788a61edf-5b7dd97cd5-zj78l
I0210 17:18:01.439790       1 scheduler.go:277] [OnUpdatePod] Finalizando processamento de atualização de pod para default/prod-deployment-average-2-77e788a61edf-5b7dd97cd5-zj78l
I0210 17:18:02.047217       1 postFilter.go:29] [PostFilter] PostFilter chamado para pod: default/prod-deployment-average-1-9a2b81a4ad79-8447964868-6npqb
I0210 17:18:02.047241       1 postFilter.go:76] Comparando pod original com o atualizado...
I0210 17:18:02.047248       1 postFilter.go:83] Successfully retrieved updated pod default/prod-deployment-average-1-9a2b81a4ad79-8447964868-6npqb from lister
I0210 17:18:02.049327       1 postFilter.go:250] [compareNodeResources] Recursos calculados no nó minikube: CPU = 8850 mCPU, Memória = 490373120 bytes
I0210 17:18:02.049352       1 postFilter.go:251] [compareNodeResources] Recursos do snapshot no nó minikube: CPU = 8850 mCPU, Memória = 490373120 bytes
I0210 17:18:02.049359       1 postFilter.go:257] [compareNodeResources] Recursos de CPU do nó minikube estão sincronizados: 8850 mCPU
I0210 17:18:02.049365       1 postFilter.go:263] [compareNodeResources] Recursos de memória do nó minikube estão sincronizados: 490373120 bytes
I0210 17:18:02.049374       1 postFilter.go:104] [Preempt] Verificando se é necessário limpar NominatedNodeName do pod default/prod-deployment-average-1-9a2b81a4ad79-8447964868-6npqb antes de continuar.
I0210 17:18:02.049471       1 scheduler.go:597] [GetControllerMetricInfo] Iniciando para o pod: default/prod-deployment-average-2-77e788a61edf-5b7dd97cd5-zj78l
I0210 17:18:02.049488       1 scheduler.go:602] [GetControllerMetricInfo] Obtendo o nome do controlador para o pod: default/prod-deployment-average-2-77e788a61edf-5b7dd97cd5-zj78l
I0210 17:18:02.049495       1 types.go:751] [ControllerName] Verificando as anotações do pod default/prod-deployment-average-2-77e788a61edf-5b7dd97cd5-zj78l
I0210 17:18:02.049500       1 types.go:769] [ControllerName] Anotação 'controller' encontrada para o pod default/prod-deployment-average-2-77e788a61edf-5b7dd97cd5-zj78l: prod-deployment-average-2-77e788a61edf
I0210 17:18:02.049506       1 scheduler.go:605] [GetControllerMetricInfo] Métricas do controlador definidas para o pod: default/prod-deployment-average-2-77e788a61edf-5b7dd97cd5-zj78l
I0210 17:18:02.049512       1 scheduler.go:83] [HigherPrecedence] Calculando precedência entre prod-deployment-average-1-9a2b81a4ad79-8447964868-6npqb e prod-deployment-average-2-77e788a61edf-5b7dd97cd5-zj78l
I0210 17:18:02.049517       1 scheduler.go:116] [WaitForPodsOnCache] Verificando se o pod prod-deployment-average-1-9a2b81a4ad79-8447964868-6npqb está no cache...
I0210 17:18:02.049521       1 scheduler.go:597] [GetControllerMetricInfo] Iniciando para o pod: default/prod-deployment-average-1-9a2b81a4ad79-8447964868-6npqb
I0210 17:18:02.049525       1 scheduler.go:602] [GetControllerMetricInfo] Obtendo o nome do controlador para o pod: default/prod-deployment-average-1-9a2b81a4ad79-8447964868-6npqb
I0210 17:18:02.049529       1 types.go:751] [ControllerName] Verificando as anotações do pod default/prod-deployment-average-1-9a2b81a4ad79-8447964868-6npqb
I0210 17:18:02.049534       1 types.go:769] [ControllerName] Anotação 'controller' encontrada para o pod default/prod-deployment-average-1-9a2b81a4ad79-8447964868-6npqb: prod-deployment-average-1-9a2b81a4ad79
I0210 17:18:02.049539       1 scheduler.go:605] [GetControllerMetricInfo] Métricas do controlador definidas para o pod: default/prod-deployment-average-1-9a2b81a4ad79-8447964868-6npqb
I0210 17:18:02.051342       1 scheduler.go:69] Estado no Informer: map[acceptablePreemptionOverhead:0.05 controller:prod-deployment-average-1-9a2b81a4ad79 qosMeasuring:average slo:0.8]
I0210 17:18:02.051368       1 scheduler.go:70] Estado real no cluster: map[acceptablePreemptionOverhead:0.05 controller:prod-deployment-average-1-9a2b81a4ad79 qosMeasuring:average slo:0.8]
I0210 17:18:02.051376       1 scheduler.go:138] [WaitForPodsOnCache] Pod prod-deployment-average-1-9a2b81a4ad79-8447964868-6npqb encontrado no cache.
I0210 17:18:02.051381       1 scheduler.go:116] [WaitForPodsOnCache] Verificando se o pod prod-deployment-average-2-77e788a61edf-5b7dd97cd5-zj78l está no cache...
I0210 17:18:02.051385       1 scheduler.go:597] [GetControllerMetricInfo] Iniciando para o pod: default/prod-deployment-average-2-77e788a61edf-5b7dd97cd5-zj78l
I0210 17:18:02.051390       1 scheduler.go:602] [GetControllerMetricInfo] Obtendo o nome do controlador para o pod: default/prod-deployment-average-2-77e788a61edf-5b7dd97cd5-zj78l
I0210 17:18:02.051395       1 types.go:751] [ControllerName] Verificando as anotações do pod default/prod-deployment-average-2-77e788a61edf-5b7dd97cd5-zj78l
I0210 17:18:02.051400       1 types.go:769] [ControllerName] Anotação 'controller' encontrada para o pod default/prod-deployment-average-2-77e788a61edf-5b7dd97cd5-zj78l: prod-deployment-average-2-77e788a61edf
I0210 17:18:02.051405       1 scheduler.go:605] [GetControllerMetricInfo] Métricas do controlador definidas para o pod: default/prod-deployment-average-2-77e788a61edf-5b7dd97cd5-zj78l
I0210 17:18:02.052970       1 scheduler.go:69] Estado no Informer: map[acceptablePreemptionOverhead:0.05 controller:prod-deployment-average-2-77e788a61edf qosMeasuring:average slo:0.8]
I0210 17:18:02.052995       1 scheduler.go:70] Estado real no cluster: map[acceptablePreemptionOverhead:0.05 controller:prod-deployment-average-2-77e788a61edf qosMeasuring:average slo:0.8]
I0210 17:18:02.053003       1 scheduler.go:138] [WaitForPodsOnCache] Pod prod-deployment-average-2-77e788a61edf-5b7dd97cd5-zj78l encontrado no cache.
I0210 17:18:02.053008       1 scheduler.go:597] [GetControllerMetricInfo] Iniciando para o pod: default/prod-deployment-average-1-9a2b81a4ad79-8447964868-6npqb
I0210 17:18:02.053013       1 scheduler.go:602] [GetControllerMetricInfo] Obtendo o nome do controlador para o pod: default/prod-deployment-average-1-9a2b81a4ad79-8447964868-6npqb
I0210 17:18:02.053017       1 types.go:751] [ControllerName] Verificando as anotações do pod default/prod-deployment-average-1-9a2b81a4ad79-8447964868-6npqb
I0210 17:18:02.053022       1 types.go:769] [ControllerName] Anotação 'controller' encontrada para o pod default/prod-deployment-average-1-9a2b81a4ad79-8447964868-6npqb: prod-deployment-average-1-9a2b81a4ad79
I0210 17:18:02.053027       1 scheduler.go:605] [GetControllerMetricInfo] Métricas do controlador definidas para o pod: default/prod-deployment-average-1-9a2b81a4ad79-8447964868-6npqb
I0210 17:18:02.053035       1 scheduler.go:597] [GetControllerMetricInfo] Iniciando para o pod: default/prod-deployment-average-2-77e788a61edf-5b7dd97cd5-zj78l
I0210 17:18:02.053043       1 scheduler.go:602] [GetControllerMetricInfo] Obtendo o nome do controlador para o pod: default/prod-deployment-average-2-77e788a61edf-5b7dd97cd5-zj78l
I0210 17:18:02.053046       1 types.go:751] [ControllerName] Verificando as anotações do pod default/prod-deployment-average-2-77e788a61edf-5b7dd97cd5-zj78l
I0210 17:18:02.053051       1 types.go:769] [ControllerName] Anotação 'controller' encontrada para o pod default/prod-deployment-average-2-77e788a61edf-5b7dd97cd5-zj78l: prod-deployment-average-2-77e788a61edf
I0210 17:18:02.053057       1 scheduler.go:605] [GetControllerMetricInfo] Métricas do controlador definidas para o pod: default/prod-deployment-average-2-77e788a61edf-5b7dd97cd5-zj78l
I0210 17:18:02.053063       1 types.go:546] [QoSMetric] qosMeasuringApproach: average
I0210 17:18:02.053070       1 types.go:532] [QoS DEBUG] effectiveRunning: 50.838781 | discardedRunning: 0.000000 | waiting: 33.129937 | binding: 0.005775 | denominator: 83.974493
I0210 17:18:02.053080       1 types.go:538] [QoS DEBUG] QoS calculado: 0.605407
I0210 17:18:02.053085       1 types.go:611] [COMPUTE QoS METRIC - AVERAGE] The pod prod-deployment-average-1-9a2b81a4ad79-8447964868-6npqb: availability 0.605407 | runtime 50.838781 | pendingTime 33.129937 | nRunning: 0 | nWaiting: 1 | residualContr 0 | estimatedOverhead 0.002887 | QoSMetric -20.428904
I0210 17:18:02.053100       1 types.go:546] [QoSMetric] qosMeasuringApproach: average
I0210 17:18:02.053106       1 types.go:532] [QoS DEBUG] effectiveRunning: 2.133089 | discardedRunning: 0.000000 | waiting: 80.910821 | binding: 0.005600 | denominator: 83.049510
I0210 17:18:02.053112       1 types.go:538] [QoS DEBUG] QoS calculado: 0.025685
I0210 17:18:02.053116       1 types.go:611] [COMPUTE QoS METRIC - AVERAGE] The pod prod-deployment-average-2-77e788a61edf-5b7dd97cd5-zj78l: availability 0.025685 | runtime 2.133089 | pendingTime 80.910821 | nRunning: 1 | nWaiting: 0 | residualContr 0 | estimatedOverhead 0.005600 | QoSMetric -80.388747
I0210 17:18:02.053124       1 scheduler.go:97] [HigherPrecedence] Métricas para prod-deployment-average-1-9a2b81a4ad79-8447964868-6npqb: QoS = -20.428904, Importância = 0.80
I0210 17:18:02.053130       1 scheduler.go:98] [HigherPrecedence] Métricas para prod-deployment-average-2-77e788a61edf-5b7dd97cd5-zj78l: QoS = -80.388747, Importância = 0.80
I0210 17:18:02.053137       1 scheduler.go:109] [HigherPrecedence] Decisão final: prod-deployment-average-1-9a2b81a4ad79-8447964868-6npqb tem precedência sobre prod-deployment-average-2-77e788a61edf-5b7dd97cd5-zj78l? false
I0210 17:18:02.053216       1 postFilter.go:154] [PREEMPT CALL] No node was chosen to allocate pod prod-deployment-average-1-9a2b81a4ad79-8447964868-6npqb
W0210 17:18:02.053230       1 postFilter.go:45] [PostFilter] Nenhum nó nominado após a preempção para o pod: default/prod-deployment-average-1-9a2b81a4ad79-8447964868-6npqb
I0210 17:18:29.911239       1 postFilter.go:29] [PostFilter] PostFilter chamado para pod: default/prod-deployment-average-1-9a2b81a4ad79-8447964868-6npqb
I0210 17:18:29.911261       1 postFilter.go:76] Comparando pod original com o atualizado...
I0210 17:18:29.911267       1 postFilter.go:83] Successfully retrieved updated pod default/prod-deployment-average-1-9a2b81a4ad79-8447964868-6npqb from lister
I0210 17:18:29.913235       1 postFilter.go:250] [compareNodeResources] Recursos calculados no nó minikube: CPU = 8850 mCPU, Memória = 490373120 bytes
I0210 17:18:29.913259       1 postFilter.go:251] [compareNodeResources] Recursos do snapshot no nó minikube: CPU = 8850 mCPU, Memória = 490373120 bytes
I0210 17:18:29.913266       1 postFilter.go:257] [compareNodeResources] Recursos de CPU do nó minikube estão sincronizados: 8850 mCPU
I0210 17:18:29.913272       1 postFilter.go:263] [compareNodeResources] Recursos de memória do nó minikube estão sincronizados: 490373120 bytes
I0210 17:18:29.913281       1 postFilter.go:104] [Preempt] Verificando se é necessário limpar NominatedNodeName do pod default/prod-deployment-average-1-9a2b81a4ad79-8447964868-6npqb antes de continuar.
I0210 17:18:29.913375       1 scheduler.go:597] [GetControllerMetricInfo] Iniciando para o pod: default/prod-deployment-average-2-77e788a61edf-5b7dd97cd5-zj78l
I0210 17:18:29.913385       1 scheduler.go:602] [GetControllerMetricInfo] Obtendo o nome do controlador para o pod: default/prod-deployment-average-2-77e788a61edf-5b7dd97cd5-zj78l
I0210 17:18:29.913391       1 types.go:751] [ControllerName] Verificando as anotações do pod default/prod-deployment-average-2-77e788a61edf-5b7dd97cd5-zj78l
I0210 17:18:29.913396       1 types.go:769] [ControllerName] Anotação 'controller' encontrada para o pod default/prod-deployment-average-2-77e788a61edf-5b7dd97cd5-zj78l: prod-deployment-average-2-77e788a61edf
I0210 17:18:29.913402       1 scheduler.go:605] [GetControllerMetricInfo] Métricas do controlador definidas para o pod: default/prod-deployment-average-2-77e788a61edf-5b7dd97cd5-zj78l
I0210 17:18:29.913407       1 scheduler.go:83] [HigherPrecedence] Calculando precedência entre prod-deployment-average-1-9a2b81a4ad79-8447964868-6npqb e prod-deployment-average-2-77e788a61edf-5b7dd97cd5-zj78l
I0210 17:18:29.913412       1 scheduler.go:116] [WaitForPodsOnCache] Verificando se o pod prod-deployment-average-1-9a2b81a4ad79-8447964868-6npqb está no cache...
I0210 17:18:29.913416       1 scheduler.go:597] [GetControllerMetricInfo] Iniciando para o pod: default/prod-deployment-average-1-9a2b81a4ad79-8447964868-6npqb
I0210 17:18:29.913419       1 scheduler.go:602] [GetControllerMetricInfo] Obtendo o nome do controlador para o pod: default/prod-deployment-average-1-9a2b81a4ad79-8447964868-6npqb
I0210 17:18:29.913423       1 types.go:751] [ControllerName] Verificando as anotações do pod default/prod-deployment-average-1-9a2b81a4ad79-8447964868-6npqb
I0210 17:18:29.913428       1 types.go:769] [ControllerName] Anotação 'controller' encontrada para o pod default/prod-deployment-average-1-9a2b81a4ad79-8447964868-6npqb: prod-deployment-average-1-9a2b81a4ad79
I0210 17:18:29.913435       1 scheduler.go:605] [GetControllerMetricInfo] Métricas do controlador definidas para o pod: default/prod-deployment-average-1-9a2b81a4ad79-8447964868-6npqb
I0210 17:18:29.915364       1 scheduler.go:69] Estado no Informer: map[acceptablePreemptionOverhead:0.05 controller:prod-deployment-average-1-9a2b81a4ad79 qosMeasuring:average slo:0.8]
I0210 17:18:29.915396       1 scheduler.go:70] Estado real no cluster: map[acceptablePreemptionOverhead:0.05 controller:prod-deployment-average-1-9a2b81a4ad79 qosMeasuring:average slo:0.8]
I0210 17:18:29.915405       1 scheduler.go:138] [WaitForPodsOnCache] Pod prod-deployment-average-1-9a2b81a4ad79-8447964868-6npqb encontrado no cache.
I0210 17:18:29.915409       1 scheduler.go:116] [WaitForPodsOnCache] Verificando se o pod prod-deployment-average-2-77e788a61edf-5b7dd97cd5-zj78l está no cache...
I0210 17:18:29.915414       1 scheduler.go:597] [GetControllerMetricInfo] Iniciando para o pod: default/prod-deployment-average-2-77e788a61edf-5b7dd97cd5-zj78l
I0210 17:18:29.915417       1 scheduler.go:602] [GetControllerMetricInfo] Obtendo o nome do controlador para o pod: default/prod-deployment-average-2-77e788a61edf-5b7dd97cd5-zj78l
I0210 17:18:29.915421       1 types.go:751] [ControllerName] Verificando as anotações do pod default/prod-deployment-average-2-77e788a61edf-5b7dd97cd5-zj78l
I0210 17:18:29.915425       1 types.go:769] [ControllerName] Anotação 'controller' encontrada para o pod default/prod-deployment-average-2-77e788a61edf-5b7dd97cd5-zj78l: prod-deployment-average-2-77e788a61edf
I0210 17:18:29.915430       1 scheduler.go:605] [GetControllerMetricInfo] Métricas do controlador definidas para o pod: default/prod-deployment-average-2-77e788a61edf-5b7dd97cd5-zj78l
I0210 17:18:29.916833       1 scheduler.go:69] Estado no Informer: map[acceptablePreemptionOverhead:0.05 controller:prod-deployment-average-2-77e788a61edf qosMeasuring:average slo:0.8]
I0210 17:18:29.916858       1 scheduler.go:70] Estado real no cluster: map[acceptablePreemptionOverhead:0.05 controller:prod-deployment-average-2-77e788a61edf qosMeasuring:average slo:0.8]
I0210 17:18:29.916868       1 scheduler.go:138] [WaitForPodsOnCache] Pod prod-deployment-average-2-77e788a61edf-5b7dd97cd5-zj78l encontrado no cache.
I0210 17:18:29.916873       1 scheduler.go:597] [GetControllerMetricInfo] Iniciando para o pod: default/prod-deployment-average-1-9a2b81a4ad79-8447964868-6npqb
I0210 17:18:29.916877       1 scheduler.go:602] [GetControllerMetricInfo] Obtendo o nome do controlador para o pod: default/prod-deployment-average-1-9a2b81a4ad79-8447964868-6npqb
I0210 17:18:29.916880       1 types.go:751] [ControllerName] Verificando as anotações do pod default/prod-deployment-average-1-9a2b81a4ad79-8447964868-6npqb
I0210 17:18:29.916883       1 types.go:769] [ControllerName] Anotação 'controller' encontrada para o pod default/prod-deployment-average-1-9a2b81a4ad79-8447964868-6npqb: prod-deployment-average-1-9a2b81a4ad79
I0210 17:18:29.916888       1 scheduler.go:605] [GetControllerMetricInfo] Métricas do controlador definidas para o pod: default/prod-deployment-average-1-9a2b81a4ad79-8447964868-6npqb
I0210 17:18:29.916894       1 scheduler.go:597] [GetControllerMetricInfo] Iniciando para o pod: default/prod-deployment-average-2-77e788a61edf-5b7dd97cd5-zj78l
I0210 17:18:29.916897       1 scheduler.go:602] [GetControllerMetricInfo] Obtendo o nome do controlador para o pod: default/prod-deployment-average-2-77e788a61edf-5b7dd97cd5-zj78l
I0210 17:18:29.916901       1 types.go:751] [ControllerName] Verificando as anotações do pod default/prod-deployment-average-2-77e788a61edf-5b7dd97cd5-zj78l
I0210 17:18:29.916905       1 types.go:769] [ControllerName] Anotação 'controller' encontrada para o pod default/prod-deployment-average-2-77e788a61edf-5b7dd97cd5-zj78l: prod-deployment-average-2-77e788a61edf
I0210 17:18:29.916909       1 scheduler.go:605] [GetControllerMetricInfo] Métricas do controlador definidas para o pod: default/prod-deployment-average-2-77e788a61edf-5b7dd97cd5-zj78l
I0210 17:18:29.916917       1 types.go:546] [QoSMetric] qosMeasuringApproach: average
I0210 17:18:29.916926       1 types.go:532] [QoS DEBUG] effectiveRunning: 50.838781 | discardedRunning: 0.000000 | waiting: 60.993832 | binding: 0.005775 | denominator: 111.838388
I0210 17:18:29.916936       1 types.go:538] [QoS DEBUG] QoS calculado: 0.454574
I0210 17:18:29.916943       1 types.go:611] [COMPUTE QoS METRIC - AVERAGE] The pod prod-deployment-average-1-9a2b81a4ad79-8447964868-6npqb: availability 0.454574 | runtime 50.838781 | pendingTime 60.993832 | nRunning: 0 | nWaiting: 1 | residualContr 0 | estimatedOverhead 0.002887 | QoSMetric -48.292799
I0210 17:18:29.916956       1 types.go:546] [QoSMetric] qosMeasuringApproach: average
I0210 17:18:29.916961       1 types.go:532] [QoS DEBUG] effectiveRunning: 29.996984 | discardedRunning: 0.000000 | waiting: 80.910821 | binding: 0.005600 | denominator: 110.913405
I0210 17:18:29.916967       1 types.go:538] [QoS DEBUG] QoS calculado: 0.270454
I0210 17:18:29.916971       1 types.go:611] [COMPUTE QoS METRIC - AVERAGE] The pod prod-deployment-average-2-77e788a61edf-5b7dd97cd5-zj78l: availability 0.270454 | runtime 29.996984 | pendingTime 80.910821 | nRunning: 1 | nWaiting: 0 | residualContr 0 | estimatedOverhead 0.005600 | QoSMetric -73.422774
I0210 17:18:29.916977       1 scheduler.go:97] [HigherPrecedence] Métricas para prod-deployment-average-1-9a2b81a4ad79-8447964868-6npqb: QoS = -48.292799, Importância = 0.80
I0210 17:18:29.916982       1 scheduler.go:98] [HigherPrecedence] Métricas para prod-deployment-average-2-77e788a61edf-5b7dd97cd5-zj78l: QoS = -73.422774, Importância = 0.80
I0210 17:18:29.916988       1 scheduler.go:109] [HigherPrecedence] Decisão final: prod-deployment-average-1-9a2b81a4ad79-8447964868-6npqb tem precedência sobre prod-deployment-average-2-77e788a61edf-5b7dd97cd5-zj78l? false
I0210 17:18:29.917017       1 postFilter.go:154] [PREEMPT CALL] No node was chosen to allocate pod prod-deployment-average-1-9a2b81a4ad79-8447964868-6npqb
W0210 17:18:29.917029       1 postFilter.go:45] [PostFilter] Nenhum nó nominado após a preempção para o pod: default/prod-deployment-average-1-9a2b81a4ad79-8447964868-6npqb
