I0129 14:00:27.828908       1 serving.go:386] Generated self-signed cert in-memory
W0129 14:00:27.830446       1 client_config.go:659] Neither --kubeconfig nor --master was specified.  Using the inClusterConfig.  This might not work.
I0129 14:00:28.097804       1 scheduler.go:218] [OnAddPod] Pod adicionado: kube-system/coredns-6f6b679f8f-9pkz6, Anotações: map[]
I0129 14:00:28.105059       1 scheduler.go:70] Estado no Informer: map[]
I0129 14:00:28.105436       1 scheduler.go:71] Estado real no cluster: map[]
I0129 14:00:28.105786       1 scheduler.go:224] [OnAddPod] Ignorando pod kube-system/coredns-6f6b679f8f-9pkz6 pois pertence ao namespace kube-system
I0129 14:00:28.106010       1 scheduler.go:218] [OnAddPod] Pod adicionado: kube-system/custom-scheduler-bc7f46cc-2857m, Anotações: map[]
I0129 14:00:28.108718       1 scheduler.go:70] Estado no Informer: map[]
I0129 14:00:28.108757       1 scheduler.go:71] Estado real no cluster: map[]
I0129 14:00:28.108767       1 scheduler.go:224] [OnAddPod] Ignorando pod kube-system/custom-scheduler-bc7f46cc-2857m pois pertence ao namespace kube-system
I0129 14:00:28.108956       1 scheduler.go:218] [OnAddPod] Pod adicionado: kube-system/etcd-minikube, Anotações: map[kubeadm.kubernetes.io/etcd.advertise-client-urls:https://192.168.39.80:2379 kubernetes.io/config.hash:815005a07b4075d89953668b2e11f03a kubernetes.io/config.mirror:815005a07b4075d89953668b2e11f03a kubernetes.io/config.seen:2025-01-28T13:04:04.704387234Z kubernetes.io/config.source:file]
I0129 14:00:28.112043       1 scheduler.go:70] Estado no Informer: map[kubeadm.kubernetes.io/etcd.advertise-client-urls:https://192.168.39.80:2379 kubernetes.io/config.hash:815005a07b4075d89953668b2e11f03a kubernetes.io/config.mirror:815005a07b4075d89953668b2e11f03a kubernetes.io/config.seen:2025-01-28T13:04:04.704387234Z kubernetes.io/config.source:file]
I0129 14:00:28.112642       1 scheduler.go:71] Estado real no cluster: map[kubeadm.kubernetes.io/etcd.advertise-client-urls:https://192.168.39.80:2379 kubernetes.io/config.hash:815005a07b4075d89953668b2e11f03a kubernetes.io/config.mirror:815005a07b4075d89953668b2e11f03a kubernetes.io/config.seen:2025-01-28T13:04:04.704387234Z kubernetes.io/config.source:file]
I0129 14:00:28.113032       1 scheduler.go:224] [OnAddPod] Ignorando pod kube-system/etcd-minikube pois pertence ao namespace kube-system
I0129 14:00:28.113209       1 scheduler.go:218] [OnAddPod] Pod adicionado: kube-system/kube-apiserver-minikube, Anotações: map[kubeadm.kubernetes.io/kube-apiserver.advertise-address.endpoint:192.168.39.80:8443 kubernetes.io/config.hash:9166f2e0b4696e596bb6e6c5b98bd673 kubernetes.io/config.mirror:9166f2e0b4696e596bb6e6c5b98bd673 kubernetes.io/config.seen:2025-01-28T13:04:04.704391154Z kubernetes.io/config.source:file]
I0129 14:00:28.116293       1 scheduler.go:70] Estado no Informer: map[kubeadm.kubernetes.io/kube-apiserver.advertise-address.endpoint:192.168.39.80:8443 kubernetes.io/config.hash:9166f2e0b4696e596bb6e6c5b98bd673 kubernetes.io/config.mirror:9166f2e0b4696e596bb6e6c5b98bd673 kubernetes.io/config.seen:2025-01-28T13:04:04.704391154Z kubernetes.io/config.source:file]
I0129 14:00:28.116339       1 scheduler.go:71] Estado real no cluster: map[kubeadm.kubernetes.io/kube-apiserver.advertise-address.endpoint:192.168.39.80:8443 kubernetes.io/config.hash:9166f2e0b4696e596bb6e6c5b98bd673 kubernetes.io/config.mirror:9166f2e0b4696e596bb6e6c5b98bd673 kubernetes.io/config.seen:2025-01-28T13:04:04.704391154Z kubernetes.io/config.source:file]
I0129 14:00:28.116352       1 scheduler.go:224] [OnAddPod] Ignorando pod kube-system/kube-apiserver-minikube pois pertence ao namespace kube-system
I0129 14:00:28.116720       1 scheduler.go:218] [OnAddPod] Pod adicionado: kube-system/kube-controller-manager-minikube, Anotações: map[kubernetes.io/config.hash:6e07439efa4d6dab7ea55fed1a35452a kubernetes.io/config.mirror:6e07439efa4d6dab7ea55fed1a35452a kubernetes.io/config.seen:2025-01-28T13:04:04.704392886Z kubernetes.io/config.source:file]
I0129 14:00:28.119710       1 scheduler.go:70] Estado no Informer: map[kubernetes.io/config.hash:6e07439efa4d6dab7ea55fed1a35452a kubernetes.io/config.mirror:6e07439efa4d6dab7ea55fed1a35452a kubernetes.io/config.seen:2025-01-28T13:04:04.704392886Z kubernetes.io/config.source:file]
I0129 14:00:28.120048       1 scheduler.go:71] Estado real no cluster: map[kubernetes.io/config.hash:6e07439efa4d6dab7ea55fed1a35452a kubernetes.io/config.mirror:6e07439efa4d6dab7ea55fed1a35452a kubernetes.io/config.seen:2025-01-28T13:04:04.704392886Z kubernetes.io/config.source:file]
I0129 14:00:28.120259       1 scheduler.go:224] [OnAddPod] Ignorando pod kube-system/kube-controller-manager-minikube pois pertence ao namespace kube-system
I0129 14:00:28.120570       1 scheduler.go:218] [OnAddPod] Pod adicionado: kube-system/kube-proxy-rd98k, Anotações: map[]
I0129 14:00:28.124412       1 scheduler.go:70] Estado no Informer: map[]
I0129 14:00:28.124449       1 scheduler.go:71] Estado real no cluster: map[]
I0129 14:00:28.124458       1 scheduler.go:224] [OnAddPod] Ignorando pod kube-system/kube-proxy-rd98k pois pertence ao namespace kube-system
I0129 14:00:28.124785       1 scheduler.go:218] [OnAddPod] Pod adicionado: kube-system/kube-scheduler-minikube, Anotações: map[kubernetes.io/config.hash:e039200acb850c82bb901653cc38ff6e kubernetes.io/config.mirror:e039200acb850c82bb901653cc38ff6e kubernetes.io/config.seen:2025-01-28T13:04:04.704394408Z kubernetes.io/config.source:file]
I0129 14:00:28.129210       1 scheduler.go:70] Estado no Informer: map[kubernetes.io/config.hash:e039200acb850c82bb901653cc38ff6e kubernetes.io/config.mirror:e039200acb850c82bb901653cc38ff6e kubernetes.io/config.seen:2025-01-28T13:04:04.704394408Z kubernetes.io/config.source:file]
I0129 14:00:28.129525       1 scheduler.go:71] Estado real no cluster: map[kubernetes.io/config.hash:e039200acb850c82bb901653cc38ff6e kubernetes.io/config.mirror:e039200acb850c82bb901653cc38ff6e kubernetes.io/config.seen:2025-01-28T13:04:04.704394408Z kubernetes.io/config.source:file]
I0129 14:00:28.129710       1 scheduler.go:224] [OnAddPod] Ignorando pod kube-system/kube-scheduler-minikube pois pertence ao namespace kube-system
I0129 14:00:28.130016       1 scheduler.go:218] [OnAddPod] Pod adicionado: kube-system/storage-provisioner, Anotações: map[kubectl.kubernetes.io/last-applied-configuration:{"apiVersion":"v1","kind":"Pod","metadata":{"annotations":{},"labels":{"addonmanager.kubernetes.io/mode":"Reconcile","integration-test":"storage-provisioner"},"name":"storage-provisioner","namespace":"kube-system"},"spec":{"containers":[{"command":["/storage-provisioner"],"image":"gcr.io/k8s-minikube/storage-provisioner:v5","imagePullPolicy":"IfNotPresent","name":"storage-provisioner","volumeMounts":[{"mountPath":"/tmp","name":"tmp"}]}],"hostNetwork":true,"serviceAccountName":"storage-provisioner","volumes":[{"hostPath":{"path":"/tmp","type":"Directory"},"name":"tmp"}]}}
]
I0129 14:00:28.133187       1 scheduler.go:70] Estado no Informer: map[kubectl.kubernetes.io/last-applied-configuration:{"apiVersion":"v1","kind":"Pod","metadata":{"annotations":{},"labels":{"addonmanager.kubernetes.io/mode":"Reconcile","integration-test":"storage-provisioner"},"name":"storage-provisioner","namespace":"kube-system"},"spec":{"containers":[{"command":["/storage-provisioner"],"image":"gcr.io/k8s-minikube/storage-provisioner:v5","imagePullPolicy":"IfNotPresent","name":"storage-provisioner","volumeMounts":[{"mountPath":"/tmp","name":"tmp"}]}],"hostNetwork":true,"serviceAccountName":"storage-provisioner","volumes":[{"hostPath":{"path":"/tmp","type":"Directory"},"name":"tmp"}]}}
]
I0129 14:00:28.133229       1 scheduler.go:71] Estado real no cluster: map[kubectl.kubernetes.io/last-applied-configuration:{"apiVersion":"v1","kind":"Pod","metadata":{"annotations":{},"labels":{"addonmanager.kubernetes.io/mode":"Reconcile","integration-test":"storage-provisioner"},"name":"storage-provisioner","namespace":"kube-system"},"spec":{"containers":[{"command":["/storage-provisioner"],"image":"gcr.io/k8s-minikube/storage-provisioner:v5","imagePullPolicy":"IfNotPresent","name":"storage-provisioner","volumeMounts":[{"mountPath":"/tmp","name":"tmp"}]}],"hostNetwork":true,"serviceAccountName":"storage-provisioner","volumes":[{"hostPath":{"path":"/tmp","type":"Directory"},"name":"tmp"}]}}
]
I0129 14:00:28.133240       1 scheduler.go:224] [OnAddPod] Ignorando pod kube-system/storage-provisioner pois pertence ao namespace kube-system
I0129 14:00:28.188059       1 scheduler.go:662] PodInformer sincronizado com sucesso
I0129 14:00:28.192668       1 server.go:167] "Starting Kubernetes Scheduler" version="v0.0.0-master+$Format:%H$"
I0129 14:00:28.192744       1 server.go:169] "Golang settings" GOGC="" GOMAXPROCS="" GOTRACEBACK=""
I0129 14:00:28.202876       1 secure_serving.go:213] Serving securely on [::]:10259
I0129 14:00:28.203356       1 requestheader_controller.go:172] Starting RequestHeaderAuthRequestController
I0129 14:00:28.203420       1 shared_informer.go:313] Waiting for caches to sync for RequestHeaderAuthRequestController
I0129 14:00:28.203760       1 tlsconfig.go:243] "Starting DynamicServingCertificateController"
I0129 14:00:28.205681       1 configmap_cafile_content.go:205] "Starting controller" name="client-ca::kube-system::extension-apiserver-authentication::client-ca-file"
I0129 14:00:28.206852       1 shared_informer.go:313] Waiting for caches to sync for client-ca::kube-system::extension-apiserver-authentication::client-ca-file
I0129 14:00:28.206516       1 configmap_cafile_content.go:205] "Starting controller" name="client-ca::kube-system::extension-apiserver-authentication::requestheader-client-ca-file"
I0129 14:00:28.207060       1 shared_informer.go:313] Waiting for caches to sync for client-ca::kube-system::extension-apiserver-authentication::requestheader-client-ca-file
I0129 14:00:28.304307       1 shared_informer.go:320] Caches are synced for RequestHeaderAuthRequestController
I0129 14:00:28.304526       1 leaderelection.go:254] attempting to acquire leader lease kube-system/kube-scheduler...
I0129 14:00:28.310997       1 shared_informer.go:320] Caches are synced for client-ca::kube-system::extension-apiserver-authentication::requestheader-client-ca-file
I0129 14:00:28.311369       1 shared_informer.go:320] Caches are synced for client-ca::kube-system::extension-apiserver-authentication::client-ca-file
I0129 14:00:28.332660       1 leaderelection.go:268] successfully acquired lease kube-system/kube-scheduler
I0129 14:00:28.559757       1 scheduler.go:258] [OnUpdatePod] Iniciando processamento de atualização de pod
I0129 14:00:28.559876       1 scheduler.go:262] [OnUpdatePod] Pod atualizado detectado: kube-system/custom-scheduler-bc7f46cc-2857m, Anotações: map[]
I0129 14:00:28.560817       1 scheduler.go:265] [OnUpdatePod] Comparando estado no Informer e estado real no cluster para o pod kube-system/custom-scheduler-bc7f46cc-2857m
I0129 14:00:28.567822       1 scheduler.go:70] Estado no Informer: map[]
I0129 14:00:28.568347       1 scheduler.go:71] Estado real no cluster: map[]
I0129 14:00:28.568779       1 scheduler.go:270] [OnUpdatePod] Pod kube-system/custom-scheduler-bc7f46cc-2857m pertence ao namespace 'kube-system'. Ignorando...
I0129 14:01:50.236444       1 scheduler.go:218] [OnAddPod] Pod adicionado: default/test-deployment2-7b58dbd49-l84n4, Anotações: map[acceptablePreemptionOverhead:10 controller:test-controller2 qosMeasuring:average]
I0129 14:01:50.252066       1 scheduler.go:146] [Reserve] resources reserved at node minikube for pod test-deployment2-7b58dbd49-l84n4_default at 2025-01-29 14:01:50.252033003 +0000 UTC m=+83.355588178
I0129 14:01:50.255297       1 types.go:743] [ControllerName] Verificando as anotações do pod default/test-deployment2-7b58dbd49-l84n4
I0129 14:01:50.255484       1 types.go:761] [ControllerName] Anotação 'controller' encontrada para o pod default/test-deployment2-7b58dbd49-l84n4: test-controller2
I0129 14:01:50.282305       1 scheduler.go:148] [Reserve] Status de alocação atual para o pod test-deployment2-7b58dbd49-l84n4_default: 
I0129 14:01:50.282382       1 scheduler.go:150] [Reserve] Status de alocação atualizado para o pod test-deployment2-7b58dbd49-l84n4_default: allocating
I0129 14:01:50.282500       1 scheduler.go:174] [PreBind] Validando o pod test-deployment2-7b58dbd49-l84n4 antes de vincular ao node minikube
I0129 14:01:50.288214       1 scheduler.go:70] Estado no Informer: map[acceptablePreemptionOverhead:10 controller:test-controller2 qosMeasuring:average]
I0129 14:01:50.289920       1 scheduler.go:71] Estado real no cluster: map[acceptablePreemptionOverhead:10 controller:test-controller2 qosMeasuring:average]
I0129 14:01:50.309499       1 scheduler.go:182] [PostBind] Chamado para pod test-deployment2-7b58dbd49-l84n4
I0129 14:01:50.309554       1 scheduler.go:200] [PostBind] Pod test-deployment2-7b58dbd49-l84n4 - Início do binding: 2025-01-29 14:01:50.282533953 +0000 UTC m=+83.386089230, Fim do binding: 2025-01-29 14:01:50.309538053 +0000 UTC m=+83.413093178
I0129 14:01:50.309968       1 types.go:743] [ControllerName] Verificando as anotações do pod default/test-deployment2-7b58dbd49-l84n4
I0129 14:01:50.310198       1 types.go:761] [ControllerName] Anotação 'controller' encontrada para o pod default/test-deployment2-7b58dbd49-l84n4: test-controller2
I0129 14:01:50.310277       1 scheduler.go:207] [PostBind] Métricas atualizadas para o pod test-deployment2-7b58dbd49-l84n4
I0129 14:01:50.319691       1 scheduler.go:229] [OnAddPod] Adicionando pod default/test-deployment2-7b58dbd49-l84n4 com os seguintes detalhes:
I0129 14:01:50.321474       1 types.go:743] [ControllerName] Verificando as anotações do pod default/test-deployment2-7b58dbd49-l84n4
I0129 14:01:50.321780       1 types.go:761] [ControllerName] Anotação 'controller' encontrada para o pod default/test-deployment2-7b58dbd49-l84n4: test-controller2
I0129 14:01:50.322164       1 scheduler.go:238] [OnAddPod] Atualizando métricas para o pod default/test-deployment2-7b58dbd49-l84n4
I0129 14:01:50.322865       1 types.go:743] [ControllerName] Verificando as anotações do pod default/test-deployment2-7b58dbd49-l84n4
I0129 14:01:50.322992       1 types.go:761] [ControllerName] Anotação 'controller' encontrada para o pod default/test-deployment2-7b58dbd49-l84n4: test-controller2
I0129 14:01:50.324437       1 scheduler.go:251] [OnAddPod] Pod default/test-deployment2-7b58dbd49-l84n4 adicionado com sucesso
I0129 14:01:50.324636       1 scheduler.go:258] [OnUpdatePod] Iniciando processamento de atualização de pod
I0129 14:01:50.325347       1 scheduler.go:262] [OnUpdatePod] Pod atualizado detectado: default/test-deployment2-7b58dbd49-l84n4, Anotações: map[acceptablePreemptionOverhead:10 controller:test-controller2 qosMeasuring:average]
I0129 14:01:50.325609       1 scheduler.go:265] [OnUpdatePod] Comparando estado no Informer e estado real no cluster para o pod default/test-deployment2-7b58dbd49-l84n4
I0129 14:01:50.333538       1 scheduler.go:70] Estado no Informer: map[acceptablePreemptionOverhead:10 controller:test-controller2 qosMeasuring:average]
I0129 14:01:50.333608       1 scheduler.go:71] Estado real no cluster: map[acceptablePreemptionOverhead:10 controller:test-controller2 qosMeasuring:average]
I0129 14:01:50.333638       1 scheduler.go:275] [OnUpdatePod] Atualizando informações de métricas para o pod default/test-deployment2-7b58dbd49-l84n4
I0129 14:01:50.333674       1 types.go:743] [ControllerName] Verificando as anotações do pod default/test-deployment2-7b58dbd49-l84n4
I0129 14:01:50.333698       1 types.go:761] [ControllerName] Anotação 'controller' encontrada para o pod default/test-deployment2-7b58dbd49-l84n4: test-controller2
I0129 14:01:50.333707       1 scheduler.go:277] [OnUpdatePod] Atualizando 'LastStatus' do pod default/test-deployment2-7b58dbd49-l84n4 nas métricas
I0129 14:01:50.333711       1 scheduler.go:279] [OnUpdatePod] Métrica atualizada para o pod default/test-deployment2-7b58dbd49-l84n4
I0129 14:01:50.333719       1 scheduler.go:283] [OnUpdatePod] Finalizando processamento de atualização de pod para default/test-deployment2-7b58dbd49-l84n4
I0129 14:01:50.504852       1 scheduler.go:258] [OnUpdatePod] Iniciando processamento de atualização de pod
I0129 14:01:50.505007       1 scheduler.go:262] [OnUpdatePod] Pod atualizado detectado: default/test-deployment2-7b58dbd49-l84n4, Anotações: map[acceptablePreemptionOverhead:10 controller:test-controller2 qosMeasuring:average]
I0129 14:01:50.505160       1 scheduler.go:265] [OnUpdatePod] Comparando estado no Informer e estado real no cluster para o pod default/test-deployment2-7b58dbd49-l84n4
I0129 14:01:50.529694       1 scheduler.go:70] Estado no Informer: map[acceptablePreemptionOverhead:10 controller:test-controller2 qosMeasuring:average]
I0129 14:01:50.529787       1 scheduler.go:71] Estado real no cluster: map[acceptablePreemptionOverhead:10 controller:test-controller2 qosMeasuring:average]
I0129 14:01:50.529813       1 scheduler.go:275] [OnUpdatePod] Atualizando informações de métricas para o pod default/test-deployment2-7b58dbd49-l84n4
I0129 14:01:50.529826       1 types.go:743] [ControllerName] Verificando as anotações do pod default/test-deployment2-7b58dbd49-l84n4
I0129 14:01:50.529860       1 types.go:761] [ControllerName] Anotação 'controller' encontrada para o pod default/test-deployment2-7b58dbd49-l84n4: test-controller2
I0129 14:01:50.529923       1 scheduler.go:277] [OnUpdatePod] Atualizando 'LastStatus' do pod default/test-deployment2-7b58dbd49-l84n4 nas métricas
I0129 14:01:50.530023       1 scheduler.go:279] [OnUpdatePod] Métrica atualizada para o pod default/test-deployment2-7b58dbd49-l84n4
I0129 14:01:50.530044       1 scheduler.go:283] [OnUpdatePod] Finalizando processamento de atualização de pod para default/test-deployment2-7b58dbd49-l84n4
I0129 14:01:55.647806       1 scheduler.go:258] [OnUpdatePod] Iniciando processamento de atualização de pod
I0129 14:01:55.661362       1 scheduler.go:262] [OnUpdatePod] Pod atualizado detectado: default/test-deployment2-7b58dbd49-l84n4, Anotações: map[acceptablePreemptionOverhead:10 controller:test-controller2 qosMeasuring:average]
I0129 14:01:55.661456       1 scheduler.go:265] [OnUpdatePod] Comparando estado no Informer e estado real no cluster para o pod default/test-deployment2-7b58dbd49-l84n4
I0129 14:01:56.526559       1 scheduler.go:70] Estado no Informer: map[acceptablePreemptionOverhead:10 controller:test-controller2 qosMeasuring:average]
I0129 14:01:56.534041       1 scheduler.go:71] Estado real no cluster: map[acceptablePreemptionOverhead:10 controller:test-controller2 qosMeasuring:average]
I0129 14:01:56.534223       1 scheduler.go:275] [OnUpdatePod] Atualizando informações de métricas para o pod default/test-deployment2-7b58dbd49-l84n4
I0129 14:01:56.534241       1 types.go:743] [ControllerName] Verificando as anotações do pod default/test-deployment2-7b58dbd49-l84n4
I0129 14:01:56.540740       1 types.go:761] [ControllerName] Anotação 'controller' encontrada para o pod default/test-deployment2-7b58dbd49-l84n4: test-controller2
I0129 14:01:56.544907       1 scheduler.go:277] [OnUpdatePod] Atualizando 'LastStatus' do pod default/test-deployment2-7b58dbd49-l84n4 nas métricas
I0129 14:01:56.544920       1 scheduler.go:279] [OnUpdatePod] Métrica atualizada para o pod default/test-deployment2-7b58dbd49-l84n4
I0129 14:01:56.544939       1 scheduler.go:283] [OnUpdatePod] Finalizando processamento de atualização de pod para default/test-deployment2-7b58dbd49-l84n4
I0129 14:03:34.251741       1 scheduler.go:218] [OnAddPod] Pod adicionado: default/test-deployment3-84f8ccf757-5tmfc, Anotações: map[acceptablePreemptionOverhead:10 controller:test-controller3 qosMeasuring:average]
I0129 14:03:34.275412       1 postFilter.go:29] [PostFilter] PostFilter chamado para pod: default/test-deployment3-84f8ccf757-5tmfc
I0129 14:03:34.276098       1 postFilter.go:76] [Preempt] Comparando pod original com o atualizado...
I0129 14:03:34.279358       1 postFilter.go:83] [Preempt] Successfully retrieved updated pod default/test-deployment3-84f8ccf757-5tmfc from lister
I0129 14:03:34.607255       1 scheduler.go:70] Estado no Informer: map[acceptablePreemptionOverhead:10 controller:test-controller3 qosMeasuring:average]
I0129 14:03:34.620585       1 scheduler.go:71] Estado real no cluster: map[acceptablePreemptionOverhead:10 controller:test-controller3 qosMeasuring:average]
I0129 14:03:34.657710       1 postFilter.go:233] [compareNodeResources] Recursos calculados no nó minikube: CPU = 1450 mCPU, Memória = 459276288 bytes
I0129 14:03:34.665988       1 postFilter.go:234] [compareNodeResources] Recursos do snapshot no nó minikube: CPU = 1450 mCPU, Memória = 459276288 bytes
I0129 14:03:34.666156       1 postFilter.go:240] [compareNodeResources] Recursos de CPU do nó minikube estão sincronizados: 1450 mCPU
I0129 14:03:34.666209       1 postFilter.go:246] [compareNodeResources] Recursos de memória do nó minikube estão sincronizados: 459276288 bytes
I0129 14:03:34.666844       1 scheduler.go:606] [GetControllerMetricInfo] Iniciando para o pod: default/test-deployment2-7b58dbd49-l84n4
I0129 14:03:34.666929       1 scheduler.go:611] [GetControllerMetricInfo] Obtendo o nome do controlador para o pod: default/test-deployment2-7b58dbd49-l84n4
I0129 14:03:34.667037       1 types.go:743] [ControllerName] Verificando as anotações do pod default/test-deployment2-7b58dbd49-l84n4
I0129 14:03:34.667090       1 types.go:761] [ControllerName] Anotação 'controller' encontrada para o pod default/test-deployment2-7b58dbd49-l84n4: test-controller2
I0129 14:03:34.667157       1 scheduler.go:614] [GetControllerMetricInfo] Métricas do controlador definidas para o pod: default/test-deployment2-7b58dbd49-l84n4
I0129 14:03:34.667204       1 scheduler.go:84] [HigherPrecedence] Calculando precedência entre test-deployment3-84f8ccf757-5tmfc e test-deployment2-7b58dbd49-l84n4
I0129 14:03:34.667242       1 scheduler.go:117] [WaitForPodsOnCache] Verificando se o pod test-deployment3-84f8ccf757-5tmfc está no cache...
I0129 14:03:34.667314       1 scheduler.go:606] [GetControllerMetricInfo] Iniciando para o pod: default/test-deployment3-84f8ccf757-5tmfc
I0129 14:03:34.667330       1 scheduler.go:611] [GetControllerMetricInfo] Obtendo o nome do controlador para o pod: default/test-deployment3-84f8ccf757-5tmfc
I0129 14:03:34.667342       1 types.go:743] [ControllerName] Verificando as anotações do pod default/test-deployment3-84f8ccf757-5tmfc
I0129 14:03:34.667354       1 types.go:761] [ControllerName] Anotação 'controller' encontrada para o pod default/test-deployment3-84f8ccf757-5tmfc: test-controller3
I0129 14:03:34.667405       1 scheduler.go:614] [GetControllerMetricInfo] Métricas do controlador definidas para o pod: default/test-deployment3-84f8ccf757-5tmfc
W0129 14:03:34.667481       1 scheduler.go:125] [cacheMiss] Métricas não encontradas para o pod: default/test-deployment3-84f8ccf757-5tmfc
I0129 14:03:34.669509       1 scheduler.go:229] [OnAddPod] Adicionando pod default/test-deployment3-84f8ccf757-5tmfc com os seguintes detalhes:
I0129 14:03:34.953800       1 scheduler.go:70] Estado no Informer: map[acceptablePreemptionOverhead:10 controller:test-controller3 qosMeasuring:average]
I0129 14:03:34.954524       1 scheduler.go:71] Estado real no cluster: map[acceptablePreemptionOverhead:10 controller:test-controller3 qosMeasuring:average]
W0129 14:03:34.956757       1 scheduler.go:135] [WaitForPodsOnCache] Pod test-deployment3-84f8ccf757-5tmfc não encontrado no cache. Tentando novamente...
I0129 14:03:34.960229       1 types.go:743] [ControllerName] Verificando as anotações do pod default/test-deployment3-84f8ccf757-5tmfc
I0129 14:03:34.964551       1 types.go:761] [ControllerName] Anotação 'controller' encontrada para o pod default/test-deployment3-84f8ccf757-5tmfc: test-controller3
I0129 14:03:34.983954       1 scheduler.go:238] [OnAddPod] Atualizando métricas para o pod default/test-deployment3-84f8ccf757-5tmfc
I0129 14:03:34.984383       1 types.go:743] [ControllerName] Verificando as anotações do pod default/test-deployment3-84f8ccf757-5tmfc
I0129 14:03:34.984584       1 types.go:761] [ControllerName] Anotação 'controller' encontrada para o pod default/test-deployment3-84f8ccf757-5tmfc: test-controller3
I0129 14:03:34.984842       1 scheduler.go:251] [OnAddPod] Pod default/test-deployment3-84f8ccf757-5tmfc adicionado com sucesso
I0129 14:03:35.061227       1 scheduler.go:606] [GetControllerMetricInfo] Iniciando para o pod: default/test-deployment3-84f8ccf757-5tmfc
I0129 14:03:35.061270       1 scheduler.go:611] [GetControllerMetricInfo] Obtendo o nome do controlador para o pod: default/test-deployment3-84f8ccf757-5tmfc
I0129 14:03:35.061281       1 types.go:743] [ControllerName] Verificando as anotações do pod default/test-deployment3-84f8ccf757-5tmfc
I0129 14:03:35.061294       1 types.go:761] [ControllerName] Anotação 'controller' encontrada para o pod default/test-deployment3-84f8ccf757-5tmfc: test-controller3
I0129 14:03:35.061305       1 scheduler.go:614] [GetControllerMetricInfo] Métricas do controlador definidas para o pod: default/test-deployment3-84f8ccf757-5tmfc
I0129 14:03:35.076220       1 scheduler.go:70] Estado no Informer: map[acceptablePreemptionOverhead:10 controller:test-controller3 qosMeasuring:average]
I0129 14:03:35.076581       1 scheduler.go:71] Estado real no cluster: map[acceptablePreemptionOverhead:10 controller:test-controller3 qosMeasuring:average]
I0129 14:03:35.083058       1 scheduler.go:139] [WaitForPodsOnCache] Pod test-deployment3-84f8ccf757-5tmfc encontrado no cache.
I0129 14:03:35.083243       1 scheduler.go:117] [WaitForPodsOnCache] Verificando se o pod test-deployment2-7b58dbd49-l84n4 está no cache...
I0129 14:03:35.083255       1 scheduler.go:606] [GetControllerMetricInfo] Iniciando para o pod: default/test-deployment2-7b58dbd49-l84n4
I0129 14:03:35.083265       1 scheduler.go:611] [GetControllerMetricInfo] Obtendo o nome do controlador para o pod: default/test-deployment2-7b58dbd49-l84n4
I0129 14:03:35.083275       1 types.go:743] [ControllerName] Verificando as anotações do pod default/test-deployment2-7b58dbd49-l84n4
I0129 14:03:35.083288       1 types.go:761] [ControllerName] Anotação 'controller' encontrada para o pod default/test-deployment2-7b58dbd49-l84n4: test-controller2
I0129 14:03:35.083299       1 scheduler.go:614] [GetControllerMetricInfo] Métricas do controlador definidas para o pod: default/test-deployment2-7b58dbd49-l84n4
I0129 14:03:35.112369       1 scheduler.go:70] Estado no Informer: map[acceptablePreemptionOverhead:10 controller:test-controller2 qosMeasuring:average]
I0129 14:03:35.112472       1 scheduler.go:71] Estado real no cluster: map[acceptablePreemptionOverhead:10 controller:test-controller2 qosMeasuring:average]
I0129 14:03:35.112491       1 scheduler.go:139] [WaitForPodsOnCache] Pod test-deployment2-7b58dbd49-l84n4 encontrado no cache.
I0129 14:03:35.112502       1 scheduler.go:606] [GetControllerMetricInfo] Iniciando para o pod: default/test-deployment3-84f8ccf757-5tmfc
I0129 14:03:35.112513       1 scheduler.go:611] [GetControllerMetricInfo] Obtendo o nome do controlador para o pod: default/test-deployment3-84f8ccf757-5tmfc
I0129 14:03:35.112523       1 types.go:743] [ControllerName] Verificando as anotações do pod default/test-deployment3-84f8ccf757-5tmfc
I0129 14:03:35.112535       1 types.go:761] [ControllerName] Anotação 'controller' encontrada para o pod default/test-deployment3-84f8ccf757-5tmfc: test-controller3
I0129 14:03:35.113798       1 scheduler.go:614] [GetControllerMetricInfo] Métricas do controlador definidas para o pod: default/test-deployment3-84f8ccf757-5tmfc
I0129 14:03:35.113817       1 scheduler.go:606] [GetControllerMetricInfo] Iniciando para o pod: default/test-deployment2-7b58dbd49-l84n4
I0129 14:03:35.113826       1 scheduler.go:611] [GetControllerMetricInfo] Obtendo o nome do controlador para o pod: default/test-deployment2-7b58dbd49-l84n4
I0129 14:03:35.113835       1 types.go:743] [ControllerName] Verificando as anotações do pod default/test-deployment2-7b58dbd49-l84n4
I0129 14:03:35.113846       1 types.go:761] [ControllerName] Anotação 'controller' encontrada para o pod default/test-deployment2-7b58dbd49-l84n4: test-controller2
I0129 14:03:35.113856       1 scheduler.go:614] [GetControllerMetricInfo] Métricas do controlador definidas para o pod: default/test-deployment2-7b58dbd49-l84n4
I0129 14:03:35.113903       1 scheduler.go:98] [HigherPrecedence] Métricas para test-deployment3-84f8ccf757-5tmfc: QoS = -3.067190, Importância = 0.80
I0129 14:03:35.113933       1 scheduler.go:99] [HigherPrecedence] Métricas para test-deployment2-7b58dbd49-l84n4: QoS = 25.752871, Importância = 0.80
I0129 14:03:35.113946       1 scheduler.go:110] [HigherPrecedence] Decisão final: test-deployment3-84f8ccf757-5tmfc tem precedência sobre test-deployment2-7b58dbd49-l84n4? true
I0129 14:03:35.113956       1 types.go:743] [ControllerName] Verificando as anotações do pod default/test-deployment3-84f8ccf757-5tmfc
I0129 14:03:35.113965       1 types.go:761] [ControllerName] Anotação 'controller' encontrada para o pod default/test-deployment3-84f8ccf757-5tmfc: test-controller3
I0129 14:03:35.113971       1 types.go:743] [ControllerName] Verificando as anotações do pod default/test-deployment2-7b58dbd49-l84n4
I0129 14:03:35.113978       1 types.go:761] [ControllerName] Anotação 'controller' encontrada para o pod default/test-deployment2-7b58dbd49-l84n4: test-controller2
I0129 14:03:35.113987       1 scheduler.go:606] [GetControllerMetricInfo] Iniciando para o pod: default/test-deployment2-7b58dbd49-l84n4
I0129 14:03:35.113995       1 scheduler.go:611] [GetControllerMetricInfo] Obtendo o nome do controlador para o pod: default/test-deployment2-7b58dbd49-l84n4
I0129 14:03:35.114001       1 types.go:743] [ControllerName] Verificando as anotações do pod default/test-deployment2-7b58dbd49-l84n4
I0129 14:03:35.114008       1 types.go:761] [ControllerName] Anotação 'controller' encontrada para o pod default/test-deployment2-7b58dbd49-l84n4: test-controller2
I0129 14:03:35.114016       1 scheduler.go:614] [GetControllerMetricInfo] Métricas do controlador definidas para o pod: default/test-deployment2-7b58dbd49-l84n4
I0129 14:03:35.114024       1 scheduler.go:606] [GetControllerMetricInfo] Iniciando para o pod: default/test-deployment2-7b58dbd49-l84n4
I0129 14:03:35.114032       1 scheduler.go:611] [GetControllerMetricInfo] Obtendo o nome do controlador para o pod: default/test-deployment2-7b58dbd49-l84n4
I0129 14:03:35.114038       1 types.go:743] [ControllerName] Verificando as anotações do pod default/test-deployment2-7b58dbd49-l84n4
I0129 14:03:35.114046       1 types.go:761] [ControllerName] Anotação 'controller' encontrada para o pod default/test-deployment2-7b58dbd49-l84n4: test-controller2
I0129 14:03:35.114073       1 scheduler.go:614] [GetControllerMetricInfo] Métricas do controlador definidas para o pod: default/test-deployment2-7b58dbd49-l84n4
I0129 14:03:35.114082       1 types.go:743] [ControllerName] Verificando as anotações do pod default/test-deployment2-7b58dbd49-l84n4
I0129 14:03:35.114088       1 types.go:761] [ControllerName] Anotação 'controller' encontrada para o pod default/test-deployment2-7b58dbd49-l84n4: test-controller2
I0129 14:03:35.114618       1 scheduler.go:606] [GetControllerMetricInfo] Iniciando para o pod: default/test-deployment2-7b58dbd49-l84n4
I0129 14:03:35.114635       1 scheduler.go:611] [GetControllerMetricInfo] Obtendo o nome do controlador para o pod: default/test-deployment2-7b58dbd49-l84n4
I0129 14:03:35.114642       1 types.go:743] [ControllerName] Verificando as anotações do pod default/test-deployment2-7b58dbd49-l84n4
I0129 14:03:35.114651       1 types.go:761] [ControllerName] Anotação 'controller' encontrada para o pod default/test-deployment2-7b58dbd49-l84n4: test-controller2
I0129 14:03:35.114660       1 scheduler.go:614] [GetControllerMetricInfo] Métricas do controlador definidas para o pod: default/test-deployment2-7b58dbd49-l84n4
I0129 14:03:35.114736       1 scheduler.go:606] [GetControllerMetricInfo] Iniciando para o pod: default/test-deployment2-7b58dbd49-l84n4
I0129 14:03:35.114745       1 scheduler.go:611] [GetControllerMetricInfo] Obtendo o nome do controlador para o pod: default/test-deployment2-7b58dbd49-l84n4
I0129 14:03:35.114752       1 types.go:743] [ControllerName] Verificando as anotações do pod default/test-deployment2-7b58dbd49-l84n4
I0129 14:03:35.114759       1 types.go:761] [ControllerName] Anotação 'controller' encontrada para o pod default/test-deployment2-7b58dbd49-l84n4: test-controller2
I0129 14:03:35.114829       1 scheduler.go:614] [GetControllerMetricInfo] Métricas do controlador definidas para o pod: default/test-deployment2-7b58dbd49-l84n4
I0129 14:03:35.114862       1 postFilter.go:147] [PREEMPT CALL] The node minikube  was chosen to allocate pod test-deployment3-84f8ccf757-5tmfc
I0129 14:03:35.114877       1 postFilter.go:151] [Preempt] Iniciando a remoção dos pods preemptados no nó minikube para alocar o pod default/test-deployment3-84f8ccf757-5tmfc. Total de vítimas: 1
I0129 14:03:35.114936       1 postFilter.go:155] [Preempt] Tentando remover o pod default/test-deployment2-7b58dbd49-l84n4 no nó minikube
I0129 14:03:35.204450       1 scheduler.go:258] [OnUpdatePod] Iniciando processamento de atualização de pod
I0129 14:03:35.204589       1 scheduler.go:262] [OnUpdatePod] Pod atualizado detectado: default/test-deployment2-7b58dbd49-l84n4, Anotações: map[acceptablePreemptionOverhead:10 controller:test-controller2 qosMeasuring:average]
I0129 14:03:35.205448       1 scheduler.go:265] [OnUpdatePod] Comparando estado no Informer e estado real no cluster para o pod default/test-deployment2-7b58dbd49-l84n4
E0129 14:03:35.290634       1 scheduler.go:67] Erro ao buscar estado real do pod test-deployment2-7b58dbd49-l84n4: pods "test-deployment2-7b58dbd49-l84n4" not found
I0129 14:03:35.290705       1 scheduler.go:275] [OnUpdatePod] Atualizando informações de métricas para o pod default/test-deployment2-7b58dbd49-l84n4
I0129 14:03:35.290715       1 types.go:743] [ControllerName] Verificando as anotações do pod default/test-deployment2-7b58dbd49-l84n4
I0129 14:03:35.290722       1 types.go:761] [ControllerName] Anotação 'controller' encontrada para o pod default/test-deployment2-7b58dbd49-l84n4: test-controller2
I0129 14:03:35.290733       1 scheduler.go:277] [OnUpdatePod] Atualizando 'LastStatus' do pod default/test-deployment2-7b58dbd49-l84n4 nas métricas
I0129 14:03:35.290737       1 scheduler.go:279] [OnUpdatePod] Métrica atualizada para o pod default/test-deployment2-7b58dbd49-l84n4
I0129 14:03:35.290749       1 scheduler.go:283] [OnUpdatePod] Finalizando processamento de atualização de pod para default/test-deployment2-7b58dbd49-l84n4
I0129 14:03:35.290822       1 types.go:743] [ControllerName] Verificando as anotações do pod default/test-deployment2-7b58dbd49-l84n4
I0129 14:03:35.290828       1 types.go:761] [ControllerName] Anotação 'controller' encontrada para o pod default/test-deployment2-7b58dbd49-l84n4: test-controller2
I0129 14:03:35.311058       1 postFilter.go:168] [Preempt] Pod default/test-deployment2-7b58dbd49-l84n4 removido com sucesso no nó minikube
I0129 14:03:35.311100       1 postFilter.go:174] test-deployment2-7b58dbd49-l84n4_default preempted by test-deployment3-84f8ccf757-5tmfc_default on node minikube
I0129 14:03:35.316179       1 postFilter.go:179] [Preempt] Total de pods preemptados no nó minikube: 1
I0129 14:03:35.316287       1 postFilter.go:186] [Preempt] Verificando pods de menor precedência no nó minikube que precisam ter o campo NominatedNodeName limpo
I0129 14:03:35.316304       1 postFilter.go:196] [Preempt] Finalizado para o nó minikube. Pod default/test-deployment3-84f8ccf757-5tmfc deve ser alocado agora.
I0129 14:03:35.316315       1 postFilter.go:49] [PostFilter] Nó nominado para o pod default/test-deployment3-84f8ccf757-5tmfc: minikube
I0129 14:03:35.323395       1 scheduler.go:291] [OnDeletePod] Iniciando a execução do OnDeletePod
I0129 14:03:35.323461       1 scheduler.go:300] [OnDeletePod] DeepCopy realizado para o pod default/test-deployment2-7b58dbd49-l84n4
I0129 14:03:35.323822       1 scheduler.go:307] [OnDeletePod] Pod deletado detectado: default/test-deployment2-7b58dbd49-l84n4
I0129 14:03:35.329299       1 scheduler.go:309] [OnDeletePod] Atualizando métricas do pod default/test-deployment2-7b58dbd49-l84n4
I0129 14:03:35.329358       1 types.go:743] [ControllerName] Verificando as anotações do pod default/test-deployment2-7b58dbd49-l84n4
I0129 14:03:35.329366       1 types.go:761] [ControllerName] Anotação 'controller' encontrada para o pod default/test-deployment2-7b58dbd49-l84n4: test-controller2
I0129 14:03:35.329378       1 scheduler.go:311] [OnDeletePod] Verificando o estado do pod default/test-deployment2-7b58dbd49-l84n4 nas métricas
I0129 14:03:35.329384       1 scheduler.go:321] [OnDeletePod] EndTime atualizado para o pod default/test-deployment2-7b58dbd49-l84n4: 2025-01-29 14:03:35.329380742 +0000 UTC m=+188.432935839
I0129 14:03:35.329413       1 scheduler.go:325] [OnDeletePod] Finalizando a execução do OnDeletePod para o pod default/test-deployment2-7b58dbd49-l84n4
I0129 14:03:35.329455       1 scheduler.go:218] [OnAddPod] Pod adicionado: default/test-deployment2-7b58dbd49-24pwt, Anotações: map[acceptablePreemptionOverhead:10 controller:test-controller2 qosMeasuring:average]
I0129 14:03:35.374669       1 scheduler.go:70] Estado no Informer: map[acceptablePreemptionOverhead:10 controller:test-controller2 qosMeasuring:average]
I0129 14:03:35.374854       1 scheduler.go:71] Estado real no cluster: map[acceptablePreemptionOverhead:10 controller:test-controller2 qosMeasuring:average]
I0129 14:03:35.377803       1 scheduler.go:229] [OnAddPod] Adicionando pod default/test-deployment2-7b58dbd49-24pwt com os seguintes detalhes:
I0129 14:03:35.377942       1 types.go:743] [ControllerName] Verificando as anotações do pod default/test-deployment2-7b58dbd49-24pwt
I0129 14:03:35.377965       1 types.go:761] [ControllerName] Anotação 'controller' encontrada para o pod default/test-deployment2-7b58dbd49-24pwt: test-controller2
I0129 14:03:35.378409       1 scheduler.go:238] [OnAddPod] Atualizando métricas para o pod default/test-deployment2-7b58dbd49-24pwt
I0129 14:03:35.378604       1 types.go:743] [ControllerName] Verificando as anotações do pod default/test-deployment2-7b58dbd49-24pwt
I0129 14:03:35.378638       1 types.go:761] [ControllerName] Anotação 'controller' encontrada para o pod default/test-deployment2-7b58dbd49-24pwt: test-controller2
I0129 14:03:35.378703       1 scheduler.go:251] [OnAddPod] Pod default/test-deployment2-7b58dbd49-24pwt adicionado com sucesso
I0129 14:03:35.383749       1 postFilter.go:29] [PostFilter] PostFilter chamado para pod: default/test-deployment2-7b58dbd49-24pwt
I0129 14:03:35.383847       1 postFilter.go:76] [Preempt] Comparando pod original com o atualizado...
I0129 14:03:35.383875       1 postFilter.go:83] [Preempt] Successfully retrieved updated pod default/test-deployment2-7b58dbd49-24pwt from lister
I0129 14:03:35.396515       1 scheduler.go:258] [OnUpdatePod] Iniciando processamento de atualização de pod
I0129 14:03:35.396958       1 scheduler.go:262] [OnUpdatePod] Pod atualizado detectado: default/test-deployment3-84f8ccf757-5tmfc, Anotações: map[acceptablePreemptionOverhead:10 controller:test-controller3 qosMeasuring:average]
I0129 14:03:35.398862       1 scheduler.go:265] [OnUpdatePod] Comparando estado no Informer e estado real no cluster para o pod default/test-deployment3-84f8ccf757-5tmfc
I0129 14:03:35.710615       1 scheduler.go:70] Estado no Informer: map[acceptablePreemptionOverhead:10 controller:test-controller3 qosMeasuring:average]
I0129 14:03:35.710711       1 scheduler.go:71] Estado real no cluster: map[acceptablePreemptionOverhead:10 controller:test-controller3 qosMeasuring:average]
I0129 14:03:35.710735       1 scheduler.go:275] [OnUpdatePod] Atualizando informações de métricas para o pod default/test-deployment3-84f8ccf757-5tmfc
I0129 14:03:35.710748       1 types.go:743] [ControllerName] Verificando as anotações do pod default/test-deployment3-84f8ccf757-5tmfc
I0129 14:03:35.711257       1 types.go:761] [ControllerName] Anotação 'controller' encontrada para o pod default/test-deployment3-84f8ccf757-5tmfc: test-controller3
I0129 14:03:35.711276       1 scheduler.go:277] [OnUpdatePod] Atualizando 'LastStatus' do pod default/test-deployment3-84f8ccf757-5tmfc nas métricas
I0129 14:03:35.711284       1 scheduler.go:279] [OnUpdatePod] Métrica atualizada para o pod default/test-deployment3-84f8ccf757-5tmfc
I0129 14:03:35.711301       1 scheduler.go:283] [OnUpdatePod] Finalizando processamento de atualização de pod para default/test-deployment3-84f8ccf757-5tmfc
I0129 14:03:35.718925       1 postFilter.go:233] [compareNodeResources] Recursos calculados no nó minikube: CPU = 750 mCPU, Memória = 178257920 bytes
I0129 14:03:35.718989       1 postFilter.go:234] [compareNodeResources] Recursos do snapshot no nó minikube: CPU = 750 mCPU, Memória = 178257920 bytes
I0129 14:03:35.719002       1 postFilter.go:240] [compareNodeResources] Recursos de CPU do nó minikube estão sincronizados: 750 mCPU
I0129 14:03:35.719013       1 postFilter.go:246] [compareNodeResources] Recursos de memória do nó minikube estão sincronizados: 178257920 bytes
I0129 14:03:35.736099       1 postFilter.go:147] [PREEMPT CALL] The node minikube  was chosen to allocate pod test-deployment2-7b58dbd49-24pwt
I0129 14:03:35.736206       1 postFilter.go:151] [Preempt] Iniciando a remoção dos pods preemptados no nó minikube para alocar o pod default/test-deployment2-7b58dbd49-24pwt. Total de vítimas: 0
I0129 14:03:35.736230       1 postFilter.go:179] [Preempt] Total de pods preemptados no nó minikube: 0
I0129 14:03:35.736293       1 scheduler.go:84] [HigherPrecedence] Calculando precedência entre test-deployment2-7b58dbd49-24pwt e test-deployment3-84f8ccf757-5tmfc
I0129 14:03:35.736301       1 scheduler.go:117] [WaitForPodsOnCache] Verificando se o pod test-deployment2-7b58dbd49-24pwt está no cache...
I0129 14:03:35.736311       1 scheduler.go:606] [GetControllerMetricInfo] Iniciando para o pod: default/test-deployment2-7b58dbd49-24pwt
I0129 14:03:35.736318       1 scheduler.go:611] [GetControllerMetricInfo] Obtendo o nome do controlador para o pod: default/test-deployment2-7b58dbd49-24pwt
I0129 14:03:35.736328       1 types.go:743] [ControllerName] Verificando as anotações do pod default/test-deployment2-7b58dbd49-24pwt
I0129 14:03:35.736337       1 types.go:761] [ControllerName] Anotação 'controller' encontrada para o pod default/test-deployment2-7b58dbd49-24pwt: test-controller2
I0129 14:03:35.736351       1 scheduler.go:614] [GetControllerMetricInfo] Métricas do controlador definidas para o pod: default/test-deployment2-7b58dbd49-24pwt
I0129 14:03:35.741588       1 scheduler.go:70] Estado no Informer: map[acceptablePreemptionOverhead:10 controller:test-controller2 qosMeasuring:average]
I0129 14:03:35.742725       1 scheduler.go:71] Estado real no cluster: map[acceptablePreemptionOverhead:10 controller:test-controller2 qosMeasuring:average]
I0129 14:03:35.742869       1 scheduler.go:139] [WaitForPodsOnCache] Pod test-deployment2-7b58dbd49-24pwt encontrado no cache.
I0129 14:03:35.742877       1 scheduler.go:117] [WaitForPodsOnCache] Verificando se o pod test-deployment3-84f8ccf757-5tmfc está no cache...
I0129 14:03:35.742885       1 scheduler.go:606] [GetControllerMetricInfo] Iniciando para o pod: default/test-deployment3-84f8ccf757-5tmfc
I0129 14:03:35.742979       1 scheduler.go:611] [GetControllerMetricInfo] Obtendo o nome do controlador para o pod: default/test-deployment3-84f8ccf757-5tmfc
I0129 14:03:35.742988       1 types.go:743] [ControllerName] Verificando as anotações do pod default/test-deployment3-84f8ccf757-5tmfc
I0129 14:03:35.742998       1 types.go:761] [ControllerName] Anotação 'controller' encontrada para o pod default/test-deployment3-84f8ccf757-5tmfc: test-controller3
I0129 14:03:35.743007       1 scheduler.go:614] [GetControllerMetricInfo] Métricas do controlador definidas para o pod: default/test-deployment3-84f8ccf757-5tmfc
I0129 14:03:35.753698       1 scheduler.go:70] Estado no Informer: map[acceptablePreemptionOverhead:10 controller:test-controller3 qosMeasuring:average]
I0129 14:03:35.753824       1 scheduler.go:71] Estado real no cluster: map[acceptablePreemptionOverhead:10 controller:test-controller3 qosMeasuring:average]
I0129 14:03:35.753854       1 scheduler.go:139] [WaitForPodsOnCache] Pod test-deployment3-84f8ccf757-5tmfc encontrado no cache.
I0129 14:03:35.753944       1 scheduler.go:606] [GetControllerMetricInfo] Iniciando para o pod: default/test-deployment2-7b58dbd49-24pwt
I0129 14:03:35.753966       1 scheduler.go:611] [GetControllerMetricInfo] Obtendo o nome do controlador para o pod: default/test-deployment2-7b58dbd49-24pwt
I0129 14:03:35.753985       1 types.go:743] [ControllerName] Verificando as anotações do pod default/test-deployment2-7b58dbd49-24pwt
I0129 14:03:35.754053       1 types.go:761] [ControllerName] Anotação 'controller' encontrada para o pod default/test-deployment2-7b58dbd49-24pwt: test-controller2
I0129 14:03:35.754073       1 scheduler.go:614] [GetControllerMetricInfo] Métricas do controlador definidas para o pod: default/test-deployment2-7b58dbd49-24pwt
I0129 14:03:35.754094       1 scheduler.go:606] [GetControllerMetricInfo] Iniciando para o pod: default/test-deployment3-84f8ccf757-5tmfc
I0129 14:03:35.754162       1 scheduler.go:611] [GetControllerMetricInfo] Obtendo o nome do controlador para o pod: default/test-deployment3-84f8ccf757-5tmfc
I0129 14:03:35.754212       1 types.go:743] [ControllerName] Verificando as anotações do pod default/test-deployment3-84f8ccf757-5tmfc
I0129 14:03:35.754302       1 types.go:761] [ControllerName] Anotação 'controller' encontrada para o pod default/test-deployment3-84f8ccf757-5tmfc: test-controller3
I0129 14:03:35.754363       1 scheduler.go:614] [GetControllerMetricInfo] Métricas do controlador definidas para o pod: default/test-deployment3-84f8ccf757-5tmfc
I0129 14:03:35.754395       1 scheduler.go:98] [HigherPrecedence] Métricas para test-deployment2-7b58dbd49-24pwt: QoS = 25.195635, Importância = 0.80
I0129 14:03:35.755418       1 scheduler.go:99] [HigherPrecedence] Métricas para test-deployment3-84f8ccf757-5tmfc: QoS = -4.136286, Importância = 0.80
I0129 14:03:35.755579       1 scheduler.go:110] [HigherPrecedence] Decisão final: test-deployment2-7b58dbd49-24pwt tem precedência sobre test-deployment3-84f8ccf757-5tmfc? false
I0129 14:03:35.755614       1 postFilter.go:186] [Preempt] Verificando pods de menor precedência no nó minikube que precisam ter o campo NominatedNodeName limpo
I0129 14:03:35.755773       1 postFilter.go:196] [Preempt] Finalizado para o nó minikube. Pod default/test-deployment2-7b58dbd49-24pwt deve ser alocado agora.
I0129 14:03:35.755908       1 postFilter.go:49] [PostFilter] Nó nominado para o pod default/test-deployment2-7b58dbd49-24pwt: minikube
I0129 14:03:36.179685       1 scheduler.go:258] [OnUpdatePod] Iniciando processamento de atualização de pod
I0129 14:03:36.179801       1 scheduler.go:262] [OnUpdatePod] Pod atualizado detectado: default/test-deployment2-7b58dbd49-24pwt, Anotações: map[acceptablePreemptionOverhead:10 controller:test-controller2 qosMeasuring:average]
I0129 14:03:36.179837       1 scheduler.go:265] [OnUpdatePod] Comparando estado no Informer e estado real no cluster para o pod default/test-deployment2-7b58dbd49-24pwt
I0129 14:03:36.197821       1 scheduler.go:70] Estado no Informer: map[acceptablePreemptionOverhead:10 controller:test-controller2 qosMeasuring:average]
I0129 14:03:36.197930       1 scheduler.go:71] Estado real no cluster: map[acceptablePreemptionOverhead:10 controller:test-controller2 qosMeasuring:average]
I0129 14:03:36.197961       1 scheduler.go:275] [OnUpdatePod] Atualizando informações de métricas para o pod default/test-deployment2-7b58dbd49-24pwt
I0129 14:03:36.197977       1 types.go:743] [ControllerName] Verificando as anotações do pod default/test-deployment2-7b58dbd49-24pwt
I0129 14:03:36.197991       1 types.go:761] [ControllerName] Anotação 'controller' encontrada para o pod default/test-deployment2-7b58dbd49-24pwt: test-controller2
I0129 14:03:36.198010       1 scheduler.go:277] [OnUpdatePod] Atualizando 'LastStatus' do pod default/test-deployment2-7b58dbd49-24pwt nas métricas
I0129 14:03:36.198030       1 scheduler.go:279] [OnUpdatePod] Métrica atualizada para o pod default/test-deployment2-7b58dbd49-24pwt
I0129 14:03:36.198052       1 scheduler.go:283] [OnUpdatePod] Finalizando processamento de atualização de pod para default/test-deployment2-7b58dbd49-24pwt
I0129 14:03:36.490408       1 postFilter.go:29] [PostFilter] PostFilter chamado para pod: default/test-deployment3-84f8ccf757-5tmfc
I0129 14:03:36.490512       1 postFilter.go:76] [Preempt] Comparando pod original com o atualizado...
I0129 14:03:36.490535       1 postFilter.go:83] [Preempt] Successfully retrieved updated pod default/test-deployment3-84f8ccf757-5tmfc from lister
I0129 14:03:36.512906       1 postFilter.go:233] [compareNodeResources] Recursos calculados no nó minikube: CPU = 750 mCPU, Memória = 178257920 bytes
I0129 14:03:36.512999       1 postFilter.go:234] [compareNodeResources] Recursos do snapshot no nó minikube: CPU = 750 mCPU, Memória = 178257920 bytes
I0129 14:03:36.513020       1 postFilter.go:240] [compareNodeResources] Recursos de CPU do nó minikube estão sincronizados: 750 mCPU
I0129 14:03:36.513095       1 postFilter.go:246] [compareNodeResources] Recursos de memória do nó minikube estão sincronizados: 178257920 bytes
I0129 14:03:36.520004       1 postFilter.go:147] [PREEMPT CALL] The node minikube  was chosen to allocate pod test-deployment3-84f8ccf757-5tmfc
I0129 14:03:36.520241       1 postFilter.go:151] [Preempt] Iniciando a remoção dos pods preemptados no nó minikube para alocar o pod default/test-deployment3-84f8ccf757-5tmfc. Total de vítimas: 0
I0129 14:03:36.520375       1 postFilter.go:179] [Preempt] Total de pods preemptados no nó minikube: 0
W0129 14:03:36.520647       1 scheduler.go:79] [HigherPrecedence] Tentativa de comparar o pod test-deployment3-84f8ccf757-5tmfc consigo mesmo. Retornando false.
I0129 14:03:36.520718       1 scheduler.go:84] [HigherPrecedence] Calculando precedência entre test-deployment3-84f8ccf757-5tmfc e test-deployment2-7b58dbd49-24pwt
I0129 14:03:36.520730       1 scheduler.go:117] [WaitForPodsOnCache] Verificando se o pod test-deployment3-84f8ccf757-5tmfc está no cache...
I0129 14:03:36.520871       1 scheduler.go:606] [GetControllerMetricInfo] Iniciando para o pod: default/test-deployment3-84f8ccf757-5tmfc
I0129 14:03:36.521008       1 scheduler.go:611] [GetControllerMetricInfo] Obtendo o nome do controlador para o pod: default/test-deployment3-84f8ccf757-5tmfc
I0129 14:03:36.521741       1 types.go:743] [ControllerName] Verificando as anotações do pod default/test-deployment3-84f8ccf757-5tmfc
I0129 14:03:36.521892       1 types.go:761] [ControllerName] Anotação 'controller' encontrada para o pod default/test-deployment3-84f8ccf757-5tmfc: test-controller3
I0129 14:03:36.522036       1 scheduler.go:614] [GetControllerMetricInfo] Métricas do controlador definidas para o pod: default/test-deployment3-84f8ccf757-5tmfc
I0129 14:03:36.535497       1 scheduler.go:70] Estado no Informer: map[acceptablePreemptionOverhead:10 controller:test-controller3 qosMeasuring:average]
I0129 14:03:36.535531       1 scheduler.go:71] Estado real no cluster: map[acceptablePreemptionOverhead:10 controller:test-controller3 qosMeasuring:average]
I0129 14:03:36.535542       1 scheduler.go:139] [WaitForPodsOnCache] Pod test-deployment3-84f8ccf757-5tmfc encontrado no cache.
I0129 14:03:36.535548       1 scheduler.go:117] [WaitForPodsOnCache] Verificando se o pod test-deployment2-7b58dbd49-24pwt está no cache...
I0129 14:03:36.535555       1 scheduler.go:606] [GetControllerMetricInfo] Iniciando para o pod: default/test-deployment2-7b58dbd49-24pwt
I0129 14:03:36.535561       1 scheduler.go:611] [GetControllerMetricInfo] Obtendo o nome do controlador para o pod: default/test-deployment2-7b58dbd49-24pwt
I0129 14:03:36.535569       1 types.go:743] [ControllerName] Verificando as anotações do pod default/test-deployment2-7b58dbd49-24pwt
I0129 14:03:36.535576       1 types.go:761] [ControllerName] Anotação 'controller' encontrada para o pod default/test-deployment2-7b58dbd49-24pwt: test-controller2
I0129 14:03:36.535583       1 scheduler.go:614] [GetControllerMetricInfo] Métricas do controlador definidas para o pod: default/test-deployment2-7b58dbd49-24pwt
I0129 14:03:36.541908       1 scheduler.go:70] Estado no Informer: map[acceptablePreemptionOverhead:10 controller:test-controller2 qosMeasuring:average]
I0129 14:03:36.542091       1 scheduler.go:71] Estado real no cluster: map[acceptablePreemptionOverhead:10 controller:test-controller2 qosMeasuring:average]
I0129 14:03:36.542106       1 scheduler.go:139] [WaitForPodsOnCache] Pod test-deployment2-7b58dbd49-24pwt encontrado no cache.
I0129 14:03:36.542222       1 scheduler.go:606] [GetControllerMetricInfo] Iniciando para o pod: default/test-deployment3-84f8ccf757-5tmfc
I0129 14:03:36.542229       1 scheduler.go:611] [GetControllerMetricInfo] Obtendo o nome do controlador para o pod: default/test-deployment3-84f8ccf757-5tmfc
I0129 14:03:36.542328       1 types.go:743] [ControllerName] Verificando as anotações do pod default/test-deployment3-84f8ccf757-5tmfc
I0129 14:03:36.542341       1 types.go:761] [ControllerName] Anotação 'controller' encontrada para o pod default/test-deployment3-84f8ccf757-5tmfc: test-controller3
I0129 14:03:36.542458       1 scheduler.go:614] [GetControllerMetricInfo] Métricas do controlador definidas para o pod: default/test-deployment3-84f8ccf757-5tmfc
I0129 14:03:36.542682       1 scheduler.go:606] [GetControllerMetricInfo] Iniciando para o pod: default/test-deployment2-7b58dbd49-24pwt
I0129 14:03:36.542708       1 scheduler.go:611] [GetControllerMetricInfo] Obtendo o nome do controlador para o pod: default/test-deployment2-7b58dbd49-24pwt
I0129 14:03:36.542843       1 types.go:743] [ControllerName] Verificando as anotações do pod default/test-deployment2-7b58dbd49-24pwt
I0129 14:03:36.542851       1 types.go:761] [ControllerName] Anotação 'controller' encontrada para o pod default/test-deployment2-7b58dbd49-24pwt: test-controller2
I0129 14:03:36.542857       1 scheduler.go:614] [GetControllerMetricInfo] Métricas do controlador definidas para o pod: default/test-deployment2-7b58dbd49-24pwt
I0129 14:03:36.542960       1 scheduler.go:98] [HigherPrecedence] Métricas para test-deployment3-84f8ccf757-5tmfc: QoS = -4.920711, Importância = 0.80
I0129 14:03:36.542975       1 scheduler.go:99] [HigherPrecedence] Métricas para test-deployment2-7b58dbd49-24pwt: QoS = 24.411209, Importância = 0.80
I0129 14:03:36.543072       1 scheduler.go:110] [HigherPrecedence] Decisão final: test-deployment3-84f8ccf757-5tmfc tem precedência sobre test-deployment2-7b58dbd49-24pwt? true
I0129 14:03:36.543095       1 postFilter.go:186] [Preempt] Verificando pods de menor precedência no nó minikube que precisam ter o campo NominatedNodeName limpo
I0129 14:03:36.543213       1 postFilter.go:188] [Preempt] Limpando o campo NominatedNodeName do pod default/test-deployment2-7b58dbd49-24pwt
I0129 14:03:36.684839       1 scheduler.go:258] [OnUpdatePod] Iniciando processamento de atualização de pod
I0129 14:03:36.684943       1 scheduler.go:262] [OnUpdatePod] Pod atualizado detectado: default/test-deployment2-7b58dbd49-24pwt, Anotações: map[acceptablePreemptionOverhead:10 controller:test-controller2 qosMeasuring:average]
I0129 14:03:36.684987       1 scheduler.go:265] [OnUpdatePod] Comparando estado no Informer e estado real no cluster para o pod default/test-deployment2-7b58dbd49-24pwt
I0129 14:03:36.709260       1 postFilter.go:196] [Preempt] Finalizado para o nó minikube. Pod default/test-deployment3-84f8ccf757-5tmfc deve ser alocado agora.
I0129 14:03:36.709380       1 postFilter.go:49] [PostFilter] Nó nominado para o pod default/test-deployment3-84f8ccf757-5tmfc: minikube
I0129 14:03:36.710186       1 scheduler.go:70] Estado no Informer: map[acceptablePreemptionOverhead:10 controller:test-controller2 qosMeasuring:average]
I0129 14:03:36.710213       1 scheduler.go:71] Estado real no cluster: map[acceptablePreemptionOverhead:10 controller:test-controller2 qosMeasuring:average]
I0129 14:03:36.710228       1 scheduler.go:275] [OnUpdatePod] Atualizando informações de métricas para o pod default/test-deployment2-7b58dbd49-24pwt
I0129 14:03:36.717209       1 types.go:743] [ControllerName] Verificando as anotações do pod default/test-deployment2-7b58dbd49-24pwt
I0129 14:03:36.717233       1 types.go:761] [ControllerName] Anotação 'controller' encontrada para o pod default/test-deployment2-7b58dbd49-24pwt: test-controller2
I0129 14:03:36.717298       1 scheduler.go:277] [OnUpdatePod] Atualizando 'LastStatus' do pod default/test-deployment2-7b58dbd49-24pwt nas métricas
I0129 14:03:36.717307       1 scheduler.go:279] [OnUpdatePod] Métrica atualizada para o pod default/test-deployment2-7b58dbd49-24pwt
I0129 14:03:36.717321       1 scheduler.go:283] [OnUpdatePod] Finalizando processamento de atualização de pod para default/test-deployment2-7b58dbd49-24pwt
I0129 14:03:58.339832       1 scheduler.go:54] [QueueSort] Comparando prioridade de test-deployment3-84f8ccf757-5tmfc com test-deployment2-7b58dbd49-24pwt
I0129 14:03:58.340834       1 scheduler.go:84] [HigherPrecedence] Calculando precedência entre test-deployment3-84f8ccf757-5tmfc e test-deployment2-7b58dbd49-24pwt
I0129 14:03:58.343067       1 scheduler.go:117] [WaitForPodsOnCache] Verificando se o pod test-deployment3-84f8ccf757-5tmfc está no cache...
I0129 14:03:58.343271       1 scheduler.go:606] [GetControllerMetricInfo] Iniciando para o pod: default/test-deployment3-84f8ccf757-5tmfc
I0129 14:03:58.343291       1 scheduler.go:611] [GetControllerMetricInfo] Obtendo o nome do controlador para o pod: default/test-deployment3-84f8ccf757-5tmfc
I0129 14:03:58.343306       1 types.go:743] [ControllerName] Verificando as anotações do pod default/test-deployment3-84f8ccf757-5tmfc
I0129 14:03:58.343322       1 types.go:761] [ControllerName] Anotação 'controller' encontrada para o pod default/test-deployment3-84f8ccf757-5tmfc: test-controller3
I0129 14:03:58.344241       1 scheduler.go:614] [GetControllerMetricInfo] Métricas do controlador definidas para o pod: default/test-deployment3-84f8ccf757-5tmfc
I0129 14:03:58.360618       1 scheduler.go:70] Estado no Informer: map[acceptablePreemptionOverhead:10 controller:test-controller3 qosMeasuring:average]
I0129 14:03:58.360712       1 scheduler.go:71] Estado real no cluster: map[acceptablePreemptionOverhead:10 controller:test-controller3 qosMeasuring:average]
I0129 14:03:58.360732       1 scheduler.go:139] [WaitForPodsOnCache] Pod test-deployment3-84f8ccf757-5tmfc encontrado no cache.
I0129 14:03:58.360744       1 scheduler.go:117] [WaitForPodsOnCache] Verificando se o pod test-deployment2-7b58dbd49-24pwt está no cache...
I0129 14:03:58.360757       1 scheduler.go:606] [GetControllerMetricInfo] Iniciando para o pod: default/test-deployment2-7b58dbd49-24pwt
I0129 14:03:58.360770       1 scheduler.go:611] [GetControllerMetricInfo] Obtendo o nome do controlador para o pod: default/test-deployment2-7b58dbd49-24pwt
I0129 14:03:58.360783       1 types.go:743] [ControllerName] Verificando as anotações do pod default/test-deployment2-7b58dbd49-24pwt
I0129 14:03:58.360796       1 types.go:761] [ControllerName] Anotação 'controller' encontrada para o pod default/test-deployment2-7b58dbd49-24pwt: test-controller2
I0129 14:03:58.360811       1 scheduler.go:614] [GetControllerMetricInfo] Métricas do controlador definidas para o pod: default/test-deployment2-7b58dbd49-24pwt
I0129 14:03:58.374238       1 scheduler.go:70] Estado no Informer: map[acceptablePreemptionOverhead:10 controller:test-controller2 qosMeasuring:average]
I0129 14:03:58.374365       1 scheduler.go:71] Estado real no cluster: map[acceptablePreemptionOverhead:10 controller:test-controller2 qosMeasuring:average]
I0129 14:03:58.374389       1 scheduler.go:139] [WaitForPodsOnCache] Pod test-deployment2-7b58dbd49-24pwt encontrado no cache.
I0129 14:03:58.374403       1 scheduler.go:606] [GetControllerMetricInfo] Iniciando para o pod: default/test-deployment3-84f8ccf757-5tmfc
I0129 14:03:58.374416       1 scheduler.go:611] [GetControllerMetricInfo] Obtendo o nome do controlador para o pod: default/test-deployment3-84f8ccf757-5tmfc
I0129 14:03:58.374429       1 types.go:743] [ControllerName] Verificando as anotações do pod default/test-deployment3-84f8ccf757-5tmfc
I0129 14:03:58.374442       1 types.go:761] [ControllerName] Anotação 'controller' encontrada para o pod default/test-deployment3-84f8ccf757-5tmfc: test-controller3
I0129 14:03:58.374456       1 scheduler.go:614] [GetControllerMetricInfo] Métricas do controlador definidas para o pod: default/test-deployment3-84f8ccf757-5tmfc
I0129 14:03:58.374486       1 scheduler.go:606] [GetControllerMetricInfo] Iniciando para o pod: default/test-deployment2-7b58dbd49-24pwt
I0129 14:03:58.374498       1 scheduler.go:611] [GetControllerMetricInfo] Obtendo o nome do controlador para o pod: default/test-deployment2-7b58dbd49-24pwt
I0129 14:03:58.374507       1 types.go:743] [ControllerName] Verificando as anotações do pod default/test-deployment2-7b58dbd49-24pwt
I0129 14:03:58.374518       1 types.go:761] [ControllerName] Anotação 'controller' encontrada para o pod default/test-deployment2-7b58dbd49-24pwt: test-controller2
I0129 14:03:58.374530       1 scheduler.go:614] [GetControllerMetricInfo] Métricas do controlador definidas para o pod: default/test-deployment2-7b58dbd49-24pwt
I0129 14:03:58.374571       1 scheduler.go:98] [HigherPrecedence] Métricas para test-deployment3-84f8ccf757-5tmfc: QoS = -26.740609, Importância = 0.80
I0129 14:03:58.374593       1 scheduler.go:99] [HigherPrecedence] Métricas para test-deployment2-7b58dbd49-24pwt: QoS = 2.591312, Importância = 0.80
I0129 14:03:58.374610       1 scheduler.go:110] [HigherPrecedence] Decisão final: test-deployment3-84f8ccf757-5tmfc tem precedência sobre test-deployment2-7b58dbd49-24pwt? true
I0129 14:03:58.374626       1 scheduler.go:60] [QueueSort] Precedência determinada: test-deployment3-84f8ccf757-5tmfc tem precedência sobre test-deployment2-7b58dbd49-24pwt? true
I0129 14:03:58.382099       1 scheduler.go:146] [Reserve] resources reserved at node minikube for pod test-deployment3-84f8ccf757-5tmfc_default at 2025-01-29 14:03:58.382081502 +0000 UTC m=+211.485636793
I0129 14:03:58.382576       1 types.go:743] [ControllerName] Verificando as anotações do pod default/test-deployment3-84f8ccf757-5tmfc
I0129 14:03:58.382817       1 types.go:761] [ControllerName] Anotação 'controller' encontrada para o pod default/test-deployment3-84f8ccf757-5tmfc: test-controller3
I0129 14:03:58.382998       1 scheduler.go:148] [Reserve] Status de alocação atual para o pod test-deployment3-84f8ccf757-5tmfc_default: 
I0129 14:03:58.383277       1 scheduler.go:150] [Reserve] Status de alocação atualizado para o pod test-deployment3-84f8ccf757-5tmfc_default: allocating
I0129 14:03:58.386853       1 postFilter.go:29] [PostFilter] PostFilter chamado para pod: default/test-deployment2-7b58dbd49-24pwt
I0129 14:03:58.387238       1 postFilter.go:76] [Preempt] Comparando pod original com o atualizado...
I0129 14:03:58.387417       1 postFilter.go:83] [Preempt] Successfully retrieved updated pod default/test-deployment2-7b58dbd49-24pwt from lister
I0129 14:03:58.389265       1 scheduler.go:174] [PreBind] Validando o pod test-deployment3-84f8ccf757-5tmfc antes de vincular ao node minikube
I0129 14:03:58.396253       1 postFilter.go:233] [compareNodeResources] Recursos calculados no nó minikube: CPU = 1450 mCPU, Memória = 459276288 bytes
I0129 14:03:58.396581       1 postFilter.go:234] [compareNodeResources] Recursos do snapshot no nó minikube: CPU = 1450 mCPU, Memória = 459276288 bytes
I0129 14:03:58.396633       1 postFilter.go:240] [compareNodeResources] Recursos de CPU do nó minikube estão sincronizados: 1450 mCPU
I0129 14:03:58.396646       1 postFilter.go:246] [compareNodeResources] Recursos de memória do nó minikube estão sincronizados: 459276288 bytes
I0129 14:03:58.396883       1 scheduler.go:606] [GetControllerMetricInfo] Iniciando para o pod: default/test-deployment3-84f8ccf757-5tmfc
I0129 14:03:58.396928       1 scheduler.go:611] [GetControllerMetricInfo] Obtendo o nome do controlador para o pod: default/test-deployment3-84f8ccf757-5tmfc
I0129 14:03:58.396939       1 types.go:743] [ControllerName] Verificando as anotações do pod default/test-deployment3-84f8ccf757-5tmfc
I0129 14:03:58.396948       1 types.go:761] [ControllerName] Anotação 'controller' encontrada para o pod default/test-deployment3-84f8ccf757-5tmfc: test-controller3
I0129 14:03:58.396958       1 scheduler.go:614] [GetControllerMetricInfo] Métricas do controlador definidas para o pod: default/test-deployment3-84f8ccf757-5tmfc
I0129 14:03:58.396967       1 scheduler.go:84] [HigherPrecedence] Calculando precedência entre test-deployment2-7b58dbd49-24pwt e test-deployment3-84f8ccf757-5tmfc
I0129 14:03:58.396975       1 scheduler.go:117] [WaitForPodsOnCache] Verificando se o pod test-deployment2-7b58dbd49-24pwt está no cache...
I0129 14:03:58.396981       1 scheduler.go:606] [GetControllerMetricInfo] Iniciando para o pod: default/test-deployment2-7b58dbd49-24pwt
I0129 14:03:58.396989       1 scheduler.go:611] [GetControllerMetricInfo] Obtendo o nome do controlador para o pod: default/test-deployment2-7b58dbd49-24pwt
I0129 14:03:58.396996       1 types.go:743] [ControllerName] Verificando as anotações do pod default/test-deployment2-7b58dbd49-24pwt
I0129 14:03:58.397003       1 types.go:761] [ControllerName] Anotação 'controller' encontrada para o pod default/test-deployment2-7b58dbd49-24pwt: test-controller2
I0129 14:03:58.397011       1 scheduler.go:614] [GetControllerMetricInfo] Métricas do controlador definidas para o pod: default/test-deployment2-7b58dbd49-24pwt
I0129 14:03:58.405804       1 scheduler.go:70] Estado no Informer: map[acceptablePreemptionOverhead:10 controller:test-controller2 qosMeasuring:average]
I0129 14:03:58.406075       1 scheduler.go:71] Estado real no cluster: map[acceptablePreemptionOverhead:10 controller:test-controller2 qosMeasuring:average]
I0129 14:03:58.406280       1 scheduler.go:139] [WaitForPodsOnCache] Pod test-deployment2-7b58dbd49-24pwt encontrado no cache.
I0129 14:03:58.406548       1 scheduler.go:117] [WaitForPodsOnCache] Verificando se o pod test-deployment3-84f8ccf757-5tmfc está no cache...
I0129 14:03:58.406667       1 scheduler.go:606] [GetControllerMetricInfo] Iniciando para o pod: default/test-deployment3-84f8ccf757-5tmfc
I0129 14:03:58.406832       1 scheduler.go:611] [GetControllerMetricInfo] Obtendo o nome do controlador para o pod: default/test-deployment3-84f8ccf757-5tmfc
I0129 14:03:58.406974       1 types.go:743] [ControllerName] Verificando as anotações do pod default/test-deployment3-84f8ccf757-5tmfc
I0129 14:03:58.407092       1 types.go:761] [ControllerName] Anotação 'controller' encontrada para o pod default/test-deployment3-84f8ccf757-5tmfc: test-controller3
I0129 14:03:58.407103       1 scheduler.go:614] [GetControllerMetricInfo] Métricas do controlador definidas para o pod: default/test-deployment3-84f8ccf757-5tmfc
I0129 14:03:58.425668       1 scheduler.go:70] Estado no Informer: map[acceptablePreemptionOverhead:10 controller:test-controller3 qosMeasuring:average]
I0129 14:03:58.425735       1 scheduler.go:71] Estado real no cluster: map[acceptablePreemptionOverhead:10 controller:test-controller3 qosMeasuring:average]
I0129 14:03:58.425748       1 scheduler.go:139] [WaitForPodsOnCache] Pod test-deployment3-84f8ccf757-5tmfc encontrado no cache.
I0129 14:03:58.425757       1 scheduler.go:606] [GetControllerMetricInfo] Iniciando para o pod: default/test-deployment2-7b58dbd49-24pwt
I0129 14:03:58.425763       1 scheduler.go:611] [GetControllerMetricInfo] Obtendo o nome do controlador para o pod: default/test-deployment2-7b58dbd49-24pwt
I0129 14:03:58.425776       1 types.go:743] [ControllerName] Verificando as anotações do pod default/test-deployment2-7b58dbd49-24pwt
I0129 14:03:58.425783       1 types.go:761] [ControllerName] Anotação 'controller' encontrada para o pod default/test-deployment2-7b58dbd49-24pwt: test-controller2
I0129 14:03:58.425791       1 scheduler.go:614] [GetControllerMetricInfo] Métricas do controlador definidas para o pod: default/test-deployment2-7b58dbd49-24pwt
I0129 14:03:58.425802       1 scheduler.go:606] [GetControllerMetricInfo] Iniciando para o pod: default/test-deployment3-84f8ccf757-5tmfc
I0129 14:03:58.425807       1 scheduler.go:611] [GetControllerMetricInfo] Obtendo o nome do controlador para o pod: default/test-deployment3-84f8ccf757-5tmfc
I0129 14:03:58.425811       1 types.go:743] [ControllerName] Verificando as anotações do pod default/test-deployment3-84f8ccf757-5tmfc
I0129 14:03:58.425816       1 types.go:761] [ControllerName] Anotação 'controller' encontrada para o pod default/test-deployment3-84f8ccf757-5tmfc: test-controller3
I0129 14:03:58.425831       1 scheduler.go:614] [GetControllerMetricInfo] Métricas do controlador definidas para o pod: default/test-deployment3-84f8ccf757-5tmfc
I0129 14:03:58.425847       1 scheduler.go:98] [HigherPrecedence] Métricas para test-deployment2-7b58dbd49-24pwt: QoS = 2.534959, Importância = 0.80
I0129 14:03:58.425858       1 scheduler.go:99] [HigherPrecedence] Métricas para test-deployment3-84f8ccf757-5tmfc: QoS = -26.796962, Importância = 0.80
I0129 14:03:58.425865       1 scheduler.go:110] [HigherPrecedence] Decisão final: test-deployment2-7b58dbd49-24pwt tem precedência sobre test-deployment3-84f8ccf757-5tmfc? false
I0129 14:03:58.425913       1 postFilter.go:144] [PREEMPT CALL] No node was chosen to allocate pod test-deployment2-7b58dbd49-24pwt
W0129 14:03:58.425946       1 postFilter.go:45] [PostFilter] Nenhum nó nominado após a preempção para o pod: default/test-deployment2-7b58dbd49-24pwt
I0129 14:03:58.426903       1 scheduler.go:182] [PostBind] Chamado para pod test-deployment3-84f8ccf757-5tmfc
I0129 14:03:58.426946       1 scheduler.go:200] [PostBind] Pod test-deployment3-84f8ccf757-5tmfc - Início do binding: 2025-01-29 14:03:58.389718186 +0000 UTC m=+211.493273853, Fim do binding: 2025-01-29 14:03:58.426941784 +0000 UTC m=+211.530496930
I0129 14:03:58.426964       1 types.go:743] [ControllerName] Verificando as anotações do pod default/test-deployment3-84f8ccf757-5tmfc
I0129 14:03:58.426971       1 types.go:761] [ControllerName] Anotação 'controller' encontrada para o pod default/test-deployment3-84f8ccf757-5tmfc: test-controller3
I0129 14:03:58.426993       1 scheduler.go:207] [PostBind] Métricas atualizadas para o pod test-deployment3-84f8ccf757-5tmfc
I0129 14:03:58.427360       1 scheduler.go:258] [OnUpdatePod] Iniciando processamento de atualização de pod
I0129 14:03:58.427413       1 scheduler.go:262] [OnUpdatePod] Pod atualizado detectado: default/test-deployment3-84f8ccf757-5tmfc, Anotações: map[acceptablePreemptionOverhead:10 controller:test-controller3 qosMeasuring:average]
I0129 14:03:58.427437       1 scheduler.go:265] [OnUpdatePod] Comparando estado no Informer e estado real no cluster para o pod default/test-deployment3-84f8ccf757-5tmfc
I0129 14:03:58.531715       1 scheduler.go:70] Estado no Informer: map[acceptablePreemptionOverhead:10 controller:test-controller3 qosMeasuring:average]
I0129 14:03:58.531793       1 scheduler.go:71] Estado real no cluster: map[acceptablePreemptionOverhead:10 controller:test-controller3 qosMeasuring:average]
I0129 14:03:58.531814       1 scheduler.go:275] [OnUpdatePod] Atualizando informações de métricas para o pod default/test-deployment3-84f8ccf757-5tmfc
I0129 14:03:58.531826       1 types.go:743] [ControllerName] Verificando as anotações do pod default/test-deployment3-84f8ccf757-5tmfc
I0129 14:03:58.531835       1 types.go:761] [ControllerName] Anotação 'controller' encontrada para o pod default/test-deployment3-84f8ccf757-5tmfc: test-controller3
I0129 14:03:58.531849       1 scheduler.go:277] [OnUpdatePod] Atualizando 'LastStatus' do pod default/test-deployment3-84f8ccf757-5tmfc nas métricas
I0129 14:03:58.531856       1 scheduler.go:279] [OnUpdatePod] Métrica atualizada para o pod default/test-deployment3-84f8ccf757-5tmfc
I0129 14:03:58.531869       1 scheduler.go:283] [OnUpdatePod] Finalizando processamento de atualização de pod para default/test-deployment3-84f8ccf757-5tmfc
I0129 14:03:58.685976       1 scheduler.go:258] [OnUpdatePod] Iniciando processamento de atualização de pod
I0129 14:03:58.686234       1 scheduler.go:262] [OnUpdatePod] Pod atualizado detectado: default/test-deployment3-84f8ccf757-5tmfc, Anotações: map[acceptablePreemptionOverhead:10 controller:test-controller3 qosMeasuring:average]
I0129 14:03:58.686295       1 scheduler.go:265] [OnUpdatePod] Comparando estado no Informer e estado real no cluster para o pod default/test-deployment3-84f8ccf757-5tmfc
I0129 14:03:58.714926       1 scheduler.go:70] Estado no Informer: map[acceptablePreemptionOverhead:10 controller:test-controller3 qosMeasuring:average]
I0129 14:03:58.715203       1 scheduler.go:71] Estado real no cluster: map[acceptablePreemptionOverhead:10 controller:test-controller3 qosMeasuring:average]
I0129 14:03:58.715238       1 scheduler.go:275] [OnUpdatePod] Atualizando informações de métricas para o pod default/test-deployment3-84f8ccf757-5tmfc
I0129 14:03:58.715339       1 types.go:743] [ControllerName] Verificando as anotações do pod default/test-deployment3-84f8ccf757-5tmfc
I0129 14:03:58.715350       1 types.go:761] [ControllerName] Anotação 'controller' encontrada para o pod default/test-deployment3-84f8ccf757-5tmfc: test-controller3
I0129 14:03:58.715363       1 scheduler.go:277] [OnUpdatePod] Atualizando 'LastStatus' do pod default/test-deployment3-84f8ccf757-5tmfc nas métricas
I0129 14:03:58.715371       1 scheduler.go:279] [OnUpdatePod] Métrica atualizada para o pod default/test-deployment3-84f8ccf757-5tmfc
I0129 14:03:58.715463       1 scheduler.go:283] [OnUpdatePod] Finalizando processamento de atualização de pod para default/test-deployment3-84f8ccf757-5tmfc
I0129 14:04:02.875086       1 scheduler.go:258] [OnUpdatePod] Iniciando processamento de atualização de pod
I0129 14:04:02.877752       1 scheduler.go:262] [OnUpdatePod] Pod atualizado detectado: default/test-deployment3-84f8ccf757-5tmfc, Anotações: map[acceptablePreemptionOverhead:10 controller:test-controller3 qosMeasuring:average]
I0129 14:04:02.882723       1 scheduler.go:265] [OnUpdatePod] Comparando estado no Informer e estado real no cluster para o pod default/test-deployment3-84f8ccf757-5tmfc
I0129 14:04:02.902571       1 scheduler.go:70] Estado no Informer: map[acceptablePreemptionOverhead:10 controller:test-controller3 qosMeasuring:average]
I0129 14:04:02.902649       1 scheduler.go:71] Estado real no cluster: map[acceptablePreemptionOverhead:10 controller:test-controller3 qosMeasuring:average]
I0129 14:04:02.902727       1 scheduler.go:275] [OnUpdatePod] Atualizando informações de métricas para o pod default/test-deployment3-84f8ccf757-5tmfc
I0129 14:04:02.902741       1 types.go:743] [ControllerName] Verificando as anotações do pod default/test-deployment3-84f8ccf757-5tmfc
I0129 14:04:02.902750       1 types.go:761] [ControllerName] Anotação 'controller' encontrada para o pod default/test-deployment3-84f8ccf757-5tmfc: test-controller3
I0129 14:04:02.902763       1 scheduler.go:277] [OnUpdatePod] Atualizando 'LastStatus' do pod default/test-deployment3-84f8ccf757-5tmfc nas métricas
I0129 14:04:02.903653       1 scheduler.go:279] [OnUpdatePod] Métrica atualizada para o pod default/test-deployment3-84f8ccf757-5tmfc
I0129 14:04:02.904075       1 scheduler.go:283] [OnUpdatePod] Finalizando processamento de atualização de pod para default/test-deployment3-84f8ccf757-5tmfc
I0129 14:04:28.376453       1 postFilter.go:29] [PostFilter] PostFilter chamado para pod: default/test-deployment2-7b58dbd49-24pwt
I0129 14:04:28.376501       1 postFilter.go:76] [Preempt] Comparando pod original com o atualizado...
I0129 14:04:28.376521       1 postFilter.go:83] [Preempt] Successfully retrieved updated pod default/test-deployment2-7b58dbd49-24pwt from lister
I0129 14:04:28.392557       1 postFilter.go:233] [compareNodeResources] Recursos calculados no nó minikube: CPU = 1450 mCPU, Memória = 459276288 bytes
I0129 14:04:28.392675       1 postFilter.go:234] [compareNodeResources] Recursos do snapshot no nó minikube: CPU = 1450 mCPU, Memória = 459276288 bytes
I0129 14:04:28.392697       1 postFilter.go:240] [compareNodeResources] Recursos de CPU do nó minikube estão sincronizados: 1450 mCPU
I0129 14:04:28.392726       1 postFilter.go:246] [compareNodeResources] Recursos de memória do nó minikube estão sincronizados: 459276288 bytes
I0129 14:04:28.393079       1 scheduler.go:606] [GetControllerMetricInfo] Iniciando para o pod: default/test-deployment3-84f8ccf757-5tmfc
I0129 14:04:28.393253       1 scheduler.go:611] [GetControllerMetricInfo] Obtendo o nome do controlador para o pod: default/test-deployment3-84f8ccf757-5tmfc
I0129 14:04:28.393325       1 types.go:743] [ControllerName] Verificando as anotações do pod default/test-deployment3-84f8ccf757-5tmfc
I0129 14:04:28.393343       1 types.go:761] [ControllerName] Anotação 'controller' encontrada para o pod default/test-deployment3-84f8ccf757-5tmfc: test-controller3
I0129 14:04:28.393358       1 scheduler.go:614] [GetControllerMetricInfo] Métricas do controlador definidas para o pod: default/test-deployment3-84f8ccf757-5tmfc
I0129 14:04:28.393372       1 scheduler.go:84] [HigherPrecedence] Calculando precedência entre test-deployment2-7b58dbd49-24pwt e test-deployment3-84f8ccf757-5tmfc
I0129 14:04:28.393383       1 scheduler.go:117] [WaitForPodsOnCache] Verificando se o pod test-deployment2-7b58dbd49-24pwt está no cache...
I0129 14:04:28.393415       1 scheduler.go:606] [GetControllerMetricInfo] Iniciando para o pod: default/test-deployment2-7b58dbd49-24pwt
I0129 14:04:28.393427       1 scheduler.go:611] [GetControllerMetricInfo] Obtendo o nome do controlador para o pod: default/test-deployment2-7b58dbd49-24pwt
I0129 14:04:28.393437       1 types.go:743] [ControllerName] Verificando as anotações do pod default/test-deployment2-7b58dbd49-24pwt
I0129 14:04:28.393450       1 types.go:761] [ControllerName] Anotação 'controller' encontrada para o pod default/test-deployment2-7b58dbd49-24pwt: test-controller2
I0129 14:04:28.393462       1 scheduler.go:614] [GetControllerMetricInfo] Métricas do controlador definidas para o pod: default/test-deployment2-7b58dbd49-24pwt
I0129 14:04:28.411600       1 scheduler.go:70] Estado no Informer: map[acceptablePreemptionOverhead:10 controller:test-controller2 qosMeasuring:average]
I0129 14:04:28.412197       1 scheduler.go:71] Estado real no cluster: map[acceptablePreemptionOverhead:10 controller:test-controller2 qosMeasuring:average]
I0129 14:04:28.412231       1 scheduler.go:139] [WaitForPodsOnCache] Pod test-deployment2-7b58dbd49-24pwt encontrado no cache.
I0129 14:04:28.412243       1 scheduler.go:117] [WaitForPodsOnCache] Verificando se o pod test-deployment3-84f8ccf757-5tmfc está no cache...
I0129 14:04:28.412255       1 scheduler.go:606] [GetControllerMetricInfo] Iniciando para o pod: default/test-deployment3-84f8ccf757-5tmfc
I0129 14:04:28.412265       1 scheduler.go:611] [GetControllerMetricInfo] Obtendo o nome do controlador para o pod: default/test-deployment3-84f8ccf757-5tmfc
I0129 14:04:28.412277       1 types.go:743] [ControllerName] Verificando as anotações do pod default/test-deployment3-84f8ccf757-5tmfc
I0129 14:04:28.412289       1 types.go:761] [ControllerName] Anotação 'controller' encontrada para o pod default/test-deployment3-84f8ccf757-5tmfc: test-controller3
I0129 14:04:28.412301       1 scheduler.go:614] [GetControllerMetricInfo] Métricas do controlador definidas para o pod: default/test-deployment3-84f8ccf757-5tmfc
I0129 14:04:28.429554       1 scheduler.go:70] Estado no Informer: map[acceptablePreemptionOverhead:10 controller:test-controller3 qosMeasuring:average]
I0129 14:04:28.430794       1 scheduler.go:71] Estado real no cluster: map[acceptablePreemptionOverhead:10 controller:test-controller3 qosMeasuring:average]
I0129 14:04:28.430882       1 scheduler.go:139] [WaitForPodsOnCache] Pod test-deployment3-84f8ccf757-5tmfc encontrado no cache.
I0129 14:04:28.430894       1 scheduler.go:606] [GetControllerMetricInfo] Iniciando para o pod: default/test-deployment2-7b58dbd49-24pwt
I0129 14:04:28.430902       1 scheduler.go:611] [GetControllerMetricInfo] Obtendo o nome do controlador para o pod: default/test-deployment2-7b58dbd49-24pwt
I0129 14:04:28.430919       1 types.go:743] [ControllerName] Verificando as anotações do pod default/test-deployment2-7b58dbd49-24pwt
I0129 14:04:28.430929       1 types.go:761] [ControllerName] Anotação 'controller' encontrada para o pod default/test-deployment2-7b58dbd49-24pwt: test-controller2
I0129 14:04:28.430938       1 scheduler.go:614] [GetControllerMetricInfo] Métricas do controlador definidas para o pod: default/test-deployment2-7b58dbd49-24pwt
I0129 14:04:28.430952       1 scheduler.go:606] [GetControllerMetricInfo] Iniciando para o pod: default/test-deployment3-84f8ccf757-5tmfc
I0129 14:04:28.430958       1 scheduler.go:611] [GetControllerMetricInfo] Obtendo o nome do controlador para o pod: default/test-deployment3-84f8ccf757-5tmfc
I0129 14:04:28.430964       1 types.go:743] [ControllerName] Verificando as anotações do pod default/test-deployment3-84f8ccf757-5tmfc
I0129 14:04:28.430971       1 types.go:761] [ControllerName] Anotação 'controller' encontrada para o pod default/test-deployment3-84f8ccf757-5tmfc: test-controller3
I0129 14:04:28.430981       1 scheduler.go:614] [GetControllerMetricInfo] Métricas do controlador definidas para o pod: default/test-deployment3-84f8ccf757-5tmfc
I0129 14:04:28.431013       1 scheduler.go:98] [HigherPrecedence] Métricas para test-deployment2-7b58dbd49-24pwt: QoS = -27.461443, Importância = 0.80
I0129 14:04:28.431026       1 scheduler.go:99] [HigherPrecedence] Métricas para test-deployment3-84f8ccf757-5tmfc: QoS = -16.972559, Importância = 0.80
I0129 14:04:28.431036       1 scheduler.go:110] [HigherPrecedence] Decisão final: test-deployment2-7b58dbd49-24pwt tem precedência sobre test-deployment3-84f8ccf757-5tmfc? true
I0129 14:04:28.431048       1 types.go:743] [ControllerName] Verificando as anotações do pod default/test-deployment2-7b58dbd49-24pwt
I0129 14:04:28.431055       1 types.go:761] [ControllerName] Anotação 'controller' encontrada para o pod default/test-deployment2-7b58dbd49-24pwt: test-controller2
I0129 14:04:28.431060       1 types.go:743] [ControllerName] Verificando as anotações do pod default/test-deployment3-84f8ccf757-5tmfc
I0129 14:04:28.431066       1 types.go:761] [ControllerName] Anotação 'controller' encontrada para o pod default/test-deployment3-84f8ccf757-5tmfc: test-controller3
I0129 14:04:28.431072       1 scheduler.go:606] [GetControllerMetricInfo] Iniciando para o pod: default/test-deployment3-84f8ccf757-5tmfc
I0129 14:04:28.431078       1 scheduler.go:611] [GetControllerMetricInfo] Obtendo o nome do controlador para o pod: default/test-deployment3-84f8ccf757-5tmfc
I0129 14:04:28.431084       1 types.go:743] [ControllerName] Verificando as anotações do pod default/test-deployment3-84f8ccf757-5tmfc
I0129 14:04:28.431090       1 types.go:761] [ControllerName] Anotação 'controller' encontrada para o pod default/test-deployment3-84f8ccf757-5tmfc: test-controller3
I0129 14:04:28.431096       1 scheduler.go:614] [GetControllerMetricInfo] Métricas do controlador definidas para o pod: default/test-deployment3-84f8ccf757-5tmfc
I0129 14:04:28.431102       1 scheduler.go:606] [GetControllerMetricInfo] Iniciando para o pod: default/test-deployment3-84f8ccf757-5tmfc
I0129 14:04:28.431107       1 scheduler.go:611] [GetControllerMetricInfo] Obtendo o nome do controlador para o pod: default/test-deployment3-84f8ccf757-5tmfc
I0129 14:04:28.431229       1 types.go:743] [ControllerName] Verificando as anotações do pod default/test-deployment3-84f8ccf757-5tmfc
I0129 14:04:28.431239       1 types.go:761] [ControllerName] Anotação 'controller' encontrada para o pod default/test-deployment3-84f8ccf757-5tmfc: test-controller3
I0129 14:04:28.431251       1 scheduler.go:614] [GetControllerMetricInfo] Métricas do controlador definidas para o pod: default/test-deployment3-84f8ccf757-5tmfc
I0129 14:04:28.431259       1 types.go:743] [ControllerName] Verificando as anotações do pod default/test-deployment3-84f8ccf757-5tmfc
I0129 14:04:28.431265       1 types.go:761] [ControllerName] Anotação 'controller' encontrada para o pod default/test-deployment3-84f8ccf757-5tmfc: test-controller3
I0129 14:04:28.431399       1 scheduler.go:606] [GetControllerMetricInfo] Iniciando para o pod: default/test-deployment3-84f8ccf757-5tmfc
I0129 14:04:28.431407       1 scheduler.go:611] [GetControllerMetricInfo] Obtendo o nome do controlador para o pod: default/test-deployment3-84f8ccf757-5tmfc
I0129 14:04:28.431413       1 types.go:743] [ControllerName] Verificando as anotações do pod default/test-deployment3-84f8ccf757-5tmfc
I0129 14:04:28.431419       1 types.go:761] [ControllerName] Anotação 'controller' encontrada para o pod default/test-deployment3-84f8ccf757-5tmfc: test-controller3
I0129 14:04:28.431426       1 scheduler.go:614] [GetControllerMetricInfo] Métricas do controlador definidas para o pod: default/test-deployment3-84f8ccf757-5tmfc
I0129 14:04:28.431437       1 scheduler.go:606] [GetControllerMetricInfo] Iniciando para o pod: default/test-deployment3-84f8ccf757-5tmfc
I0129 14:04:28.431446       1 scheduler.go:611] [GetControllerMetricInfo] Obtendo o nome do controlador para o pod: default/test-deployment3-84f8ccf757-5tmfc
I0129 14:04:28.431453       1 types.go:743] [ControllerName] Verificando as anotações do pod default/test-deployment3-84f8ccf757-5tmfc
I0129 14:04:28.431518       1 types.go:761] [ControllerName] Anotação 'controller' encontrada para o pod default/test-deployment3-84f8ccf757-5tmfc: test-controller3
I0129 14:04:28.431528       1 scheduler.go:614] [GetControllerMetricInfo] Métricas do controlador definidas para o pod: default/test-deployment3-84f8ccf757-5tmfc
I0129 14:04:28.432922       1 postFilter.go:147] [PREEMPT CALL] The node minikube  was chosen to allocate pod test-deployment2-7b58dbd49-24pwt
I0129 14:04:28.433010       1 postFilter.go:151] [Preempt] Iniciando a remoção dos pods preemptados no nó minikube para alocar o pod default/test-deployment2-7b58dbd49-24pwt. Total de vítimas: 1
I0129 14:04:28.433031       1 postFilter.go:155] [Preempt] Tentando remover o pod default/test-deployment3-84f8ccf757-5tmfc no nó minikube
I0129 14:04:28.504534       1 scheduler.go:258] [OnUpdatePod] Iniciando processamento de atualização de pod
I0129 14:04:28.528385       1 scheduler.go:262] [OnUpdatePod] Pod atualizado detectado: default/test-deployment3-84f8ccf757-5tmfc, Anotações: map[acceptablePreemptionOverhead:10 controller:test-controller3 qosMeasuring:average]
I0129 14:04:28.533641       1 scheduler.go:265] [OnUpdatePod] Comparando estado no Informer e estado real no cluster para o pod default/test-deployment3-84f8ccf757-5tmfc
I0129 14:04:28.631751       1 postFilter.go:168] [Preempt] Pod default/test-deployment3-84f8ccf757-5tmfc removido com sucesso no nó minikube
I0129 14:04:28.631860       1 postFilter.go:174] test-deployment3-84f8ccf757-5tmfc_default preempted by test-deployment2-7b58dbd49-24pwt_default on node minikube
I0129 14:04:28.631906       1 postFilter.go:179] [Preempt] Total de pods preemptados no nó minikube: 1
I0129 14:04:28.631930       1 postFilter.go:186] [Preempt] Verificando pods de menor precedência no nó minikube que precisam ter o campo NominatedNodeName limpo
I0129 14:04:28.631948       1 postFilter.go:196] [Preempt] Finalizado para o nó minikube. Pod default/test-deployment2-7b58dbd49-24pwt deve ser alocado agora.
I0129 14:04:28.631960       1 postFilter.go:49] [PostFilter] Nó nominado para o pod default/test-deployment2-7b58dbd49-24pwt: minikube
E0129 14:04:29.214429       1 scheduler.go:67] Erro ao buscar estado real do pod test-deployment3-84f8ccf757-5tmfc: pods "test-deployment3-84f8ccf757-5tmfc" not found
I0129 14:04:29.214523       1 scheduler.go:275] [OnUpdatePod] Atualizando informações de métricas para o pod default/test-deployment3-84f8ccf757-5tmfc
I0129 14:04:29.214548       1 types.go:743] [ControllerName] Verificando as anotações do pod default/test-deployment3-84f8ccf757-5tmfc
I0129 14:04:29.214564       1 types.go:761] [ControllerName] Anotação 'controller' encontrada para o pod default/test-deployment3-84f8ccf757-5tmfc: test-controller3
I0129 14:04:29.214579       1 scheduler.go:277] [OnUpdatePod] Atualizando 'LastStatus' do pod default/test-deployment3-84f8ccf757-5tmfc nas métricas
I0129 14:04:29.214586       1 scheduler.go:279] [OnUpdatePod] Métrica atualizada para o pod default/test-deployment3-84f8ccf757-5tmfc
I0129 14:04:29.214606       1 scheduler.go:283] [OnUpdatePod] Finalizando processamento de atualização de pod para default/test-deployment3-84f8ccf757-5tmfc
I0129 14:04:29.214620       1 scheduler.go:291] [OnDeletePod] Iniciando a execução do OnDeletePod
I0129 14:04:29.214724       1 scheduler.go:300] [OnDeletePod] DeepCopy realizado para o pod default/test-deployment3-84f8ccf757-5tmfc
I0129 14:04:29.221788       1 types.go:743] [ControllerName] Verificando as anotações do pod default/test-deployment3-84f8ccf757-5tmfc
I0129 14:04:29.221953       1 types.go:761] [ControllerName] Anotação 'controller' encontrada para o pod default/test-deployment3-84f8ccf757-5tmfc: test-controller3
I0129 14:04:29.226737       1 postFilter.go:29] [PostFilter] PostFilter chamado para pod: default/test-deployment3-84f8ccf757-hkk2f
I0129 14:04:29.227717       1 postFilter.go:76] [Preempt] Comparando pod original com o atualizado...
I0129 14:04:29.227845       1 postFilter.go:83] [Preempt] Successfully retrieved updated pod default/test-deployment3-84f8ccf757-hkk2f from lister
I0129 14:04:29.233103       1 scheduler.go:307] [OnDeletePod] Pod deletado detectado: default/test-deployment3-84f8ccf757-5tmfc
I0129 14:04:29.234083       1 scheduler.go:309] [OnDeletePod] Atualizando métricas do pod default/test-deployment3-84f8ccf757-5tmfc
I0129 14:04:29.234210       1 types.go:743] [ControllerName] Verificando as anotações do pod default/test-deployment3-84f8ccf757-5tmfc
I0129 14:04:29.237573       1 types.go:761] [ControllerName] Anotação 'controller' encontrada para o pod default/test-deployment3-84f8ccf757-5tmfc: test-controller3
I0129 14:04:29.237620       1 scheduler.go:311] [OnDeletePod] Verificando o estado do pod default/test-deployment3-84f8ccf757-5tmfc nas métricas
I0129 14:04:29.237637       1 scheduler.go:321] [OnDeletePod] EndTime atualizado para o pod default/test-deployment3-84f8ccf757-5tmfc: 2025-01-29 14:04:29.237632447 +0000 UTC m=+242.341187487
I0129 14:04:29.237655       1 scheduler.go:325] [OnDeletePod] Finalizando a execução do OnDeletePod para o pod default/test-deployment3-84f8ccf757-5tmfc
I0129 14:04:29.237676       1 scheduler.go:258] [OnUpdatePod] Iniciando processamento de atualização de pod
I0129 14:04:29.237705       1 scheduler.go:262] [OnUpdatePod] Pod atualizado detectado: default/test-deployment2-7b58dbd49-24pwt, Anotações: map[acceptablePreemptionOverhead:10 controller:test-controller2 qosMeasuring:average]
I0129 14:04:29.237720       1 scheduler.go:265] [OnUpdatePod] Comparando estado no Informer e estado real no cluster para o pod default/test-deployment2-7b58dbd49-24pwt
I0129 14:04:29.495293       1 postFilter.go:233] [compareNodeResources] Recursos calculados no nó minikube: CPU = 750 mCPU, Memória = 178257920 bytes
I0129 14:04:29.495355       1 postFilter.go:234] [compareNodeResources] Recursos do snapshot no nó minikube: CPU = 750 mCPU, Memória = 178257920 bytes
I0129 14:04:29.495368       1 postFilter.go:240] [compareNodeResources] Recursos de CPU do nó minikube estão sincronizados: 750 mCPU
I0129 14:04:29.495378       1 postFilter.go:246] [compareNodeResources] Recursos de memória do nó minikube estão sincronizados: 178257920 bytes
I0129 14:04:29.496669       1 postFilter.go:147] [PREEMPT CALL] The node minikube  was chosen to allocate pod test-deployment3-84f8ccf757-hkk2f
I0129 14:04:29.498305       1 postFilter.go:151] [Preempt] Iniciando a remoção dos pods preemptados no nó minikube para alocar o pod default/test-deployment3-84f8ccf757-hkk2f. Total de vítimas: 0
I0129 14:04:29.498340       1 postFilter.go:179] [Preempt] Total de pods preemptados no nó minikube: 0
I0129 14:04:29.499100       1 scheduler.go:84] [HigherPrecedence] Calculando precedência entre test-deployment3-84f8ccf757-hkk2f e test-deployment2-7b58dbd49-24pwt
I0129 14:04:29.499402       1 scheduler.go:117] [WaitForPodsOnCache] Verificando se o pod test-deployment3-84f8ccf757-hkk2f está no cache...
I0129 14:04:29.499518       1 scheduler.go:606] [GetControllerMetricInfo] Iniciando para o pod: default/test-deployment3-84f8ccf757-hkk2f
I0129 14:04:29.499531       1 scheduler.go:611] [GetControllerMetricInfo] Obtendo o nome do controlador para o pod: default/test-deployment3-84f8ccf757-hkk2f
I0129 14:04:29.499539       1 types.go:743] [ControllerName] Verificando as anotações do pod default/test-deployment3-84f8ccf757-hkk2f
I0129 14:04:29.499653       1 types.go:761] [ControllerName] Anotação 'controller' encontrada para o pod default/test-deployment3-84f8ccf757-hkk2f: test-controller3
I0129 14:04:29.499963       1 scheduler.go:614] [GetControllerMetricInfo] Métricas do controlador definidas para o pod: default/test-deployment3-84f8ccf757-hkk2f
W0129 14:04:29.500103       1 scheduler.go:125] [cacheMiss] Métricas não encontradas para o pod: default/test-deployment3-84f8ccf757-hkk2f
I0129 14:04:29.502902       1 scheduler.go:70] Estado no Informer: map[acceptablePreemptionOverhead:10 controller:test-controller2 qosMeasuring:average]
I0129 14:04:29.502974       1 scheduler.go:71] Estado real no cluster: map[acceptablePreemptionOverhead:10 controller:test-controller2 qosMeasuring:average]
I0129 14:04:29.502994       1 scheduler.go:275] [OnUpdatePod] Atualizando informações de métricas para o pod default/test-deployment2-7b58dbd49-24pwt
I0129 14:04:29.848093       1 scheduler.go:70] Estado no Informer: map[acceptablePreemptionOverhead:10 controller:test-controller3 qosMeasuring:average]
I0129 14:04:29.849891       1 scheduler.go:71] Estado real no cluster: map[acceptablePreemptionOverhead:10 controller:test-controller3 qosMeasuring:average]
W0129 14:04:29.850327       1 scheduler.go:135] [WaitForPodsOnCache] Pod test-deployment3-84f8ccf757-hkk2f não encontrado no cache. Tentando novamente...
I0129 14:04:29.850730       1 types.go:743] [ControllerName] Verificando as anotações do pod default/test-deployment2-7b58dbd49-24pwt
I0129 14:04:29.853431       1 types.go:761] [ControllerName] Anotação 'controller' encontrada para o pod default/test-deployment2-7b58dbd49-24pwt: test-controller2
I0129 14:04:29.853743       1 scheduler.go:277] [OnUpdatePod] Atualizando 'LastStatus' do pod default/test-deployment2-7b58dbd49-24pwt nas métricas
I0129 14:04:29.853940       1 scheduler.go:279] [OnUpdatePod] Métrica atualizada para o pod default/test-deployment2-7b58dbd49-24pwt
I0129 14:04:29.854222       1 scheduler.go:283] [OnUpdatePod] Finalizando processamento de atualização de pod para default/test-deployment2-7b58dbd49-24pwt
I0129 14:04:29.854577       1 scheduler.go:218] [OnAddPod] Pod adicionado: default/test-deployment3-84f8ccf757-hkk2f, Anotações: map[acceptablePreemptionOverhead:10 controller:test-controller3 qosMeasuring:average]
I0129 14:04:29.875398       1 scheduler.go:70] Estado no Informer: map[acceptablePreemptionOverhead:10 controller:test-controller3 qosMeasuring:average]
I0129 14:04:29.875589       1 scheduler.go:71] Estado real no cluster: map[acceptablePreemptionOverhead:10 controller:test-controller3 qosMeasuring:average]
I0129 14:04:29.881664       1 scheduler.go:229] [OnAddPod] Adicionando pod default/test-deployment3-84f8ccf757-hkk2f com os seguintes detalhes:
I0129 14:04:29.881736       1 types.go:743] [ControllerName] Verificando as anotações do pod default/test-deployment3-84f8ccf757-hkk2f
I0129 14:04:29.881754       1 types.go:761] [ControllerName] Anotação 'controller' encontrada para o pod default/test-deployment3-84f8ccf757-hkk2f: test-controller3
I0129 14:04:29.881806       1 scheduler.go:238] [OnAddPod] Atualizando métricas para o pod default/test-deployment3-84f8ccf757-hkk2f
I0129 14:04:29.881816       1 types.go:743] [ControllerName] Verificando as anotações do pod default/test-deployment3-84f8ccf757-hkk2f
I0129 14:04:29.881824       1 types.go:761] [ControllerName] Anotação 'controller' encontrada para o pod default/test-deployment3-84f8ccf757-hkk2f: test-controller3
I0129 14:04:29.881842       1 scheduler.go:251] [OnAddPod] Pod default/test-deployment3-84f8ccf757-hkk2f adicionado com sucesso
I0129 14:04:29.951610       1 scheduler.go:606] [GetControllerMetricInfo] Iniciando para o pod: default/test-deployment3-84f8ccf757-hkk2f
I0129 14:04:29.951660       1 scheduler.go:611] [GetControllerMetricInfo] Obtendo o nome do controlador para o pod: default/test-deployment3-84f8ccf757-hkk2f
I0129 14:04:29.951670       1 types.go:743] [ControllerName] Verificando as anotações do pod default/test-deployment3-84f8ccf757-hkk2f
I0129 14:04:29.951678       1 types.go:761] [ControllerName] Anotação 'controller' encontrada para o pod default/test-deployment3-84f8ccf757-hkk2f: test-controller3
I0129 14:04:29.951686       1 scheduler.go:614] [GetControllerMetricInfo] Métricas do controlador definidas para o pod: default/test-deployment3-84f8ccf757-hkk2f
I0129 14:04:30.254489       1 scheduler.go:70] Estado no Informer: map[acceptablePreemptionOverhead:10 controller:test-controller3 qosMeasuring:average]
I0129 14:04:30.254547       1 scheduler.go:71] Estado real no cluster: map[acceptablePreemptionOverhead:10 controller:test-controller3 qosMeasuring:average]
I0129 14:04:30.254567       1 scheduler.go:139] [WaitForPodsOnCache] Pod test-deployment3-84f8ccf757-hkk2f encontrado no cache.
I0129 14:04:30.254580       1 scheduler.go:117] [WaitForPodsOnCache] Verificando se o pod test-deployment2-7b58dbd49-24pwt está no cache...
I0129 14:04:30.254592       1 scheduler.go:606] [GetControllerMetricInfo] Iniciando para o pod: default/test-deployment2-7b58dbd49-24pwt
I0129 14:04:30.254604       1 scheduler.go:611] [GetControllerMetricInfo] Obtendo o nome do controlador para o pod: default/test-deployment2-7b58dbd49-24pwt
I0129 14:04:30.254616       1 types.go:743] [ControllerName] Verificando as anotações do pod default/test-deployment2-7b58dbd49-24pwt
I0129 14:04:30.254630       1 types.go:761] [ControllerName] Anotação 'controller' encontrada para o pod default/test-deployment2-7b58dbd49-24pwt: test-controller2
I0129 14:04:30.254644       1 scheduler.go:614] [GetControllerMetricInfo] Métricas do controlador definidas para o pod: default/test-deployment2-7b58dbd49-24pwt
I0129 14:04:30.284704       1 scheduler.go:70] Estado no Informer: map[acceptablePreemptionOverhead:10 controller:test-controller2 qosMeasuring:average]
I0129 14:04:30.284822       1 scheduler.go:71] Estado real no cluster: map[acceptablePreemptionOverhead:10 controller:test-controller2 qosMeasuring:average]
I0129 14:04:30.284836       1 scheduler.go:139] [WaitForPodsOnCache] Pod test-deployment2-7b58dbd49-24pwt encontrado no cache.
I0129 14:04:30.284845       1 scheduler.go:606] [GetControllerMetricInfo] Iniciando para o pod: default/test-deployment3-84f8ccf757-hkk2f
I0129 14:04:30.284852       1 scheduler.go:611] [GetControllerMetricInfo] Obtendo o nome do controlador para o pod: default/test-deployment3-84f8ccf757-hkk2f
I0129 14:04:30.284860       1 types.go:743] [ControllerName] Verificando as anotações do pod default/test-deployment3-84f8ccf757-hkk2f
I0129 14:04:30.284867       1 types.go:761] [ControllerName] Anotação 'controller' encontrada para o pod default/test-deployment3-84f8ccf757-hkk2f: test-controller3
I0129 14:04:30.284876       1 scheduler.go:614] [GetControllerMetricInfo] Métricas do controlador definidas para o pod: default/test-deployment3-84f8ccf757-hkk2f
I0129 14:04:30.284887       1 scheduler.go:606] [GetControllerMetricInfo] Iniciando para o pod: default/test-deployment2-7b58dbd49-24pwt
I0129 14:04:30.284926       1 scheduler.go:611] [GetControllerMetricInfo] Obtendo o nome do controlador para o pod: default/test-deployment2-7b58dbd49-24pwt
I0129 14:04:30.284963       1 types.go:743] [ControllerName] Verificando as anotações do pod default/test-deployment2-7b58dbd49-24pwt
I0129 14:04:30.284971       1 types.go:761] [ControllerName] Anotação 'controller' encontrada para o pod default/test-deployment2-7b58dbd49-24pwt: test-controller2
I0129 14:04:30.284977       1 scheduler.go:614] [GetControllerMetricInfo] Métricas do controlador definidas para o pod: default/test-deployment2-7b58dbd49-24pwt
I0129 14:04:30.284998       1 scheduler.go:98] [HigherPrecedence] Métricas para test-deployment3-84f8ccf757-hkk2f: QoS = -18.241666, Importância = 0.80
I0129 14:04:30.285009       1 scheduler.go:99] [HigherPrecedence] Métricas para test-deployment2-7b58dbd49-24pwt: QoS = -28.566865, Importância = 0.80
I0129 14:04:30.285018       1 scheduler.go:110] [HigherPrecedence] Decisão final: test-deployment3-84f8ccf757-hkk2f tem precedência sobre test-deployment2-7b58dbd49-24pwt? false
I0129 14:04:30.285041       1 postFilter.go:186] [Preempt] Verificando pods de menor precedência no nó minikube que precisam ter o campo NominatedNodeName limpo
I0129 14:04:30.285057       1 postFilter.go:196] [Preempt] Finalizado para o nó minikube. Pod default/test-deployment3-84f8ccf757-hkk2f deve ser alocado agora.
I0129 14:04:30.285065       1 postFilter.go:49] [PostFilter] Nó nominado para o pod default/test-deployment3-84f8ccf757-hkk2f: minikube
I0129 14:04:30.394300       1 scheduler.go:258] [OnUpdatePod] Iniciando processamento de atualização de pod
I0129 14:04:30.394354       1 scheduler.go:262] [OnUpdatePod] Pod atualizado detectado: default/test-deployment3-84f8ccf757-hkk2f, Anotações: map[acceptablePreemptionOverhead:10 controller:test-controller3 qosMeasuring:average]
I0129 14:04:30.394386       1 scheduler.go:265] [OnUpdatePod] Comparando estado no Informer e estado real no cluster para o pod default/test-deployment3-84f8ccf757-hkk2f
I0129 14:04:30.406263       1 scheduler.go:70] Estado no Informer: map[acceptablePreemptionOverhead:10 controller:test-controller3 qosMeasuring:average]
I0129 14:04:30.406297       1 scheduler.go:71] Estado real no cluster: map[acceptablePreemptionOverhead:10 controller:test-controller3 qosMeasuring:average]
I0129 14:04:30.406310       1 scheduler.go:275] [OnUpdatePod] Atualizando informações de métricas para o pod default/test-deployment3-84f8ccf757-hkk2f
I0129 14:04:30.406319       1 types.go:743] [ControllerName] Verificando as anotações do pod default/test-deployment3-84f8ccf757-hkk2f
I0129 14:04:30.406326       1 types.go:761] [ControllerName] Anotação 'controller' encontrada para o pod default/test-deployment3-84f8ccf757-hkk2f: test-controller3
I0129 14:04:30.406352       1 scheduler.go:277] [OnUpdatePod] Atualizando 'LastStatus' do pod default/test-deployment3-84f8ccf757-hkk2f nas métricas
I0129 14:04:30.406358       1 scheduler.go:279] [OnUpdatePod] Métrica atualizada para o pod default/test-deployment3-84f8ccf757-hkk2f
I0129 14:04:30.406370       1 scheduler.go:283] [OnUpdatePod] Finalizando processamento de atualização de pod para default/test-deployment3-84f8ccf757-hkk2f
I0129 14:04:33.546471       1 postFilter.go:29] [PostFilter] PostFilter chamado para pod: default/test-deployment2-7b58dbd49-24pwt
I0129 14:04:33.546586       1 postFilter.go:76] [Preempt] Comparando pod original com o atualizado...
I0129 14:04:33.546607       1 postFilter.go:83] [Preempt] Successfully retrieved updated pod default/test-deployment2-7b58dbd49-24pwt from lister
I0129 14:04:33.590863       1 postFilter.go:233] [compareNodeResources] Recursos calculados no nó minikube: CPU = 750 mCPU, Memória = 178257920 bytes
I0129 14:04:33.598497       1 postFilter.go:234] [compareNodeResources] Recursos do snapshot no nó minikube: CPU = 750 mCPU, Memória = 178257920 bytes
I0129 14:04:33.598536       1 postFilter.go:240] [compareNodeResources] Recursos de CPU do nó minikube estão sincronizados: 750 mCPU
I0129 14:04:33.598552       1 postFilter.go:246] [compareNodeResources] Recursos de memória do nó minikube estão sincronizados: 178257920 bytes
I0129 14:04:33.599018       1 postFilter.go:147] [PREEMPT CALL] The node minikube  was chosen to allocate pod test-deployment2-7b58dbd49-24pwt
I0129 14:04:33.599045       1 postFilter.go:151] [Preempt] Iniciando a remoção dos pods preemptados no nó minikube para alocar o pod default/test-deployment2-7b58dbd49-24pwt. Total de vítimas: 0
I0129 14:04:33.599077       1 postFilter.go:179] [Preempt] Total de pods preemptados no nó minikube: 0
W0129 14:04:33.599292       1 scheduler.go:79] [HigherPrecedence] Tentativa de comparar o pod test-deployment2-7b58dbd49-24pwt consigo mesmo. Retornando false.
I0129 14:04:33.599311       1 scheduler.go:84] [HigherPrecedence] Calculando precedência entre test-deployment2-7b58dbd49-24pwt e test-deployment3-84f8ccf757-hkk2f
I0129 14:04:33.599324       1 scheduler.go:117] [WaitForPodsOnCache] Verificando se o pod test-deployment2-7b58dbd49-24pwt está no cache...
I0129 14:04:33.599351       1 scheduler.go:606] [GetControllerMetricInfo] Iniciando para o pod: default/test-deployment2-7b58dbd49-24pwt
I0129 14:04:33.599363       1 scheduler.go:611] [GetControllerMetricInfo] Obtendo o nome do controlador para o pod: default/test-deployment2-7b58dbd49-24pwt
I0129 14:04:33.599376       1 types.go:743] [ControllerName] Verificando as anotações do pod default/test-deployment2-7b58dbd49-24pwt
I0129 14:04:33.599389       1 types.go:761] [ControllerName] Anotação 'controller' encontrada para o pod default/test-deployment2-7b58dbd49-24pwt: test-controller2
I0129 14:04:33.599402       1 scheduler.go:614] [GetControllerMetricInfo] Métricas do controlador definidas para o pod: default/test-deployment2-7b58dbd49-24pwt
I0129 14:04:33.617239       1 scheduler.go:70] Estado no Informer: map[acceptablePreemptionOverhead:10 controller:test-controller2 qosMeasuring:average]
I0129 14:04:33.617292       1 scheduler.go:71] Estado real no cluster: map[acceptablePreemptionOverhead:10 controller:test-controller2 qosMeasuring:average]
I0129 14:04:33.617305       1 scheduler.go:139] [WaitForPodsOnCache] Pod test-deployment2-7b58dbd49-24pwt encontrado no cache.
I0129 14:04:33.617314       1 scheduler.go:117] [WaitForPodsOnCache] Verificando se o pod test-deployment3-84f8ccf757-hkk2f está no cache...
I0129 14:04:33.617323       1 scheduler.go:606] [GetControllerMetricInfo] Iniciando para o pod: default/test-deployment3-84f8ccf757-hkk2f
I0129 14:04:33.617332       1 scheduler.go:611] [GetControllerMetricInfo] Obtendo o nome do controlador para o pod: default/test-deployment3-84f8ccf757-hkk2f
I0129 14:04:33.617341       1 types.go:743] [ControllerName] Verificando as anotações do pod default/test-deployment3-84f8ccf757-hkk2f
I0129 14:04:33.617351       1 types.go:761] [ControllerName] Anotação 'controller' encontrada para o pod default/test-deployment3-84f8ccf757-hkk2f: test-controller3
I0129 14:04:33.617361       1 scheduler.go:614] [GetControllerMetricInfo] Métricas do controlador definidas para o pod: default/test-deployment3-84f8ccf757-hkk2f
I0129 14:04:33.632543       1 scheduler.go:70] Estado no Informer: map[acceptablePreemptionOverhead:10 controller:test-controller3 qosMeasuring:average]
I0129 14:04:33.632608       1 scheduler.go:71] Estado real no cluster: map[acceptablePreemptionOverhead:10 controller:test-controller3 qosMeasuring:average]
I0129 14:04:33.632622       1 scheduler.go:139] [WaitForPodsOnCache] Pod test-deployment3-84f8ccf757-hkk2f encontrado no cache.
I0129 14:04:33.632630       1 scheduler.go:606] [GetControllerMetricInfo] Iniciando para o pod: default/test-deployment2-7b58dbd49-24pwt
I0129 14:04:33.632638       1 scheduler.go:611] [GetControllerMetricInfo] Obtendo o nome do controlador para o pod: default/test-deployment2-7b58dbd49-24pwt
I0129 14:04:33.632652       1 types.go:743] [ControllerName] Verificando as anotações do pod default/test-deployment2-7b58dbd49-24pwt
I0129 14:04:33.632660       1 types.go:761] [ControllerName] Anotação 'controller' encontrada para o pod default/test-deployment2-7b58dbd49-24pwt: test-controller2
I0129 14:04:33.632668       1 scheduler.go:614] [GetControllerMetricInfo] Métricas do controlador definidas para o pod: default/test-deployment2-7b58dbd49-24pwt
I0129 14:04:33.632679       1 scheduler.go:606] [GetControllerMetricInfo] Iniciando para o pod: default/test-deployment3-84f8ccf757-hkk2f
I0129 14:04:33.632686       1 scheduler.go:611] [GetControllerMetricInfo] Obtendo o nome do controlador para o pod: default/test-deployment3-84f8ccf757-hkk2f
I0129 14:04:33.632692       1 types.go:743] [ControllerName] Verificando as anotações do pod default/test-deployment3-84f8ccf757-hkk2f
I0129 14:04:33.632699       1 types.go:761] [ControllerName] Anotação 'controller' encontrada para o pod default/test-deployment3-84f8ccf757-hkk2f: test-controller3
I0129 14:04:33.632706       1 scheduler.go:614] [GetControllerMetricInfo] Métricas do controlador definidas para o pod: default/test-deployment3-84f8ccf757-hkk2f
I0129 14:04:33.632721       1 scheduler.go:98] [HigherPrecedence] Métricas para test-deployment2-7b58dbd49-24pwt: QoS = -32.667384, Importância = 0.80
I0129 14:04:33.632765       1 scheduler.go:99] [HigherPrecedence] Métricas para test-deployment3-84f8ccf757-hkk2f: QoS = -22.342185, Importância = 0.80
I0129 14:04:33.632777       1 scheduler.go:110] [HigherPrecedence] Decisão final: test-deployment2-7b58dbd49-24pwt tem precedência sobre test-deployment3-84f8ccf757-hkk2f? true
I0129 14:04:33.632795       1 postFilter.go:186] [Preempt] Verificando pods de menor precedência no nó minikube que precisam ter o campo NominatedNodeName limpo
I0129 14:04:33.632811       1 postFilter.go:188] [Preempt] Limpando o campo NominatedNodeName do pod default/test-deployment3-84f8ccf757-hkk2f
I0129 14:04:33.689689       1 postFilter.go:196] [Preempt] Finalizado para o nó minikube. Pod default/test-deployment2-7b58dbd49-24pwt deve ser alocado agora.
I0129 14:04:33.689791       1 postFilter.go:49] [PostFilter] Nó nominado para o pod default/test-deployment2-7b58dbd49-24pwt: minikube
I0129 14:04:33.706485       1 scheduler.go:258] [OnUpdatePod] Iniciando processamento de atualização de pod
I0129 14:04:33.706621       1 scheduler.go:262] [OnUpdatePod] Pod atualizado detectado: default/test-deployment3-84f8ccf757-hkk2f, Anotações: map[acceptablePreemptionOverhead:10 controller:test-controller3 qosMeasuring:average]
I0129 14:04:33.707228       1 scheduler.go:265] [OnUpdatePod] Comparando estado no Informer e estado real no cluster para o pod default/test-deployment3-84f8ccf757-hkk2f
I0129 14:04:33.717063       1 scheduler.go:70] Estado no Informer: map[acceptablePreemptionOverhead:10 controller:test-controller3 qosMeasuring:average]
I0129 14:04:33.718337       1 scheduler.go:71] Estado real no cluster: map[acceptablePreemptionOverhead:10 controller:test-controller3 qosMeasuring:average]
I0129 14:04:33.718469       1 scheduler.go:275] [OnUpdatePod] Atualizando informações de métricas para o pod default/test-deployment3-84f8ccf757-hkk2f
I0129 14:04:33.718482       1 types.go:743] [ControllerName] Verificando as anotações do pod default/test-deployment3-84f8ccf757-hkk2f
I0129 14:04:33.718491       1 types.go:761] [ControllerName] Anotação 'controller' encontrada para o pod default/test-deployment3-84f8ccf757-hkk2f: test-controller3
I0129 14:04:33.718580       1 scheduler.go:277] [OnUpdatePod] Atualizando 'LastStatus' do pod default/test-deployment3-84f8ccf757-hkk2f nas métricas
I0129 14:04:33.718590       1 scheduler.go:279] [OnUpdatePod] Métrica atualizada para o pod default/test-deployment3-84f8ccf757-hkk2f
I0129 14:04:33.718604       1 scheduler.go:283] [OnUpdatePod] Finalizando processamento de atualização de pod para default/test-deployment3-84f8ccf757-hkk2f
I0129 14:04:58.380262       1 scheduler.go:54] [QueueSort] Comparando prioridade de test-deployment2-7b58dbd49-24pwt com test-deployment3-84f8ccf757-hkk2f
I0129 14:04:58.380585       1 scheduler.go:84] [HigherPrecedence] Calculando precedência entre test-deployment2-7b58dbd49-24pwt e test-deployment3-84f8ccf757-hkk2f
I0129 14:04:58.380665       1 scheduler.go:117] [WaitForPodsOnCache] Verificando se o pod test-deployment2-7b58dbd49-24pwt está no cache...
I0129 14:04:58.380720       1 scheduler.go:606] [GetControllerMetricInfo] Iniciando para o pod: default/test-deployment2-7b58dbd49-24pwt
I0129 14:04:58.380775       1 scheduler.go:611] [GetControllerMetricInfo] Obtendo o nome do controlador para o pod: default/test-deployment2-7b58dbd49-24pwt
I0129 14:04:58.380945       1 types.go:743] [ControllerName] Verificando as anotações do pod default/test-deployment2-7b58dbd49-24pwt
I0129 14:04:58.381045       1 types.go:761] [ControllerName] Anotação 'controller' encontrada para o pod default/test-deployment2-7b58dbd49-24pwt: test-controller2
I0129 14:04:58.387518       1 scheduler.go:614] [GetControllerMetricInfo] Métricas do controlador definidas para o pod: default/test-deployment2-7b58dbd49-24pwt
I0129 14:04:58.497778       1 scheduler.go:70] Estado no Informer: map[acceptablePreemptionOverhead:10 controller:test-controller2 qosMeasuring:average]
I0129 14:04:58.503457       1 scheduler.go:71] Estado real no cluster: map[acceptablePreemptionOverhead:10 controller:test-controller2 qosMeasuring:average]
I0129 14:04:58.505314       1 scheduler.go:139] [WaitForPodsOnCache] Pod test-deployment2-7b58dbd49-24pwt encontrado no cache.
I0129 14:04:58.505369       1 scheduler.go:117] [WaitForPodsOnCache] Verificando se o pod test-deployment3-84f8ccf757-hkk2f está no cache...
I0129 14:04:58.505383       1 scheduler.go:606] [GetControllerMetricInfo] Iniciando para o pod: default/test-deployment3-84f8ccf757-hkk2f
I0129 14:04:58.505395       1 scheduler.go:611] [GetControllerMetricInfo] Obtendo o nome do controlador para o pod: default/test-deployment3-84f8ccf757-hkk2f
I0129 14:04:58.505408       1 types.go:743] [ControllerName] Verificando as anotações do pod default/test-deployment3-84f8ccf757-hkk2f
I0129 14:04:58.505423       1 types.go:761] [ControllerName] Anotação 'controller' encontrada para o pod default/test-deployment3-84f8ccf757-hkk2f: test-controller3
I0129 14:04:58.505465       1 scheduler.go:614] [GetControllerMetricInfo] Métricas do controlador definidas para o pod: default/test-deployment3-84f8ccf757-hkk2f
I0129 14:04:58.523459       1 scheduler.go:70] Estado no Informer: map[acceptablePreemptionOverhead:10 controller:test-controller3 qosMeasuring:average]
I0129 14:04:58.523587       1 scheduler.go:71] Estado real no cluster: map[acceptablePreemptionOverhead:10 controller:test-controller3 qosMeasuring:average]
I0129 14:04:58.523609       1 scheduler.go:139] [WaitForPodsOnCache] Pod test-deployment3-84f8ccf757-hkk2f encontrado no cache.
I0129 14:04:58.523623       1 scheduler.go:606] [GetControllerMetricInfo] Iniciando para o pod: default/test-deployment2-7b58dbd49-24pwt
I0129 14:04:58.523636       1 scheduler.go:611] [GetControllerMetricInfo] Obtendo o nome do controlador para o pod: default/test-deployment2-7b58dbd49-24pwt
I0129 14:04:58.523648       1 types.go:743] [ControllerName] Verificando as anotações do pod default/test-deployment2-7b58dbd49-24pwt
I0129 14:04:58.523661       1 types.go:761] [ControllerName] Anotação 'controller' encontrada para o pod default/test-deployment2-7b58dbd49-24pwt: test-controller2
I0129 14:04:58.523675       1 scheduler.go:614] [GetControllerMetricInfo] Métricas do controlador definidas para o pod: default/test-deployment2-7b58dbd49-24pwt
I0129 14:04:58.523708       1 scheduler.go:606] [GetControllerMetricInfo] Iniciando para o pod: default/test-deployment3-84f8ccf757-hkk2f
I0129 14:04:58.523719       1 scheduler.go:611] [GetControllerMetricInfo] Obtendo o nome do controlador para o pod: default/test-deployment3-84f8ccf757-hkk2f
I0129 14:04:58.523728       1 types.go:743] [ControllerName] Verificando as anotações do pod default/test-deployment3-84f8ccf757-hkk2f
I0129 14:04:58.523738       1 types.go:761] [ControllerName] Anotação 'controller' encontrada para o pod default/test-deployment3-84f8ccf757-hkk2f: test-controller3
I0129 14:04:58.523749       1 scheduler.go:614] [GetControllerMetricInfo] Métricas do controlador definidas para o pod: default/test-deployment3-84f8ccf757-hkk2f
I0129 14:04:58.523781       1 scheduler.go:98] [HigherPrecedence] Métricas para test-deployment2-7b58dbd49-24pwt: QoS = -57.448648, Importância = 0.80
I0129 14:04:58.523849       1 scheduler.go:99] [HigherPrecedence] Métricas para test-deployment3-84f8ccf757-hkk2f: QoS = -47.123449, Importância = 0.80
I0129 14:04:58.523864       1 scheduler.go:110] [HigherPrecedence] Decisão final: test-deployment2-7b58dbd49-24pwt tem precedência sobre test-deployment3-84f8ccf757-hkk2f? true
I0129 14:04:58.523899       1 scheduler.go:60] [QueueSort] Precedência determinada: test-deployment2-7b58dbd49-24pwt tem precedência sobre test-deployment3-84f8ccf757-hkk2f? true
I0129 14:04:58.526191       1 scheduler.go:146] [Reserve] resources reserved at node minikube for pod test-deployment2-7b58dbd49-24pwt_default at 2025-01-29 14:04:58.525112058 +0000 UTC m=+271.628667355
I0129 14:04:58.526421       1 types.go:743] [ControllerName] Verificando as anotações do pod default/test-deployment2-7b58dbd49-24pwt
I0129 14:04:58.526439       1 types.go:761] [ControllerName] Anotação 'controller' encontrada para o pod default/test-deployment2-7b58dbd49-24pwt: test-controller2
I0129 14:04:58.526483       1 scheduler.go:148] [Reserve] Status de alocação atual para o pod test-deployment2-7b58dbd49-24pwt_default: 
I0129 14:04:58.526495       1 scheduler.go:150] [Reserve] Status de alocação atualizado para o pod test-deployment2-7b58dbd49-24pwt_default: allocating
I0129 14:04:58.530390       1 postFilter.go:29] [PostFilter] PostFilter chamado para pod: default/test-deployment3-84f8ccf757-hkk2f
I0129 14:04:58.530481       1 postFilter.go:76] [Preempt] Comparando pod original com o atualizado...
I0129 14:04:58.530499       1 postFilter.go:83] [Preempt] Successfully retrieved updated pod default/test-deployment3-84f8ccf757-hkk2f from lister
I0129 14:04:58.531043       1 scheduler.go:174] [PreBind] Validando o pod test-deployment2-7b58dbd49-24pwt antes de vincular ao node minikube
I0129 14:04:58.562973       1 postFilter.go:233] [compareNodeResources] Recursos calculados no nó minikube: CPU = 1450 mCPU, Memória = 459276288 bytes
I0129 14:04:58.571827       1 postFilter.go:234] [compareNodeResources] Recursos do snapshot no nó minikube: CPU = 1450 mCPU, Memória = 459276288 bytes
I0129 14:04:58.571859       1 postFilter.go:240] [compareNodeResources] Recursos de CPU do nó minikube estão sincronizados: 1450 mCPU
I0129 14:04:58.571872       1 postFilter.go:246] [compareNodeResources] Recursos de memória do nó minikube estão sincronizados: 459276288 bytes
I0129 14:04:58.578439       1 scheduler.go:606] [GetControllerMetricInfo] Iniciando para o pod: default/test-deployment2-7b58dbd49-24pwt
I0129 14:04:58.578467       1 scheduler.go:611] [GetControllerMetricInfo] Obtendo o nome do controlador para o pod: default/test-deployment2-7b58dbd49-24pwt
I0129 14:04:58.578478       1 types.go:743] [ControllerName] Verificando as anotações do pod default/test-deployment2-7b58dbd49-24pwt
I0129 14:04:58.578489       1 types.go:761] [ControllerName] Anotação 'controller' encontrada para o pod default/test-deployment2-7b58dbd49-24pwt: test-controller2
I0129 14:04:58.578500       1 scheduler.go:614] [GetControllerMetricInfo] Métricas do controlador definidas para o pod: default/test-deployment2-7b58dbd49-24pwt
I0129 14:04:58.578512       1 scheduler.go:84] [HigherPrecedence] Calculando precedência entre test-deployment3-84f8ccf757-hkk2f e test-deployment2-7b58dbd49-24pwt
I0129 14:04:58.578521       1 scheduler.go:117] [WaitForPodsOnCache] Verificando se o pod test-deployment3-84f8ccf757-hkk2f está no cache...
I0129 14:04:58.578530       1 scheduler.go:606] [GetControllerMetricInfo] Iniciando para o pod: default/test-deployment3-84f8ccf757-hkk2f
I0129 14:04:58.578538       1 scheduler.go:611] [GetControllerMetricInfo] Obtendo o nome do controlador para o pod: default/test-deployment3-84f8ccf757-hkk2f
I0129 14:04:58.578545       1 types.go:743] [ControllerName] Verificando as anotações do pod default/test-deployment3-84f8ccf757-hkk2f
I0129 14:04:58.578555       1 types.go:761] [ControllerName] Anotação 'controller' encontrada para o pod default/test-deployment3-84f8ccf757-hkk2f: test-controller3
I0129 14:04:58.578571       1 scheduler.go:614] [GetControllerMetricInfo] Métricas do controlador definidas para o pod: default/test-deployment3-84f8ccf757-hkk2f
I0129 14:04:58.584442       1 scheduler.go:182] [PostBind] Chamado para pod test-deployment2-7b58dbd49-24pwt
I0129 14:04:58.600002       1 scheduler.go:200] [PostBind] Pod test-deployment2-7b58dbd49-24pwt - Início do binding: 2025-01-29 14:04:58.531052246 +0000 UTC m=+271.634607547, Fim do binding: 2025-01-29 14:04:58.599989664 +0000 UTC m=+271.703545016
I0129 14:04:58.598800       1 scheduler.go:70] Estado no Informer: map[acceptablePreemptionOverhead:10 controller:test-controller3 qosMeasuring:average]
I0129 14:04:58.600202       1 scheduler.go:71] Estado real no cluster: map[acceptablePreemptionOverhead:10 controller:test-controller3 qosMeasuring:average]
I0129 14:04:58.600217       1 scheduler.go:139] [WaitForPodsOnCache] Pod test-deployment3-84f8ccf757-hkk2f encontrado no cache.
I0129 14:04:58.600228       1 scheduler.go:117] [WaitForPodsOnCache] Verificando se o pod test-deployment2-7b58dbd49-24pwt está no cache...
I0129 14:04:58.600236       1 scheduler.go:606] [GetControllerMetricInfo] Iniciando para o pod: default/test-deployment2-7b58dbd49-24pwt
I0129 14:04:58.600261       1 types.go:743] [ControllerName] Verificando as anotações do pod default/test-deployment2-7b58dbd49-24pwt
I0129 14:04:58.600301       1 types.go:761] [ControllerName] Anotação 'controller' encontrada para o pod default/test-deployment2-7b58dbd49-24pwt: test-controller2
I0129 14:04:58.600345       1 scheduler.go:207] [PostBind] Métricas atualizadas para o pod test-deployment2-7b58dbd49-24pwt
I0129 14:04:58.599353       1 scheduler.go:258] [OnUpdatePod] Iniciando processamento de atualização de pod
I0129 14:04:58.604646       1 scheduler.go:262] [OnUpdatePod] Pod atualizado detectado: default/test-deployment2-7b58dbd49-24pwt, Anotações: map[acceptablePreemptionOverhead:10 controller:test-controller2 qosMeasuring:average]
I0129 14:04:58.604722       1 scheduler.go:265] [OnUpdatePod] Comparando estado no Informer e estado real no cluster para o pod default/test-deployment2-7b58dbd49-24pwt
I0129 14:04:58.606002       1 scheduler.go:611] [GetControllerMetricInfo] Obtendo o nome do controlador para o pod: default/test-deployment2-7b58dbd49-24pwt
I0129 14:04:58.606097       1 types.go:743] [ControllerName] Verificando as anotações do pod default/test-deployment2-7b58dbd49-24pwt
I0129 14:04:58.606203       1 types.go:761] [ControllerName] Anotação 'controller' encontrada para o pod default/test-deployment2-7b58dbd49-24pwt: test-controller2
I0129 14:04:58.606227       1 scheduler.go:614] [GetControllerMetricInfo] Métricas do controlador definidas para o pod: default/test-deployment2-7b58dbd49-24pwt
I0129 14:04:58.627561       1 scheduler.go:70] Estado no Informer: map[acceptablePreemptionOverhead:10 controller:test-controller2 qosMeasuring:average]
I0129 14:04:58.627612       1 scheduler.go:71] Estado real no cluster: map[acceptablePreemptionOverhead:10 controller:test-controller2 qosMeasuring:average]
I0129 14:04:58.627627       1 scheduler.go:275] [OnUpdatePod] Atualizando informações de métricas para o pod default/test-deployment2-7b58dbd49-24pwt
I0129 14:04:58.628077       1 scheduler.go:70] Estado no Informer: map[acceptablePreemptionOverhead:10 controller:test-controller2 qosMeasuring:average]
I0129 14:04:58.628413       1 scheduler.go:71] Estado real no cluster: map[acceptablePreemptionOverhead:10 controller:test-controller2 qosMeasuring:average]
I0129 14:04:58.628755       1 scheduler.go:139] [WaitForPodsOnCache] Pod test-deployment2-7b58dbd49-24pwt encontrado no cache.
I0129 14:04:58.628902       1 scheduler.go:606] [GetControllerMetricInfo] Iniciando para o pod: default/test-deployment3-84f8ccf757-hkk2f
I0129 14:04:58.629026       1 types.go:743] [ControllerName] Verificando as anotações do pod default/test-deployment2-7b58dbd49-24pwt
I0129 14:04:58.629292       1 types.go:761] [ControllerName] Anotação 'controller' encontrada para o pod default/test-deployment2-7b58dbd49-24pwt: test-controller2
I0129 14:04:58.629525       1 scheduler.go:277] [OnUpdatePod] Atualizando 'LastStatus' do pod default/test-deployment2-7b58dbd49-24pwt nas métricas
I0129 14:04:58.629559       1 scheduler.go:279] [OnUpdatePod] Métrica atualizada para o pod default/test-deployment2-7b58dbd49-24pwt
I0129 14:04:58.629823       1 scheduler.go:283] [OnUpdatePod] Finalizando processamento de atualização de pod para default/test-deployment2-7b58dbd49-24pwt
I0129 14:04:58.629950       1 scheduler.go:258] [OnUpdatePod] Iniciando processamento de atualização de pod
I0129 14:04:58.630229       1 scheduler.go:262] [OnUpdatePod] Pod atualizado detectado: default/test-deployment2-7b58dbd49-24pwt, Anotações: map[acceptablePreemptionOverhead:10 controller:test-controller2 qosMeasuring:average]
I0129 14:04:58.630342       1 scheduler.go:265] [OnUpdatePod] Comparando estado no Informer e estado real no cluster para o pod default/test-deployment2-7b58dbd49-24pwt
I0129 14:04:58.632363       1 scheduler.go:611] [GetControllerMetricInfo] Obtendo o nome do controlador para o pod: default/test-deployment3-84f8ccf757-hkk2f
I0129 14:04:58.637680       1 types.go:743] [ControllerName] Verificando as anotações do pod default/test-deployment3-84f8ccf757-hkk2f
I0129 14:04:58.637804       1 types.go:761] [ControllerName] Anotação 'controller' encontrada para o pod default/test-deployment3-84f8ccf757-hkk2f: test-controller3
I0129 14:04:58.637828       1 scheduler.go:614] [GetControllerMetricInfo] Métricas do controlador definidas para o pod: default/test-deployment3-84f8ccf757-hkk2f
I0129 14:04:58.637851       1 scheduler.go:606] [GetControllerMetricInfo] Iniciando para o pod: default/test-deployment2-7b58dbd49-24pwt
I0129 14:04:58.637865       1 scheduler.go:611] [GetControllerMetricInfo] Obtendo o nome do controlador para o pod: default/test-deployment2-7b58dbd49-24pwt
I0129 14:04:58.637878       1 types.go:743] [ControllerName] Verificando as anotações do pod default/test-deployment2-7b58dbd49-24pwt
I0129 14:04:58.637892       1 types.go:761] [ControllerName] Anotação 'controller' encontrada para o pod default/test-deployment2-7b58dbd49-24pwt: test-controller2
I0129 14:04:58.637907       1 scheduler.go:614] [GetControllerMetricInfo] Métricas do controlador definidas para o pod: default/test-deployment2-7b58dbd49-24pwt
I0129 14:04:58.637931       1 scheduler.go:98] [HigherPrecedence] Métricas para test-deployment3-84f8ccf757-hkk2f: QoS = -47.321386, Importância = 0.80
I0129 14:04:58.637950       1 scheduler.go:99] [HigherPrecedence] Métricas para test-deployment2-7b58dbd49-24pwt: QoS = -57.707909, Importância = 0.80
I0129 14:04:58.637965       1 scheduler.go:110] [HigherPrecedence] Decisão final: test-deployment3-84f8ccf757-hkk2f tem precedência sobre test-deployment2-7b58dbd49-24pwt? false
I0129 14:04:58.638065       1 postFilter.go:144] [PREEMPT CALL] No node was chosen to allocate pod test-deployment3-84f8ccf757-hkk2f
W0129 14:04:58.638085       1 postFilter.go:45] [PostFilter] Nenhum nó nominado após a preempção para o pod: default/test-deployment3-84f8ccf757-hkk2f
I0129 14:04:58.644203       1 scheduler.go:70] Estado no Informer: map[acceptablePreemptionOverhead:10 controller:test-controller2 qosMeasuring:average]
I0129 14:04:58.644250       1 scheduler.go:71] Estado real no cluster: map[acceptablePreemptionOverhead:10 controller:test-controller2 qosMeasuring:average]
I0129 14:04:58.644271       1 scheduler.go:275] [OnUpdatePod] Atualizando informações de métricas para o pod default/test-deployment2-7b58dbd49-24pwt
I0129 14:04:58.644279       1 types.go:743] [ControllerName] Verificando as anotações do pod default/test-deployment2-7b58dbd49-24pwt
I0129 14:04:58.644286       1 types.go:761] [ControllerName] Anotação 'controller' encontrada para o pod default/test-deployment2-7b58dbd49-24pwt: test-controller2
I0129 14:04:58.644297       1 scheduler.go:277] [OnUpdatePod] Atualizando 'LastStatus' do pod default/test-deployment2-7b58dbd49-24pwt nas métricas
I0129 14:04:58.644303       1 scheduler.go:279] [OnUpdatePod] Métrica atualizada para o pod default/test-deployment2-7b58dbd49-24pwt
I0129 14:04:58.644353       1 scheduler.go:283] [OnUpdatePod] Finalizando processamento de atualização de pod para default/test-deployment2-7b58dbd49-24pwt
I0129 14:05:01.574968       1 postFilter.go:29] [PostFilter] PostFilter chamado para pod: default/test-deployment3-84f8ccf757-hkk2f
I0129 14:05:01.575340       1 postFilter.go:76] [Preempt] Comparando pod original com o atualizado...
I0129 14:05:01.575410       1 postFilter.go:83] [Preempt] Successfully retrieved updated pod default/test-deployment3-84f8ccf757-hkk2f from lister
I0129 14:05:01.902537       1 postFilter.go:233] [compareNodeResources] Recursos calculados no nó minikube: CPU = 1450 mCPU, Memória = 459276288 bytes
I0129 14:05:01.902725       1 postFilter.go:234] [compareNodeResources] Recursos do snapshot no nó minikube: CPU = 1450 mCPU, Memória = 459276288 bytes
I0129 14:05:01.902749       1 postFilter.go:240] [compareNodeResources] Recursos de CPU do nó minikube estão sincronizados: 1450 mCPU
I0129 14:05:01.902765       1 postFilter.go:246] [compareNodeResources] Recursos de memória do nó minikube estão sincronizados: 459276288 bytes
I0129 14:05:01.903583       1 scheduler.go:606] [GetControllerMetricInfo] Iniciando para o pod: default/test-deployment2-7b58dbd49-24pwt
I0129 14:05:01.910790       1 scheduler.go:611] [GetControllerMetricInfo] Obtendo o nome do controlador para o pod: default/test-deployment2-7b58dbd49-24pwt
I0129 14:05:01.910849       1 types.go:743] [ControllerName] Verificando as anotações do pod default/test-deployment2-7b58dbd49-24pwt
I0129 14:05:01.910865       1 types.go:761] [ControllerName] Anotação 'controller' encontrada para o pod default/test-deployment2-7b58dbd49-24pwt: test-controller2
I0129 14:05:01.910921       1 scheduler.go:614] [GetControllerMetricInfo] Métricas do controlador definidas para o pod: default/test-deployment2-7b58dbd49-24pwt
I0129 14:05:01.910936       1 scheduler.go:84] [HigherPrecedence] Calculando precedência entre test-deployment3-84f8ccf757-hkk2f e test-deployment2-7b58dbd49-24pwt
I0129 14:05:01.910948       1 scheduler.go:117] [WaitForPodsOnCache] Verificando se o pod test-deployment3-84f8ccf757-hkk2f está no cache...
I0129 14:05:01.910958       1 scheduler.go:606] [GetControllerMetricInfo] Iniciando para o pod: default/test-deployment3-84f8ccf757-hkk2f
I0129 14:05:01.911108       1 scheduler.go:611] [GetControllerMetricInfo] Obtendo o nome do controlador para o pod: default/test-deployment3-84f8ccf757-hkk2f
I0129 14:05:01.911359       1 types.go:743] [ControllerName] Verificando as anotações do pod default/test-deployment3-84f8ccf757-hkk2f
I0129 14:05:01.911373       1 types.go:761] [ControllerName] Anotação 'controller' encontrada para o pod default/test-deployment3-84f8ccf757-hkk2f: test-controller3
I0129 14:05:01.911386       1 scheduler.go:614] [GetControllerMetricInfo] Métricas do controlador definidas para o pod: default/test-deployment3-84f8ccf757-hkk2f
I0129 14:05:01.927690       1 scheduler.go:70] Estado no Informer: map[acceptablePreemptionOverhead:10 controller:test-controller3 qosMeasuring:average]
I0129 14:05:01.928090       1 scheduler.go:71] Estado real no cluster: map[acceptablePreemptionOverhead:10 controller:test-controller3 qosMeasuring:average]
I0129 14:05:01.928348       1 scheduler.go:139] [WaitForPodsOnCache] Pod test-deployment3-84f8ccf757-hkk2f encontrado no cache.
I0129 14:05:01.928574       1 scheduler.go:117] [WaitForPodsOnCache] Verificando se o pod test-deployment2-7b58dbd49-24pwt está no cache...
I0129 14:05:01.928789       1 scheduler.go:606] [GetControllerMetricInfo] Iniciando para o pod: default/test-deployment2-7b58dbd49-24pwt
I0129 14:05:01.928804       1 scheduler.go:611] [GetControllerMetricInfo] Obtendo o nome do controlador para o pod: default/test-deployment2-7b58dbd49-24pwt
I0129 14:05:01.928816       1 types.go:743] [ControllerName] Verificando as anotações do pod default/test-deployment2-7b58dbd49-24pwt
I0129 14:05:01.928828       1 types.go:761] [ControllerName] Anotação 'controller' encontrada para o pod default/test-deployment2-7b58dbd49-24pwt: test-controller2
I0129 14:05:01.928862       1 scheduler.go:614] [GetControllerMetricInfo] Métricas do controlador definidas para o pod: default/test-deployment2-7b58dbd49-24pwt
I0129 14:05:01.940311       1 scheduler.go:70] Estado no Informer: map[acceptablePreemptionOverhead:10 controller:test-controller2 qosMeasuring:average]
I0129 14:05:01.940353       1 scheduler.go:71] Estado real no cluster: map[acceptablePreemptionOverhead:10 controller:test-controller2 qosMeasuring:average]
I0129 14:05:01.940366       1 scheduler.go:139] [WaitForPodsOnCache] Pod test-deployment2-7b58dbd49-24pwt encontrado no cache.
I0129 14:05:01.940376       1 scheduler.go:606] [GetControllerMetricInfo] Iniciando para o pod: default/test-deployment3-84f8ccf757-hkk2f
I0129 14:05:01.940386       1 scheduler.go:611] [GetControllerMetricInfo] Obtendo o nome do controlador para o pod: default/test-deployment3-84f8ccf757-hkk2f
I0129 14:05:01.940396       1 types.go:743] [ControllerName] Verificando as anotações do pod default/test-deployment3-84f8ccf757-hkk2f
I0129 14:05:01.940406       1 types.go:761] [ControllerName] Anotação 'controller' encontrada para o pod default/test-deployment3-84f8ccf757-hkk2f: test-controller3
I0129 14:05:01.940417       1 scheduler.go:614] [GetControllerMetricInfo] Métricas do controlador definidas para o pod: default/test-deployment3-84f8ccf757-hkk2f
I0129 14:05:01.940431       1 scheduler.go:606] [GetControllerMetricInfo] Iniciando para o pod: default/test-deployment2-7b58dbd49-24pwt
I0129 14:05:01.940440       1 scheduler.go:611] [GetControllerMetricInfo] Obtendo o nome do controlador para o pod: default/test-deployment2-7b58dbd49-24pwt
I0129 14:05:01.940447       1 types.go:743] [ControllerName] Verificando as anotações do pod default/test-deployment2-7b58dbd49-24pwt
I0129 14:05:01.940459       1 types.go:761] [ControllerName] Anotação 'controller' encontrada para o pod default/test-deployment2-7b58dbd49-24pwt: test-controller2
I0129 14:05:01.940468       1 scheduler.go:614] [GetControllerMetricInfo] Métricas do controlador definidas para o pod: default/test-deployment2-7b58dbd49-24pwt
I0129 14:05:01.940488       1 scheduler.go:98] [HigherPrecedence] Métricas para test-deployment3-84f8ccf757-hkk2f: QoS = -50.653809, Importância = 0.80
I0129 14:05:01.940504       1 scheduler.go:99] [HigherPrecedence] Métricas para test-deployment2-7b58dbd49-24pwt: QoS = -56.874803, Importância = 0.80
I0129 14:05:01.940516       1 scheduler.go:110] [HigherPrecedence] Decisão final: test-deployment3-84f8ccf757-hkk2f tem precedência sobre test-deployment2-7b58dbd49-24pwt? false
I0129 14:05:01.940566       1 postFilter.go:144] [PREEMPT CALL] No node was chosen to allocate pod test-deployment3-84f8ccf757-hkk2f
W0129 14:05:01.940575       1 postFilter.go:45] [PostFilter] Nenhum nó nominado após a preempção para o pod: default/test-deployment3-84f8ccf757-hkk2f
I0129 14:05:03.159721       1 scheduler.go:258] [OnUpdatePod] Iniciando processamento de atualização de pod
I0129 14:05:03.159923       1 scheduler.go:262] [OnUpdatePod] Pod atualizado detectado: default/test-deployment2-7b58dbd49-24pwt, Anotações: map[acceptablePreemptionOverhead:10 controller:test-controller2 qosMeasuring:average]
I0129 14:05:03.159968       1 scheduler.go:265] [OnUpdatePod] Comparando estado no Informer e estado real no cluster para o pod default/test-deployment2-7b58dbd49-24pwt
I0129 14:05:03.171690       1 scheduler.go:70] Estado no Informer: map[acceptablePreemptionOverhead:10 controller:test-controller2 qosMeasuring:average]
I0129 14:05:03.172774       1 scheduler.go:71] Estado real no cluster: map[acceptablePreemptionOverhead:10 controller:test-controller2 qosMeasuring:average]
I0129 14:05:03.173348       1 scheduler.go:275] [OnUpdatePod] Atualizando informações de métricas para o pod default/test-deployment2-7b58dbd49-24pwt
I0129 14:05:03.173468       1 types.go:743] [ControllerName] Verificando as anotações do pod default/test-deployment2-7b58dbd49-24pwt
I0129 14:05:03.173481       1 types.go:761] [ControllerName] Anotação 'controller' encontrada para o pod default/test-deployment2-7b58dbd49-24pwt: test-controller2
I0129 14:05:03.173495       1 scheduler.go:277] [OnUpdatePod] Atualizando 'LastStatus' do pod default/test-deployment2-7b58dbd49-24pwt nas métricas
I0129 14:05:03.173502       1 scheduler.go:279] [OnUpdatePod] Métrica atualizada para o pod default/test-deployment2-7b58dbd49-24pwt
I0129 14:05:03.174577       1 scheduler.go:283] [OnUpdatePod] Finalizando processamento de atualização de pod para default/test-deployment2-7b58dbd49-24pwt
I0129 14:05:28.527888       1 postFilter.go:29] [PostFilter] PostFilter chamado para pod: default/test-deployment3-84f8ccf757-hkk2f
I0129 14:05:28.541395       1 postFilter.go:76] [Preempt] Comparando pod original com o atualizado...
I0129 14:05:28.541490       1 postFilter.go:83] [Preempt] Successfully retrieved updated pod default/test-deployment3-84f8ccf757-hkk2f from lister
I0129 14:05:28.558107       1 postFilter.go:233] [compareNodeResources] Recursos calculados no nó minikube: CPU = 1450 mCPU, Memória = 459276288 bytes
I0129 14:05:28.561626       1 postFilter.go:234] [compareNodeResources] Recursos do snapshot no nó minikube: CPU = 1450 mCPU, Memória = 459276288 bytes
I0129 14:05:28.561809       1 postFilter.go:240] [compareNodeResources] Recursos de CPU do nó minikube estão sincronizados: 1450 mCPU
I0129 14:05:28.562214       1 postFilter.go:246] [compareNodeResources] Recursos de memória do nó minikube estão sincronizados: 459276288 bytes
I0129 14:05:28.564600       1 scheduler.go:606] [GetControllerMetricInfo] Iniciando para o pod: default/test-deployment2-7b58dbd49-24pwt
I0129 14:05:28.564651       1 scheduler.go:611] [GetControllerMetricInfo] Obtendo o nome do controlador para o pod: default/test-deployment2-7b58dbd49-24pwt
I0129 14:05:28.564725       1 types.go:743] [ControllerName] Verificando as anotações do pod default/test-deployment2-7b58dbd49-24pwt
I0129 14:05:28.564738       1 types.go:761] [ControllerName] Anotação 'controller' encontrada para o pod default/test-deployment2-7b58dbd49-24pwt: test-controller2
I0129 14:05:28.564748       1 scheduler.go:614] [GetControllerMetricInfo] Métricas do controlador definidas para o pod: default/test-deployment2-7b58dbd49-24pwt
I0129 14:05:28.564823       1 scheduler.go:84] [HigherPrecedence] Calculando precedência entre test-deployment3-84f8ccf757-hkk2f e test-deployment2-7b58dbd49-24pwt
I0129 14:05:28.564903       1 scheduler.go:117] [WaitForPodsOnCache] Verificando se o pod test-deployment3-84f8ccf757-hkk2f está no cache...
I0129 14:05:28.564914       1 scheduler.go:606] [GetControllerMetricInfo] Iniciando para o pod: default/test-deployment3-84f8ccf757-hkk2f
I0129 14:05:28.565026       1 scheduler.go:611] [GetControllerMetricInfo] Obtendo o nome do controlador para o pod: default/test-deployment3-84f8ccf757-hkk2f
I0129 14:05:28.565152       1 types.go:743] [ControllerName] Verificando as anotações do pod default/test-deployment3-84f8ccf757-hkk2f
I0129 14:05:28.565162       1 types.go:761] [ControllerName] Anotação 'controller' encontrada para o pod default/test-deployment3-84f8ccf757-hkk2f: test-controller3
I0129 14:05:28.565170       1 scheduler.go:614] [GetControllerMetricInfo] Métricas do controlador definidas para o pod: default/test-deployment3-84f8ccf757-hkk2f
I0129 14:05:28.572091       1 scheduler.go:70] Estado no Informer: map[acceptablePreemptionOverhead:10 controller:test-controller3 qosMeasuring:average]
I0129 14:05:28.572395       1 scheduler.go:71] Estado real no cluster: map[acceptablePreemptionOverhead:10 controller:test-controller3 qosMeasuring:average]
I0129 14:05:28.572467       1 scheduler.go:139] [WaitForPodsOnCache] Pod test-deployment3-84f8ccf757-hkk2f encontrado no cache.
I0129 14:05:28.572476       1 scheduler.go:117] [WaitForPodsOnCache] Verificando se o pod test-deployment2-7b58dbd49-24pwt está no cache...
I0129 14:05:28.572484       1 scheduler.go:606] [GetControllerMetricInfo] Iniciando para o pod: default/test-deployment2-7b58dbd49-24pwt
I0129 14:05:28.572491       1 scheduler.go:611] [GetControllerMetricInfo] Obtendo o nome do controlador para o pod: default/test-deployment2-7b58dbd49-24pwt
I0129 14:05:28.572498       1 types.go:743] [ControllerName] Verificando as anotações do pod default/test-deployment2-7b58dbd49-24pwt
I0129 14:05:28.572523       1 types.go:761] [ControllerName] Anotação 'controller' encontrada para o pod default/test-deployment2-7b58dbd49-24pwt: test-controller2
I0129 14:05:28.572531       1 scheduler.go:614] [GetControllerMetricInfo] Métricas do controlador definidas para o pod: default/test-deployment2-7b58dbd49-24pwt
I0129 14:05:28.581030       1 scheduler.go:70] Estado no Informer: map[acceptablePreemptionOverhead:10 controller:test-controller2 qosMeasuring:average]
I0129 14:05:28.581095       1 scheduler.go:71] Estado real no cluster: map[acceptablePreemptionOverhead:10 controller:test-controller2 qosMeasuring:average]
I0129 14:05:28.581107       1 scheduler.go:139] [WaitForPodsOnCache] Pod test-deployment2-7b58dbd49-24pwt encontrado no cache.
I0129 14:05:28.582352       1 scheduler.go:606] [GetControllerMetricInfo] Iniciando para o pod: default/test-deployment3-84f8ccf757-hkk2f
I0129 14:05:28.582444       1 scheduler.go:611] [GetControllerMetricInfo] Obtendo o nome do controlador para o pod: default/test-deployment3-84f8ccf757-hkk2f
I0129 14:05:28.582520       1 types.go:743] [ControllerName] Verificando as anotações do pod default/test-deployment3-84f8ccf757-hkk2f
I0129 14:05:28.583448       1 types.go:761] [ControllerName] Anotação 'controller' encontrada para o pod default/test-deployment3-84f8ccf757-hkk2f: test-controller3
I0129 14:05:28.583464       1 scheduler.go:614] [GetControllerMetricInfo] Métricas do controlador definidas para o pod: default/test-deployment3-84f8ccf757-hkk2f
I0129 14:05:28.583474       1 scheduler.go:606] [GetControllerMetricInfo] Iniciando para o pod: default/test-deployment2-7b58dbd49-24pwt
I0129 14:05:28.583480       1 scheduler.go:611] [GetControllerMetricInfo] Obtendo o nome do controlador para o pod: default/test-deployment2-7b58dbd49-24pwt
I0129 14:05:28.583485       1 types.go:743] [ControllerName] Verificando as anotações do pod default/test-deployment2-7b58dbd49-24pwt
I0129 14:05:28.583491       1 types.go:761] [ControllerName] Anotação 'controller' encontrada para o pod default/test-deployment2-7b58dbd49-24pwt: test-controller2
I0129 14:05:28.583496       1 scheduler.go:614] [GetControllerMetricInfo] Métricas do controlador definidas para o pod: default/test-deployment2-7b58dbd49-24pwt
I0129 14:05:28.583523       1 scheduler.go:98] [HigherPrecedence] Métricas para test-deployment3-84f8ccf757-hkk2f: QoS = -77.307632, Importância = 0.80
I0129 14:05:28.583533       1 scheduler.go:99] [HigherPrecedence] Métricas para test-deployment2-7b58dbd49-24pwt: QoS = -50.211347, Importância = 0.80
I0129 14:05:28.583541       1 scheduler.go:110] [HigherPrecedence] Decisão final: test-deployment3-84f8ccf757-hkk2f tem precedência sobre test-deployment2-7b58dbd49-24pwt? true
I0129 14:05:28.583548       1 types.go:743] [ControllerName] Verificando as anotações do pod default/test-deployment3-84f8ccf757-hkk2f
I0129 14:05:28.583553       1 types.go:761] [ControllerName] Anotação 'controller' encontrada para o pod default/test-deployment3-84f8ccf757-hkk2f: test-controller3
I0129 14:05:28.583558       1 types.go:743] [ControllerName] Verificando as anotações do pod default/test-deployment2-7b58dbd49-24pwt
I0129 14:05:28.583563       1 types.go:761] [ControllerName] Anotação 'controller' encontrada para o pod default/test-deployment2-7b58dbd49-24pwt: test-controller2
I0129 14:05:28.583568       1 scheduler.go:606] [GetControllerMetricInfo] Iniciando para o pod: default/test-deployment2-7b58dbd49-24pwt
I0129 14:05:28.583573       1 scheduler.go:611] [GetControllerMetricInfo] Obtendo o nome do controlador para o pod: default/test-deployment2-7b58dbd49-24pwt
I0129 14:05:28.583578       1 types.go:743] [ControllerName] Verificando as anotações do pod default/test-deployment2-7b58dbd49-24pwt
I0129 14:05:28.583582       1 types.go:761] [ControllerName] Anotação 'controller' encontrada para o pod default/test-deployment2-7b58dbd49-24pwt: test-controller2
I0129 14:05:28.583587       1 scheduler.go:614] [GetControllerMetricInfo] Métricas do controlador definidas para o pod: default/test-deployment2-7b58dbd49-24pwt
I0129 14:05:28.583592       1 scheduler.go:606] [GetControllerMetricInfo] Iniciando para o pod: default/test-deployment2-7b58dbd49-24pwt
I0129 14:05:28.583597       1 scheduler.go:611] [GetControllerMetricInfo] Obtendo o nome do controlador para o pod: default/test-deployment2-7b58dbd49-24pwt
I0129 14:05:28.583601       1 types.go:743] [ControllerName] Verificando as anotações do pod default/test-deployment2-7b58dbd49-24pwt
I0129 14:05:28.583605       1 types.go:761] [ControllerName] Anotação 'controller' encontrada para o pod default/test-deployment2-7b58dbd49-24pwt: test-controller2
I0129 14:05:28.583610       1 scheduler.go:614] [GetControllerMetricInfo] Métricas do controlador definidas para o pod: default/test-deployment2-7b58dbd49-24pwt
I0129 14:05:28.583615       1 types.go:743] [ControllerName] Verificando as anotações do pod default/test-deployment2-7b58dbd49-24pwt
I0129 14:05:28.583638       1 types.go:761] [ControllerName] Anotação 'controller' encontrada para o pod default/test-deployment2-7b58dbd49-24pwt: test-controller2
I0129 14:05:28.584032       1 postFilter.go:144] [PREEMPT CALL] No node was chosen to allocate pod test-deployment3-84f8ccf757-hkk2f
W0129 14:05:28.584815       1 postFilter.go:45] [PostFilter] Nenhum nó nominado após a preempção para o pod: default/test-deployment3-84f8ccf757-hkk2f
I0129 14:05:58.531895       1 postFilter.go:29] [PostFilter] PostFilter chamado para pod: default/test-deployment3-84f8ccf757-hkk2f
I0129 14:05:58.534108       1 postFilter.go:76] [Preempt] Comparando pod original com o atualizado...
I0129 14:05:58.558473       1 postFilter.go:83] [Preempt] Successfully retrieved updated pod default/test-deployment3-84f8ccf757-hkk2f from lister
I0129 14:05:58.574420       1 postFilter.go:233] [compareNodeResources] Recursos calculados no nó minikube: CPU = 1450 mCPU, Memória = 459276288 bytes
I0129 14:05:58.574454       1 postFilter.go:234] [compareNodeResources] Recursos do snapshot no nó minikube: CPU = 1450 mCPU, Memória = 459276288 bytes
I0129 14:05:58.574465       1 postFilter.go:240] [compareNodeResources] Recursos de CPU do nó minikube estão sincronizados: 1450 mCPU
I0129 14:05:58.574487       1 postFilter.go:246] [compareNodeResources] Recursos de memória do nó minikube estão sincronizados: 459276288 bytes
I0129 14:05:58.575216       1 scheduler.go:606] [GetControllerMetricInfo] Iniciando para o pod: default/test-deployment2-7b58dbd49-24pwt
I0129 14:05:58.575233       1 scheduler.go:611] [GetControllerMetricInfo] Obtendo o nome do controlador para o pod: default/test-deployment2-7b58dbd49-24pwt
I0129 14:05:58.575243       1 types.go:743] [ControllerName] Verificando as anotações do pod default/test-deployment2-7b58dbd49-24pwt
I0129 14:05:58.575253       1 types.go:761] [ControllerName] Anotação 'controller' encontrada para o pod default/test-deployment2-7b58dbd49-24pwt: test-controller2
I0129 14:05:58.575263       1 scheduler.go:614] [GetControllerMetricInfo] Métricas do controlador definidas para o pod: default/test-deployment2-7b58dbd49-24pwt
I0129 14:05:58.575274       1 scheduler.go:84] [HigherPrecedence] Calculando precedência entre test-deployment3-84f8ccf757-hkk2f e test-deployment2-7b58dbd49-24pwt
I0129 14:05:58.575282       1 scheduler.go:117] [WaitForPodsOnCache] Verificando se o pod test-deployment3-84f8ccf757-hkk2f está no cache...
I0129 14:05:58.575289       1 scheduler.go:606] [GetControllerMetricInfo] Iniciando para o pod: default/test-deployment3-84f8ccf757-hkk2f
I0129 14:05:58.575297       1 scheduler.go:611] [GetControllerMetricInfo] Obtendo o nome do controlador para o pod: default/test-deployment3-84f8ccf757-hkk2f
I0129 14:05:58.575303       1 types.go:743] [ControllerName] Verificando as anotações do pod default/test-deployment3-84f8ccf757-hkk2f
I0129 14:05:58.575312       1 types.go:761] [ControllerName] Anotação 'controller' encontrada para o pod default/test-deployment3-84f8ccf757-hkk2f: test-controller3
I0129 14:05:58.575320       1 scheduler.go:614] [GetControllerMetricInfo] Métricas do controlador definidas para o pod: default/test-deployment3-84f8ccf757-hkk2f
I0129 14:05:58.581915       1 scheduler.go:70] Estado no Informer: map[acceptablePreemptionOverhead:10 controller:test-controller3 qosMeasuring:average]
I0129 14:05:58.582098       1 scheduler.go:71] Estado real no cluster: map[acceptablePreemptionOverhead:10 controller:test-controller3 qosMeasuring:average]
I0129 14:05:58.582192       1 scheduler.go:139] [WaitForPodsOnCache] Pod test-deployment3-84f8ccf757-hkk2f encontrado no cache.
I0129 14:05:58.582200       1 scheduler.go:117] [WaitForPodsOnCache] Verificando se o pod test-deployment2-7b58dbd49-24pwt está no cache...
I0129 14:05:58.582209       1 scheduler.go:606] [GetControllerMetricInfo] Iniciando para o pod: default/test-deployment2-7b58dbd49-24pwt
I0129 14:05:58.582216       1 scheduler.go:611] [GetControllerMetricInfo] Obtendo o nome do controlador para o pod: default/test-deployment2-7b58dbd49-24pwt
I0129 14:05:58.582224       1 types.go:743] [ControllerName] Verificando as anotações do pod default/test-deployment2-7b58dbd49-24pwt
I0129 14:05:58.582233       1 types.go:761] [ControllerName] Anotação 'controller' encontrada para o pod default/test-deployment2-7b58dbd49-24pwt: test-controller2
I0129 14:05:58.582241       1 scheduler.go:614] [GetControllerMetricInfo] Métricas do controlador definidas para o pod: default/test-deployment2-7b58dbd49-24pwt
I0129 14:05:58.595230       1 scheduler.go:70] Estado no Informer: map[acceptablePreemptionOverhead:10 controller:test-controller2 qosMeasuring:average]
I0129 14:05:58.595261       1 scheduler.go:71] Estado real no cluster: map[acceptablePreemptionOverhead:10 controller:test-controller2 qosMeasuring:average]
I0129 14:05:58.595271       1 scheduler.go:139] [WaitForPodsOnCache] Pod test-deployment2-7b58dbd49-24pwt encontrado no cache.
I0129 14:05:58.595280       1 scheduler.go:606] [GetControllerMetricInfo] Iniciando para o pod: default/test-deployment3-84f8ccf757-hkk2f
I0129 14:05:58.595287       1 scheduler.go:611] [GetControllerMetricInfo] Obtendo o nome do controlador para o pod: default/test-deployment3-84f8ccf757-hkk2f
I0129 14:05:58.595295       1 types.go:743] [ControllerName] Verificando as anotações do pod default/test-deployment3-84f8ccf757-hkk2f
I0129 14:05:58.595303       1 types.go:761] [ControllerName] Anotação 'controller' encontrada para o pod default/test-deployment3-84f8ccf757-hkk2f: test-controller3
I0129 14:05:58.595312       1 scheduler.go:614] [GetControllerMetricInfo] Métricas do controlador definidas para o pod: default/test-deployment3-84f8ccf757-hkk2f
I0129 14:05:58.595323       1 scheduler.go:606] [GetControllerMetricInfo] Iniciando para o pod: default/test-deployment2-7b58dbd49-24pwt
I0129 14:05:58.595329       1 scheduler.go:611] [GetControllerMetricInfo] Obtendo o nome do controlador para o pod: default/test-deployment2-7b58dbd49-24pwt
I0129 14:05:58.595335       1 types.go:743] [ControllerName] Verificando as anotações do pod default/test-deployment2-7b58dbd49-24pwt
I0129 14:05:58.595341       1 types.go:761] [ControllerName] Anotação 'controller' encontrada para o pod default/test-deployment2-7b58dbd49-24pwt: test-controller2
I0129 14:05:58.595347       1 scheduler.go:614] [GetControllerMetricInfo] Métricas do controlador definidas para o pod: default/test-deployment2-7b58dbd49-24pwt
I0129 14:05:58.595364       1 scheduler.go:98] [HigherPrecedence] Métricas para test-deployment3-84f8ccf757-hkk2f: QoS = -107.318148, Importância = 0.80
I0129 14:05:58.595377       1 scheduler.go:99] [HigherPrecedence] Métricas para test-deployment2-7b58dbd49-24pwt: QoS = -42.708718, Importância = 0.80
I0129 14:05:58.595386       1 scheduler.go:110] [HigherPrecedence] Decisão final: test-deployment3-84f8ccf757-hkk2f tem precedência sobre test-deployment2-7b58dbd49-24pwt? true
I0129 14:05:58.595395       1 types.go:743] [ControllerName] Verificando as anotações do pod default/test-deployment3-84f8ccf757-hkk2f
I0129 14:05:58.595401       1 types.go:761] [ControllerName] Anotação 'controller' encontrada para o pod default/test-deployment3-84f8ccf757-hkk2f: test-controller3
I0129 14:05:58.595406       1 types.go:743] [ControllerName] Verificando as anotações do pod default/test-deployment2-7b58dbd49-24pwt
I0129 14:05:58.595411       1 types.go:761] [ControllerName] Anotação 'controller' encontrada para o pod default/test-deployment2-7b58dbd49-24pwt: test-controller2
I0129 14:05:58.595417       1 scheduler.go:606] [GetControllerMetricInfo] Iniciando para o pod: default/test-deployment2-7b58dbd49-24pwt
I0129 14:05:58.595422       1 scheduler.go:611] [GetControllerMetricInfo] Obtendo o nome do controlador para o pod: default/test-deployment2-7b58dbd49-24pwt
I0129 14:05:58.595427       1 types.go:743] [ControllerName] Verificando as anotações do pod default/test-deployment2-7b58dbd49-24pwt
I0129 14:05:58.595432       1 types.go:761] [ControllerName] Anotação 'controller' encontrada para o pod default/test-deployment2-7b58dbd49-24pwt: test-controller2
I0129 14:05:58.595440       1 scheduler.go:614] [GetControllerMetricInfo] Métricas do controlador definidas para o pod: default/test-deployment2-7b58dbd49-24pwt
I0129 14:05:58.595445       1 scheduler.go:606] [GetControllerMetricInfo] Iniciando para o pod: default/test-deployment2-7b58dbd49-24pwt
I0129 14:05:58.595451       1 scheduler.go:611] [GetControllerMetricInfo] Obtendo o nome do controlador para o pod: default/test-deployment2-7b58dbd49-24pwt
I0129 14:05:58.595459       1 types.go:743] [ControllerName] Verificando as anotações do pod default/test-deployment2-7b58dbd49-24pwt
I0129 14:05:58.595465       1 types.go:761] [ControllerName] Anotação 'controller' encontrada para o pod default/test-deployment2-7b58dbd49-24pwt: test-controller2
I0129 14:05:58.595471       1 scheduler.go:614] [GetControllerMetricInfo] Métricas do controlador definidas para o pod: default/test-deployment2-7b58dbd49-24pwt
I0129 14:05:58.595478       1 types.go:743] [ControllerName] Verificando as anotações do pod default/test-deployment2-7b58dbd49-24pwt
I0129 14:05:58.595483       1 types.go:761] [ControllerName] Anotação 'controller' encontrada para o pod default/test-deployment2-7b58dbd49-24pwt: test-controller2
I0129 14:05:58.595588       1 scheduler.go:606] [GetControllerMetricInfo] Iniciando para o pod: default/test-deployment2-7b58dbd49-24pwt
I0129 14:05:58.595595       1 scheduler.go:611] [GetControllerMetricInfo] Obtendo o nome do controlador para o pod: default/test-deployment2-7b58dbd49-24pwt
I0129 14:05:58.595600       1 types.go:743] [ControllerName] Verificando as anotações do pod default/test-deployment2-7b58dbd49-24pwt
I0129 14:05:58.595605       1 types.go:761] [ControllerName] Anotação 'controller' encontrada para o pod default/test-deployment2-7b58dbd49-24pwt: test-controller2
I0129 14:05:58.595611       1 scheduler.go:614] [GetControllerMetricInfo] Métricas do controlador definidas para o pod: default/test-deployment2-7b58dbd49-24pwt
I0129 14:05:58.595619       1 scheduler.go:606] [GetControllerMetricInfo] Iniciando para o pod: default/test-deployment2-7b58dbd49-24pwt
I0129 14:05:58.595625       1 scheduler.go:611] [GetControllerMetricInfo] Obtendo o nome do controlador para o pod: default/test-deployment2-7b58dbd49-24pwt
I0129 14:05:58.595630       1 types.go:743] [ControllerName] Verificando as anotações do pod default/test-deployment2-7b58dbd49-24pwt
I0129 14:05:58.595635       1 types.go:761] [ControllerName] Anotação 'controller' encontrada para o pod default/test-deployment2-7b58dbd49-24pwt: test-controller2
I0129 14:05:58.595640       1 scheduler.go:614] [GetControllerMetricInfo] Métricas do controlador definidas para o pod: default/test-deployment2-7b58dbd49-24pwt
I0129 14:05:58.595663       1 postFilter.go:147] [PREEMPT CALL] The node minikube  was chosen to allocate pod test-deployment3-84f8ccf757-hkk2f
I0129 14:05:58.595688       1 postFilter.go:151] [Preempt] Iniciando a remoção dos pods preemptados no nó minikube para alocar o pod default/test-deployment3-84f8ccf757-hkk2f. Total de vítimas: 1
I0129 14:05:58.595716       1 postFilter.go:155] [Preempt] Tentando remover o pod default/test-deployment2-7b58dbd49-24pwt no nó minikube
I0129 14:05:58.635634       1 scheduler.go:258] [OnUpdatePod] Iniciando processamento de atualização de pod
I0129 14:05:58.640663       1 scheduler.go:262] [OnUpdatePod] Pod atualizado detectado: default/test-deployment2-7b58dbd49-24pwt, Anotações: map[acceptablePreemptionOverhead:10 controller:test-controller2 qosMeasuring:average]
I0129 14:05:58.640825       1 scheduler.go:265] [OnUpdatePod] Comparando estado no Informer e estado real no cluster para o pod default/test-deployment2-7b58dbd49-24pwt
E0129 14:05:58.689794       1 scheduler.go:67] Erro ao buscar estado real do pod test-deployment2-7b58dbd49-24pwt: pods "test-deployment2-7b58dbd49-24pwt" not found
I0129 14:05:58.696079       1 scheduler.go:275] [OnUpdatePod] Atualizando informações de métricas para o pod default/test-deployment2-7b58dbd49-24pwt
I0129 14:05:58.695940       1 postFilter.go:168] [Preempt] Pod default/test-deployment2-7b58dbd49-24pwt removido com sucesso no nó minikube
I0129 14:05:58.698300       1 postFilter.go:174] test-deployment2-7b58dbd49-24pwt_default preempted by test-deployment3-84f8ccf757-hkk2f_default on node minikube
I0129 14:05:58.698460       1 postFilter.go:179] [Preempt] Total de pods preemptados no nó minikube: 1
I0129 14:05:58.698602       1 postFilter.go:186] [Preempt] Verificando pods de menor precedência no nó minikube que precisam ter o campo NominatedNodeName limpo
I0129 14:05:58.698753       1 postFilter.go:196] [Preempt] Finalizado para o nó minikube. Pod default/test-deployment3-84f8ccf757-hkk2f deve ser alocado agora.
I0129 14:05:58.700550       1 postFilter.go:49] [PostFilter] Nó nominado para o pod default/test-deployment3-84f8ccf757-hkk2f: minikube
I0129 14:05:58.713337       1 types.go:743] [ControllerName] Verificando as anotações do pod default/test-deployment2-7b58dbd49-24pwt
I0129 14:05:58.713470       1 types.go:761] [ControllerName] Anotação 'controller' encontrada para o pod default/test-deployment2-7b58dbd49-24pwt: test-controller2
I0129 14:05:58.713505       1 scheduler.go:277] [OnUpdatePod] Atualizando 'LastStatus' do pod default/test-deployment2-7b58dbd49-24pwt nas métricas
I0129 14:05:58.714239       1 scheduler.go:279] [OnUpdatePod] Métrica atualizada para o pod default/test-deployment2-7b58dbd49-24pwt
I0129 14:05:58.715025       1 scheduler.go:283] [OnUpdatePod] Finalizando processamento de atualização de pod para default/test-deployment2-7b58dbd49-24pwt
I0129 14:05:58.715093       1 scheduler.go:291] [OnDeletePod] Iniciando a execução do OnDeletePod
I0129 14:05:58.715187       1 scheduler.go:300] [OnDeletePod] DeepCopy realizado para o pod default/test-deployment2-7b58dbd49-24pwt
I0129 14:05:58.717254       1 scheduler.go:307] [OnDeletePod] Pod deletado detectado: default/test-deployment2-7b58dbd49-24pwt
I0129 14:05:58.717350       1 scheduler.go:309] [OnDeletePod] Atualizando métricas do pod default/test-deployment2-7b58dbd49-24pwt
I0129 14:05:58.718287       1 types.go:743] [ControllerName] Verificando as anotações do pod default/test-deployment2-7b58dbd49-24pwt
I0129 14:05:58.718368       1 types.go:761] [ControllerName] Anotação 'controller' encontrada para o pod default/test-deployment2-7b58dbd49-24pwt: test-controller2
I0129 14:05:58.718380       1 scheduler.go:311] [OnDeletePod] Verificando o estado do pod default/test-deployment2-7b58dbd49-24pwt nas métricas
I0129 14:05:58.718408       1 scheduler.go:321] [OnDeletePod] EndTime atualizado para o pod default/test-deployment2-7b58dbd49-24pwt: 2025-01-29 14:05:58.718403334 +0000 UTC m=+331.821958494
I0129 14:05:58.718451       1 scheduler.go:325] [OnDeletePod] Finalizando a execução do OnDeletePod para o pod default/test-deployment2-7b58dbd49-24pwt
I0129 14:05:58.718508       1 types.go:743] [ControllerName] Verificando as anotações do pod default/test-deployment2-7b58dbd49-24pwt
I0129 14:05:58.718536       1 types.go:761] [ControllerName] Anotação 'controller' encontrada para o pod default/test-deployment2-7b58dbd49-24pwt: test-controller2
I0129 14:05:59.141000       1 scheduler.go:258] [OnUpdatePod] Iniciando processamento de atualização de pod
I0129 14:05:59.162533       1 scheduler.go:262] [OnUpdatePod] Pod atualizado detectado: default/test-deployment3-84f8ccf757-hkk2f, Anotações: map[acceptablePreemptionOverhead:10 controller:test-controller3 qosMeasuring:average]
I0129 14:05:59.162591       1 scheduler.go:265] [OnUpdatePod] Comparando estado no Informer e estado real no cluster para o pod default/test-deployment3-84f8ccf757-hkk2f
I0129 14:05:59.194446       1 scheduler.go:70] Estado no Informer: map[acceptablePreemptionOverhead:10 controller:test-controller3 qosMeasuring:average]
I0129 14:05:59.194501       1 scheduler.go:71] Estado real no cluster: map[acceptablePreemptionOverhead:10 controller:test-controller3 qosMeasuring:average]
I0129 14:05:59.194512       1 scheduler.go:275] [OnUpdatePod] Atualizando informações de métricas para o pod default/test-deployment3-84f8ccf757-hkk2f
I0129 14:05:59.194519       1 types.go:743] [ControllerName] Verificando as anotações do pod default/test-deployment3-84f8ccf757-hkk2f
I0129 14:05:59.194525       1 types.go:761] [ControllerName] Anotação 'controller' encontrada para o pod default/test-deployment3-84f8ccf757-hkk2f: test-controller3
I0129 14:05:59.194533       1 scheduler.go:277] [OnUpdatePod] Atualizando 'LastStatus' do pod default/test-deployment3-84f8ccf757-hkk2f nas métricas
I0129 14:05:59.194537       1 scheduler.go:279] [OnUpdatePod] Métrica atualizada para o pod default/test-deployment3-84f8ccf757-hkk2f
I0129 14:05:59.194545       1 scheduler.go:283] [OnUpdatePod] Finalizando processamento de atualização de pod para default/test-deployment3-84f8ccf757-hkk2f
I0129 14:05:59.194565       1 scheduler.go:218] [OnAddPod] Pod adicionado: default/test-deployment2-7b58dbd49-ljztq, Anotações: map[acceptablePreemptionOverhead:10 controller:test-controller2 qosMeasuring:average]
I0129 14:05:59.203240       1 postFilter.go:29] [PostFilter] PostFilter chamado para pod: default/test-deployment2-7b58dbd49-ljztq
I0129 14:05:59.203280       1 postFilter.go:76] [Preempt] Comparando pod original com o atualizado...
I0129 14:05:59.203288       1 postFilter.go:83] [Preempt] Successfully retrieved updated pod default/test-deployment2-7b58dbd49-ljztq from lister
I0129 14:05:59.390393       1 scheduler.go:70] Estado no Informer: map[acceptablePreemptionOverhead:10 controller:test-controller2 qosMeasuring:average]
I0129 14:05:59.390478       1 scheduler.go:71] Estado real no cluster: map[acceptablePreemptionOverhead:10 controller:test-controller2 qosMeasuring:average]
I0129 14:05:59.392562       1 scheduler.go:229] [OnAddPod] Adicionando pod default/test-deployment2-7b58dbd49-ljztq com os seguintes detalhes:
I0129 14:05:59.392777       1 types.go:743] [ControllerName] Verificando as anotações do pod default/test-deployment2-7b58dbd49-ljztq
I0129 14:05:59.392791       1 types.go:761] [ControllerName] Anotação 'controller' encontrada para o pod default/test-deployment2-7b58dbd49-ljztq: test-controller2
I0129 14:05:59.392803       1 scheduler.go:238] [OnAddPod] Atualizando métricas para o pod default/test-deployment2-7b58dbd49-ljztq
I0129 14:05:59.392861       1 types.go:743] [ControllerName] Verificando as anotações do pod default/test-deployment2-7b58dbd49-ljztq
I0129 14:05:59.392870       1 types.go:761] [ControllerName] Anotação 'controller' encontrada para o pod default/test-deployment2-7b58dbd49-ljztq: test-controller2
I0129 14:05:59.392885       1 scheduler.go:251] [OnAddPod] Pod default/test-deployment2-7b58dbd49-ljztq adicionado com sucesso
I0129 14:05:59.395347       1 postFilter.go:233] [compareNodeResources] Recursos calculados no nó minikube: CPU = 750 mCPU, Memória = 178257920 bytes
I0129 14:05:59.395592       1 postFilter.go:234] [compareNodeResources] Recursos do snapshot no nó minikube: CPU = 750 mCPU, Memória = 178257920 bytes
I0129 14:05:59.395609       1 postFilter.go:240] [compareNodeResources] Recursos de CPU do nó minikube estão sincronizados: 750 mCPU
I0129 14:05:59.395618       1 postFilter.go:246] [compareNodeResources] Recursos de memória do nó minikube estão sincronizados: 178257920 bytes
I0129 14:05:59.396100       1 postFilter.go:147] [PREEMPT CALL] The node minikube  was chosen to allocate pod test-deployment2-7b58dbd49-ljztq
I0129 14:05:59.396201       1 postFilter.go:151] [Preempt] Iniciando a remoção dos pods preemptados no nó minikube para alocar o pod default/test-deployment2-7b58dbd49-ljztq. Total de vítimas: 0
I0129 14:05:59.396231       1 postFilter.go:179] [Preempt] Total de pods preemptados no nó minikube: 0
I0129 14:05:59.396305       1 scheduler.go:84] [HigherPrecedence] Calculando precedência entre test-deployment2-7b58dbd49-ljztq e test-deployment3-84f8ccf757-hkk2f
I0129 14:05:59.396319       1 scheduler.go:117] [WaitForPodsOnCache] Verificando se o pod test-deployment2-7b58dbd49-ljztq está no cache...
I0129 14:05:59.396330       1 scheduler.go:606] [GetControllerMetricInfo] Iniciando para o pod: default/test-deployment2-7b58dbd49-ljztq
I0129 14:05:59.396338       1 scheduler.go:611] [GetControllerMetricInfo] Obtendo o nome do controlador para o pod: default/test-deployment2-7b58dbd49-ljztq
I0129 14:05:59.396346       1 types.go:743] [ControllerName] Verificando as anotações do pod default/test-deployment2-7b58dbd49-ljztq
I0129 14:05:59.396354       1 types.go:761] [ControllerName] Anotação 'controller' encontrada para o pod default/test-deployment2-7b58dbd49-ljztq: test-controller2
I0129 14:05:59.396362       1 scheduler.go:614] [GetControllerMetricInfo] Métricas do controlador definidas para o pod: default/test-deployment2-7b58dbd49-ljztq
I0129 14:05:59.734997       1 scheduler.go:70] Estado no Informer: map[acceptablePreemptionOverhead:10 controller:test-controller2 qosMeasuring:average]
I0129 14:05:59.735036       1 scheduler.go:71] Estado real no cluster: map[acceptablePreemptionOverhead:10 controller:test-controller2 qosMeasuring:average]
I0129 14:05:59.735048       1 scheduler.go:139] [WaitForPodsOnCache] Pod test-deployment2-7b58dbd49-ljztq encontrado no cache.
I0129 14:05:59.735055       1 scheduler.go:117] [WaitForPodsOnCache] Verificando se o pod test-deployment3-84f8ccf757-hkk2f está no cache...
I0129 14:05:59.735064       1 scheduler.go:606] [GetControllerMetricInfo] Iniciando para o pod: default/test-deployment3-84f8ccf757-hkk2f
I0129 14:05:59.735071       1 scheduler.go:611] [GetControllerMetricInfo] Obtendo o nome do controlador para o pod: default/test-deployment3-84f8ccf757-hkk2f
I0129 14:05:59.735079       1 types.go:743] [ControllerName] Verificando as anotações do pod default/test-deployment3-84f8ccf757-hkk2f
I0129 14:05:59.735087       1 types.go:761] [ControllerName] Anotação 'controller' encontrada para o pod default/test-deployment3-84f8ccf757-hkk2f: test-controller3
I0129 14:05:59.735096       1 scheduler.go:614] [GetControllerMetricInfo] Métricas do controlador definidas para o pod: default/test-deployment3-84f8ccf757-hkk2f
I0129 14:05:59.769563       1 scheduler.go:70] Estado no Informer: map[acceptablePreemptionOverhead:10 controller:test-controller3 qosMeasuring:average]
I0129 14:05:59.769594       1 scheduler.go:71] Estado real no cluster: map[acceptablePreemptionOverhead:10 controller:test-controller3 qosMeasuring:average]
I0129 14:05:59.769603       1 scheduler.go:139] [WaitForPodsOnCache] Pod test-deployment3-84f8ccf757-hkk2f encontrado no cache.
I0129 14:05:59.769612       1 scheduler.go:606] [GetControllerMetricInfo] Iniciando para o pod: default/test-deployment2-7b58dbd49-ljztq
I0129 14:05:59.769619       1 scheduler.go:611] [GetControllerMetricInfo] Obtendo o nome do controlador para o pod: default/test-deployment2-7b58dbd49-ljztq
I0129 14:05:59.769626       1 types.go:743] [ControllerName] Verificando as anotações do pod default/test-deployment2-7b58dbd49-ljztq
I0129 14:05:59.769632       1 types.go:761] [ControllerName] Anotação 'controller' encontrada para o pod default/test-deployment2-7b58dbd49-ljztq: test-controller2
I0129 14:05:59.769647       1 scheduler.go:614] [GetControllerMetricInfo] Métricas do controlador definidas para o pod: default/test-deployment2-7b58dbd49-ljztq
I0129 14:05:59.769658       1 scheduler.go:606] [GetControllerMetricInfo] Iniciando para o pod: default/test-deployment3-84f8ccf757-hkk2f
I0129 14:05:59.769663       1 scheduler.go:611] [GetControllerMetricInfo] Obtendo o nome do controlador para o pod: default/test-deployment3-84f8ccf757-hkk2f
I0129 14:05:59.769668       1 types.go:743] [ControllerName] Verificando as anotações do pod default/test-deployment3-84f8ccf757-hkk2f
I0129 14:05:59.769674       1 types.go:761] [ControllerName] Anotação 'controller' encontrada para o pod default/test-deployment3-84f8ccf757-hkk2f: test-controller3
I0129 14:05:59.769679       1 scheduler.go:614] [GetControllerMetricInfo] Métricas do controlador definidas para o pod: default/test-deployment3-84f8ccf757-hkk2f
I0129 14:05:59.769694       1 scheduler.go:98] [HigherPrecedence] Métricas para test-deployment2-7b58dbd49-ljztq: QoS = -44.053241, Importância = 0.80
I0129 14:05:59.769704       1 scheduler.go:99] [HigherPrecedence] Métricas para test-deployment3-84f8ccf757-hkk2f: QoS = -108.139177, Importância = 0.80
I0129 14:05:59.769712       1 scheduler.go:110] [HigherPrecedence] Decisão final: test-deployment2-7b58dbd49-ljztq tem precedência sobre test-deployment3-84f8ccf757-hkk2f? false
I0129 14:05:59.769730       1 postFilter.go:186] [Preempt] Verificando pods de menor precedência no nó minikube que precisam ter o campo NominatedNodeName limpo
I0129 14:05:59.769746       1 postFilter.go:196] [Preempt] Finalizado para o nó minikube. Pod default/test-deployment2-7b58dbd49-ljztq deve ser alocado agora.
I0129 14:05:59.769754       1 postFilter.go:49] [PostFilter] Nó nominado para o pod default/test-deployment2-7b58dbd49-ljztq: minikube
I0129 14:06:00.393655       1 scheduler.go:258] [OnUpdatePod] Iniciando processamento de atualização de pod
I0129 14:06:00.395948       1 scheduler.go:262] [OnUpdatePod] Pod atualizado detectado: default/test-deployment2-7b58dbd49-ljztq, Anotações: map[acceptablePreemptionOverhead:10 controller:test-controller2 qosMeasuring:average]
I0129 14:06:00.396046       1 scheduler.go:265] [OnUpdatePod] Comparando estado no Informer e estado real no cluster para o pod default/test-deployment2-7b58dbd49-ljztq
I0129 14:06:00.414665       1 scheduler.go:70] Estado no Informer: map[acceptablePreemptionOverhead:10 controller:test-controller2 qosMeasuring:average]
I0129 14:06:00.414780       1 scheduler.go:71] Estado real no cluster: map[acceptablePreemptionOverhead:10 controller:test-controller2 qosMeasuring:average]
I0129 14:06:00.414800       1 scheduler.go:275] [OnUpdatePod] Atualizando informações de métricas para o pod default/test-deployment2-7b58dbd49-ljztq
I0129 14:06:00.414812       1 types.go:743] [ControllerName] Verificando as anotações do pod default/test-deployment2-7b58dbd49-ljztq
I0129 14:06:00.414821       1 types.go:761] [ControllerName] Anotação 'controller' encontrada para o pod default/test-deployment2-7b58dbd49-ljztq: test-controller2
I0129 14:06:00.417007       1 scheduler.go:277] [OnUpdatePod] Atualizando 'LastStatus' do pod default/test-deployment2-7b58dbd49-ljztq nas métricas
I0129 14:06:00.417212       1 scheduler.go:279] [OnUpdatePod] Métrica atualizada para o pod default/test-deployment2-7b58dbd49-ljztq
I0129 14:06:00.417233       1 scheduler.go:283] [OnUpdatePod] Finalizando processamento de atualização de pod para default/test-deployment2-7b58dbd49-ljztq
I0129 14:06:09.642517       1 postFilter.go:29] [PostFilter] PostFilter chamado para pod: default/test-deployment3-84f8ccf757-hkk2f
I0129 14:06:09.644799       1 postFilter.go:76] [Preempt] Comparando pod original com o atualizado...
I0129 14:06:09.645521       1 postFilter.go:83] [Preempt] Successfully retrieved updated pod default/test-deployment3-84f8ccf757-hkk2f from lister
I0129 14:06:09.669271       1 postFilter.go:233] [compareNodeResources] Recursos calculados no nó minikube: CPU = 750 mCPU, Memória = 178257920 bytes
I0129 14:06:09.675092       1 postFilter.go:234] [compareNodeResources] Recursos do snapshot no nó minikube: CPU = 750 mCPU, Memória = 178257920 bytes
I0129 14:06:09.675361       1 postFilter.go:240] [compareNodeResources] Recursos de CPU do nó minikube estão sincronizados: 750 mCPU
I0129 14:06:09.675550       1 postFilter.go:246] [compareNodeResources] Recursos de memória do nó minikube estão sincronizados: 178257920 bytes
I0129 14:06:09.675947       1 postFilter.go:147] [PREEMPT CALL] The node minikube  was chosen to allocate pod test-deployment3-84f8ccf757-hkk2f
I0129 14:06:09.676328       1 postFilter.go:151] [Preempt] Iniciando a remoção dos pods preemptados no nó minikube para alocar o pod default/test-deployment3-84f8ccf757-hkk2f. Total de vítimas: 0
I0129 14:06:09.676543       1 postFilter.go:179] [Preempt] Total de pods preemptados no nó minikube: 0
W0129 14:06:09.676851       1 scheduler.go:79] [HigherPrecedence] Tentativa de comparar o pod test-deployment3-84f8ccf757-hkk2f consigo mesmo. Retornando false.
I0129 14:06:09.677104       1 scheduler.go:84] [HigherPrecedence] Calculando precedência entre test-deployment3-84f8ccf757-hkk2f e test-deployment2-7b58dbd49-ljztq
I0129 14:06:09.677275       1 scheduler.go:117] [WaitForPodsOnCache] Verificando se o pod test-deployment3-84f8ccf757-hkk2f está no cache...
I0129 14:06:09.677363       1 scheduler.go:606] [GetControllerMetricInfo] Iniciando para o pod: default/test-deployment3-84f8ccf757-hkk2f
I0129 14:06:09.677429       1 scheduler.go:611] [GetControllerMetricInfo] Obtendo o nome do controlador para o pod: default/test-deployment3-84f8ccf757-hkk2f
I0129 14:06:09.677530       1 types.go:743] [ControllerName] Verificando as anotações do pod default/test-deployment3-84f8ccf757-hkk2f
I0129 14:06:09.677820       1 types.go:761] [ControllerName] Anotação 'controller' encontrada para o pod default/test-deployment3-84f8ccf757-hkk2f: test-controller3
I0129 14:06:09.677853       1 scheduler.go:614] [GetControllerMetricInfo] Métricas do controlador definidas para o pod: default/test-deployment3-84f8ccf757-hkk2f
I0129 14:06:09.700659       1 scheduler.go:70] Estado no Informer: map[acceptablePreemptionOverhead:10 controller:test-controller3 qosMeasuring:average]
I0129 14:06:09.700845       1 scheduler.go:71] Estado real no cluster: map[acceptablePreemptionOverhead:10 controller:test-controller3 qosMeasuring:average]
I0129 14:06:09.700884       1 scheduler.go:139] [WaitForPodsOnCache] Pod test-deployment3-84f8ccf757-hkk2f encontrado no cache.
I0129 14:06:09.700905       1 scheduler.go:117] [WaitForPodsOnCache] Verificando se o pod test-deployment2-7b58dbd49-ljztq está no cache...
I0129 14:06:09.700926       1 scheduler.go:606] [GetControllerMetricInfo] Iniciando para o pod: default/test-deployment2-7b58dbd49-ljztq
I0129 14:06:09.700946       1 scheduler.go:611] [GetControllerMetricInfo] Obtendo o nome do controlador para o pod: default/test-deployment2-7b58dbd49-ljztq
I0129 14:06:09.700966       1 types.go:743] [ControllerName] Verificando as anotações do pod default/test-deployment2-7b58dbd49-ljztq
I0129 14:06:09.700986       1 types.go:761] [ControllerName] Anotação 'controller' encontrada para o pod default/test-deployment2-7b58dbd49-ljztq: test-controller2
I0129 14:06:09.701007       1 scheduler.go:614] [GetControllerMetricInfo] Métricas do controlador definidas para o pod: default/test-deployment2-7b58dbd49-ljztq
I0129 14:06:09.715823       1 scheduler.go:70] Estado no Informer: map[acceptablePreemptionOverhead:10 controller:test-controller2 qosMeasuring:average]
I0129 14:06:09.715900       1 scheduler.go:71] Estado real no cluster: map[acceptablePreemptionOverhead:10 controller:test-controller2 qosMeasuring:average]
I0129 14:06:09.715914       1 scheduler.go:139] [WaitForPodsOnCache] Pod test-deployment2-7b58dbd49-ljztq encontrado no cache.
I0129 14:06:09.715923       1 scheduler.go:606] [GetControllerMetricInfo] Iniciando para o pod: default/test-deployment3-84f8ccf757-hkk2f
I0129 14:06:09.715946       1 scheduler.go:611] [GetControllerMetricInfo] Obtendo o nome do controlador para o pod: default/test-deployment3-84f8ccf757-hkk2f
I0129 14:06:09.715955       1 types.go:743] [ControllerName] Verificando as anotações do pod default/test-deployment3-84f8ccf757-hkk2f
I0129 14:06:09.715964       1 types.go:761] [ControllerName] Anotação 'controller' encontrada para o pod default/test-deployment3-84f8ccf757-hkk2f: test-controller3
I0129 14:06:09.715973       1 scheduler.go:614] [GetControllerMetricInfo] Métricas do controlador definidas para o pod: default/test-deployment3-84f8ccf757-hkk2f
I0129 14:06:09.715985       1 scheduler.go:606] [GetControllerMetricInfo] Iniciando para o pod: default/test-deployment2-7b58dbd49-ljztq
I0129 14:06:09.715991       1 scheduler.go:611] [GetControllerMetricInfo] Obtendo o nome do controlador para o pod: default/test-deployment2-7b58dbd49-ljztq
I0129 14:06:09.715997       1 types.go:743] [ControllerName] Verificando as anotações do pod default/test-deployment2-7b58dbd49-ljztq
I0129 14:06:09.716005       1 types.go:761] [ControllerName] Anotação 'controller' encontrada para o pod default/test-deployment2-7b58dbd49-ljztq: test-controller2
I0129 14:06:09.716012       1 scheduler.go:614] [GetControllerMetricInfo] Métricas do controlador definidas para o pod: default/test-deployment2-7b58dbd49-ljztq
I0129 14:06:09.716481       1 scheduler.go:98] [HigherPrecedence] Métricas para test-deployment3-84f8ccf757-hkk2f: QoS = -118.419975, Importância = 0.80
I0129 14:06:09.716550       1 scheduler.go:99] [HigherPrecedence] Métricas para test-deployment2-7b58dbd49-ljztq: QoS = -54.334039, Importância = 0.80
I0129 14:06:09.716564       1 scheduler.go:110] [HigherPrecedence] Decisão final: test-deployment3-84f8ccf757-hkk2f tem precedência sobre test-deployment2-7b58dbd49-ljztq? true
I0129 14:06:09.716586       1 postFilter.go:186] [Preempt] Verificando pods de menor precedência no nó minikube que precisam ter o campo NominatedNodeName limpo
I0129 14:06:09.716604       1 postFilter.go:188] [Preempt] Limpando o campo NominatedNodeName do pod default/test-deployment2-7b58dbd49-ljztq
I0129 14:06:09.741649       1 postFilter.go:196] [Preempt] Finalizado para o nó minikube. Pod default/test-deployment3-84f8ccf757-hkk2f deve ser alocado agora.
I0129 14:06:09.745371       1 postFilter.go:49] [PostFilter] Nó nominado para o pod default/test-deployment3-84f8ccf757-hkk2f: minikube
I0129 14:06:09.747793       1 scheduler.go:258] [OnUpdatePod] Iniciando processamento de atualização de pod
I0129 14:06:09.752372       1 scheduler.go:262] [OnUpdatePod] Pod atualizado detectado: default/test-deployment2-7b58dbd49-ljztq, Anotações: map[acceptablePreemptionOverhead:10 controller:test-controller2 qosMeasuring:average]
I0129 14:06:09.753768       1 scheduler.go:265] [OnUpdatePod] Comparando estado no Informer e estado real no cluster para o pod default/test-deployment2-7b58dbd49-ljztq
I0129 14:06:09.764333       1 scheduler.go:70] Estado no Informer: map[acceptablePreemptionOverhead:10 controller:test-controller2 qosMeasuring:average]
I0129 14:06:09.765640       1 scheduler.go:71] Estado real no cluster: map[acceptablePreemptionOverhead:10 controller:test-controller2 qosMeasuring:average]
I0129 14:06:09.765947       1 scheduler.go:275] [OnUpdatePod] Atualizando informações de métricas para o pod default/test-deployment2-7b58dbd49-ljztq
I0129 14:06:09.766096       1 types.go:743] [ControllerName] Verificando as anotações do pod default/test-deployment2-7b58dbd49-ljztq
I0129 14:06:09.766245       1 types.go:761] [ControllerName] Anotação 'controller' encontrada para o pod default/test-deployment2-7b58dbd49-ljztq: test-controller2
I0129 14:06:09.767100       1 scheduler.go:277] [OnUpdatePod] Atualizando 'LastStatus' do pod default/test-deployment2-7b58dbd49-ljztq nas métricas
I0129 14:06:09.767267       1 scheduler.go:279] [OnUpdatePod] Métrica atualizada para o pod default/test-deployment2-7b58dbd49-ljztq
I0129 14:06:09.767418       1 scheduler.go:283] [OnUpdatePod] Finalizando processamento de atualização de pod para default/test-deployment2-7b58dbd49-ljztq
I0129 14:06:28.532707       1 scheduler.go:54] [QueueSort] Comparando prioridade de test-deployment3-84f8ccf757-hkk2f com test-deployment2-7b58dbd49-ljztq
I0129 14:06:28.532851       1 scheduler.go:84] [HigherPrecedence] Calculando precedência entre test-deployment3-84f8ccf757-hkk2f e test-deployment2-7b58dbd49-ljztq
I0129 14:06:28.532884       1 scheduler.go:117] [WaitForPodsOnCache] Verificando se o pod test-deployment3-84f8ccf757-hkk2f está no cache...
I0129 14:06:28.532933       1 scheduler.go:606] [GetControllerMetricInfo] Iniciando para o pod: default/test-deployment3-84f8ccf757-hkk2f
I0129 14:06:28.532946       1 scheduler.go:611] [GetControllerMetricInfo] Obtendo o nome do controlador para o pod: default/test-deployment3-84f8ccf757-hkk2f
I0129 14:06:28.534530       1 types.go:743] [ControllerName] Verificando as anotações do pod default/test-deployment3-84f8ccf757-hkk2f
I0129 14:06:28.534991       1 types.go:761] [ControllerName] Anotação 'controller' encontrada para o pod default/test-deployment3-84f8ccf757-hkk2f: test-controller3
I0129 14:06:28.535377       1 scheduler.go:614] [GetControllerMetricInfo] Métricas do controlador definidas para o pod: default/test-deployment3-84f8ccf757-hkk2f
I0129 14:06:28.555232       1 scheduler.go:70] Estado no Informer: map[acceptablePreemptionOverhead:10 controller:test-controller3 qosMeasuring:average]
I0129 14:06:28.555648       1 scheduler.go:71] Estado real no cluster: map[acceptablePreemptionOverhead:10 controller:test-controller3 qosMeasuring:average]
I0129 14:06:28.555670       1 scheduler.go:139] [WaitForPodsOnCache] Pod test-deployment3-84f8ccf757-hkk2f encontrado no cache.
I0129 14:06:28.555702       1 scheduler.go:117] [WaitForPodsOnCache] Verificando se o pod test-deployment2-7b58dbd49-ljztq está no cache...
I0129 14:06:28.555713       1 scheduler.go:606] [GetControllerMetricInfo] Iniciando para o pod: default/test-deployment2-7b58dbd49-ljztq
I0129 14:06:28.555723       1 scheduler.go:611] [GetControllerMetricInfo] Obtendo o nome do controlador para o pod: default/test-deployment2-7b58dbd49-ljztq
I0129 14:06:28.555733       1 types.go:743] [ControllerName] Verificando as anotações do pod default/test-deployment2-7b58dbd49-ljztq
I0129 14:06:28.555754       1 types.go:761] [ControllerName] Anotação 'controller' encontrada para o pod default/test-deployment2-7b58dbd49-ljztq: test-controller2
I0129 14:06:28.555769       1 scheduler.go:614] [GetControllerMetricInfo] Métricas do controlador definidas para o pod: default/test-deployment2-7b58dbd49-ljztq
I0129 14:06:28.567711       1 scheduler.go:70] Estado no Informer: map[acceptablePreemptionOverhead:10 controller:test-controller2 qosMeasuring:average]
I0129 14:06:28.567758       1 scheduler.go:71] Estado real no cluster: map[acceptablePreemptionOverhead:10 controller:test-controller2 qosMeasuring:average]
I0129 14:06:28.567771       1 scheduler.go:139] [WaitForPodsOnCache] Pod test-deployment2-7b58dbd49-ljztq encontrado no cache.
I0129 14:06:28.567782       1 scheduler.go:606] [GetControllerMetricInfo] Iniciando para o pod: default/test-deployment3-84f8ccf757-hkk2f
I0129 14:06:28.567816       1 scheduler.go:611] [GetControllerMetricInfo] Obtendo o nome do controlador para o pod: default/test-deployment3-84f8ccf757-hkk2f
I0129 14:06:28.567827       1 types.go:743] [ControllerName] Verificando as anotações do pod default/test-deployment3-84f8ccf757-hkk2f
I0129 14:06:28.567837       1 types.go:761] [ControllerName] Anotação 'controller' encontrada para o pod default/test-deployment3-84f8ccf757-hkk2f: test-controller3
I0129 14:06:28.567848       1 scheduler.go:614] [GetControllerMetricInfo] Métricas do controlador definidas para o pod: default/test-deployment3-84f8ccf757-hkk2f
I0129 14:06:28.567874       1 scheduler.go:606] [GetControllerMetricInfo] Iniciando para o pod: default/test-deployment2-7b58dbd49-ljztq
I0129 14:06:28.567882       1 scheduler.go:611] [GetControllerMetricInfo] Obtendo o nome do controlador para o pod: default/test-deployment2-7b58dbd49-ljztq
I0129 14:06:28.567890       1 types.go:743] [ControllerName] Verificando as anotações do pod default/test-deployment2-7b58dbd49-ljztq
I0129 14:06:28.567898       1 types.go:761] [ControllerName] Anotação 'controller' encontrada para o pod default/test-deployment2-7b58dbd49-ljztq: test-controller2
I0129 14:06:28.567907       1 scheduler.go:614] [GetControllerMetricInfo] Métricas do controlador definidas para o pod: default/test-deployment2-7b58dbd49-ljztq
I0129 14:06:28.567926       1 scheduler.go:98] [HigherPrecedence] Métricas para test-deployment3-84f8ccf757-hkk2f: QoS = -137.275719, Importância = 0.80
I0129 14:06:28.567969       1 scheduler.go:99] [HigherPrecedence] Métricas para test-deployment2-7b58dbd49-ljztq: QoS = -73.189783, Importância = 0.80
I0129 14:06:28.567982       1 scheduler.go:110] [HigherPrecedence] Decisão final: test-deployment3-84f8ccf757-hkk2f tem precedência sobre test-deployment2-7b58dbd49-ljztq? true
I0129 14:06:28.567995       1 scheduler.go:60] [QueueSort] Precedência determinada: test-deployment3-84f8ccf757-hkk2f tem precedência sobre test-deployment2-7b58dbd49-ljztq? true
I0129 14:06:28.568762       1 scheduler.go:146] [Reserve] resources reserved at node minikube for pod test-deployment3-84f8ccf757-hkk2f_default at 2025-01-29 14:06:28.568751185 +0000 UTC m=+361.672306425
I0129 14:06:28.568869       1 types.go:743] [ControllerName] Verificando as anotações do pod default/test-deployment3-84f8ccf757-hkk2f
I0129 14:06:28.568886       1 types.go:761] [ControllerName] Anotação 'controller' encontrada para o pod default/test-deployment3-84f8ccf757-hkk2f: test-controller3
I0129 14:06:28.568903       1 scheduler.go:148] [Reserve] Status de alocação atual para o pod test-deployment3-84f8ccf757-hkk2f_default: 
I0129 14:06:28.568935       1 scheduler.go:150] [Reserve] Status de alocação atualizado para o pod test-deployment3-84f8ccf757-hkk2f_default: allocating
I0129 14:06:28.570052       1 postFilter.go:29] [PostFilter] PostFilter chamado para pod: default/test-deployment2-7b58dbd49-ljztq
I0129 14:06:28.570219       1 postFilter.go:76] [Preempt] Comparando pod original com o atualizado...
I0129 14:06:28.570280       1 postFilter.go:83] [Preempt] Successfully retrieved updated pod default/test-deployment2-7b58dbd49-ljztq from lister
I0129 14:06:28.570681       1 scheduler.go:174] [PreBind] Validando o pod test-deployment3-84f8ccf757-hkk2f antes de vincular ao node minikube
I0129 14:06:28.582746       1 postFilter.go:233] [compareNodeResources] Recursos calculados no nó minikube: CPU = 1450 mCPU, Memória = 459276288 bytes
I0129 14:06:28.582803       1 postFilter.go:234] [compareNodeResources] Recursos do snapshot no nó minikube: CPU = 1450 mCPU, Memória = 459276288 bytes
I0129 14:06:28.582815       1 postFilter.go:240] [compareNodeResources] Recursos de CPU do nó minikube estão sincronizados: 1450 mCPU
I0129 14:06:28.582824       1 postFilter.go:246] [compareNodeResources] Recursos de memória do nó minikube estão sincronizados: 459276288 bytes
I0129 14:06:28.583042       1 scheduler.go:606] [GetControllerMetricInfo] Iniciando para o pod: default/test-deployment3-84f8ccf757-hkk2f
I0129 14:06:28.583053       1 scheduler.go:611] [GetControllerMetricInfo] Obtendo o nome do controlador para o pod: default/test-deployment3-84f8ccf757-hkk2f
I0129 14:06:28.583061       1 types.go:743] [ControllerName] Verificando as anotações do pod default/test-deployment3-84f8ccf757-hkk2f
I0129 14:06:28.583068       1 types.go:761] [ControllerName] Anotação 'controller' encontrada para o pod default/test-deployment3-84f8ccf757-hkk2f: test-controller3
I0129 14:06:28.583077       1 scheduler.go:614] [GetControllerMetricInfo] Métricas do controlador definidas para o pod: default/test-deployment3-84f8ccf757-hkk2f
I0129 14:06:28.583085       1 scheduler.go:84] [HigherPrecedence] Calculando precedência entre test-deployment2-7b58dbd49-ljztq e test-deployment3-84f8ccf757-hkk2f
I0129 14:06:28.583093       1 scheduler.go:117] [WaitForPodsOnCache] Verificando se o pod test-deployment2-7b58dbd49-ljztq está no cache...
I0129 14:06:28.583205       1 scheduler.go:606] [GetControllerMetricInfo] Iniciando para o pod: default/test-deployment2-7b58dbd49-ljztq
I0129 14:06:28.583218       1 scheduler.go:611] [GetControllerMetricInfo] Obtendo o nome do controlador para o pod: default/test-deployment2-7b58dbd49-ljztq
I0129 14:06:28.583224       1 types.go:743] [ControllerName] Verificando as anotações do pod default/test-deployment2-7b58dbd49-ljztq
I0129 14:06:28.583231       1 types.go:761] [ControllerName] Anotação 'controller' encontrada para o pod default/test-deployment2-7b58dbd49-ljztq: test-controller2
I0129 14:06:28.583239       1 scheduler.go:614] [GetControllerMetricInfo] Métricas do controlador definidas para o pod: default/test-deployment2-7b58dbd49-ljztq
I0129 14:06:28.602883       1 scheduler.go:182] [PostBind] Chamado para pod test-deployment3-84f8ccf757-hkk2f
I0129 14:06:28.603006       1 scheduler.go:200] [PostBind] Pod test-deployment3-84f8ccf757-hkk2f - Início do binding: 2025-01-29 14:06:28.570742596 +0000 UTC m=+361.674297969, Fim do binding: 2025-01-29 14:06:28.603000764 +0000 UTC m=+361.706556051
I0129 14:06:28.605073       1 scheduler.go:70] Estado no Informer: map[acceptablePreemptionOverhead:10 controller:test-controller2 qosMeasuring:average]
I0129 14:06:28.605190       1 scheduler.go:71] Estado real no cluster: map[acceptablePreemptionOverhead:10 controller:test-controller2 qosMeasuring:average]
I0129 14:06:28.605203       1 scheduler.go:139] [WaitForPodsOnCache] Pod test-deployment2-7b58dbd49-ljztq encontrado no cache.
I0129 14:06:28.605209       1 scheduler.go:117] [WaitForPodsOnCache] Verificando se o pod test-deployment3-84f8ccf757-hkk2f está no cache...
I0129 14:06:28.605215       1 scheduler.go:606] [GetControllerMetricInfo] Iniciando para o pod: default/test-deployment3-84f8ccf757-hkk2f
I0129 14:06:28.605226       1 types.go:743] [ControllerName] Verificando as anotações do pod default/test-deployment3-84f8ccf757-hkk2f
I0129 14:06:28.605257       1 types.go:761] [ControllerName] Anotação 'controller' encontrada para o pod default/test-deployment3-84f8ccf757-hkk2f: test-controller3
I0129 14:06:28.605306       1 scheduler.go:207] [PostBind] Métricas atualizadas para o pod test-deployment3-84f8ccf757-hkk2f
I0129 14:06:28.605331       1 scheduler.go:611] [GetControllerMetricInfo] Obtendo o nome do controlador para o pod: default/test-deployment3-84f8ccf757-hkk2f
I0129 14:06:28.605336       1 types.go:743] [ControllerName] Verificando as anotações do pod default/test-deployment3-84f8ccf757-hkk2f
I0129 14:06:28.605341       1 types.go:761] [ControllerName] Anotação 'controller' encontrada para o pod default/test-deployment3-84f8ccf757-hkk2f: test-controller3
I0129 14:06:28.605347       1 scheduler.go:614] [GetControllerMetricInfo] Métricas do controlador definidas para o pod: default/test-deployment3-84f8ccf757-hkk2f
I0129 14:06:28.608942       1 scheduler.go:258] [OnUpdatePod] Iniciando processamento de atualização de pod
I0129 14:06:28.609231       1 scheduler.go:262] [OnUpdatePod] Pod atualizado detectado: default/test-deployment3-84f8ccf757-hkk2f, Anotações: map[acceptablePreemptionOverhead:10 controller:test-controller3 qosMeasuring:average]
I0129 14:06:28.609247       1 scheduler.go:265] [OnUpdatePod] Comparando estado no Informer e estado real no cluster para o pod default/test-deployment3-84f8ccf757-hkk2f
I0129 14:06:28.616315       1 scheduler.go:70] Estado no Informer: map[acceptablePreemptionOverhead:10 controller:test-controller3 qosMeasuring:average]
I0129 14:06:28.616366       1 scheduler.go:71] Estado real no cluster: map[acceptablePreemptionOverhead:10 controller:test-controller3 qosMeasuring:average]
I0129 14:06:28.616377       1 scheduler.go:139] [WaitForPodsOnCache] Pod test-deployment3-84f8ccf757-hkk2f encontrado no cache.
I0129 14:06:28.616383       1 scheduler.go:606] [GetControllerMetricInfo] Iniciando para o pod: default/test-deployment2-7b58dbd49-ljztq
I0129 14:06:28.616389       1 scheduler.go:611] [GetControllerMetricInfo] Obtendo o nome do controlador para o pod: default/test-deployment2-7b58dbd49-ljztq
I0129 14:06:28.616394       1 types.go:743] [ControllerName] Verificando as anotações do pod default/test-deployment2-7b58dbd49-ljztq
I0129 14:06:28.616400       1 types.go:761] [ControllerName] Anotação 'controller' encontrada para o pod default/test-deployment2-7b58dbd49-ljztq: test-controller2
I0129 14:06:28.616407       1 scheduler.go:614] [GetControllerMetricInfo] Métricas do controlador definidas para o pod: default/test-deployment2-7b58dbd49-ljztq
I0129 14:06:28.616415       1 scheduler.go:606] [GetControllerMetricInfo] Iniciando para o pod: default/test-deployment3-84f8ccf757-hkk2f
I0129 14:06:28.616420       1 scheduler.go:611] [GetControllerMetricInfo] Obtendo o nome do controlador para o pod: default/test-deployment3-84f8ccf757-hkk2f
I0129 14:06:28.616424       1 types.go:743] [ControllerName] Verificando as anotações do pod default/test-deployment3-84f8ccf757-hkk2f
I0129 14:06:28.616442       1 types.go:761] [ControllerName] Anotação 'controller' encontrada para o pod default/test-deployment3-84f8ccf757-hkk2f: test-controller3
I0129 14:06:28.616469       1 scheduler.go:614] [GetControllerMetricInfo] Métricas do controlador definidas para o pod: default/test-deployment3-84f8ccf757-hkk2f
I0129 14:06:28.616504       1 scheduler.go:98] [HigherPrecedence] Métricas para test-deployment2-7b58dbd49-ljztq: QoS = -73.240025, Importância = 0.80
I0129 14:06:28.616537       1 scheduler.go:99] [HigherPrecedence] Métricas para test-deployment3-84f8ccf757-hkk2f: QoS = -137.366990, Importância = 0.80
I0129 14:06:28.616545       1 scheduler.go:110] [HigherPrecedence] Decisão final: test-deployment2-7b58dbd49-ljztq tem precedência sobre test-deployment3-84f8ccf757-hkk2f? false
I0129 14:06:28.616907       1 postFilter.go:144] [PREEMPT CALL] No node was chosen to allocate pod test-deployment2-7b58dbd49-ljztq
W0129 14:06:28.616945       1 postFilter.go:45] [PostFilter] Nenhum nó nominado após a preempção para o pod: default/test-deployment2-7b58dbd49-ljztq
I0129 14:06:28.618453       1 scheduler.go:70] Estado no Informer: map[acceptablePreemptionOverhead:10 controller:test-controller3 qosMeasuring:average]
I0129 14:06:28.618491       1 scheduler.go:71] Estado real no cluster: map[acceptablePreemptionOverhead:10 controller:test-controller3 qosMeasuring:average]
I0129 14:06:28.618504       1 scheduler.go:275] [OnUpdatePod] Atualizando informações de métricas para o pod default/test-deployment3-84f8ccf757-hkk2f
I0129 14:06:28.618615       1 types.go:743] [ControllerName] Verificando as anotações do pod default/test-deployment3-84f8ccf757-hkk2f
I0129 14:06:28.618624       1 types.go:761] [ControllerName] Anotação 'controller' encontrada para o pod default/test-deployment3-84f8ccf757-hkk2f: test-controller3
I0129 14:06:28.618634       1 scheduler.go:277] [OnUpdatePod] Atualizando 'LastStatus' do pod default/test-deployment3-84f8ccf757-hkk2f nas métricas
I0129 14:06:28.618764       1 scheduler.go:279] [OnUpdatePod] Métrica atualizada para o pod default/test-deployment3-84f8ccf757-hkk2f
I0129 14:06:28.618774       1 scheduler.go:283] [OnUpdatePod] Finalizando processamento de atualização de pod para default/test-deployment3-84f8ccf757-hkk2f
I0129 14:06:28.772192       1 scheduler.go:258] [OnUpdatePod] Iniciando processamento de atualização de pod
I0129 14:06:28.772343       1 scheduler.go:262] [OnUpdatePod] Pod atualizado detectado: default/test-deployment3-84f8ccf757-hkk2f, Anotações: map[acceptablePreemptionOverhead:10 controller:test-controller3 qosMeasuring:average]
I0129 14:06:28.772378       1 scheduler.go:265] [OnUpdatePod] Comparando estado no Informer e estado real no cluster para o pod default/test-deployment3-84f8ccf757-hkk2f
I0129 14:06:28.796452       1 scheduler.go:70] Estado no Informer: map[acceptablePreemptionOverhead:10 controller:test-controller3 qosMeasuring:average]
I0129 14:06:28.799246       1 scheduler.go:71] Estado real no cluster: map[acceptablePreemptionOverhead:10 controller:test-controller3 qosMeasuring:average]
I0129 14:06:28.800425       1 scheduler.go:275] [OnUpdatePod] Atualizando informações de métricas para o pod default/test-deployment3-84f8ccf757-hkk2f
I0129 14:06:28.800782       1 types.go:743] [ControllerName] Verificando as anotações do pod default/test-deployment3-84f8ccf757-hkk2f
I0129 14:06:28.801394       1 types.go:761] [ControllerName] Anotação 'controller' encontrada para o pod default/test-deployment3-84f8ccf757-hkk2f: test-controller3
I0129 14:06:28.802925       1 scheduler.go:277] [OnUpdatePod] Atualizando 'LastStatus' do pod default/test-deployment3-84f8ccf757-hkk2f nas métricas
I0129 14:06:28.803077       1 scheduler.go:279] [OnUpdatePod] Métrica atualizada para o pod default/test-deployment3-84f8ccf757-hkk2f
I0129 14:06:28.803335       1 scheduler.go:283] [OnUpdatePod] Finalizando processamento de atualização de pod para default/test-deployment3-84f8ccf757-hkk2f
I0129 14:06:30.659463       1 postFilter.go:29] [PostFilter] PostFilter chamado para pod: default/test-deployment2-7b58dbd49-ljztq
I0129 14:06:30.666027       1 postFilter.go:76] [Preempt] Comparando pod original com o atualizado...
I0129 14:06:30.666219       1 postFilter.go:83] [Preempt] Successfully retrieved updated pod default/test-deployment2-7b58dbd49-ljztq from lister
I0129 14:06:30.775502       1 postFilter.go:233] [compareNodeResources] Recursos calculados no nó minikube: CPU = 1450 mCPU, Memória = 459276288 bytes
I0129 14:06:30.775668       1 postFilter.go:234] [compareNodeResources] Recursos do snapshot no nó minikube: CPU = 1450 mCPU, Memória = 459276288 bytes
I0129 14:06:30.776210       1 postFilter.go:240] [compareNodeResources] Recursos de CPU do nó minikube estão sincronizados: 1450 mCPU
I0129 14:06:30.776223       1 postFilter.go:246] [compareNodeResources] Recursos de memória do nó minikube estão sincronizados: 459276288 bytes
I0129 14:06:30.777021       1 scheduler.go:606] [GetControllerMetricInfo] Iniciando para o pod: default/test-deployment3-84f8ccf757-hkk2f
I0129 14:06:30.777959       1 scheduler.go:611] [GetControllerMetricInfo] Obtendo o nome do controlador para o pod: default/test-deployment3-84f8ccf757-hkk2f
I0129 14:06:30.778209       1 types.go:743] [ControllerName] Verificando as anotações do pod default/test-deployment3-84f8ccf757-hkk2f
I0129 14:06:30.778488       1 types.go:761] [ControllerName] Anotação 'controller' encontrada para o pod default/test-deployment3-84f8ccf757-hkk2f: test-controller3
I0129 14:06:30.778878       1 scheduler.go:614] [GetControllerMetricInfo] Métricas do controlador definidas para o pod: default/test-deployment3-84f8ccf757-hkk2f
I0129 14:06:30.779029       1 scheduler.go:84] [HigherPrecedence] Calculando precedência entre test-deployment2-7b58dbd49-ljztq e test-deployment3-84f8ccf757-hkk2f
I0129 14:06:30.779290       1 scheduler.go:117] [WaitForPodsOnCache] Verificando se o pod test-deployment2-7b58dbd49-ljztq está no cache...
I0129 14:06:30.779482       1 scheduler.go:606] [GetControllerMetricInfo] Iniciando para o pod: default/test-deployment2-7b58dbd49-ljztq
I0129 14:06:30.779660       1 scheduler.go:611] [GetControllerMetricInfo] Obtendo o nome do controlador para o pod: default/test-deployment2-7b58dbd49-ljztq
I0129 14:06:30.779835       1 types.go:743] [ControllerName] Verificando as anotações do pod default/test-deployment2-7b58dbd49-ljztq
I0129 14:06:30.780053       1 types.go:761] [ControllerName] Anotação 'controller' encontrada para o pod default/test-deployment2-7b58dbd49-ljztq: test-controller2
I0129 14:06:30.781809       1 scheduler.go:614] [GetControllerMetricInfo] Métricas do controlador definidas para o pod: default/test-deployment2-7b58dbd49-ljztq
I0129 14:06:30.811426       1 scheduler.go:70] Estado no Informer: map[acceptablePreemptionOverhead:10 controller:test-controller2 qosMeasuring:average]
I0129 14:06:30.818291       1 scheduler.go:71] Estado real no cluster: map[acceptablePreemptionOverhead:10 controller:test-controller2 qosMeasuring:average]
I0129 14:06:30.818403       1 scheduler.go:139] [WaitForPodsOnCache] Pod test-deployment2-7b58dbd49-ljztq encontrado no cache.
I0129 14:06:30.818429       1 scheduler.go:117] [WaitForPodsOnCache] Verificando se o pod test-deployment3-84f8ccf757-hkk2f está no cache...
I0129 14:06:30.818506       1 scheduler.go:606] [GetControllerMetricInfo] Iniciando para o pod: default/test-deployment3-84f8ccf757-hkk2f
I0129 14:06:30.818556       1 scheduler.go:611] [GetControllerMetricInfo] Obtendo o nome do controlador para o pod: default/test-deployment3-84f8ccf757-hkk2f
I0129 14:06:30.818670       1 types.go:743] [ControllerName] Verificando as anotações do pod default/test-deployment3-84f8ccf757-hkk2f
I0129 14:06:30.818721       1 types.go:761] [ControllerName] Anotação 'controller' encontrada para o pod default/test-deployment3-84f8ccf757-hkk2f: test-controller3
I0129 14:06:30.818746       1 scheduler.go:614] [GetControllerMetricInfo] Métricas do controlador definidas para o pod: default/test-deployment3-84f8ccf757-hkk2f
I0129 14:06:30.824634       1 scheduler.go:70] Estado no Informer: map[acceptablePreemptionOverhead:10 controller:test-controller3 qosMeasuring:average]
I0129 14:06:30.824691       1 scheduler.go:71] Estado real no cluster: map[acceptablePreemptionOverhead:10 controller:test-controller3 qosMeasuring:average]
I0129 14:06:30.824702       1 scheduler.go:139] [WaitForPodsOnCache] Pod test-deployment3-84f8ccf757-hkk2f encontrado no cache.
I0129 14:06:30.824709       1 scheduler.go:606] [GetControllerMetricInfo] Iniciando para o pod: default/test-deployment2-7b58dbd49-ljztq
I0129 14:06:30.824725       1 scheduler.go:611] [GetControllerMetricInfo] Obtendo o nome do controlador para o pod: default/test-deployment2-7b58dbd49-ljztq
I0129 14:06:30.824732       1 types.go:743] [ControllerName] Verificando as anotações do pod default/test-deployment2-7b58dbd49-ljztq
I0129 14:06:30.824739       1 types.go:761] [ControllerName] Anotação 'controller' encontrada para o pod default/test-deployment2-7b58dbd49-ljztq: test-controller2
I0129 14:06:30.824747       1 scheduler.go:614] [GetControllerMetricInfo] Métricas do controlador definidas para o pod: default/test-deployment2-7b58dbd49-ljztq
I0129 14:06:30.824757       1 scheduler.go:606] [GetControllerMetricInfo] Iniciando para o pod: default/test-deployment3-84f8ccf757-hkk2f
I0129 14:06:30.824788       1 scheduler.go:611] [GetControllerMetricInfo] Obtendo o nome do controlador para o pod: default/test-deployment3-84f8ccf757-hkk2f
I0129 14:06:30.824794       1 types.go:743] [ControllerName] Verificando as anotações do pod default/test-deployment3-84f8ccf757-hkk2f
I0129 14:06:30.824800       1 types.go:761] [ControllerName] Anotação 'controller' encontrada para o pod default/test-deployment3-84f8ccf757-hkk2f: test-controller3
I0129 14:06:30.824806       1 scheduler.go:614] [GetControllerMetricInfo] Métricas do controlador definidas para o pod: default/test-deployment3-84f8ccf757-hkk2f
I0129 14:06:30.824821       1 scheduler.go:98] [HigherPrecedence] Métricas para test-deployment2-7b58dbd49-ljztq: QoS = -75.435966, Importância = 0.80
I0129 14:06:30.824832       1 scheduler.go:99] [HigherPrecedence] Métricas para test-deployment3-84f8ccf757-hkk2f: QoS = -136.818005, Importância = 0.80
I0129 14:06:30.824839       1 scheduler.go:110] [HigherPrecedence] Decisão final: test-deployment2-7b58dbd49-ljztq tem precedência sobre test-deployment3-84f8ccf757-hkk2f? false
I0129 14:06:30.824876       1 postFilter.go:144] [PREEMPT CALL] No node was chosen to allocate pod test-deployment2-7b58dbd49-ljztq
W0129 14:06:30.824909       1 postFilter.go:45] [PostFilter] Nenhum nó nominado após a preempção para o pod: default/test-deployment2-7b58dbd49-ljztq
I0129 14:06:33.276562       1 scheduler.go:258] [OnUpdatePod] Iniciando processamento de atualização de pod
I0129 14:06:33.276699       1 scheduler.go:262] [OnUpdatePod] Pod atualizado detectado: default/test-deployment3-84f8ccf757-hkk2f, Anotações: map[acceptablePreemptionOverhead:10 controller:test-controller3 qosMeasuring:average]
I0129 14:06:33.276788       1 scheduler.go:265] [OnUpdatePod] Comparando estado no Informer e estado real no cluster para o pod default/test-deployment3-84f8ccf757-hkk2f
I0129 14:06:33.298490       1 scheduler.go:70] Estado no Informer: map[acceptablePreemptionOverhead:10 controller:test-controller3 qosMeasuring:average]
I0129 14:06:33.298653       1 scheduler.go:71] Estado real no cluster: map[acceptablePreemptionOverhead:10 controller:test-controller3 qosMeasuring:average]
I0129 14:06:33.298695       1 scheduler.go:275] [OnUpdatePod] Atualizando informações de métricas para o pod default/test-deployment3-84f8ccf757-hkk2f
I0129 14:06:33.298716       1 types.go:743] [ControllerName] Verificando as anotações do pod default/test-deployment3-84f8ccf757-hkk2f
I0129 14:06:33.304929       1 types.go:761] [ControllerName] Anotação 'controller' encontrada para o pod default/test-deployment3-84f8ccf757-hkk2f: test-controller3
I0129 14:06:33.305024       1 scheduler.go:277] [OnUpdatePod] Atualizando 'LastStatus' do pod default/test-deployment3-84f8ccf757-hkk2f nas métricas
I0129 14:06:33.305041       1 scheduler.go:279] [OnUpdatePod] Métrica atualizada para o pod default/test-deployment3-84f8ccf757-hkk2f
I0129 14:06:33.311095       1 scheduler.go:283] [OnUpdatePod] Finalizando processamento de atualização de pod para default/test-deployment3-84f8ccf757-hkk2f
I0129 14:06:58.570721       1 postFilter.go:29] [PostFilter] PostFilter chamado para pod: default/test-deployment2-7b58dbd49-ljztq
I0129 14:06:58.570826       1 postFilter.go:76] [Preempt] Comparando pod original com o atualizado...
I0129 14:06:58.570867       1 postFilter.go:83] [Preempt] Successfully retrieved updated pod default/test-deployment2-7b58dbd49-ljztq from lister
I0129 14:06:58.594899       1 postFilter.go:233] [compareNodeResources] Recursos calculados no nó minikube: CPU = 1450 mCPU, Memória = 459276288 bytes
I0129 14:06:58.595010       1 postFilter.go:234] [compareNodeResources] Recursos do snapshot no nó minikube: CPU = 1450 mCPU, Memória = 459276288 bytes
I0129 14:06:58.595043       1 postFilter.go:240] [compareNodeResources] Recursos de CPU do nó minikube estão sincronizados: 1450 mCPU
I0129 14:06:58.595059       1 postFilter.go:246] [compareNodeResources] Recursos de memória do nó minikube estão sincronizados: 459276288 bytes
I0129 14:06:58.597110       1 scheduler.go:606] [GetControllerMetricInfo] Iniciando para o pod: default/test-deployment3-84f8ccf757-hkk2f
I0129 14:06:58.597324       1 scheduler.go:611] [GetControllerMetricInfo] Obtendo o nome do controlador para o pod: default/test-deployment3-84f8ccf757-hkk2f
I0129 14:06:58.597363       1 types.go:743] [ControllerName] Verificando as anotações do pod default/test-deployment3-84f8ccf757-hkk2f
I0129 14:06:58.597460       1 types.go:761] [ControllerName] Anotação 'controller' encontrada para o pod default/test-deployment3-84f8ccf757-hkk2f: test-controller3
I0129 14:06:58.597755       1 scheduler.go:614] [GetControllerMetricInfo] Métricas do controlador definidas para o pod: default/test-deployment3-84f8ccf757-hkk2f
I0129 14:06:58.597794       1 scheduler.go:84] [HigherPrecedence] Calculando precedência entre test-deployment2-7b58dbd49-ljztq e test-deployment3-84f8ccf757-hkk2f
I0129 14:06:58.597808       1 scheduler.go:117] [WaitForPodsOnCache] Verificando se o pod test-deployment2-7b58dbd49-ljztq está no cache...
I0129 14:06:58.597819       1 scheduler.go:606] [GetControllerMetricInfo] Iniciando para o pod: default/test-deployment2-7b58dbd49-ljztq
I0129 14:06:58.598336       1 scheduler.go:611] [GetControllerMetricInfo] Obtendo o nome do controlador para o pod: default/test-deployment2-7b58dbd49-ljztq
I0129 14:06:58.598411       1 types.go:743] [ControllerName] Verificando as anotações do pod default/test-deployment2-7b58dbd49-ljztq
I0129 14:06:58.598428       1 types.go:761] [ControllerName] Anotação 'controller' encontrada para o pod default/test-deployment2-7b58dbd49-ljztq: test-controller2
I0129 14:06:58.598441       1 scheduler.go:614] [GetControllerMetricInfo] Métricas do controlador definidas para o pod: default/test-deployment2-7b58dbd49-ljztq
I0129 14:06:58.610443       1 scheduler.go:70] Estado no Informer: map[acceptablePreemptionOverhead:10 controller:test-controller2 qosMeasuring:average]
I0129 14:06:58.610617       1 scheduler.go:71] Estado real no cluster: map[acceptablePreemptionOverhead:10 controller:test-controller2 qosMeasuring:average]
I0129 14:06:58.610801       1 scheduler.go:139] [WaitForPodsOnCache] Pod test-deployment2-7b58dbd49-ljztq encontrado no cache.
I0129 14:06:58.610951       1 scheduler.go:117] [WaitForPodsOnCache] Verificando se o pod test-deployment3-84f8ccf757-hkk2f está no cache...
I0129 14:06:58.610985       1 scheduler.go:606] [GetControllerMetricInfo] Iniciando para o pod: default/test-deployment3-84f8ccf757-hkk2f
I0129 14:06:58.616212       1 scheduler.go:611] [GetControllerMetricInfo] Obtendo o nome do controlador para o pod: default/test-deployment3-84f8ccf757-hkk2f
I0129 14:06:58.616223       1 types.go:743] [ControllerName] Verificando as anotações do pod default/test-deployment3-84f8ccf757-hkk2f
I0129 14:06:58.616232       1 types.go:761] [ControllerName] Anotação 'controller' encontrada para o pod default/test-deployment3-84f8ccf757-hkk2f: test-controller3
I0129 14:06:58.616242       1 scheduler.go:614] [GetControllerMetricInfo] Métricas do controlador definidas para o pod: default/test-deployment3-84f8ccf757-hkk2f
I0129 14:06:58.625413       1 scheduler.go:70] Estado no Informer: map[acceptablePreemptionOverhead:10 controller:test-controller3 qosMeasuring:average]
I0129 14:06:58.631774       1 scheduler.go:71] Estado real no cluster: map[acceptablePreemptionOverhead:10 controller:test-controller3 qosMeasuring:average]
I0129 14:06:58.632078       1 scheduler.go:139] [WaitForPodsOnCache] Pod test-deployment3-84f8ccf757-hkk2f encontrado no cache.
I0129 14:06:58.633236       1 scheduler.go:606] [GetControllerMetricInfo] Iniciando para o pod: default/test-deployment2-7b58dbd49-ljztq
I0129 14:06:58.633493       1 scheduler.go:611] [GetControllerMetricInfo] Obtendo o nome do controlador para o pod: default/test-deployment2-7b58dbd49-ljztq
I0129 14:06:58.633655       1 types.go:743] [ControllerName] Verificando as anotações do pod default/test-deployment2-7b58dbd49-ljztq
I0129 14:06:58.633802       1 types.go:761] [ControllerName] Anotação 'controller' encontrada para o pod default/test-deployment2-7b58dbd49-ljztq: test-controller2
I0129 14:06:58.633937       1 scheduler.go:614] [GetControllerMetricInfo] Métricas do controlador definidas para o pod: default/test-deployment2-7b58dbd49-ljztq
I0129 14:06:58.634067       1 scheduler.go:606] [GetControllerMetricInfo] Iniciando para o pod: default/test-deployment3-84f8ccf757-hkk2f
I0129 14:06:58.634204       1 scheduler.go:611] [GetControllerMetricInfo] Obtendo o nome do controlador para o pod: default/test-deployment3-84f8ccf757-hkk2f
I0129 14:06:58.634363       1 types.go:743] [ControllerName] Verificando as anotações do pod default/test-deployment3-84f8ccf757-hkk2f
I0129 14:06:58.634496       1 types.go:761] [ControllerName] Anotação 'controller' encontrada para o pod default/test-deployment3-84f8ccf757-hkk2f: test-controller3
I0129 14:06:58.634751       1 scheduler.go:614] [GetControllerMetricInfo] Métricas do controlador definidas para o pod: default/test-deployment3-84f8ccf757-hkk2f
I0129 14:06:58.636162       1 scheduler.go:98] [HigherPrecedence] Métricas para test-deployment2-7b58dbd49-ljztq: QoS = -103.254711, Importância = 0.80
I0129 14:06:58.636347       1 scheduler.go:99] [HigherPrecedence] Métricas para test-deployment3-84f8ccf757-hkk2f: QoS = -129.863318, Importância = 0.80
I0129 14:06:58.636522       1 scheduler.go:110] [HigherPrecedence] Decisão final: test-deployment2-7b58dbd49-ljztq tem precedência sobre test-deployment3-84f8ccf757-hkk2f? false
I0129 14:06:58.636770       1 postFilter.go:144] [PREEMPT CALL] No node was chosen to allocate pod test-deployment2-7b58dbd49-ljztq
W0129 14:06:58.637796       1 postFilter.go:45] [PostFilter] Nenhum nó nominado após a preempção para o pod: default/test-deployment2-7b58dbd49-ljztq
I0129 14:07:28.571483       1 postFilter.go:29] [PostFilter] PostFilter chamado para pod: default/test-deployment2-7b58dbd49-ljztq
I0129 14:07:28.575514       1 postFilter.go:76] [Preempt] Comparando pod original com o atualizado...
I0129 14:07:28.575653       1 postFilter.go:83] [Preempt] Successfully retrieved updated pod default/test-deployment2-7b58dbd49-ljztq from lister
I0129 14:07:28.594669       1 postFilter.go:233] [compareNodeResources] Recursos calculados no nó minikube: CPU = 1450 mCPU, Memória = 459276288 bytes
I0129 14:07:28.600505       1 postFilter.go:234] [compareNodeResources] Recursos do snapshot no nó minikube: CPU = 1450 mCPU, Memória = 459276288 bytes
I0129 14:07:28.600616       1 postFilter.go:240] [compareNodeResources] Recursos de CPU do nó minikube estão sincronizados: 1450 mCPU
I0129 14:07:28.600637       1 postFilter.go:246] [compareNodeResources] Recursos de memória do nó minikube estão sincronizados: 459276288 bytes
I0129 14:07:28.606942       1 scheduler.go:606] [GetControllerMetricInfo] Iniciando para o pod: default/test-deployment3-84f8ccf757-hkk2f
I0129 14:07:28.607333       1 scheduler.go:611] [GetControllerMetricInfo] Obtendo o nome do controlador para o pod: default/test-deployment3-84f8ccf757-hkk2f
I0129 14:07:28.607523       1 types.go:743] [ControllerName] Verificando as anotações do pod default/test-deployment3-84f8ccf757-hkk2f
I0129 14:07:28.607730       1 types.go:761] [ControllerName] Anotação 'controller' encontrada para o pod default/test-deployment3-84f8ccf757-hkk2f: test-controller3
I0129 14:07:28.607956       1 scheduler.go:614] [GetControllerMetricInfo] Métricas do controlador definidas para o pod: default/test-deployment3-84f8ccf757-hkk2f
I0129 14:07:28.608081       1 scheduler.go:84] [HigherPrecedence] Calculando precedência entre test-deployment2-7b58dbd49-ljztq e test-deployment3-84f8ccf757-hkk2f
I0129 14:07:28.608468       1 scheduler.go:117] [WaitForPodsOnCache] Verificando se o pod test-deployment2-7b58dbd49-ljztq está no cache...
I0129 14:07:28.608682       1 scheduler.go:606] [GetControllerMetricInfo] Iniciando para o pod: default/test-deployment2-7b58dbd49-ljztq
I0129 14:07:28.608893       1 scheduler.go:611] [GetControllerMetricInfo] Obtendo o nome do controlador para o pod: default/test-deployment2-7b58dbd49-ljztq
I0129 14:07:28.609087       1 types.go:743] [ControllerName] Verificando as anotações do pod default/test-deployment2-7b58dbd49-ljztq
I0129 14:07:28.609354       1 types.go:761] [ControllerName] Anotação 'controller' encontrada para o pod default/test-deployment2-7b58dbd49-ljztq: test-controller2
I0129 14:07:28.609762       1 scheduler.go:614] [GetControllerMetricInfo] Métricas do controlador definidas para o pod: default/test-deployment2-7b58dbd49-ljztq
I0129 14:07:28.626092       1 scheduler.go:70] Estado no Informer: map[acceptablePreemptionOverhead:10 controller:test-controller2 qosMeasuring:average]
I0129 14:07:28.626268       1 scheduler.go:71] Estado real no cluster: map[acceptablePreemptionOverhead:10 controller:test-controller2 qosMeasuring:average]
I0129 14:07:28.626279       1 scheduler.go:139] [WaitForPodsOnCache] Pod test-deployment2-7b58dbd49-ljztq encontrado no cache.
I0129 14:07:28.626286       1 scheduler.go:117] [WaitForPodsOnCache] Verificando se o pod test-deployment3-84f8ccf757-hkk2f está no cache...
I0129 14:07:28.626296       1 scheduler.go:606] [GetControllerMetricInfo] Iniciando para o pod: default/test-deployment3-84f8ccf757-hkk2f
I0129 14:07:28.626302       1 scheduler.go:611] [GetControllerMetricInfo] Obtendo o nome do controlador para o pod: default/test-deployment3-84f8ccf757-hkk2f
I0129 14:07:28.626311       1 types.go:743] [ControllerName] Verificando as anotações do pod default/test-deployment3-84f8ccf757-hkk2f
I0129 14:07:28.626319       1 types.go:761] [ControllerName] Anotação 'controller' encontrada para o pod default/test-deployment3-84f8ccf757-hkk2f: test-controller3
I0129 14:07:28.626346       1 scheduler.go:614] [GetControllerMetricInfo] Métricas do controlador definidas para o pod: default/test-deployment3-84f8ccf757-hkk2f
I0129 14:07:28.645305       1 scheduler.go:70] Estado no Informer: map[acceptablePreemptionOverhead:10 controller:test-controller3 qosMeasuring:average]
I0129 14:07:28.650787       1 scheduler.go:71] Estado real no cluster: map[acceptablePreemptionOverhead:10 controller:test-controller3 qosMeasuring:average]
I0129 14:07:28.650822       1 scheduler.go:139] [WaitForPodsOnCache] Pod test-deployment3-84f8ccf757-hkk2f encontrado no cache.
I0129 14:07:28.650833       1 scheduler.go:606] [GetControllerMetricInfo] Iniciando para o pod: default/test-deployment2-7b58dbd49-ljztq
I0129 14:07:28.650840       1 scheduler.go:611] [GetControllerMetricInfo] Obtendo o nome do controlador para o pod: default/test-deployment2-7b58dbd49-ljztq
I0129 14:07:28.650849       1 types.go:743] [ControllerName] Verificando as anotações do pod default/test-deployment2-7b58dbd49-ljztq
I0129 14:07:28.650857       1 types.go:761] [ControllerName] Anotação 'controller' encontrada para o pod default/test-deployment2-7b58dbd49-ljztq: test-controller2
I0129 14:07:28.650866       1 scheduler.go:614] [GetControllerMetricInfo] Métricas do controlador definidas para o pod: default/test-deployment2-7b58dbd49-ljztq
I0129 14:07:28.650882       1 scheduler.go:606] [GetControllerMetricInfo] Iniciando para o pod: default/test-deployment3-84f8ccf757-hkk2f
I0129 14:07:28.650888       1 scheduler.go:611] [GetControllerMetricInfo] Obtendo o nome do controlador para o pod: default/test-deployment3-84f8ccf757-hkk2f
I0129 14:07:28.650893       1 types.go:743] [ControllerName] Verificando as anotações do pod default/test-deployment3-84f8ccf757-hkk2f
I0129 14:07:28.650898       1 types.go:761] [ControllerName] Anotação 'controller' encontrada para o pod default/test-deployment3-84f8ccf757-hkk2f: test-controller3
I0129 14:07:28.650905       1 scheduler.go:614] [GetControllerMetricInfo] Métricas do controlador definidas para o pod: default/test-deployment3-84f8ccf757-hkk2f
I0129 14:07:28.650944       1 scheduler.go:98] [HigherPrecedence] Métricas para test-deployment2-7b58dbd49-ljztq: QoS = -133.265015, Importância = 0.80
I0129 14:07:28.650957       1 scheduler.go:99] [HigherPrecedence] Métricas para test-deployment3-84f8ccf757-hkk2f: QoS = -122.360742, Importância = 0.80
I0129 14:07:28.650989       1 scheduler.go:110] [HigherPrecedence] Decisão final: test-deployment2-7b58dbd49-ljztq tem precedência sobre test-deployment3-84f8ccf757-hkk2f? true
I0129 14:07:28.650999       1 types.go:743] [ControllerName] Verificando as anotações do pod default/test-deployment2-7b58dbd49-ljztq
I0129 14:07:28.651005       1 types.go:761] [ControllerName] Anotação 'controller' encontrada para o pod default/test-deployment2-7b58dbd49-ljztq: test-controller2
I0129 14:07:28.651010       1 types.go:743] [ControllerName] Verificando as anotações do pod default/test-deployment3-84f8ccf757-hkk2f
I0129 14:07:28.651016       1 types.go:761] [ControllerName] Anotação 'controller' encontrada para o pod default/test-deployment3-84f8ccf757-hkk2f: test-controller3
I0129 14:07:28.651022       1 scheduler.go:606] [GetControllerMetricInfo] Iniciando para o pod: default/test-deployment3-84f8ccf757-hkk2f
I0129 14:07:28.651028       1 scheduler.go:611] [GetControllerMetricInfo] Obtendo o nome do controlador para o pod: default/test-deployment3-84f8ccf757-hkk2f
I0129 14:07:28.651032       1 types.go:743] [ControllerName] Verificando as anotações do pod default/test-deployment3-84f8ccf757-hkk2f
I0129 14:07:28.651037       1 types.go:761] [ControllerName] Anotação 'controller' encontrada para o pod default/test-deployment3-84f8ccf757-hkk2f: test-controller3
I0129 14:07:28.651044       1 scheduler.go:614] [GetControllerMetricInfo] Métricas do controlador definidas para o pod: default/test-deployment3-84f8ccf757-hkk2f
I0129 14:07:28.651049       1 scheduler.go:606] [GetControllerMetricInfo] Iniciando para o pod: default/test-deployment3-84f8ccf757-hkk2f
I0129 14:07:28.651054       1 scheduler.go:611] [GetControllerMetricInfo] Obtendo o nome do controlador para o pod: default/test-deployment3-84f8ccf757-hkk2f
I0129 14:07:28.651059       1 types.go:743] [ControllerName] Verificando as anotações do pod default/test-deployment3-84f8ccf757-hkk2f
I0129 14:07:28.651064       1 types.go:761] [ControllerName] Anotação 'controller' encontrada para o pod default/test-deployment3-84f8ccf757-hkk2f: test-controller3
I0129 14:07:28.651075       1 scheduler.go:614] [GetControllerMetricInfo] Métricas do controlador definidas para o pod: default/test-deployment3-84f8ccf757-hkk2f
I0129 14:07:28.651081       1 types.go:743] [ControllerName] Verificando as anotações do pod default/test-deployment3-84f8ccf757-hkk2f
I0129 14:07:28.651086       1 types.go:761] [ControllerName] Anotação 'controller' encontrada para o pod default/test-deployment3-84f8ccf757-hkk2f: test-controller3
I0129 14:07:28.651349       1 scheduler.go:606] [GetControllerMetricInfo] Iniciando para o pod: default/test-deployment3-84f8ccf757-hkk2f
I0129 14:07:28.651359       1 scheduler.go:611] [GetControllerMetricInfo] Obtendo o nome do controlador para o pod: default/test-deployment3-84f8ccf757-hkk2f
I0129 14:07:28.651364       1 types.go:743] [ControllerName] Verificando as anotações do pod default/test-deployment3-84f8ccf757-hkk2f
I0129 14:07:28.651370       1 types.go:761] [ControllerName] Anotação 'controller' encontrada para o pod default/test-deployment3-84f8ccf757-hkk2f: test-controller3
I0129 14:07:28.651376       1 scheduler.go:614] [GetControllerMetricInfo] Métricas do controlador definidas para o pod: default/test-deployment3-84f8ccf757-hkk2f
I0129 14:07:28.651385       1 scheduler.go:606] [GetControllerMetricInfo] Iniciando para o pod: default/test-deployment3-84f8ccf757-hkk2f
I0129 14:07:28.651390       1 scheduler.go:611] [GetControllerMetricInfo] Obtendo o nome do controlador para o pod: default/test-deployment3-84f8ccf757-hkk2f
I0129 14:07:28.651395       1 types.go:743] [ControllerName] Verificando as anotações do pod default/test-deployment3-84f8ccf757-hkk2f
I0129 14:07:28.651401       1 types.go:761] [ControllerName] Anotação 'controller' encontrada para o pod default/test-deployment3-84f8ccf757-hkk2f: test-controller3
I0129 14:07:28.651407       1 scheduler.go:614] [GetControllerMetricInfo] Métricas do controlador definidas para o pod: default/test-deployment3-84f8ccf757-hkk2f
I0129 14:07:28.651430       1 postFilter.go:147] [PREEMPT CALL] The node minikube  was chosen to allocate pod test-deployment2-7b58dbd49-ljztq
I0129 14:07:28.651455       1 postFilter.go:151] [Preempt] Iniciando a remoção dos pods preemptados no nó minikube para alocar o pod default/test-deployment2-7b58dbd49-ljztq. Total de vítimas: 1
I0129 14:07:28.651483       1 postFilter.go:155] [Preempt] Tentando remover o pod default/test-deployment3-84f8ccf757-hkk2f no nó minikube
I0129 14:07:28.842042       1 scheduler.go:258] [OnUpdatePod] Iniciando processamento de atualização de pod
I0129 14:07:28.842279       1 scheduler.go:262] [OnUpdatePod] Pod atualizado detectado: default/test-deployment3-84f8ccf757-hkk2f, Anotações: map[acceptablePreemptionOverhead:10 controller:test-controller3 qosMeasuring:average]
I0129 14:07:28.842348       1 scheduler.go:265] [OnUpdatePod] Comparando estado no Informer e estado real no cluster para o pod default/test-deployment3-84f8ccf757-hkk2f
I0129 14:07:29.131030       1 postFilter.go:168] [Preempt] Pod default/test-deployment3-84f8ccf757-hkk2f removido com sucesso no nó minikube
I0129 14:07:29.136628       1 postFilter.go:174] test-deployment3-84f8ccf757-hkk2f_default preempted by test-deployment2-7b58dbd49-ljztq_default on node minikube
I0129 14:07:29.138078       1 postFilter.go:179] [Preempt] Total de pods preemptados no nó minikube: 1
I0129 14:07:29.138664       1 postFilter.go:186] [Preempt] Verificando pods de menor precedência no nó minikube que precisam ter o campo NominatedNodeName limpo
I0129 14:07:29.138990       1 postFilter.go:196] [Preempt] Finalizado para o nó minikube. Pod default/test-deployment2-7b58dbd49-ljztq deve ser alocado agora.
I0129 14:07:29.139242       1 postFilter.go:49] [PostFilter] Nó nominado para o pod default/test-deployment2-7b58dbd49-ljztq: minikube
I0129 14:07:29.143229       1 scheduler.go:70] Estado no Informer: map[acceptablePreemptionOverhead:10 controller:test-controller3 qosMeasuring:average]
I0129 14:07:29.143533       1 scheduler.go:71] Estado real no cluster: map[acceptablePreemptionOverhead:10 controller:test-controller3 qosMeasuring:average]
I0129 14:07:29.143815       1 scheduler.go:275] [OnUpdatePod] Atualizando informações de métricas para o pod default/test-deployment3-84f8ccf757-hkk2f
I0129 14:07:29.144052       1 types.go:743] [ControllerName] Verificando as anotações do pod default/test-deployment3-84f8ccf757-hkk2f
I0129 14:07:29.144230       1 types.go:761] [ControllerName] Anotação 'controller' encontrada para o pod default/test-deployment3-84f8ccf757-hkk2f: test-controller3
I0129 14:07:29.144428       1 scheduler.go:277] [OnUpdatePod] Atualizando 'LastStatus' do pod default/test-deployment3-84f8ccf757-hkk2f nas métricas
I0129 14:07:29.144700       1 scheduler.go:279] [OnUpdatePod] Métrica atualizada para o pod default/test-deployment3-84f8ccf757-hkk2f
I0129 14:07:29.144964       1 scheduler.go:283] [OnUpdatePod] Finalizando processamento de atualização de pod para default/test-deployment3-84f8ccf757-hkk2f
I0129 14:07:29.145361       1 types.go:743] [ControllerName] Verificando as anotações do pod default/test-deployment3-84f8ccf757-hkk2f
I0129 14:07:29.145533       1 types.go:761] [ControllerName] Anotação 'controller' encontrada para o pod default/test-deployment3-84f8ccf757-hkk2f: test-controller3
I0129 14:07:29.146596       1 scheduler.go:291] [OnDeletePod] Iniciando a execução do OnDeletePod
I0129 14:07:29.146914       1 scheduler.go:300] [OnDeletePod] DeepCopy realizado para o pod default/test-deployment3-84f8ccf757-hkk2f
I0129 14:07:29.147791       1 scheduler.go:307] [OnDeletePod] Pod deletado detectado: default/test-deployment3-84f8ccf757-hkk2f
I0129 14:07:29.148196       1 scheduler.go:309] [OnDeletePod] Atualizando métricas do pod default/test-deployment3-84f8ccf757-hkk2f
I0129 14:07:29.148301       1 types.go:743] [ControllerName] Verificando as anotações do pod default/test-deployment3-84f8ccf757-hkk2f
I0129 14:07:29.148451       1 types.go:761] [ControllerName] Anotação 'controller' encontrada para o pod default/test-deployment3-84f8ccf757-hkk2f: test-controller3
I0129 14:07:29.148570       1 scheduler.go:311] [OnDeletePod] Verificando o estado do pod default/test-deployment3-84f8ccf757-hkk2f nas métricas
I0129 14:07:29.148657       1 scheduler.go:321] [OnDeletePod] EndTime atualizado para o pod default/test-deployment3-84f8ccf757-hkk2f: 2025-01-29 14:07:29.148649946 +0000 UTC m=+422.252205086
I0129 14:07:29.148825       1 scheduler.go:325] [OnDeletePod] Finalizando a execução do OnDeletePod para o pod default/test-deployment3-84f8ccf757-hkk2f
I0129 14:07:29.349247       1 scheduler.go:218] [OnAddPod] Pod adicionado: default/test-deployment3-84f8ccf757-zb4jq, Anotações: map[acceptablePreemptionOverhead:10 controller:test-controller3 qosMeasuring:average]
I0129 14:07:29.363875       1 postFilter.go:29] [PostFilter] PostFilter chamado para pod: default/test-deployment3-84f8ccf757-zb4jq
I0129 14:07:29.369222       1 postFilter.go:76] [Preempt] Comparando pod original com o atualizado...
I0129 14:07:29.369248       1 postFilter.go:83] [Preempt] Successfully retrieved updated pod default/test-deployment3-84f8ccf757-zb4jq from lister
I0129 14:07:29.675735       1 scheduler.go:70] Estado no Informer: map[acceptablePreemptionOverhead:10 controller:test-controller3 qosMeasuring:average]
I0129 14:07:29.677439       1 scheduler.go:71] Estado real no cluster: map[acceptablePreemptionOverhead:10 controller:test-controller3 qosMeasuring:average]
I0129 14:07:29.679704       1 scheduler.go:229] [OnAddPod] Adicionando pod default/test-deployment3-84f8ccf757-zb4jq com os seguintes detalhes:
I0129 14:07:29.683829       1 types.go:743] [ControllerName] Verificando as anotações do pod default/test-deployment3-84f8ccf757-zb4jq
I0129 14:07:29.683861       1 types.go:761] [ControllerName] Anotação 'controller' encontrada para o pod default/test-deployment3-84f8ccf757-zb4jq: test-controller3
I0129 14:07:29.683910       1 scheduler.go:238] [OnAddPod] Atualizando métricas para o pod default/test-deployment3-84f8ccf757-zb4jq
I0129 14:07:29.683919       1 types.go:743] [ControllerName] Verificando as anotações do pod default/test-deployment3-84f8ccf757-zb4jq
I0129 14:07:29.683927       1 types.go:761] [ControllerName] Anotação 'controller' encontrada para o pod default/test-deployment3-84f8ccf757-zb4jq: test-controller3
I0129 14:07:29.683949       1 scheduler.go:251] [OnAddPod] Pod default/test-deployment3-84f8ccf757-zb4jq adicionado com sucesso
I0129 14:07:29.683980       1 scheduler.go:258] [OnUpdatePod] Iniciando processamento de atualização de pod
I0129 14:07:29.684020       1 scheduler.go:262] [OnUpdatePod] Pod atualizado detectado: default/test-deployment2-7b58dbd49-ljztq, Anotações: map[acceptablePreemptionOverhead:10 controller:test-controller2 qosMeasuring:average]
I0129 14:07:29.684039       1 scheduler.go:265] [OnUpdatePod] Comparando estado no Informer e estado real no cluster para o pod default/test-deployment2-7b58dbd49-ljztq
I0129 14:07:29.717687       1 postFilter.go:233] [compareNodeResources] Recursos calculados no nó minikube: CPU = 750 mCPU, Memória = 178257920 bytes
I0129 14:07:29.717750       1 postFilter.go:234] [compareNodeResources] Recursos do snapshot no nó minikube: CPU = 750 mCPU, Memória = 178257920 bytes
I0129 14:07:29.717761       1 postFilter.go:240] [compareNodeResources] Recursos de CPU do nó minikube estão sincronizados: 750 mCPU
I0129 14:07:29.717780       1 postFilter.go:246] [compareNodeResources] Recursos de memória do nó minikube estão sincronizados: 178257920 bytes
I0129 14:07:29.717972       1 postFilter.go:147] [PREEMPT CALL] The node minikube  was chosen to allocate pod test-deployment3-84f8ccf757-zb4jq
I0129 14:07:29.717986       1 postFilter.go:151] [Preempt] Iniciando a remoção dos pods preemptados no nó minikube para alocar o pod default/test-deployment3-84f8ccf757-zb4jq. Total de vítimas: 0
I0129 14:07:29.718006       1 postFilter.go:179] [Preempt] Total de pods preemptados no nó minikube: 0
I0129 14:07:29.718082       1 scheduler.go:84] [HigherPrecedence] Calculando precedência entre test-deployment3-84f8ccf757-zb4jq e test-deployment2-7b58dbd49-ljztq
I0129 14:07:29.718091       1 scheduler.go:117] [WaitForPodsOnCache] Verificando se o pod test-deployment3-84f8ccf757-zb4jq está no cache...
I0129 14:07:29.718099       1 scheduler.go:606] [GetControllerMetricInfo] Iniciando para o pod: default/test-deployment3-84f8ccf757-zb4jq
I0129 14:07:29.731102       1 scheduler.go:70] Estado no Informer: map[acceptablePreemptionOverhead:10 controller:test-controller2 qosMeasuring:average]
I0129 14:07:29.731206       1 scheduler.go:71] Estado real no cluster: map[acceptablePreemptionOverhead:10 controller:test-controller2 qosMeasuring:average]
I0129 14:07:29.731223       1 scheduler.go:275] [OnUpdatePod] Atualizando informações de métricas para o pod default/test-deployment2-7b58dbd49-ljztq
I0129 14:07:29.718107       1 scheduler.go:611] [GetControllerMetricInfo] Obtendo o nome do controlador para o pod: default/test-deployment3-84f8ccf757-zb4jq
I0129 14:07:29.731286       1 types.go:743] [ControllerName] Verificando as anotações do pod default/test-deployment3-84f8ccf757-zb4jq
I0129 14:07:29.731294       1 types.go:761] [ControllerName] Anotação 'controller' encontrada para o pod default/test-deployment3-84f8ccf757-zb4jq: test-controller3
I0129 14:07:29.731303       1 scheduler.go:614] [GetControllerMetricInfo] Métricas do controlador definidas para o pod: default/test-deployment3-84f8ccf757-zb4jq
I0129 14:07:29.731384       1 types.go:743] [ControllerName] Verificando as anotações do pod default/test-deployment2-7b58dbd49-ljztq
I0129 14:07:29.731399       1 types.go:761] [ControllerName] Anotação 'controller' encontrada para o pod default/test-deployment2-7b58dbd49-ljztq: test-controller2
I0129 14:07:29.731410       1 scheduler.go:277] [OnUpdatePod] Atualizando 'LastStatus' do pod default/test-deployment2-7b58dbd49-ljztq nas métricas
I0129 14:07:29.731415       1 scheduler.go:279] [OnUpdatePod] Métrica atualizada para o pod default/test-deployment2-7b58dbd49-ljztq
I0129 14:07:29.731444       1 scheduler.go:283] [OnUpdatePod] Finalizando processamento de atualização de pod para default/test-deployment2-7b58dbd49-ljztq
I0129 14:07:29.801478       1 scheduler.go:70] Estado no Informer: map[acceptablePreemptionOverhead:10 controller:test-controller3 qosMeasuring:average]
I0129 14:07:29.801532       1 scheduler.go:71] Estado real no cluster: map[acceptablePreemptionOverhead:10 controller:test-controller3 qosMeasuring:average]
I0129 14:07:29.801544       1 scheduler.go:139] [WaitForPodsOnCache] Pod test-deployment3-84f8ccf757-zb4jq encontrado no cache.
I0129 14:07:29.801549       1 scheduler.go:117] [WaitForPodsOnCache] Verificando se o pod test-deployment2-7b58dbd49-ljztq está no cache...
I0129 14:07:29.801556       1 scheduler.go:606] [GetControllerMetricInfo] Iniciando para o pod: default/test-deployment2-7b58dbd49-ljztq
I0129 14:07:29.801562       1 scheduler.go:611] [GetControllerMetricInfo] Obtendo o nome do controlador para o pod: default/test-deployment2-7b58dbd49-ljztq
I0129 14:07:29.801575       1 types.go:743] [ControllerName] Verificando as anotações do pod default/test-deployment2-7b58dbd49-ljztq
I0129 14:07:29.801582       1 types.go:761] [ControllerName] Anotação 'controller' encontrada para o pod default/test-deployment2-7b58dbd49-ljztq: test-controller2
I0129 14:07:29.801590       1 scheduler.go:614] [GetControllerMetricInfo] Métricas do controlador definidas para o pod: default/test-deployment2-7b58dbd49-ljztq
I0129 14:07:29.815224       1 scheduler.go:70] Estado no Informer: map[acceptablePreemptionOverhead:10 controller:test-controller2 qosMeasuring:average]
I0129 14:07:29.815366       1 scheduler.go:71] Estado real no cluster: map[acceptablePreemptionOverhead:10 controller:test-controller2 qosMeasuring:average]
I0129 14:07:29.815379       1 scheduler.go:139] [WaitForPodsOnCache] Pod test-deployment2-7b58dbd49-ljztq encontrado no cache.
I0129 14:07:29.815386       1 scheduler.go:606] [GetControllerMetricInfo] Iniciando para o pod: default/test-deployment3-84f8ccf757-zb4jq
I0129 14:07:29.815391       1 scheduler.go:611] [GetControllerMetricInfo] Obtendo o nome do controlador para o pod: default/test-deployment3-84f8ccf757-zb4jq
I0129 14:07:29.815397       1 types.go:743] [ControllerName] Verificando as anotações do pod default/test-deployment3-84f8ccf757-zb4jq
I0129 14:07:29.815403       1 types.go:761] [ControllerName] Anotação 'controller' encontrada para o pod default/test-deployment3-84f8ccf757-zb4jq: test-controller3
I0129 14:07:29.815487       1 scheduler.go:614] [GetControllerMetricInfo] Métricas do controlador definidas para o pod: default/test-deployment3-84f8ccf757-zb4jq
I0129 14:07:29.815501       1 scheduler.go:606] [GetControllerMetricInfo] Iniciando para o pod: default/test-deployment2-7b58dbd49-ljztq
I0129 14:07:29.815505       1 scheduler.go:611] [GetControllerMetricInfo] Obtendo o nome do controlador para o pod: default/test-deployment2-7b58dbd49-ljztq
I0129 14:07:29.815509       1 types.go:743] [ControllerName] Verificando as anotações do pod default/test-deployment2-7b58dbd49-ljztq
I0129 14:07:29.815513       1 types.go:761] [ControllerName] Anotação 'controller' encontrada para o pod default/test-deployment2-7b58dbd49-ljztq: test-controller2
I0129 14:07:29.815517       1 scheduler.go:614] [GetControllerMetricInfo] Métricas do controlador definidas para o pod: default/test-deployment2-7b58dbd49-ljztq
I0129 14:07:29.815530       1 scheduler.go:98] [HigherPrecedence] Métricas para test-deployment3-84f8ccf757-zb4jq: QoS = -122.932093, Importância = 0.80
I0129 14:07:29.819317       1 scheduler.go:99] [HigherPrecedence] Métricas para test-deployment2-7b58dbd49-ljztq: QoS = -134.375020, Importância = 0.80
I0129 14:07:29.819330       1 scheduler.go:110] [HigherPrecedence] Decisão final: test-deployment3-84f8ccf757-zb4jq tem precedência sobre test-deployment2-7b58dbd49-ljztq? false
I0129 14:07:29.819345       1 postFilter.go:186] [Preempt] Verificando pods de menor precedência no nó minikube que precisam ter o campo NominatedNodeName limpo
I0129 14:07:29.819408       1 postFilter.go:196] [Preempt] Finalizado para o nó minikube. Pod default/test-deployment3-84f8ccf757-zb4jq deve ser alocado agora.
I0129 14:07:29.819418       1 postFilter.go:49] [PostFilter] Nó nominado para o pod default/test-deployment3-84f8ccf757-zb4jq: minikube
I0129 14:07:30.102040       1 scheduler.go:258] [OnUpdatePod] Iniciando processamento de atualização de pod
I0129 14:07:30.102254       1 scheduler.go:262] [OnUpdatePod] Pod atualizado detectado: default/test-deployment3-84f8ccf757-zb4jq, Anotações: map[acceptablePreemptionOverhead:10 controller:test-controller3 qosMeasuring:average]
I0129 14:07:30.102290       1 scheduler.go:265] [OnUpdatePod] Comparando estado no Informer e estado real no cluster para o pod default/test-deployment3-84f8ccf757-zb4jq
I0129 14:07:30.120706       1 scheduler.go:70] Estado no Informer: map[acceptablePreemptionOverhead:10 controller:test-controller3 qosMeasuring:average]
I0129 14:07:30.120811       1 scheduler.go:71] Estado real no cluster: map[acceptablePreemptionOverhead:10 controller:test-controller3 qosMeasuring:average]
I0129 14:07:30.120838       1 scheduler.go:275] [OnUpdatePod] Atualizando informações de métricas para o pod default/test-deployment3-84f8ccf757-zb4jq
I0129 14:07:30.120853       1 types.go:743] [ControllerName] Verificando as anotações do pod default/test-deployment3-84f8ccf757-zb4jq
I0129 14:07:30.120865       1 types.go:761] [ControllerName] Anotação 'controller' encontrada para o pod default/test-deployment3-84f8ccf757-zb4jq: test-controller3
I0129 14:07:30.120883       1 scheduler.go:277] [OnUpdatePod] Atualizando 'LastStatus' do pod default/test-deployment3-84f8ccf757-zb4jq nas métricas
I0129 14:07:30.120892       1 scheduler.go:279] [OnUpdatePod] Métrica atualizada para o pod default/test-deployment3-84f8ccf757-zb4jq
I0129 14:07:30.122809       1 scheduler.go:283] [OnUpdatePod] Finalizando processamento de atualização de pod para default/test-deployment3-84f8ccf757-zb4jq
I0129 14:07:39.739921       1 postFilter.go:29] [PostFilter] PostFilter chamado para pod: default/test-deployment2-7b58dbd49-ljztq
I0129 14:07:39.739971       1 postFilter.go:76] [Preempt] Comparando pod original com o atualizado...
I0129 14:07:39.739990       1 postFilter.go:83] [Preempt] Successfully retrieved updated pod default/test-deployment2-7b58dbd49-ljztq from lister
I0129 14:07:39.759993       1 postFilter.go:233] [compareNodeResources] Recursos calculados no nó minikube: CPU = 750 mCPU, Memória = 178257920 bytes
I0129 14:07:39.760094       1 postFilter.go:234] [compareNodeResources] Recursos do snapshot no nó minikube: CPU = 750 mCPU, Memória = 178257920 bytes
I0129 14:07:39.760114       1 postFilter.go:240] [compareNodeResources] Recursos de CPU do nó minikube estão sincronizados: 750 mCPU
I0129 14:07:39.760700       1 postFilter.go:246] [compareNodeResources] Recursos de memória do nó minikube estão sincronizados: 178257920 bytes
I0129 14:07:39.764508       1 postFilter.go:147] [PREEMPT CALL] The node minikube  was chosen to allocate pod test-deployment2-7b58dbd49-ljztq
I0129 14:07:39.766210       1 postFilter.go:151] [Preempt] Iniciando a remoção dos pods preemptados no nó minikube para alocar o pod default/test-deployment2-7b58dbd49-ljztq. Total de vítimas: 0
I0129 14:07:39.766336       1 postFilter.go:179] [Preempt] Total de pods preemptados no nó minikube: 0
W0129 14:07:39.766426       1 scheduler.go:79] [HigherPrecedence] Tentativa de comparar o pod test-deployment2-7b58dbd49-ljztq consigo mesmo. Retornando false.
I0129 14:07:39.766440       1 scheduler.go:84] [HigherPrecedence] Calculando precedência entre test-deployment2-7b58dbd49-ljztq e test-deployment3-84f8ccf757-zb4jq
I0129 14:07:39.766452       1 scheduler.go:117] [WaitForPodsOnCache] Verificando se o pod test-deployment2-7b58dbd49-ljztq está no cache...
I0129 14:07:39.766465       1 scheduler.go:606] [GetControllerMetricInfo] Iniciando para o pod: default/test-deployment2-7b58dbd49-ljztq
I0129 14:07:39.766477       1 scheduler.go:611] [GetControllerMetricInfo] Obtendo o nome do controlador para o pod: default/test-deployment2-7b58dbd49-ljztq
I0129 14:07:39.766490       1 types.go:743] [ControllerName] Verificando as anotações do pod default/test-deployment2-7b58dbd49-ljztq
I0129 14:07:39.766502       1 types.go:761] [ControllerName] Anotação 'controller' encontrada para o pod default/test-deployment2-7b58dbd49-ljztq: test-controller2
I0129 14:07:39.766516       1 scheduler.go:614] [GetControllerMetricInfo] Métricas do controlador definidas para o pod: default/test-deployment2-7b58dbd49-ljztq
I0129 14:07:39.785746       1 scheduler.go:70] Estado no Informer: map[acceptablePreemptionOverhead:10 controller:test-controller2 qosMeasuring:average]
I0129 14:07:39.785793       1 scheduler.go:71] Estado real no cluster: map[acceptablePreemptionOverhead:10 controller:test-controller2 qosMeasuring:average]
I0129 14:07:39.785806       1 scheduler.go:139] [WaitForPodsOnCache] Pod test-deployment2-7b58dbd49-ljztq encontrado no cache.
I0129 14:07:39.785814       1 scheduler.go:117] [WaitForPodsOnCache] Verificando se o pod test-deployment3-84f8ccf757-zb4jq está no cache...
I0129 14:07:39.785823       1 scheduler.go:606] [GetControllerMetricInfo] Iniciando para o pod: default/test-deployment3-84f8ccf757-zb4jq
I0129 14:07:39.785832       1 scheduler.go:611] [GetControllerMetricInfo] Obtendo o nome do controlador para o pod: default/test-deployment3-84f8ccf757-zb4jq
I0129 14:07:39.785842       1 types.go:743] [ControllerName] Verificando as anotações do pod default/test-deployment3-84f8ccf757-zb4jq
I0129 14:07:39.785851       1 types.go:761] [ControllerName] Anotação 'controller' encontrada para o pod default/test-deployment3-84f8ccf757-zb4jq: test-controller3
I0129 14:07:39.785862       1 scheduler.go:614] [GetControllerMetricInfo] Métricas do controlador definidas para o pod: default/test-deployment3-84f8ccf757-zb4jq
I0129 14:07:39.794845       1 scheduler.go:70] Estado no Informer: map[acceptablePreemptionOverhead:10 controller:test-controller3 qosMeasuring:average]
I0129 14:07:39.794886       1 scheduler.go:71] Estado real no cluster: map[acceptablePreemptionOverhead:10 controller:test-controller3 qosMeasuring:average]
I0129 14:07:39.794898       1 scheduler.go:139] [WaitForPodsOnCache] Pod test-deployment3-84f8ccf757-zb4jq encontrado no cache.
I0129 14:07:39.794909       1 scheduler.go:606] [GetControllerMetricInfo] Iniciando para o pod: default/test-deployment2-7b58dbd49-ljztq
I0129 14:07:39.794918       1 scheduler.go:611] [GetControllerMetricInfo] Obtendo o nome do controlador para o pod: default/test-deployment2-7b58dbd49-ljztq
I0129 14:07:39.794927       1 types.go:743] [ControllerName] Verificando as anotações do pod default/test-deployment2-7b58dbd49-ljztq
I0129 14:07:39.794937       1 types.go:761] [ControllerName] Anotação 'controller' encontrada para o pod default/test-deployment2-7b58dbd49-ljztq: test-controller2
I0129 14:07:39.794947       1 scheduler.go:614] [GetControllerMetricInfo] Métricas do controlador definidas para o pod: default/test-deployment2-7b58dbd49-ljztq
I0129 14:07:39.794962       1 scheduler.go:606] [GetControllerMetricInfo] Iniciando para o pod: default/test-deployment3-84f8ccf757-zb4jq
I0129 14:07:39.794969       1 scheduler.go:611] [GetControllerMetricInfo] Obtendo o nome do controlador para o pod: default/test-deployment3-84f8ccf757-zb4jq
I0129 14:07:39.794976       1 types.go:743] [ControllerName] Verificando as anotações do pod default/test-deployment3-84f8ccf757-zb4jq
I0129 14:07:39.794984       1 types.go:761] [ControllerName] Anotação 'controller' encontrada para o pod default/test-deployment3-84f8ccf757-zb4jq: test-controller3
I0129 14:07:39.794991       1 scheduler.go:614] [GetControllerMetricInfo] Métricas do controlador definidas para o pod: default/test-deployment3-84f8ccf757-zb4jq
I0129 14:07:39.795010       1 scheduler.go:98] [HigherPrecedence] Métricas para test-deployment2-7b58dbd49-ljztq: QoS = -144.423377, Importância = 0.80
I0129 14:07:39.795025       1 scheduler.go:99] [HigherPrecedence] Métricas para test-deployment3-84f8ccf757-zb4jq: QoS = -132.980451, Importância = 0.80
I0129 14:07:39.795036       1 scheduler.go:110] [HigherPrecedence] Decisão final: test-deployment2-7b58dbd49-ljztq tem precedência sobre test-deployment3-84f8ccf757-zb4jq? true
I0129 14:07:39.795062       1 postFilter.go:186] [Preempt] Verificando pods de menor precedência no nó minikube que precisam ter o campo NominatedNodeName limpo
I0129 14:07:39.795081       1 postFilter.go:188] [Preempt] Limpando o campo NominatedNodeName do pod default/test-deployment3-84f8ccf757-zb4jq
I0129 14:07:39.825286       1 postFilter.go:196] [Preempt] Finalizado para o nó minikube. Pod default/test-deployment2-7b58dbd49-ljztq deve ser alocado agora.
I0129 14:07:39.825523       1 scheduler.go:258] [OnUpdatePod] Iniciando processamento de atualização de pod
I0129 14:07:39.830404       1 scheduler.go:262] [OnUpdatePod] Pod atualizado detectado: default/test-deployment3-84f8ccf757-zb4jq, Anotações: map[acceptablePreemptionOverhead:10 controller:test-controller3 qosMeasuring:average]
I0129 14:07:39.830698       1 scheduler.go:265] [OnUpdatePod] Comparando estado no Informer e estado real no cluster para o pod default/test-deployment3-84f8ccf757-zb4jq
I0129 14:07:39.831311       1 postFilter.go:49] [PostFilter] Nó nominado para o pod default/test-deployment2-7b58dbd49-ljztq: minikube
I0129 14:07:39.846988       1 scheduler.go:70] Estado no Informer: map[acceptablePreemptionOverhead:10 controller:test-controller3 qosMeasuring:average]
I0129 14:07:39.847059       1 scheduler.go:71] Estado real no cluster: map[acceptablePreemptionOverhead:10 controller:test-controller3 qosMeasuring:average]
I0129 14:07:39.847079       1 scheduler.go:275] [OnUpdatePod] Atualizando informações de métricas para o pod default/test-deployment3-84f8ccf757-zb4jq
I0129 14:07:39.847090       1 types.go:743] [ControllerName] Verificando as anotações do pod default/test-deployment3-84f8ccf757-zb4jq
I0129 14:07:39.847100       1 types.go:761] [ControllerName] Anotação 'controller' encontrada para o pod default/test-deployment3-84f8ccf757-zb4jq: test-controller3
I0129 14:07:39.847182       1 scheduler.go:277] [OnUpdatePod] Atualizando 'LastStatus' do pod default/test-deployment3-84f8ccf757-zb4jq nas métricas
I0129 14:07:39.847196       1 scheduler.go:279] [OnUpdatePod] Métrica atualizada para o pod default/test-deployment3-84f8ccf757-zb4jq
I0129 14:07:39.847216       1 scheduler.go:283] [OnUpdatePod] Finalizando processamento de atualização de pod para default/test-deployment3-84f8ccf757-zb4jq
I0129 14:07:58.571664       1 scheduler.go:54] [QueueSort] Comparando prioridade de test-deployment2-7b58dbd49-ljztq com test-deployment3-84f8ccf757-zb4jq
I0129 14:07:58.571906       1 scheduler.go:84] [HigherPrecedence] Calculando precedência entre test-deployment2-7b58dbd49-ljztq e test-deployment3-84f8ccf757-zb4jq
I0129 14:07:58.576489       1 scheduler.go:117] [WaitForPodsOnCache] Verificando se o pod test-deployment2-7b58dbd49-ljztq está no cache...
I0129 14:07:58.577039       1 scheduler.go:606] [GetControllerMetricInfo] Iniciando para o pod: default/test-deployment2-7b58dbd49-ljztq
I0129 14:07:58.577534       1 scheduler.go:611] [GetControllerMetricInfo] Obtendo o nome do controlador para o pod: default/test-deployment2-7b58dbd49-ljztq
I0129 14:07:58.578854       1 types.go:743] [ControllerName] Verificando as anotações do pod default/test-deployment2-7b58dbd49-ljztq
I0129 14:07:58.579265       1 types.go:761] [ControllerName] Anotação 'controller' encontrada para o pod default/test-deployment2-7b58dbd49-ljztq: test-controller2
I0129 14:07:58.579440       1 scheduler.go:614] [GetControllerMetricInfo] Métricas do controlador definidas para o pod: default/test-deployment2-7b58dbd49-ljztq
I0129 14:07:58.600900       1 scheduler.go:70] Estado no Informer: map[acceptablePreemptionOverhead:10 controller:test-controller2 qosMeasuring:average]
I0129 14:07:58.600989       1 scheduler.go:71] Estado real no cluster: map[acceptablePreemptionOverhead:10 controller:test-controller2 qosMeasuring:average]
I0129 14:07:58.601009       1 scheduler.go:139] [WaitForPodsOnCache] Pod test-deployment2-7b58dbd49-ljztq encontrado no cache.
I0129 14:07:58.601019       1 scheduler.go:117] [WaitForPodsOnCache] Verificando se o pod test-deployment3-84f8ccf757-zb4jq está no cache...
I0129 14:07:58.601030       1 scheduler.go:606] [GetControllerMetricInfo] Iniciando para o pod: default/test-deployment3-84f8ccf757-zb4jq
I0129 14:07:58.601040       1 scheduler.go:611] [GetControllerMetricInfo] Obtendo o nome do controlador para o pod: default/test-deployment3-84f8ccf757-zb4jq
I0129 14:07:58.601052       1 types.go:743] [ControllerName] Verificando as anotações do pod default/test-deployment3-84f8ccf757-zb4jq
I0129 14:07:58.601064       1 types.go:761] [ControllerName] Anotação 'controller' encontrada para o pod default/test-deployment3-84f8ccf757-zb4jq: test-controller3
I0129 14:07:58.601076       1 scheduler.go:614] [GetControllerMetricInfo] Métricas do controlador definidas para o pod: default/test-deployment3-84f8ccf757-zb4jq
I0129 14:07:58.612526       1 scheduler.go:70] Estado no Informer: map[acceptablePreemptionOverhead:10 controller:test-controller3 qosMeasuring:average]
I0129 14:07:58.612565       1 scheduler.go:71] Estado real no cluster: map[acceptablePreemptionOverhead:10 controller:test-controller3 qosMeasuring:average]
I0129 14:07:58.612579       1 scheduler.go:139] [WaitForPodsOnCache] Pod test-deployment3-84f8ccf757-zb4jq encontrado no cache.
I0129 14:07:58.612591       1 scheduler.go:606] [GetControllerMetricInfo] Iniciando para o pod: default/test-deployment2-7b58dbd49-ljztq
I0129 14:07:58.612600       1 scheduler.go:611] [GetControllerMetricInfo] Obtendo o nome do controlador para o pod: default/test-deployment2-7b58dbd49-ljztq
I0129 14:07:58.612610       1 types.go:743] [ControllerName] Verificando as anotações do pod default/test-deployment2-7b58dbd49-ljztq
I0129 14:07:58.612621       1 types.go:761] [ControllerName] Anotação 'controller' encontrada para o pod default/test-deployment2-7b58dbd49-ljztq: test-controller2
I0129 14:07:58.612633       1 scheduler.go:614] [GetControllerMetricInfo] Métricas do controlador definidas para o pod: default/test-deployment2-7b58dbd49-ljztq
I0129 14:07:58.612648       1 scheduler.go:606] [GetControllerMetricInfo] Iniciando para o pod: default/test-deployment3-84f8ccf757-zb4jq
I0129 14:07:58.612657       1 scheduler.go:611] [GetControllerMetricInfo] Obtendo o nome do controlador para o pod: default/test-deployment3-84f8ccf757-zb4jq
I0129 14:07:58.612665       1 types.go:743] [ControllerName] Verificando as anotações do pod default/test-deployment3-84f8ccf757-zb4jq
I0129 14:07:58.612675       1 types.go:761] [ControllerName] Anotação 'controller' encontrada para o pod default/test-deployment3-84f8ccf757-zb4jq: test-controller3
I0129 14:07:58.612683       1 scheduler.go:614] [GetControllerMetricInfo] Métricas do controlador definidas para o pod: default/test-deployment3-84f8ccf757-zb4jq
I0129 14:07:58.612704       1 scheduler.go:98] [HigherPrecedence] Métricas para test-deployment2-7b58dbd49-ljztq: QoS = -163.228838, Importância = 0.80
I0129 14:07:58.612720       1 scheduler.go:99] [HigherPrecedence] Métricas para test-deployment3-84f8ccf757-zb4jq: QoS = -151.785912, Importância = 0.80
I0129 14:07:58.612734       1 scheduler.go:110] [HigherPrecedence] Decisão final: test-deployment2-7b58dbd49-ljztq tem precedência sobre test-deployment3-84f8ccf757-zb4jq? true
I0129 14:07:58.612751       1 scheduler.go:60] [QueueSort] Precedência determinada: test-deployment2-7b58dbd49-ljztq tem precedência sobre test-deployment3-84f8ccf757-zb4jq? true
I0129 14:07:58.613223       1 scheduler.go:146] [Reserve] resources reserved at node minikube for pod test-deployment2-7b58dbd49-ljztq_default at 2025-01-29 14:07:58.613109719 +0000 UTC m=+451.716664928
I0129 14:07:58.613260       1 types.go:743] [ControllerName] Verificando as anotações do pod default/test-deployment2-7b58dbd49-ljztq
I0129 14:07:58.613272       1 types.go:761] [ControllerName] Anotação 'controller' encontrada para o pod default/test-deployment2-7b58dbd49-ljztq: test-controller2
I0129 14:07:58.613284       1 scheduler.go:148] [Reserve] Status de alocação atual para o pod test-deployment2-7b58dbd49-ljztq_default: 
I0129 14:07:58.613294       1 scheduler.go:150] [Reserve] Status de alocação atualizado para o pod test-deployment2-7b58dbd49-ljztq_default: allocating
I0129 14:07:58.613561       1 postFilter.go:29] [PostFilter] PostFilter chamado para pod: default/test-deployment3-84f8ccf757-zb4jq
I0129 14:07:58.613579       1 postFilter.go:76] [Preempt] Comparando pod original com o atualizado...
I0129 14:07:58.613593       1 postFilter.go:83] [Preempt] Successfully retrieved updated pod default/test-deployment3-84f8ccf757-zb4jq from lister
I0129 14:07:58.622276       1 postFilter.go:233] [compareNodeResources] Recursos calculados no nó minikube: CPU = 1450 mCPU, Memória = 459276288 bytes
I0129 14:07:58.622352       1 postFilter.go:234] [compareNodeResources] Recursos do snapshot no nó minikube: CPU = 1450 mCPU, Memória = 459276288 bytes
I0129 14:07:58.622366       1 postFilter.go:240] [compareNodeResources] Recursos de CPU do nó minikube estão sincronizados: 1450 mCPU
I0129 14:07:58.622378       1 postFilter.go:246] [compareNodeResources] Recursos de memória do nó minikube estão sincronizados: 459276288 bytes
I0129 14:07:58.622535       1 scheduler.go:606] [GetControllerMetricInfo] Iniciando para o pod: default/test-deployment2-7b58dbd49-ljztq
I0129 14:07:58.622545       1 scheduler.go:611] [GetControllerMetricInfo] Obtendo o nome do controlador para o pod: default/test-deployment2-7b58dbd49-ljztq
I0129 14:07:58.622554       1 types.go:743] [ControllerName] Verificando as anotações do pod default/test-deployment2-7b58dbd49-ljztq
I0129 14:07:58.622562       1 types.go:761] [ControllerName] Anotação 'controller' encontrada para o pod default/test-deployment2-7b58dbd49-ljztq: test-controller2
I0129 14:07:58.622571       1 scheduler.go:614] [GetControllerMetricInfo] Métricas do controlador definidas para o pod: default/test-deployment2-7b58dbd49-ljztq
I0129 14:07:58.622580       1 scheduler.go:84] [HigherPrecedence] Calculando precedência entre test-deployment3-84f8ccf757-zb4jq e test-deployment2-7b58dbd49-ljztq
I0129 14:07:58.622588       1 scheduler.go:117] [WaitForPodsOnCache] Verificando se o pod test-deployment3-84f8ccf757-zb4jq está no cache...
I0129 14:07:58.622595       1 scheduler.go:606] [GetControllerMetricInfo] Iniciando para o pod: default/test-deployment3-84f8ccf757-zb4jq
I0129 14:07:58.622602       1 scheduler.go:611] [GetControllerMetricInfo] Obtendo o nome do controlador para o pod: default/test-deployment3-84f8ccf757-zb4jq
I0129 14:07:58.622608       1 types.go:743] [ControllerName] Verificando as anotações do pod default/test-deployment3-84f8ccf757-zb4jq
I0129 14:07:58.622616       1 types.go:761] [ControllerName] Anotação 'controller' encontrada para o pod default/test-deployment3-84f8ccf757-zb4jq: test-controller3
I0129 14:07:58.622624       1 scheduler.go:614] [GetControllerMetricInfo] Métricas do controlador definidas para o pod: default/test-deployment3-84f8ccf757-zb4jq
I0129 14:07:58.626394       1 scheduler.go:174] [PreBind] Validando o pod test-deployment2-7b58dbd49-ljztq antes de vincular ao node minikube
I0129 14:07:58.642328       1 scheduler.go:70] Estado no Informer: map[acceptablePreemptionOverhead:10 controller:test-controller3 qosMeasuring:average]
I0129 14:07:58.642402       1 scheduler.go:71] Estado real no cluster: map[acceptablePreemptionOverhead:10 controller:test-controller3 qosMeasuring:average]
I0129 14:07:58.642415       1 scheduler.go:139] [WaitForPodsOnCache] Pod test-deployment3-84f8ccf757-zb4jq encontrado no cache.
I0129 14:07:58.642424       1 scheduler.go:117] [WaitForPodsOnCache] Verificando se o pod test-deployment2-7b58dbd49-ljztq está no cache...
I0129 14:07:58.642431       1 scheduler.go:606] [GetControllerMetricInfo] Iniciando para o pod: default/test-deployment2-7b58dbd49-ljztq
I0129 14:07:58.642438       1 scheduler.go:611] [GetControllerMetricInfo] Obtendo o nome do controlador para o pod: default/test-deployment2-7b58dbd49-ljztq
I0129 14:07:58.642445       1 types.go:743] [ControllerName] Verificando as anotações do pod default/test-deployment2-7b58dbd49-ljztq
I0129 14:07:58.642453       1 types.go:761] [ControllerName] Anotação 'controller' encontrada para o pod default/test-deployment2-7b58dbd49-ljztq: test-controller2
I0129 14:07:58.642460       1 scheduler.go:614] [GetControllerMetricInfo] Métricas do controlador definidas para o pod: default/test-deployment2-7b58dbd49-ljztq
I0129 14:07:58.653924       1 scheduler.go:182] [PostBind] Chamado para pod test-deployment2-7b58dbd49-ljztq
I0129 14:07:58.653976       1 scheduler.go:200] [PostBind] Pod test-deployment2-7b58dbd49-ljztq - Início do binding: 2025-01-29 14:07:58.626411715 +0000 UTC m=+451.729966844, Fim do binding: 2025-01-29 14:07:58.653971401 +0000 UTC m=+451.757526601
I0129 14:07:58.660307       1 scheduler.go:258] [OnUpdatePod] Iniciando processamento de atualização de pod
I0129 14:07:58.660379       1 scheduler.go:262] [OnUpdatePod] Pod atualizado detectado: default/test-deployment2-7b58dbd49-ljztq, Anotações: map[acceptablePreemptionOverhead:10 controller:test-controller2 qosMeasuring:average]
I0129 14:07:58.660396       1 scheduler.go:265] [OnUpdatePod] Comparando estado no Informer e estado real no cluster para o pod default/test-deployment2-7b58dbd49-ljztq
I0129 14:07:58.672577       1 scheduler.go:70] Estado no Informer: map[acceptablePreemptionOverhead:10 controller:test-controller2 qosMeasuring:average]
I0129 14:07:58.673343       1 scheduler.go:71] Estado real no cluster: map[acceptablePreemptionOverhead:10 controller:test-controller2 qosMeasuring:average]
I0129 14:07:58.673588       1 scheduler.go:139] [WaitForPodsOnCache] Pod test-deployment2-7b58dbd49-ljztq encontrado no cache.
I0129 14:07:58.673730       1 scheduler.go:606] [GetControllerMetricInfo] Iniciando para o pod: default/test-deployment3-84f8ccf757-zb4jq
I0129 14:07:58.673863       1 types.go:743] [ControllerName] Verificando as anotações do pod default/test-deployment2-7b58dbd49-ljztq
I0129 14:07:58.673998       1 types.go:761] [ControllerName] Anotação 'controller' encontrada para o pod default/test-deployment2-7b58dbd49-ljztq: test-controller2
I0129 14:07:58.674165       1 scheduler.go:207] [PostBind] Métricas atualizadas para o pod test-deployment2-7b58dbd49-ljztq
I0129 14:07:58.678189       1 scheduler.go:611] [GetControllerMetricInfo] Obtendo o nome do controlador para o pod: default/test-deployment3-84f8ccf757-zb4jq
I0129 14:07:58.678415       1 types.go:743] [ControllerName] Verificando as anotações do pod default/test-deployment3-84f8ccf757-zb4jq
I0129 14:07:58.678604       1 types.go:761] [ControllerName] Anotação 'controller' encontrada para o pod default/test-deployment3-84f8ccf757-zb4jq: test-controller3
I0129 14:07:58.678798       1 scheduler.go:614] [GetControllerMetricInfo] Métricas do controlador definidas para o pod: default/test-deployment3-84f8ccf757-zb4jq
I0129 14:07:58.679231       1 scheduler.go:606] [GetControllerMetricInfo] Iniciando para o pod: default/test-deployment2-7b58dbd49-ljztq
I0129 14:07:58.681170       1 scheduler.go:611] [GetControllerMetricInfo] Obtendo o nome do controlador para o pod: default/test-deployment2-7b58dbd49-ljztq
I0129 14:07:58.681202       1 types.go:743] [ControllerName] Verificando as anotações do pod default/test-deployment2-7b58dbd49-ljztq
I0129 14:07:58.681209       1 types.go:761] [ControllerName] Anotação 'controller' encontrada para o pod default/test-deployment2-7b58dbd49-ljztq: test-controller2
I0129 14:07:58.681214       1 scheduler.go:614] [GetControllerMetricInfo] Métricas do controlador definidas para o pod: default/test-deployment2-7b58dbd49-ljztq
I0129 14:07:58.681229       1 scheduler.go:98] [HigherPrecedence] Métricas para test-deployment3-84f8ccf757-zb4jq: QoS = -151.836593, Importância = 0.80
I0129 14:07:58.681237       1 scheduler.go:99] [HigherPrecedence] Métricas para test-deployment2-7b58dbd49-ljztq: QoS = -163.327951, Importância = 0.80
I0129 14:07:58.681243       1 scheduler.go:110] [HigherPrecedence] Decisão final: test-deployment3-84f8ccf757-zb4jq tem precedência sobre test-deployment2-7b58dbd49-ljztq? false
I0129 14:07:58.681281       1 postFilter.go:144] [PREEMPT CALL] No node was chosen to allocate pod test-deployment3-84f8ccf757-zb4jq
W0129 14:07:58.681330       1 postFilter.go:45] [PostFilter] Nenhum nó nominado após a preempção para o pod: default/test-deployment3-84f8ccf757-zb4jq
I0129 14:07:58.683469       1 scheduler.go:70] Estado no Informer: map[acceptablePreemptionOverhead:10 controller:test-controller2 qosMeasuring:average]
I0129 14:07:58.683506       1 scheduler.go:71] Estado real no cluster: map[acceptablePreemptionOverhead:10 controller:test-controller2 qosMeasuring:average]
I0129 14:07:58.683517       1 scheduler.go:275] [OnUpdatePod] Atualizando informações de métricas para o pod default/test-deployment2-7b58dbd49-ljztq
I0129 14:07:58.683541       1 types.go:743] [ControllerName] Verificando as anotações do pod default/test-deployment2-7b58dbd49-ljztq
I0129 14:07:58.683547       1 types.go:761] [ControllerName] Anotação 'controller' encontrada para o pod default/test-deployment2-7b58dbd49-ljztq: test-controller2
I0129 14:07:58.683554       1 scheduler.go:277] [OnUpdatePod] Atualizando 'LastStatus' do pod default/test-deployment2-7b58dbd49-ljztq nas métricas
I0129 14:07:58.683577       1 scheduler.go:279] [OnUpdatePod] Métrica atualizada para o pod default/test-deployment2-7b58dbd49-ljztq
I0129 14:07:58.683604       1 scheduler.go:283] [OnUpdatePod] Finalizando processamento de atualização de pod para default/test-deployment2-7b58dbd49-ljztq
I0129 14:07:58.702063       1 scheduler.go:258] [OnUpdatePod] Iniciando processamento de atualização de pod
I0129 14:07:58.702149       1 scheduler.go:262] [OnUpdatePod] Pod atualizado detectado: default/test-deployment2-7b58dbd49-ljztq, Anotações: map[acceptablePreemptionOverhead:10 controller:test-controller2 qosMeasuring:average]
I0129 14:07:58.702165       1 scheduler.go:265] [OnUpdatePod] Comparando estado no Informer e estado real no cluster para o pod default/test-deployment2-7b58dbd49-ljztq
I0129 14:07:58.709295       1 scheduler.go:70] Estado no Informer: map[acceptablePreemptionOverhead:10 controller:test-controller2 qosMeasuring:average]
I0129 14:07:58.711190       1 scheduler.go:71] Estado real no cluster: map[acceptablePreemptionOverhead:10 controller:test-controller2 qosMeasuring:average]
I0129 14:07:58.711264       1 scheduler.go:275] [OnUpdatePod] Atualizando informações de métricas para o pod default/test-deployment2-7b58dbd49-ljztq
I0129 14:07:58.711290       1 types.go:743] [ControllerName] Verificando as anotações do pod default/test-deployment2-7b58dbd49-ljztq
I0129 14:07:58.711297       1 types.go:761] [ControllerName] Anotação 'controller' encontrada para o pod default/test-deployment2-7b58dbd49-ljztq: test-controller2
I0129 14:07:58.711307       1 scheduler.go:277] [OnUpdatePod] Atualizando 'LastStatus' do pod default/test-deployment2-7b58dbd49-ljztq nas métricas
I0129 14:07:58.711389       1 scheduler.go:279] [OnUpdatePod] Métrica atualizada para o pod default/test-deployment2-7b58dbd49-ljztq
I0129 14:07:58.711399       1 scheduler.go:283] [OnUpdatePod] Finalizando processamento de atualização de pod para default/test-deployment2-7b58dbd49-ljztq
I0129 14:08:00.757679       1 postFilter.go:29] [PostFilter] PostFilter chamado para pod: default/test-deployment3-84f8ccf757-zb4jq
I0129 14:08:00.757716       1 postFilter.go:76] [Preempt] Comparando pod original com o atualizado...
I0129 14:08:00.757730       1 postFilter.go:83] [Preempt] Successfully retrieved updated pod default/test-deployment3-84f8ccf757-zb4jq from lister
I0129 14:08:00.912841       1 postFilter.go:233] [compareNodeResources] Recursos calculados no nó minikube: CPU = 1450 mCPU, Memória = 459276288 bytes
I0129 14:08:00.915755       1 postFilter.go:234] [compareNodeResources] Recursos do snapshot no nó minikube: CPU = 1450 mCPU, Memória = 459276288 bytes
I0129 14:08:00.916276       1 postFilter.go:240] [compareNodeResources] Recursos de CPU do nó minikube estão sincronizados: 1450 mCPU
I0129 14:08:00.916435       1 postFilter.go:246] [compareNodeResources] Recursos de memória do nó minikube estão sincronizados: 459276288 bytes
I0129 14:08:00.916826       1 scheduler.go:606] [GetControllerMetricInfo] Iniciando para o pod: default/test-deployment2-7b58dbd49-ljztq
I0129 14:08:00.916958       1 scheduler.go:611] [GetControllerMetricInfo] Obtendo o nome do controlador para o pod: default/test-deployment2-7b58dbd49-ljztq
I0129 14:08:00.917701       1 types.go:743] [ControllerName] Verificando as anotações do pod default/test-deployment2-7b58dbd49-ljztq
I0129 14:08:00.918073       1 types.go:761] [ControllerName] Anotação 'controller' encontrada para o pod default/test-deployment2-7b58dbd49-ljztq: test-controller2
I0129 14:08:00.918428       1 scheduler.go:614] [GetControllerMetricInfo] Métricas do controlador definidas para o pod: default/test-deployment2-7b58dbd49-ljztq
I0129 14:08:00.929411       1 scheduler.go:84] [HigherPrecedence] Calculando precedência entre test-deployment3-84f8ccf757-zb4jq e test-deployment2-7b58dbd49-ljztq
I0129 14:08:00.929438       1 scheduler.go:117] [WaitForPodsOnCache] Verificando se o pod test-deployment3-84f8ccf757-zb4jq está no cache...
I0129 14:08:00.929449       1 scheduler.go:606] [GetControllerMetricInfo] Iniciando para o pod: default/test-deployment3-84f8ccf757-zb4jq
I0129 14:08:00.929459       1 scheduler.go:611] [GetControllerMetricInfo] Obtendo o nome do controlador para o pod: default/test-deployment3-84f8ccf757-zb4jq
I0129 14:08:00.929468       1 types.go:743] [ControllerName] Verificando as anotações do pod default/test-deployment3-84f8ccf757-zb4jq
I0129 14:08:00.929479       1 types.go:761] [ControllerName] Anotação 'controller' encontrada para o pod default/test-deployment3-84f8ccf757-zb4jq: test-controller3
I0129 14:08:00.929490       1 scheduler.go:614] [GetControllerMetricInfo] Métricas do controlador definidas para o pod: default/test-deployment3-84f8ccf757-zb4jq
I0129 14:08:00.944280       1 scheduler.go:70] Estado no Informer: map[acceptablePreemptionOverhead:10 controller:test-controller3 qosMeasuring:average]
I0129 14:08:00.947352       1 scheduler.go:71] Estado real no cluster: map[acceptablePreemptionOverhead:10 controller:test-controller3 qosMeasuring:average]
I0129 14:08:00.947428       1 scheduler.go:139] [WaitForPodsOnCache] Pod test-deployment3-84f8ccf757-zb4jq encontrado no cache.
I0129 14:08:00.947441       1 scheduler.go:117] [WaitForPodsOnCache] Verificando se o pod test-deployment2-7b58dbd49-ljztq está no cache...
I0129 14:08:00.947472       1 scheduler.go:606] [GetControllerMetricInfo] Iniciando para o pod: default/test-deployment2-7b58dbd49-ljztq
I0129 14:08:00.947477       1 scheduler.go:611] [GetControllerMetricInfo] Obtendo o nome do controlador para o pod: default/test-deployment2-7b58dbd49-ljztq
I0129 14:08:00.947486       1 types.go:743] [ControllerName] Verificando as anotações do pod default/test-deployment2-7b58dbd49-ljztq
I0129 14:08:00.947500       1 types.go:761] [ControllerName] Anotação 'controller' encontrada para o pod default/test-deployment2-7b58dbd49-ljztq: test-controller2
I0129 14:08:00.947510       1 scheduler.go:614] [GetControllerMetricInfo] Métricas do controlador definidas para o pod: default/test-deployment2-7b58dbd49-ljztq
I0129 14:08:00.957855       1 scheduler.go:70] Estado no Informer: map[acceptablePreemptionOverhead:10 controller:test-controller2 qosMeasuring:average]
I0129 14:08:00.957916       1 scheduler.go:71] Estado real no cluster: map[acceptablePreemptionOverhead:10 controller:test-controller2 qosMeasuring:average]
I0129 14:08:00.957928       1 scheduler.go:139] [WaitForPodsOnCache] Pod test-deployment2-7b58dbd49-ljztq encontrado no cache.
I0129 14:08:00.957936       1 scheduler.go:606] [GetControllerMetricInfo] Iniciando para o pod: default/test-deployment3-84f8ccf757-zb4jq
I0129 14:08:00.957942       1 scheduler.go:611] [GetControllerMetricInfo] Obtendo o nome do controlador para o pod: default/test-deployment3-84f8ccf757-zb4jq
I0129 14:08:00.957949       1 types.go:743] [ControllerName] Verificando as anotações do pod default/test-deployment3-84f8ccf757-zb4jq
I0129 14:08:00.957957       1 types.go:761] [ControllerName] Anotação 'controller' encontrada para o pod default/test-deployment3-84f8ccf757-zb4jq: test-controller3
I0129 14:08:00.957965       1 scheduler.go:614] [GetControllerMetricInfo] Métricas do controlador definidas para o pod: default/test-deployment3-84f8ccf757-zb4jq
I0129 14:08:00.957976       1 scheduler.go:606] [GetControllerMetricInfo] Iniciando para o pod: default/test-deployment2-7b58dbd49-ljztq
I0129 14:08:00.957982       1 scheduler.go:611] [GetControllerMetricInfo] Obtendo o nome do controlador para o pod: default/test-deployment2-7b58dbd49-ljztq
I0129 14:08:00.957986       1 types.go:743] [ControllerName] Verificando as anotações do pod default/test-deployment2-7b58dbd49-ljztq
I0129 14:08:00.957992       1 types.go:761] [ControllerName] Anotação 'controller' encontrada para o pod default/test-deployment2-7b58dbd49-ljztq: test-controller2
I0129 14:08:00.957998       1 scheduler.go:614] [GetControllerMetricInfo] Métricas do controlador definidas para o pod: default/test-deployment2-7b58dbd49-ljztq
I0129 14:08:00.958013       1 scheduler.go:98] [HigherPrecedence] Métricas para test-deployment3-84f8ccf757-zb4jq: QoS = -154.141317, Importância = 0.80
I0129 14:08:00.958022       1 scheduler.go:99] [HigherPrecedence] Métricas para test-deployment2-7b58dbd49-ljztq: QoS = -162.751770, Importância = 0.80
I0129 14:08:00.958031       1 scheduler.go:110] [HigherPrecedence] Decisão final: test-deployment3-84f8ccf757-zb4jq tem precedência sobre test-deployment2-7b58dbd49-ljztq? false
I0129 14:08:00.958109       1 postFilter.go:144] [PREEMPT CALL] No node was chosen to allocate pod test-deployment3-84f8ccf757-zb4jq
W0129 14:08:00.962169       1 postFilter.go:45] [PostFilter] Nenhum nó nominado após a preempção para o pod: default/test-deployment3-84f8ccf757-zb4jq
I0129 14:08:04.189883       1 scheduler.go:258] [OnUpdatePod] Iniciando processamento de atualização de pod
I0129 14:08:04.190448       1 scheduler.go:262] [OnUpdatePod] Pod atualizado detectado: default/test-deployment2-7b58dbd49-ljztq, Anotações: map[acceptablePreemptionOverhead:10 controller:test-controller2 qosMeasuring:average]
I0129 14:08:04.190628       1 scheduler.go:265] [OnUpdatePod] Comparando estado no Informer e estado real no cluster para o pod default/test-deployment2-7b58dbd49-ljztq
I0129 14:08:04.208841       1 scheduler.go:70] Estado no Informer: map[acceptablePreemptionOverhead:10 controller:test-controller2 qosMeasuring:average]
I0129 14:08:04.209035       1 scheduler.go:71] Estado real no cluster: map[acceptablePreemptionOverhead:10 controller:test-controller2 qosMeasuring:average]
I0129 14:08:04.209087       1 scheduler.go:275] [OnUpdatePod] Atualizando informações de métricas para o pod default/test-deployment2-7b58dbd49-ljztq
I0129 14:08:04.209188       1 types.go:743] [ControllerName] Verificando as anotações do pod default/test-deployment2-7b58dbd49-ljztq
I0129 14:08:04.209220       1 types.go:761] [ControllerName] Anotação 'controller' encontrada para o pod default/test-deployment2-7b58dbd49-ljztq: test-controller2
I0129 14:08:04.209267       1 scheduler.go:277] [OnUpdatePod] Atualizando 'LastStatus' do pod default/test-deployment2-7b58dbd49-ljztq nas métricas
I0129 14:08:04.209304       1 scheduler.go:279] [OnUpdatePod] Métrica atualizada para o pod default/test-deployment2-7b58dbd49-ljztq
I0129 14:08:04.209465       1 scheduler.go:283] [OnUpdatePod] Finalizando processamento de atualização de pod para default/test-deployment2-7b58dbd49-ljztq
I0129 14:08:28.615830       1 postFilter.go:29] [PostFilter] PostFilter chamado para pod: default/test-deployment3-84f8ccf757-zb4jq
I0129 14:08:28.615990       1 postFilter.go:76] [Preempt] Comparando pod original com o atualizado...
I0129 14:08:28.616034       1 postFilter.go:83] [Preempt] Successfully retrieved updated pod default/test-deployment3-84f8ccf757-zb4jq from lister
I0129 14:08:28.641283       1 postFilter.go:233] [compareNodeResources] Recursos calculados no nó minikube: CPU = 1450 mCPU, Memória = 459276288 bytes
I0129 14:08:28.649956       1 postFilter.go:234] [compareNodeResources] Recursos do snapshot no nó minikube: CPU = 1450 mCPU, Memória = 459276288 bytes
I0129 14:08:28.655022       1 postFilter.go:240] [compareNodeResources] Recursos de CPU do nó minikube estão sincronizados: 1450 mCPU
I0129 14:08:28.655063       1 postFilter.go:246] [compareNodeResources] Recursos de memória do nó minikube estão sincronizados: 459276288 bytes
I0129 14:08:28.655812       1 scheduler.go:606] [GetControllerMetricInfo] Iniciando para o pod: default/test-deployment2-7b58dbd49-ljztq
I0129 14:08:28.655834       1 scheduler.go:611] [GetControllerMetricInfo] Obtendo o nome do controlador para o pod: default/test-deployment2-7b58dbd49-ljztq
I0129 14:08:28.655883       1 types.go:743] [ControllerName] Verificando as anotações do pod default/test-deployment2-7b58dbd49-ljztq
I0129 14:08:28.655917       1 types.go:761] [ControllerName] Anotação 'controller' encontrada para o pod default/test-deployment2-7b58dbd49-ljztq: test-controller2
I0129 14:08:28.655931       1 scheduler.go:614] [GetControllerMetricInfo] Métricas do controlador definidas para o pod: default/test-deployment2-7b58dbd49-ljztq
I0129 14:08:28.655944       1 scheduler.go:84] [HigherPrecedence] Calculando precedência entre test-deployment3-84f8ccf757-zb4jq e test-deployment2-7b58dbd49-ljztq
I0129 14:08:28.655955       1 scheduler.go:117] [WaitForPodsOnCache] Verificando se o pod test-deployment3-84f8ccf757-zb4jq está no cache...
I0129 14:08:28.655977       1 scheduler.go:606] [GetControllerMetricInfo] Iniciando para o pod: default/test-deployment3-84f8ccf757-zb4jq
I0129 14:08:28.656010       1 scheduler.go:611] [GetControllerMetricInfo] Obtendo o nome do controlador para o pod: default/test-deployment3-84f8ccf757-zb4jq
I0129 14:08:28.656019       1 types.go:743] [ControllerName] Verificando as anotações do pod default/test-deployment3-84f8ccf757-zb4jq
I0129 14:08:28.656031       1 types.go:761] [ControllerName] Anotação 'controller' encontrada para o pod default/test-deployment3-84f8ccf757-zb4jq: test-controller3
I0129 14:08:28.656042       1 scheduler.go:614] [GetControllerMetricInfo] Métricas do controlador definidas para o pod: default/test-deployment3-84f8ccf757-zb4jq
I0129 14:08:28.665569       1 scheduler.go:70] Estado no Informer: map[acceptablePreemptionOverhead:10 controller:test-controller3 qosMeasuring:average]
I0129 14:08:28.665664       1 scheduler.go:71] Estado real no cluster: map[acceptablePreemptionOverhead:10 controller:test-controller3 qosMeasuring:average]
I0129 14:08:28.666378       1 scheduler.go:139] [WaitForPodsOnCache] Pod test-deployment3-84f8ccf757-zb4jq encontrado no cache.
I0129 14:08:28.666528       1 scheduler.go:117] [WaitForPodsOnCache] Verificando se o pod test-deployment2-7b58dbd49-ljztq está no cache...
I0129 14:08:28.666543       1 scheduler.go:606] [GetControllerMetricInfo] Iniciando para o pod: default/test-deployment2-7b58dbd49-ljztq
I0129 14:08:28.666553       1 scheduler.go:611] [GetControllerMetricInfo] Obtendo o nome do controlador para o pod: default/test-deployment2-7b58dbd49-ljztq
I0129 14:08:28.666564       1 types.go:743] [ControllerName] Verificando as anotações do pod default/test-deployment2-7b58dbd49-ljztq
I0129 14:08:28.666576       1 types.go:761] [ControllerName] Anotação 'controller' encontrada para o pod default/test-deployment2-7b58dbd49-ljztq: test-controller2
I0129 14:08:28.666588       1 scheduler.go:614] [GetControllerMetricInfo] Métricas do controlador definidas para o pod: default/test-deployment2-7b58dbd49-ljztq
I0129 14:08:28.677022       1 scheduler.go:70] Estado no Informer: map[acceptablePreemptionOverhead:10 controller:test-controller2 qosMeasuring:average]
I0129 14:08:28.677063       1 scheduler.go:71] Estado real no cluster: map[acceptablePreemptionOverhead:10 controller:test-controller2 qosMeasuring:average]
I0129 14:08:28.677076       1 scheduler.go:139] [WaitForPodsOnCache] Pod test-deployment2-7b58dbd49-ljztq encontrado no cache.
I0129 14:08:28.677089       1 scheduler.go:606] [GetControllerMetricInfo] Iniciando para o pod: default/test-deployment3-84f8ccf757-zb4jq
I0129 14:08:28.677099       1 scheduler.go:611] [GetControllerMetricInfo] Obtendo o nome do controlador para o pod: default/test-deployment3-84f8ccf757-zb4jq
I0129 14:08:28.677109       1 types.go:743] [ControllerName] Verificando as anotações do pod default/test-deployment3-84f8ccf757-zb4jq
I0129 14:08:28.677250       1 types.go:761] [ControllerName] Anotação 'controller' encontrada para o pod default/test-deployment3-84f8ccf757-zb4jq: test-controller3
I0129 14:08:28.677265       1 scheduler.go:614] [GetControllerMetricInfo] Métricas do controlador definidas para o pod: default/test-deployment3-84f8ccf757-zb4jq
I0129 14:08:28.677297       1 scheduler.go:606] [GetControllerMetricInfo] Iniciando para o pod: default/test-deployment2-7b58dbd49-ljztq
I0129 14:08:28.677306       1 scheduler.go:611] [GetControllerMetricInfo] Obtendo o nome do controlador para o pod: default/test-deployment2-7b58dbd49-ljztq
I0129 14:08:28.677313       1 types.go:743] [ControllerName] Verificando as anotações do pod default/test-deployment2-7b58dbd49-ljztq
I0129 14:08:28.677322       1 types.go:761] [ControllerName] Anotação 'controller' encontrada para o pod default/test-deployment2-7b58dbd49-ljztq: test-controller2
I0129 14:08:28.677331       1 scheduler.go:614] [GetControllerMetricInfo] Métricas do controlador definidas para o pod: default/test-deployment2-7b58dbd49-ljztq
I0129 14:08:28.677353       1 scheduler.go:98] [HigherPrecedence] Métricas para test-deployment3-84f8ccf757-zb4jq: QoS = -181.869954, Importância = 0.80
I0129 14:08:28.677407       1 scheduler.go:99] [HigherPrecedence] Métricas para test-deployment2-7b58dbd49-ljztq: QoS = -155.819611, Importância = 0.80
I0129 14:08:28.677420       1 scheduler.go:110] [HigherPrecedence] Decisão final: test-deployment3-84f8ccf757-zb4jq tem precedência sobre test-deployment2-7b58dbd49-ljztq? true
I0129 14:08:28.677431       1 types.go:743] [ControllerName] Verificando as anotações do pod default/test-deployment3-84f8ccf757-zb4jq
I0129 14:08:28.677439       1 types.go:761] [ControllerName] Anotação 'controller' encontrada para o pod default/test-deployment3-84f8ccf757-zb4jq: test-controller3
I0129 14:08:28.677446       1 types.go:743] [ControllerName] Verificando as anotações do pod default/test-deployment2-7b58dbd49-ljztq
I0129 14:08:28.677455       1 types.go:761] [ControllerName] Anotação 'controller' encontrada para o pod default/test-deployment2-7b58dbd49-ljztq: test-controller2
I0129 14:08:28.677463       1 scheduler.go:606] [GetControllerMetricInfo] Iniciando para o pod: default/test-deployment2-7b58dbd49-ljztq
I0129 14:08:28.677472       1 scheduler.go:611] [GetControllerMetricInfo] Obtendo o nome do controlador para o pod: default/test-deployment2-7b58dbd49-ljztq
I0129 14:08:28.677479       1 types.go:743] [ControllerName] Verificando as anotações do pod default/test-deployment2-7b58dbd49-ljztq
I0129 14:08:28.677487       1 types.go:761] [ControllerName] Anotação 'controller' encontrada para o pod default/test-deployment2-7b58dbd49-ljztq: test-controller2
I0129 14:08:28.677495       1 scheduler.go:614] [GetControllerMetricInfo] Métricas do controlador definidas para o pod: default/test-deployment2-7b58dbd49-ljztq
I0129 14:08:28.677502       1 scheduler.go:606] [GetControllerMetricInfo] Iniciando para o pod: default/test-deployment2-7b58dbd49-ljztq
I0129 14:08:28.677510       1 scheduler.go:611] [GetControllerMetricInfo] Obtendo o nome do controlador para o pod: default/test-deployment2-7b58dbd49-ljztq
I0129 14:08:28.677533       1 types.go:743] [ControllerName] Verificando as anotações do pod default/test-deployment2-7b58dbd49-ljztq
I0129 14:08:28.677542       1 types.go:761] [ControllerName] Anotação 'controller' encontrada para o pod default/test-deployment2-7b58dbd49-ljztq: test-controller2
I0129 14:08:28.677551       1 scheduler.go:614] [GetControllerMetricInfo] Métricas do controlador definidas para o pod: default/test-deployment2-7b58dbd49-ljztq
I0129 14:08:28.677560       1 types.go:743] [ControllerName] Verificando as anotações do pod default/test-deployment2-7b58dbd49-ljztq
I0129 14:08:28.677567       1 types.go:761] [ControllerName] Anotação 'controller' encontrada para o pod default/test-deployment2-7b58dbd49-ljztq: test-controller2
I0129 14:08:28.677740       1 scheduler.go:606] [GetControllerMetricInfo] Iniciando para o pod: default/test-deployment2-7b58dbd49-ljztq
I0129 14:08:28.677751       1 scheduler.go:611] [GetControllerMetricInfo] Obtendo o nome do controlador para o pod: default/test-deployment2-7b58dbd49-ljztq
I0129 14:08:28.677759       1 types.go:743] [ControllerName] Verificando as anotações do pod default/test-deployment2-7b58dbd49-ljztq
I0129 14:08:28.677767       1 types.go:761] [ControllerName] Anotação 'controller' encontrada para o pod default/test-deployment2-7b58dbd49-ljztq: test-controller2
I0129 14:08:28.677776       1 scheduler.go:614] [GetControllerMetricInfo] Métricas do controlador definidas para o pod: default/test-deployment2-7b58dbd49-ljztq
I0129 14:08:28.677788       1 scheduler.go:606] [GetControllerMetricInfo] Iniciando para o pod: default/test-deployment2-7b58dbd49-ljztq
I0129 14:08:28.677796       1 scheduler.go:611] [GetControllerMetricInfo] Obtendo o nome do controlador para o pod: default/test-deployment2-7b58dbd49-ljztq
I0129 14:08:28.677803       1 types.go:743] [ControllerName] Verificando as anotações do pod default/test-deployment2-7b58dbd49-ljztq
I0129 14:08:28.677811       1 types.go:761] [ControllerName] Anotação 'controller' encontrada para o pod default/test-deployment2-7b58dbd49-ljztq: test-controller2
I0129 14:08:28.677819       1 scheduler.go:614] [GetControllerMetricInfo] Métricas do controlador definidas para o pod: default/test-deployment2-7b58dbd49-ljztq
I0129 14:08:28.677860       1 postFilter.go:147] [PREEMPT CALL] The node minikube  was chosen to allocate pod test-deployment3-84f8ccf757-zb4jq
I0129 14:08:28.677877       1 postFilter.go:151] [Preempt] Iniciando a remoção dos pods preemptados no nó minikube para alocar o pod default/test-deployment3-84f8ccf757-zb4jq. Total de vítimas: 1
I0129 14:08:28.677926       1 postFilter.go:155] [Preempt] Tentando remover o pod default/test-deployment2-7b58dbd49-ljztq no nó minikube
I0129 14:08:28.719781       1 postFilter.go:168] [Preempt] Pod default/test-deployment2-7b58dbd49-ljztq removido com sucesso no nó minikube
I0129 14:08:28.719846       1 postFilter.go:174] test-deployment2-7b58dbd49-ljztq_default preempted by test-deployment3-84f8ccf757-zb4jq_default on node minikube
I0129 14:08:28.719883       1 postFilter.go:179] [Preempt] Total de pods preemptados no nó minikube: 1
I0129 14:08:28.719911       1 postFilter.go:186] [Preempt] Verificando pods de menor precedência no nó minikube que precisam ter o campo NominatedNodeName limpo
I0129 14:08:28.719923       1 postFilter.go:196] [Preempt] Finalizado para o nó minikube. Pod default/test-deployment3-84f8ccf757-zb4jq deve ser alocado agora.
I0129 14:08:28.719932       1 postFilter.go:49] [PostFilter] Nó nominado para o pod default/test-deployment3-84f8ccf757-zb4jq: minikube
I0129 14:08:28.726569       1 scheduler.go:258] [OnUpdatePod] Iniciando processamento de atualização de pod
I0129 14:08:28.726626       1 scheduler.go:262] [OnUpdatePod] Pod atualizado detectado: default/test-deployment2-7b58dbd49-ljztq, Anotações: map[acceptablePreemptionOverhead:10 controller:test-controller2 qosMeasuring:average]
I0129 14:08:28.726688       1 scheduler.go:265] [OnUpdatePod] Comparando estado no Informer e estado real no cluster para o pod default/test-deployment2-7b58dbd49-ljztq
E0129 14:08:29.527622       1 scheduler.go:67] Erro ao buscar estado real do pod test-deployment2-7b58dbd49-ljztq: pods "test-deployment2-7b58dbd49-ljztq" not found
I0129 14:08:29.527972       1 scheduler.go:275] [OnUpdatePod] Atualizando informações de métricas para o pod default/test-deployment2-7b58dbd49-ljztq
I0129 14:08:29.528017       1 types.go:743] [ControllerName] Verificando as anotações do pod default/test-deployment2-7b58dbd49-ljztq
I0129 14:08:29.528043       1 types.go:761] [ControllerName] Anotação 'controller' encontrada para o pod default/test-deployment2-7b58dbd49-ljztq: test-controller2
I0129 14:08:29.528087       1 scheduler.go:277] [OnUpdatePod] Atualizando 'LastStatus' do pod default/test-deployment2-7b58dbd49-ljztq nas métricas
I0129 14:08:29.528241       1 scheduler.go:279] [OnUpdatePod] Métrica atualizada para o pod default/test-deployment2-7b58dbd49-ljztq
I0129 14:08:29.533932       1 scheduler.go:283] [OnUpdatePod] Finalizando processamento de atualização de pod para default/test-deployment2-7b58dbd49-ljztq
I0129 14:08:29.534079       1 scheduler.go:291] [OnDeletePod] Iniciando a execução do OnDeletePod
I0129 14:08:29.534487       1 scheduler.go:300] [OnDeletePod] DeepCopy realizado para o pod default/test-deployment2-7b58dbd49-ljztq
I0129 14:08:29.536962       1 scheduler.go:307] [OnDeletePod] Pod deletado detectado: default/test-deployment2-7b58dbd49-ljztq
I0129 14:08:29.537102       1 scheduler.go:309] [OnDeletePod] Atualizando métricas do pod default/test-deployment2-7b58dbd49-ljztq
I0129 14:08:29.537221       1 types.go:743] [ControllerName] Verificando as anotações do pod default/test-deployment2-7b58dbd49-ljztq
I0129 14:08:29.537249       1 types.go:761] [ControllerName] Anotação 'controller' encontrada para o pod default/test-deployment2-7b58dbd49-ljztq: test-controller2
I0129 14:08:29.537357       1 scheduler.go:311] [OnDeletePod] Verificando o estado do pod default/test-deployment2-7b58dbd49-ljztq nas métricas
I0129 14:08:29.537384       1 scheduler.go:321] [OnDeletePod] EndTime atualizado para o pod default/test-deployment2-7b58dbd49-ljztq: 2025-01-29 14:08:29.537379475 +0000 UTC m=+482.640934585
I0129 14:08:29.537507       1 scheduler.go:325] [OnDeletePod] Finalizando a execução do OnDeletePod para o pod default/test-deployment2-7b58dbd49-ljztq
I0129 14:08:29.537624       1 scheduler.go:258] [OnUpdatePod] Iniciando processamento de atualização de pod
I0129 14:08:29.537754       1 scheduler.go:262] [OnUpdatePod] Pod atualizado detectado: default/test-deployment3-84f8ccf757-zb4jq, Anotações: map[acceptablePreemptionOverhead:10 controller:test-controller3 qosMeasuring:average]
I0129 14:08:29.537921       1 scheduler.go:265] [OnUpdatePod] Comparando estado no Informer e estado real no cluster para o pod default/test-deployment3-84f8ccf757-zb4jq
I0129 14:08:29.549674       1 types.go:743] [ControllerName] Verificando as anotações do pod default/test-deployment2-7b58dbd49-ljztq
I0129 14:08:29.550632       1 types.go:761] [ControllerName] Anotação 'controller' encontrada para o pod default/test-deployment2-7b58dbd49-ljztq: test-controller2
I0129 14:08:29.573853       1 scheduler.go:70] Estado no Informer: map[acceptablePreemptionOverhead:10 controller:test-controller3 qosMeasuring:average]
I0129 14:08:29.573990       1 scheduler.go:71] Estado real no cluster: map[acceptablePreemptionOverhead:10 controller:test-controller3 qosMeasuring:average]
I0129 14:08:29.574030       1 scheduler.go:275] [OnUpdatePod] Atualizando informações de métricas para o pod default/test-deployment3-84f8ccf757-zb4jq
I0129 14:08:29.574049       1 types.go:743] [ControllerName] Verificando as anotações do pod default/test-deployment3-84f8ccf757-zb4jq
I0129 14:08:29.574064       1 types.go:761] [ControllerName] Anotação 'controller' encontrada para o pod default/test-deployment3-84f8ccf757-zb4jq: test-controller3
I0129 14:08:29.574084       1 scheduler.go:277] [OnUpdatePod] Atualizando 'LastStatus' do pod default/test-deployment3-84f8ccf757-zb4jq nas métricas
I0129 14:08:29.574107       1 scheduler.go:279] [OnUpdatePod] Métrica atualizada para o pod default/test-deployment3-84f8ccf757-zb4jq
I0129 14:08:29.574314       1 scheduler.go:283] [OnUpdatePod] Finalizando processamento de atualização de pod para default/test-deployment3-84f8ccf757-zb4jq
I0129 14:08:29.590705       1 scheduler.go:218] [OnAddPod] Pod adicionado: default/test-deployment2-7b58dbd49-w52nk, Anotações: map[acceptablePreemptionOverhead:10 controller:test-controller2 qosMeasuring:average]
I0129 14:08:29.608372       1 scheduler.go:70] Estado no Informer: map[acceptablePreemptionOverhead:10 controller:test-controller2 qosMeasuring:average]
I0129 14:08:29.608575       1 scheduler.go:71] Estado real no cluster: map[acceptablePreemptionOverhead:10 controller:test-controller2 qosMeasuring:average]
I0129 14:08:29.615703       1 scheduler.go:229] [OnAddPod] Adicionando pod default/test-deployment2-7b58dbd49-w52nk com os seguintes detalhes:
I0129 14:08:29.617106       1 types.go:743] [ControllerName] Verificando as anotações do pod default/test-deployment2-7b58dbd49-w52nk
I0129 14:08:29.617447       1 types.go:761] [ControllerName] Anotação 'controller' encontrada para o pod default/test-deployment2-7b58dbd49-w52nk: test-controller2
I0129 14:08:29.617512       1 scheduler.go:238] [OnAddPod] Atualizando métricas para o pod default/test-deployment2-7b58dbd49-w52nk
I0129 14:08:29.617519       1 types.go:743] [ControllerName] Verificando as anotações do pod default/test-deployment2-7b58dbd49-w52nk
I0129 14:08:29.617523       1 types.go:761] [ControllerName] Anotação 'controller' encontrada para o pod default/test-deployment2-7b58dbd49-w52nk: test-controller2
I0129 14:08:29.617537       1 scheduler.go:251] [OnAddPod] Pod default/test-deployment2-7b58dbd49-w52nk adicionado com sucesso
I0129 14:08:29.625471       1 postFilter.go:29] [PostFilter] PostFilter chamado para pod: default/test-deployment2-7b58dbd49-w52nk
I0129 14:08:29.625530       1 postFilter.go:76] [Preempt] Comparando pod original com o atualizado...
I0129 14:08:29.625538       1 postFilter.go:83] [Preempt] Successfully retrieved updated pod default/test-deployment2-7b58dbd49-w52nk from lister
I0129 14:08:29.652839       1 postFilter.go:233] [compareNodeResources] Recursos calculados no nó minikube: CPU = 750 mCPU, Memória = 178257920 bytes
I0129 14:08:29.652888       1 postFilter.go:234] [compareNodeResources] Recursos do snapshot no nó minikube: CPU = 750 mCPU, Memória = 178257920 bytes
I0129 14:08:29.652895       1 postFilter.go:240] [compareNodeResources] Recursos de CPU do nó minikube estão sincronizados: 750 mCPU
I0129 14:08:29.652901       1 postFilter.go:246] [compareNodeResources] Recursos de memória do nó minikube estão sincronizados: 178257920 bytes
I0129 14:08:29.653378       1 postFilter.go:147] [PREEMPT CALL] The node minikube  was chosen to allocate pod test-deployment2-7b58dbd49-w52nk
I0129 14:08:29.653395       1 postFilter.go:151] [Preempt] Iniciando a remoção dos pods preemptados no nó minikube para alocar o pod default/test-deployment2-7b58dbd49-w52nk. Total de vítimas: 0
I0129 14:08:29.653410       1 postFilter.go:179] [Preempt] Total de pods preemptados no nó minikube: 0
I0129 14:08:29.653466       1 scheduler.go:84] [HigherPrecedence] Calculando precedência entre test-deployment2-7b58dbd49-w52nk e test-deployment3-84f8ccf757-zb4jq
I0129 14:08:29.653472       1 scheduler.go:117] [WaitForPodsOnCache] Verificando se o pod test-deployment2-7b58dbd49-w52nk está no cache...
I0129 14:08:29.653478       1 scheduler.go:606] [GetControllerMetricInfo] Iniciando para o pod: default/test-deployment2-7b58dbd49-w52nk
I0129 14:08:29.653483       1 scheduler.go:611] [GetControllerMetricInfo] Obtendo o nome do controlador para o pod: default/test-deployment2-7b58dbd49-w52nk
I0129 14:08:29.653490       1 types.go:743] [ControllerName] Verificando as anotações do pod default/test-deployment2-7b58dbd49-w52nk
I0129 14:08:29.653495       1 types.go:761] [ControllerName] Anotação 'controller' encontrada para o pod default/test-deployment2-7b58dbd49-w52nk: test-controller2
I0129 14:08:29.653501       1 scheduler.go:614] [GetControllerMetricInfo] Métricas do controlador definidas para o pod: default/test-deployment2-7b58dbd49-w52nk
I0129 14:08:29.688347       1 scheduler.go:70] Estado no Informer: map[acceptablePreemptionOverhead:10 controller:test-controller2 qosMeasuring:average]
I0129 14:08:29.688598       1 scheduler.go:71] Estado real no cluster: map[acceptablePreemptionOverhead:10 controller:test-controller2 qosMeasuring:average]
I0129 14:08:29.688623       1 scheduler.go:139] [WaitForPodsOnCache] Pod test-deployment2-7b58dbd49-w52nk encontrado no cache.
I0129 14:08:29.688640       1 scheduler.go:117] [WaitForPodsOnCache] Verificando se o pod test-deployment3-84f8ccf757-zb4jq está no cache...
I0129 14:08:29.690005       1 scheduler.go:606] [GetControllerMetricInfo] Iniciando para o pod: default/test-deployment3-84f8ccf757-zb4jq
I0129 14:08:29.690026       1 scheduler.go:611] [GetControllerMetricInfo] Obtendo o nome do controlador para o pod: default/test-deployment3-84f8ccf757-zb4jq
I0129 14:08:29.690080       1 types.go:743] [ControllerName] Verificando as anotações do pod default/test-deployment3-84f8ccf757-zb4jq
I0129 14:08:29.690099       1 types.go:761] [ControllerName] Anotação 'controller' encontrada para o pod default/test-deployment3-84f8ccf757-zb4jq: test-controller3
I0129 14:08:29.690183       1 scheduler.go:614] [GetControllerMetricInfo] Métricas do controlador definidas para o pod: default/test-deployment3-84f8ccf757-zb4jq
I0129 14:08:29.962775       1 scheduler.go:70] Estado no Informer: map[acceptablePreemptionOverhead:10 controller:test-controller3 qosMeasuring:average]
I0129 14:08:29.963022       1 scheduler.go:71] Estado real no cluster: map[acceptablePreemptionOverhead:10 controller:test-controller3 qosMeasuring:average]
I0129 14:08:29.963248       1 scheduler.go:139] [WaitForPodsOnCache] Pod test-deployment3-84f8ccf757-zb4jq encontrado no cache.
I0129 14:08:29.969730       1 scheduler.go:606] [GetControllerMetricInfo] Iniciando para o pod: default/test-deployment2-7b58dbd49-w52nk
I0129 14:08:29.969835       1 scheduler.go:611] [GetControllerMetricInfo] Obtendo o nome do controlador para o pod: default/test-deployment2-7b58dbd49-w52nk
I0129 14:08:29.969857       1 types.go:743] [ControllerName] Verificando as anotações do pod default/test-deployment2-7b58dbd49-w52nk
I0129 14:08:29.969867       1 types.go:761] [ControllerName] Anotação 'controller' encontrada para o pod default/test-deployment2-7b58dbd49-w52nk: test-controller2
I0129 14:08:29.969873       1 scheduler.go:614] [GetControllerMetricInfo] Métricas do controlador definidas para o pod: default/test-deployment2-7b58dbd49-w52nk
I0129 14:08:29.969881       1 scheduler.go:606] [GetControllerMetricInfo] Iniciando para o pod: default/test-deployment3-84f8ccf757-zb4jq
I0129 14:08:29.969889       1 scheduler.go:611] [GetControllerMetricInfo] Obtendo o nome do controlador para o pod: default/test-deployment3-84f8ccf757-zb4jq
I0129 14:08:29.969913       1 types.go:743] [ControllerName] Verificando as anotações do pod default/test-deployment3-84f8ccf757-zb4jq
I0129 14:08:29.969913       1 types.go:761] [ControllerName] Anotação 'controller' encontrada para o pod default/test-deployment3-84f8ccf757-zb4jq: test-controller3
I0129 14:08:29.969950       1 scheduler.go:614] [GetControllerMetricInfo] Métricas do controlador definidas para o pod: default/test-deployment3-84f8ccf757-zb4jq
I0129 14:08:29.969962       1 scheduler.go:98] [HigherPrecedence] Métricas para test-deployment2-7b58dbd49-w52nk: QoS = -156.242420, Importância = 0.80
I0129 14:08:29.969984       1 scheduler.go:99] [HigherPrecedence] Métricas para test-deployment3-84f8ccf757-zb4jq: QoS = -182.867479, Importância = 0.80
I0129 14:08:29.969988       1 scheduler.go:110] [HigherPrecedence] Decisão final: test-deployment2-7b58dbd49-w52nk tem precedência sobre test-deployment3-84f8ccf757-zb4jq? false
I0129 14:08:29.970014       1 postFilter.go:186] [Preempt] Verificando pods de menor precedência no nó minikube que precisam ter o campo NominatedNodeName limpo
I0129 14:08:29.970044       1 postFilter.go:196] [Preempt] Finalizado para o nó minikube. Pod default/test-deployment2-7b58dbd49-w52nk deve ser alocado agora.
I0129 14:08:29.970045       1 postFilter.go:49] [PostFilter] Nó nominado para o pod default/test-deployment2-7b58dbd49-w52nk: minikube
I0129 14:08:30.203899       1 scheduler.go:258] [OnUpdatePod] Iniciando processamento de atualização de pod
I0129 14:08:30.208317       1 scheduler.go:262] [OnUpdatePod] Pod atualizado detectado: default/test-deployment2-7b58dbd49-w52nk, Anotações: map[acceptablePreemptionOverhead:10 controller:test-controller2 qosMeasuring:average]
I0129 14:08:30.209271       1 scheduler.go:265] [OnUpdatePod] Comparando estado no Informer e estado real no cluster para o pod default/test-deployment2-7b58dbd49-w52nk
I0129 14:08:30.262435       1 scheduler.go:70] Estado no Informer: map[acceptablePreemptionOverhead:10 controller:test-controller2 qosMeasuring:average]
I0129 14:08:30.262791       1 scheduler.go:71] Estado real no cluster: map[acceptablePreemptionOverhead:10 controller:test-controller2 qosMeasuring:average]
I0129 14:08:30.262941       1 scheduler.go:275] [OnUpdatePod] Atualizando informações de métricas para o pod default/test-deployment2-7b58dbd49-w52nk
I0129 14:08:30.263070       1 types.go:743] [ControllerName] Verificando as anotações do pod default/test-deployment2-7b58dbd49-w52nk
I0129 14:08:30.263228       1 types.go:761] [ControllerName] Anotação 'controller' encontrada para o pod default/test-deployment2-7b58dbd49-w52nk: test-controller2
I0129 14:08:30.263360       1 scheduler.go:277] [OnUpdatePod] Atualizando 'LastStatus' do pod default/test-deployment2-7b58dbd49-w52nk nas métricas
I0129 14:08:30.264446       1 scheduler.go:279] [OnUpdatePod] Métrica atualizada para o pod default/test-deployment2-7b58dbd49-w52nk
I0129 14:08:30.264598       1 scheduler.go:283] [OnUpdatePod] Finalizando processamento de atualização de pod para default/test-deployment2-7b58dbd49-w52nk
I0129 14:08:36.792581       1 postFilter.go:29] [PostFilter] PostFilter chamado para pod: default/test-deployment3-84f8ccf757-zb4jq
I0129 14:08:36.801438       1 postFilter.go:76] [Preempt] Comparando pod original com o atualizado...
I0129 14:08:36.801497       1 postFilter.go:83] [Preempt] Successfully retrieved updated pod default/test-deployment3-84f8ccf757-zb4jq from lister
I0129 14:08:36.824934       1 postFilter.go:233] [compareNodeResources] Recursos calculados no nó minikube: CPU = 750 mCPU, Memória = 178257920 bytes
I0129 14:08:36.825008       1 postFilter.go:234] [compareNodeResources] Recursos do snapshot no nó minikube: CPU = 750 mCPU, Memória = 178257920 bytes
I0129 14:08:36.825035       1 postFilter.go:240] [compareNodeResources] Recursos de CPU do nó minikube estão sincronizados: 750 mCPU
I0129 14:08:36.825049       1 postFilter.go:246] [compareNodeResources] Recursos de memória do nó minikube estão sincronizados: 178257920 bytes
I0129 14:08:36.828454       1 postFilter.go:147] [PREEMPT CALL] The node minikube  was chosen to allocate pod test-deployment3-84f8ccf757-zb4jq
I0129 14:08:36.828484       1 postFilter.go:151] [Preempt] Iniciando a remoção dos pods preemptados no nó minikube para alocar o pod default/test-deployment3-84f8ccf757-zb4jq. Total de vítimas: 0
I0129 14:08:36.828506       1 postFilter.go:179] [Preempt] Total de pods preemptados no nó minikube: 0
W0129 14:08:36.828589       1 scheduler.go:79] [HigherPrecedence] Tentativa de comparar o pod test-deployment3-84f8ccf757-zb4jq consigo mesmo. Retornando false.
I0129 14:08:36.828598       1 scheduler.go:84] [HigherPrecedence] Calculando precedência entre test-deployment3-84f8ccf757-zb4jq e test-deployment2-7b58dbd49-w52nk
I0129 14:08:36.828606       1 scheduler.go:117] [WaitForPodsOnCache] Verificando se o pod test-deployment3-84f8ccf757-zb4jq está no cache...
I0129 14:08:36.828614       1 scheduler.go:606] [GetControllerMetricInfo] Iniciando para o pod: default/test-deployment3-84f8ccf757-zb4jq
I0129 14:08:36.828623       1 scheduler.go:611] [GetControllerMetricInfo] Obtendo o nome do controlador para o pod: default/test-deployment3-84f8ccf757-zb4jq
I0129 14:08:36.828655       1 types.go:743] [ControllerName] Verificando as anotações do pod default/test-deployment3-84f8ccf757-zb4jq
I0129 14:08:36.828664       1 types.go:761] [ControllerName] Anotação 'controller' encontrada para o pod default/test-deployment3-84f8ccf757-zb4jq: test-controller3
I0129 14:08:36.828761       1 scheduler.go:614] [GetControllerMetricInfo] Métricas do controlador definidas para o pod: default/test-deployment3-84f8ccf757-zb4jq
I0129 14:08:36.835481       1 scheduler.go:70] Estado no Informer: map[acceptablePreemptionOverhead:10 controller:test-controller3 qosMeasuring:average]
I0129 14:08:36.835519       1 scheduler.go:71] Estado real no cluster: map[acceptablePreemptionOverhead:10 controller:test-controller3 qosMeasuring:average]
I0129 14:08:36.835557       1 scheduler.go:139] [WaitForPodsOnCache] Pod test-deployment3-84f8ccf757-zb4jq encontrado no cache.
I0129 14:08:36.835566       1 scheduler.go:117] [WaitForPodsOnCache] Verificando se o pod test-deployment2-7b58dbd49-w52nk está no cache...
I0129 14:08:36.835575       1 scheduler.go:606] [GetControllerMetricInfo] Iniciando para o pod: default/test-deployment2-7b58dbd49-w52nk
I0129 14:08:36.835583       1 scheduler.go:611] [GetControllerMetricInfo] Obtendo o nome do controlador para o pod: default/test-deployment2-7b58dbd49-w52nk
I0129 14:08:36.835591       1 types.go:743] [ControllerName] Verificando as anotações do pod default/test-deployment2-7b58dbd49-w52nk
I0129 14:08:36.835602       1 types.go:761] [ControllerName] Anotação 'controller' encontrada para o pod default/test-deployment2-7b58dbd49-w52nk: test-controller2
I0129 14:08:36.835612       1 scheduler.go:614] [GetControllerMetricInfo] Métricas do controlador definidas para o pod: default/test-deployment2-7b58dbd49-w52nk
I0129 14:08:36.845427       1 scheduler.go:70] Estado no Informer: map[acceptablePreemptionOverhead:10 controller:test-controller2 qosMeasuring:average]
I0129 14:08:36.846251       1 scheduler.go:71] Estado real no cluster: map[acceptablePreemptionOverhead:10 controller:test-controller2 qosMeasuring:average]
I0129 14:08:36.846323       1 scheduler.go:139] [WaitForPodsOnCache] Pod test-deployment2-7b58dbd49-w52nk encontrado no cache.
I0129 14:08:36.846334       1 scheduler.go:606] [GetControllerMetricInfo] Iniciando para o pod: default/test-deployment3-84f8ccf757-zb4jq
I0129 14:08:36.846346       1 scheduler.go:611] [GetControllerMetricInfo] Obtendo o nome do controlador para o pod: default/test-deployment3-84f8ccf757-zb4jq
I0129 14:08:36.846354       1 types.go:743] [ControllerName] Verificando as anotações do pod default/test-deployment3-84f8ccf757-zb4jq
I0129 14:08:36.846363       1 types.go:761] [ControllerName] Anotação 'controller' encontrada para o pod default/test-deployment3-84f8ccf757-zb4jq: test-controller3
I0129 14:08:36.846373       1 scheduler.go:614] [GetControllerMetricInfo] Métricas do controlador definidas para o pod: default/test-deployment3-84f8ccf757-zb4jq
I0129 14:08:36.846385       1 scheduler.go:606] [GetControllerMetricInfo] Iniciando para o pod: default/test-deployment2-7b58dbd49-w52nk
I0129 14:08:36.846393       1 scheduler.go:611] [GetControllerMetricInfo] Obtendo o nome do controlador para o pod: default/test-deployment2-7b58dbd49-w52nk
I0129 14:08:36.846399       1 types.go:743] [ControllerName] Verificando as anotações do pod default/test-deployment2-7b58dbd49-w52nk
I0129 14:08:36.846407       1 types.go:761] [ControllerName] Anotação 'controller' encontrada para o pod default/test-deployment2-7b58dbd49-w52nk: test-controller2
I0129 14:08:36.846416       1 scheduler.go:614] [GetControllerMetricInfo] Métricas do controlador definidas para o pod: default/test-deployment2-7b58dbd49-w52nk
I0129 14:08:36.846435       1 scheduler.go:98] [HigherPrecedence] Métricas para test-deployment3-84f8ccf757-zb4jq: QoS = -190.042612, Importância = 0.80
I0129 14:08:36.847354       1 scheduler.go:99] [HigherPrecedence] Métricas para test-deployment2-7b58dbd49-w52nk: QoS = -163.417553, Importância = 0.80
I0129 14:08:36.847411       1 scheduler.go:110] [HigherPrecedence] Decisão final: test-deployment3-84f8ccf757-zb4jq tem precedência sobre test-deployment2-7b58dbd49-w52nk? true
I0129 14:08:36.847435       1 postFilter.go:186] [Preempt] Verificando pods de menor precedência no nó minikube que precisam ter o campo NominatedNodeName limpo
I0129 14:08:36.847453       1 postFilter.go:188] [Preempt] Limpando o campo NominatedNodeName do pod default/test-deployment2-7b58dbd49-w52nk
I0129 14:08:37.013238       1 postFilter.go:196] [Preempt] Finalizado para o nó minikube. Pod default/test-deployment3-84f8ccf757-zb4jq deve ser alocado agora.
I0129 14:08:37.016406       1 postFilter.go:49] [PostFilter] Nó nominado para o pod default/test-deployment3-84f8ccf757-zb4jq: minikube
I0129 14:08:37.024433       1 scheduler.go:258] [OnUpdatePod] Iniciando processamento de atualização de pod
I0129 14:08:37.042283       1 scheduler.go:262] [OnUpdatePod] Pod atualizado detectado: default/test-deployment2-7b58dbd49-w52nk, Anotações: map[acceptablePreemptionOverhead:10 controller:test-controller2 qosMeasuring:average]
I0129 14:08:37.042397       1 scheduler.go:265] [OnUpdatePod] Comparando estado no Informer e estado real no cluster para o pod default/test-deployment2-7b58dbd49-w52nk
I0129 14:08:37.059725       1 scheduler.go:70] Estado no Informer: map[acceptablePreemptionOverhead:10 controller:test-controller2 qosMeasuring:average]
I0129 14:08:37.059766       1 scheduler.go:71] Estado real no cluster: map[acceptablePreemptionOverhead:10 controller:test-controller2 qosMeasuring:average]
I0129 14:08:37.059782       1 scheduler.go:275] [OnUpdatePod] Atualizando informações de métricas para o pod default/test-deployment2-7b58dbd49-w52nk
I0129 14:08:37.059793       1 types.go:743] [ControllerName] Verificando as anotações do pod default/test-deployment2-7b58dbd49-w52nk
I0129 14:08:37.059802       1 types.go:761] [ControllerName] Anotação 'controller' encontrada para o pod default/test-deployment2-7b58dbd49-w52nk: test-controller2
I0129 14:08:37.059815       1 scheduler.go:277] [OnUpdatePod] Atualizando 'LastStatus' do pod default/test-deployment2-7b58dbd49-w52nk nas métricas
I0129 14:08:37.059822       1 scheduler.go:279] [OnUpdatePod] Métrica atualizada para o pod default/test-deployment2-7b58dbd49-w52nk
I0129 14:08:37.059836       1 scheduler.go:283] [OnUpdatePod] Finalizando processamento de atualização de pod para default/test-deployment2-7b58dbd49-w52nk
I0129 14:08:58.616433       1 scheduler.go:54] [QueueSort] Comparando prioridade de test-deployment3-84f8ccf757-zb4jq com test-deployment2-7b58dbd49-w52nk
I0129 14:08:58.616761       1 scheduler.go:84] [HigherPrecedence] Calculando precedência entre test-deployment3-84f8ccf757-zb4jq e test-deployment2-7b58dbd49-w52nk
I0129 14:08:58.617419       1 scheduler.go:117] [WaitForPodsOnCache] Verificando se o pod test-deployment3-84f8ccf757-zb4jq está no cache...
I0129 14:08:58.617918       1 scheduler.go:606] [GetControllerMetricInfo] Iniciando para o pod: default/test-deployment3-84f8ccf757-zb4jq
I0129 14:08:58.618468       1 scheduler.go:611] [GetControllerMetricInfo] Obtendo o nome do controlador para o pod: default/test-deployment3-84f8ccf757-zb4jq
I0129 14:08:58.635318       1 types.go:743] [ControllerName] Verificando as anotações do pod default/test-deployment3-84f8ccf757-zb4jq
I0129 14:08:58.635454       1 types.go:761] [ControllerName] Anotação 'controller' encontrada para o pod default/test-deployment3-84f8ccf757-zb4jq: test-controller3
I0129 14:08:58.635479       1 scheduler.go:614] [GetControllerMetricInfo] Métricas do controlador definidas para o pod: default/test-deployment3-84f8ccf757-zb4jq
I0129 14:08:58.656680       1 scheduler.go:70] Estado no Informer: map[acceptablePreemptionOverhead:10 controller:test-controller3 qosMeasuring:average]
I0129 14:08:58.657301       1 scheduler.go:71] Estado real no cluster: map[acceptablePreemptionOverhead:10 controller:test-controller3 qosMeasuring:average]
I0129 14:08:58.664592       1 scheduler.go:139] [WaitForPodsOnCache] Pod test-deployment3-84f8ccf757-zb4jq encontrado no cache.
I0129 14:08:58.664627       1 scheduler.go:117] [WaitForPodsOnCache] Verificando se o pod test-deployment2-7b58dbd49-w52nk está no cache...
I0129 14:08:58.664642       1 scheduler.go:606] [GetControllerMetricInfo] Iniciando para o pod: default/test-deployment2-7b58dbd49-w52nk
I0129 14:08:58.668334       1 scheduler.go:611] [GetControllerMetricInfo] Obtendo o nome do controlador para o pod: default/test-deployment2-7b58dbd49-w52nk
I0129 14:08:58.668366       1 types.go:743] [ControllerName] Verificando as anotações do pod default/test-deployment2-7b58dbd49-w52nk
I0129 14:08:58.668381       1 types.go:761] [ControllerName] Anotação 'controller' encontrada para o pod default/test-deployment2-7b58dbd49-w52nk: test-controller2
I0129 14:08:58.668394       1 scheduler.go:614] [GetControllerMetricInfo] Métricas do controlador definidas para o pod: default/test-deployment2-7b58dbd49-w52nk
I0129 14:08:58.682382       1 scheduler.go:70] Estado no Informer: map[acceptablePreemptionOverhead:10 controller:test-controller2 qosMeasuring:average]
I0129 14:08:58.682490       1 scheduler.go:71] Estado real no cluster: map[acceptablePreemptionOverhead:10 controller:test-controller2 qosMeasuring:average]
I0129 14:08:58.682524       1 scheduler.go:139] [WaitForPodsOnCache] Pod test-deployment2-7b58dbd49-w52nk encontrado no cache.
I0129 14:08:58.682538       1 scheduler.go:606] [GetControllerMetricInfo] Iniciando para o pod: default/test-deployment3-84f8ccf757-zb4jq
I0129 14:08:58.682553       1 scheduler.go:611] [GetControllerMetricInfo] Obtendo o nome do controlador para o pod: default/test-deployment3-84f8ccf757-zb4jq
I0129 14:08:58.682572       1 types.go:743] [ControllerName] Verificando as anotações do pod default/test-deployment3-84f8ccf757-zb4jq
I0129 14:08:58.682584       1 types.go:761] [ControllerName] Anotação 'controller' encontrada para o pod default/test-deployment3-84f8ccf757-zb4jq: test-controller3
I0129 14:08:58.682598       1 scheduler.go:614] [GetControllerMetricInfo] Métricas do controlador definidas para o pod: default/test-deployment3-84f8ccf757-zb4jq
I0129 14:08:58.682713       1 scheduler.go:606] [GetControllerMetricInfo] Iniciando para o pod: default/test-deployment2-7b58dbd49-w52nk
I0129 14:08:58.682835       1 scheduler.go:611] [GetControllerMetricInfo] Obtendo o nome do controlador para o pod: default/test-deployment2-7b58dbd49-w52nk
I0129 14:08:58.683286       1 types.go:743] [ControllerName] Verificando as anotações do pod default/test-deployment2-7b58dbd49-w52nk
I0129 14:08:58.683350       1 types.go:761] [ControllerName] Anotação 'controller' encontrada para o pod default/test-deployment2-7b58dbd49-w52nk: test-controller2
I0129 14:08:58.683366       1 scheduler.go:614] [GetControllerMetricInfo] Métricas do controlador definidas para o pod: default/test-deployment2-7b58dbd49-w52nk
I0129 14:08:58.683397       1 scheduler.go:98] [HigherPrecedence] Métricas para test-deployment3-84f8ccf757-zb4jq: QoS = -211.830733, Importância = 0.80
I0129 14:08:58.683418       1 scheduler.go:99] [HigherPrecedence] Métricas para test-deployment2-7b58dbd49-w52nk: QoS = -185.205674, Importância = 0.80
I0129 14:08:58.683436       1 scheduler.go:110] [HigherPrecedence] Decisão final: test-deployment3-84f8ccf757-zb4jq tem precedência sobre test-deployment2-7b58dbd49-w52nk? true
I0129 14:08:58.683453       1 scheduler.go:60] [QueueSort] Precedência determinada: test-deployment3-84f8ccf757-zb4jq tem precedência sobre test-deployment2-7b58dbd49-w52nk? true
I0129 14:08:58.684720       1 scheduler.go:146] [Reserve] resources reserved at node minikube for pod test-deployment3-84f8ccf757-zb4jq_default at 2025-01-29 14:08:58.684704987 +0000 UTC m=+511.788260537
I0129 14:08:58.684821       1 types.go:743] [ControllerName] Verificando as anotações do pod default/test-deployment3-84f8ccf757-zb4jq
I0129 14:08:58.684834       1 types.go:761] [ControllerName] Anotação 'controller' encontrada para o pod default/test-deployment3-84f8ccf757-zb4jq: test-controller3
I0129 14:08:58.684845       1 scheduler.go:148] [Reserve] Status de alocação atual para o pod test-deployment3-84f8ccf757-zb4jq_default: 
I0129 14:08:58.684854       1 scheduler.go:150] [Reserve] Status de alocação atualizado para o pod test-deployment3-84f8ccf757-zb4jq_default: allocating
I0129 14:08:58.685047       1 postFilter.go:29] [PostFilter] PostFilter chamado para pod: default/test-deployment2-7b58dbd49-w52nk
I0129 14:08:58.685071       1 postFilter.go:76] [Preempt] Comparando pod original com o atualizado...
I0129 14:08:58.685089       1 postFilter.go:83] [Preempt] Successfully retrieved updated pod default/test-deployment2-7b58dbd49-w52nk from lister
I0129 14:08:58.685512       1 scheduler.go:174] [PreBind] Validando o pod test-deployment3-84f8ccf757-zb4jq antes de vincular ao node minikube
I0129 14:08:58.698838       1 postFilter.go:233] [compareNodeResources] Recursos calculados no nó minikube: CPU = 1450 mCPU, Memória = 459276288 bytes
I0129 14:08:58.698906       1 postFilter.go:234] [compareNodeResources] Recursos do snapshot no nó minikube: CPU = 1450 mCPU, Memória = 459276288 bytes
I0129 14:08:58.698921       1 postFilter.go:240] [compareNodeResources] Recursos de CPU do nó minikube estão sincronizados: 1450 mCPU
I0129 14:08:58.699039       1 postFilter.go:246] [compareNodeResources] Recursos de memória do nó minikube estão sincronizados: 459276288 bytes
I0129 14:08:58.699706       1 scheduler.go:606] [GetControllerMetricInfo] Iniciando para o pod: default/test-deployment3-84f8ccf757-zb4jq
I0129 14:08:58.699760       1 scheduler.go:611] [GetControllerMetricInfo] Obtendo o nome do controlador para o pod: default/test-deployment3-84f8ccf757-zb4jq
I0129 14:08:58.699771       1 types.go:743] [ControllerName] Verificando as anotações do pod default/test-deployment3-84f8ccf757-zb4jq
I0129 14:08:58.699780       1 types.go:761] [ControllerName] Anotação 'controller' encontrada para o pod default/test-deployment3-84f8ccf757-zb4jq: test-controller3
I0129 14:08:58.699789       1 scheduler.go:614] [GetControllerMetricInfo] Métricas do controlador definidas para o pod: default/test-deployment3-84f8ccf757-zb4jq
I0129 14:08:58.699799       1 scheduler.go:84] [HigherPrecedence] Calculando precedência entre test-deployment2-7b58dbd49-w52nk e test-deployment3-84f8ccf757-zb4jq
I0129 14:08:58.699807       1 scheduler.go:117] [WaitForPodsOnCache] Verificando se o pod test-deployment2-7b58dbd49-w52nk está no cache...
I0129 14:08:58.699814       1 scheduler.go:606] [GetControllerMetricInfo] Iniciando para o pod: default/test-deployment2-7b58dbd49-w52nk
I0129 14:08:58.699822       1 scheduler.go:611] [GetControllerMetricInfo] Obtendo o nome do controlador para o pod: default/test-deployment2-7b58dbd49-w52nk
I0129 14:08:58.699828       1 types.go:743] [ControllerName] Verificando as anotações do pod default/test-deployment2-7b58dbd49-w52nk
I0129 14:08:58.699835       1 types.go:761] [ControllerName] Anotação 'controller' encontrada para o pod default/test-deployment2-7b58dbd49-w52nk: test-controller2
I0129 14:08:58.699844       1 scheduler.go:614] [GetControllerMetricInfo] Métricas do controlador definidas para o pod: default/test-deployment2-7b58dbd49-w52nk
I0129 14:08:58.709597       1 scheduler.go:70] Estado no Informer: map[acceptablePreemptionOverhead:10 controller:test-controller2 qosMeasuring:average]
I0129 14:08:58.709629       1 scheduler.go:71] Estado real no cluster: map[acceptablePreemptionOverhead:10 controller:test-controller2 qosMeasuring:average]
I0129 14:08:58.709638       1 scheduler.go:139] [WaitForPodsOnCache] Pod test-deployment2-7b58dbd49-w52nk encontrado no cache.
I0129 14:08:58.709644       1 scheduler.go:117] [WaitForPodsOnCache] Verificando se o pod test-deployment3-84f8ccf757-zb4jq está no cache...
I0129 14:08:58.709651       1 scheduler.go:606] [GetControllerMetricInfo] Iniciando para o pod: default/test-deployment3-84f8ccf757-zb4jq
I0129 14:08:58.709658       1 scheduler.go:611] [GetControllerMetricInfo] Obtendo o nome do controlador para o pod: default/test-deployment3-84f8ccf757-zb4jq
I0129 14:08:58.709665       1 types.go:743] [ControllerName] Verificando as anotações do pod default/test-deployment3-84f8ccf757-zb4jq
I0129 14:08:58.709672       1 types.go:761] [ControllerName] Anotação 'controller' encontrada para o pod default/test-deployment3-84f8ccf757-zb4jq: test-controller3
I0129 14:08:58.709680       1 scheduler.go:614] [GetControllerMetricInfo] Métricas do controlador definidas para o pod: default/test-deployment3-84f8ccf757-zb4jq
I0129 14:08:58.716271       1 scheduler.go:182] [PostBind] Chamado para pod test-deployment3-84f8ccf757-zb4jq
I0129 14:08:58.716292       1 scheduler.go:200] [PostBind] Pod test-deployment3-84f8ccf757-zb4jq - Início do binding: 2025-01-29 14:08:58.685520725 +0000 UTC m=+511.789076192, Fim do binding: 2025-01-29 14:08:58.716287547 +0000 UTC m=+511.819842656
I0129 14:08:58.716839       1 scheduler.go:258] [OnUpdatePod] Iniciando processamento de atualização de pod
I0129 14:08:58.716868       1 scheduler.go:262] [OnUpdatePod] Pod atualizado detectado: default/test-deployment3-84f8ccf757-zb4jq, Anotações: map[acceptablePreemptionOverhead:10 controller:test-controller3 qosMeasuring:average]
I0129 14:08:58.716883       1 scheduler.go:265] [OnUpdatePod] Comparando estado no Informer e estado real no cluster para o pod default/test-deployment3-84f8ccf757-zb4jq
I0129 14:08:58.735074       1 scheduler.go:70] Estado no Informer: map[acceptablePreemptionOverhead:10 controller:test-controller3 qosMeasuring:average]
I0129 14:08:58.735459       1 scheduler.go:71] Estado real no cluster: map[acceptablePreemptionOverhead:10 controller:test-controller3 qosMeasuring:average]
I0129 14:08:58.735532       1 scheduler.go:275] [OnUpdatePod] Atualizando informações de métricas para o pod default/test-deployment3-84f8ccf757-zb4jq
I0129 14:08:58.735866       1 scheduler.go:70] Estado no Informer: map[acceptablePreemptionOverhead:10 controller:test-controller3 qosMeasuring:average]
I0129 14:08:58.736100       1 scheduler.go:71] Estado real no cluster: map[acceptablePreemptionOverhead:10 controller:test-controller3 qosMeasuring:average]
I0129 14:08:58.736222       1 scheduler.go:139] [WaitForPodsOnCache] Pod test-deployment3-84f8ccf757-zb4jq encontrado no cache.
I0129 14:08:58.736247       1 scheduler.go:606] [GetControllerMetricInfo] Iniciando para o pod: default/test-deployment2-7b58dbd49-w52nk
I0129 14:08:58.736331       1 types.go:743] [ControllerName] Verificando as anotações do pod default/test-deployment3-84f8ccf757-zb4jq
I0129 14:08:58.736418       1 types.go:761] [ControllerName] Anotação 'controller' encontrada para o pod default/test-deployment3-84f8ccf757-zb4jq: test-controller3
I0129 14:08:58.736680       1 scheduler.go:207] [PostBind] Métricas atualizadas para o pod test-deployment3-84f8ccf757-zb4jq
I0129 14:08:58.737485       1 scheduler.go:611] [GetControllerMetricInfo] Obtendo o nome do controlador para o pod: default/test-deployment2-7b58dbd49-w52nk
I0129 14:08:58.737533       1 types.go:743] [ControllerName] Verificando as anotações do pod default/test-deployment2-7b58dbd49-w52nk
I0129 14:08:58.737543       1 types.go:761] [ControllerName] Anotação 'controller' encontrada para o pod default/test-deployment2-7b58dbd49-w52nk: test-controller2
I0129 14:08:58.737550       1 scheduler.go:614] [GetControllerMetricInfo] Métricas do controlador definidas para o pod: default/test-deployment2-7b58dbd49-w52nk
I0129 14:08:58.737563       1 scheduler.go:606] [GetControllerMetricInfo] Iniciando para o pod: default/test-deployment3-84f8ccf757-zb4jq
I0129 14:08:58.737569       1 scheduler.go:611] [GetControllerMetricInfo] Obtendo o nome do controlador para o pod: default/test-deployment3-84f8ccf757-zb4jq
I0129 14:08:58.737574       1 types.go:743] [ControllerName] Verificando as anotações do pod default/test-deployment3-84f8ccf757-zb4jq
I0129 14:08:58.737580       1 types.go:761] [ControllerName] Anotação 'controller' encontrada para o pod default/test-deployment3-84f8ccf757-zb4jq: test-controller3
I0129 14:08:58.737586       1 scheduler.go:614] [GetControllerMetricInfo] Métricas do controlador definidas para o pod: default/test-deployment3-84f8ccf757-zb4jq
I0129 14:08:58.737605       1 scheduler.go:98] [HigherPrecedence] Métricas para test-deployment2-7b58dbd49-w52nk: QoS = -185.288752, Importância = 0.80
I0129 14:08:58.737614       1 scheduler.go:99] [HigherPrecedence] Métricas para test-deployment3-84f8ccf757-zb4jq: QoS = -211.944684, Importância = 0.80
I0129 14:08:58.737623       1 scheduler.go:110] [HigherPrecedence] Decisão final: test-deployment2-7b58dbd49-w52nk tem precedência sobre test-deployment3-84f8ccf757-zb4jq? false
I0129 14:08:58.737689       1 postFilter.go:144] [PREEMPT CALL] No node was chosen to allocate pod test-deployment2-7b58dbd49-w52nk
W0129 14:08:58.737720       1 postFilter.go:45] [PostFilter] Nenhum nó nominado após a preempção para o pod: default/test-deployment2-7b58dbd49-w52nk
I0129 14:08:58.738732       1 types.go:743] [ControllerName] Verificando as anotações do pod default/test-deployment3-84f8ccf757-zb4jq
I0129 14:08:58.738782       1 types.go:761] [ControllerName] Anotação 'controller' encontrada para o pod default/test-deployment3-84f8ccf757-zb4jq: test-controller3
I0129 14:08:58.738792       1 scheduler.go:277] [OnUpdatePod] Atualizando 'LastStatus' do pod default/test-deployment3-84f8ccf757-zb4jq nas métricas
I0129 14:08:58.738797       1 scheduler.go:279] [OnUpdatePod] Métrica atualizada para o pod default/test-deployment3-84f8ccf757-zb4jq
I0129 14:08:58.738809       1 scheduler.go:283] [OnUpdatePod] Finalizando processamento de atualização de pod para default/test-deployment3-84f8ccf757-zb4jq
I0129 14:08:58.790762       1 scheduler.go:258] [OnUpdatePod] Iniciando processamento de atualização de pod
I0129 14:08:58.790889       1 scheduler.go:262] [OnUpdatePod] Pod atualizado detectado: default/test-deployment3-84f8ccf757-zb4jq, Anotações: map[acceptablePreemptionOverhead:10 controller:test-controller3 qosMeasuring:average]
I0129 14:08:58.790914       1 scheduler.go:265] [OnUpdatePod] Comparando estado no Informer e estado real no cluster para o pod default/test-deployment3-84f8ccf757-zb4jq
I0129 14:08:58.806535       1 scheduler.go:70] Estado no Informer: map[acceptablePreemptionOverhead:10 controller:test-controller3 qosMeasuring:average]
I0129 14:08:58.806605       1 scheduler.go:71] Estado real no cluster: map[acceptablePreemptionOverhead:10 controller:test-controller3 qosMeasuring:average]
I0129 14:08:58.806624       1 scheduler.go:275] [OnUpdatePod] Atualizando informações de métricas para o pod default/test-deployment3-84f8ccf757-zb4jq
I0129 14:08:58.806634       1 types.go:743] [ControllerName] Verificando as anotações do pod default/test-deployment3-84f8ccf757-zb4jq
I0129 14:08:58.806643       1 types.go:761] [ControllerName] Anotação 'controller' encontrada para o pod default/test-deployment3-84f8ccf757-zb4jq: test-controller3
I0129 14:08:58.806699       1 scheduler.go:277] [OnUpdatePod] Atualizando 'LastStatus' do pod default/test-deployment3-84f8ccf757-zb4jq nas métricas
I0129 14:08:58.806708       1 scheduler.go:279] [OnUpdatePod] Métrica atualizada para o pod default/test-deployment3-84f8ccf757-zb4jq
I0129 14:08:58.806721       1 scheduler.go:283] [OnUpdatePod] Finalizando processamento de atualização de pod para default/test-deployment3-84f8ccf757-zb4jq
I0129 14:09:00.812820       1 postFilter.go:29] [PostFilter] PostFilter chamado para pod: default/test-deployment2-7b58dbd49-w52nk
I0129 14:09:00.813054       1 postFilter.go:76] [Preempt] Comparando pod original com o atualizado...
I0129 14:09:00.813172       1 postFilter.go:83] [Preempt] Successfully retrieved updated pod default/test-deployment2-7b58dbd49-w52nk from lister
I0129 14:09:00.820649       1 postFilter.go:233] [compareNodeResources] Recursos calculados no nó minikube: CPU = 1450 mCPU, Memória = 459276288 bytes
I0129 14:09:00.820695       1 postFilter.go:234] [compareNodeResources] Recursos do snapshot no nó minikube: CPU = 1450 mCPU, Memória = 459276288 bytes
I0129 14:09:00.820704       1 postFilter.go:240] [compareNodeResources] Recursos de CPU do nó minikube estão sincronizados: 1450 mCPU
I0129 14:09:00.820711       1 postFilter.go:246] [compareNodeResources] Recursos de memória do nó minikube estão sincronizados: 459276288 bytes
I0129 14:09:00.820880       1 scheduler.go:606] [GetControllerMetricInfo] Iniciando para o pod: default/test-deployment3-84f8ccf757-zb4jq
I0129 14:09:00.820888       1 scheduler.go:611] [GetControllerMetricInfo] Obtendo o nome do controlador para o pod: default/test-deployment3-84f8ccf757-zb4jq
I0129 14:09:00.820895       1 types.go:743] [ControllerName] Verificando as anotações do pod default/test-deployment3-84f8ccf757-zb4jq
I0129 14:09:00.820902       1 types.go:761] [ControllerName] Anotação 'controller' encontrada para o pod default/test-deployment3-84f8ccf757-zb4jq: test-controller3
I0129 14:09:00.820910       1 scheduler.go:614] [GetControllerMetricInfo] Métricas do controlador definidas para o pod: default/test-deployment3-84f8ccf757-zb4jq
I0129 14:09:00.820934       1 scheduler.go:84] [HigherPrecedence] Calculando precedência entre test-deployment2-7b58dbd49-w52nk e test-deployment3-84f8ccf757-zb4jq
I0129 14:09:00.820941       1 scheduler.go:117] [WaitForPodsOnCache] Verificando se o pod test-deployment2-7b58dbd49-w52nk está no cache...
I0129 14:09:00.820946       1 scheduler.go:606] [GetControllerMetricInfo] Iniciando para o pod: default/test-deployment2-7b58dbd49-w52nk
I0129 14:09:00.820951       1 scheduler.go:611] [GetControllerMetricInfo] Obtendo o nome do controlador para o pod: default/test-deployment2-7b58dbd49-w52nk
I0129 14:09:00.820955       1 types.go:743] [ControllerName] Verificando as anotações do pod default/test-deployment2-7b58dbd49-w52nk
I0129 14:09:00.820964       1 types.go:761] [ControllerName] Anotação 'controller' encontrada para o pod default/test-deployment2-7b58dbd49-w52nk: test-controller2
I0129 14:09:00.820969       1 scheduler.go:614] [GetControllerMetricInfo] Métricas do controlador definidas para o pod: default/test-deployment2-7b58dbd49-w52nk
I0129 14:09:00.837549       1 scheduler.go:70] Estado no Informer: map[acceptablePreemptionOverhead:10 controller:test-controller2 qosMeasuring:average]
I0129 14:09:00.838367       1 scheduler.go:71] Estado real no cluster: map[acceptablePreemptionOverhead:10 controller:test-controller2 qosMeasuring:average]
I0129 14:09:00.839997       1 scheduler.go:139] [WaitForPodsOnCache] Pod test-deployment2-7b58dbd49-w52nk encontrado no cache.
I0129 14:09:00.840064       1 scheduler.go:117] [WaitForPodsOnCache] Verificando se o pod test-deployment3-84f8ccf757-zb4jq está no cache...
I0129 14:09:00.840073       1 scheduler.go:606] [GetControllerMetricInfo] Iniciando para o pod: default/test-deployment3-84f8ccf757-zb4jq
I0129 14:09:00.840080       1 scheduler.go:611] [GetControllerMetricInfo] Obtendo o nome do controlador para o pod: default/test-deployment3-84f8ccf757-zb4jq
I0129 14:09:00.840088       1 types.go:743] [ControllerName] Verificando as anotações do pod default/test-deployment3-84f8ccf757-zb4jq
I0129 14:09:00.840096       1 types.go:761] [ControllerName] Anotação 'controller' encontrada para o pod default/test-deployment3-84f8ccf757-zb4jq: test-controller3
I0129 14:09:00.840104       1 scheduler.go:614] [GetControllerMetricInfo] Métricas do controlador definidas para o pod: default/test-deployment3-84f8ccf757-zb4jq
I0129 14:09:00.849648       1 scheduler.go:70] Estado no Informer: map[acceptablePreemptionOverhead:10 controller:test-controller3 qosMeasuring:average]
I0129 14:09:00.849675       1 scheduler.go:71] Estado real no cluster: map[acceptablePreemptionOverhead:10 controller:test-controller3 qosMeasuring:average]
I0129 14:09:00.849688       1 scheduler.go:139] [WaitForPodsOnCache] Pod test-deployment3-84f8ccf757-zb4jq encontrado no cache.
I0129 14:09:00.849697       1 scheduler.go:606] [GetControllerMetricInfo] Iniciando para o pod: default/test-deployment2-7b58dbd49-w52nk
I0129 14:09:00.849703       1 scheduler.go:611] [GetControllerMetricInfo] Obtendo o nome do controlador para o pod: default/test-deployment2-7b58dbd49-w52nk
I0129 14:09:00.849711       1 types.go:743] [ControllerName] Verificando as anotações do pod default/test-deployment2-7b58dbd49-w52nk
I0129 14:09:00.849718       1 types.go:761] [ControllerName] Anotação 'controller' encontrada para o pod default/test-deployment2-7b58dbd49-w52nk: test-controller2
I0129 14:09:00.849726       1 scheduler.go:614] [GetControllerMetricInfo] Métricas do controlador definidas para o pod: default/test-deployment2-7b58dbd49-w52nk
I0129 14:09:00.849738       1 scheduler.go:606] [GetControllerMetricInfo] Iniciando para o pod: default/test-deployment3-84f8ccf757-zb4jq
I0129 14:09:00.849744       1 scheduler.go:611] [GetControllerMetricInfo] Obtendo o nome do controlador para o pod: default/test-deployment3-84f8ccf757-zb4jq
I0129 14:09:00.849748       1 types.go:743] [ControllerName] Verificando as anotações do pod default/test-deployment3-84f8ccf757-zb4jq
I0129 14:09:00.849754       1 types.go:761] [ControllerName] Anotação 'controller' encontrada para o pod default/test-deployment3-84f8ccf757-zb4jq: test-controller3
I0129 14:09:00.849759       1 scheduler.go:614] [GetControllerMetricInfo] Métricas do controlador definidas para o pod: default/test-deployment3-84f8ccf757-zb4jq
I0129 14:09:00.849774       1 scheduler.go:98] [HigherPrecedence] Métricas para test-deployment2-7b58dbd49-w52nk: QoS = -187.409872, Importância = 0.80
I0129 14:09:00.849785       1 scheduler.go:99] [HigherPrecedence] Métricas para test-deployment3-84f8ccf757-zb4jq: QoS = -211.414404, Importância = 0.80
I0129 14:09:00.849792       1 scheduler.go:110] [HigherPrecedence] Decisão final: test-deployment2-7b58dbd49-w52nk tem precedência sobre test-deployment3-84f8ccf757-zb4jq? false
I0129 14:09:00.849850       1 postFilter.go:144] [PREEMPT CALL] No node was chosen to allocate pod test-deployment2-7b58dbd49-w52nk
W0129 14:09:00.849856       1 postFilter.go:45] [PostFilter] Nenhum nó nominado após a preempção para o pod: default/test-deployment2-7b58dbd49-w52nk
I0129 14:09:10.392359       1 scheduler.go:258] [OnUpdatePod] Iniciando processamento de atualização de pod
I0129 14:09:10.401273       1 scheduler.go:262] [OnUpdatePod] Pod atualizado detectado: default/test-deployment3-84f8ccf757-zb4jq, Anotações: map[acceptablePreemptionOverhead:10 controller:test-controller3 qosMeasuring:average]
I0129 14:09:10.402487       1 scheduler.go:265] [OnUpdatePod] Comparando estado no Informer e estado real no cluster para o pod default/test-deployment3-84f8ccf757-zb4jq
I0129 14:09:10.541801       1 scheduler.go:70] Estado no Informer: map[acceptablePreemptionOverhead:10 controller:test-controller3 qosMeasuring:average]
I0129 14:09:10.545898       1 scheduler.go:71] Estado real no cluster: map[acceptablePreemptionOverhead:10 controller:test-controller3 qosMeasuring:average]
I0129 14:09:10.546534       1 scheduler.go:275] [OnUpdatePod] Atualizando informações de métricas para o pod default/test-deployment3-84f8ccf757-zb4jq
I0129 14:09:10.547076       1 types.go:743] [ControllerName] Verificando as anotações do pod default/test-deployment3-84f8ccf757-zb4jq
I0129 14:09:10.547547       1 types.go:761] [ControllerName] Anotação 'controller' encontrada para o pod default/test-deployment3-84f8ccf757-zb4jq: test-controller3
I0129 14:09:10.547857       1 scheduler.go:277] [OnUpdatePod] Atualizando 'LastStatus' do pod default/test-deployment3-84f8ccf757-zb4jq nas métricas
I0129 14:09:10.548482       1 scheduler.go:279] [OnUpdatePod] Métrica atualizada para o pod default/test-deployment3-84f8ccf757-zb4jq
I0129 14:09:10.548742       1 scheduler.go:283] [OnUpdatePod] Finalizando processamento de atualização de pod para default/test-deployment3-84f8ccf757-zb4jq
I0129 14:09:28.685866       1 postFilter.go:29] [PostFilter] PostFilter chamado para pod: default/test-deployment2-7b58dbd49-w52nk
I0129 14:09:28.685959       1 postFilter.go:76] [Preempt] Comparando pod original com o atualizado...
I0129 14:09:28.685999       1 postFilter.go:83] [Preempt] Successfully retrieved updated pod default/test-deployment2-7b58dbd49-w52nk from lister
I0129 14:09:28.706008       1 postFilter.go:233] [compareNodeResources] Recursos calculados no nó minikube: CPU = 1450 mCPU, Memória = 459276288 bytes
I0129 14:09:28.706447       1 postFilter.go:234] [compareNodeResources] Recursos do snapshot no nó minikube: CPU = 1450 mCPU, Memória = 459276288 bytes
I0129 14:09:28.707332       1 postFilter.go:240] [compareNodeResources] Recursos de CPU do nó minikube estão sincronizados: 1450 mCPU
I0129 14:09:28.711277       1 postFilter.go:246] [compareNodeResources] Recursos de memória do nó minikube estão sincronizados: 459276288 bytes
I0129 14:09:28.711968       1 scheduler.go:606] [GetControllerMetricInfo] Iniciando para o pod: default/test-deployment3-84f8ccf757-zb4jq
I0129 14:09:28.712061       1 scheduler.go:611] [GetControllerMetricInfo] Obtendo o nome do controlador para o pod: default/test-deployment3-84f8ccf757-zb4jq
I0129 14:09:28.712085       1 types.go:743] [ControllerName] Verificando as anotações do pod default/test-deployment3-84f8ccf757-zb4jq
I0129 14:09:28.712106       1 types.go:761] [ControllerName] Anotação 'controller' encontrada para o pod default/test-deployment3-84f8ccf757-zb4jq: test-controller3
I0129 14:09:28.712236       1 scheduler.go:614] [GetControllerMetricInfo] Métricas do controlador definidas para o pod: default/test-deployment3-84f8ccf757-zb4jq
I0129 14:09:28.712259       1 scheduler.go:84] [HigherPrecedence] Calculando precedência entre test-deployment2-7b58dbd49-w52nk e test-deployment3-84f8ccf757-zb4jq
I0129 14:09:28.712272       1 scheduler.go:117] [WaitForPodsOnCache] Verificando se o pod test-deployment2-7b58dbd49-w52nk está no cache...
I0129 14:09:28.712307       1 scheduler.go:606] [GetControllerMetricInfo] Iniciando para o pod: default/test-deployment2-7b58dbd49-w52nk
I0129 14:09:28.712319       1 scheduler.go:611] [GetControllerMetricInfo] Obtendo o nome do controlador para o pod: default/test-deployment2-7b58dbd49-w52nk
I0129 14:09:28.712394       1 types.go:743] [ControllerName] Verificando as anotações do pod default/test-deployment2-7b58dbd49-w52nk
I0129 14:09:28.712575       1 types.go:761] [ControllerName] Anotação 'controller' encontrada para o pod default/test-deployment2-7b58dbd49-w52nk: test-controller2
I0129 14:09:28.712611       1 scheduler.go:614] [GetControllerMetricInfo] Métricas do controlador definidas para o pod: default/test-deployment2-7b58dbd49-w52nk
I0129 14:09:28.720719       1 scheduler.go:70] Estado no Informer: map[acceptablePreemptionOverhead:10 controller:test-controller2 qosMeasuring:average]
I0129 14:09:28.720872       1 scheduler.go:71] Estado real no cluster: map[acceptablePreemptionOverhead:10 controller:test-controller2 qosMeasuring:average]
I0129 14:09:28.720893       1 scheduler.go:139] [WaitForPodsOnCache] Pod test-deployment2-7b58dbd49-w52nk encontrado no cache.
I0129 14:09:28.720903       1 scheduler.go:117] [WaitForPodsOnCache] Verificando se o pod test-deployment3-84f8ccf757-zb4jq está no cache...
I0129 14:09:28.721263       1 scheduler.go:606] [GetControllerMetricInfo] Iniciando para o pod: default/test-deployment3-84f8ccf757-zb4jq
I0129 14:09:28.721478       1 scheduler.go:611] [GetControllerMetricInfo] Obtendo o nome do controlador para o pod: default/test-deployment3-84f8ccf757-zb4jq
I0129 14:09:28.721615       1 types.go:743] [ControllerName] Verificando as anotações do pod default/test-deployment3-84f8ccf757-zb4jq
I0129 14:09:28.721629       1 types.go:761] [ControllerName] Anotação 'controller' encontrada para o pod default/test-deployment3-84f8ccf757-zb4jq: test-controller3
I0129 14:09:28.721642       1 scheduler.go:614] [GetControllerMetricInfo] Métricas do controlador definidas para o pod: default/test-deployment3-84f8ccf757-zb4jq
I0129 14:09:28.735651       1 scheduler.go:70] Estado no Informer: map[acceptablePreemptionOverhead:10 controller:test-controller3 qosMeasuring:average]
I0129 14:09:28.735733       1 scheduler.go:71] Estado real no cluster: map[acceptablePreemptionOverhead:10 controller:test-controller3 qosMeasuring:average]
I0129 14:09:28.735748       1 scheduler.go:139] [WaitForPodsOnCache] Pod test-deployment3-84f8ccf757-zb4jq encontrado no cache.
I0129 14:09:28.735759       1 scheduler.go:606] [GetControllerMetricInfo] Iniciando para o pod: default/test-deployment2-7b58dbd49-w52nk
I0129 14:09:28.735768       1 scheduler.go:611] [GetControllerMetricInfo] Obtendo o nome do controlador para o pod: default/test-deployment2-7b58dbd49-w52nk
I0129 14:09:28.735778       1 types.go:743] [ControllerName] Verificando as anotações do pod default/test-deployment2-7b58dbd49-w52nk
I0129 14:09:28.735788       1 types.go:761] [ControllerName] Anotação 'controller' encontrada para o pod default/test-deployment2-7b58dbd49-w52nk: test-controller2
I0129 14:09:28.735797       1 scheduler.go:614] [GetControllerMetricInfo] Métricas do controlador definidas para o pod: default/test-deployment2-7b58dbd49-w52nk
I0129 14:09:28.735812       1 scheduler.go:606] [GetControllerMetricInfo] Iniciando para o pod: default/test-deployment3-84f8ccf757-zb4jq
I0129 14:09:28.735827       1 scheduler.go:611] [GetControllerMetricInfo] Obtendo o nome do controlador para o pod: default/test-deployment3-84f8ccf757-zb4jq
I0129 14:09:28.735833       1 types.go:743] [ControllerName] Verificando as anotações do pod default/test-deployment3-84f8ccf757-zb4jq
I0129 14:09:28.735840       1 types.go:761] [ControllerName] Anotação 'controller' encontrada para o pod default/test-deployment3-84f8ccf757-zb4jq: test-controller3
I0129 14:09:28.735854       1 scheduler.go:614] [GetControllerMetricInfo] Métricas do controlador definidas para o pod: default/test-deployment3-84f8ccf757-zb4jq
I0129 14:09:28.735892       1 scheduler.go:98] [HigherPrecedence] Métricas para test-deployment2-7b58dbd49-w52nk: QoS = -215.301208, Importância = 0.80
I0129 14:09:28.735907       1 scheduler.go:99] [HigherPrecedence] Métricas para test-deployment3-84f8ccf757-zb4jq: QoS = -204.441570, Importância = 0.80
I0129 14:09:28.735919       1 scheduler.go:110] [HigherPrecedence] Decisão final: test-deployment2-7b58dbd49-w52nk tem precedência sobre test-deployment3-84f8ccf757-zb4jq? true
I0129 14:09:28.735930       1 types.go:743] [ControllerName] Verificando as anotações do pod default/test-deployment2-7b58dbd49-w52nk
I0129 14:09:28.735938       1 types.go:761] [ControllerName] Anotação 'controller' encontrada para o pod default/test-deployment2-7b58dbd49-w52nk: test-controller2
I0129 14:09:28.735944       1 types.go:743] [ControllerName] Verificando as anotações do pod default/test-deployment3-84f8ccf757-zb4jq
I0129 14:09:28.735952       1 types.go:761] [ControllerName] Anotação 'controller' encontrada para o pod default/test-deployment3-84f8ccf757-zb4jq: test-controller3
I0129 14:09:28.736000       1 scheduler.go:606] [GetControllerMetricInfo] Iniciando para o pod: default/test-deployment3-84f8ccf757-zb4jq
I0129 14:09:28.736043       1 scheduler.go:611] [GetControllerMetricInfo] Obtendo o nome do controlador para o pod: default/test-deployment3-84f8ccf757-zb4jq
I0129 14:09:28.736087       1 types.go:743] [ControllerName] Verificando as anotações do pod default/test-deployment3-84f8ccf757-zb4jq
I0129 14:09:28.736204       1 types.go:761] [ControllerName] Anotação 'controller' encontrada para o pod default/test-deployment3-84f8ccf757-zb4jq: test-controller3
I0129 14:09:28.736215       1 scheduler.go:614] [GetControllerMetricInfo] Métricas do controlador definidas para o pod: default/test-deployment3-84f8ccf757-zb4jq
I0129 14:09:28.736222       1 scheduler.go:606] [GetControllerMetricInfo] Iniciando para o pod: default/test-deployment3-84f8ccf757-zb4jq
I0129 14:09:28.736229       1 scheduler.go:611] [GetControllerMetricInfo] Obtendo o nome do controlador para o pod: default/test-deployment3-84f8ccf757-zb4jq
I0129 14:09:28.736236       1 types.go:743] [ControllerName] Verificando as anotações do pod default/test-deployment3-84f8ccf757-zb4jq
I0129 14:09:28.736244       1 types.go:761] [ControllerName] Anotação 'controller' encontrada para o pod default/test-deployment3-84f8ccf757-zb4jq: test-controller3
I0129 14:09:28.736252       1 scheduler.go:614] [GetControllerMetricInfo] Métricas do controlador definidas para o pod: default/test-deployment3-84f8ccf757-zb4jq
I0129 14:09:28.736261       1 types.go:743] [ControllerName] Verificando as anotações do pod default/test-deployment3-84f8ccf757-zb4jq
I0129 14:09:28.736303       1 types.go:761] [ControllerName] Anotação 'controller' encontrada para o pod default/test-deployment3-84f8ccf757-zb4jq: test-controller3
I0129 14:09:28.736474       1 scheduler.go:606] [GetControllerMetricInfo] Iniciando para o pod: default/test-deployment3-84f8ccf757-zb4jq
I0129 14:09:28.736520       1 scheduler.go:611] [GetControllerMetricInfo] Obtendo o nome do controlador para o pod: default/test-deployment3-84f8ccf757-zb4jq
I0129 14:09:28.736612       1 types.go:743] [ControllerName] Verificando as anotações do pod default/test-deployment3-84f8ccf757-zb4jq
I0129 14:09:28.736619       1 types.go:761] [ControllerName] Anotação 'controller' encontrada para o pod default/test-deployment3-84f8ccf757-zb4jq: test-controller3
I0129 14:09:28.736627       1 scheduler.go:614] [GetControllerMetricInfo] Métricas do controlador definidas para o pod: default/test-deployment3-84f8ccf757-zb4jq
I0129 14:09:28.736639       1 scheduler.go:606] [GetControllerMetricInfo] Iniciando para o pod: default/test-deployment3-84f8ccf757-zb4jq
I0129 14:09:28.736647       1 scheduler.go:611] [GetControllerMetricInfo] Obtendo o nome do controlador para o pod: default/test-deployment3-84f8ccf757-zb4jq
I0129 14:09:28.736653       1 types.go:743] [ControllerName] Verificando as anotações do pod default/test-deployment3-84f8ccf757-zb4jq
I0129 14:09:28.736660       1 types.go:761] [ControllerName] Anotação 'controller' encontrada para o pod default/test-deployment3-84f8ccf757-zb4jq: test-controller3
I0129 14:09:28.736667       1 scheduler.go:614] [GetControllerMetricInfo] Métricas do controlador definidas para o pod: default/test-deployment3-84f8ccf757-zb4jq
I0129 14:09:28.736723       1 postFilter.go:147] [PREEMPT CALL] The node minikube  was chosen to allocate pod test-deployment2-7b58dbd49-w52nk
I0129 14:09:28.736772       1 postFilter.go:151] [Preempt] Iniciando a remoção dos pods preemptados no nó minikube para alocar o pod default/test-deployment2-7b58dbd49-w52nk. Total de vítimas: 1
I0129 14:09:28.736825       1 postFilter.go:155] [Preempt] Tentando remover o pod default/test-deployment3-84f8ccf757-zb4jq no nó minikube
I0129 14:09:28.885889       1 scheduler.go:258] [OnUpdatePod] Iniciando processamento de atualização de pod
I0129 14:09:28.885989       1 scheduler.go:262] [OnUpdatePod] Pod atualizado detectado: default/test-deployment3-84f8ccf757-zb4jq, Anotações: map[acceptablePreemptionOverhead:10 controller:test-controller3 qosMeasuring:average]
I0129 14:09:28.886023       1 scheduler.go:265] [OnUpdatePod] Comparando estado no Informer e estado real no cluster para o pod default/test-deployment3-84f8ccf757-zb4jq
I0129 14:09:29.196314       1 scheduler.go:70] Estado no Informer: map[acceptablePreemptionOverhead:10 controller:test-controller3 qosMeasuring:average]
I0129 14:09:29.196374       1 scheduler.go:71] Estado real no cluster: map[acceptablePreemptionOverhead:10 controller:test-controller3 qosMeasuring:average]
I0129 14:09:29.196396       1 scheduler.go:275] [OnUpdatePod] Atualizando informações de métricas para o pod default/test-deployment3-84f8ccf757-zb4jq
I0129 14:09:29.196412       1 types.go:743] [ControllerName] Verificando as anotações do pod default/test-deployment3-84f8ccf757-zb4jq
I0129 14:09:29.196425       1 types.go:761] [ControllerName] Anotação 'controller' encontrada para o pod default/test-deployment3-84f8ccf757-zb4jq: test-controller3
I0129 14:09:29.196458       1 scheduler.go:277] [OnUpdatePod] Atualizando 'LastStatus' do pod default/test-deployment3-84f8ccf757-zb4jq nas métricas
I0129 14:09:29.196469       1 scheduler.go:279] [OnUpdatePod] Métrica atualizada para o pod default/test-deployment3-84f8ccf757-zb4jq
I0129 14:09:29.196496       1 scheduler.go:283] [OnUpdatePod] Finalizando processamento de atualização de pod para default/test-deployment3-84f8ccf757-zb4jq
I0129 14:09:29.196578       1 types.go:743] [ControllerName] Verificando as anotações do pod default/test-deployment3-84f8ccf757-zb4jq
I0129 14:09:29.196589       1 types.go:761] [ControllerName] Anotação 'controller' encontrada para o pod default/test-deployment3-84f8ccf757-zb4jq: test-controller3
I0129 14:09:29.197075       1 postFilter.go:168] [Preempt] Pod default/test-deployment3-84f8ccf757-zb4jq removido com sucesso no nó minikube
I0129 14:09:29.197107       1 postFilter.go:174] test-deployment3-84f8ccf757-zb4jq_default preempted by test-deployment2-7b58dbd49-w52nk_default on node minikube
I0129 14:09:29.197688       1 postFilter.go:179] [Preempt] Total de pods preemptados no nó minikube: 1
I0129 14:09:29.198032       1 postFilter.go:186] [Preempt] Verificando pods de menor precedência no nó minikube que precisam ter o campo NominatedNodeName limpo
I0129 14:09:29.208323       1 postFilter.go:196] [Preempt] Finalizado para o nó minikube. Pod default/test-deployment2-7b58dbd49-w52nk deve ser alocado agora.
I0129 14:09:29.215591       1 postFilter.go:49] [PostFilter] Nó nominado para o pod default/test-deployment2-7b58dbd49-w52nk: minikube
I0129 14:09:29.209079       1 scheduler.go:291] [OnDeletePod] Iniciando a execução do OnDeletePod
I0129 14:09:29.231470       1 scheduler.go:300] [OnDeletePod] DeepCopy realizado para o pod default/test-deployment3-84f8ccf757-zb4jq
I0129 14:09:29.240088       1 scheduler.go:307] [OnDeletePod] Pod deletado detectado: default/test-deployment3-84f8ccf757-zb4jq
I0129 14:09:29.240270       1 scheduler.go:309] [OnDeletePod] Atualizando métricas do pod default/test-deployment3-84f8ccf757-zb4jq
I0129 14:09:29.240400       1 types.go:743] [ControllerName] Verificando as anotações do pod default/test-deployment3-84f8ccf757-zb4jq
I0129 14:09:29.240431       1 types.go:761] [ControllerName] Anotação 'controller' encontrada para o pod default/test-deployment3-84f8ccf757-zb4jq: test-controller3
I0129 14:09:29.241314       1 scheduler.go:311] [OnDeletePod] Verificando o estado do pod default/test-deployment3-84f8ccf757-zb4jq nas métricas
I0129 14:09:29.241720       1 scheduler.go:321] [OnDeletePod] EndTime atualizado para o pod default/test-deployment3-84f8ccf757-zb4jq: 2025-01-29 14:09:29.24171003 +0000 UTC m=+542.345265128
I0129 14:09:29.241844       1 scheduler.go:325] [OnDeletePod] Finalizando a execução do OnDeletePod para o pod default/test-deployment3-84f8ccf757-zb4jq
I0129 14:09:29.249983       1 scheduler.go:218] [OnAddPod] Pod adicionado: default/test-deployment3-84f8ccf757-9grx4, Anotações: map[acceptablePreemptionOverhead:10 controller:test-controller3 qosMeasuring:average]
I0129 14:09:29.266938       1 scheduler.go:70] Estado no Informer: map[acceptablePreemptionOverhead:10 controller:test-controller3 qosMeasuring:average]
I0129 14:09:29.267034       1 scheduler.go:71] Estado real no cluster: map[acceptablePreemptionOverhead:10 controller:test-controller3 qosMeasuring:average]
I0129 14:09:29.270428       1 scheduler.go:229] [OnAddPod] Adicionando pod default/test-deployment3-84f8ccf757-9grx4 com os seguintes detalhes:
I0129 14:09:29.270567       1 types.go:743] [ControllerName] Verificando as anotações do pod default/test-deployment3-84f8ccf757-9grx4
I0129 14:09:29.270579       1 types.go:761] [ControllerName] Anotação 'controller' encontrada para o pod default/test-deployment3-84f8ccf757-9grx4: test-controller3
I0129 14:09:29.270590       1 scheduler.go:238] [OnAddPod] Atualizando métricas para o pod default/test-deployment3-84f8ccf757-9grx4
I0129 14:09:29.270595       1 types.go:743] [ControllerName] Verificando as anotações do pod default/test-deployment3-84f8ccf757-9grx4
I0129 14:09:29.271833       1 types.go:761] [ControllerName] Anotação 'controller' encontrada para o pod default/test-deployment3-84f8ccf757-9grx4: test-controller3
I0129 14:09:29.271936       1 scheduler.go:251] [OnAddPod] Pod default/test-deployment3-84f8ccf757-9grx4 adicionado com sucesso
I0129 14:09:29.294734       1 scheduler.go:258] [OnUpdatePod] Iniciando processamento de atualização de pod
I0129 14:09:29.310901       1 scheduler.go:262] [OnUpdatePod] Pod atualizado detectado: default/test-deployment2-7b58dbd49-w52nk, Anotações: map[acceptablePreemptionOverhead:10 controller:test-controller2 qosMeasuring:average]
I0129 14:09:29.315725       1 scheduler.go:265] [OnUpdatePod] Comparando estado no Informer e estado real no cluster para o pod default/test-deployment2-7b58dbd49-w52nk
I0129 14:09:29.315617       1 postFilter.go:29] [PostFilter] PostFilter chamado para pod: default/test-deployment3-84f8ccf757-9grx4
I0129 14:09:29.317084       1 postFilter.go:76] [Preempt] Comparando pod original com o atualizado...
I0129 14:09:29.317097       1 postFilter.go:83] [Preempt] Successfully retrieved updated pod default/test-deployment3-84f8ccf757-9grx4 from lister
I0129 14:09:29.859830       1 postFilter.go:233] [compareNodeResources] Recursos calculados no nó minikube: CPU = 750 mCPU, Memória = 178257920 bytes
I0129 14:09:29.859872       1 postFilter.go:234] [compareNodeResources] Recursos do snapshot no nó minikube: CPU = 750 mCPU, Memória = 178257920 bytes
I0129 14:09:29.859889       1 postFilter.go:240] [compareNodeResources] Recursos de CPU do nó minikube estão sincronizados: 750 mCPU
I0129 14:09:29.859904       1 postFilter.go:246] [compareNodeResources] Recursos de memória do nó minikube estão sincronizados: 178257920 bytes
I0129 14:09:29.883109       1 scheduler.go:70] Estado no Informer: map[acceptablePreemptionOverhead:10 controller:test-controller2 qosMeasuring:average]
I0129 14:09:29.883573       1 scheduler.go:71] Estado real no cluster: map[acceptablePreemptionOverhead:10 controller:test-controller2 qosMeasuring:average]
I0129 14:09:29.895621       1 scheduler.go:275] [OnUpdatePod] Atualizando informações de métricas para o pod default/test-deployment2-7b58dbd49-w52nk
I0129 14:09:29.895701       1 types.go:743] [ControllerName] Verificando as anotações do pod default/test-deployment2-7b58dbd49-w52nk
I0129 14:09:29.895717       1 types.go:761] [ControllerName] Anotação 'controller' encontrada para o pod default/test-deployment2-7b58dbd49-w52nk: test-controller2
I0129 14:09:29.895733       1 scheduler.go:277] [OnUpdatePod] Atualizando 'LastStatus' do pod default/test-deployment2-7b58dbd49-w52nk nas métricas
I0129 14:09:29.895741       1 scheduler.go:279] [OnUpdatePod] Métrica atualizada para o pod default/test-deployment2-7b58dbd49-w52nk
I0129 14:09:29.895758       1 scheduler.go:283] [OnUpdatePod] Finalizando processamento de atualização de pod para default/test-deployment2-7b58dbd49-w52nk
I0129 14:09:29.902563       1 postFilter.go:147] [PREEMPT CALL] The node minikube  was chosen to allocate pod test-deployment3-84f8ccf757-9grx4
I0129 14:09:29.903027       1 postFilter.go:151] [Preempt] Iniciando a remoção dos pods preemptados no nó minikube para alocar o pod default/test-deployment3-84f8ccf757-9grx4. Total de vítimas: 0
I0129 14:09:29.903228       1 postFilter.go:179] [Preempt] Total de pods preemptados no nó minikube: 0
I0129 14:09:29.903516       1 scheduler.go:84] [HigherPrecedence] Calculando precedência entre test-deployment3-84f8ccf757-9grx4 e test-deployment2-7b58dbd49-w52nk
I0129 14:09:29.903651       1 scheduler.go:117] [WaitForPodsOnCache] Verificando se o pod test-deployment3-84f8ccf757-9grx4 está no cache...
I0129 14:09:29.903663       1 scheduler.go:606] [GetControllerMetricInfo] Iniciando para o pod: default/test-deployment3-84f8ccf757-9grx4
I0129 14:09:29.903670       1 scheduler.go:611] [GetControllerMetricInfo] Obtendo o nome do controlador para o pod: default/test-deployment3-84f8ccf757-9grx4
I0129 14:09:29.903679       1 types.go:743] [ControllerName] Verificando as anotações do pod default/test-deployment3-84f8ccf757-9grx4
I0129 14:09:29.903782       1 types.go:761] [ControllerName] Anotação 'controller' encontrada para o pod default/test-deployment3-84f8ccf757-9grx4: test-controller3
I0129 14:09:29.906242       1 scheduler.go:614] [GetControllerMetricInfo] Métricas do controlador definidas para o pod: default/test-deployment3-84f8ccf757-9grx4
I0129 14:09:29.953632       1 scheduler.go:70] Estado no Informer: map[acceptablePreemptionOverhead:10 controller:test-controller3 qosMeasuring:average]
I0129 14:09:29.953707       1 scheduler.go:71] Estado real no cluster: map[acceptablePreemptionOverhead:10 controller:test-controller3 qosMeasuring:average]
I0129 14:09:29.953719       1 scheduler.go:139] [WaitForPodsOnCache] Pod test-deployment3-84f8ccf757-9grx4 encontrado no cache.
I0129 14:09:29.953725       1 scheduler.go:117] [WaitForPodsOnCache] Verificando se o pod test-deployment2-7b58dbd49-w52nk está no cache...
I0129 14:09:29.953734       1 scheduler.go:606] [GetControllerMetricInfo] Iniciando para o pod: default/test-deployment2-7b58dbd49-w52nk
I0129 14:09:29.953740       1 scheduler.go:611] [GetControllerMetricInfo] Obtendo o nome do controlador para o pod: default/test-deployment2-7b58dbd49-w52nk
I0129 14:09:29.953746       1 types.go:743] [ControllerName] Verificando as anotações do pod default/test-deployment2-7b58dbd49-w52nk
I0129 14:09:29.953754       1 types.go:761] [ControllerName] Anotação 'controller' encontrada para o pod default/test-deployment2-7b58dbd49-w52nk: test-controller2
I0129 14:09:29.953761       1 scheduler.go:614] [GetControllerMetricInfo] Métricas do controlador definidas para o pod: default/test-deployment2-7b58dbd49-w52nk
I0129 14:09:29.961306       1 scheduler.go:70] Estado no Informer: map[acceptablePreemptionOverhead:10 controller:test-controller2 qosMeasuring:average]
I0129 14:09:29.961360       1 scheduler.go:71] Estado real no cluster: map[acceptablePreemptionOverhead:10 controller:test-controller2 qosMeasuring:average]
I0129 14:09:29.961370       1 scheduler.go:139] [WaitForPodsOnCache] Pod test-deployment2-7b58dbd49-w52nk encontrado no cache.
I0129 14:09:29.961377       1 scheduler.go:606] [GetControllerMetricInfo] Iniciando para o pod: default/test-deployment3-84f8ccf757-9grx4
I0129 14:09:29.961384       1 scheduler.go:611] [GetControllerMetricInfo] Obtendo o nome do controlador para o pod: default/test-deployment3-84f8ccf757-9grx4
I0129 14:09:29.961390       1 types.go:743] [ControllerName] Verificando as anotações do pod default/test-deployment3-84f8ccf757-9grx4
I0129 14:09:29.961396       1 types.go:761] [ControllerName] Anotação 'controller' encontrada para o pod default/test-deployment3-84f8ccf757-9grx4: test-controller3
I0129 14:09:29.961404       1 scheduler.go:614] [GetControllerMetricInfo] Métricas do controlador definidas para o pod: default/test-deployment3-84f8ccf757-9grx4
I0129 14:09:29.961414       1 scheduler.go:606] [GetControllerMetricInfo] Iniciando para o pod: default/test-deployment2-7b58dbd49-w52nk
I0129 14:09:29.961420       1 scheduler.go:611] [GetControllerMetricInfo] Obtendo o nome do controlador para o pod: default/test-deployment2-7b58dbd49-w52nk
I0129 14:09:29.961424       1 types.go:743] [ControllerName] Verificando as anotações do pod default/test-deployment2-7b58dbd49-w52nk
I0129 14:09:29.961428       1 types.go:761] [ControllerName] Anotação 'controller' encontrada para o pod default/test-deployment2-7b58dbd49-w52nk: test-controller2
I0129 14:09:29.961434       1 scheduler.go:614] [GetControllerMetricInfo] Métricas do controlador definidas para o pod: default/test-deployment2-7b58dbd49-w52nk
I0129 14:09:29.961448       1 scheduler.go:98] [HigherPrecedence] Métricas para test-deployment3-84f8ccf757-9grx4: QoS = -205.204359, Importância = 0.80
I0129 14:09:29.961460       1 scheduler.go:99] [HigherPrecedence] Métricas para test-deployment2-7b58dbd49-w52nk: QoS = -216.492467, Importância = 0.80
I0129 14:09:29.961495       1 scheduler.go:110] [HigherPrecedence] Decisão final: test-deployment3-84f8ccf757-9grx4 tem precedência sobre test-deployment2-7b58dbd49-w52nk? false
I0129 14:09:29.961512       1 postFilter.go:186] [Preempt] Verificando pods de menor precedência no nó minikube que precisam ter o campo NominatedNodeName limpo
I0129 14:09:29.961554       1 postFilter.go:196] [Preempt] Finalizado para o nó minikube. Pod default/test-deployment3-84f8ccf757-9grx4 deve ser alocado agora.
I0129 14:09:29.961585       1 postFilter.go:49] [PostFilter] Nó nominado para o pod default/test-deployment3-84f8ccf757-9grx4: minikube
I0129 14:09:30.027409       1 scheduler.go:258] [OnUpdatePod] Iniciando processamento de atualização de pod
I0129 14:09:30.027548       1 scheduler.go:262] [OnUpdatePod] Pod atualizado detectado: default/test-deployment3-84f8ccf757-9grx4, Anotações: map[acceptablePreemptionOverhead:10 controller:test-controller3 qosMeasuring:average]
I0129 14:09:30.028715       1 scheduler.go:265] [OnUpdatePod] Comparando estado no Informer e estado real no cluster para o pod default/test-deployment3-84f8ccf757-9grx4
I0129 14:09:30.037064       1 scheduler.go:70] Estado no Informer: map[acceptablePreemptionOverhead:10 controller:test-controller3 qosMeasuring:average]
I0129 14:09:30.037377       1 scheduler.go:71] Estado real no cluster: map[acceptablePreemptionOverhead:10 controller:test-controller3 qosMeasuring:average]
I0129 14:09:30.037510       1 scheduler.go:275] [OnUpdatePod] Atualizando informações de métricas para o pod default/test-deployment3-84f8ccf757-9grx4
I0129 14:09:30.037652       1 types.go:743] [ControllerName] Verificando as anotações do pod default/test-deployment3-84f8ccf757-9grx4
I0129 14:09:30.037696       1 types.go:761] [ControllerName] Anotação 'controller' encontrada para o pod default/test-deployment3-84f8ccf757-9grx4: test-controller3
I0129 14:09:30.038210       1 scheduler.go:277] [OnUpdatePod] Atualizando 'LastStatus' do pod default/test-deployment3-84f8ccf757-9grx4 nas métricas
I0129 14:09:30.038327       1 scheduler.go:279] [OnUpdatePod] Métrica atualizada para o pod default/test-deployment3-84f8ccf757-9grx4
I0129 14:09:30.038962       1 scheduler.go:283] [OnUpdatePod] Finalizando processamento de atualização de pod para default/test-deployment3-84f8ccf757-9grx4
I0129 14:09:37.842795       1 postFilter.go:29] [PostFilter] PostFilter chamado para pod: default/test-deployment2-7b58dbd49-w52nk
I0129 14:09:37.842860       1 postFilter.go:76] [Preempt] Comparando pod original com o atualizado...
I0129 14:09:37.842873       1 postFilter.go:83] [Preempt] Successfully retrieved updated pod default/test-deployment2-7b58dbd49-w52nk from lister
I0129 14:09:37.847839       1 postFilter.go:233] [compareNodeResources] Recursos calculados no nó minikube: CPU = 750 mCPU, Memória = 178257920 bytes
I0129 14:09:37.847894       1 postFilter.go:234] [compareNodeResources] Recursos do snapshot no nó minikube: CPU = 750 mCPU, Memória = 178257920 bytes
I0129 14:09:37.847906       1 postFilter.go:240] [compareNodeResources] Recursos de CPU do nó minikube estão sincronizados: 750 mCPU
I0129 14:09:37.847916       1 postFilter.go:246] [compareNodeResources] Recursos de memória do nó minikube estão sincronizados: 178257920 bytes
I0129 14:09:37.848174       1 postFilter.go:147] [PREEMPT CALL] The node minikube  was chosen to allocate pod test-deployment2-7b58dbd49-w52nk
I0129 14:09:37.848224       1 postFilter.go:151] [Preempt] Iniciando a remoção dos pods preemptados no nó minikube para alocar o pod default/test-deployment2-7b58dbd49-w52nk. Total de vítimas: 0
I0129 14:09:37.848245       1 postFilter.go:179] [Preempt] Total de pods preemptados no nó minikube: 0
W0129 14:09:37.848320       1 scheduler.go:79] [HigherPrecedence] Tentativa de comparar o pod test-deployment2-7b58dbd49-w52nk consigo mesmo. Retornando false.
I0129 14:09:37.848362       1 scheduler.go:84] [HigherPrecedence] Calculando precedência entre test-deployment2-7b58dbd49-w52nk e test-deployment3-84f8ccf757-9grx4
I0129 14:09:37.848372       1 scheduler.go:117] [WaitForPodsOnCache] Verificando se o pod test-deployment2-7b58dbd49-w52nk está no cache...
I0129 14:09:37.848380       1 scheduler.go:606] [GetControllerMetricInfo] Iniciando para o pod: default/test-deployment2-7b58dbd49-w52nk
I0129 14:09:37.848387       1 scheduler.go:611] [GetControllerMetricInfo] Obtendo o nome do controlador para o pod: default/test-deployment2-7b58dbd49-w52nk
I0129 14:09:37.848395       1 types.go:743] [ControllerName] Verificando as anotações do pod default/test-deployment2-7b58dbd49-w52nk
I0129 14:09:37.848403       1 types.go:761] [ControllerName] Anotação 'controller' encontrada para o pod default/test-deployment2-7b58dbd49-w52nk: test-controller2
I0129 14:09:37.848411       1 scheduler.go:614] [GetControllerMetricInfo] Métricas do controlador definidas para o pod: default/test-deployment2-7b58dbd49-w52nk
I0129 14:09:37.852246       1 scheduler.go:70] Estado no Informer: map[acceptablePreemptionOverhead:10 controller:test-controller2 qosMeasuring:average]
I0129 14:09:37.852304       1 scheduler.go:71] Estado real no cluster: map[acceptablePreemptionOverhead:10 controller:test-controller2 qosMeasuring:average]
I0129 14:09:37.852317       1 scheduler.go:139] [WaitForPodsOnCache] Pod test-deployment2-7b58dbd49-w52nk encontrado no cache.
I0129 14:09:37.852324       1 scheduler.go:117] [WaitForPodsOnCache] Verificando se o pod test-deployment3-84f8ccf757-9grx4 está no cache...
I0129 14:09:37.852331       1 scheduler.go:606] [GetControllerMetricInfo] Iniciando para o pod: default/test-deployment3-84f8ccf757-9grx4
I0129 14:09:37.852338       1 scheduler.go:611] [GetControllerMetricInfo] Obtendo o nome do controlador para o pod: default/test-deployment3-84f8ccf757-9grx4
I0129 14:09:37.852344       1 types.go:743] [ControllerName] Verificando as anotações do pod default/test-deployment3-84f8ccf757-9grx4
I0129 14:09:37.852351       1 types.go:761] [ControllerName] Anotação 'controller' encontrada para o pod default/test-deployment3-84f8ccf757-9grx4: test-controller3
I0129 14:09:37.852359       1 scheduler.go:614] [GetControllerMetricInfo] Métricas do controlador definidas para o pod: default/test-deployment3-84f8ccf757-9grx4
I0129 14:09:37.855664       1 scheduler.go:70] Estado no Informer: map[acceptablePreemptionOverhead:10 controller:test-controller3 qosMeasuring:average]
I0129 14:09:37.856528       1 scheduler.go:71] Estado real no cluster: map[acceptablePreemptionOverhead:10 controller:test-controller3 qosMeasuring:average]
I0129 14:09:37.856947       1 scheduler.go:139] [WaitForPodsOnCache] Pod test-deployment3-84f8ccf757-9grx4 encontrado no cache.
I0129 14:09:37.857084       1 scheduler.go:606] [GetControllerMetricInfo] Iniciando para o pod: default/test-deployment2-7b58dbd49-w52nk
I0129 14:09:37.857093       1 scheduler.go:611] [GetControllerMetricInfo] Obtendo o nome do controlador para o pod: default/test-deployment2-7b58dbd49-w52nk
I0129 14:09:37.857099       1 types.go:743] [ControllerName] Verificando as anotações do pod default/test-deployment2-7b58dbd49-w52nk
I0129 14:09:37.857206       1 types.go:761] [ControllerName] Anotação 'controller' encontrada para o pod default/test-deployment2-7b58dbd49-w52nk: test-controller2
I0129 14:09:37.857218       1 scheduler.go:614] [GetControllerMetricInfo] Métricas do controlador definidas para o pod: default/test-deployment2-7b58dbd49-w52nk
I0129 14:09:37.857230       1 scheduler.go:606] [GetControllerMetricInfo] Iniciando para o pod: default/test-deployment3-84f8ccf757-9grx4
I0129 14:09:37.857236       1 scheduler.go:611] [GetControllerMetricInfo] Obtendo o nome do controlador para o pod: default/test-deployment3-84f8ccf757-9grx4
I0129 14:09:37.857332       1 types.go:743] [ControllerName] Verificando as anotações do pod default/test-deployment3-84f8ccf757-9grx4
I0129 14:09:37.857341       1 types.go:761] [ControllerName] Anotação 'controller' encontrada para o pod default/test-deployment3-84f8ccf757-9grx4: test-controller3
I0129 14:09:37.857348       1 scheduler.go:614] [GetControllerMetricInfo] Métricas do controlador definidas para o pod: default/test-deployment3-84f8ccf757-9grx4
I0129 14:09:37.857363       1 scheduler.go:98] [HigherPrecedence] Métricas para test-deployment2-7b58dbd49-w52nk: QoS = -224.437316, Importância = 0.80
I0129 14:09:37.857468       1 scheduler.go:99] [HigherPrecedence] Métricas para test-deployment3-84f8ccf757-9grx4: QoS = -213.149208, Importância = 0.80
I0129 14:09:37.857479       1 scheduler.go:110] [HigherPrecedence] Decisão final: test-deployment2-7b58dbd49-w52nk tem precedência sobre test-deployment3-84f8ccf757-9grx4? true
I0129 14:09:37.857497       1 postFilter.go:186] [Preempt] Verificando pods de menor precedência no nó minikube que precisam ter o campo NominatedNodeName limpo
I0129 14:09:37.857622       1 postFilter.go:188] [Preempt] Limpando o campo NominatedNodeName do pod default/test-deployment3-84f8ccf757-9grx4
I0129 14:09:37.873302       1 scheduler.go:258] [OnUpdatePod] Iniciando processamento de atualização de pod
I0129 14:09:37.873348       1 scheduler.go:262] [OnUpdatePod] Pod atualizado detectado: default/test-deployment3-84f8ccf757-9grx4, Anotações: map[acceptablePreemptionOverhead:10 controller:test-controller3 qosMeasuring:average]
I0129 14:09:37.873376       1 scheduler.go:265] [OnUpdatePod] Comparando estado no Informer e estado real no cluster para o pod default/test-deployment3-84f8ccf757-9grx4
I0129 14:09:37.878260       1 postFilter.go:196] [Preempt] Finalizado para o nó minikube. Pod default/test-deployment2-7b58dbd49-w52nk deve ser alocado agora.
I0129 14:09:37.878281       1 postFilter.go:49] [PostFilter] Nó nominado para o pod default/test-deployment2-7b58dbd49-w52nk: minikube
I0129 14:09:37.880784       1 scheduler.go:70] Estado no Informer: map[acceptablePreemptionOverhead:10 controller:test-controller3 qosMeasuring:average]
I0129 14:09:37.880940       1 scheduler.go:71] Estado real no cluster: map[acceptablePreemptionOverhead:10 controller:test-controller3 qosMeasuring:average]
I0129 14:09:37.881203       1 scheduler.go:275] [OnUpdatePod] Atualizando informações de métricas para o pod default/test-deployment3-84f8ccf757-9grx4
I0129 14:09:37.881354       1 types.go:743] [ControllerName] Verificando as anotações do pod default/test-deployment3-84f8ccf757-9grx4
I0129 14:09:37.881511       1 types.go:761] [ControllerName] Anotação 'controller' encontrada para o pod default/test-deployment3-84f8ccf757-9grx4: test-controller3
I0129 14:09:37.882234       1 scheduler.go:277] [OnUpdatePod] Atualizando 'LastStatus' do pod default/test-deployment3-84f8ccf757-9grx4 nas métricas
I0129 14:09:37.883441       1 scheduler.go:279] [OnUpdatePod] Métrica atualizada para o pod default/test-deployment3-84f8ccf757-9grx4
I0129 14:09:37.883541       1 scheduler.go:283] [OnUpdatePod] Finalizando processamento de atualização de pod para default/test-deployment3-84f8ccf757-9grx4
I0129 14:09:58.685771       1 scheduler.go:54] [QueueSort] Comparando prioridade de test-deployment2-7b58dbd49-w52nk com test-deployment3-84f8ccf757-9grx4
I0129 14:09:58.686031       1 scheduler.go:84] [HigherPrecedence] Calculando precedência entre test-deployment2-7b58dbd49-w52nk e test-deployment3-84f8ccf757-9grx4
I0129 14:09:58.686063       1 scheduler.go:117] [WaitForPodsOnCache] Verificando se o pod test-deployment2-7b58dbd49-w52nk está no cache...
I0129 14:09:58.688060       1 scheduler.go:606] [GetControllerMetricInfo] Iniciando para o pod: default/test-deployment2-7b58dbd49-w52nk
I0129 14:09:58.688272       1 scheduler.go:611] [GetControllerMetricInfo] Obtendo o nome do controlador para o pod: default/test-deployment2-7b58dbd49-w52nk
I0129 14:09:58.688307       1 types.go:743] [ControllerName] Verificando as anotações do pod default/test-deployment2-7b58dbd49-w52nk
I0129 14:09:58.689244       1 types.go:761] [ControllerName] Anotação 'controller' encontrada para o pod default/test-deployment2-7b58dbd49-w52nk: test-controller2
I0129 14:09:58.689300       1 scheduler.go:614] [GetControllerMetricInfo] Métricas do controlador definidas para o pod: default/test-deployment2-7b58dbd49-w52nk
I0129 14:09:58.712058       1 scheduler.go:70] Estado no Informer: map[acceptablePreemptionOverhead:10 controller:test-controller2 qosMeasuring:average]
I0129 14:09:58.714515       1 scheduler.go:71] Estado real no cluster: map[acceptablePreemptionOverhead:10 controller:test-controller2 qosMeasuring:average]
I0129 14:09:58.715281       1 scheduler.go:139] [WaitForPodsOnCache] Pod test-deployment2-7b58dbd49-w52nk encontrado no cache.
I0129 14:09:58.715451       1 scheduler.go:117] [WaitForPodsOnCache] Verificando se o pod test-deployment3-84f8ccf757-9grx4 está no cache...
I0129 14:09:58.715596       1 scheduler.go:606] [GetControllerMetricInfo] Iniciando para o pod: default/test-deployment3-84f8ccf757-9grx4
I0129 14:09:58.715991       1 scheduler.go:611] [GetControllerMetricInfo] Obtendo o nome do controlador para o pod: default/test-deployment3-84f8ccf757-9grx4
I0129 14:09:58.716539       1 types.go:743] [ControllerName] Verificando as anotações do pod default/test-deployment3-84f8ccf757-9grx4
I0129 14:09:58.716703       1 types.go:761] [ControllerName] Anotação 'controller' encontrada para o pod default/test-deployment3-84f8ccf757-9grx4: test-controller3
I0129 14:09:58.717008       1 scheduler.go:614] [GetControllerMetricInfo] Métricas do controlador definidas para o pod: default/test-deployment3-84f8ccf757-9grx4
I0129 14:09:58.724472       1 scheduler.go:70] Estado no Informer: map[acceptablePreemptionOverhead:10 controller:test-controller3 qosMeasuring:average]
I0129 14:09:58.724566       1 scheduler.go:71] Estado real no cluster: map[acceptablePreemptionOverhead:10 controller:test-controller3 qosMeasuring:average]
I0129 14:09:58.724583       1 scheduler.go:139] [WaitForPodsOnCache] Pod test-deployment3-84f8ccf757-9grx4 encontrado no cache.
I0129 14:09:58.724594       1 scheduler.go:606] [GetControllerMetricInfo] Iniciando para o pod: default/test-deployment2-7b58dbd49-w52nk
I0129 14:09:58.724604       1 scheduler.go:611] [GetControllerMetricInfo] Obtendo o nome do controlador para o pod: default/test-deployment2-7b58dbd49-w52nk
I0129 14:09:58.724614       1 types.go:743] [ControllerName] Verificando as anotações do pod default/test-deployment2-7b58dbd49-w52nk
I0129 14:09:58.724625       1 types.go:761] [ControllerName] Anotação 'controller' encontrada para o pod default/test-deployment2-7b58dbd49-w52nk: test-controller2
I0129 14:09:58.724641       1 scheduler.go:614] [GetControllerMetricInfo] Métricas do controlador definidas para o pod: default/test-deployment2-7b58dbd49-w52nk
I0129 14:09:58.724670       1 scheduler.go:606] [GetControllerMetricInfo] Iniciando para o pod: default/test-deployment3-84f8ccf757-9grx4
I0129 14:09:58.724678       1 scheduler.go:611] [GetControllerMetricInfo] Obtendo o nome do controlador para o pod: default/test-deployment3-84f8ccf757-9grx4
I0129 14:09:58.724686       1 types.go:743] [ControllerName] Verificando as anotações do pod default/test-deployment3-84f8ccf757-9grx4
I0129 14:09:58.724695       1 types.go:761] [ControllerName] Anotação 'controller' encontrada para o pod default/test-deployment3-84f8ccf757-9grx4: test-controller3
I0129 14:09:58.724704       1 scheduler.go:614] [GetControllerMetricInfo] Métricas do controlador definidas para o pod: default/test-deployment3-84f8ccf757-9grx4
I0129 14:09:58.724726       1 scheduler.go:98] [HigherPrecedence] Métricas para test-deployment2-7b58dbd49-w52nk: QoS = -245.274977, Importância = 0.80
I0129 14:09:58.724743       1 scheduler.go:99] [HigherPrecedence] Métricas para test-deployment3-84f8ccf757-9grx4: QoS = -233.986869, Importância = 0.80
I0129 14:09:58.724755       1 scheduler.go:110] [HigherPrecedence] Decisão final: test-deployment2-7b58dbd49-w52nk tem precedência sobre test-deployment3-84f8ccf757-9grx4? true
I0129 14:09:58.724767       1 scheduler.go:60] [QueueSort] Precedência determinada: test-deployment2-7b58dbd49-w52nk tem precedência sobre test-deployment3-84f8ccf757-9grx4? true
I0129 14:09:58.726084       1 scheduler.go:146] [Reserve] resources reserved at node minikube for pod test-deployment2-7b58dbd49-w52nk_default at 2025-01-29 14:09:58.72607186 +0000 UTC m=+571.829627091
I0129 14:09:58.726285       1 types.go:743] [ControllerName] Verificando as anotações do pod default/test-deployment2-7b58dbd49-w52nk
I0129 14:09:58.726299       1 types.go:761] [ControllerName] Anotação 'controller' encontrada para o pod default/test-deployment2-7b58dbd49-w52nk: test-controller2
I0129 14:09:58.726337       1 scheduler.go:148] [Reserve] Status de alocação atual para o pod test-deployment2-7b58dbd49-w52nk_default: 
I0129 14:09:58.726360       1 scheduler.go:150] [Reserve] Status de alocação atualizado para o pod test-deployment2-7b58dbd49-w52nk_default: allocating
I0129 14:09:58.726573       1 postFilter.go:29] [PostFilter] PostFilter chamado para pod: default/test-deployment3-84f8ccf757-9grx4
I0129 14:09:58.726600       1 postFilter.go:76] [Preempt] Comparando pod original com o atualizado...
I0129 14:09:58.726614       1 postFilter.go:83] [Preempt] Successfully retrieved updated pod default/test-deployment3-84f8ccf757-9grx4 from lister
I0129 14:09:58.727099       1 scheduler.go:174] [PreBind] Validando o pod test-deployment2-7b58dbd49-w52nk antes de vincular ao node minikube
I0129 14:09:59.776845       1 scheduler.go:182] [PostBind] Chamado para pod test-deployment2-7b58dbd49-w52nk
I0129 14:09:59.776939       1 scheduler.go:200] [PostBind] Pod test-deployment2-7b58dbd49-w52nk - Início do binding: 2025-01-29 14:09:58.727108125 +0000 UTC m=+571.830663444, Fim do binding: 2025-01-29 14:09:59.776927063 +0000 UTC m=+572.880482648
I0129 14:09:59.776975       1 types.go:743] [ControllerName] Verificando as anotações do pod default/test-deployment2-7b58dbd49-w52nk
I0129 14:09:59.776989       1 types.go:761] [ControllerName] Anotação 'controller' encontrada para o pod default/test-deployment2-7b58dbd49-w52nk: test-controller2
I0129 14:09:59.777026       1 scheduler.go:207] [PostBind] Métricas atualizadas para o pod test-deployment2-7b58dbd49-w52nk
I0129 14:09:59.804826       1 postFilter.go:233] [compareNodeResources] Recursos calculados no nó minikube: CPU = 1450 mCPU, Memória = 459276288 bytes
I0129 14:09:59.806590       1 postFilter.go:234] [compareNodeResources] Recursos do snapshot no nó minikube: CPU = 1450 mCPU, Memória = 459276288 bytes
I0129 14:09:59.807076       1 postFilter.go:240] [compareNodeResources] Recursos de CPU do nó minikube estão sincronizados: 1450 mCPU
I0129 14:09:59.813259       1 postFilter.go:246] [compareNodeResources] Recursos de memória do nó minikube estão sincronizados: 459276288 bytes
I0129 14:09:59.816518       1 scheduler.go:606] [GetControllerMetricInfo] Iniciando para o pod: default/test-deployment2-7b58dbd49-w52nk
I0129 14:09:59.816848       1 scheduler.go:611] [GetControllerMetricInfo] Obtendo o nome do controlador para o pod: default/test-deployment2-7b58dbd49-w52nk
I0129 14:09:59.811496       1 scheduler.go:258] [OnUpdatePod] Iniciando processamento de atualização de pod
I0129 14:09:59.819938       1 scheduler.go:262] [OnUpdatePod] Pod atualizado detectado: default/test-deployment2-7b58dbd49-w52nk, Anotações: map[acceptablePreemptionOverhead:10 controller:test-controller2 qosMeasuring:average]
I0129 14:09:59.820201       1 scheduler.go:265] [OnUpdatePod] Comparando estado no Informer e estado real no cluster para o pod default/test-deployment2-7b58dbd49-w52nk
I0129 14:09:59.820423       1 types.go:743] [ControllerName] Verificando as anotações do pod default/test-deployment2-7b58dbd49-w52nk
I0129 14:09:59.820433       1 types.go:761] [ControllerName] Anotação 'controller' encontrada para o pod default/test-deployment2-7b58dbd49-w52nk: test-controller2
I0129 14:09:59.820443       1 scheduler.go:614] [GetControllerMetricInfo] Métricas do controlador definidas para o pod: default/test-deployment2-7b58dbd49-w52nk
I0129 14:09:59.820451       1 scheduler.go:84] [HigherPrecedence] Calculando precedência entre test-deployment3-84f8ccf757-9grx4 e test-deployment2-7b58dbd49-w52nk
I0129 14:09:59.820459       1 scheduler.go:117] [WaitForPodsOnCache] Verificando se o pod test-deployment3-84f8ccf757-9grx4 está no cache...
I0129 14:09:59.820465       1 scheduler.go:606] [GetControllerMetricInfo] Iniciando para o pod: default/test-deployment3-84f8ccf757-9grx4
I0129 14:09:59.820471       1 scheduler.go:611] [GetControllerMetricInfo] Obtendo o nome do controlador para o pod: default/test-deployment3-84f8ccf757-9grx4
I0129 14:09:59.820477       1 types.go:743] [ControllerName] Verificando as anotações do pod default/test-deployment3-84f8ccf757-9grx4
I0129 14:09:59.820484       1 types.go:761] [ControllerName] Anotação 'controller' encontrada para o pod default/test-deployment3-84f8ccf757-9grx4: test-controller3
I0129 14:09:59.820491       1 scheduler.go:614] [GetControllerMetricInfo] Métricas do controlador definidas para o pod: default/test-deployment3-84f8ccf757-9grx4
I0129 14:09:59.841562       1 scheduler.go:70] Estado no Informer: map[acceptablePreemptionOverhead:10 controller:test-controller2 qosMeasuring:average]
I0129 14:09:59.842394       1 scheduler.go:71] Estado real no cluster: map[acceptablePreemptionOverhead:10 controller:test-controller2 qosMeasuring:average]
I0129 14:09:59.842872       1 scheduler.go:275] [OnUpdatePod] Atualizando informações de métricas para o pod default/test-deployment2-7b58dbd49-w52nk
I0129 14:10:00.048950       1 scheduler.go:70] Estado no Informer: map[acceptablePreemptionOverhead:10 controller:test-controller3 qosMeasuring:average]
I0129 14:10:00.051616       1 scheduler.go:71] Estado real no cluster: map[acceptablePreemptionOverhead:10 controller:test-controller3 qosMeasuring:average]
I0129 14:10:00.051747       1 scheduler.go:139] [WaitForPodsOnCache] Pod test-deployment3-84f8ccf757-9grx4 encontrado no cache.
I0129 14:10:00.052814       1 scheduler.go:117] [WaitForPodsOnCache] Verificando se o pod test-deployment2-7b58dbd49-w52nk está no cache...
I0129 14:10:00.053082       1 scheduler.go:606] [GetControllerMetricInfo] Iniciando para o pod: default/test-deployment2-7b58dbd49-w52nk
I0129 14:10:00.053462       1 types.go:743] [ControllerName] Verificando as anotações do pod default/test-deployment2-7b58dbd49-w52nk
I0129 14:10:00.053771       1 types.go:761] [ControllerName] Anotação 'controller' encontrada para o pod default/test-deployment2-7b58dbd49-w52nk: test-controller2
I0129 14:10:00.054289       1 scheduler.go:277] [OnUpdatePod] Atualizando 'LastStatus' do pod default/test-deployment2-7b58dbd49-w52nk nas métricas
I0129 14:10:00.054579       1 scheduler.go:279] [OnUpdatePod] Métrica atualizada para o pod default/test-deployment2-7b58dbd49-w52nk
I0129 14:10:00.055094       1 scheduler.go:283] [OnUpdatePod] Finalizando processamento de atualização de pod para default/test-deployment2-7b58dbd49-w52nk
I0129 14:10:00.055715       1 scheduler.go:611] [GetControllerMetricInfo] Obtendo o nome do controlador para o pod: default/test-deployment2-7b58dbd49-w52nk
I0129 14:10:00.055991       1 types.go:743] [ControllerName] Verificando as anotações do pod default/test-deployment2-7b58dbd49-w52nk
I0129 14:10:00.056977       1 types.go:761] [ControllerName] Anotação 'controller' encontrada para o pod default/test-deployment2-7b58dbd49-w52nk: test-controller2
I0129 14:10:00.058290       1 scheduler.go:614] [GetControllerMetricInfo] Métricas do controlador definidas para o pod: default/test-deployment2-7b58dbd49-w52nk
I0129 14:10:00.251988       1 scheduler.go:70] Estado no Informer: map[acceptablePreemptionOverhead:10 controller:test-controller2 qosMeasuring:average]
I0129 14:10:00.258092       1 scheduler.go:71] Estado real no cluster: map[acceptablePreemptionOverhead:10 controller:test-controller2 qosMeasuring:average]
I0129 14:10:00.258706       1 scheduler.go:139] [WaitForPodsOnCache] Pod test-deployment2-7b58dbd49-w52nk encontrado no cache.
I0129 14:10:00.258842       1 scheduler.go:606] [GetControllerMetricInfo] Iniciando para o pod: default/test-deployment3-84f8ccf757-9grx4
I0129 14:10:00.258854       1 scheduler.go:611] [GetControllerMetricInfo] Obtendo o nome do controlador para o pod: default/test-deployment3-84f8ccf757-9grx4
I0129 14:10:00.258865       1 types.go:743] [ControllerName] Verificando as anotações do pod default/test-deployment3-84f8ccf757-9grx4
I0129 14:10:00.258882       1 types.go:761] [ControllerName] Anotação 'controller' encontrada para o pod default/test-deployment3-84f8ccf757-9grx4: test-controller3
I0129 14:10:00.258895       1 scheduler.go:614] [GetControllerMetricInfo] Métricas do controlador definidas para o pod: default/test-deployment3-84f8ccf757-9grx4
I0129 14:10:00.258913       1 scheduler.go:606] [GetControllerMetricInfo] Iniciando para o pod: default/test-deployment2-7b58dbd49-w52nk
I0129 14:10:00.258923       1 scheduler.go:611] [GetControllerMetricInfo] Obtendo o nome do controlador para o pod: default/test-deployment2-7b58dbd49-w52nk
I0129 14:10:00.258930       1 types.go:743] [ControllerName] Verificando as anotações do pod default/test-deployment2-7b58dbd49-w52nk
I0129 14:10:00.258940       1 types.go:761] [ControllerName] Anotação 'controller' encontrada para o pod default/test-deployment2-7b58dbd49-w52nk: test-controller2
I0129 14:10:00.258950       1 scheduler.go:614] [GetControllerMetricInfo] Métricas do controlador definidas para o pod: default/test-deployment2-7b58dbd49-w52nk
I0129 14:10:00.258973       1 scheduler.go:98] [HigherPrecedence] Métricas para test-deployment3-84f8ccf757-9grx4: QoS = -235.121297, Importância = 0.80
I0129 14:10:00.258990       1 scheduler.go:99] [HigherPrecedence] Métricas para test-deployment2-7b58dbd49-w52nk: QoS = -246.617461, Importância = 0.80
I0129 14:10:00.259004       1 scheduler.go:110] [HigherPrecedence] Decisão final: test-deployment3-84f8ccf757-9grx4 tem precedência sobre test-deployment2-7b58dbd49-w52nk? false
I0129 14:10:00.259066       1 postFilter.go:144] [PREEMPT CALL] No node was chosen to allocate pod test-deployment3-84f8ccf757-9grx4
W0129 14:10:00.259078       1 postFilter.go:45] [PostFilter] Nenhum nó nominado após a preempção para o pod: default/test-deployment3-84f8ccf757-9grx4
I0129 14:10:00.253866       1 scheduler.go:258] [OnUpdatePod] Iniciando processamento de atualização de pod
I0129 14:10:00.268286       1 scheduler.go:262] [OnUpdatePod] Pod atualizado detectado: default/test-deployment2-7b58dbd49-w52nk, Anotações: map[acceptablePreemptionOverhead:10 controller:test-controller2 qosMeasuring:average]
I0129 14:10:00.268317       1 scheduler.go:265] [OnUpdatePod] Comparando estado no Informer e estado real no cluster para o pod default/test-deployment2-7b58dbd49-w52nk
I0129 14:10:00.292701       1 scheduler.go:70] Estado no Informer: map[acceptablePreemptionOverhead:10 controller:test-controller2 qosMeasuring:average]
I0129 14:10:00.292732       1 scheduler.go:71] Estado real no cluster: map[acceptablePreemptionOverhead:10 controller:test-controller2 qosMeasuring:average]
I0129 14:10:00.292745       1 scheduler.go:275] [OnUpdatePod] Atualizando informações de métricas para o pod default/test-deployment2-7b58dbd49-w52nk
I0129 14:10:00.292756       1 types.go:743] [ControllerName] Verificando as anotações do pod default/test-deployment2-7b58dbd49-w52nk
I0129 14:10:00.292763       1 types.go:761] [ControllerName] Anotação 'controller' encontrada para o pod default/test-deployment2-7b58dbd49-w52nk: test-controller2
I0129 14:10:00.292919       1 scheduler.go:277] [OnUpdatePod] Atualizando 'LastStatus' do pod default/test-deployment2-7b58dbd49-w52nk nas métricas
I0129 14:10:00.292926       1 scheduler.go:279] [OnUpdatePod] Métrica atualizada para o pod default/test-deployment2-7b58dbd49-w52nk
I0129 14:10:00.292937       1 scheduler.go:283] [OnUpdatePod] Finalizando processamento de atualização de pod para default/test-deployment2-7b58dbd49-w52nk
I0129 14:10:02.863861       1 postFilter.go:29] [PostFilter] PostFilter chamado para pod: default/test-deployment3-84f8ccf757-9grx4
I0129 14:10:02.864007       1 postFilter.go:76] [Preempt] Comparando pod original com o atualizado...
I0129 14:10:02.864031       1 postFilter.go:83] [Preempt] Successfully retrieved updated pod default/test-deployment3-84f8ccf757-9grx4 from lister
I0129 14:10:02.884760       1 postFilter.go:233] [compareNodeResources] Recursos calculados no nó minikube: CPU = 1450 mCPU, Memória = 459276288 bytes
I0129 14:10:02.885356       1 postFilter.go:234] [compareNodeResources] Recursos do snapshot no nó minikube: CPU = 1450 mCPU, Memória = 459276288 bytes
I0129 14:10:02.885498       1 postFilter.go:240] [compareNodeResources] Recursos de CPU do nó minikube estão sincronizados: 1450 mCPU
I0129 14:10:02.885717       1 postFilter.go:246] [compareNodeResources] Recursos de memória do nó minikube estão sincronizados: 459276288 bytes
I0129 14:10:02.886638       1 scheduler.go:606] [GetControllerMetricInfo] Iniciando para o pod: default/test-deployment2-7b58dbd49-w52nk
I0129 14:10:02.887084       1 scheduler.go:611] [GetControllerMetricInfo] Obtendo o nome do controlador para o pod: default/test-deployment2-7b58dbd49-w52nk
I0129 14:10:02.887686       1 types.go:743] [ControllerName] Verificando as anotações do pod default/test-deployment2-7b58dbd49-w52nk
I0129 14:10:02.887859       1 types.go:761] [ControllerName] Anotação 'controller' encontrada para o pod default/test-deployment2-7b58dbd49-w52nk: test-controller2
I0129 14:10:02.888172       1 scheduler.go:614] [GetControllerMetricInfo] Métricas do controlador definidas para o pod: default/test-deployment2-7b58dbd49-w52nk
I0129 14:10:02.889310       1 scheduler.go:84] [HigherPrecedence] Calculando precedência entre test-deployment3-84f8ccf757-9grx4 e test-deployment2-7b58dbd49-w52nk
I0129 14:10:02.889339       1 scheduler.go:117] [WaitForPodsOnCache] Verificando se o pod test-deployment3-84f8ccf757-9grx4 está no cache...
I0129 14:10:02.889350       1 scheduler.go:606] [GetControllerMetricInfo] Iniciando para o pod: default/test-deployment3-84f8ccf757-9grx4
I0129 14:10:02.889361       1 scheduler.go:611] [GetControllerMetricInfo] Obtendo o nome do controlador para o pod: default/test-deployment3-84f8ccf757-9grx4
I0129 14:10:02.889476       1 types.go:743] [ControllerName] Verificando as anotações do pod default/test-deployment3-84f8ccf757-9grx4
I0129 14:10:02.889495       1 types.go:761] [ControllerName] Anotação 'controller' encontrada para o pod default/test-deployment3-84f8ccf757-9grx4: test-controller3
I0129 14:10:02.889509       1 scheduler.go:614] [GetControllerMetricInfo] Métricas do controlador definidas para o pod: default/test-deployment3-84f8ccf757-9grx4
I0129 14:10:02.907644       1 scheduler.go:70] Estado no Informer: map[acceptablePreemptionOverhead:10 controller:test-controller3 qosMeasuring:average]
I0129 14:10:02.907714       1 scheduler.go:71] Estado real no cluster: map[acceptablePreemptionOverhead:10 controller:test-controller3 qosMeasuring:average]
I0129 14:10:02.907730       1 scheduler.go:139] [WaitForPodsOnCache] Pod test-deployment3-84f8ccf757-9grx4 encontrado no cache.
I0129 14:10:02.907738       1 scheduler.go:117] [WaitForPodsOnCache] Verificando se o pod test-deployment2-7b58dbd49-w52nk está no cache...
I0129 14:10:02.907747       1 scheduler.go:606] [GetControllerMetricInfo] Iniciando para o pod: default/test-deployment2-7b58dbd49-w52nk
I0129 14:10:02.907755       1 scheduler.go:611] [GetControllerMetricInfo] Obtendo o nome do controlador para o pod: default/test-deployment2-7b58dbd49-w52nk
I0129 14:10:02.907765       1 types.go:743] [ControllerName] Verificando as anotações do pod default/test-deployment2-7b58dbd49-w52nk
I0129 14:10:02.907774       1 types.go:761] [ControllerName] Anotação 'controller' encontrada para o pod default/test-deployment2-7b58dbd49-w52nk: test-controller2
I0129 14:10:02.907784       1 scheduler.go:614] [GetControllerMetricInfo] Métricas do controlador definidas para o pod: default/test-deployment2-7b58dbd49-w52nk
I0129 14:10:02.921928       1 scheduler.go:70] Estado no Informer: map[acceptablePreemptionOverhead:10 controller:test-controller2 qosMeasuring:average]
I0129 14:10:02.921960       1 scheduler.go:71] Estado real no cluster: map[acceptablePreemptionOverhead:10 controller:test-controller2 qosMeasuring:average]
I0129 14:10:02.921970       1 scheduler.go:139] [WaitForPodsOnCache] Pod test-deployment2-7b58dbd49-w52nk encontrado no cache.
I0129 14:10:02.921979       1 scheduler.go:606] [GetControllerMetricInfo] Iniciando para o pod: default/test-deployment3-84f8ccf757-9grx4
I0129 14:10:02.921986       1 scheduler.go:611] [GetControllerMetricInfo] Obtendo o nome do controlador para o pod: default/test-deployment3-84f8ccf757-9grx4
I0129 14:10:02.921995       1 types.go:743] [ControllerName] Verificando as anotações do pod default/test-deployment3-84f8ccf757-9grx4
I0129 14:10:02.922003       1 types.go:761] [ControllerName] Anotação 'controller' encontrada para o pod default/test-deployment3-84f8ccf757-9grx4: test-controller3
I0129 14:10:02.922011       1 scheduler.go:614] [GetControllerMetricInfo] Métricas do controlador definidas para o pod: default/test-deployment3-84f8ccf757-9grx4
I0129 14:10:02.922032       1 scheduler.go:606] [GetControllerMetricInfo] Iniciando para o pod: default/test-deployment2-7b58dbd49-w52nk
I0129 14:10:02.922039       1 scheduler.go:611] [GetControllerMetricInfo] Obtendo o nome do controlador para o pod: default/test-deployment2-7b58dbd49-w52nk
I0129 14:10:02.922044       1 types.go:743] [ControllerName] Verificando as anotações do pod default/test-deployment2-7b58dbd49-w52nk
I0129 14:10:02.922051       1 types.go:761] [ControllerName] Anotação 'controller' encontrada para o pod default/test-deployment2-7b58dbd49-w52nk: test-controller2
I0129 14:10:02.922058       1 scheduler.go:614] [GetControllerMetricInfo] Métricas do controlador definidas para o pod: default/test-deployment2-7b58dbd49-w52nk
I0129 14:10:02.922074       1 scheduler.go:98] [HigherPrecedence] Métricas para test-deployment3-84f8ccf757-9grx4: QoS = -238.190145, Importância = 0.80
I0129 14:10:02.922088       1 scheduler.go:99] [HigherPrecedence] Métricas para test-deployment2-7b58dbd49-w52nk: QoS = -245.850249, Importância = 0.80
I0129 14:10:02.922098       1 scheduler.go:110] [HigherPrecedence] Decisão final: test-deployment3-84f8ccf757-9grx4 tem precedência sobre test-deployment2-7b58dbd49-w52nk? false
I0129 14:10:02.922637       1 postFilter.go:144] [PREEMPT CALL] No node was chosen to allocate pod test-deployment3-84f8ccf757-9grx4
W0129 14:10:02.922652       1 postFilter.go:45] [PostFilter] Nenhum nó nominado após a preempção para o pod: default/test-deployment3-84f8ccf757-9grx4
I0129 14:10:07.718579       1 scheduler.go:258] [OnUpdatePod] Iniciando processamento de atualização de pod
I0129 14:10:07.718848       1 scheduler.go:262] [OnUpdatePod] Pod atualizado detectado: default/test-deployment2-7b58dbd49-w52nk, Anotações: map[acceptablePreemptionOverhead:10 controller:test-controller2 qosMeasuring:average]
I0129 14:10:07.718874       1 scheduler.go:265] [OnUpdatePod] Comparando estado no Informer e estado real no cluster para o pod default/test-deployment2-7b58dbd49-w52nk
I0129 14:10:07.753801       1 scheduler.go:70] Estado no Informer: map[acceptablePreemptionOverhead:10 controller:test-controller2 qosMeasuring:average]
I0129 14:10:07.753855       1 scheduler.go:71] Estado real no cluster: map[acceptablePreemptionOverhead:10 controller:test-controller2 qosMeasuring:average]
I0129 14:10:07.753869       1 scheduler.go:275] [OnUpdatePod] Atualizando informações de métricas para o pod default/test-deployment2-7b58dbd49-w52nk
I0129 14:10:07.753878       1 types.go:743] [ControllerName] Verificando as anotações do pod default/test-deployment2-7b58dbd49-w52nk
I0129 14:10:07.753917       1 types.go:761] [ControllerName] Anotação 'controller' encontrada para o pod default/test-deployment2-7b58dbd49-w52nk: test-controller2
I0129 14:10:07.753928       1 scheduler.go:277] [OnUpdatePod] Atualizando 'LastStatus' do pod default/test-deployment2-7b58dbd49-w52nk nas métricas
I0129 14:10:07.753939       1 scheduler.go:279] [OnUpdatePod] Métrica atualizada para o pod default/test-deployment2-7b58dbd49-w52nk
I0129 14:10:07.753949       1 scheduler.go:283] [OnUpdatePod] Finalizando processamento de atualização de pod para default/test-deployment2-7b58dbd49-w52nk
I0129 14:10:28.727880       1 postFilter.go:29] [PostFilter] PostFilter chamado para pod: default/test-deployment3-84f8ccf757-9grx4
I0129 14:10:28.729436       1 postFilter.go:76] [Preempt] Comparando pod original com o atualizado...
I0129 14:10:28.729571       1 postFilter.go:83] [Preempt] Successfully retrieved updated pod default/test-deployment3-84f8ccf757-9grx4 from lister
I0129 14:10:28.744894       1 postFilter.go:233] [compareNodeResources] Recursos calculados no nó minikube: CPU = 1450 mCPU, Memória = 459276288 bytes
I0129 14:10:28.744996       1 postFilter.go:234] [compareNodeResources] Recursos do snapshot no nó minikube: CPU = 1450 mCPU, Memória = 459276288 bytes
I0129 14:10:28.745029       1 postFilter.go:240] [compareNodeResources] Recursos de CPU do nó minikube estão sincronizados: 1450 mCPU
I0129 14:10:28.745045       1 postFilter.go:246] [compareNodeResources] Recursos de memória do nó minikube estão sincronizados: 459276288 bytes
I0129 14:10:28.745797       1 scheduler.go:606] [GetControllerMetricInfo] Iniciando para o pod: default/test-deployment2-7b58dbd49-w52nk
I0129 14:10:28.745882       1 scheduler.go:611] [GetControllerMetricInfo] Obtendo o nome do controlador para o pod: default/test-deployment2-7b58dbd49-w52nk
I0129 14:10:28.745918       1 types.go:743] [ControllerName] Verificando as anotações do pod default/test-deployment2-7b58dbd49-w52nk
