I0121 15:39:43.798254       1 serving.go:386] Generated self-signed cert in-memory
W0121 15:39:43.800041       1 client_config.go:659] Neither --kubeconfig nor --master was specified.  Using the inClusterConfig.  This might not work.
I0121 15:39:44.324986       1 scheduler.go:213] [OnAddPod] Pod adicionado: kube-system/coredns-6f6b679f8f-xx8lj, Anotações: map[]
I0121 15:39:44.331091       1 scheduler.go:69] Estado no Informer: map[]
I0121 15:39:44.331209       1 scheduler.go:70] Estado real no cluster: map[]
I0121 15:39:44.331331       1 scheduler.go:213] [OnAddPod] Pod adicionado: kube-system/custom-scheduler-868c6bbc7d-lxxfc, Anotações: map[]
I0121 15:39:44.334600       1 scheduler.go:69] Estado no Informer: map[]
I0121 15:39:44.334645       1 scheduler.go:70] Estado real no cluster: map[]
I0121 15:39:44.334818       1 scheduler.go:213] [OnAddPod] Pod adicionado: kube-system/etcd-minikube, Anotações: map[kubeadm.kubernetes.io/etcd.advertise-client-urls:https://192.168.39.119:2379 kubernetes.io/config.hash:3a5551ad61f7fbf125ce653897eeacd8 kubernetes.io/config.mirror:3a5551ad61f7fbf125ce653897eeacd8 kubernetes.io/config.seen:2024-12-12T12:29:04.213820860Z kubernetes.io/config.source:file]
I0121 15:39:44.340194       1 scheduler.go:69] Estado no Informer: map[kubeadm.kubernetes.io/etcd.advertise-client-urls:https://192.168.39.119:2379 kubernetes.io/config.hash:3a5551ad61f7fbf125ce653897eeacd8 kubernetes.io/config.mirror:3a5551ad61f7fbf125ce653897eeacd8 kubernetes.io/config.seen:2024-12-12T12:29:04.213820860Z kubernetes.io/config.source:file]
I0121 15:39:44.340273       1 scheduler.go:70] Estado real no cluster: map[kubeadm.kubernetes.io/etcd.advertise-client-urls:https://192.168.39.119:2379 kubernetes.io/config.hash:3a5551ad61f7fbf125ce653897eeacd8 kubernetes.io/config.mirror:3a5551ad61f7fbf125ce653897eeacd8 kubernetes.io/config.seen:2024-12-12T12:29:04.213820860Z kubernetes.io/config.source:file]
I0121 15:39:44.340383       1 scheduler.go:213] [OnAddPod] Pod adicionado: kube-system/kube-apiserver-minikube, Anotações: map[kubeadm.kubernetes.io/kube-apiserver.advertise-address.endpoint:192.168.39.119:8443 kubernetes.io/config.hash:94c2aa8ccf03c75abd3c81fba50edac4 kubernetes.io/config.mirror:94c2aa8ccf03c75abd3c81fba50edac4 kubernetes.io/config.seen:2024-12-12T12:29:04.213826155Z kubernetes.io/config.source:file]
I0121 15:39:44.343693       1 scheduler.go:69] Estado no Informer: map[kubeadm.kubernetes.io/kube-apiserver.advertise-address.endpoint:192.168.39.119:8443 kubernetes.io/config.hash:94c2aa8ccf03c75abd3c81fba50edac4 kubernetes.io/config.mirror:94c2aa8ccf03c75abd3c81fba50edac4 kubernetes.io/config.seen:2024-12-12T12:29:04.213826155Z kubernetes.io/config.source:file]
I0121 15:39:44.343745       1 scheduler.go:70] Estado real no cluster: map[kubeadm.kubernetes.io/kube-apiserver.advertise-address.endpoint:192.168.39.119:8443 kubernetes.io/config.hash:94c2aa8ccf03c75abd3c81fba50edac4 kubernetes.io/config.mirror:94c2aa8ccf03c75abd3c81fba50edac4 kubernetes.io/config.seen:2024-12-12T12:29:04.213826155Z kubernetes.io/config.source:file]
I0121 15:39:44.343790       1 scheduler.go:213] [OnAddPod] Pod adicionado: kube-system/kube-controller-manager-minikube, Anotações: map[kubernetes.io/config.hash:6e07439efa4d6dab7ea55fed1a35452a kubernetes.io/config.mirror:6e07439efa4d6dab7ea55fed1a35452a kubernetes.io/config.seen:2024-12-12T12:29:04.213827785Z kubernetes.io/config.source:file]
I0121 15:39:44.346383       1 scheduler.go:69] Estado no Informer: map[kubernetes.io/config.hash:6e07439efa4d6dab7ea55fed1a35452a kubernetes.io/config.mirror:6e07439efa4d6dab7ea55fed1a35452a kubernetes.io/config.seen:2024-12-12T12:29:04.213827785Z kubernetes.io/config.source:file]
I0121 15:39:44.346554       1 scheduler.go:70] Estado real no cluster: map[kubernetes.io/config.hash:6e07439efa4d6dab7ea55fed1a35452a kubernetes.io/config.mirror:6e07439efa4d6dab7ea55fed1a35452a kubernetes.io/config.seen:2024-12-12T12:29:04.213827785Z kubernetes.io/config.source:file]
I0121 15:39:44.346769       1 scheduler.go:213] [OnAddPod] Pod adicionado: kube-system/kube-proxy-lp7w9, Anotações: map[]
I0121 15:39:44.348916       1 scheduler.go:69] Estado no Informer: map[]
I0121 15:39:44.349164       1 scheduler.go:70] Estado real no cluster: map[]
I0121 15:39:44.349320       1 scheduler.go:213] [OnAddPod] Pod adicionado: kube-system/kube-scheduler-minikube, Anotações: map[kubernetes.io/config.hash:e039200acb850c82bb901653cc38ff6e kubernetes.io/config.mirror:e039200acb850c82bb901653cc38ff6e kubernetes.io/config.seen:2024-12-12T12:29:04.213829083Z kubernetes.io/config.source:file]
I0121 15:39:44.351960       1 scheduler.go:69] Estado no Informer: map[kubernetes.io/config.hash:e039200acb850c82bb901653cc38ff6e kubernetes.io/config.mirror:e039200acb850c82bb901653cc38ff6e kubernetes.io/config.seen:2024-12-12T12:29:04.213829083Z kubernetes.io/config.source:file]
I0121 15:39:44.352069       1 scheduler.go:70] Estado real no cluster: map[kubernetes.io/config.hash:e039200acb850c82bb901653cc38ff6e kubernetes.io/config.mirror:e039200acb850c82bb901653cc38ff6e kubernetes.io/config.seen:2024-12-12T12:29:04.213829083Z kubernetes.io/config.source:file]
I0121 15:39:44.352252       1 scheduler.go:213] [OnAddPod] Pod adicionado: kube-system/storage-provisioner, Anotações: map[kubectl.kubernetes.io/last-applied-configuration:{"apiVersion":"v1","kind":"Pod","metadata":{"annotations":{},"labels":{"addonmanager.kubernetes.io/mode":"Reconcile","integration-test":"storage-provisioner"},"name":"storage-provisioner","namespace":"kube-system"},"spec":{"containers":[{"command":["/storage-provisioner"],"image":"gcr.io/k8s-minikube/storage-provisioner:v5","imagePullPolicy":"IfNotPresent","name":"storage-provisioner","volumeMounts":[{"mountPath":"/tmp","name":"tmp"}]}],"hostNetwork":true,"serviceAccountName":"storage-provisioner","volumes":[{"hostPath":{"path":"/tmp","type":"Directory"},"name":"tmp"}]}}
]
I0121 15:39:44.355115       1 scheduler.go:69] Estado no Informer: map[kubectl.kubernetes.io/last-applied-configuration:{"apiVersion":"v1","kind":"Pod","metadata":{"annotations":{},"labels":{"addonmanager.kubernetes.io/mode":"Reconcile","integration-test":"storage-provisioner"},"name":"storage-provisioner","namespace":"kube-system"},"spec":{"containers":[{"command":["/storage-provisioner"],"image":"gcr.io/k8s-minikube/storage-provisioner:v5","imagePullPolicy":"IfNotPresent","name":"storage-provisioner","volumeMounts":[{"mountPath":"/tmp","name":"tmp"}]}],"hostNetwork":true,"serviceAccountName":"storage-provisioner","volumes":[{"hostPath":{"path":"/tmp","type":"Directory"},"name":"tmp"}]}}
]
I0121 15:39:44.355379       1 scheduler.go:70] Estado real no cluster: map[kubectl.kubernetes.io/last-applied-configuration:{"apiVersion":"v1","kind":"Pod","metadata":{"annotations":{},"labels":{"addonmanager.kubernetes.io/mode":"Reconcile","integration-test":"storage-provisioner"},"name":"storage-provisioner","namespace":"kube-system"},"spec":{"containers":[{"command":["/storage-provisioner"],"image":"gcr.io/k8s-minikube/storage-provisioner:v5","imagePullPolicy":"IfNotPresent","name":"storage-provisioner","volumeMounts":[{"mountPath":"/tmp","name":"tmp"}]}],"hostNetwork":true,"serviceAccountName":"storage-provisioner","volumes":[{"hostPath":{"path":"/tmp","type":"Directory"},"name":"tmp"}]}}
]
I0121 15:39:44.391901       1 scheduler.go:620] PodInformer sincronizado com sucesso
I0121 15:39:44.395573       1 server.go:167] "Starting Kubernetes Scheduler" version="v0.0.0-master+$Format:%H$"
I0121 15:39:44.395770       1 server.go:169] "Golang settings" GOGC="" GOMAXPROCS="" GOTRACEBACK=""
I0121 15:39:44.405339       1 requestheader_controller.go:172] Starting RequestHeaderAuthRequestController
I0121 15:39:44.405972       1 shared_informer.go:313] Waiting for caches to sync for RequestHeaderAuthRequestController
I0121 15:39:44.405888       1 configmap_cafile_content.go:205] "Starting controller" name="client-ca::kube-system::extension-apiserver-authentication::client-ca-file"
I0121 15:39:44.406377       1 shared_informer.go:313] Waiting for caches to sync for client-ca::kube-system::extension-apiserver-authentication::client-ca-file
I0121 15:39:44.405950       1 configmap_cafile_content.go:205] "Starting controller" name="client-ca::kube-system::extension-apiserver-authentication::requestheader-client-ca-file"
I0121 15:39:44.408819       1 shared_informer.go:313] Waiting for caches to sync for client-ca::kube-system::extension-apiserver-authentication::requestheader-client-ca-file
I0121 15:39:44.409874       1 tlsconfig.go:243] "Starting DynamicServingCertificateController"
I0121 15:39:44.409812       1 secure_serving.go:213] Serving securely on [::]:10259
I0121 15:39:44.410375       1 leaderelection.go:254] attempting to acquire leader lease kube-system/kube-scheduler...
I0121 15:39:44.425318       1 leaderelection.go:268] successfully acquired lease kube-system/kube-scheduler
I0121 15:39:44.507201       1 shared_informer.go:320] Caches are synced for RequestHeaderAuthRequestController
I0121 15:39:44.507369       1 shared_informer.go:320] Caches are synced for client-ca::kube-system::extension-apiserver-authentication::client-ca-file
I0121 15:39:44.511966       1 shared_informer.go:320] Caches are synced for client-ca::kube-system::extension-apiserver-authentication::requestheader-client-ca-file
I0121 15:40:20.854885       1 scheduler.go:145] [Reserve] resources reserved at node minikube for pod test-deployment2-59c6b78cd5-8zfst_default at 2025-01-21 15:40:20.854816414 +0000 UTC m=+37.509384956
I0121 15:40:20.855287       1 types.go:743] [ControllerName] Verificando as anotações do pod default/test-deployment2-59c6b78cd5-8zfst
I0121 15:40:20.855520       1 types.go:761] [ControllerName] Anotação 'controller' encontrada para o pod default/test-deployment2-59c6b78cd5-8zfst: test-controller2
I0121 15:40:20.856179       1 scheduler.go:213] [OnAddPod] Pod adicionado: default/test-deployment2-59c6b78cd5-8zfst, Anotações: map[controller:test-controller2]
I0121 15:40:20.888523       1 scheduler.go:69] Estado no Informer: map[controller:test-controller2]
I0121 15:40:20.888752       1 scheduler.go:70] Estado real no cluster: map[controller:test-controller2]
I0121 15:40:20.911400       1 scheduler.go:147] [Reserve] Status de alocação atual para o pod test-deployment2-59c6b78cd5-8zfst_default: 
I0121 15:40:20.911701       1 scheduler.go:149] [Reserve] Status de alocação atualizado para o pod test-deployment2-59c6b78cd5-8zfst_default: allocating
I0121 15:40:20.912256       1 scheduler.go:173] [PreBind] Validando o pod test-deployment2-59c6b78cd5-8zfst antes de vincular ao node minikube
I0121 15:40:20.913343       1 types.go:743] [ControllerName] Verificando as anotações do pod default/test-deployment2-59c6b78cd5-8zfst
I0121 15:40:20.913848       1 types.go:761] [ControllerName] Anotação 'controller' encontrada para o pod default/test-deployment2-59c6b78cd5-8zfst: test-controller2
I0121 15:40:20.914044       1 types.go:743] [ControllerName] Verificando as anotações do pod default/test-deployment2-59c6b78cd5-8zfst
I0121 15:40:20.916079       1 types.go:761] [ControllerName] Anotação 'controller' encontrada para o pod default/test-deployment2-59c6b78cd5-8zfst: test-controller2
I0121 15:40:20.933365       1 scheduler.go:181] [PostBind] Chamado para pod test-deployment2-59c6b78cd5-8zfst
I0121 15:40:20.933441       1 scheduler.go:199] [PostBind] Pod test-deployment2-59c6b78cd5-8zfst - Início do binding: 2025-01-21 15:40:20.912525636 +0000 UTC m=+37.567094150, Fim do binding: 2025-01-21 15:40:20.933432301 +0000 UTC m=+37.588001152
I0121 15:40:20.933738       1 types.go:743] [ControllerName] Verificando as anotações do pod default/test-deployment2-59c6b78cd5-8zfst
I0121 15:40:20.933787       1 types.go:761] [ControllerName] Anotação 'controller' encontrada para o pod default/test-deployment2-59c6b78cd5-8zfst: test-controller2
I0121 15:40:20.933953       1 scheduler.go:206] [PostBind] Métricas atualizadas para o pod test-deployment2-59c6b78cd5-8zfst
I0121 15:40:20.953703       1 scheduler.go:247] [OnUpdatePod] Pod atualizado: default/test-deployment2-59c6b78cd5-8zfst, Anotações: map[controller:test-controller2]
I0121 15:40:21.023836       1 scheduler.go:69] Estado no Informer: map[controller:test-controller2]
I0121 15:40:21.025551       1 scheduler.go:70] Estado real no cluster: map[controller:test-controller2]
I0121 15:40:21.025778       1 types.go:743] [ControllerName] Verificando as anotações do pod default/test-deployment2-59c6b78cd5-8zfst
I0121 15:40:21.025918       1 types.go:761] [ControllerName] Anotação 'controller' encontrada para o pod default/test-deployment2-59c6b78cd5-8zfst: test-controller2
I0121 15:40:21.032326       1 scheduler.go:247] [OnUpdatePod] Pod atualizado: default/test-deployment2-59c6b78cd5-8zfst, Anotações: map[controller:test-controller2]
I0121 15:40:21.043108       1 scheduler.go:69] Estado no Informer: map[controller:test-controller2]
I0121 15:40:21.043182       1 scheduler.go:70] Estado real no cluster: map[controller:test-controller2]
I0121 15:40:21.043200       1 types.go:743] [ControllerName] Verificando as anotações do pod default/test-deployment2-59c6b78cd5-8zfst
I0121 15:40:21.043211       1 types.go:761] [ControllerName] Anotação 'controller' encontrada para o pod default/test-deployment2-59c6b78cd5-8zfst: test-controller2
I0121 15:40:25.185822       1 scheduler.go:247] [OnUpdatePod] Pod atualizado: default/test-deployment2-59c6b78cd5-8zfst, Anotações: map[controller:test-controller2]
I0121 15:40:25.198064       1 scheduler.go:69] Estado no Informer: map[controller:test-controller2]
I0121 15:40:25.198416       1 scheduler.go:70] Estado real no cluster: map[controller:test-controller2]
I0121 15:40:25.198670       1 types.go:743] [ControllerName] Verificando as anotações do pod default/test-deployment2-59c6b78cd5-8zfst
I0121 15:40:25.198960       1 types.go:761] [ControllerName] Anotação 'controller' encontrada para o pod default/test-deployment2-59c6b78cd5-8zfst: test-controller2
I0121 15:40:56.588054       1 scheduler.go:213] [OnAddPod] Pod adicionado: default/test-deployment3-6c95cffb97-t2wrq, Anotações: map[controller:test-controller3]
I0121 15:40:56.589518       1 postFilter.go:74] Comparando pod original com o atualizado...
I0121 15:40:56.600652       1 postFilter.go:81] Successfully retrieved updated pod default/test-deployment3-6c95cffb97-t2wrq from lister
I0121 15:40:56.621995       1 scheduler.go:69] Estado no Informer: map[controller:test-controller3]
I0121 15:40:56.622380       1 scheduler.go:70] Estado real no cluster: map[controller:test-controller3]
I0121 15:40:56.624760       1 types.go:743] [ControllerName] Verificando as anotações do pod default/test-deployment3-6c95cffb97-t2wrq
I0121 15:40:56.624972       1 types.go:761] [ControllerName] Anotação 'controller' encontrada para o pod default/test-deployment3-6c95cffb97-t2wrq: test-controller3
I0121 15:40:56.625965       1 postFilter.go:204] Recursos CPU do nó minikube estão sincronizados: 2000 mCPU
I0121 15:40:56.626199       1 postFilter.go:211] Recursos Memória do nó minikube estão sincronizados: 2216124416 bytes
I0121 15:40:56.627418       1 scheduler.go:564] [GetControllerMetricInfo] Iniciando para o pod: default/test-deployment2-59c6b78cd5-8zfst
I0121 15:40:56.631077       1 types.go:743] [ControllerName] Verificando as anotações do pod default/test-deployment3-6c95cffb97-t2wrq
I0121 15:40:56.631253       1 types.go:761] [ControllerName] Anotação 'controller' encontrada para o pod default/test-deployment3-6c95cffb97-t2wrq: test-controller3
I0121 15:40:56.631447       1 scheduler.go:569] [GetControllerMetricInfo] Obtendo o nome do controlador para o pod: default/test-deployment2-59c6b78cd5-8zfst
I0121 15:40:56.631648       1 types.go:743] [ControllerName] Verificando as anotações do pod default/test-deployment2-59c6b78cd5-8zfst
I0121 15:40:56.631747       1 types.go:761] [ControllerName] Anotação 'controller' encontrada para o pod default/test-deployment2-59c6b78cd5-8zfst: test-controller2
I0121 15:40:56.631811       1 scheduler.go:572] [GetControllerMetricInfo] Métricas do controlador definidas para o pod: default/test-deployment2-59c6b78cd5-8zfst
I0121 15:40:56.631904       1 scheduler.go:83] [HigherPrecedence] Calculando precedência entre test-deployment3-6c95cffb97-t2wrq e test-deployment2-59c6b78cd5-8zfst
I0121 15:40:56.631959       1 scheduler.go:116] [WaitForPodsOnCache] Verificando se o pod test-deployment3-6c95cffb97-t2wrq está no cache...
I0121 15:40:56.632048       1 scheduler.go:564] [GetControllerMetricInfo] Iniciando para o pod: default/test-deployment3-6c95cffb97-t2wrq
I0121 15:40:56.632102       1 scheduler.go:569] [GetControllerMetricInfo] Obtendo o nome do controlador para o pod: default/test-deployment3-6c95cffb97-t2wrq
I0121 15:40:56.632191       1 types.go:743] [ControllerName] Verificando as anotações do pod default/test-deployment3-6c95cffb97-t2wrq
I0121 15:40:56.632250       1 types.go:761] [ControllerName] Anotação 'controller' encontrada para o pod default/test-deployment3-6c95cffb97-t2wrq: test-controller3
I0121 15:40:56.632339       1 scheduler.go:572] [GetControllerMetricInfo] Métricas do controlador definidas para o pod: default/test-deployment3-6c95cffb97-t2wrq
I0121 15:40:56.649908       1 scheduler.go:69] Estado no Informer: map[controller:test-controller3]
I0121 15:40:56.650412       1 scheduler.go:70] Estado real no cluster: map[controller:test-controller3]
I0121 15:40:56.650751       1 scheduler.go:138] [WaitForPodsOnCache] Pod test-deployment3-6c95cffb97-t2wrq encontrado no cache.
I0121 15:40:56.651075       1 scheduler.go:116] [WaitForPodsOnCache] Verificando se o pod test-deployment2-59c6b78cd5-8zfst está no cache...
I0121 15:40:56.651273       1 scheduler.go:564] [GetControllerMetricInfo] Iniciando para o pod: default/test-deployment2-59c6b78cd5-8zfst
I0121 15:40:56.651587       1 scheduler.go:569] [GetControllerMetricInfo] Obtendo o nome do controlador para o pod: default/test-deployment2-59c6b78cd5-8zfst
I0121 15:40:56.651824       1 types.go:743] [ControllerName] Verificando as anotações do pod default/test-deployment2-59c6b78cd5-8zfst
I0121 15:40:56.652051       1 types.go:761] [ControllerName] Anotação 'controller' encontrada para o pod default/test-deployment2-59c6b78cd5-8zfst: test-controller2
I0121 15:40:56.652293       1 scheduler.go:572] [GetControllerMetricInfo] Métricas do controlador definidas para o pod: default/test-deployment2-59c6b78cd5-8zfst
I0121 15:40:56.661081       1 scheduler.go:69] Estado no Informer: map[controller:test-controller2]
I0121 15:40:56.661364       1 scheduler.go:70] Estado real no cluster: map[controller:test-controller2]
I0121 15:40:56.661694       1 scheduler.go:138] [WaitForPodsOnCache] Pod test-deployment2-59c6b78cd5-8zfst encontrado no cache.
I0121 15:40:56.661931       1 scheduler.go:564] [GetControllerMetricInfo] Iniciando para o pod: default/test-deployment3-6c95cffb97-t2wrq
I0121 15:40:56.662155       1 scheduler.go:569] [GetControllerMetricInfo] Obtendo o nome do controlador para o pod: default/test-deployment3-6c95cffb97-t2wrq
I0121 15:40:56.662364       1 types.go:743] [ControllerName] Verificando as anotações do pod default/test-deployment3-6c95cffb97-t2wrq
I0121 15:40:56.662735       1 types.go:761] [ControllerName] Anotação 'controller' encontrada para o pod default/test-deployment3-6c95cffb97-t2wrq: test-controller3
I0121 15:40:56.662971       1 scheduler.go:572] [GetControllerMetricInfo] Métricas do controlador definidas para o pod: default/test-deployment3-6c95cffb97-t2wrq
I0121 15:40:56.663215       1 scheduler.go:564] [GetControllerMetricInfo] Iniciando para o pod: default/test-deployment2-59c6b78cd5-8zfst
I0121 15:40:56.663422       1 scheduler.go:569] [GetControllerMetricInfo] Obtendo o nome do controlador para o pod: default/test-deployment2-59c6b78cd5-8zfst
I0121 15:40:56.663675       1 types.go:743] [ControllerName] Verificando as anotações do pod default/test-deployment2-59c6b78cd5-8zfst
I0121 15:40:56.663886       1 types.go:761] [ControllerName] Anotação 'controller' encontrada para o pod default/test-deployment2-59c6b78cd5-8zfst: test-controller2
I0121 15:40:56.664101       1 scheduler.go:572] [GetControllerMetricInfo] Métricas do controlador definidas para o pod: default/test-deployment2-59c6b78cd5-8zfst
I0121 15:40:56.664277       1 scheduler.go:97] [HigherPrecedence] Métricas para test-deployment3-6c95cffb97-t2wrq: QoS = -3.031897, Importância = 0.80
I0121 15:40:56.664595       1 scheduler.go:98] [HigherPrecedence] Métricas para test-deployment2-59c6b78cd5-8zfst: QoS = 7.970276, Importância = 0.80
I0121 15:40:56.664827       1 scheduler.go:109] [HigherPrecedence] Decisão final: test-deployment3-6c95cffb97-t2wrq tem precedência sobre test-deployment2-59c6b78cd5-8zfst? true
I0121 15:40:56.665053       1 types.go:743] [ControllerName] Verificando as anotações do pod default/test-deployment3-6c95cffb97-t2wrq
I0121 15:40:56.665269       1 types.go:761] [ControllerName] Anotação 'controller' encontrada para o pod default/test-deployment3-6c95cffb97-t2wrq: test-controller3
I0121 15:40:56.665440       1 types.go:743] [ControllerName] Verificando as anotações do pod default/test-deployment2-59c6b78cd5-8zfst
I0121 15:40:56.665624       1 types.go:761] [ControllerName] Anotação 'controller' encontrada para o pod default/test-deployment2-59c6b78cd5-8zfst: test-controller2
I0121 15:40:56.665825       1 scheduler.go:564] [GetControllerMetricInfo] Iniciando para o pod: default/test-deployment2-59c6b78cd5-8zfst
I0121 15:40:56.665979       1 scheduler.go:569] [GetControllerMetricInfo] Obtendo o nome do controlador para o pod: default/test-deployment2-59c6b78cd5-8zfst
I0121 15:40:56.666177       1 types.go:743] [ControllerName] Verificando as anotações do pod default/test-deployment2-59c6b78cd5-8zfst
I0121 15:40:56.666355       1 types.go:761] [ControllerName] Anotação 'controller' encontrada para o pod default/test-deployment2-59c6b78cd5-8zfst: test-controller2
I0121 15:40:56.666718       1 scheduler.go:572] [GetControllerMetricInfo] Métricas do controlador definidas para o pod: default/test-deployment2-59c6b78cd5-8zfst
I0121 15:40:56.666904       1 scheduler.go:564] [GetControllerMetricInfo] Iniciando para o pod: default/test-deployment2-59c6b78cd5-8zfst
I0121 15:40:56.667103       1 scheduler.go:569] [GetControllerMetricInfo] Obtendo o nome do controlador para o pod: default/test-deployment2-59c6b78cd5-8zfst
I0121 15:40:56.667282       1 types.go:743] [ControllerName] Verificando as anotações do pod default/test-deployment2-59c6b78cd5-8zfst
I0121 15:40:56.667428       1 types.go:761] [ControllerName] Anotação 'controller' encontrada para o pod default/test-deployment2-59c6b78cd5-8zfst: test-controller2
I0121 15:40:56.667594       1 scheduler.go:572] [GetControllerMetricInfo] Métricas do controlador definidas para o pod: default/test-deployment2-59c6b78cd5-8zfst
I0121 15:40:56.667818       1 types.go:743] [ControllerName] Verificando as anotações do pod default/test-deployment2-59c6b78cd5-8zfst
I0121 15:40:56.668045       1 types.go:761] [ControllerName] Anotação 'controller' encontrada para o pod default/test-deployment2-59c6b78cd5-8zfst: test-controller2
I0121 15:40:56.668429       1 scheduler.go:564] [GetControllerMetricInfo] Iniciando para o pod: default/test-deployment2-59c6b78cd5-8zfst
I0121 15:40:56.668655       1 scheduler.go:569] [GetControllerMetricInfo] Obtendo o nome do controlador para o pod: default/test-deployment2-59c6b78cd5-8zfst
I0121 15:40:56.668875       1 types.go:743] [ControllerName] Verificando as anotações do pod default/test-deployment2-59c6b78cd5-8zfst
I0121 15:40:56.669082       1 types.go:761] [ControllerName] Anotação 'controller' encontrada para o pod default/test-deployment2-59c6b78cd5-8zfst: test-controller2
I0121 15:40:56.669338       1 scheduler.go:572] [GetControllerMetricInfo] Métricas do controlador definidas para o pod: default/test-deployment2-59c6b78cd5-8zfst
I0121 15:40:56.669560       1 scheduler.go:564] [GetControllerMetricInfo] Iniciando para o pod: default/test-deployment2-59c6b78cd5-8zfst
I0121 15:40:56.669712       1 scheduler.go:569] [GetControllerMetricInfo] Obtendo o nome do controlador para o pod: default/test-deployment2-59c6b78cd5-8zfst
I0121 15:40:56.669917       1 types.go:743] [ControllerName] Verificando as anotações do pod default/test-deployment2-59c6b78cd5-8zfst
I0121 15:40:56.670206       1 types.go:761] [ControllerName] Anotação 'controller' encontrada para o pod default/test-deployment2-59c6b78cd5-8zfst: test-controller2
I0121 15:40:56.670554       1 scheduler.go:572] [GetControllerMetricInfo] Métricas do controlador definidas para o pod: default/test-deployment2-59c6b78cd5-8zfst
I0121 15:40:56.670922       1 postFilter.go:145] [PREEMPT CALL] The node minikube  was chosen to allocate pod test-deployment3-6c95cffb97-t2wrq
I0121 15:40:56.690427       1 scheduler.go:247] [OnUpdatePod] Pod atualizado: default/test-deployment2-59c6b78cd5-8zfst, Anotações: map[controller:test-controller2]
I0121 15:40:56.755999       1 scheduler.go:69] Estado no Informer: map[controller:test-controller2]
I0121 15:40:56.756049       1 scheduler.go:70] Estado real no cluster: map[controller:test-controller2]
I0121 15:40:56.756061       1 types.go:743] [ControllerName] Verificando as anotações do pod default/test-deployment2-59c6b78cd5-8zfst
I0121 15:40:56.756067       1 types.go:761] [ControllerName] Anotação 'controller' encontrada para o pod default/test-deployment2-59c6b78cd5-8zfst: test-controller2
I0121 15:40:56.756116       1 scheduler.go:213] [OnAddPod] Pod adicionado: default/test-deployment2-59c6b78cd5-zcbs6, Anotações: map[controller:test-controller2]
I0121 15:40:56.756220       1 postFilter.go:74] Comparando pod original com o atualizado...
I0121 15:40:56.756241       1 postFilter.go:81] Successfully retrieved updated pod default/test-deployment2-59c6b78cd5-zcbs6 from lister
I0121 15:40:56.756304       1 types.go:743] [ControllerName] Verificando as anotações do pod default/test-deployment2-59c6b78cd5-8zfst
I0121 15:40:56.756313       1 types.go:761] [ControllerName] Anotação 'controller' encontrada para o pod default/test-deployment2-59c6b78cd5-8zfst: test-controller2
I0121 15:40:56.768521       1 postFilter.go:204] Recursos CPU do nó minikube estão sincronizados: 2000 mCPU
I0121 15:40:56.768562       1 postFilter.go:211] Recursos Memória do nó minikube estão sincronizados: 2216124416 bytes
I0121 15:40:56.768917       1 scheduler.go:564] [GetControllerMetricInfo] Iniciando para o pod: default/test-deployment2-59c6b78cd5-8zfst
I0121 15:40:56.768925       1 scheduler.go:569] [GetControllerMetricInfo] Obtendo o nome do controlador para o pod: default/test-deployment2-59c6b78cd5-8zfst
I0121 15:40:56.769006       1 types.go:743] [ControllerName] Verificando as anotações do pod default/test-deployment2-59c6b78cd5-8zfst
I0121 15:40:56.769015       1 types.go:761] [ControllerName] Anotação 'controller' encontrada para o pod default/test-deployment2-59c6b78cd5-8zfst: test-controller2
I0121 15:40:56.769021       1 scheduler.go:572] [GetControllerMetricInfo] Métricas do controlador definidas para o pod: default/test-deployment2-59c6b78cd5-8zfst
I0121 15:40:56.769027       1 scheduler.go:83] [HigherPrecedence] Calculando precedência entre test-deployment2-59c6b78cd5-zcbs6 e test-deployment2-59c6b78cd5-8zfst
I0121 15:40:56.769033       1 scheduler.go:116] [WaitForPodsOnCache] Verificando se o pod test-deployment2-59c6b78cd5-zcbs6 está no cache...
I0121 15:40:56.769037       1 scheduler.go:564] [GetControllerMetricInfo] Iniciando para o pod: default/test-deployment2-59c6b78cd5-zcbs6
I0121 15:40:56.769040       1 scheduler.go:569] [GetControllerMetricInfo] Obtendo o nome do controlador para o pod: default/test-deployment2-59c6b78cd5-zcbs6
I0121 15:40:56.769044       1 types.go:743] [ControllerName] Verificando as anotações do pod default/test-deployment2-59c6b78cd5-zcbs6
I0121 15:40:56.769048       1 types.go:761] [ControllerName] Anotação 'controller' encontrada para o pod default/test-deployment2-59c6b78cd5-zcbs6: test-controller2
I0121 15:40:56.769052       1 scheduler.go:572] [GetControllerMetricInfo] Métricas do controlador definidas para o pod: default/test-deployment2-59c6b78cd5-zcbs6
W0121 15:40:56.769122       1 scheduler.go:124] [cacheMiss] Métricas não encontradas para o pod: default/test-deployment2-59c6b78cd5-zcbs6
I0121 15:40:56.769545       1 scheduler.go:69] Estado no Informer: map[controller:test-controller2]
I0121 15:40:56.769600       1 scheduler.go:70] Estado real no cluster: map[controller:test-controller2]
I0121 15:40:56.775923       1 scheduler.go:69] Estado no Informer: map[controller:test-controller2]
I0121 15:40:56.775954       1 scheduler.go:70] Estado real no cluster: map[controller:test-controller2]
W0121 15:40:56.775963       1 scheduler.go:134] [WaitForPodsOnCache] Pod test-deployment2-59c6b78cd5-zcbs6 não encontrado no cache. Tentando novamente...
I0121 15:40:56.775985       1 types.go:743] [ControllerName] Verificando as anotações do pod default/test-deployment2-59c6b78cd5-zcbs6
I0121 15:40:56.775992       1 types.go:761] [ControllerName] Anotação 'controller' encontrada para o pod default/test-deployment2-59c6b78cd5-zcbs6: test-controller2
I0121 15:40:56.776019       1 types.go:743] [ControllerName] Verificando as anotações do pod default/test-deployment2-59c6b78cd5-zcbs6
I0121 15:40:56.776023       1 types.go:761] [ControllerName] Anotação 'controller' encontrada para o pod default/test-deployment2-59c6b78cd5-zcbs6: test-controller2
I0121 15:40:56.776080       1 scheduler.go:247] [OnUpdatePod] Pod atualizado: default/test-deployment3-6c95cffb97-t2wrq, Anotações: map[controller:test-controller3]
I0121 15:40:56.789359       1 scheduler.go:69] Estado no Informer: map[controller:test-controller3]
I0121 15:40:56.789404       1 scheduler.go:70] Estado real no cluster: map[controller:test-controller3]
I0121 15:40:56.789415       1 types.go:743] [ControllerName] Verificando as anotações do pod default/test-deployment3-6c95cffb97-t2wrq
I0121 15:40:56.789421       1 types.go:761] [ControllerName] Anotação 'controller' encontrada para o pod default/test-deployment3-6c95cffb97-t2wrq: test-controller3
I0121 15:40:56.876546       1 scheduler.go:564] [GetControllerMetricInfo] Iniciando para o pod: default/test-deployment2-59c6b78cd5-zcbs6
I0121 15:40:56.876672       1 scheduler.go:569] [GetControllerMetricInfo] Obtendo o nome do controlador para o pod: default/test-deployment2-59c6b78cd5-zcbs6
I0121 15:40:56.876692       1 types.go:743] [ControllerName] Verificando as anotações do pod default/test-deployment2-59c6b78cd5-zcbs6
I0121 15:40:56.876709       1 types.go:761] [ControllerName] Anotação 'controller' encontrada para o pod default/test-deployment2-59c6b78cd5-zcbs6: test-controller2
I0121 15:40:56.876736       1 scheduler.go:572] [GetControllerMetricInfo] Métricas do controlador definidas para o pod: default/test-deployment2-59c6b78cd5-zcbs6
I0121 15:40:57.070016       1 scheduler.go:69] Estado no Informer: map[controller:test-controller2]
I0121 15:40:57.070129       1 scheduler.go:70] Estado real no cluster: map[controller:test-controller2]
I0121 15:40:57.070151       1 scheduler.go:138] [WaitForPodsOnCache] Pod test-deployment2-59c6b78cd5-zcbs6 encontrado no cache.
I0121 15:40:57.070426       1 scheduler.go:116] [WaitForPodsOnCache] Verificando se o pod test-deployment2-59c6b78cd5-8zfst está no cache...
I0121 15:40:57.070610       1 scheduler.go:564] [GetControllerMetricInfo] Iniciando para o pod: default/test-deployment2-59c6b78cd5-8zfst
I0121 15:40:57.070700       1 scheduler.go:569] [GetControllerMetricInfo] Obtendo o nome do controlador para o pod: default/test-deployment2-59c6b78cd5-8zfst
I0121 15:40:57.070720       1 types.go:743] [ControllerName] Verificando as anotações do pod default/test-deployment2-59c6b78cd5-8zfst
I0121 15:40:57.070735       1 types.go:761] [ControllerName] Anotação 'controller' encontrada para o pod default/test-deployment2-59c6b78cd5-8zfst: test-controller2
I0121 15:40:57.070750       1 scheduler.go:572] [GetControllerMetricInfo] Métricas do controlador definidas para o pod: default/test-deployment2-59c6b78cd5-8zfst
I0121 15:40:57.082115       1 scheduler.go:69] Estado no Informer: map[controller:test-controller2]
I0121 15:40:57.082175       1 scheduler.go:70] Estado real no cluster: map[controller:test-controller2]
I0121 15:40:57.082187       1 scheduler.go:138] [WaitForPodsOnCache] Pod test-deployment2-59c6b78cd5-8zfst encontrado no cache.
I0121 15:40:57.082195       1 scheduler.go:564] [GetControllerMetricInfo] Iniciando para o pod: default/test-deployment2-59c6b78cd5-zcbs6
I0121 15:40:57.082202       1 scheduler.go:569] [GetControllerMetricInfo] Obtendo o nome do controlador para o pod: default/test-deployment2-59c6b78cd5-zcbs6
I0121 15:40:57.082210       1 types.go:743] [ControllerName] Verificando as anotações do pod default/test-deployment2-59c6b78cd5-zcbs6
I0121 15:40:57.082218       1 types.go:761] [ControllerName] Anotação 'controller' encontrada para o pod default/test-deployment2-59c6b78cd5-zcbs6: test-controller2
I0121 15:40:57.082225       1 scheduler.go:572] [GetControllerMetricInfo] Métricas do controlador definidas para o pod: default/test-deployment2-59c6b78cd5-zcbs6
I0121 15:40:57.082236       1 scheduler.go:564] [GetControllerMetricInfo] Iniciando para o pod: default/test-deployment2-59c6b78cd5-8zfst
I0121 15:40:57.082242       1 scheduler.go:569] [GetControllerMetricInfo] Obtendo o nome do controlador para o pod: default/test-deployment2-59c6b78cd5-8zfst
I0121 15:40:57.083630       1 types.go:743] [ControllerName] Verificando as anotações do pod default/test-deployment2-59c6b78cd5-8zfst
I0121 15:40:57.083675       1 types.go:761] [ControllerName] Anotação 'controller' encontrada para o pod default/test-deployment2-59c6b78cd5-8zfst: test-controller2
I0121 15:40:57.083685       1 scheduler.go:572] [GetControllerMetricInfo] Métricas do controlador definidas para o pod: default/test-deployment2-59c6b78cd5-8zfst
I0121 15:40:57.083774       1 scheduler.go:97] [HigherPrecedence] Métricas para test-deployment2-59c6b78cd5-zcbs6: QoS = 7.245988, Importância = 0.80
I0121 15:40:57.083789       1 scheduler.go:98] [HigherPrecedence] Métricas para test-deployment2-59c6b78cd5-8zfst: QoS = 3.214631, Importância = 0.80
I0121 15:40:57.083797       1 scheduler.go:109] [HigherPrecedence] Decisão final: test-deployment2-59c6b78cd5-zcbs6 tem precedência sobre test-deployment2-59c6b78cd5-8zfst? false
I0121 15:40:57.083848       1 postFilter.go:142] [PREEMPT CALL] No node was chosen to allocate pod test-deployment2-59c6b78cd5-zcbs6
I0121 15:40:57.147002       1 scheduler.go:247] [OnUpdatePod] Pod atualizado: default/test-deployment2-59c6b78cd5-zcbs6, Anotações: map[controller:test-controller2]
I0121 15:40:57.155353       1 scheduler.go:69] Estado no Informer: map[controller:test-controller2]
I0121 15:40:57.155403       1 scheduler.go:70] Estado real no cluster: map[controller:test-controller2]
I0121 15:40:57.155560       1 types.go:743] [ControllerName] Verificando as anotações do pod default/test-deployment2-59c6b78cd5-zcbs6
I0121 15:40:57.155760       1 types.go:761] [ControllerName] Anotação 'controller' encontrada para o pod default/test-deployment2-59c6b78cd5-zcbs6: test-controller2
I0121 15:40:57.503555       1 types.go:743] [ControllerName] Verificando as anotações do pod default/test-deployment2-59c6b78cd5-8zfst
I0121 15:40:57.503776       1 types.go:761] [ControllerName] Anotação 'controller' encontrada para o pod default/test-deployment2-59c6b78cd5-8zfst: test-controller2
I0121 15:40:58.487591       1 scheduler.go:53] [QueueSort] Comparando prioridade de test-deployment2-59c6b78cd5-zcbs6 com test-deployment3-6c95cffb97-t2wrq
I0121 15:40:58.488151       1 scheduler.go:83] [HigherPrecedence] Calculando precedência entre test-deployment2-59c6b78cd5-zcbs6 e test-deployment3-6c95cffb97-t2wrq
I0121 15:40:58.488322       1 scheduler.go:116] [WaitForPodsOnCache] Verificando se o pod test-deployment2-59c6b78cd5-zcbs6 está no cache...
I0121 15:40:58.488622       1 scheduler.go:564] [GetControllerMetricInfo] Iniciando para o pod: default/test-deployment2-59c6b78cd5-zcbs6
I0121 15:40:58.488721       1 scheduler.go:569] [GetControllerMetricInfo] Obtendo o nome do controlador para o pod: default/test-deployment2-59c6b78cd5-zcbs6
I0121 15:40:58.488923       1 types.go:743] [ControllerName] Verificando as anotações do pod default/test-deployment2-59c6b78cd5-zcbs6
I0121 15:40:58.488988       1 types.go:761] [ControllerName] Anotação 'controller' encontrada para o pod default/test-deployment2-59c6b78cd5-zcbs6: test-controller2
I0121 15:40:58.489363       1 scheduler.go:572] [GetControllerMetricInfo] Métricas do controlador definidas para o pod: default/test-deployment2-59c6b78cd5-zcbs6
I0121 15:40:58.499125       1 scheduler.go:69] Estado no Informer: map[controller:test-controller2]
I0121 15:40:58.499301       1 scheduler.go:70] Estado real no cluster: map[controller:test-controller2]
I0121 15:40:58.499853       1 scheduler.go:138] [WaitForPodsOnCache] Pod test-deployment2-59c6b78cd5-zcbs6 encontrado no cache.
I0121 15:40:58.499984       1 scheduler.go:116] [WaitForPodsOnCache] Verificando se o pod test-deployment3-6c95cffb97-t2wrq está no cache...
I0121 15:40:58.500250       1 scheduler.go:564] [GetControllerMetricInfo] Iniciando para o pod: default/test-deployment3-6c95cffb97-t2wrq
I0121 15:40:58.500567       1 scheduler.go:569] [GetControllerMetricInfo] Obtendo o nome do controlador para o pod: default/test-deployment3-6c95cffb97-t2wrq
I0121 15:40:58.500723       1 types.go:743] [ControllerName] Verificando as anotações do pod default/test-deployment3-6c95cffb97-t2wrq
I0121 15:40:58.500923       1 types.go:761] [ControllerName] Anotação 'controller' encontrada para o pod default/test-deployment3-6c95cffb97-t2wrq: test-controller3
I0121 15:40:58.501022       1 scheduler.go:572] [GetControllerMetricInfo] Métricas do controlador definidas para o pod: default/test-deployment3-6c95cffb97-t2wrq
I0121 15:40:58.506390       1 scheduler.go:69] Estado no Informer: map[controller:test-controller3]
I0121 15:40:58.506813       1 scheduler.go:70] Estado real no cluster: map[controller:test-controller3]
I0121 15:40:58.506981       1 scheduler.go:138] [WaitForPodsOnCache] Pod test-deployment3-6c95cffb97-t2wrq encontrado no cache.
I0121 15:40:58.507182       1 scheduler.go:564] [GetControllerMetricInfo] Iniciando para o pod: default/test-deployment2-59c6b78cd5-zcbs6
I0121 15:40:58.507281       1 scheduler.go:569] [GetControllerMetricInfo] Obtendo o nome do controlador para o pod: default/test-deployment2-59c6b78cd5-zcbs6
I0121 15:40:58.507581       1 types.go:743] [ControllerName] Verificando as anotações do pod default/test-deployment2-59c6b78cd5-zcbs6
I0121 15:40:58.507683       1 types.go:761] [ControllerName] Anotação 'controller' encontrada para o pod default/test-deployment2-59c6b78cd5-zcbs6: test-controller2
I0121 15:40:58.507884       1 scheduler.go:572] [GetControllerMetricInfo] Métricas do controlador definidas para o pod: default/test-deployment2-59c6b78cd5-zcbs6
I0121 15:40:58.507995       1 scheduler.go:564] [GetControllerMetricInfo] Iniciando para o pod: default/test-deployment3-6c95cffb97-t2wrq
I0121 15:40:58.508260       1 scheduler.go:569] [GetControllerMetricInfo] Obtendo o nome do controlador para o pod: default/test-deployment3-6c95cffb97-t2wrq
I0121 15:40:58.508610       1 types.go:743] [ControllerName] Verificando as anotações do pod default/test-deployment3-6c95cffb97-t2wrq
I0121 15:40:58.508810       1 types.go:761] [ControllerName] Anotação 'controller' encontrada para o pod default/test-deployment3-6c95cffb97-t2wrq: test-controller3
I0121 15:40:58.508920       1 scheduler.go:572] [GetControllerMetricInfo] Métricas do controlador definidas para o pod: default/test-deployment3-6c95cffb97-t2wrq
I0121 15:40:58.509399       1 scheduler.go:97] [HigherPrecedence] Métricas para test-deployment2-59c6b78cd5-zcbs6: QoS = 5.710826, Importância = 0.80
I0121 15:40:58.509873       1 scheduler.go:98] [HigherPrecedence] Métricas para test-deployment3-6c95cffb97-t2wrq: QoS = -4.888069, Importância = 0.80
I0121 15:40:58.510202       1 scheduler.go:109] [HigherPrecedence] Decisão final: test-deployment2-59c6b78cd5-zcbs6 tem precedência sobre test-deployment3-6c95cffb97-t2wrq? false
I0121 15:40:58.510408       1 scheduler.go:59] [QueueSort] Precedência determinada: test-deployment2-59c6b78cd5-zcbs6 tem precedência sobre test-deployment3-6c95cffb97-t2wrq? false
I0121 15:40:58.511434       1 scheduler.go:145] [Reserve] resources reserved at node minikube for pod test-deployment3-6c95cffb97-t2wrq_default at 2025-01-21 15:40:58.511420436 +0000 UTC m=+75.165989159
I0121 15:40:58.511743       1 types.go:743] [ControllerName] Verificando as anotações do pod default/test-deployment3-6c95cffb97-t2wrq
I0121 15:40:58.511952       1 types.go:761] [ControllerName] Anotação 'controller' encontrada para o pod default/test-deployment3-6c95cffb97-t2wrq: test-controller3
I0121 15:40:58.512148       1 scheduler.go:147] [Reserve] Status de alocação atual para o pod test-deployment3-6c95cffb97-t2wrq_default: 
I0121 15:40:58.512276       1 scheduler.go:149] [Reserve] Status de alocação atualizado para o pod test-deployment3-6c95cffb97-t2wrq_default: allocating
I0121 15:40:58.512846       1 postFilter.go:74] Comparando pod original com o atualizado...
I0121 15:40:58.513026       1 postFilter.go:81] Successfully retrieved updated pod default/test-deployment2-59c6b78cd5-zcbs6 from lister
I0121 15:40:58.513346       1 scheduler.go:173] [PreBind] Validando o pod test-deployment3-6c95cffb97-t2wrq antes de vincular ao node minikube
I0121 15:40:58.529981       1 postFilter.go:204] Recursos CPU do nó minikube estão sincronizados: 2000 mCPU
I0121 15:40:58.530167       1 postFilter.go:211] Recursos Memória do nó minikube estão sincronizados: 2216124416 bytes
I0121 15:40:58.530580       1 scheduler.go:564] [GetControllerMetricInfo] Iniciando para o pod: default/test-deployment3-6c95cffb97-t2wrq
I0121 15:40:58.530740       1 scheduler.go:569] [GetControllerMetricInfo] Obtendo o nome do controlador para o pod: default/test-deployment3-6c95cffb97-t2wrq
I0121 15:40:58.530858       1 types.go:743] [ControllerName] Verificando as anotações do pod default/test-deployment3-6c95cffb97-t2wrq
I0121 15:40:58.530936       1 types.go:761] [ControllerName] Anotação 'controller' encontrada para o pod default/test-deployment3-6c95cffb97-t2wrq: test-controller3
I0121 15:40:58.531089       1 scheduler.go:572] [GetControllerMetricInfo] Métricas do controlador definidas para o pod: default/test-deployment3-6c95cffb97-t2wrq
I0121 15:40:58.531166       1 scheduler.go:83] [HigherPrecedence] Calculando precedência entre test-deployment2-59c6b78cd5-zcbs6 e test-deployment3-6c95cffb97-t2wrq
I0121 15:40:58.531285       1 scheduler.go:116] [WaitForPodsOnCache] Verificando se o pod test-deployment2-59c6b78cd5-zcbs6 está no cache...
I0121 15:40:58.531404       1 scheduler.go:564] [GetControllerMetricInfo] Iniciando para o pod: default/test-deployment2-59c6b78cd5-zcbs6
I0121 15:40:58.531529       1 scheduler.go:569] [GetControllerMetricInfo] Obtendo o nome do controlador para o pod: default/test-deployment2-59c6b78cd5-zcbs6
I0121 15:40:58.531606       1 types.go:743] [ControllerName] Verificando as anotações do pod default/test-deployment2-59c6b78cd5-zcbs6
I0121 15:40:58.531724       1 types.go:761] [ControllerName] Anotação 'controller' encontrada para o pod default/test-deployment2-59c6b78cd5-zcbs6: test-controller2
I0121 15:40:58.531844       1 scheduler.go:572] [GetControllerMetricInfo] Métricas do controlador definidas para o pod: default/test-deployment2-59c6b78cd5-zcbs6
I0121 15:40:58.667188       1 scheduler.go:247] [OnUpdatePod] Pod atualizado: default/test-deployment3-6c95cffb97-t2wrq, Anotações: map[controller:test-controller3]
I0121 15:40:58.678429       1 scheduler.go:181] [PostBind] Chamado para pod test-deployment3-6c95cffb97-t2wrq
I0121 15:40:58.678772       1 scheduler.go:199] [PostBind] Pod test-deployment3-6c95cffb97-t2wrq - Início do binding: 2025-01-21 15:40:58.51342566 +0000 UTC m=+75.167994689, Fim do binding: 2025-01-21 15:40:58.678759769 +0000 UTC m=+75.333328788
I0121 15:40:58.680432       1 scheduler.go:69] Estado no Informer: map[controller:test-controller2]
I0121 15:40:58.680622       1 scheduler.go:70] Estado real no cluster: map[controller:test-controller2]
I0121 15:40:58.680645       1 scheduler.go:138] [WaitForPodsOnCache] Pod test-deployment2-59c6b78cd5-zcbs6 encontrado no cache.
I0121 15:40:58.680914       1 scheduler.go:116] [WaitForPodsOnCache] Verificando se o pod test-deployment3-6c95cffb97-t2wrq está no cache...
I0121 15:40:58.681091       1 scheduler.go:564] [GetControllerMetricInfo] Iniciando para o pod: default/test-deployment3-6c95cffb97-t2wrq
I0121 15:40:58.681278       1 types.go:743] [ControllerName] Verificando as anotações do pod default/test-deployment3-6c95cffb97-t2wrq
I0121 15:40:58.681642       1 types.go:761] [ControllerName] Anotação 'controller' encontrada para o pod default/test-deployment3-6c95cffb97-t2wrq: test-controller3
I0121 15:40:58.681713       1 scheduler.go:206] [PostBind] Métricas atualizadas para o pod test-deployment3-6c95cffb97-t2wrq
I0121 15:40:58.682157       1 scheduler.go:569] [GetControllerMetricInfo] Obtendo o nome do controlador para o pod: default/test-deployment3-6c95cffb97-t2wrq
I0121 15:40:58.682234       1 types.go:743] [ControllerName] Verificando as anotações do pod default/test-deployment3-6c95cffb97-t2wrq
I0121 15:40:58.682249       1 types.go:761] [ControllerName] Anotação 'controller' encontrada para o pod default/test-deployment3-6c95cffb97-t2wrq: test-controller3
I0121 15:40:58.682262       1 scheduler.go:572] [GetControllerMetricInfo] Métricas do controlador definidas para o pod: default/test-deployment3-6c95cffb97-t2wrq
I0121 15:40:58.719167       1 scheduler.go:69] Estado no Informer: map[controller:test-controller3]
I0121 15:40:58.719251       1 scheduler.go:70] Estado real no cluster: map[controller:test-controller3]
I0121 15:40:58.719268       1 scheduler.go:138] [WaitForPodsOnCache] Pod test-deployment3-6c95cffb97-t2wrq encontrado no cache.
I0121 15:40:58.719283       1 scheduler.go:564] [GetControllerMetricInfo] Iniciando para o pod: default/test-deployment2-59c6b78cd5-zcbs6
I0121 15:40:58.719294       1 scheduler.go:569] [GetControllerMetricInfo] Obtendo o nome do controlador para o pod: default/test-deployment2-59c6b78cd5-zcbs6
I0121 15:40:58.719418       1 scheduler.go:69] Estado no Informer: map[controller:test-controller3]
I0121 15:40:58.719601       1 scheduler.go:70] Estado real no cluster: map[controller:test-controller3]
I0121 15:40:58.719311       1 types.go:743] [ControllerName] Verificando as anotações do pod default/test-deployment2-59c6b78cd5-zcbs6
I0121 15:40:58.720175       1 types.go:761] [ControllerName] Anotação 'controller' encontrada para o pod default/test-deployment2-59c6b78cd5-zcbs6: test-controller2
I0121 15:40:58.720331       1 scheduler.go:572] [GetControllerMetricInfo] Métricas do controlador definidas para o pod: default/test-deployment2-59c6b78cd5-zcbs6
I0121 15:40:58.720610       1 types.go:743] [ControllerName] Verificando as anotações do pod default/test-deployment3-6c95cffb97-t2wrq
I0121 15:40:58.720917       1 types.go:761] [ControllerName] Anotação 'controller' encontrada para o pod default/test-deployment3-6c95cffb97-t2wrq: test-controller3
I0121 15:40:58.721545       1 scheduler.go:247] [OnUpdatePod] Pod atualizado: default/test-deployment3-6c95cffb97-t2wrq, Anotações: map[controller:test-controller3]
I0121 15:40:58.721623       1 scheduler.go:564] [GetControllerMetricInfo] Iniciando para o pod: default/test-deployment3-6c95cffb97-t2wrq
I0121 15:40:58.722230       1 scheduler.go:569] [GetControllerMetricInfo] Obtendo o nome do controlador para o pod: default/test-deployment3-6c95cffb97-t2wrq
I0121 15:40:58.722241       1 types.go:743] [ControllerName] Verificando as anotações do pod default/test-deployment3-6c95cffb97-t2wrq
I0121 15:40:58.722251       1 types.go:761] [ControllerName] Anotação 'controller' encontrada para o pod default/test-deployment3-6c95cffb97-t2wrq: test-controller3
I0121 15:40:58.722267       1 scheduler.go:572] [GetControllerMetricInfo] Métricas do controlador definidas para o pod: default/test-deployment3-6c95cffb97-t2wrq
I0121 15:40:58.722291       1 scheduler.go:97] [HigherPrecedence] Métricas para test-deployment2-59c6b78cd5-zcbs6: QoS = 5.667737, Importância = 0.80
I0121 15:40:58.722307       1 scheduler.go:98] [HigherPrecedence] Métricas para test-deployment3-6c95cffb97-t2wrq: QoS = -2.880994, Importância = 0.80
I0121 15:40:58.722318       1 scheduler.go:109] [HigherPrecedence] Decisão final: test-deployment2-59c6b78cd5-zcbs6 tem precedência sobre test-deployment3-6c95cffb97-t2wrq? false
I0121 15:40:58.722759       1 postFilter.go:142] [PREEMPT CALL] No node was chosen to allocate pod test-deployment2-59c6b78cd5-zcbs6
I0121 15:40:58.727786       1 scheduler.go:69] Estado no Informer: map[controller:test-controller3]
I0121 15:40:58.727851       1 scheduler.go:70] Estado real no cluster: map[controller:test-controller3]
I0121 15:40:58.727866       1 types.go:743] [ControllerName] Verificando as anotações do pod default/test-deployment3-6c95cffb97-t2wrq
I0121 15:40:58.727876       1 types.go:761] [ControllerName] Anotação 'controller' encontrada para o pod default/test-deployment3-6c95cffb97-t2wrq: test-controller3
I0121 15:41:01.514892       1 postFilter.go:74] Comparando pod original com o atualizado...
I0121 15:41:01.515330       1 postFilter.go:81] Successfully retrieved updated pod default/test-deployment2-59c6b78cd5-zcbs6 from lister
I0121 15:41:01.524419       1 postFilter.go:204] Recursos CPU do nó minikube estão sincronizados: 2000 mCPU
I0121 15:41:01.524638       1 postFilter.go:211] Recursos Memória do nó minikube estão sincronizados: 2216124416 bytes
I0121 15:41:01.525661       1 scheduler.go:564] [GetControllerMetricInfo] Iniciando para o pod: default/test-deployment3-6c95cffb97-t2wrq
I0121 15:41:01.525739       1 scheduler.go:569] [GetControllerMetricInfo] Obtendo o nome do controlador para o pod: default/test-deployment3-6c95cffb97-t2wrq
I0121 15:41:01.525758       1 types.go:743] [ControllerName] Verificando as anotações do pod default/test-deployment3-6c95cffb97-t2wrq
I0121 15:41:01.525774       1 types.go:761] [ControllerName] Anotação 'controller' encontrada para o pod default/test-deployment3-6c95cffb97-t2wrq: test-controller3
I0121 15:41:01.526170       1 scheduler.go:572] [GetControllerMetricInfo] Métricas do controlador definidas para o pod: default/test-deployment3-6c95cffb97-t2wrq
I0121 15:41:01.526192       1 scheduler.go:83] [HigherPrecedence] Calculando precedência entre test-deployment2-59c6b78cd5-zcbs6 e test-deployment3-6c95cffb97-t2wrq
I0121 15:41:01.526205       1 scheduler.go:116] [WaitForPodsOnCache] Verificando se o pod test-deployment2-59c6b78cd5-zcbs6 está no cache...
I0121 15:41:01.526215       1 scheduler.go:564] [GetControllerMetricInfo] Iniciando para o pod: default/test-deployment2-59c6b78cd5-zcbs6
I0121 15:41:01.526226       1 scheduler.go:569] [GetControllerMetricInfo] Obtendo o nome do controlador para o pod: default/test-deployment2-59c6b78cd5-zcbs6
I0121 15:41:01.526236       1 types.go:743] [ControllerName] Verificando as anotações do pod default/test-deployment2-59c6b78cd5-zcbs6
I0121 15:41:01.526249       1 types.go:761] [ControllerName] Anotação 'controller' encontrada para o pod default/test-deployment2-59c6b78cd5-zcbs6: test-controller2
I0121 15:41:01.526260       1 scheduler.go:572] [GetControllerMetricInfo] Métricas do controlador definidas para o pod: default/test-deployment2-59c6b78cd5-zcbs6
I0121 15:41:01.541252       1 scheduler.go:69] Estado no Informer: map[controller:test-controller2]
I0121 15:41:01.541786       1 scheduler.go:70] Estado real no cluster: map[controller:test-controller2]
I0121 15:41:01.542293       1 scheduler.go:138] [WaitForPodsOnCache] Pod test-deployment2-59c6b78cd5-zcbs6 encontrado no cache.
I0121 15:41:01.542435       1 scheduler.go:116] [WaitForPodsOnCache] Verificando se o pod test-deployment3-6c95cffb97-t2wrq está no cache...
I0121 15:41:01.542448       1 scheduler.go:564] [GetControllerMetricInfo] Iniciando para o pod: default/test-deployment3-6c95cffb97-t2wrq
I0121 15:41:01.542895       1 scheduler.go:569] [GetControllerMetricInfo] Obtendo o nome do controlador para o pod: default/test-deployment3-6c95cffb97-t2wrq
I0121 15:41:01.543270       1 types.go:743] [ControllerName] Verificando as anotações do pod default/test-deployment3-6c95cffb97-t2wrq
I0121 15:41:01.543795       1 types.go:761] [ControllerName] Anotação 'controller' encontrada para o pod default/test-deployment3-6c95cffb97-t2wrq: test-controller3
I0121 15:41:01.543884       1 scheduler.go:572] [GetControllerMetricInfo] Métricas do controlador definidas para o pod: default/test-deployment3-6c95cffb97-t2wrq
I0121 15:41:01.560385       1 scheduler.go:69] Estado no Informer: map[controller:test-controller3]
I0121 15:41:01.560416       1 scheduler.go:70] Estado real no cluster: map[controller:test-controller3]
I0121 15:41:01.560425       1 scheduler.go:138] [WaitForPodsOnCache] Pod test-deployment3-6c95cffb97-t2wrq encontrado no cache.
I0121 15:41:01.560434       1 scheduler.go:564] [GetControllerMetricInfo] Iniciando para o pod: default/test-deployment2-59c6b78cd5-zcbs6
I0121 15:41:01.560441       1 scheduler.go:569] [GetControllerMetricInfo] Obtendo o nome do controlador para o pod: default/test-deployment2-59c6b78cd5-zcbs6
I0121 15:41:01.560449       1 types.go:743] [ControllerName] Verificando as anotações do pod default/test-deployment2-59c6b78cd5-zcbs6
I0121 15:41:01.560525       1 types.go:761] [ControllerName] Anotação 'controller' encontrada para o pod default/test-deployment2-59c6b78cd5-zcbs6: test-controller2
I0121 15:41:01.560536       1 scheduler.go:572] [GetControllerMetricInfo] Métricas do controlador definidas para o pod: default/test-deployment2-59c6b78cd5-zcbs6
I0121 15:41:01.560548       1 scheduler.go:564] [GetControllerMetricInfo] Iniciando para o pod: default/test-deployment3-6c95cffb97-t2wrq
I0121 15:41:01.560554       1 scheduler.go:569] [GetControllerMetricInfo] Obtendo o nome do controlador para o pod: default/test-deployment3-6c95cffb97-t2wrq
I0121 15:41:01.560560       1 types.go:743] [ControllerName] Verificando as anotações do pod default/test-deployment3-6c95cffb97-t2wrq
I0121 15:41:01.560566       1 types.go:761] [ControllerName] Anotação 'controller' encontrada para o pod default/test-deployment3-6c95cffb97-t2wrq: test-controller3
I0121 15:41:01.560572       1 scheduler.go:572] [GetControllerMetricInfo] Métricas do controlador definidas para o pod: default/test-deployment3-6c95cffb97-t2wrq
I0121 15:41:01.560591       1 scheduler.go:97] [HigherPrecedence] Métricas para test-deployment2-59c6b78cd5-zcbs6: QoS = 2.672712, Importância = 0.80
I0121 15:41:01.560605       1 scheduler.go:98] [HigherPrecedence] Métricas para test-deployment3-6c95cffb97-t2wrq: QoS = -2.132238, Importância = 0.80
I0121 15:41:01.560614       1 scheduler.go:109] [HigherPrecedence] Decisão final: test-deployment2-59c6b78cd5-zcbs6 tem precedência sobre test-deployment3-6c95cffb97-t2wrq? false
I0121 15:41:01.560664       1 postFilter.go:142] [PREEMPT CALL] No node was chosen to allocate pod test-deployment2-59c6b78cd5-zcbs6
I0121 15:41:02.023051       1 scheduler.go:247] [OnUpdatePod] Pod atualizado: default/test-deployment3-6c95cffb97-t2wrq, Anotações: map[controller:test-controller3]
I0121 15:41:02.046429       1 scheduler.go:69] Estado no Informer: map[controller:test-controller3]
I0121 15:41:02.047392       1 scheduler.go:70] Estado real no cluster: map[controller:test-controller3]
I0121 15:41:02.047915       1 types.go:743] [ControllerName] Verificando as anotações do pod default/test-deployment3-6c95cffb97-t2wrq
I0121 15:41:02.048242       1 types.go:761] [ControllerName] Anotação 'controller' encontrada para o pod default/test-deployment3-6c95cffb97-t2wrq: test-controller3
I0121 15:46:14.445060       1 postFilter.go:74] Comparando pod original com o atualizado...
I0121 15:46:14.445776       1 postFilter.go:81] Successfully retrieved updated pod default/test-deployment2-59c6b78cd5-zcbs6 from lister
I0121 15:46:14.464669       1 postFilter.go:204] Recursos CPU do nó minikube estão sincronizados: 2000 mCPU
I0121 15:46:14.465036       1 postFilter.go:211] Recursos Memória do nó minikube estão sincronizados: 2216124416 bytes
I0121 15:46:14.466235       1 scheduler.go:564] [GetControllerMetricInfo] Iniciando para o pod: default/test-deployment3-6c95cffb97-t2wrq
I0121 15:46:14.466805       1 scheduler.go:569] [GetControllerMetricInfo] Obtendo o nome do controlador para o pod: default/test-deployment3-6c95cffb97-t2wrq
I0121 15:46:14.466977       1 types.go:743] [ControllerName] Verificando as anotações do pod default/test-deployment3-6c95cffb97-t2wrq
I0121 15:46:14.467241       1 types.go:761] [ControllerName] Anotação 'controller' encontrada para o pod default/test-deployment3-6c95cffb97-t2wrq: test-controller3
I0121 15:46:14.467385       1 scheduler.go:572] [GetControllerMetricInfo] Métricas do controlador definidas para o pod: default/test-deployment3-6c95cffb97-t2wrq
I0121 15:46:14.467574       1 scheduler.go:83] [HigherPrecedence] Calculando precedência entre test-deployment2-59c6b78cd5-zcbs6 e test-deployment3-6c95cffb97-t2wrq
I0121 15:46:14.467750       1 scheduler.go:116] [WaitForPodsOnCache] Verificando se o pod test-deployment2-59c6b78cd5-zcbs6 está no cache...
I0121 15:46:14.467962       1 scheduler.go:564] [GetControllerMetricInfo] Iniciando para o pod: default/test-deployment2-59c6b78cd5-zcbs6
I0121 15:46:14.468126       1 scheduler.go:569] [GetControllerMetricInfo] Obtendo o nome do controlador para o pod: default/test-deployment2-59c6b78cd5-zcbs6
I0121 15:46:14.468336       1 types.go:743] [ControllerName] Verificando as anotações do pod default/test-deployment2-59c6b78cd5-zcbs6
I0121 15:46:14.468748       1 types.go:761] [ControllerName] Anotação 'controller' encontrada para o pod default/test-deployment2-59c6b78cd5-zcbs6: test-controller2
I0121 15:46:14.468958       1 scheduler.go:572] [GetControllerMetricInfo] Métricas do controlador definidas para o pod: default/test-deployment2-59c6b78cd5-zcbs6
I0121 15:46:14.476250       1 scheduler.go:69] Estado no Informer: map[controller:test-controller2]
I0121 15:46:14.476388       1 scheduler.go:70] Estado real no cluster: map[controller:test-controller2]
I0121 15:46:14.476410       1 scheduler.go:138] [WaitForPodsOnCache] Pod test-deployment2-59c6b78cd5-zcbs6 encontrado no cache.
I0121 15:46:14.476423       1 scheduler.go:116] [WaitForPodsOnCache] Verificando se o pod test-deployment3-6c95cffb97-t2wrq está no cache...
I0121 15:46:14.476442       1 scheduler.go:564] [GetControllerMetricInfo] Iniciando para o pod: default/test-deployment3-6c95cffb97-t2wrq
I0121 15:46:14.476454       1 scheduler.go:569] [GetControllerMetricInfo] Obtendo o nome do controlador para o pod: default/test-deployment3-6c95cffb97-t2wrq
I0121 15:46:14.476579       1 types.go:743] [ControllerName] Verificando as anotações do pod default/test-deployment3-6c95cffb97-t2wrq
I0121 15:46:14.476595       1 types.go:761] [ControllerName] Anotação 'controller' encontrada para o pod default/test-deployment3-6c95cffb97-t2wrq: test-controller3
I0121 15:46:14.476611       1 scheduler.go:572] [GetControllerMetricInfo] Métricas do controlador definidas para o pod: default/test-deployment3-6c95cffb97-t2wrq
I0121 15:46:14.484378       1 scheduler.go:69] Estado no Informer: map[controller:test-controller3]
I0121 15:46:14.484767       1 scheduler.go:70] Estado real no cluster: map[controller:test-controller3]
I0121 15:46:14.484824       1 scheduler.go:138] [WaitForPodsOnCache] Pod test-deployment3-6c95cffb97-t2wrq encontrado no cache.
I0121 15:46:14.484861       1 scheduler.go:564] [GetControllerMetricInfo] Iniciando para o pod: default/test-deployment2-59c6b78cd5-zcbs6
I0121 15:46:14.484898       1 scheduler.go:569] [GetControllerMetricInfo] Obtendo o nome do controlador para o pod: default/test-deployment2-59c6b78cd5-zcbs6
I0121 15:46:14.484994       1 types.go:743] [ControllerName] Verificando as anotações do pod default/test-deployment2-59c6b78cd5-zcbs6
I0121 15:46:14.485035       1 types.go:761] [ControllerName] Anotação 'controller' encontrada para o pod default/test-deployment2-59c6b78cd5-zcbs6: test-controller2
I0121 15:46:14.485071       1 scheduler.go:572] [GetControllerMetricInfo] Métricas do controlador definidas para o pod: default/test-deployment2-59c6b78cd5-zcbs6
I0121 15:46:14.485144       1 scheduler.go:564] [GetControllerMetricInfo] Iniciando para o pod: default/test-deployment3-6c95cffb97-t2wrq
I0121 15:46:14.485332       1 scheduler.go:569] [GetControllerMetricInfo] Obtendo o nome do controlador para o pod: default/test-deployment3-6c95cffb97-t2wrq
I0121 15:46:14.485565       1 types.go:743] [ControllerName] Verificando as anotações do pod default/test-deployment3-6c95cffb97-t2wrq
I0121 15:46:14.485609       1 types.go:761] [ControllerName] Anotação 'controller' encontrada para o pod default/test-deployment3-6c95cffb97-t2wrq: test-controller3
I0121 15:46:14.485644       1 scheduler.go:572] [GetControllerMetricInfo] Métricas do controlador definidas para o pod: default/test-deployment3-6c95cffb97-t2wrq
I0121 15:46:14.485692       1 scheduler.go:97] [HigherPrecedence] Métricas para test-deployment2-59c6b78cd5-zcbs6: QoS = -310.268668, Importância = 0.80
I0121 15:46:14.485824       1 scheduler.go:98] [HigherPrecedence] Métricas para test-deployment3-6c95cffb97-t2wrq: QoS = 76.103107, Importância = 0.80
I0121 15:46:14.485868       1 scheduler.go:109] [HigherPrecedence] Decisão final: test-deployment2-59c6b78cd5-zcbs6 tem precedência sobre test-deployment3-6c95cffb97-t2wrq? true
I0121 15:46:14.485902       1 types.go:743] [ControllerName] Verificando as anotações do pod default/test-deployment2-59c6b78cd5-zcbs6
I0121 15:46:14.485936       1 types.go:761] [ControllerName] Anotação 'controller' encontrada para o pod default/test-deployment2-59c6b78cd5-zcbs6: test-controller2
I0121 15:46:14.485967       1 types.go:743] [ControllerName] Verificando as anotações do pod default/test-deployment3-6c95cffb97-t2wrq
I0121 15:46:14.485998       1 types.go:761] [ControllerName] Anotação 'controller' encontrada para o pod default/test-deployment3-6c95cffb97-t2wrq: test-controller3
I0121 15:46:14.486030       1 scheduler.go:564] [GetControllerMetricInfo] Iniciando para o pod: default/test-deployment3-6c95cffb97-t2wrq
I0121 15:46:14.486118       1 scheduler.go:569] [GetControllerMetricInfo] Obtendo o nome do controlador para o pod: default/test-deployment3-6c95cffb97-t2wrq
I0121 15:46:14.486155       1 types.go:743] [ControllerName] Verificando as anotações do pod default/test-deployment3-6c95cffb97-t2wrq
I0121 15:46:14.486187       1 types.go:761] [ControllerName] Anotação 'controller' encontrada para o pod default/test-deployment3-6c95cffb97-t2wrq: test-controller3
I0121 15:46:14.486219       1 scheduler.go:572] [GetControllerMetricInfo] Métricas do controlador definidas para o pod: default/test-deployment3-6c95cffb97-t2wrq
I0121 15:46:14.486249       1 scheduler.go:564] [GetControllerMetricInfo] Iniciando para o pod: default/test-deployment3-6c95cffb97-t2wrq
I0121 15:46:14.486283       1 scheduler.go:569] [GetControllerMetricInfo] Obtendo o nome do controlador para o pod: default/test-deployment3-6c95cffb97-t2wrq
I0121 15:46:14.486314       1 types.go:743] [ControllerName] Verificando as anotações do pod default/test-deployment3-6c95cffb97-t2wrq
I0121 15:46:14.486345       1 types.go:761] [ControllerName] Anotação 'controller' encontrada para o pod default/test-deployment3-6c95cffb97-t2wrq: test-controller3
I0121 15:46:14.486384       1 scheduler.go:572] [GetControllerMetricInfo] Métricas do controlador definidas para o pod: default/test-deployment3-6c95cffb97-t2wrq
I0121 15:46:14.486563       1 types.go:743] [ControllerName] Verificando as anotações do pod default/test-deployment3-6c95cffb97-t2wrq
I0121 15:46:14.486603       1 types.go:761] [ControllerName] Anotação 'controller' encontrada para o pod default/test-deployment3-6c95cffb97-t2wrq: test-controller3
I0121 15:46:14.486903       1 scheduler.go:564] [GetControllerMetricInfo] Iniciando para o pod: default/test-deployment3-6c95cffb97-t2wrq
I0121 15:46:14.486960       1 scheduler.go:569] [GetControllerMetricInfo] Obtendo o nome do controlador para o pod: default/test-deployment3-6c95cffb97-t2wrq
I0121 15:46:14.486993       1 types.go:743] [ControllerName] Verificando as anotações do pod default/test-deployment3-6c95cffb97-t2wrq
I0121 15:46:14.487025       1 types.go:761] [ControllerName] Anotação 'controller' encontrada para o pod default/test-deployment3-6c95cffb97-t2wrq: test-controller3
I0121 15:46:14.487058       1 scheduler.go:572] [GetControllerMetricInfo] Métricas do controlador definidas para o pod: default/test-deployment3-6c95cffb97-t2wrq
I0121 15:46:14.487157       1 scheduler.go:564] [GetControllerMetricInfo] Iniciando para o pod: default/test-deployment3-6c95cffb97-t2wrq
I0121 15:46:14.487195       1 scheduler.go:569] [GetControllerMetricInfo] Obtendo o nome do controlador para o pod: default/test-deployment3-6c95cffb97-t2wrq
I0121 15:46:14.487226       1 types.go:743] [ControllerName] Verificando as anotações do pod default/test-deployment3-6c95cffb97-t2wrq
I0121 15:46:14.487257       1 types.go:761] [ControllerName] Anotação 'controller' encontrada para o pod default/test-deployment3-6c95cffb97-t2wrq: test-controller3
I0121 15:46:14.487288       1 scheduler.go:572] [GetControllerMetricInfo] Métricas do controlador definidas para o pod: default/test-deployment3-6c95cffb97-t2wrq
I0121 15:46:14.487339       1 postFilter.go:145] [PREEMPT CALL] The node minikube  was chosen to allocate pod test-deployment2-59c6b78cd5-zcbs6
I0121 15:46:14.550900       1 scheduler.go:247] [OnUpdatePod] Pod atualizado: default/test-deployment3-6c95cffb97-t2wrq, Anotações: map[controller:test-controller3]
I0121 15:46:14.603190       1 scheduler.go:69] Estado no Informer: map[controller:test-controller3]
I0121 15:46:14.611841       1 scheduler.go:70] Estado real no cluster: map[controller:test-controller3]
I0121 15:46:14.611903       1 types.go:743] [ControllerName] Verificando as anotações do pod default/test-deployment3-6c95cffb97-t2wrq
I0121 15:46:14.611913       1 types.go:761] [ControllerName] Anotação 'controller' encontrada para o pod default/test-deployment3-6c95cffb97-t2wrq: test-controller3
I0121 15:46:14.611990       1 types.go:743] [ControllerName] Verificando as anotações do pod default/test-deployment3-6c95cffb97-t2wrq
I0121 15:46:14.611998       1 types.go:761] [ControllerName] Anotação 'controller' encontrada para o pod default/test-deployment3-6c95cffb97-t2wrq: test-controller3
I0121 15:46:14.618917       1 scheduler.go:247] [OnUpdatePod] Pod atualizado: default/test-deployment2-59c6b78cd5-zcbs6, Anotações: map[controller:test-controller2]
I0121 15:46:14.645622       1 scheduler.go:69] Estado no Informer: map[controller:test-controller2]
I0121 15:46:14.645649       1 scheduler.go:70] Estado real no cluster: map[controller:test-controller2]
I0121 15:46:14.645711       1 types.go:743] [ControllerName] Verificando as anotações do pod default/test-deployment2-59c6b78cd5-zcbs6
I0121 15:46:14.645717       1 types.go:761] [ControllerName] Anotação 'controller' encontrada para o pod default/test-deployment2-59c6b78cd5-zcbs6: test-controller2
I0121 15:46:14.645843       1 scheduler.go:213] [OnAddPod] Pod adicionado: default/test-deployment3-6c95cffb97-bpsqd, Anotações: map[controller:test-controller3]
I0121 15:46:14.649565       1 postFilter.go:74] Comparando pod original com o atualizado...
I0121 15:46:14.649917       1 postFilter.go:81] Successfully retrieved updated pod default/test-deployment3-6c95cffb97-bpsqd from lister
I0121 15:46:14.662122       1 scheduler.go:69] Estado no Informer: map[controller:test-controller3]
I0121 15:46:14.662141       1 scheduler.go:70] Estado real no cluster: map[controller:test-controller3]
I0121 15:46:14.662568       1 types.go:743] [ControllerName] Verificando as anotações do pod default/test-deployment3-6c95cffb97-bpsqd
I0121 15:46:14.662578       1 types.go:761] [ControllerName] Anotação 'controller' encontrada para o pod default/test-deployment3-6c95cffb97-bpsqd: test-controller3
I0121 15:46:14.662587       1 types.go:743] [ControllerName] Verificando as anotações do pod default/test-deployment3-6c95cffb97-bpsqd
I0121 15:46:14.662590       1 types.go:761] [ControllerName] Anotação 'controller' encontrada para o pod default/test-deployment3-6c95cffb97-bpsqd: test-controller3
I0121 15:46:14.662902       1 postFilter.go:204] Recursos CPU do nó minikube estão sincronizados: 2000 mCPU
I0121 15:46:14.662911       1 postFilter.go:211] Recursos Memória do nó minikube estão sincronizados: 2216124416 bytes
I0121 15:46:14.663002       1 scheduler.go:564] [GetControllerMetricInfo] Iniciando para o pod: default/test-deployment3-6c95cffb97-t2wrq
I0121 15:46:14.663008       1 scheduler.go:569] [GetControllerMetricInfo] Obtendo o nome do controlador para o pod: default/test-deployment3-6c95cffb97-t2wrq
I0121 15:46:14.663012       1 types.go:743] [ControllerName] Verificando as anotações do pod default/test-deployment3-6c95cffb97-t2wrq
I0121 15:46:14.663017       1 types.go:761] [ControllerName] Anotação 'controller' encontrada para o pod default/test-deployment3-6c95cffb97-t2wrq: test-controller3
I0121 15:46:14.663022       1 scheduler.go:572] [GetControllerMetricInfo] Métricas do controlador definidas para o pod: default/test-deployment3-6c95cffb97-t2wrq
I0121 15:46:14.663027       1 scheduler.go:83] [HigherPrecedence] Calculando precedência entre test-deployment3-6c95cffb97-bpsqd e test-deployment3-6c95cffb97-t2wrq
I0121 15:46:14.663032       1 scheduler.go:116] [WaitForPodsOnCache] Verificando se o pod test-deployment3-6c95cffb97-bpsqd está no cache...
I0121 15:46:14.663055       1 scheduler.go:564] [GetControllerMetricInfo] Iniciando para o pod: default/test-deployment3-6c95cffb97-bpsqd
I0121 15:46:14.663059       1 scheduler.go:569] [GetControllerMetricInfo] Obtendo o nome do controlador para o pod: default/test-deployment3-6c95cffb97-bpsqd
I0121 15:46:14.663063       1 types.go:743] [ControllerName] Verificando as anotações do pod default/test-deployment3-6c95cffb97-bpsqd
I0121 15:46:14.663067       1 types.go:761] [ControllerName] Anotação 'controller' encontrada para o pod default/test-deployment3-6c95cffb97-bpsqd: test-controller3
I0121 15:46:14.663079       1 scheduler.go:572] [GetControllerMetricInfo] Métricas do controlador definidas para o pod: default/test-deployment3-6c95cffb97-bpsqd
I0121 15:46:14.675298       1 scheduler.go:69] Estado no Informer: map[controller:test-controller3]
I0121 15:46:14.675377       1 scheduler.go:70] Estado real no cluster: map[controller:test-controller3]
I0121 15:46:14.675383       1 scheduler.go:138] [WaitForPodsOnCache] Pod test-deployment3-6c95cffb97-bpsqd encontrado no cache.
I0121 15:46:14.675388       1 scheduler.go:116] [WaitForPodsOnCache] Verificando se o pod test-deployment3-6c95cffb97-t2wrq está no cache...
I0121 15:46:14.675393       1 scheduler.go:564] [GetControllerMetricInfo] Iniciando para o pod: default/test-deployment3-6c95cffb97-t2wrq
I0121 15:46:14.675398       1 scheduler.go:569] [GetControllerMetricInfo] Obtendo o nome do controlador para o pod: default/test-deployment3-6c95cffb97-t2wrq
I0121 15:46:14.675404       1 types.go:743] [ControllerName] Verificando as anotações do pod default/test-deployment3-6c95cffb97-t2wrq
I0121 15:46:14.675409       1 types.go:761] [ControllerName] Anotação 'controller' encontrada para o pod default/test-deployment3-6c95cffb97-t2wrq: test-controller3
I0121 15:46:14.675415       1 scheduler.go:572] [GetControllerMetricInfo] Métricas do controlador definidas para o pod: default/test-deployment3-6c95cffb97-t2wrq
I0121 15:46:14.696326       1 scheduler.go:69] Estado no Informer: map[controller:test-controller3]
I0121 15:46:14.696532       1 scheduler.go:70] Estado real no cluster: map[controller:test-controller3]
I0121 15:46:14.696577       1 scheduler.go:138] [WaitForPodsOnCache] Pod test-deployment3-6c95cffb97-t2wrq encontrado no cache.
I0121 15:46:14.696799       1 scheduler.go:564] [GetControllerMetricInfo] Iniciando para o pod: default/test-deployment3-6c95cffb97-bpsqd
I0121 15:46:14.696845       1 scheduler.go:569] [GetControllerMetricInfo] Obtendo o nome do controlador para o pod: default/test-deployment3-6c95cffb97-bpsqd
I0121 15:46:14.696942       1 types.go:743] [ControllerName] Verificando as anotações do pod default/test-deployment3-6c95cffb97-bpsqd
I0121 15:46:14.697058       1 types.go:761] [ControllerName] Anotação 'controller' encontrada para o pod default/test-deployment3-6c95cffb97-bpsqd: test-controller3
I0121 15:46:14.697179       1 scheduler.go:572] [GetControllerMetricInfo] Métricas do controlador definidas para o pod: default/test-deployment3-6c95cffb97-bpsqd
I0121 15:46:14.697200       1 scheduler.go:564] [GetControllerMetricInfo] Iniciando para o pod: default/test-deployment3-6c95cffb97-t2wrq
I0121 15:46:14.697214       1 scheduler.go:569] [GetControllerMetricInfo] Obtendo o nome do controlador para o pod: default/test-deployment3-6c95cffb97-t2wrq
I0121 15:46:14.697277       1 types.go:743] [ControllerName] Verificando as anotações do pod default/test-deployment3-6c95cffb97-t2wrq
I0121 15:46:14.697385       1 types.go:761] [ControllerName] Anotação 'controller' encontrada para o pod default/test-deployment3-6c95cffb97-t2wrq: test-controller3
I0121 15:46:14.697477       1 scheduler.go:572] [GetControllerMetricInfo] Métricas do controlador definidas para o pod: default/test-deployment3-6c95cffb97-t2wrq
I0121 15:46:14.697618       1 scheduler.go:97] [HigherPrecedence] Métricas para test-deployment3-6c95cffb97-bpsqd: QoS = 75.571614, Importância = 0.80
I0121 15:46:14.697661       1 scheduler.go:98] [HigherPrecedence] Métricas para test-deployment3-6c95cffb97-t2wrq: QoS = 33.541458, Importância = 0.80
I0121 15:46:14.697759       1 scheduler.go:109] [HigherPrecedence] Decisão final: test-deployment3-6c95cffb97-bpsqd tem precedência sobre test-deployment3-6c95cffb97-t2wrq? false
I0121 15:46:14.697924       1 postFilter.go:142] [PREEMPT CALL] No node was chosen to allocate pod test-deployment3-6c95cffb97-bpsqd
I0121 15:46:15.263892       1 scheduler.go:247] [OnUpdatePod] Pod atualizado: default/test-deployment3-6c95cffb97-bpsqd, Anotações: map[controller:test-controller3]
I0121 15:46:15.271095       1 scheduler.go:69] Estado no Informer: map[controller:test-controller3]
I0121 15:46:15.271421       1 scheduler.go:70] Estado real no cluster: map[controller:test-controller3]
I0121 15:46:15.271649       1 types.go:743] [ControllerName] Verificando as anotações do pod default/test-deployment3-6c95cffb97-bpsqd
I0121 15:46:15.271767       1 types.go:761] [ControllerName] Anotação 'controller' encontrada para o pod default/test-deployment3-6c95cffb97-bpsqd: test-controller3
I0121 15:46:16.978229       1 types.go:743] [ControllerName] Verificando as anotações do pod default/test-deployment3-6c95cffb97-t2wrq
I0121 15:46:16.978808       1 types.go:761] [ControllerName] Anotação 'controller' encontrada para o pod default/test-deployment3-6c95cffb97-t2wrq: test-controller3
I0121 15:46:16.978383       1 postFilter.go:74] Comparando pod original com o atualizado...
I0121 15:46:16.979008       1 postFilter.go:81] Successfully retrieved updated pod default/test-deployment3-6c95cffb97-bpsqd from lister
I0121 15:46:16.995766       1 postFilter.go:204] Recursos CPU do nó minikube estão sincronizados: 2000 mCPU
I0121 15:46:16.995837       1 postFilter.go:211] Recursos Memória do nó minikube estão sincronizados: 2216124416 bytes
I0121 15:46:16.998337       1 postFilter.go:145] [PREEMPT CALL] The node minikube  was chosen to allocate pod test-deployment3-6c95cffb97-bpsqd
I0121 15:46:16.998551       1 scheduler.go:83] [HigherPrecedence] Calculando precedência entre test-deployment3-6c95cffb97-bpsqd e test-deployment2-59c6b78cd5-zcbs6
I0121 15:46:16.998567       1 scheduler.go:116] [WaitForPodsOnCache] Verificando se o pod test-deployment3-6c95cffb97-bpsqd está no cache...
I0121 15:46:16.998578       1 scheduler.go:564] [GetControllerMetricInfo] Iniciando para o pod: default/test-deployment3-6c95cffb97-bpsqd
I0121 15:46:16.998587       1 scheduler.go:569] [GetControllerMetricInfo] Obtendo o nome do controlador para o pod: default/test-deployment3-6c95cffb97-bpsqd
I0121 15:46:16.998597       1 types.go:743] [ControllerName] Verificando as anotações do pod default/test-deployment3-6c95cffb97-bpsqd
I0121 15:46:16.998607       1 types.go:761] [ControllerName] Anotação 'controller' encontrada para o pod default/test-deployment3-6c95cffb97-bpsqd: test-controller3
I0121 15:46:16.998618       1 scheduler.go:572] [GetControllerMetricInfo] Métricas do controlador definidas para o pod: default/test-deployment3-6c95cffb97-bpsqd
I0121 15:46:17.005946       1 scheduler.go:69] Estado no Informer: map[controller:test-controller3]
I0121 15:46:17.006097       1 scheduler.go:70] Estado real no cluster: map[controller:test-controller3]
I0121 15:46:17.006188       1 scheduler.go:138] [WaitForPodsOnCache] Pod test-deployment3-6c95cffb97-bpsqd encontrado no cache.
I0121 15:46:17.006220       1 scheduler.go:116] [WaitForPodsOnCache] Verificando se o pod test-deployment2-59c6b78cd5-zcbs6 está no cache...
I0121 15:46:17.006575       1 scheduler.go:564] [GetControllerMetricInfo] Iniciando para o pod: default/test-deployment2-59c6b78cd5-zcbs6
I0121 15:46:17.008619       1 scheduler.go:569] [GetControllerMetricInfo] Obtendo o nome do controlador para o pod: default/test-deployment2-59c6b78cd5-zcbs6
I0121 15:46:17.008726       1 types.go:743] [ControllerName] Verificando as anotações do pod default/test-deployment2-59c6b78cd5-zcbs6
I0121 15:46:17.008738       1 types.go:761] [ControllerName] Anotação 'controller' encontrada para o pod default/test-deployment2-59c6b78cd5-zcbs6: test-controller2
I0121 15:46:17.008748       1 scheduler.go:572] [GetControllerMetricInfo] Métricas do controlador definidas para o pod: default/test-deployment2-59c6b78cd5-zcbs6
I0121 15:46:17.014618       1 scheduler.go:69] Estado no Informer: map[controller:test-controller2]
I0121 15:46:17.014702       1 scheduler.go:70] Estado real no cluster: map[controller:test-controller2]
I0121 15:46:17.014713       1 scheduler.go:138] [WaitForPodsOnCache] Pod test-deployment2-59c6b78cd5-zcbs6 encontrado no cache.
I0121 15:46:17.014721       1 scheduler.go:564] [GetControllerMetricInfo] Iniciando para o pod: default/test-deployment3-6c95cffb97-bpsqd
I0121 15:46:17.014731       1 scheduler.go:569] [GetControllerMetricInfo] Obtendo o nome do controlador para o pod: default/test-deployment3-6c95cffb97-bpsqd
I0121 15:46:17.014738       1 types.go:743] [ControllerName] Verificando as anotações do pod default/test-deployment3-6c95cffb97-bpsqd
I0121 15:46:17.014746       1 types.go:761] [ControllerName] Anotação 'controller' encontrada para o pod default/test-deployment3-6c95cffb97-bpsqd: test-controller3
I0121 15:46:17.014753       1 scheduler.go:572] [GetControllerMetricInfo] Métricas do controlador definidas para o pod: default/test-deployment3-6c95cffb97-bpsqd
I0121 15:46:17.014767       1 scheduler.go:564] [GetControllerMetricInfo] Iniciando para o pod: default/test-deployment2-59c6b78cd5-zcbs6
I0121 15:46:17.014773       1 scheduler.go:569] [GetControllerMetricInfo] Obtendo o nome do controlador para o pod: default/test-deployment2-59c6b78cd5-zcbs6
I0121 15:46:17.014778       1 types.go:743] [ControllerName] Verificando as anotações do pod default/test-deployment2-59c6b78cd5-zcbs6
I0121 15:46:17.014789       1 types.go:761] [ControllerName] Anotação 'controller' encontrada para o pod default/test-deployment2-59c6b78cd5-zcbs6: test-controller2
I0121 15:46:17.014795       1 scheduler.go:572] [GetControllerMetricInfo] Métricas do controlador definidas para o pod: default/test-deployment2-59c6b78cd5-zcbs6
I0121 15:46:17.014809       1 scheduler.go:97] [HigherPrecedence] Métricas para test-deployment3-6c95cffb97-bpsqd: QoS = 73.815174, Importância = 0.80
I0121 15:46:17.014848       1 scheduler.go:98] [HigherPrecedence] Métricas para test-deployment2-59c6b78cd5-zcbs6: QoS = -312.799553, Importância = 0.80
I0121 15:46:17.014859       1 scheduler.go:109] [HigherPrecedence] Decisão final: test-deployment3-6c95cffb97-bpsqd tem precedência sobre test-deployment2-59c6b78cd5-zcbs6? false
I0121 15:46:17.034941       1 scheduler.go:247] [OnUpdatePod] Pod atualizado: default/test-deployment3-6c95cffb97-bpsqd, Anotações: map[controller:test-controller3]
I0121 15:46:17.038402       1 scheduler.go:69] Estado no Informer: map[controller:test-controller3]
I0121 15:46:17.038560       1 scheduler.go:70] Estado real no cluster: map[controller:test-controller3]
I0121 15:46:17.038751       1 types.go:743] [ControllerName] Verificando as anotações do pod default/test-deployment3-6c95cffb97-bpsqd
I0121 15:46:17.039061       1 types.go:761] [ControllerName] Anotação 'controller' encontrada para o pod default/test-deployment3-6c95cffb97-bpsqd: test-controller3
I0121 15:46:22.822948       1 postFilter.go:74] Comparando pod original com o atualizado...
I0121 15:46:22.823198       1 postFilter.go:81] Successfully retrieved updated pod default/test-deployment2-59c6b78cd5-zcbs6 from lister
I0121 15:46:22.833723       1 postFilter.go:204] Recursos CPU do nó minikube estão sincronizados: 2000 mCPU
I0121 15:46:22.833823       1 postFilter.go:211] Recursos Memória do nó minikube estão sincronizados: 2216124416 bytes
I0121 15:46:22.834604       1 postFilter.go:145] [PREEMPT CALL] The node minikube  was chosen to allocate pod test-deployment2-59c6b78cd5-zcbs6
W0121 15:46:22.835003       1 scheduler.go:78] [HigherPrecedence] Tentativa de comparar o pod test-deployment2-59c6b78cd5-zcbs6 consigo mesmo. Retornando false.
I0121 15:46:22.835083       1 scheduler.go:83] [HigherPrecedence] Calculando precedência entre test-deployment2-59c6b78cd5-zcbs6 e test-deployment3-6c95cffb97-bpsqd
I0121 15:46:22.835099       1 scheduler.go:116] [WaitForPodsOnCache] Verificando se o pod test-deployment2-59c6b78cd5-zcbs6 está no cache...
I0121 15:46:22.835113       1 scheduler.go:564] [GetControllerMetricInfo] Iniciando para o pod: default/test-deployment2-59c6b78cd5-zcbs6
I0121 15:46:22.835126       1 scheduler.go:569] [GetControllerMetricInfo] Obtendo o nome do controlador para o pod: default/test-deployment2-59c6b78cd5-zcbs6
I0121 15:46:22.835139       1 types.go:743] [ControllerName] Verificando as anotações do pod default/test-deployment2-59c6b78cd5-zcbs6
I0121 15:46:22.835316       1 types.go:761] [ControllerName] Anotação 'controller' encontrada para o pod default/test-deployment2-59c6b78cd5-zcbs6: test-controller2
I0121 15:46:22.835393       1 scheduler.go:572] [GetControllerMetricInfo] Métricas do controlador definidas para o pod: default/test-deployment2-59c6b78cd5-zcbs6
I0121 15:46:22.842819       1 scheduler.go:69] Estado no Informer: map[controller:test-controller2]
I0121 15:46:22.843043       1 scheduler.go:70] Estado real no cluster: map[controller:test-controller2]
I0121 15:46:22.843431       1 scheduler.go:138] [WaitForPodsOnCache] Pod test-deployment2-59c6b78cd5-zcbs6 encontrado no cache.
I0121 15:46:22.843703       1 scheduler.go:116] [WaitForPodsOnCache] Verificando se o pod test-deployment3-6c95cffb97-bpsqd está no cache...
I0121 15:46:22.844050       1 scheduler.go:564] [GetControllerMetricInfo] Iniciando para o pod: default/test-deployment3-6c95cffb97-bpsqd
I0121 15:46:22.844903       1 scheduler.go:569] [GetControllerMetricInfo] Obtendo o nome do controlador para o pod: default/test-deployment3-6c95cffb97-bpsqd
I0121 15:46:22.845070       1 types.go:743] [ControllerName] Verificando as anotações do pod default/test-deployment3-6c95cffb97-bpsqd
I0121 15:46:22.845701       1 types.go:761] [ControllerName] Anotação 'controller' encontrada para o pod default/test-deployment3-6c95cffb97-bpsqd: test-controller3
I0121 15:46:22.846068       1 scheduler.go:572] [GetControllerMetricInfo] Métricas do controlador definidas para o pod: default/test-deployment3-6c95cffb97-bpsqd
I0121 15:46:22.851948       1 scheduler.go:69] Estado no Informer: map[controller:test-controller3]
I0121 15:46:22.852061       1 scheduler.go:70] Estado real no cluster: map[controller:test-controller3]
I0121 15:46:22.852082       1 scheduler.go:138] [WaitForPodsOnCache] Pod test-deployment3-6c95cffb97-bpsqd encontrado no cache.
I0121 15:46:22.852095       1 scheduler.go:564] [GetControllerMetricInfo] Iniciando para o pod: default/test-deployment2-59c6b78cd5-zcbs6
I0121 15:46:22.852108       1 scheduler.go:569] [GetControllerMetricInfo] Obtendo o nome do controlador para o pod: default/test-deployment2-59c6b78cd5-zcbs6
I0121 15:46:22.852120       1 types.go:743] [ControllerName] Verificando as anotações do pod default/test-deployment2-59c6b78cd5-zcbs6
I0121 15:46:22.852132       1 types.go:761] [ControllerName] Anotação 'controller' encontrada para o pod default/test-deployment2-59c6b78cd5-zcbs6: test-controller2
I0121 15:46:22.852146       1 scheduler.go:572] [GetControllerMetricInfo] Métricas do controlador definidas para o pod: default/test-deployment2-59c6b78cd5-zcbs6
I0121 15:46:22.852164       1 scheduler.go:564] [GetControllerMetricInfo] Iniciando para o pod: default/test-deployment3-6c95cffb97-bpsqd
I0121 15:46:22.852176       1 scheduler.go:569] [GetControllerMetricInfo] Obtendo o nome do controlador para o pod: default/test-deployment3-6c95cffb97-bpsqd
I0121 15:46:22.852186       1 types.go:743] [ControllerName] Verificando as anotações do pod default/test-deployment3-6c95cffb97-bpsqd
I0121 15:46:22.852198       1 types.go:761] [ControllerName] Anotação 'controller' encontrada para o pod default/test-deployment3-6c95cffb97-bpsqd: test-controller3
I0121 15:46:22.852210       1 scheduler.go:572] [GetControllerMetricInfo] Métricas do controlador definidas para o pod: default/test-deployment3-6c95cffb97-bpsqd
I0121 15:46:22.852777       1 scheduler.go:97] [HigherPrecedence] Métricas para test-deployment2-59c6b78cd5-zcbs6: QoS = -318.636178, Importância = 0.80
I0121 15:46:22.852864       1 scheduler.go:98] [HigherPrecedence] Métricas para test-deployment3-6c95cffb97-bpsqd: QoS = 67.978549, Importância = 0.80
I0121 15:46:22.852886       1 scheduler.go:109] [HigherPrecedence] Decisão final: test-deployment2-59c6b78cd5-zcbs6 tem precedência sobre test-deployment3-6c95cffb97-bpsqd? true
I0121 15:46:22.881607       1 scheduler.go:247] [OnUpdatePod] Pod atualizado: default/test-deployment3-6c95cffb97-bpsqd, Anotações: map[controller:test-controller3]
I0121 15:46:22.890906       1 scheduler.go:69] Estado no Informer: map[controller:test-controller3]
I0121 15:46:22.891374       1 scheduler.go:70] Estado real no cluster: map[controller:test-controller3]
I0121 15:46:22.891690       1 types.go:743] [ControllerName] Verificando as anotações do pod default/test-deployment3-6c95cffb97-bpsqd
I0121 15:46:22.892148       1 types.go:761] [ControllerName] Anotação 'controller' encontrada para o pod default/test-deployment3-6c95cffb97-bpsqd: test-controller3
I0121 15:51:44.451929       1 scheduler.go:53] [QueueSort] Comparando prioridade de test-deployment2-59c6b78cd5-zcbs6 com test-deployment3-6c95cffb97-bpsqd
I0121 15:51:44.452005       1 scheduler.go:83] [HigherPrecedence] Calculando precedência entre test-deployment2-59c6b78cd5-zcbs6 e test-deployment3-6c95cffb97-bpsqd
I0121 15:51:44.452023       1 scheduler.go:116] [WaitForPodsOnCache] Verificando se o pod test-deployment2-59c6b78cd5-zcbs6 está no cache...
I0121 15:51:44.452055       1 scheduler.go:564] [GetControllerMetricInfo] Iniciando para o pod: default/test-deployment2-59c6b78cd5-zcbs6
I0121 15:51:44.452068       1 scheduler.go:569] [GetControllerMetricInfo] Obtendo o nome do controlador para o pod: default/test-deployment2-59c6b78cd5-zcbs6
I0121 15:51:44.452084       1 types.go:743] [ControllerName] Verificando as anotações do pod default/test-deployment2-59c6b78cd5-zcbs6
I0121 15:51:44.452109       1 types.go:761] [ControllerName] Anotação 'controller' encontrada para o pod default/test-deployment2-59c6b78cd5-zcbs6: test-controller2
I0121 15:51:44.452125       1 scheduler.go:572] [GetControllerMetricInfo] Métricas do controlador definidas para o pod: default/test-deployment2-59c6b78cd5-zcbs6
I0121 15:51:44.635684       1 scheduler.go:69] Estado no Informer: map[controller:test-controller2]
I0121 15:51:44.636082       1 scheduler.go:70] Estado real no cluster: map[controller:test-controller2]
I0121 15:51:44.636253       1 scheduler.go:138] [WaitForPodsOnCache] Pod test-deployment2-59c6b78cd5-zcbs6 encontrado no cache.
I0121 15:51:44.636686       1 scheduler.go:116] [WaitForPodsOnCache] Verificando se o pod test-deployment3-6c95cffb97-bpsqd está no cache...
I0121 15:51:44.636870       1 scheduler.go:564] [GetControllerMetricInfo] Iniciando para o pod: default/test-deployment3-6c95cffb97-bpsqd
I0121 15:51:44.637095       1 scheduler.go:569] [GetControllerMetricInfo] Obtendo o nome do controlador para o pod: default/test-deployment3-6c95cffb97-bpsqd
I0121 15:51:44.637203       1 types.go:743] [ControllerName] Verificando as anotações do pod default/test-deployment3-6c95cffb97-bpsqd
I0121 15:51:44.637402       1 types.go:761] [ControllerName] Anotação 'controller' encontrada para o pod default/test-deployment3-6c95cffb97-bpsqd: test-controller3
I0121 15:51:44.637454       1 scheduler.go:572] [GetControllerMetricInfo] Métricas do controlador definidas para o pod: default/test-deployment3-6c95cffb97-bpsqd
I0121 15:51:44.643942       1 scheduler.go:69] Estado no Informer: map[controller:test-controller3]
I0121 15:51:44.643982       1 scheduler.go:70] Estado real no cluster: map[controller:test-controller3]
I0121 15:51:44.643997       1 scheduler.go:138] [WaitForPodsOnCache] Pod test-deployment3-6c95cffb97-bpsqd encontrado no cache.
I0121 15:51:44.644010       1 scheduler.go:564] [GetControllerMetricInfo] Iniciando para o pod: default/test-deployment2-59c6b78cd5-zcbs6
I0121 15:51:44.644021       1 scheduler.go:569] [GetControllerMetricInfo] Obtendo o nome do controlador para o pod: default/test-deployment2-59c6b78cd5-zcbs6
I0121 15:51:44.644033       1 types.go:743] [ControllerName] Verificando as anotações do pod default/test-deployment2-59c6b78cd5-zcbs6
I0121 15:51:44.644045       1 types.go:761] [ControllerName] Anotação 'controller' encontrada para o pod default/test-deployment2-59c6b78cd5-zcbs6: test-controller2
I0121 15:51:44.644059       1 scheduler.go:572] [GetControllerMetricInfo] Métricas do controlador definidas para o pod: default/test-deployment2-59c6b78cd5-zcbs6
I0121 15:51:44.644119       1 scheduler.go:564] [GetControllerMetricInfo] Iniciando para o pod: default/test-deployment3-6c95cffb97-bpsqd
I0121 15:51:44.644130       1 scheduler.go:569] [GetControllerMetricInfo] Obtendo o nome do controlador para o pod: default/test-deployment3-6c95cffb97-bpsqd
I0121 15:51:44.644143       1 types.go:743] [ControllerName] Verificando as anotações do pod default/test-deployment3-6c95cffb97-bpsqd
I0121 15:51:44.644153       1 types.go:761] [ControllerName] Anotação 'controller' encontrada para o pod default/test-deployment3-6c95cffb97-bpsqd: test-controller3
I0121 15:51:44.644164       1 scheduler.go:572] [GetControllerMetricInfo] Métricas do controlador definidas para o pod: default/test-deployment3-6c95cffb97-bpsqd
I0121 15:51:44.645647       1 scheduler.go:97] [HigherPrecedence] Métricas para test-deployment2-59c6b78cd5-zcbs6: QoS = -640.253101, Importância = 0.80
I0121 15:51:44.645792       1 scheduler.go:98] [HigherPrecedence] Métricas para test-deployment3-6c95cffb97-bpsqd: QoS = -253.638373, Importância = 0.80
I0121 15:51:44.645813       1 scheduler.go:109] [HigherPrecedence] Decisão final: test-deployment2-59c6b78cd5-zcbs6 tem precedência sobre test-deployment3-6c95cffb97-bpsqd? true
I0121 15:51:44.645828       1 scheduler.go:59] [QueueSort] Precedência determinada: test-deployment2-59c6b78cd5-zcbs6 tem precedência sobre test-deployment3-6c95cffb97-bpsqd? true
I0121 15:51:44.647912       1 scheduler.go:145] [Reserve] resources reserved at node minikube for pod test-deployment2-59c6b78cd5-zcbs6_default at 2025-01-21 15:51:44.647896341 +0000 UTC m=+721.302465104
I0121 15:51:44.648015       1 types.go:743] [ControllerName] Verificando as anotações do pod default/test-deployment2-59c6b78cd5-zcbs6
I0121 15:51:44.648031       1 types.go:761] [ControllerName] Anotação 'controller' encontrada para o pod default/test-deployment2-59c6b78cd5-zcbs6: test-controller2
I0121 15:51:44.648069       1 scheduler.go:147] [Reserve] Status de alocação atual para o pod test-deployment2-59c6b78cd5-zcbs6_default: 
I0121 15:51:44.648085       1 scheduler.go:149] [Reserve] Status de alocação atualizado para o pod test-deployment2-59c6b78cd5-zcbs6_default: allocating
I0121 15:51:44.649005       1 postFilter.go:74] Comparando pod original com o atualizado...
I0121 15:51:44.649097       1 postFilter.go:81] Successfully retrieved updated pod default/test-deployment3-6c95cffb97-bpsqd from lister
I0121 15:51:44.649235       1 scheduler.go:173] [PreBind] Validando o pod test-deployment2-59c6b78cd5-zcbs6 antes de vincular ao node minikube
I0121 15:51:44.659227       1 postFilter.go:204] Recursos CPU do nó minikube estão sincronizados: 2000 mCPU
I0121 15:51:44.659578       1 postFilter.go:211] Recursos Memória do nó minikube estão sincronizados: 2216124416 bytes
I0121 15:51:44.660841       1 scheduler.go:564] [GetControllerMetricInfo] Iniciando para o pod: default/test-deployment2-59c6b78cd5-zcbs6
I0121 15:51:44.667408       1 scheduler.go:569] [GetControllerMetricInfo] Obtendo o nome do controlador para o pod: default/test-deployment2-59c6b78cd5-zcbs6
I0121 15:51:44.667713       1 types.go:743] [ControllerName] Verificando as anotações do pod default/test-deployment2-59c6b78cd5-zcbs6
I0121 15:51:44.668103       1 types.go:761] [ControllerName] Anotação 'controller' encontrada para o pod default/test-deployment2-59c6b78cd5-zcbs6: test-controller2
I0121 15:51:44.668353       1 scheduler.go:572] [GetControllerMetricInfo] Métricas do controlador definidas para o pod: default/test-deployment2-59c6b78cd5-zcbs6
I0121 15:51:44.669847       1 scheduler.go:83] [HigherPrecedence] Calculando precedência entre test-deployment3-6c95cffb97-bpsqd e test-deployment2-59c6b78cd5-zcbs6
I0121 15:51:44.670105       1 scheduler.go:116] [WaitForPodsOnCache] Verificando se o pod test-deployment3-6c95cffb97-bpsqd está no cache...
I0121 15:51:44.670308       1 scheduler.go:564] [GetControllerMetricInfo] Iniciando para o pod: default/test-deployment3-6c95cffb97-bpsqd
I0121 15:51:44.670658       1 scheduler.go:569] [GetControllerMetricInfo] Obtendo o nome do controlador para o pod: default/test-deployment3-6c95cffb97-bpsqd
I0121 15:51:44.671074       1 types.go:743] [ControllerName] Verificando as anotações do pod default/test-deployment3-6c95cffb97-bpsqd
I0121 15:51:44.671561       1 types.go:761] [ControllerName] Anotação 'controller' encontrada para o pod default/test-deployment3-6c95cffb97-bpsqd: test-controller3
I0121 15:51:44.671934       1 scheduler.go:572] [GetControllerMetricInfo] Métricas do controlador definidas para o pod: default/test-deployment3-6c95cffb97-bpsqd
I0121 15:51:44.679278       1 scheduler.go:181] [PostBind] Chamado para pod test-deployment2-59c6b78cd5-zcbs6
I0121 15:51:44.680545       1 scheduler.go:199] [PostBind] Pod test-deployment2-59c6b78cd5-zcbs6 - Início do binding: 2025-01-21 15:51:44.64945269 +0000 UTC m=+721.304022008, Fim do binding: 2025-01-21 15:51:44.680450407 +0000 UTC m=+721.335019430
I0121 15:51:44.689539       1 scheduler.go:247] [OnUpdatePod] Pod atualizado: default/test-deployment2-59c6b78cd5-zcbs6, Anotações: map[controller:test-controller2]
I0121 15:51:44.692982       1 scheduler.go:69] Estado no Informer: map[controller:test-controller3]
I0121 15:51:44.693157       1 scheduler.go:70] Estado real no cluster: map[controller:test-controller3]
I0121 15:51:44.693281       1 scheduler.go:138] [WaitForPodsOnCache] Pod test-deployment3-6c95cffb97-bpsqd encontrado no cache.
I0121 15:51:44.693371       1 scheduler.go:116] [WaitForPodsOnCache] Verificando se o pod test-deployment2-59c6b78cd5-zcbs6 está no cache...
I0121 15:51:44.693399       1 scheduler.go:564] [GetControllerMetricInfo] Iniciando para o pod: default/test-deployment2-59c6b78cd5-zcbs6
I0121 15:51:44.693520       1 types.go:743] [ControllerName] Verificando as anotações do pod default/test-deployment2-59c6b78cd5-zcbs6
I0121 15:51:44.693578       1 types.go:761] [ControllerName] Anotação 'controller' encontrada para o pod default/test-deployment2-59c6b78cd5-zcbs6: test-controller2
I0121 15:51:44.693693       1 scheduler.go:206] [PostBind] Métricas atualizadas para o pod test-deployment2-59c6b78cd5-zcbs6
I0121 15:51:44.693819       1 scheduler.go:569] [GetControllerMetricInfo] Obtendo o nome do controlador para o pod: default/test-deployment2-59c6b78cd5-zcbs6
I0121 15:51:44.693968       1 types.go:743] [ControllerName] Verificando as anotações do pod default/test-deployment2-59c6b78cd5-zcbs6
I0121 15:51:44.694080       1 types.go:761] [ControllerName] Anotação 'controller' encontrada para o pod default/test-deployment2-59c6b78cd5-zcbs6: test-controller2
I0121 15:51:44.694134       1 scheduler.go:572] [GetControllerMetricInfo] Métricas do controlador definidas para o pod: default/test-deployment2-59c6b78cd5-zcbs6
I0121 15:51:44.724060       1 scheduler.go:69] Estado no Informer: map[controller:test-controller2]
I0121 15:51:44.724117       1 scheduler.go:70] Estado real no cluster: map[controller:test-controller2]
I0121 15:51:44.724185       1 scheduler.go:69] Estado no Informer: map[controller:test-controller2]
I0121 15:51:44.724195       1 scheduler.go:70] Estado real no cluster: map[controller:test-controller2]
I0121 15:51:44.724202       1 scheduler.go:138] [WaitForPodsOnCache] Pod test-deployment2-59c6b78cd5-zcbs6 encontrado no cache.
I0121 15:51:44.724210       1 scheduler.go:564] [GetControllerMetricInfo] Iniciando para o pod: default/test-deployment3-6c95cffb97-bpsqd
I0121 15:51:44.724222       1 types.go:743] [ControllerName] Verificando as anotações do pod default/test-deployment2-59c6b78cd5-zcbs6
I0121 15:51:44.724229       1 types.go:761] [ControllerName] Anotação 'controller' encontrada para o pod default/test-deployment2-59c6b78cd5-zcbs6: test-controller2
I0121 15:51:44.724447       1 scheduler.go:247] [OnUpdatePod] Pod atualizado: default/test-deployment2-59c6b78cd5-zcbs6, Anotações: map[controller:test-controller2]
I0121 15:51:44.728934       1 scheduler.go:69] Estado no Informer: map[controller:test-controller2]
I0121 15:51:44.728985       1 scheduler.go:70] Estado real no cluster: map[controller:test-controller2]
I0121 15:51:44.729632       1 scheduler.go:569] [GetControllerMetricInfo] Obtendo o nome do controlador para o pod: default/test-deployment3-6c95cffb97-bpsqd
I0121 15:51:44.729823       1 types.go:743] [ControllerName] Verificando as anotações do pod default/test-deployment3-6c95cffb97-bpsqd
I0121 15:51:44.730034       1 types.go:761] [ControllerName] Anotação 'controller' encontrada para o pod default/test-deployment3-6c95cffb97-bpsqd: test-controller3
I0121 15:51:44.730347       1 scheduler.go:572] [GetControllerMetricInfo] Métricas do controlador definidas para o pod: default/test-deployment3-6c95cffb97-bpsqd
I0121 15:51:44.731735       1 types.go:743] [ControllerName] Verificando as anotações do pod default/test-deployment2-59c6b78cd5-zcbs6
I0121 15:51:44.732013       1 types.go:761] [ControllerName] Anotação 'controller' encontrada para o pod default/test-deployment2-59c6b78cd5-zcbs6: test-controller2
I0121 15:51:44.732696       1 scheduler.go:564] [GetControllerMetricInfo] Iniciando para o pod: default/test-deployment2-59c6b78cd5-zcbs6
I0121 15:51:44.732961       1 scheduler.go:569] [GetControllerMetricInfo] Obtendo o nome do controlador para o pod: default/test-deployment2-59c6b78cd5-zcbs6
I0121 15:51:44.733306       1 types.go:743] [ControllerName] Verificando as anotações do pod default/test-deployment2-59c6b78cd5-zcbs6
I0121 15:51:44.733663       1 types.go:761] [ControllerName] Anotação 'controller' encontrada para o pod default/test-deployment2-59c6b78cd5-zcbs6: test-controller2
I0121 15:51:44.734006       1 scheduler.go:572] [GetControllerMetricInfo] Métricas do controlador definidas para o pod: default/test-deployment2-59c6b78cd5-zcbs6
I0121 15:51:44.734452       1 scheduler.go:97] [HigherPrecedence] Métricas para test-deployment3-6c95cffb97-bpsqd: QoS = -253.855190, Importância = 0.80
I0121 15:51:44.734959       1 scheduler.go:98] [HigherPrecedence] Métricas para test-deployment2-59c6b78cd5-zcbs6: QoS = -640.499963, Importância = 0.80
I0121 15:51:44.735446       1 scheduler.go:109] [HigherPrecedence] Decisão final: test-deployment3-6c95cffb97-bpsqd tem precedência sobre test-deployment2-59c6b78cd5-zcbs6? false
I0121 15:51:44.736338       1 postFilter.go:142] [PREEMPT CALL] No node was chosen to allocate pod test-deployment3-6c95cffb97-bpsqd
I0121 15:51:48.927139       1 scheduler.go:247] [OnUpdatePod] Pod atualizado: default/test-deployment2-59c6b78cd5-zcbs6, Anotações: map[controller:test-controller2]
I0121 15:51:48.935951       1 scheduler.go:69] Estado no Informer: map[controller:test-controller2]
I0121 15:51:48.936046       1 scheduler.go:70] Estado real no cluster: map[controller:test-controller2]
I0121 15:51:48.936066       1 types.go:743] [ControllerName] Verificando as anotações do pod default/test-deployment2-59c6b78cd5-zcbs6
I0121 15:51:48.936078       1 types.go:761] [ControllerName] Anotação 'controller' encontrada para o pod default/test-deployment2-59c6b78cd5-zcbs6: test-controller2
I0121 15:51:49.119425       1 postFilter.go:74] Comparando pod original com o atualizado...
I0121 15:51:49.119647       1 postFilter.go:81] Successfully retrieved updated pod default/test-deployment3-6c95cffb97-bpsqd from lister
I0121 15:51:49.127613       1 postFilter.go:204] Recursos CPU do nó minikube estão sincronizados: 2000 mCPU
I0121 15:51:49.128291       1 postFilter.go:211] Recursos Memória do nó minikube estão sincronizados: 2216124416 bytes
I0121 15:51:49.129746       1 scheduler.go:564] [GetControllerMetricInfo] Iniciando para o pod: default/test-deployment2-59c6b78cd5-zcbs6
I0121 15:51:49.130415       1 scheduler.go:569] [GetControllerMetricInfo] Obtendo o nome do controlador para o pod: default/test-deployment2-59c6b78cd5-zcbs6
I0121 15:51:49.131090       1 types.go:743] [ControllerName] Verificando as anotações do pod default/test-deployment2-59c6b78cd5-zcbs6
I0121 15:51:49.131752       1 types.go:761] [ControllerName] Anotação 'controller' encontrada para o pod default/test-deployment2-59c6b78cd5-zcbs6: test-controller2
I0121 15:51:49.131801       1 scheduler.go:572] [GetControllerMetricInfo] Métricas do controlador definidas para o pod: default/test-deployment2-59c6b78cd5-zcbs6
I0121 15:51:49.131820       1 scheduler.go:83] [HigherPrecedence] Calculando precedência entre test-deployment3-6c95cffb97-bpsqd e test-deployment2-59c6b78cd5-zcbs6
I0121 15:51:49.131834       1 scheduler.go:116] [WaitForPodsOnCache] Verificando se o pod test-deployment3-6c95cffb97-bpsqd está no cache...
I0121 15:51:49.131853       1 scheduler.go:564] [GetControllerMetricInfo] Iniciando para o pod: default/test-deployment3-6c95cffb97-bpsqd
I0121 15:51:49.131946       1 scheduler.go:569] [GetControllerMetricInfo] Obtendo o nome do controlador para o pod: default/test-deployment3-6c95cffb97-bpsqd
I0121 15:51:49.132033       1 types.go:743] [ControllerName] Verificando as anotações do pod default/test-deployment3-6c95cffb97-bpsqd
I0121 15:51:49.132047       1 types.go:761] [ControllerName] Anotação 'controller' encontrada para o pod default/test-deployment3-6c95cffb97-bpsqd: test-controller3
I0121 15:51:49.132120       1 scheduler.go:572] [GetControllerMetricInfo] Métricas do controlador definidas para o pod: default/test-deployment3-6c95cffb97-bpsqd
I0121 15:51:49.146609       1 scheduler.go:69] Estado no Informer: map[controller:test-controller3]
I0121 15:51:49.151662       1 scheduler.go:70] Estado real no cluster: map[controller:test-controller3]
I0121 15:51:49.153224       1 scheduler.go:138] [WaitForPodsOnCache] Pod test-deployment3-6c95cffb97-bpsqd encontrado no cache.
I0121 15:51:49.153306       1 scheduler.go:116] [WaitForPodsOnCache] Verificando se o pod test-deployment2-59c6b78cd5-zcbs6 está no cache...
I0121 15:51:49.153321       1 scheduler.go:564] [GetControllerMetricInfo] Iniciando para o pod: default/test-deployment2-59c6b78cd5-zcbs6
I0121 15:51:49.153333       1 scheduler.go:569] [GetControllerMetricInfo] Obtendo o nome do controlador para o pod: default/test-deployment2-59c6b78cd5-zcbs6
I0121 15:51:49.153343       1 types.go:743] [ControllerName] Verificando as anotações do pod default/test-deployment2-59c6b78cd5-zcbs6
I0121 15:51:49.153356       1 types.go:761] [ControllerName] Anotação 'controller' encontrada para o pod default/test-deployment2-59c6b78cd5-zcbs6: test-controller2
I0121 15:51:49.153368       1 scheduler.go:572] [GetControllerMetricInfo] Métricas do controlador definidas para o pod: default/test-deployment2-59c6b78cd5-zcbs6
I0121 15:51:49.165072       1 scheduler.go:69] Estado no Informer: map[controller:test-controller2]
I0121 15:51:49.165110       1 scheduler.go:70] Estado real no cluster: map[controller:test-controller2]
I0121 15:51:49.165123       1 scheduler.go:138] [WaitForPodsOnCache] Pod test-deployment2-59c6b78cd5-zcbs6 encontrado no cache.
I0121 15:51:49.165134       1 scheduler.go:564] [GetControllerMetricInfo] Iniciando para o pod: default/test-deployment3-6c95cffb97-bpsqd
I0121 15:51:49.165145       1 scheduler.go:569] [GetControllerMetricInfo] Obtendo o nome do controlador para o pod: default/test-deployment3-6c95cffb97-bpsqd
I0121 15:51:49.165155       1 types.go:743] [ControllerName] Verificando as anotações do pod default/test-deployment3-6c95cffb97-bpsqd
I0121 15:51:49.165167       1 types.go:761] [ControllerName] Anotação 'controller' encontrada para o pod default/test-deployment3-6c95cffb97-bpsqd: test-controller3
I0121 15:51:49.165179       1 scheduler.go:572] [GetControllerMetricInfo] Métricas do controlador definidas para o pod: default/test-deployment3-6c95cffb97-bpsqd
I0121 15:51:49.165195       1 scheduler.go:564] [GetControllerMetricInfo] Iniciando para o pod: default/test-deployment2-59c6b78cd5-zcbs6
I0121 15:51:49.165266       1 scheduler.go:569] [GetControllerMetricInfo] Obtendo o nome do controlador para o pod: default/test-deployment2-59c6b78cd5-zcbs6
I0121 15:51:49.165324       1 types.go:743] [ControllerName] Verificando as anotações do pod default/test-deployment2-59c6b78cd5-zcbs6
I0121 15:51:49.165338       1 types.go:761] [ControllerName] Anotação 'controller' encontrada para o pod default/test-deployment2-59c6b78cd5-zcbs6: test-controller2
I0121 15:51:49.165348       1 scheduler.go:572] [GetControllerMetricInfo] Métricas do controlador definidas para o pod: default/test-deployment2-59c6b78cd5-zcbs6
I0121 15:51:49.165371       1 scheduler.go:97] [HigherPrecedence] Métricas para test-deployment3-6c95cffb97-bpsqd: QoS = -258.318188, Importância = 0.80
I0121 15:51:49.165436       1 scheduler.go:98] [HigherPrecedence] Métricas para test-deployment2-59c6b78cd5-zcbs6: QoS = -639.384214, Importância = 0.80
I0121 15:51:49.165623       1 scheduler.go:109] [HigherPrecedence] Decisão final: test-deployment3-6c95cffb97-bpsqd tem precedência sobre test-deployment2-59c6b78cd5-zcbs6? false
I0121 15:51:49.165782       1 postFilter.go:142] [PREEMPT CALL] No node was chosen to allocate pod test-deployment3-6c95cffb97-bpsqd
I0121 15:55:17.989771       1 scheduler.go:247] [OnUpdatePod] Pod atualizado: default/test-deployment3-6c95cffb97-bpsqd, Anotações: map[controller:test-controller3]
E0121 15:55:18.319631       1 scheduler.go:66] Erro ao buscar estado real do pod test-deployment3-6c95cffb97-bpsqd: pods "test-deployment3-6c95cffb97-bpsqd" not found
I0121 15:55:18.319682       1 types.go:743] [ControllerName] Verificando as anotações do pod default/test-deployment3-6c95cffb97-bpsqd
I0121 15:55:18.319694       1 types.go:761] [ControllerName] Anotação 'controller' encontrada para o pod default/test-deployment3-6c95cffb97-bpsqd: test-controller3
I0121 15:55:18.319734       1 types.go:743] [ControllerName] Verificando as anotações do pod default/test-deployment3-6c95cffb97-bpsqd
I0121 15:55:18.319742       1 types.go:761] [ControllerName] Anotação 'controller' encontrada para o pod default/test-deployment3-6c95cffb97-bpsqd: test-controller3
I0121 15:55:18.320084       1 scheduler.go:247] [OnUpdatePod] Pod atualizado: default/test-deployment2-59c6b78cd5-zcbs6, Anotações: map[controller:test-controller2]
I0121 15:55:18.333146       1 scheduler.go:69] Estado no Informer: map[controller:test-controller2]
I0121 15:55:18.333241       1 scheduler.go:70] Estado real no cluster: map[controller:test-controller2]
I0121 15:55:18.333263       1 types.go:743] [ControllerName] Verificando as anotações do pod default/test-deployment2-59c6b78cd5-zcbs6
I0121 15:55:18.335235       1 types.go:761] [ControllerName] Anotação 'controller' encontrada para o pod default/test-deployment2-59c6b78cd5-zcbs6: test-controller2
I0121 15:55:18.336324       1 types.go:743] [ControllerName] Verificando as anotações do pod default/test-deployment2-59c6b78cd5-zcbs6
I0121 15:55:18.336537       1 types.go:761] [ControllerName] Anotação 'controller' encontrada para o pod default/test-deployment2-59c6b78cd5-zcbs6: test-controller2
I0121 15:55:18.338162       1 types.go:743] [ControllerName] Verificando as anotações do pod default/test-deployment3-6c95cffb97-bpsqd
I0121 15:55:18.338364       1 types.go:761] [ControllerName] Anotação 'controller' encontrada para o pod default/test-deployment3-6c95cffb97-bpsqd: test-controller3
I0121 15:55:19.176887       1 types.go:743] [ControllerName] Verificando as anotações do pod default/test-deployment2-59c6b78cd5-zcbs6
I0121 15:55:19.176978       1 types.go:761] [ControllerName] Anotação 'controller' encontrada para o pod default/test-deployment2-59c6b78cd5-zcbs6: test-controller2
I0121 15:57:34.995841       1 scheduler.go:213] [OnAddPod] Pod adicionado: default/test-deployment2-6594f5cd7f-bjrxt, Anotações: map[controller:test-controller2]
I0121 15:57:34.999877       1 scheduler.go:145] [Reserve] resources reserved at node minikube for pod test-deployment2-6594f5cd7f-bjrxt_default at 2025-01-21 15:57:34.999730434 +0000 UTC m=+1071.654299488
I0121 15:57:35.013669       1 types.go:743] [ControllerName] Verificando as anotações do pod default/test-deployment2-6594f5cd7f-bjrxt
I0121 15:57:35.015089       1 types.go:761] [ControllerName] Anotação 'controller' encontrada para o pod default/test-deployment2-6594f5cd7f-bjrxt: test-controller2
I0121 15:57:35.015398       1 scheduler.go:147] [Reserve] Status de alocação atual para o pod test-deployment2-6594f5cd7f-bjrxt_default: 
I0121 15:57:35.015450       1 scheduler.go:149] [Reserve] Status de alocação atualizado para o pod test-deployment2-6594f5cd7f-bjrxt_default: allocating
I0121 15:57:35.016217       1 scheduler.go:173] [PreBind] Validando o pod test-deployment2-6594f5cd7f-bjrxt antes de vincular ao node minikube
I0121 15:57:35.315238       1 scheduler.go:69] Estado no Informer: map[controller:test-controller2]
I0121 15:57:35.331757       1 scheduler.go:70] Estado real no cluster: map[controller:test-controller2]
I0121 15:57:35.340960       1 types.go:743] [ControllerName] Verificando as anotações do pod default/test-deployment2-6594f5cd7f-bjrxt
I0121 15:57:35.341015       1 types.go:761] [ControllerName] Anotação 'controller' encontrada para o pod default/test-deployment2-6594f5cd7f-bjrxt: test-controller2
I0121 15:57:35.341027       1 types.go:743] [ControllerName] Verificando as anotações do pod default/test-deployment2-6594f5cd7f-bjrxt
I0121 15:57:35.341033       1 types.go:761] [ControllerName] Anotação 'controller' encontrada para o pod default/test-deployment2-6594f5cd7f-bjrxt: test-controller2
I0121 15:57:35.341741       1 scheduler.go:181] [PostBind] Chamado para pod test-deployment2-6594f5cd7f-bjrxt
I0121 15:57:35.341787       1 scheduler.go:199] [PostBind] Pod test-deployment2-6594f5cd7f-bjrxt - Início do binding: 2025-01-21 15:57:35.016419666 +0000 UTC m=+1071.670988468, Fim do binding: 2025-01-21 15:57:35.341781644 +0000 UTC m=+1071.996350384
I0121 15:57:35.342416       1 types.go:743] [ControllerName] Verificando as anotações do pod default/test-deployment2-6594f5cd7f-bjrxt
I0121 15:57:35.343015       1 types.go:761] [ControllerName] Anotação 'controller' encontrada para o pod default/test-deployment2-6594f5cd7f-bjrxt: test-controller2
I0121 15:57:35.343106       1 scheduler.go:206] [PostBind] Métricas atualizadas para o pod test-deployment2-6594f5cd7f-bjrxt
I0121 15:57:35.344153       1 scheduler.go:247] [OnUpdatePod] Pod atualizado: default/test-deployment2-6594f5cd7f-bjrxt, Anotações: map[controller:test-controller2]
I0121 15:57:35.361713       1 scheduler.go:69] Estado no Informer: map[controller:test-controller2]
I0121 15:57:35.362790       1 scheduler.go:70] Estado real no cluster: map[controller:test-controller2]
I0121 15:57:35.362968       1 types.go:743] [ControllerName] Verificando as anotações do pod default/test-deployment2-6594f5cd7f-bjrxt
I0121 15:57:35.363003       1 types.go:761] [ControllerName] Anotação 'controller' encontrada para o pod default/test-deployment2-6594f5cd7f-bjrxt: test-controller2
I0121 15:57:35.363124       1 scheduler.go:247] [OnUpdatePod] Pod atualizado: default/test-deployment2-6594f5cd7f-bjrxt, Anotações: map[controller:test-controller2]
I0121 15:57:35.373381       1 scheduler.go:69] Estado no Informer: map[controller:test-controller2]
I0121 15:57:35.373401       1 scheduler.go:70] Estado real no cluster: map[controller:test-controller2]
I0121 15:57:35.373409       1 types.go:743] [ControllerName] Verificando as anotações do pod default/test-deployment2-6594f5cd7f-bjrxt
I0121 15:57:35.373415       1 types.go:761] [ControllerName] Anotação 'controller' encontrada para o pod default/test-deployment2-6594f5cd7f-bjrxt: test-controller2
I0121 15:57:41.684300       1 scheduler.go:247] [OnUpdatePod] Pod atualizado: default/test-deployment2-6594f5cd7f-bjrxt, Anotações: map[controller:test-controller2]
I0121 15:57:41.699052       1 scheduler.go:69] Estado no Informer: map[controller:test-controller2]
I0121 15:57:41.699174       1 scheduler.go:70] Estado real no cluster: map[controller:test-controller2]
I0121 15:57:41.699612       1 types.go:743] [ControllerName] Verificando as anotações do pod default/test-deployment2-6594f5cd7f-bjrxt
I0121 15:57:41.699689       1 types.go:761] [ControllerName] Anotação 'controller' encontrada para o pod default/test-deployment2-6594f5cd7f-bjrxt: test-controller2
I0121 15:58:08.880393       1 scheduler.go:213] [OnAddPod] Pod adicionado: default/test-deployment3-ff66c7fc9-c5vcz, Anotações: map[controller:test-controller3]
I0121 15:58:08.881201       1 postFilter.go:74] Comparando pod original com o atualizado...
I0121 15:58:08.883422       1 postFilter.go:81] Successfully retrieved updated pod default/test-deployment3-ff66c7fc9-c5vcz from lister
I0121 15:58:08.913918       1 scheduler.go:69] Estado no Informer: map[controller:test-controller3]
I0121 15:58:08.920811       1 scheduler.go:70] Estado real no cluster: map[controller:test-controller3]
I0121 15:58:08.918102       1 postFilter.go:204] Recursos CPU do nó minikube estão sincronizados: 2000 mCPU
I0121 15:58:08.922944       1 postFilter.go:211] Recursos Memória do nó minikube estão sincronizados: 2216124416 bytes
I0121 15:58:08.923691       1 types.go:743] [ControllerName] Verificando as anotações do pod default/test-deployment3-ff66c7fc9-c5vcz
I0121 15:58:08.924012       1 scheduler.go:564] [GetControllerMetricInfo] Iniciando para o pod: default/test-deployment2-6594f5cd7f-bjrxt
I0121 15:58:08.923782       1 types.go:761] [ControllerName] Anotação 'controller' encontrada para o pod default/test-deployment3-ff66c7fc9-c5vcz: test-controller3
I0121 15:58:08.925001       1 types.go:743] [ControllerName] Verificando as anotações do pod default/test-deployment3-ff66c7fc9-c5vcz
I0121 15:58:08.925587       1 types.go:761] [ControllerName] Anotação 'controller' encontrada para o pod default/test-deployment3-ff66c7fc9-c5vcz: test-controller3
I0121 15:58:08.927202       1 scheduler.go:569] [GetControllerMetricInfo] Obtendo o nome do controlador para o pod: default/test-deployment2-6594f5cd7f-bjrxt
I0121 15:58:08.927443       1 types.go:743] [ControllerName] Verificando as anotações do pod default/test-deployment2-6594f5cd7f-bjrxt
I0121 15:58:08.927859       1 types.go:761] [ControllerName] Anotação 'controller' encontrada para o pod default/test-deployment2-6594f5cd7f-bjrxt: test-controller2
I0121 15:58:08.927955       1 scheduler.go:572] [GetControllerMetricInfo] Métricas do controlador definidas para o pod: default/test-deployment2-6594f5cd7f-bjrxt
I0121 15:58:08.927992       1 scheduler.go:83] [HigherPrecedence] Calculando precedência entre test-deployment3-ff66c7fc9-c5vcz e test-deployment2-6594f5cd7f-bjrxt
I0121 15:58:08.928014       1 scheduler.go:116] [WaitForPodsOnCache] Verificando se o pod test-deployment3-ff66c7fc9-c5vcz está no cache...
I0121 15:58:08.928036       1 scheduler.go:564] [GetControllerMetricInfo] Iniciando para o pod: default/test-deployment3-ff66c7fc9-c5vcz
I0121 15:58:08.928105       1 scheduler.go:569] [GetControllerMetricInfo] Obtendo o nome do controlador para o pod: default/test-deployment3-ff66c7fc9-c5vcz
I0121 15:58:08.928129       1 types.go:743] [ControllerName] Verificando as anotações do pod default/test-deployment3-ff66c7fc9-c5vcz
I0121 15:58:08.928152       1 types.go:761] [ControllerName] Anotação 'controller' encontrada para o pod default/test-deployment3-ff66c7fc9-c5vcz: test-controller3
I0121 15:58:08.928175       1 scheduler.go:572] [GetControllerMetricInfo] Métricas do controlador definidas para o pod: default/test-deployment3-ff66c7fc9-c5vcz
I0121 15:58:08.952083       1 scheduler.go:69] Estado no Informer: map[controller:test-controller3]
I0121 15:58:08.952250       1 scheduler.go:70] Estado real no cluster: map[controller:test-controller3]
I0121 15:58:08.952284       1 scheduler.go:138] [WaitForPodsOnCache] Pod test-deployment3-ff66c7fc9-c5vcz encontrado no cache.
I0121 15:58:08.952304       1 scheduler.go:116] [WaitForPodsOnCache] Verificando se o pod test-deployment2-6594f5cd7f-bjrxt está no cache...
I0121 15:58:08.952323       1 scheduler.go:564] [GetControllerMetricInfo] Iniciando para o pod: default/test-deployment2-6594f5cd7f-bjrxt
I0121 15:58:08.952343       1 scheduler.go:569] [GetControllerMetricInfo] Obtendo o nome do controlador para o pod: default/test-deployment2-6594f5cd7f-bjrxt
I0121 15:58:08.952364       1 types.go:743] [ControllerName] Verificando as anotações do pod default/test-deployment2-6594f5cd7f-bjrxt
I0121 15:58:08.952384       1 types.go:761] [ControllerName] Anotação 'controller' encontrada para o pod default/test-deployment2-6594f5cd7f-bjrxt: test-controller2
I0121 15:58:08.952409       1 scheduler.go:572] [GetControllerMetricInfo] Métricas do controlador definidas para o pod: default/test-deployment2-6594f5cd7f-bjrxt
I0121 15:58:08.956945       1 scheduler.go:69] Estado no Informer: map[controller:test-controller2]
I0121 15:58:08.957391       1 scheduler.go:70] Estado real no cluster: map[controller:test-controller2]
I0121 15:58:08.957645       1 scheduler.go:138] [WaitForPodsOnCache] Pod test-deployment2-6594f5cd7f-bjrxt encontrado no cache.
I0121 15:58:08.957783       1 scheduler.go:564] [GetControllerMetricInfo] Iniciando para o pod: default/test-deployment3-ff66c7fc9-c5vcz
I0121 15:58:08.957817       1 scheduler.go:569] [GetControllerMetricInfo] Obtendo o nome do controlador para o pod: default/test-deployment3-ff66c7fc9-c5vcz
I0121 15:58:08.957947       1 types.go:743] [ControllerName] Verificando as anotações do pod default/test-deployment3-ff66c7fc9-c5vcz
I0121 15:58:08.957974       1 types.go:761] [ControllerName] Anotação 'controller' encontrada para o pod default/test-deployment3-ff66c7fc9-c5vcz: test-controller3
I0121 15:58:08.958119       1 scheduler.go:572] [GetControllerMetricInfo] Métricas do controlador definidas para o pod: default/test-deployment3-ff66c7fc9-c5vcz
I0121 15:58:08.958407       1 scheduler.go:564] [GetControllerMetricInfo] Iniciando para o pod: default/test-deployment2-6594f5cd7f-bjrxt
I0121 15:58:08.958550       1 scheduler.go:569] [GetControllerMetricInfo] Obtendo o nome do controlador para o pod: default/test-deployment2-6594f5cd7f-bjrxt
I0121 15:58:08.958839       1 types.go:743] [ControllerName] Verificando as anotações do pod default/test-deployment2-6594f5cd7f-bjrxt
I0121 15:58:08.959024       1 types.go:761] [ControllerName] Anotação 'controller' encontrada para o pod default/test-deployment2-6594f5cd7f-bjrxt: test-controller2
I0121 15:58:08.959128       1 scheduler.go:572] [GetControllerMetricInfo] Métricas do controlador definidas para o pod: default/test-deployment2-6594f5cd7f-bjrxt
I0121 15:58:08.959590       1 scheduler.go:97] [HigherPrecedence] Métricas para test-deployment3-ff66c7fc9-c5vcz: QoS = -468.425384, Importância = 0.80
I0121 15:58:08.959933       1 scheduler.go:98] [HigherPrecedence] Métricas para test-deployment2-6594f5cd7f-bjrxt: QoS = -579.917953, Importância = 0.80
I0121 15:58:08.960135       1 scheduler.go:109] [HigherPrecedence] Decisão final: test-deployment3-ff66c7fc9-c5vcz tem precedência sobre test-deployment2-6594f5cd7f-bjrxt? false
I0121 15:58:08.960509       1 postFilter.go:142] [PREEMPT CALL] No node was chosen to allocate pod test-deployment3-ff66c7fc9-c5vcz
I0121 15:58:09.465843       1 scheduler.go:247] [OnUpdatePod] Pod atualizado: default/test-deployment3-ff66c7fc9-c5vcz, Anotações: map[controller:test-controller3]
I0121 15:58:09.487979       1 scheduler.go:69] Estado no Informer: map[controller:test-controller3]
I0121 15:58:09.488089       1 scheduler.go:70] Estado real no cluster: map[controller:test-controller3]
I0121 15:58:09.488113       1 types.go:743] [ControllerName] Verificando as anotações do pod default/test-deployment3-ff66c7fc9-c5vcz
I0121 15:58:09.488128       1 types.go:761] [ControllerName] Anotação 'controller' encontrada para o pod default/test-deployment3-ff66c7fc9-c5vcz: test-controller3
I0121 15:58:23.372715       1 scheduler.go:247] [OnUpdatePod] Pod atualizado: default/test-deployment3-ff66c7fc9-c5vcz, Anotações: map[controller:test-controller3]
E0121 15:58:23.382347       1 scheduler.go:66] Erro ao buscar estado real do pod test-deployment3-ff66c7fc9-c5vcz: pods "test-deployment3-ff66c7fc9-c5vcz" not found
I0121 15:58:23.382815       1 types.go:743] [ControllerName] Verificando as anotações do pod default/test-deployment3-ff66c7fc9-c5vcz
I0121 15:58:23.382998       1 types.go:761] [ControllerName] Anotação 'controller' encontrada para o pod default/test-deployment3-ff66c7fc9-c5vcz: test-controller3
I0121 15:58:23.384731       1 types.go:743] [ControllerName] Verificando as anotações do pod default/test-deployment3-ff66c7fc9-c5vcz
I0121 15:58:23.385204       1 types.go:761] [ControllerName] Anotação 'controller' encontrada para o pod default/test-deployment3-ff66c7fc9-c5vcz: test-controller3
I0121 15:58:23.386362       1 types.go:743] [ControllerName] Verificando as anotações do pod default/test-deployment3-ff66c7fc9-c5vcz
I0121 15:58:23.386573       1 types.go:761] [ControllerName] Anotação 'controller' encontrada para o pod default/test-deployment3-ff66c7fc9-c5vcz: test-controller3
I0121 15:58:27.631403       1 postFilter.go:74] Comparando pod original com o atualizado...
I0121 15:58:27.631587       1 postFilter.go:81] Successfully retrieved updated pod default/test-deployment3-ff66c7fc9-ncdbk from lister
I0121 15:58:27.632332       1 scheduler.go:213] [OnAddPod] Pod adicionado: default/test-deployment3-ff66c7fc9-ncdbk, Anotações: map[controller:test-controller3]
I0121 15:58:27.639928       1 scheduler.go:69] Estado no Informer: map[controller:test-controller3]
I0121 15:58:27.640025       1 scheduler.go:70] Estado real no cluster: map[controller:test-controller3]
I0121 15:58:27.646382       1 types.go:743] [ControllerName] Verificando as anotações do pod default/test-deployment3-ff66c7fc9-ncdbk
I0121 15:58:27.646559       1 types.go:761] [ControllerName] Anotação 'controller' encontrada para o pod default/test-deployment3-ff66c7fc9-ncdbk: test-controller3
I0121 15:58:27.646982       1 types.go:743] [ControllerName] Verificando as anotações do pod default/test-deployment3-ff66c7fc9-ncdbk
I0121 15:58:27.647055       1 types.go:761] [ControllerName] Anotação 'controller' encontrada para o pod default/test-deployment3-ff66c7fc9-ncdbk: test-controller3
I0121 15:58:27.647988       1 postFilter.go:204] Recursos CPU do nó minikube estão sincronizados: 2000 mCPU
I0121 15:58:27.649423       1 postFilter.go:211] Recursos Memória do nó minikube estão sincronizados: 2216124416 bytes
I0121 15:58:27.654253       1 scheduler.go:564] [GetControllerMetricInfo] Iniciando para o pod: default/test-deployment2-6594f5cd7f-bjrxt
I0121 15:58:27.657535       1 scheduler.go:569] [GetControllerMetricInfo] Obtendo o nome do controlador para o pod: default/test-deployment2-6594f5cd7f-bjrxt
I0121 15:58:27.657756       1 types.go:743] [ControllerName] Verificando as anotações do pod default/test-deployment2-6594f5cd7f-bjrxt
I0121 15:58:27.658086       1 types.go:761] [ControllerName] Anotação 'controller' encontrada para o pod default/test-deployment2-6594f5cd7f-bjrxt: test-controller2
I0121 15:58:27.658294       1 scheduler.go:572] [GetControllerMetricInfo] Métricas do controlador definidas para o pod: default/test-deployment2-6594f5cd7f-bjrxt
I0121 15:58:27.658421       1 scheduler.go:83] [HigherPrecedence] Calculando precedência entre test-deployment3-ff66c7fc9-ncdbk e test-deployment2-6594f5cd7f-bjrxt
I0121 15:58:27.658867       1 scheduler.go:116] [WaitForPodsOnCache] Verificando se o pod test-deployment3-ff66c7fc9-ncdbk está no cache...
I0121 15:58:27.659029       1 scheduler.go:564] [GetControllerMetricInfo] Iniciando para o pod: default/test-deployment3-ff66c7fc9-ncdbk
I0121 15:58:27.659102       1 scheduler.go:569] [GetControllerMetricInfo] Obtendo o nome do controlador para o pod: default/test-deployment3-ff66c7fc9-ncdbk
I0121 15:58:27.659159       1 types.go:743] [ControllerName] Verificando as anotações do pod default/test-deployment3-ff66c7fc9-ncdbk
I0121 15:58:27.659278       1 types.go:761] [ControllerName] Anotação 'controller' encontrada para o pod default/test-deployment3-ff66c7fc9-ncdbk: test-controller3
I0121 15:58:27.659336       1 scheduler.go:572] [GetControllerMetricInfo] Métricas do controlador definidas para o pod: default/test-deployment3-ff66c7fc9-ncdbk
I0121 15:58:27.662529       1 scheduler.go:69] Estado no Informer: map[controller:test-controller3]
I0121 15:58:27.662897       1 scheduler.go:70] Estado real no cluster: map[controller:test-controller3]
I0121 15:58:27.666023       1 scheduler.go:138] [WaitForPodsOnCache] Pod test-deployment3-ff66c7fc9-ncdbk encontrado no cache.
I0121 15:58:27.666388       1 scheduler.go:116] [WaitForPodsOnCache] Verificando se o pod test-deployment2-6594f5cd7f-bjrxt está no cache...
I0121 15:58:27.670835       1 scheduler.go:564] [GetControllerMetricInfo] Iniciando para o pod: default/test-deployment2-6594f5cd7f-bjrxt
I0121 15:58:27.671200       1 scheduler.go:569] [GetControllerMetricInfo] Obtendo o nome do controlador para o pod: default/test-deployment2-6594f5cd7f-bjrxt
I0121 15:58:27.671809       1 types.go:743] [ControllerName] Verificando as anotações do pod default/test-deployment2-6594f5cd7f-bjrxt
I0121 15:58:27.672128       1 types.go:761] [ControllerName] Anotação 'controller' encontrada para o pod default/test-deployment2-6594f5cd7f-bjrxt: test-controller2
I0121 15:58:27.672292       1 scheduler.go:572] [GetControllerMetricInfo] Métricas do controlador definidas para o pod: default/test-deployment2-6594f5cd7f-bjrxt
I0121 15:58:27.687598       1 scheduler.go:69] Estado no Informer: map[controller:test-controller2]
I0121 15:58:27.687906       1 scheduler.go:70] Estado real no cluster: map[controller:test-controller2]
I0121 15:58:27.688743       1 scheduler.go:138] [WaitForPodsOnCache] Pod test-deployment2-6594f5cd7f-bjrxt encontrado no cache.
I0121 15:58:27.688763       1 scheduler.go:564] [GetControllerMetricInfo] Iniciando para o pod: default/test-deployment3-ff66c7fc9-ncdbk
I0121 15:58:27.689064       1 scheduler.go:569] [GetControllerMetricInfo] Obtendo o nome do controlador para o pod: default/test-deployment3-ff66c7fc9-ncdbk
I0121 15:58:27.689082       1 types.go:743] [ControllerName] Verificando as anotações do pod default/test-deployment3-ff66c7fc9-ncdbk
I0121 15:58:27.689092       1 types.go:761] [ControllerName] Anotação 'controller' encontrada para o pod default/test-deployment3-ff66c7fc9-ncdbk: test-controller3
I0121 15:58:27.689241       1 scheduler.go:572] [GetControllerMetricInfo] Métricas do controlador definidas para o pod: default/test-deployment3-ff66c7fc9-ncdbk
I0121 15:58:27.689436       1 scheduler.go:564] [GetControllerMetricInfo] Iniciando para o pod: default/test-deployment2-6594f5cd7f-bjrxt
I0121 15:58:27.689737       1 scheduler.go:569] [GetControllerMetricInfo] Obtendo o nome do controlador para o pod: default/test-deployment2-6594f5cd7f-bjrxt
I0121 15:58:27.689774       1 types.go:743] [ControllerName] Verificando as anotações do pod default/test-deployment2-6594f5cd7f-bjrxt
I0121 15:58:27.689935       1 types.go:761] [ControllerName] Anotação 'controller' encontrada para o pod default/test-deployment2-6594f5cd7f-bjrxt: test-controller2
I0121 15:58:27.689950       1 scheduler.go:572] [GetControllerMetricInfo] Métricas do controlador definidas para o pod: default/test-deployment2-6594f5cd7f-bjrxt
I0121 15:58:27.690310       1 scheduler.go:97] [HigherPrecedence] Métricas para test-deployment3-ff66c7fc9-ncdbk: QoS = -483.528624, Importância = 0.80
I0121 15:58:27.690608       1 scheduler.go:98] [HigherPrecedence] Métricas para test-deployment2-6594f5cd7f-bjrxt: QoS = -575.235345, Importância = 0.80
I0121 15:58:27.690804       1 scheduler.go:109] [HigherPrecedence] Decisão final: test-deployment3-ff66c7fc9-ncdbk tem precedência sobre test-deployment2-6594f5cd7f-bjrxt? false
I0121 15:58:27.691282       1 postFilter.go:142] [PREEMPT CALL] No node was chosen to allocate pod test-deployment3-ff66c7fc9-ncdbk
I0121 15:58:27.713685       1 scheduler.go:247] [OnUpdatePod] Pod atualizado: default/test-deployment3-ff66c7fc9-ncdbk, Anotações: map[controller:test-controller3]
I0121 15:58:27.717324       1 scheduler.go:69] Estado no Informer: map[controller:test-controller3]
I0121 15:58:27.717814       1 scheduler.go:70] Estado real no cluster: map[controller:test-controller3]
I0121 15:58:27.717864       1 types.go:743] [ControllerName] Verificando as anotações do pod default/test-deployment3-ff66c7fc9-ncdbk
I0121 15:58:27.717874       1 types.go:761] [ControllerName] Anotação 'controller' encontrada para o pod default/test-deployment3-ff66c7fc9-ncdbk: test-controller3
I0121 15:58:41.087821       1 scheduler.go:247] [OnUpdatePod] Pod atualizado: default/test-deployment3-ff66c7fc9-ncdbk, Anotações: map[controller:test-controller3]
E0121 15:58:41.103641       1 scheduler.go:66] Erro ao buscar estado real do pod test-deployment3-ff66c7fc9-ncdbk: pods "test-deployment3-ff66c7fc9-ncdbk" not found
I0121 15:58:41.104380       1 types.go:743] [ControllerName] Verificando as anotações do pod default/test-deployment3-ff66c7fc9-ncdbk
I0121 15:58:41.104637       1 types.go:761] [ControllerName] Anotação 'controller' encontrada para o pod default/test-deployment3-ff66c7fc9-ncdbk: test-controller3
I0121 15:58:41.105176       1 types.go:743] [ControllerName] Verificando as anotações do pod default/test-deployment3-ff66c7fc9-ncdbk
I0121 15:58:41.105276       1 types.go:761] [ControllerName] Anotação 'controller' encontrada para o pod default/test-deployment3-ff66c7fc9-ncdbk: test-controller3
I0121 15:58:41.105921       1 types.go:743] [ControllerName] Verificando as anotações do pod default/test-deployment3-ff66c7fc9-ncdbk
I0121 15:58:41.106182       1 types.go:761] [ControllerName] Anotação 'controller' encontrada para o pod default/test-deployment3-ff66c7fc9-ncdbk: test-controller3
I0121 15:58:42.968334       1 scheduler.go:247] [OnUpdatePod] Pod atualizado: default/test-deployment2-6594f5cd7f-bjrxt, Anotações: map[controller:test-controller2]
I0121 15:58:42.978386       1 scheduler.go:69] Estado no Informer: map[controller:test-controller2]
I0121 15:58:42.978784       1 scheduler.go:70] Estado real no cluster: map[controller:test-controller2]
I0121 15:58:42.979031       1 types.go:743] [ControllerName] Verificando as anotações do pod default/test-deployment2-6594f5cd7f-bjrxt
I0121 15:58:42.979171       1 types.go:761] [ControllerName] Anotação 'controller' encontrada para o pod default/test-deployment2-6594f5cd7f-bjrxt: test-controller2
I0121 15:58:42.979434       1 types.go:743] [ControllerName] Verificando as anotações do pod default/test-deployment2-6594f5cd7f-bjrxt
I0121 15:58:42.979588       1 types.go:761] [ControllerName] Anotação 'controller' encontrada para o pod default/test-deployment2-6594f5cd7f-bjrxt: test-controller2
I0121 15:58:44.760685       1 types.go:743] [ControllerName] Verificando as anotações do pod default/test-deployment2-6594f5cd7f-bjrxt
I0121 15:58:44.761444       1 types.go:761] [ControllerName] Anotação 'controller' encontrada para o pod default/test-deployment2-6594f5cd7f-bjrxt: test-controller2
I0121 15:58:59.854557       1 scheduler.go:145] [Reserve] resources reserved at node minikube for pod test-deployment2-6594f5cd7f-nnzcs_default at 2025-01-21 15:58:59.854446412 +0000 UTC m=+1156.509015276
I0121 15:58:59.855416       1 types.go:743] [ControllerName] Verificando as anotações do pod default/test-deployment2-6594f5cd7f-nnzcs
I0121 15:58:59.856294       1 types.go:761] [ControllerName] Anotação 'controller' encontrada para o pod default/test-deployment2-6594f5cd7f-nnzcs: test-controller2
I0121 15:58:59.857236       1 scheduler.go:147] [Reserve] Status de alocação atual para o pod test-deployment2-6594f5cd7f-nnzcs_default: 
I0121 15:58:59.857769       1 scheduler.go:149] [Reserve] Status de alocação atualizado para o pod test-deployment2-6594f5cd7f-nnzcs_default: allocating
I0121 15:58:59.858282       1 scheduler.go:173] [PreBind] Validando o pod test-deployment2-6594f5cd7f-nnzcs antes de vincular ao node minikube
I0121 15:58:59.858782       1 scheduler.go:213] [OnAddPod] Pod adicionado: default/test-deployment2-6594f5cd7f-nnzcs, Anotações: map[controller:test-controller2]
I0121 15:58:59.886323       1 scheduler.go:69] Estado no Informer: map[controller:test-controller2]
I0121 15:58:59.886600       1 scheduler.go:70] Estado real no cluster: map[controller:test-controller2]
I0121 15:58:59.887242       1 types.go:743] [ControllerName] Verificando as anotações do pod default/test-deployment2-6594f5cd7f-nnzcs
I0121 15:58:59.887438       1 types.go:761] [ControllerName] Anotação 'controller' encontrada para o pod default/test-deployment2-6594f5cd7f-nnzcs: test-controller2
I0121 15:58:59.887679       1 types.go:743] [ControllerName] Verificando as anotações do pod default/test-deployment2-6594f5cd7f-nnzcs
I0121 15:58:59.887963       1 types.go:761] [ControllerName] Anotação 'controller' encontrada para o pod default/test-deployment2-6594f5cd7f-nnzcs: test-controller2
I0121 15:58:59.906821       1 scheduler.go:181] [PostBind] Chamado para pod test-deployment2-6594f5cd7f-nnzcs
I0121 15:58:59.907055       1 scheduler.go:199] [PostBind] Pod test-deployment2-6594f5cd7f-nnzcs - Início do binding: 2025-01-21 15:58:59.858576794 +0000 UTC m=+1156.513145925, Fim do binding: 2025-01-21 15:58:59.907048344 +0000 UTC m=+1156.561616801
I0121 15:58:59.907198       1 types.go:743] [ControllerName] Verificando as anotações do pod default/test-deployment2-6594f5cd7f-nnzcs
I0121 15:58:59.907312       1 types.go:761] [ControllerName] Anotação 'controller' encontrada para o pod default/test-deployment2-6594f5cd7f-nnzcs: test-controller2
I0121 15:58:59.907422       1 scheduler.go:206] [PostBind] Métricas atualizadas para o pod test-deployment2-6594f5cd7f-nnzcs
I0121 15:58:59.907782       1 scheduler.go:247] [OnUpdatePod] Pod atualizado: default/test-deployment2-6594f5cd7f-nnzcs, Anotações: map[controller:test-controller2]
I0121 15:59:00.166447       1 scheduler.go:69] Estado no Informer: map[controller:test-controller2]
I0121 15:59:00.167262       1 scheduler.go:70] Estado real no cluster: map[controller:test-controller2]
I0121 15:59:00.167449       1 types.go:743] [ControllerName] Verificando as anotações do pod default/test-deployment2-6594f5cd7f-nnzcs
I0121 15:59:00.167863       1 types.go:761] [ControllerName] Anotação 'controller' encontrada para o pod default/test-deployment2-6594f5cd7f-nnzcs: test-controller2
I0121 15:59:00.179997       1 scheduler.go:247] [OnUpdatePod] Pod atualizado: default/test-deployment2-6594f5cd7f-nnzcs, Anotações: map[controller:test-controller2]
I0121 15:59:00.187102       1 scheduler.go:69] Estado no Informer: map[controller:test-controller2]
I0121 15:59:00.187243       1 scheduler.go:70] Estado real no cluster: map[controller:test-controller2]
I0121 15:59:00.187255       1 types.go:743] [ControllerName] Verificando as anotações do pod default/test-deployment2-6594f5cd7f-nnzcs
I0121 15:59:00.187264       1 types.go:761] [ControllerName] Anotação 'controller' encontrada para o pod default/test-deployment2-6594f5cd7f-nnzcs: test-controller2
I0121 15:59:04.866908       1 scheduler.go:247] [OnUpdatePod] Pod atualizado: default/test-deployment2-6594f5cd7f-nnzcs, Anotações: map[controller:test-controller2]
I0121 15:59:04.876322       1 scheduler.go:69] Estado no Informer: map[controller:test-controller2]
I0121 15:59:04.877075       1 scheduler.go:70] Estado real no cluster: map[controller:test-controller2]
I0121 15:59:04.877449       1 types.go:743] [ControllerName] Verificando as anotações do pod default/test-deployment2-6594f5cd7f-nnzcs
I0121 15:59:04.878329       1 types.go:761] [ControllerName] Anotação 'controller' encontrada para o pod default/test-deployment2-6594f5cd7f-nnzcs: test-controller2
I0121 15:59:50.924413       1 postFilter.go:74] Comparando pod original com o atualizado...
I0121 15:59:50.924682       1 postFilter.go:81] Successfully retrieved updated pod default/test-deployment3-ff66c7fc9-ssjgj from lister
I0121 15:59:50.928290       1 scheduler.go:213] [OnAddPod] Pod adicionado: default/test-deployment3-ff66c7fc9-ssjgj, Anotações: map[controller:test-controller3]
I0121 15:59:51.121856       1 scheduler.go:69] Estado no Informer: map[controller:test-controller3]
I0121 15:59:51.122238       1 scheduler.go:70] Estado real no cluster: map[controller:test-controller3]
I0121 15:59:51.124146       1 types.go:743] [ControllerName] Verificando as anotações do pod default/test-deployment3-ff66c7fc9-ssjgj
I0121 15:59:51.124359       1 types.go:761] [ControllerName] Anotação 'controller' encontrada para o pod default/test-deployment3-ff66c7fc9-ssjgj: test-controller3
I0121 15:59:51.124445       1 types.go:743] [ControllerName] Verificando as anotações do pod default/test-deployment3-ff66c7fc9-ssjgj
I0121 15:59:51.124746       1 types.go:761] [ControllerName] Anotação 'controller' encontrada para o pod default/test-deployment3-ff66c7fc9-ssjgj: test-controller3
I0121 15:59:51.125083       1 postFilter.go:204] Recursos CPU do nó minikube estão sincronizados: 2000 mCPU
I0121 15:59:51.125698       1 postFilter.go:211] Recursos Memória do nó minikube estão sincronizados: 2216124416 bytes
I0121 15:59:51.130965       1 scheduler.go:564] [GetControllerMetricInfo] Iniciando para o pod: default/test-deployment2-6594f5cd7f-nnzcs
I0121 15:59:51.132685       1 scheduler.go:569] [GetControllerMetricInfo] Obtendo o nome do controlador para o pod: default/test-deployment2-6594f5cd7f-nnzcs
I0121 15:59:51.133178       1 types.go:743] [ControllerName] Verificando as anotações do pod default/test-deployment2-6594f5cd7f-nnzcs
I0121 15:59:51.133392       1 types.go:761] [ControllerName] Anotação 'controller' encontrada para o pod default/test-deployment2-6594f5cd7f-nnzcs: test-controller2
I0121 15:59:51.133693       1 scheduler.go:572] [GetControllerMetricInfo] Métricas do controlador definidas para o pod: default/test-deployment2-6594f5cd7f-nnzcs
I0121 15:59:51.133743       1 scheduler.go:83] [HigherPrecedence] Calculando precedência entre test-deployment3-ff66c7fc9-ssjgj e test-deployment2-6594f5cd7f-nnzcs
I0121 15:59:51.133845       1 scheduler.go:116] [WaitForPodsOnCache] Verificando se o pod test-deployment3-ff66c7fc9-ssjgj está no cache...
I0121 15:59:51.134111       1 scheduler.go:564] [GetControllerMetricInfo] Iniciando para o pod: default/test-deployment3-ff66c7fc9-ssjgj
I0121 15:59:51.134151       1 scheduler.go:569] [GetControllerMetricInfo] Obtendo o nome do controlador para o pod: default/test-deployment3-ff66c7fc9-ssjgj
I0121 15:59:51.134184       1 types.go:743] [ControllerName] Verificando as anotações do pod default/test-deployment3-ff66c7fc9-ssjgj
I0121 15:59:51.134220       1 types.go:761] [ControllerName] Anotação 'controller' encontrada para o pod default/test-deployment3-ff66c7fc9-ssjgj: test-controller3
I0121 15:59:51.134255       1 scheduler.go:572] [GetControllerMetricInfo] Métricas do controlador definidas para o pod: default/test-deployment3-ff66c7fc9-ssjgj
I0121 15:59:51.300881       1 scheduler.go:69] Estado no Informer: map[controller:test-controller3]
I0121 15:59:51.301447       1 scheduler.go:70] Estado real no cluster: map[controller:test-controller3]
I0121 15:59:51.302392       1 scheduler.go:138] [WaitForPodsOnCache] Pod test-deployment3-ff66c7fc9-ssjgj encontrado no cache.
I0121 15:59:51.302440       1 scheduler.go:116] [WaitForPodsOnCache] Verificando se o pod test-deployment2-6594f5cd7f-nnzcs está no cache...
I0121 15:59:51.302591       1 scheduler.go:564] [GetControllerMetricInfo] Iniciando para o pod: default/test-deployment2-6594f5cd7f-nnzcs
I0121 15:59:51.302703       1 scheduler.go:569] [GetControllerMetricInfo] Obtendo o nome do controlador para o pod: default/test-deployment2-6594f5cd7f-nnzcs
I0121 15:59:51.302754       1 types.go:743] [ControllerName] Verificando as anotações do pod default/test-deployment2-6594f5cd7f-nnzcs
I0121 15:59:51.302792       1 types.go:761] [ControllerName] Anotação 'controller' encontrada para o pod default/test-deployment2-6594f5cd7f-nnzcs: test-controller2
I0121 15:59:51.303058       1 scheduler.go:572] [GetControllerMetricInfo] Métricas do controlador definidas para o pod: default/test-deployment2-6594f5cd7f-nnzcs
I0121 15:59:51.333942       1 scheduler.go:69] Estado no Informer: map[controller:test-controller2]
I0121 15:59:51.342101       1 scheduler.go:70] Estado real no cluster: map[controller:test-controller2]
I0121 15:59:51.342117       1 scheduler.go:138] [WaitForPodsOnCache] Pod test-deployment2-6594f5cd7f-nnzcs encontrado no cache.
I0121 15:59:51.342125       1 scheduler.go:564] [GetControllerMetricInfo] Iniciando para o pod: default/test-deployment3-ff66c7fc9-ssjgj
I0121 15:59:51.342595       1 scheduler.go:569] [GetControllerMetricInfo] Obtendo o nome do controlador para o pod: default/test-deployment3-ff66c7fc9-ssjgj
I0121 15:59:51.342605       1 types.go:743] [ControllerName] Verificando as anotações do pod default/test-deployment3-ff66c7fc9-ssjgj
I0121 15:59:51.342614       1 types.go:761] [ControllerName] Anotação 'controller' encontrada para o pod default/test-deployment3-ff66c7fc9-ssjgj: test-controller3
I0121 15:59:51.342623       1 scheduler.go:572] [GetControllerMetricInfo] Métricas do controlador definidas para o pod: default/test-deployment3-ff66c7fc9-ssjgj
I0121 15:59:51.342748       1 scheduler.go:564] [GetControllerMetricInfo] Iniciando para o pod: default/test-deployment2-6594f5cd7f-nnzcs
I0121 15:59:51.342757       1 scheduler.go:569] [GetControllerMetricInfo] Obtendo o nome do controlador para o pod: default/test-deployment2-6594f5cd7f-nnzcs
I0121 15:59:51.342762       1 types.go:743] [ControllerName] Verificando as anotações do pod default/test-deployment2-6594f5cd7f-nnzcs
I0121 15:59:51.342769       1 types.go:761] [ControllerName] Anotação 'controller' encontrada para o pod default/test-deployment2-6594f5cd7f-nnzcs: test-controller2
I0121 15:59:51.342776       1 scheduler.go:572] [GetControllerMetricInfo] Métricas do controlador definidas para o pod: default/test-deployment2-6594f5cd7f-nnzcs
I0121 15:59:51.343344       1 scheduler.go:97] [HigherPrecedence] Métricas para test-deployment3-ff66c7fc9-ssjgj: QoS = -498.102118, Importância = 0.80
I0121 15:59:51.343750       1 scheduler.go:98] [HigherPrecedence] Métricas para test-deployment2-6594f5cd7f-nnzcs: QoS = -559.040591, Importância = 0.80
I0121 15:59:51.344029       1 scheduler.go:109] [HigherPrecedence] Decisão final: test-deployment3-ff66c7fc9-ssjgj tem precedência sobre test-deployment2-6594f5cd7f-nnzcs? false
I0121 15:59:51.344405       1 postFilter.go:142] [PREEMPT CALL] No node was chosen to allocate pod test-deployment3-ff66c7fc9-ssjgj
I0121 15:59:51.363820       1 scheduler.go:247] [OnUpdatePod] Pod atualizado: default/test-deployment3-ff66c7fc9-ssjgj, Anotações: map[controller:test-controller3]
I0121 15:59:51.379074       1 scheduler.go:69] Estado no Informer: map[controller:test-controller3]
I0121 15:59:51.379127       1 scheduler.go:70] Estado real no cluster: map[controller:test-controller3]
I0121 15:59:51.379140       1 types.go:743] [ControllerName] Verificando as anotações do pod default/test-deployment3-ff66c7fc9-ssjgj
I0121 15:59:51.379148       1 types.go:761] [ControllerName] Anotação 'controller' encontrada para o pod default/test-deployment3-ff66c7fc9-ssjgj: test-controller3
I0121 16:00:49.989356       1 scheduler.go:247] [OnUpdatePod] Pod atualizado: default/test-deployment3-ff66c7fc9-ssjgj, Anotações: map[controller:test-controller3]
E0121 16:00:50.063193       1 scheduler.go:66] Erro ao buscar estado real do pod test-deployment3-ff66c7fc9-ssjgj: pods "test-deployment3-ff66c7fc9-ssjgj" not found
I0121 16:00:50.063678       1 types.go:743] [ControllerName] Verificando as anotações do pod default/test-deployment3-ff66c7fc9-ssjgj
I0121 16:00:50.067565       1 types.go:761] [ControllerName] Anotação 'controller' encontrada para o pod default/test-deployment3-ff66c7fc9-ssjgj: test-controller3
I0121 16:00:50.068959       1 types.go:743] [ControllerName] Verificando as anotações do pod default/test-deployment3-ff66c7fc9-ssjgj
I0121 16:00:50.069072       1 types.go:761] [ControllerName] Anotação 'controller' encontrada para o pod default/test-deployment3-ff66c7fc9-ssjgj: test-controller3
I0121 16:00:50.069199       1 types.go:743] [ControllerName] Verificando as anotações do pod default/test-deployment3-ff66c7fc9-ssjgj
I0121 16:00:50.069263       1 types.go:761] [ControllerName] Anotação 'controller' encontrada para o pod default/test-deployment3-ff66c7fc9-ssjgj: test-controller3
I0121 16:00:55.017924       1 postFilter.go:74] Comparando pod original com o atualizado...
I0121 16:00:55.024819       1 postFilter.go:81] Successfully retrieved updated pod default/test-deployment3-ff66c7fc9-t7lg2 from lister
I0121 16:00:55.017880       1 scheduler.go:213] [OnAddPod] Pod adicionado: default/test-deployment3-ff66c7fc9-t7lg2, Anotações: map[controller:test-controller3]
I0121 16:00:55.046305       1 postFilter.go:204] Recursos CPU do nó minikube estão sincronizados: 2000 mCPU
I0121 16:00:55.047304       1 postFilter.go:211] Recursos Memória do nó minikube estão sincronizados: 2216124416 bytes
I0121 16:00:55.058180       1 scheduler.go:69] Estado no Informer: map[controller:test-controller3]
I0121 16:00:55.059280       1 scheduler.go:70] Estado real no cluster: map[controller:test-controller3]
I0121 16:00:55.067106       1 scheduler.go:564] [GetControllerMetricInfo] Iniciando para o pod: default/test-deployment2-6594f5cd7f-nnzcs
I0121 16:00:55.068591       1 scheduler.go:569] [GetControllerMetricInfo] Obtendo o nome do controlador para o pod: default/test-deployment2-6594f5cd7f-nnzcs
I0121 16:00:55.068808       1 types.go:743] [ControllerName] Verificando as anotações do pod default/test-deployment2-6594f5cd7f-nnzcs
I0121 16:00:55.069058       1 types.go:761] [ControllerName] Anotação 'controller' encontrada para o pod default/test-deployment2-6594f5cd7f-nnzcs: test-controller2
I0121 16:00:55.069222       1 scheduler.go:572] [GetControllerMetricInfo] Métricas do controlador definidas para o pod: default/test-deployment2-6594f5cd7f-nnzcs
I0121 16:00:55.078256       1 scheduler.go:83] [HigherPrecedence] Calculando precedência entre test-deployment3-ff66c7fc9-t7lg2 e test-deployment2-6594f5cd7f-nnzcs
I0121 16:00:55.078998       1 scheduler.go:116] [WaitForPodsOnCache] Verificando se o pod test-deployment3-ff66c7fc9-t7lg2 está no cache...
I0121 16:00:55.079935       1 scheduler.go:564] [GetControllerMetricInfo] Iniciando para o pod: default/test-deployment3-ff66c7fc9-t7lg2
I0121 16:00:55.083285       1 scheduler.go:569] [GetControllerMetricInfo] Obtendo o nome do controlador para o pod: default/test-deployment3-ff66c7fc9-t7lg2
I0121 16:00:55.083294       1 types.go:743] [ControllerName] Verificando as anotações do pod default/test-deployment3-ff66c7fc9-t7lg2
I0121 16:00:55.083303       1 types.go:761] [ControllerName] Anotação 'controller' encontrada para o pod default/test-deployment3-ff66c7fc9-t7lg2: test-controller3
I0121 16:00:55.083309       1 scheduler.go:572] [GetControllerMetricInfo] Métricas do controlador definidas para o pod: default/test-deployment3-ff66c7fc9-t7lg2
W0121 16:00:55.083510       1 scheduler.go:124] [cacheMiss] Métricas não encontradas para o pod: default/test-deployment3-ff66c7fc9-t7lg2
I0121 16:00:55.094431       1 scheduler.go:69] Estado no Informer: map[controller:test-controller3]
I0121 16:00:55.094950       1 scheduler.go:70] Estado real no cluster: map[controller:test-controller3]
W0121 16:00:55.095154       1 scheduler.go:134] [WaitForPodsOnCache] Pod test-deployment3-ff66c7fc9-t7lg2 não encontrado no cache. Tentando novamente...
I0121 16:00:55.096971       1 types.go:743] [ControllerName] Verificando as anotações do pod default/test-deployment3-ff66c7fc9-t7lg2
I0121 16:00:55.097154       1 types.go:761] [ControllerName] Anotação 'controller' encontrada para o pod default/test-deployment3-ff66c7fc9-t7lg2: test-controller3
I0121 16:00:55.097175       1 types.go:743] [ControllerName] Verificando as anotações do pod default/test-deployment3-ff66c7fc9-t7lg2
I0121 16:00:55.097179       1 types.go:761] [ControllerName] Anotação 'controller' encontrada para o pod default/test-deployment3-ff66c7fc9-t7lg2: test-controller3
I0121 16:00:55.197663       1 scheduler.go:564] [GetControllerMetricInfo] Iniciando para o pod: default/test-deployment3-ff66c7fc9-t7lg2
I0121 16:00:55.198989       1 scheduler.go:569] [GetControllerMetricInfo] Obtendo o nome do controlador para o pod: default/test-deployment3-ff66c7fc9-t7lg2
I0121 16:00:55.201442       1 types.go:743] [ControllerName] Verificando as anotações do pod default/test-deployment3-ff66c7fc9-t7lg2
I0121 16:00:55.201783       1 types.go:761] [ControllerName] Anotação 'controller' encontrada para o pod default/test-deployment3-ff66c7fc9-t7lg2: test-controller3
I0121 16:00:55.202069       1 scheduler.go:572] [GetControllerMetricInfo] Métricas do controlador definidas para o pod: default/test-deployment3-ff66c7fc9-t7lg2
I0121 16:00:55.243966       1 scheduler.go:69] Estado no Informer: map[controller:test-controller3]
I0121 16:00:55.244819       1 scheduler.go:70] Estado real no cluster: map[controller:test-controller3]
I0121 16:00:55.244935       1 scheduler.go:138] [WaitForPodsOnCache] Pod test-deployment3-ff66c7fc9-t7lg2 encontrado no cache.
I0121 16:00:55.244967       1 scheduler.go:116] [WaitForPodsOnCache] Verificando se o pod test-deployment2-6594f5cd7f-nnzcs está no cache...
I0121 16:00:55.245002       1 scheduler.go:564] [GetControllerMetricInfo] Iniciando para o pod: default/test-deployment2-6594f5cd7f-nnzcs
I0121 16:00:55.245029       1 scheduler.go:569] [GetControllerMetricInfo] Obtendo o nome do controlador para o pod: default/test-deployment2-6594f5cd7f-nnzcs
I0121 16:00:55.245058       1 types.go:743] [ControllerName] Verificando as anotações do pod default/test-deployment2-6594f5cd7f-nnzcs
I0121 16:00:55.245085       1 types.go:761] [ControllerName] Anotação 'controller' encontrada para o pod default/test-deployment2-6594f5cd7f-nnzcs: test-controller2
I0121 16:00:55.245160       1 scheduler.go:572] [GetControllerMetricInfo] Métricas do controlador definidas para o pod: default/test-deployment2-6594f5cd7f-nnzcs
I0121 16:00:55.267757       1 scheduler.go:69] Estado no Informer: map[controller:test-controller2]
I0121 16:00:55.267821       1 scheduler.go:70] Estado real no cluster: map[controller:test-controller2]
I0121 16:00:55.267834       1 scheduler.go:138] [WaitForPodsOnCache] Pod test-deployment2-6594f5cd7f-nnzcs encontrado no cache.
I0121 16:00:55.267843       1 scheduler.go:564] [GetControllerMetricInfo] Iniciando para o pod: default/test-deployment3-ff66c7fc9-t7lg2
I0121 16:00:55.267851       1 scheduler.go:569] [GetControllerMetricInfo] Obtendo o nome do controlador para o pod: default/test-deployment3-ff66c7fc9-t7lg2
I0121 16:00:55.267859       1 types.go:743] [ControllerName] Verificando as anotações do pod default/test-deployment3-ff66c7fc9-t7lg2
I0121 16:00:55.269798       1 types.go:761] [ControllerName] Anotação 'controller' encontrada para o pod default/test-deployment3-ff66c7fc9-t7lg2: test-controller3
I0121 16:00:55.270021       1 scheduler.go:572] [GetControllerMetricInfo] Métricas do controlador definidas para o pod: default/test-deployment3-ff66c7fc9-t7lg2
I0121 16:00:55.270040       1 scheduler.go:564] [GetControllerMetricInfo] Iniciando para o pod: default/test-deployment2-6594f5cd7f-nnzcs
I0121 16:00:55.270047       1 scheduler.go:569] [GetControllerMetricInfo] Obtendo o nome do controlador para o pod: default/test-deployment2-6594f5cd7f-nnzcs
I0121 16:00:55.270052       1 types.go:743] [ControllerName] Verificando as anotações do pod default/test-deployment2-6594f5cd7f-nnzcs
I0121 16:00:55.271800       1 types.go:761] [ControllerName] Anotação 'controller' encontrada para o pod default/test-deployment2-6594f5cd7f-nnzcs: test-controller2
I0121 16:00:55.271932       1 scheduler.go:572] [GetControllerMetricInfo] Métricas do controlador definidas para o pod: default/test-deployment2-6594f5cd7f-nnzcs
I0121 16:00:55.272065       1 scheduler.go:97] [HigherPrecedence] Métricas para test-deployment3-ff66c7fc9-t7lg2: QoS = -558.101402, Importância = 0.80
I0121 16:00:55.273423       1 scheduler.go:98] [HigherPrecedence] Métricas para test-deployment2-6594f5cd7f-nnzcs: QoS = -543.056685, Importância = 0.80
I0121 16:00:55.273434       1 scheduler.go:109] [HigherPrecedence] Decisão final: test-deployment3-ff66c7fc9-t7lg2 tem precedência sobre test-deployment2-6594f5cd7f-nnzcs? true
I0121 16:00:55.273442       1 types.go:743] [ControllerName] Verificando as anotações do pod default/test-deployment3-ff66c7fc9-t7lg2
I0121 16:00:55.273449       1 types.go:761] [ControllerName] Anotação 'controller' encontrada para o pod default/test-deployment3-ff66c7fc9-t7lg2: test-controller3
I0121 16:00:55.273625       1 types.go:743] [ControllerName] Verificando as anotações do pod default/test-deployment2-6594f5cd7f-nnzcs
I0121 16:00:55.273633       1 types.go:761] [ControllerName] Anotação 'controller' encontrada para o pod default/test-deployment2-6594f5cd7f-nnzcs: test-controller2
I0121 16:00:55.273639       1 scheduler.go:564] [GetControllerMetricInfo] Iniciando para o pod: default/test-deployment2-6594f5cd7f-nnzcs
I0121 16:00:55.273645       1 scheduler.go:569] [GetControllerMetricInfo] Obtendo o nome do controlador para o pod: default/test-deployment2-6594f5cd7f-nnzcs
I0121 16:00:55.273759       1 types.go:743] [ControllerName] Verificando as anotações do pod default/test-deployment2-6594f5cd7f-nnzcs
I0121 16:00:55.273769       1 types.go:761] [ControllerName] Anotação 'controller' encontrada para o pod default/test-deployment2-6594f5cd7f-nnzcs: test-controller2
I0121 16:00:55.275035       1 scheduler.go:572] [GetControllerMetricInfo] Métricas do controlador definidas para o pod: default/test-deployment2-6594f5cd7f-nnzcs
I0121 16:00:55.275163       1 scheduler.go:564] [GetControllerMetricInfo] Iniciando para o pod: default/test-deployment2-6594f5cd7f-nnzcs
I0121 16:00:55.275172       1 scheduler.go:569] [GetControllerMetricInfo] Obtendo o nome do controlador para o pod: default/test-deployment2-6594f5cd7f-nnzcs
I0121 16:00:55.275177       1 types.go:743] [ControllerName] Verificando as anotações do pod default/test-deployment2-6594f5cd7f-nnzcs
I0121 16:00:55.275184       1 types.go:761] [ControllerName] Anotação 'controller' encontrada para o pod default/test-deployment2-6594f5cd7f-nnzcs: test-controller2
I0121 16:00:55.275191       1 scheduler.go:572] [GetControllerMetricInfo] Métricas do controlador definidas para o pod: default/test-deployment2-6594f5cd7f-nnzcs
I0121 16:00:55.275279       1 types.go:743] [ControllerName] Verificando as anotações do pod default/test-deployment2-6594f5cd7f-nnzcs
I0121 16:00:55.275290       1 types.go:761] [ControllerName] Anotação 'controller' encontrada para o pod default/test-deployment2-6594f5cd7f-nnzcs: test-controller2
I0121 16:00:55.275694       1 scheduler.go:564] [GetControllerMetricInfo] Iniciando para o pod: default/test-deployment2-6594f5cd7f-nnzcs
I0121 16:00:55.275704       1 scheduler.go:569] [GetControllerMetricInfo] Obtendo o nome do controlador para o pod: default/test-deployment2-6594f5cd7f-nnzcs
I0121 16:00:55.275709       1 types.go:743] [ControllerName] Verificando as anotações do pod default/test-deployment2-6594f5cd7f-nnzcs
I0121 16:00:55.275716       1 types.go:761] [ControllerName] Anotação 'controller' encontrada para o pod default/test-deployment2-6594f5cd7f-nnzcs: test-controller2
I0121 16:00:55.275722       1 scheduler.go:572] [GetControllerMetricInfo] Métricas do controlador definidas para o pod: default/test-deployment2-6594f5cd7f-nnzcs
I0121 16:00:55.275848       1 scheduler.go:564] [GetControllerMetricInfo] Iniciando para o pod: default/test-deployment2-6594f5cd7f-nnzcs
I0121 16:00:55.275857       1 scheduler.go:569] [GetControllerMetricInfo] Obtendo o nome do controlador para o pod: default/test-deployment2-6594f5cd7f-nnzcs
I0121 16:00:55.275988       1 types.go:743] [ControllerName] Verificando as anotações do pod default/test-deployment2-6594f5cd7f-nnzcs
I0121 16:00:55.276077       1 types.go:761] [ControllerName] Anotação 'controller' encontrada para o pod default/test-deployment2-6594f5cd7f-nnzcs: test-controller2
I0121 16:00:55.276113       1 scheduler.go:572] [GetControllerMetricInfo] Métricas do controlador definidas para o pod: default/test-deployment2-6594f5cd7f-nnzcs
I0121 16:00:55.276159       1 postFilter.go:145] [PREEMPT CALL] The node minikube  was chosen to allocate pod test-deployment3-ff66c7fc9-t7lg2
I0121 16:00:55.342409       1 scheduler.go:247] [OnUpdatePod] Pod atualizado: default/test-deployment2-6594f5cd7f-nnzcs, Anotações: map[controller:test-controller2]
I0121 16:00:55.381997       1 postFilter.go:74] Comparando pod original com o atualizado...
I0121 16:00:55.382157       1 postFilter.go:81] Successfully retrieved updated pod default/test-deployment2-6594f5cd7f-kbjpm from lister
I0121 16:00:55.389883       1 scheduler.go:69] Estado no Informer: map[controller:test-controller2]
I0121 16:00:55.389939       1 scheduler.go:70] Estado real no cluster: map[controller:test-controller2]
I0121 16:00:55.389949       1 types.go:743] [ControllerName] Verificando as anotações do pod default/test-deployment2-6594f5cd7f-nnzcs
I0121 16:00:55.389956       1 types.go:761] [ControllerName] Anotação 'controller' encontrada para o pod default/test-deployment2-6594f5cd7f-nnzcs: test-controller2
I0121 16:00:55.389996       1 scheduler.go:213] [OnAddPod] Pod adicionado: default/test-deployment2-6594f5cd7f-kbjpm, Anotações: map[controller:test-controller2]
I0121 16:00:55.405358       1 types.go:743] [ControllerName] Verificando as anotações do pod default/test-deployment2-6594f5cd7f-nnzcs
I0121 16:00:55.405544       1 types.go:761] [ControllerName] Anotação 'controller' encontrada para o pod default/test-deployment2-6594f5cd7f-nnzcs: test-controller2
I0121 16:00:55.414339       1 postFilter.go:204] Recursos CPU do nó minikube estão sincronizados: 2000 mCPU
I0121 16:00:55.415742       1 postFilter.go:211] Recursos Memória do nó minikube estão sincronizados: 2216124416 bytes
I0121 16:00:55.416328       1 scheduler.go:564] [GetControllerMetricInfo] Iniciando para o pod: default/test-deployment2-6594f5cd7f-nnzcs
I0121 16:00:55.419212       1 scheduler.go:569] [GetControllerMetricInfo] Obtendo o nome do controlador para o pod: default/test-deployment2-6594f5cd7f-nnzcs
I0121 16:00:55.419221       1 types.go:743] [ControllerName] Verificando as anotações do pod default/test-deployment2-6594f5cd7f-nnzcs
I0121 16:00:55.419228       1 types.go:761] [ControllerName] Anotação 'controller' encontrada para o pod default/test-deployment2-6594f5cd7f-nnzcs: test-controller2
I0121 16:00:55.419295       1 scheduler.go:572] [GetControllerMetricInfo] Métricas do controlador definidas para o pod: default/test-deployment2-6594f5cd7f-nnzcs
I0121 16:00:55.419317       1 scheduler.go:83] [HigherPrecedence] Calculando precedência entre test-deployment2-6594f5cd7f-kbjpm e test-deployment2-6594f5cd7f-nnzcs
I0121 16:00:55.419323       1 scheduler.go:116] [WaitForPodsOnCache] Verificando se o pod test-deployment2-6594f5cd7f-kbjpm está no cache...
I0121 16:00:55.419328       1 scheduler.go:564] [GetControllerMetricInfo] Iniciando para o pod: default/test-deployment2-6594f5cd7f-kbjpm
I0121 16:00:55.419332       1 scheduler.go:569] [GetControllerMetricInfo] Obtendo o nome do controlador para o pod: default/test-deployment2-6594f5cd7f-kbjpm
I0121 16:00:55.419336       1 types.go:743] [ControllerName] Verificando as anotações do pod default/test-deployment2-6594f5cd7f-kbjpm
I0121 16:00:55.419341       1 types.go:761] [ControllerName] Anotação 'controller' encontrada para o pod default/test-deployment2-6594f5cd7f-kbjpm: test-controller2
I0121 16:00:55.419385       1 scheduler.go:572] [GetControllerMetricInfo] Métricas do controlador definidas para o pod: default/test-deployment2-6594f5cd7f-kbjpm
W0121 16:00:55.419396       1 scheduler.go:124] [cacheMiss] Métricas não encontradas para o pod: default/test-deployment2-6594f5cd7f-kbjpm
I0121 16:00:55.434351       1 scheduler.go:69] Estado no Informer: map[controller:test-controller2]
I0121 16:00:55.434374       1 scheduler.go:70] Estado real no cluster: map[controller:test-controller2]
I0121 16:00:55.438433       1 scheduler.go:69] Estado no Informer: map[controller:test-controller2]
I0121 16:00:55.438523       1 scheduler.go:70] Estado real no cluster: map[controller:test-controller2]
W0121 16:00:55.438533       1 scheduler.go:134] [WaitForPodsOnCache] Pod test-deployment2-6594f5cd7f-kbjpm não encontrado no cache. Tentando novamente...
I0121 16:00:55.438553       1 types.go:743] [ControllerName] Verificando as anotações do pod default/test-deployment2-6594f5cd7f-kbjpm
I0121 16:00:55.438560       1 types.go:761] [ControllerName] Anotação 'controller' encontrada para o pod default/test-deployment2-6594f5cd7f-kbjpm: test-controller2
I0121 16:00:55.438573       1 types.go:743] [ControllerName] Verificando as anotações do pod default/test-deployment2-6594f5cd7f-kbjpm
I0121 16:00:55.438577       1 types.go:761] [ControllerName] Anotação 'controller' encontrada para o pod default/test-deployment2-6594f5cd7f-kbjpm: test-controller2
I0121 16:00:55.438656       1 scheduler.go:247] [OnUpdatePod] Pod atualizado: default/test-deployment3-ff66c7fc9-t7lg2, Anotações: map[controller:test-controller3]
I0121 16:00:55.447499       1 scheduler.go:69] Estado no Informer: map[controller:test-controller3]
I0121 16:00:55.447517       1 scheduler.go:70] Estado real no cluster: map[controller:test-controller3]
I0121 16:00:55.447524       1 types.go:743] [ControllerName] Verificando as anotações do pod default/test-deployment3-ff66c7fc9-t7lg2
I0121 16:00:55.447530       1 types.go:761] [ControllerName] Anotação 'controller' encontrada para o pod default/test-deployment3-ff66c7fc9-t7lg2: test-controller3
I0121 16:00:55.540024       1 scheduler.go:564] [GetControllerMetricInfo] Iniciando para o pod: default/test-deployment2-6594f5cd7f-kbjpm
I0121 16:00:55.540085       1 scheduler.go:569] [GetControllerMetricInfo] Obtendo o nome do controlador para o pod: default/test-deployment2-6594f5cd7f-kbjpm
I0121 16:00:55.540101       1 types.go:743] [ControllerName] Verificando as anotações do pod default/test-deployment2-6594f5cd7f-kbjpm
I0121 16:00:55.540123       1 types.go:761] [ControllerName] Anotação 'controller' encontrada para o pod default/test-deployment2-6594f5cd7f-kbjpm: test-controller2
I0121 16:00:55.540166       1 scheduler.go:572] [GetControllerMetricInfo] Métricas do controlador definidas para o pod: default/test-deployment2-6594f5cd7f-kbjpm
I0121 16:00:55.562602       1 scheduler.go:69] Estado no Informer: map[controller:test-controller2]
I0121 16:00:55.562669       1 scheduler.go:70] Estado real no cluster: map[controller:test-controller2]
I0121 16:00:55.562679       1 scheduler.go:138] [WaitForPodsOnCache] Pod test-deployment2-6594f5cd7f-kbjpm encontrado no cache.
I0121 16:00:55.562684       1 scheduler.go:116] [WaitForPodsOnCache] Verificando se o pod test-deployment2-6594f5cd7f-nnzcs está no cache...
I0121 16:00:55.562690       1 scheduler.go:564] [GetControllerMetricInfo] Iniciando para o pod: default/test-deployment2-6594f5cd7f-nnzcs
I0121 16:00:55.562706       1 scheduler.go:569] [GetControllerMetricInfo] Obtendo o nome do controlador para o pod: default/test-deployment2-6594f5cd7f-nnzcs
I0121 16:00:55.562713       1 types.go:743] [ControllerName] Verificando as anotações do pod default/test-deployment2-6594f5cd7f-nnzcs
I0121 16:00:55.562719       1 types.go:761] [ControllerName] Anotação 'controller' encontrada para o pod default/test-deployment2-6594f5cd7f-nnzcs: test-controller2
I0121 16:00:55.562725       1 scheduler.go:572] [GetControllerMetricInfo] Métricas do controlador definidas para o pod: default/test-deployment2-6594f5cd7f-nnzcs
I0121 16:00:55.755340       1 scheduler.go:69] Estado no Informer: map[controller:test-controller2]
I0121 16:00:55.755571       1 scheduler.go:70] Estado real no cluster: map[controller:test-controller2]
I0121 16:00:55.760290       1 scheduler.go:138] [WaitForPodsOnCache] Pod test-deployment2-6594f5cd7f-nnzcs encontrado no cache.
I0121 16:00:55.760394       1 scheduler.go:564] [GetControllerMetricInfo] Iniciando para o pod: default/test-deployment2-6594f5cd7f-kbjpm
I0121 16:00:55.760435       1 scheduler.go:569] [GetControllerMetricInfo] Obtendo o nome do controlador para o pod: default/test-deployment2-6594f5cd7f-kbjpm
I0121 16:00:55.760602       1 types.go:743] [ControllerName] Verificando as anotações do pod default/test-deployment2-6594f5cd7f-kbjpm
I0121 16:00:55.760727       1 types.go:761] [ControllerName] Anotação 'controller' encontrada para o pod default/test-deployment2-6594f5cd7f-kbjpm: test-controller2
I0121 16:00:55.760880       1 scheduler.go:572] [GetControllerMetricInfo] Métricas do controlador definidas para o pod: default/test-deployment2-6594f5cd7f-kbjpm
I0121 16:00:55.760987       1 scheduler.go:564] [GetControllerMetricInfo] Iniciando para o pod: default/test-deployment2-6594f5cd7f-nnzcs
I0121 16:00:55.761125       1 scheduler.go:569] [GetControllerMetricInfo] Obtendo o nome do controlador para o pod: default/test-deployment2-6594f5cd7f-nnzcs
I0121 16:00:55.761165       1 types.go:743] [ControllerName] Verificando as anotações do pod default/test-deployment2-6594f5cd7f-nnzcs
I0121 16:00:55.761380       1 types.go:761] [ControllerName] Anotação 'controller' encontrada para o pod default/test-deployment2-6594f5cd7f-nnzcs: test-controller2
I0121 16:00:55.761419       1 scheduler.go:572] [GetControllerMetricInfo] Métricas do controlador definidas para o pod: default/test-deployment2-6594f5cd7f-nnzcs
I0121 16:00:55.761551       1 scheduler.go:97] [HigherPrecedence] Métricas para test-deployment2-6594f5cd7f-kbjpm: QoS = -543.367214, Importância = 0.80
I0121 16:00:55.761676       1 scheduler.go:98] [HigherPrecedence] Métricas para test-deployment2-6594f5cd7f-nnzcs: QoS = -543.367214, Importância = 0.80
I0121 16:00:55.761717       1 scheduler.go:109] [HigherPrecedence] Decisão final: test-deployment2-6594f5cd7f-kbjpm tem precedência sobre test-deployment2-6594f5cd7f-nnzcs? false
I0121 16:00:55.762071       1 postFilter.go:142] [PREEMPT CALL] No node was chosen to allocate pod test-deployment2-6594f5cd7f-kbjpm
I0121 16:00:55.838236       1 scheduler.go:247] [OnUpdatePod] Pod atualizado: default/test-deployment2-6594f5cd7f-kbjpm, Anotações: map[controller:test-controller2]
I0121 16:00:55.842532       1 scheduler.go:69] Estado no Informer: map[controller:test-controller2]
I0121 16:00:55.842552       1 scheduler.go:70] Estado real no cluster: map[controller:test-controller2]
I0121 16:00:55.842560       1 types.go:743] [ControllerName] Verificando as anotações do pod default/test-deployment2-6594f5cd7f-kbjpm
I0121 16:00:55.842566       1 types.go:761] [ControllerName] Anotação 'controller' encontrada para o pod default/test-deployment2-6594f5cd7f-kbjpm: test-controller2
I0121 16:00:56.805943       1 types.go:743] [ControllerName] Verificando as anotações do pod default/test-deployment2-6594f5cd7f-nnzcs
I0121 16:00:56.805977       1 types.go:761] [ControllerName] Anotação 'controller' encontrada para o pod default/test-deployment2-6594f5cd7f-nnzcs: test-controller2
I0121 16:00:56.806140       1 scheduler.go:53] [QueueSort] Comparando prioridade de test-deployment2-6594f5cd7f-kbjpm com test-deployment3-ff66c7fc9-t7lg2
I0121 16:00:56.806173       1 scheduler.go:83] [HigherPrecedence] Calculando precedência entre test-deployment2-6594f5cd7f-kbjpm e test-deployment3-ff66c7fc9-t7lg2
I0121 16:00:56.806182       1 scheduler.go:116] [WaitForPodsOnCache] Verificando se o pod test-deployment2-6594f5cd7f-kbjpm está no cache...
I0121 16:00:56.806191       1 scheduler.go:564] [GetControllerMetricInfo] Iniciando para o pod: default/test-deployment2-6594f5cd7f-kbjpm
I0121 16:00:56.806219       1 scheduler.go:569] [GetControllerMetricInfo] Obtendo o nome do controlador para o pod: default/test-deployment2-6594f5cd7f-kbjpm
I0121 16:00:56.806227       1 types.go:743] [ControllerName] Verificando as anotações do pod default/test-deployment2-6594f5cd7f-kbjpm
I0121 16:00:56.806236       1 types.go:761] [ControllerName] Anotação 'controller' encontrada para o pod default/test-deployment2-6594f5cd7f-kbjpm: test-controller2
I0121 16:00:56.806244       1 scheduler.go:572] [GetControllerMetricInfo] Métricas do controlador definidas para o pod: default/test-deployment2-6594f5cd7f-kbjpm
I0121 16:00:56.826756       1 scheduler.go:69] Estado no Informer: map[controller:test-controller2]
I0121 16:00:56.826824       1 scheduler.go:70] Estado real no cluster: map[controller:test-controller2]
I0121 16:00:56.826836       1 scheduler.go:138] [WaitForPodsOnCache] Pod test-deployment2-6594f5cd7f-kbjpm encontrado no cache.
I0121 16:00:56.826844       1 scheduler.go:116] [WaitForPodsOnCache] Verificando se o pod test-deployment3-ff66c7fc9-t7lg2 está no cache...
I0121 16:00:56.826852       1 scheduler.go:564] [GetControllerMetricInfo] Iniciando para o pod: default/test-deployment3-ff66c7fc9-t7lg2
I0121 16:00:56.826859       1 scheduler.go:569] [GetControllerMetricInfo] Obtendo o nome do controlador para o pod: default/test-deployment3-ff66c7fc9-t7lg2
I0121 16:00:56.826868       1 types.go:743] [ControllerName] Verificando as anotações do pod default/test-deployment3-ff66c7fc9-t7lg2
I0121 16:00:56.826876       1 types.go:761] [ControllerName] Anotação 'controller' encontrada para o pod default/test-deployment3-ff66c7fc9-t7lg2: test-controller3
I0121 16:00:56.826884       1 scheduler.go:572] [GetControllerMetricInfo] Métricas do controlador definidas para o pod: default/test-deployment3-ff66c7fc9-t7lg2
I0121 16:00:56.833079       1 scheduler.go:69] Estado no Informer: map[controller:test-controller3]
I0121 16:00:56.833343       1 scheduler.go:70] Estado real no cluster: map[controller:test-controller3]
I0121 16:00:56.835361       1 scheduler.go:138] [WaitForPodsOnCache] Pod test-deployment3-ff66c7fc9-t7lg2 encontrado no cache.
I0121 16:00:56.835378       1 scheduler.go:564] [GetControllerMetricInfo] Iniciando para o pod: default/test-deployment2-6594f5cd7f-kbjpm
I0121 16:00:56.835385       1 scheduler.go:569] [GetControllerMetricInfo] Obtendo o nome do controlador para o pod: default/test-deployment2-6594f5cd7f-kbjpm
I0121 16:00:56.835441       1 types.go:743] [ControllerName] Verificando as anotações do pod default/test-deployment2-6594f5cd7f-kbjpm
I0121 16:00:56.835526       1 types.go:761] [ControllerName] Anotação 'controller' encontrada para o pod default/test-deployment2-6594f5cd7f-kbjpm: test-controller2
I0121 16:00:56.835537       1 scheduler.go:572] [GetControllerMetricInfo] Métricas do controlador definidas para o pod: default/test-deployment2-6594f5cd7f-kbjpm
I0121 16:00:56.835549       1 scheduler.go:564] [GetControllerMetricInfo] Iniciando para o pod: default/test-deployment3-ff66c7fc9-t7lg2
I0121 16:00:56.835554       1 scheduler.go:569] [GetControllerMetricInfo] Obtendo o nome do controlador para o pod: default/test-deployment3-ff66c7fc9-t7lg2
I0121 16:00:56.835559       1 types.go:743] [ControllerName] Verificando as anotações do pod default/test-deployment3-ff66c7fc9-t7lg2
I0121 16:00:56.835564       1 types.go:761] [ControllerName] Anotação 'controller' encontrada para o pod default/test-deployment3-ff66c7fc9-t7lg2: test-controller3
I0121 16:00:56.835570       1 scheduler.go:572] [GetControllerMetricInfo] Métricas do controlador definidas para o pod: default/test-deployment3-ff66c7fc9-t7lg2
I0121 16:00:56.835654       1 scheduler.go:97] [HigherPrecedence] Métricas para test-deployment2-6594f5cd7f-kbjpm: QoS = -544.407400, Importância = 0.80
I0121 16:00:56.835667       1 scheduler.go:98] [HigherPrecedence] Métricas para test-deployment3-ff66c7fc9-t7lg2: QoS = -559.838203, Importância = 0.80
I0121 16:00:56.835675       1 scheduler.go:109] [HigherPrecedence] Decisão final: test-deployment2-6594f5cd7f-kbjpm tem precedência sobre test-deployment3-ff66c7fc9-t7lg2? false
I0121 16:00:56.835684       1 scheduler.go:59] [QueueSort] Precedência determinada: test-deployment2-6594f5cd7f-kbjpm tem precedência sobre test-deployment3-ff66c7fc9-t7lg2? false
I0121 16:00:56.840065       1 scheduler.go:145] [Reserve] resources reserved at node minikube for pod test-deployment3-ff66c7fc9-t7lg2_default at 2025-01-21 16:00:56.838746795 +0000 UTC m=+1273.493315520
I0121 16:00:56.840190       1 types.go:743] [ControllerName] Verificando as anotações do pod default/test-deployment3-ff66c7fc9-t7lg2
I0121 16:00:56.840200       1 types.go:761] [ControllerName] Anotação 'controller' encontrada para o pod default/test-deployment3-ff66c7fc9-t7lg2: test-controller3
I0121 16:00:56.840296       1 scheduler.go:147] [Reserve] Status de alocação atual para o pod test-deployment3-ff66c7fc9-t7lg2_default: 
I0121 16:00:56.840313       1 scheduler.go:149] [Reserve] Status de alocação atualizado para o pod test-deployment3-ff66c7fc9-t7lg2_default: allocating
I0121 16:00:56.847343       1 postFilter.go:74] Comparando pod original com o atualizado...
I0121 16:00:56.847362       1 postFilter.go:81] Successfully retrieved updated pod default/test-deployment2-6594f5cd7f-kbjpm from lister
I0121 16:00:56.847682       1 scheduler.go:173] [PreBind] Validando o pod test-deployment3-ff66c7fc9-t7lg2 antes de vincular ao node minikube
I0121 16:00:56.854018       1 postFilter.go:204] Recursos CPU do nó minikube estão sincronizados: 2000 mCPU
I0121 16:00:56.854077       1 postFilter.go:211] Recursos Memória do nó minikube estão sincronizados: 2216124416 bytes
I0121 16:00:56.854232       1 scheduler.go:564] [GetControllerMetricInfo] Iniciando para o pod: default/test-deployment3-ff66c7fc9-t7lg2
I0121 16:00:56.854268       1 scheduler.go:569] [GetControllerMetricInfo] Obtendo o nome do controlador para o pod: default/test-deployment3-ff66c7fc9-t7lg2
I0121 16:00:56.854277       1 types.go:743] [ControllerName] Verificando as anotações do pod default/test-deployment3-ff66c7fc9-t7lg2
I0121 16:00:56.854284       1 types.go:761] [ControllerName] Anotação 'controller' encontrada para o pod default/test-deployment3-ff66c7fc9-t7lg2: test-controller3
I0121 16:00:56.854291       1 scheduler.go:572] [GetControllerMetricInfo] Métricas do controlador definidas para o pod: default/test-deployment3-ff66c7fc9-t7lg2
I0121 16:00:56.854299       1 scheduler.go:83] [HigherPrecedence] Calculando precedência entre test-deployment2-6594f5cd7f-kbjpm e test-deployment3-ff66c7fc9-t7lg2
I0121 16:00:56.854307       1 scheduler.go:116] [WaitForPodsOnCache] Verificando se o pod test-deployment2-6594f5cd7f-kbjpm está no cache...
I0121 16:00:56.854312       1 scheduler.go:564] [GetControllerMetricInfo] Iniciando para o pod: default/test-deployment2-6594f5cd7f-kbjpm
I0121 16:00:56.854318       1 scheduler.go:569] [GetControllerMetricInfo] Obtendo o nome do controlador para o pod: default/test-deployment2-6594f5cd7f-kbjpm
I0121 16:00:56.854322       1 types.go:743] [ControllerName] Verificando as anotações do pod default/test-deployment2-6594f5cd7f-kbjpm
I0121 16:00:56.854328       1 types.go:761] [ControllerName] Anotação 'controller' encontrada para o pod default/test-deployment2-6594f5cd7f-kbjpm: test-controller2
I0121 16:00:56.854335       1 scheduler.go:572] [GetControllerMetricInfo] Métricas do controlador definidas para o pod: default/test-deployment2-6594f5cd7f-kbjpm
I0121 16:00:56.895590       1 scheduler.go:181] [PostBind] Chamado para pod test-deployment3-ff66c7fc9-t7lg2
I0121 16:00:56.895639       1 scheduler.go:199] [PostBind] Pod test-deployment3-ff66c7fc9-t7lg2 - Início do binding: 2025-01-21 16:00:56.847687705 +0000 UTC m=+1273.502256331, Fim do binding: 2025-01-21 16:00:56.895634657 +0000 UTC m=+1273.550203294
I0121 16:00:56.895892       1 scheduler.go:69] Estado no Informer: map[controller:test-controller2]
I0121 16:00:56.895972       1 scheduler.go:70] Estado real no cluster: map[controller:test-controller2]
I0121 16:00:56.895982       1 scheduler.go:138] [WaitForPodsOnCache] Pod test-deployment2-6594f5cd7f-kbjpm encontrado no cache.
I0121 16:00:56.895987       1 scheduler.go:116] [WaitForPodsOnCache] Verificando se o pod test-deployment3-ff66c7fc9-t7lg2 está no cache...
I0121 16:00:56.895992       1 scheduler.go:564] [GetControllerMetricInfo] Iniciando para o pod: default/test-deployment3-ff66c7fc9-t7lg2
I0121 16:00:56.895996       1 scheduler.go:247] [OnUpdatePod] Pod atualizado: default/test-deployment3-ff66c7fc9-t7lg2, Anotações: map[controller:test-controller3]
I0121 16:00:56.896004       1 types.go:743] [ControllerName] Verificando as anotações do pod default/test-deployment3-ff66c7fc9-t7lg2
I0121 16:00:56.896146       1 types.go:761] [ControllerName] Anotação 'controller' encontrada para o pod default/test-deployment3-ff66c7fc9-t7lg2: test-controller3
I0121 16:00:56.896176       1 scheduler.go:206] [PostBind] Métricas atualizadas para o pod test-deployment3-ff66c7fc9-t7lg2
I0121 16:00:56.896295       1 scheduler.go:569] [GetControllerMetricInfo] Obtendo o nome do controlador para o pod: default/test-deployment3-ff66c7fc9-t7lg2
I0121 16:00:56.896301       1 types.go:743] [ControllerName] Verificando as anotações do pod default/test-deployment3-ff66c7fc9-t7lg2
I0121 16:00:56.896305       1 types.go:761] [ControllerName] Anotação 'controller' encontrada para o pod default/test-deployment3-ff66c7fc9-t7lg2: test-controller3
I0121 16:00:56.896310       1 scheduler.go:572] [GetControllerMetricInfo] Métricas do controlador definidas para o pod: default/test-deployment3-ff66c7fc9-t7lg2
I0121 16:00:56.904861       1 scheduler.go:69] Estado no Informer: map[controller:test-controller3]
I0121 16:00:56.904910       1 scheduler.go:70] Estado real no cluster: map[controller:test-controller3]
I0121 16:00:56.910304       1 scheduler.go:69] Estado no Informer: map[controller:test-controller3]
I0121 16:00:56.910343       1 scheduler.go:70] Estado real no cluster: map[controller:test-controller3]
I0121 16:00:56.910353       1 scheduler.go:138] [WaitForPodsOnCache] Pod test-deployment3-ff66c7fc9-t7lg2 encontrado no cache.
I0121 16:00:56.910404       1 scheduler.go:564] [GetControllerMetricInfo] Iniciando para o pod: default/test-deployment2-6594f5cd7f-kbjpm
I0121 16:00:56.910418       1 types.go:743] [ControllerName] Verificando as anotações do pod default/test-deployment3-ff66c7fc9-t7lg2
I0121 16:00:56.910424       1 types.go:761] [ControllerName] Anotação 'controller' encontrada para o pod default/test-deployment3-ff66c7fc9-t7lg2: test-controller3
I0121 16:00:56.910441       1 scheduler.go:569] [GetControllerMetricInfo] Obtendo o nome do controlador para o pod: default/test-deployment2-6594f5cd7f-kbjpm
I0121 16:00:56.910445       1 types.go:743] [ControllerName] Verificando as anotações do pod default/test-deployment2-6594f5cd7f-kbjpm
I0121 16:00:56.910487       1 types.go:761] [ControllerName] Anotação 'controller' encontrada para o pod default/test-deployment2-6594f5cd7f-kbjpm: test-controller2
I0121 16:00:56.910496       1 scheduler.go:572] [GetControllerMetricInfo] Métricas do controlador definidas para o pod: default/test-deployment2-6594f5cd7f-kbjpm
I0121 16:00:56.913670       1 scheduler.go:564] [GetControllerMetricInfo] Iniciando para o pod: default/test-deployment3-ff66c7fc9-t7lg2
I0121 16:00:56.913677       1 scheduler.go:569] [GetControllerMetricInfo] Obtendo o nome do controlador para o pod: default/test-deployment3-ff66c7fc9-t7lg2
I0121 16:00:56.913682       1 types.go:743] [ControllerName] Verificando as anotações do pod default/test-deployment3-ff66c7fc9-t7lg2
I0121 16:00:56.913689       1 types.go:761] [ControllerName] Anotação 'controller' encontrada para o pod default/test-deployment3-ff66c7fc9-t7lg2: test-controller3
I0121 16:00:56.913695       1 scheduler.go:572] [GetControllerMetricInfo] Métricas do controlador definidas para o pod: default/test-deployment3-ff66c7fc9-t7lg2
I0121 16:00:56.913712       1 scheduler.go:97] [HigherPrecedence] Métricas para test-deployment2-6594f5cd7f-kbjpm: QoS = -544.455536, Importância = 0.80
I0121 16:00:56.913742       1 scheduler.go:98] [HigherPrecedence] Métricas para test-deployment3-ff66c7fc9-t7lg2: QoS = -559.946004, Importância = 0.80
I0121 16:00:56.913750       1 scheduler.go:109] [HigherPrecedence] Decisão final: test-deployment2-6594f5cd7f-kbjpm tem precedência sobre test-deployment3-ff66c7fc9-t7lg2? false
I0121 16:00:56.913817       1 postFilter.go:142] [PREEMPT CALL] No node was chosen to allocate pod test-deployment2-6594f5cd7f-kbjpm
I0121 16:00:56.954636       1 scheduler.go:247] [OnUpdatePod] Pod atualizado: default/test-deployment3-ff66c7fc9-t7lg2, Anotações: map[controller:test-controller3]
I0121 16:00:56.964666       1 scheduler.go:69] Estado no Informer: map[controller:test-controller3]
I0121 16:00:56.964795       1 scheduler.go:70] Estado real no cluster: map[controller:test-controller3]
I0121 16:00:56.964877       1 types.go:743] [ControllerName] Verificando as anotações do pod default/test-deployment3-ff66c7fc9-t7lg2
I0121 16:00:56.964899       1 types.go:761] [ControllerName] Anotação 'controller' encontrada para o pod default/test-deployment3-ff66c7fc9-t7lg2: test-controller3
I0121 16:00:59.634223       1 postFilter.go:74] Comparando pod original com o atualizado...
I0121 16:00:59.634441       1 postFilter.go:81] Successfully retrieved updated pod default/test-deployment2-6594f5cd7f-kbjpm from lister
I0121 16:00:59.649833       1 postFilter.go:204] Recursos CPU do nó minikube estão sincronizados: 2000 mCPU
I0121 16:00:59.649928       1 postFilter.go:211] Recursos Memória do nó minikube estão sincronizados: 2216124416 bytes
I0121 16:00:59.650861       1 scheduler.go:564] [GetControllerMetricInfo] Iniciando para o pod: default/test-deployment3-ff66c7fc9-t7lg2
I0121 16:00:59.663223       1 scheduler.go:569] [GetControllerMetricInfo] Obtendo o nome do controlador para o pod: default/test-deployment3-ff66c7fc9-t7lg2
I0121 16:00:59.663256       1 types.go:743] [ControllerName] Verificando as anotações do pod default/test-deployment3-ff66c7fc9-t7lg2
I0121 16:00:59.663272       1 types.go:761] [ControllerName] Anotação 'controller' encontrada para o pod default/test-deployment3-ff66c7fc9-t7lg2: test-controller3
I0121 16:00:59.663286       1 scheduler.go:572] [GetControllerMetricInfo] Métricas do controlador definidas para o pod: default/test-deployment3-ff66c7fc9-t7lg2
I0121 16:00:59.663300       1 scheduler.go:83] [HigherPrecedence] Calculando precedência entre test-deployment2-6594f5cd7f-kbjpm e test-deployment3-ff66c7fc9-t7lg2
I0121 16:00:59.663312       1 scheduler.go:116] [WaitForPodsOnCache] Verificando se o pod test-deployment2-6594f5cd7f-kbjpm está no cache...
I0121 16:00:59.663321       1 scheduler.go:564] [GetControllerMetricInfo] Iniciando para o pod: default/test-deployment2-6594f5cd7f-kbjpm
I0121 16:00:59.663330       1 scheduler.go:569] [GetControllerMetricInfo] Obtendo o nome do controlador para o pod: default/test-deployment2-6594f5cd7f-kbjpm
I0121 16:00:59.663344       1 types.go:743] [ControllerName] Verificando as anotações do pod default/test-deployment2-6594f5cd7f-kbjpm
I0121 16:00:59.663354       1 types.go:761] [ControllerName] Anotação 'controller' encontrada para o pod default/test-deployment2-6594f5cd7f-kbjpm: test-controller2
I0121 16:00:59.663364       1 scheduler.go:572] [GetControllerMetricInfo] Métricas do controlador definidas para o pod: default/test-deployment2-6594f5cd7f-kbjpm
I0121 16:00:59.676410       1 scheduler.go:69] Estado no Informer: map[controller:test-controller2]
I0121 16:00:59.677645       1 scheduler.go:70] Estado real no cluster: map[controller:test-controller2]
I0121 16:00:59.678025       1 scheduler.go:138] [WaitForPodsOnCache] Pod test-deployment2-6594f5cd7f-kbjpm encontrado no cache.
I0121 16:00:59.679068       1 scheduler.go:116] [WaitForPodsOnCache] Verificando se o pod test-deployment3-ff66c7fc9-t7lg2 está no cache...
I0121 16:00:59.679291       1 scheduler.go:564] [GetControllerMetricInfo] Iniciando para o pod: default/test-deployment3-ff66c7fc9-t7lg2
I0121 16:00:59.679576       1 scheduler.go:569] [GetControllerMetricInfo] Obtendo o nome do controlador para o pod: default/test-deployment3-ff66c7fc9-t7lg2
I0121 16:00:59.679852       1 types.go:743] [ControllerName] Verificando as anotações do pod default/test-deployment3-ff66c7fc9-t7lg2
I0121 16:00:59.680046       1 types.go:761] [ControllerName] Anotação 'controller' encontrada para o pod default/test-deployment3-ff66c7fc9-t7lg2: test-controller3
I0121 16:00:59.680307       1 scheduler.go:572] [GetControllerMetricInfo] Métricas do controlador definidas para o pod: default/test-deployment3-ff66c7fc9-t7lg2
I0121 16:00:59.690807       1 scheduler.go:69] Estado no Informer: map[controller:test-controller3]
I0121 16:00:59.690884       1 scheduler.go:70] Estado real no cluster: map[controller:test-controller3]
I0121 16:00:59.690904       1 scheduler.go:138] [WaitForPodsOnCache] Pod test-deployment3-ff66c7fc9-t7lg2 encontrado no cache.
I0121 16:00:59.690915       1 scheduler.go:564] [GetControllerMetricInfo] Iniciando para o pod: default/test-deployment2-6594f5cd7f-kbjpm
I0121 16:00:59.690926       1 scheduler.go:569] [GetControllerMetricInfo] Obtendo o nome do controlador para o pod: default/test-deployment2-6594f5cd7f-kbjpm
I0121 16:00:59.690936       1 types.go:743] [ControllerName] Verificando as anotações do pod default/test-deployment2-6594f5cd7f-kbjpm
I0121 16:00:59.690947       1 types.go:761] [ControllerName] Anotação 'controller' encontrada para o pod default/test-deployment2-6594f5cd7f-kbjpm: test-controller2
I0121 16:00:59.690958       1 scheduler.go:572] [GetControllerMetricInfo] Métricas do controlador definidas para o pod: default/test-deployment2-6594f5cd7f-kbjpm
I0121 16:00:59.690980       1 scheduler.go:564] [GetControllerMetricInfo] Iniciando para o pod: default/test-deployment3-ff66c7fc9-t7lg2
I0121 16:00:59.690989       1 scheduler.go:569] [GetControllerMetricInfo] Obtendo o nome do controlador para o pod: default/test-deployment3-ff66c7fc9-t7lg2
I0121 16:00:59.690996       1 types.go:743] [ControllerName] Verificando as anotações do pod default/test-deployment3-ff66c7fc9-t7lg2
I0121 16:00:59.691004       1 types.go:761] [ControllerName] Anotação 'controller' encontrada para o pod default/test-deployment3-ff66c7fc9-t7lg2: test-controller3
I0121 16:00:59.691014       1 scheduler.go:572] [GetControllerMetricInfo] Métricas do controlador definidas para o pod: default/test-deployment3-ff66c7fc9-t7lg2
I0121 16:00:59.691037       1 scheduler.go:97] [HigherPrecedence] Métricas para test-deployment2-6594f5cd7f-kbjpm: QoS = -547.264534, Importância = 0.80
I0121 16:00:59.691055       1 scheduler.go:98] [HigherPrecedence] Métricas para test-deployment3-ff66c7fc9-t7lg2: QoS = -559.243754, Importância = 0.80
I0121 16:00:59.691068       1 scheduler.go:109] [HigherPrecedence] Decisão final: test-deployment2-6594f5cd7f-kbjpm tem precedência sobre test-deployment3-ff66c7fc9-t7lg2? false
I0121 16:00:59.691178       1 postFilter.go:142] [PREEMPT CALL] No node was chosen to allocate pod test-deployment2-6594f5cd7f-kbjpm
I0121 16:01:00.371748       1 scheduler.go:247] [OnUpdatePod] Pod atualizado: default/test-deployment3-ff66c7fc9-t7lg2, Anotações: map[controller:test-controller3]
I0121 16:01:00.395599       1 scheduler.go:69] Estado no Informer: map[controller:test-controller3]
I0121 16:01:00.395665       1 scheduler.go:70] Estado real no cluster: map[controller:test-controller3]
I0121 16:01:00.395682       1 types.go:743] [ControllerName] Verificando as anotações do pod default/test-deployment3-ff66c7fc9-t7lg2
I0121 16:01:00.398576       1 types.go:761] [ControllerName] Anotação 'controller' encontrada para o pod default/test-deployment3-ff66c7fc9-t7lg2: test-controller3
I0121 16:06:14.672825       1 postFilter.go:74] Comparando pod original com o atualizado...
I0121 16:06:14.673008       1 postFilter.go:81] Successfully retrieved updated pod default/test-deployment2-6594f5cd7f-kbjpm from lister
I0121 16:06:14.692420       1 postFilter.go:204] Recursos CPU do nó minikube estão sincronizados: 2000 mCPU
I0121 16:06:14.692581       1 postFilter.go:211] Recursos Memória do nó minikube estão sincronizados: 2216124416 bytes
I0121 16:06:14.700435       1 scheduler.go:564] [GetControllerMetricInfo] Iniciando para o pod: default/test-deployment3-ff66c7fc9-t7lg2
I0121 16:06:14.700650       1 scheduler.go:569] [GetControllerMetricInfo] Obtendo o nome do controlador para o pod: default/test-deployment3-ff66c7fc9-t7lg2
I0121 16:06:14.700688       1 types.go:743] [ControllerName] Verificando as anotações do pod default/test-deployment3-ff66c7fc9-t7lg2
I0121 16:06:14.700702       1 types.go:761] [ControllerName] Anotação 'controller' encontrada para o pod default/test-deployment3-ff66c7fc9-t7lg2: test-controller3
I0121 16:06:14.700719       1 scheduler.go:572] [GetControllerMetricInfo] Métricas do controlador definidas para o pod: default/test-deployment3-ff66c7fc9-t7lg2
I0121 16:06:14.700750       1 scheduler.go:83] [HigherPrecedence] Calculando precedência entre test-deployment2-6594f5cd7f-kbjpm e test-deployment3-ff66c7fc9-t7lg2
I0121 16:06:14.700764       1 scheduler.go:116] [WaitForPodsOnCache] Verificando se o pod test-deployment2-6594f5cd7f-kbjpm está no cache...
I0121 16:06:14.700789       1 scheduler.go:564] [GetControllerMetricInfo] Iniciando para o pod: default/test-deployment2-6594f5cd7f-kbjpm
I0121 16:06:14.709207       1 scheduler.go:569] [GetControllerMetricInfo] Obtendo o nome do controlador para o pod: default/test-deployment2-6594f5cd7f-kbjpm
I0121 16:06:14.709222       1 types.go:743] [ControllerName] Verificando as anotações do pod default/test-deployment2-6594f5cd7f-kbjpm
I0121 16:06:14.709234       1 types.go:761] [ControllerName] Anotação 'controller' encontrada para o pod default/test-deployment2-6594f5cd7f-kbjpm: test-controller2
I0121 16:06:14.709246       1 scheduler.go:572] [GetControllerMetricInfo] Métricas do controlador definidas para o pod: default/test-deployment2-6594f5cd7f-kbjpm
I0121 16:06:14.720913       1 scheduler.go:69] Estado no Informer: map[controller:test-controller2]
I0121 16:06:14.721386       1 scheduler.go:70] Estado real no cluster: map[controller:test-controller2]
I0121 16:06:14.724596       1 scheduler.go:138] [WaitForPodsOnCache] Pod test-deployment2-6594f5cd7f-kbjpm encontrado no cache.
I0121 16:06:14.724666       1 scheduler.go:116] [WaitForPodsOnCache] Verificando se o pod test-deployment3-ff66c7fc9-t7lg2 está no cache...
I0121 16:06:14.724680       1 scheduler.go:564] [GetControllerMetricInfo] Iniciando para o pod: default/test-deployment3-ff66c7fc9-t7lg2
I0121 16:06:14.724690       1 scheduler.go:569] [GetControllerMetricInfo] Obtendo o nome do controlador para o pod: default/test-deployment3-ff66c7fc9-t7lg2
I0121 16:06:14.724700       1 types.go:743] [ControllerName] Verificando as anotações do pod default/test-deployment3-ff66c7fc9-t7lg2
I0121 16:06:14.724712       1 types.go:761] [ControllerName] Anotação 'controller' encontrada para o pod default/test-deployment3-ff66c7fc9-t7lg2: test-controller3
I0121 16:06:14.724763       1 scheduler.go:572] [GetControllerMetricInfo] Métricas do controlador definidas para o pod: default/test-deployment3-ff66c7fc9-t7lg2
I0121 16:06:14.740906       1 scheduler.go:69] Estado no Informer: map[controller:test-controller3]
I0121 16:06:14.740996       1 scheduler.go:70] Estado real no cluster: map[controller:test-controller3]
I0121 16:06:14.741012       1 scheduler.go:138] [WaitForPodsOnCache] Pod test-deployment3-ff66c7fc9-t7lg2 encontrado no cache.
I0121 16:06:14.741022       1 scheduler.go:564] [GetControllerMetricInfo] Iniciando para o pod: default/test-deployment2-6594f5cd7f-kbjpm
I0121 16:06:14.741033       1 scheduler.go:569] [GetControllerMetricInfo] Obtendo o nome do controlador para o pod: default/test-deployment2-6594f5cd7f-kbjpm
I0121 16:06:14.741042       1 types.go:743] [ControllerName] Verificando as anotações do pod default/test-deployment2-6594f5cd7f-kbjpm
I0121 16:06:14.741051       1 types.go:761] [ControllerName] Anotação 'controller' encontrada para o pod default/test-deployment2-6594f5cd7f-kbjpm: test-controller2
I0121 16:06:14.741063       1 scheduler.go:572] [GetControllerMetricInfo] Métricas do controlador definidas para o pod: default/test-deployment2-6594f5cd7f-kbjpm
I0121 16:06:14.741114       1 scheduler.go:564] [GetControllerMetricInfo] Iniciando para o pod: default/test-deployment3-ff66c7fc9-t7lg2
I0121 16:06:14.741123       1 scheduler.go:569] [GetControllerMetricInfo] Obtendo o nome do controlador para o pod: default/test-deployment3-ff66c7fc9-t7lg2
I0121 16:06:14.741130       1 types.go:743] [ControllerName] Verificando as anotações do pod default/test-deployment3-ff66c7fc9-t7lg2
I0121 16:06:14.741139       1 types.go:761] [ControllerName] Anotação 'controller' encontrada para o pod default/test-deployment3-ff66c7fc9-t7lg2: test-controller3
I0121 16:06:14.741153       1 scheduler.go:572] [GetControllerMetricInfo] Métricas do controlador definidas para o pod: default/test-deployment3-ff66c7fc9-t7lg2
I0121 16:06:14.741176       1 scheduler.go:97] [HigherPrecedence] Métricas para test-deployment2-6594f5cd7f-kbjpm: QoS = -862.301982, Importância = 0.80
I0121 16:06:14.741277       1 scheduler.go:98] [HigherPrecedence] Métricas para test-deployment3-ff66c7fc9-t7lg2: QoS = -480.484392, Importância = 0.80
I0121 16:06:14.741293       1 scheduler.go:109] [HigherPrecedence] Decisão final: test-deployment2-6594f5cd7f-kbjpm tem precedência sobre test-deployment3-ff66c7fc9-t7lg2? true
I0121 16:06:14.741303       1 types.go:743] [ControllerName] Verificando as anotações do pod default/test-deployment2-6594f5cd7f-kbjpm
I0121 16:06:14.741312       1 types.go:761] [ControllerName] Anotação 'controller' encontrada para o pod default/test-deployment2-6594f5cd7f-kbjpm: test-controller2
I0121 16:06:14.741319       1 types.go:743] [ControllerName] Verificando as anotações do pod default/test-deployment3-ff66c7fc9-t7lg2
I0121 16:06:14.741327       1 types.go:761] [ControllerName] Anotação 'controller' encontrada para o pod default/test-deployment3-ff66c7fc9-t7lg2: test-controller3
I0121 16:06:14.741335       1 scheduler.go:564] [GetControllerMetricInfo] Iniciando para o pod: default/test-deployment3-ff66c7fc9-t7lg2
I0121 16:06:14.741342       1 scheduler.go:569] [GetControllerMetricInfo] Obtendo o nome do controlador para o pod: default/test-deployment3-ff66c7fc9-t7lg2
I0121 16:06:14.741348       1 types.go:743] [ControllerName] Verificando as anotações do pod default/test-deployment3-ff66c7fc9-t7lg2
I0121 16:06:14.741356       1 types.go:761] [ControllerName] Anotação 'controller' encontrada para o pod default/test-deployment3-ff66c7fc9-t7lg2: test-controller3
I0121 16:06:14.741365       1 scheduler.go:572] [GetControllerMetricInfo] Métricas do controlador definidas para o pod: default/test-deployment3-ff66c7fc9-t7lg2
I0121 16:06:14.741373       1 scheduler.go:564] [GetControllerMetricInfo] Iniciando para o pod: default/test-deployment3-ff66c7fc9-t7lg2
I0121 16:06:14.741381       1 scheduler.go:569] [GetControllerMetricInfo] Obtendo o nome do controlador para o pod: default/test-deployment3-ff66c7fc9-t7lg2
I0121 16:06:14.741389       1 types.go:743] [ControllerName] Verificando as anotações do pod default/test-deployment3-ff66c7fc9-t7lg2
I0121 16:06:14.741397       1 types.go:761] [ControllerName] Anotação 'controller' encontrada para o pod default/test-deployment3-ff66c7fc9-t7lg2: test-controller3
I0121 16:06:14.741405       1 scheduler.go:572] [GetControllerMetricInfo] Métricas do controlador definidas para o pod: default/test-deployment3-ff66c7fc9-t7lg2
I0121 16:06:14.741416       1 types.go:743] [ControllerName] Verificando as anotações do pod default/test-deployment3-ff66c7fc9-t7lg2
I0121 16:06:14.741423       1 types.go:761] [ControllerName] Anotação 'controller' encontrada para o pod default/test-deployment3-ff66c7fc9-t7lg2: test-controller3
I0121 16:06:14.745990       1 scheduler.go:564] [GetControllerMetricInfo] Iniciando para o pod: default/test-deployment3-ff66c7fc9-t7lg2
I0121 16:06:14.746026       1 scheduler.go:569] [GetControllerMetricInfo] Obtendo o nome do controlador para o pod: default/test-deployment3-ff66c7fc9-t7lg2
I0121 16:06:14.746038       1 types.go:743] [ControllerName] Verificando as anotações do pod default/test-deployment3-ff66c7fc9-t7lg2
I0121 16:06:14.746048       1 types.go:761] [ControllerName] Anotação 'controller' encontrada para o pod default/test-deployment3-ff66c7fc9-t7lg2: test-controller3
I0121 16:06:14.746060       1 scheduler.go:572] [GetControllerMetricInfo] Métricas do controlador definidas para o pod: default/test-deployment3-ff66c7fc9-t7lg2
I0121 16:06:14.746100       1 scheduler.go:564] [GetControllerMetricInfo] Iniciando para o pod: default/test-deployment3-ff66c7fc9-t7lg2
I0121 16:06:14.746108       1 scheduler.go:569] [GetControllerMetricInfo] Obtendo o nome do controlador para o pod: default/test-deployment3-ff66c7fc9-t7lg2
I0121 16:06:14.746116       1 types.go:743] [ControllerName] Verificando as anotações do pod default/test-deployment3-ff66c7fc9-t7lg2
I0121 16:06:14.746123       1 types.go:761] [ControllerName] Anotação 'controller' encontrada para o pod default/test-deployment3-ff66c7fc9-t7lg2: test-controller3
I0121 16:06:14.746132       1 scheduler.go:572] [GetControllerMetricInfo] Métricas do controlador definidas para o pod: default/test-deployment3-ff66c7fc9-t7lg2
I0121 16:06:14.746162       1 postFilter.go:145] [PREEMPT CALL] The node minikube  was chosen to allocate pod test-deployment2-6594f5cd7f-kbjpm
I0121 16:06:14.784840       1 scheduler.go:247] [OnUpdatePod] Pod atualizado: default/test-deployment3-ff66c7fc9-t7lg2, Anotações: map[controller:test-controller3]
I0121 16:06:14.809644       1 scheduler.go:69] Estado no Informer: map[controller:test-controller3]
I0121 16:06:14.809694       1 scheduler.go:70] Estado real no cluster: map[controller:test-controller3]
I0121 16:06:14.809706       1 types.go:743] [ControllerName] Verificando as anotações do pod default/test-deployment3-ff66c7fc9-t7lg2
I0121 16:06:14.809712       1 types.go:761] [ControllerName] Anotação 'controller' encontrada para o pod default/test-deployment3-ff66c7fc9-t7lg2: test-controller3
I0121 16:06:14.810159       1 types.go:743] [ControllerName] Verificando as anotações do pod default/test-deployment3-ff66c7fc9-t7lg2
I0121 16:06:14.810614       1 types.go:761] [ControllerName] Anotação 'controller' encontrada para o pod default/test-deployment3-ff66c7fc9-t7lg2: test-controller3
I0121 16:06:14.829853       1 scheduler.go:247] [OnUpdatePod] Pod atualizado: default/test-deployment2-6594f5cd7f-kbjpm, Anotações: map[controller:test-controller2]
I0121 16:06:15.048229       1 scheduler.go:69] Estado no Informer: map[controller:test-controller2]
I0121 16:06:15.053984       1 scheduler.go:70] Estado real no cluster: map[controller:test-controller2]
I0121 16:06:15.063970       1 types.go:743] [ControllerName] Verificando as anotações do pod default/test-deployment2-6594f5cd7f-kbjpm
I0121 16:06:15.064064       1 types.go:761] [ControllerName] Anotação 'controller' encontrada para o pod default/test-deployment2-6594f5cd7f-kbjpm: test-controller2
I0121 16:06:15.071368       1 scheduler.go:213] [OnAddPod] Pod adicionado: default/test-deployment3-ff66c7fc9-47zn9, Anotações: map[controller:test-controller3]
I0121 16:06:15.072314       1 postFilter.go:74] Comparando pod original com o atualizado...
I0121 16:06:15.072397       1 postFilter.go:81] Successfully retrieved updated pod default/test-deployment3-ff66c7fc9-47zn9 from lister
I0121 16:06:15.110428       1 scheduler.go:69] Estado no Informer: map[controller:test-controller3]
I0121 16:06:15.110794       1 scheduler.go:70] Estado real no cluster: map[controller:test-controller3]
I0121 16:06:15.113056       1 postFilter.go:204] Recursos CPU do nó minikube estão sincronizados: 2000 mCPU
I0121 16:06:15.113389       1 postFilter.go:211] Recursos Memória do nó minikube estão sincronizados: 2216124416 bytes
I0121 16:06:15.115397       1 scheduler.go:564] [GetControllerMetricInfo] Iniciando para o pod: default/test-deployment3-ff66c7fc9-t7lg2
I0121 16:06:15.115618       1 types.go:743] [ControllerName] Verificando as anotações do pod default/test-deployment3-ff66c7fc9-47zn9
I0121 16:06:15.115686       1 types.go:761] [ControllerName] Anotação 'controller' encontrada para o pod default/test-deployment3-ff66c7fc9-47zn9: test-controller3
I0121 16:06:15.115710       1 types.go:743] [ControllerName] Verificando as anotações do pod default/test-deployment3-ff66c7fc9-47zn9
I0121 16:06:15.115724       1 types.go:761] [ControllerName] Anotação 'controller' encontrada para o pod default/test-deployment3-ff66c7fc9-47zn9: test-controller3
I0121 16:06:15.115791       1 scheduler.go:569] [GetControllerMetricInfo] Obtendo o nome do controlador para o pod: default/test-deployment3-ff66c7fc9-t7lg2
I0121 16:06:15.115831       1 types.go:743] [ControllerName] Verificando as anotações do pod default/test-deployment3-ff66c7fc9-t7lg2
I0121 16:06:15.115849       1 types.go:761] [ControllerName] Anotação 'controller' encontrada para o pod default/test-deployment3-ff66c7fc9-t7lg2: test-controller3
I0121 16:06:15.115864       1 scheduler.go:572] [GetControllerMetricInfo] Métricas do controlador definidas para o pod: default/test-deployment3-ff66c7fc9-t7lg2
I0121 16:06:15.115928       1 scheduler.go:83] [HigherPrecedence] Calculando precedência entre test-deployment3-ff66c7fc9-47zn9 e test-deployment3-ff66c7fc9-t7lg2
I0121 16:06:15.115969       1 scheduler.go:116] [WaitForPodsOnCache] Verificando se o pod test-deployment3-ff66c7fc9-47zn9 está no cache...
I0121 16:06:15.115986       1 scheduler.go:564] [GetControllerMetricInfo] Iniciando para o pod: default/test-deployment3-ff66c7fc9-47zn9
I0121 16:06:15.116000       1 scheduler.go:569] [GetControllerMetricInfo] Obtendo o nome do controlador para o pod: default/test-deployment3-ff66c7fc9-47zn9
I0121 16:06:15.116014       1 types.go:743] [ControllerName] Verificando as anotações do pod default/test-deployment3-ff66c7fc9-47zn9
I0121 16:06:15.116070       1 types.go:761] [ControllerName] Anotação 'controller' encontrada para o pod default/test-deployment3-ff66c7fc9-47zn9: test-controller3
I0121 16:06:15.116109       1 scheduler.go:572] [GetControllerMetricInfo] Métricas do controlador definidas para o pod: default/test-deployment3-ff66c7fc9-47zn9
I0121 16:06:15.132904       1 scheduler.go:69] Estado no Informer: map[controller:test-controller3]
I0121 16:06:15.133368       1 scheduler.go:70] Estado real no cluster: map[controller:test-controller3]
I0121 16:06:15.133567       1 scheduler.go:138] [WaitForPodsOnCache] Pod test-deployment3-ff66c7fc9-47zn9 encontrado no cache.
I0121 16:06:15.135672       1 scheduler.go:116] [WaitForPodsOnCache] Verificando se o pod test-deployment3-ff66c7fc9-t7lg2 está no cache...
I0121 16:06:15.135690       1 scheduler.go:564] [GetControllerMetricInfo] Iniciando para o pod: default/test-deployment3-ff66c7fc9-t7lg2
I0121 16:06:15.135696       1 scheduler.go:569] [GetControllerMetricInfo] Obtendo o nome do controlador para o pod: default/test-deployment3-ff66c7fc9-t7lg2
I0121 16:06:15.135702       1 types.go:743] [ControllerName] Verificando as anotações do pod default/test-deployment3-ff66c7fc9-t7lg2
I0121 16:06:15.135769       1 types.go:761] [ControllerName] Anotação 'controller' encontrada para o pod default/test-deployment3-ff66c7fc9-t7lg2: test-controller3
I0121 16:06:15.135777       1 scheduler.go:572] [GetControllerMetricInfo] Métricas do controlador definidas para o pod: default/test-deployment3-ff66c7fc9-t7lg2
I0121 16:06:15.192274       1 scheduler.go:69] Estado no Informer: map[controller:test-controller3]
I0121 16:06:15.199316       1 scheduler.go:70] Estado real no cluster: map[controller:test-controller3]
I0121 16:06:15.199345       1 scheduler.go:138] [WaitForPodsOnCache] Pod test-deployment3-ff66c7fc9-t7lg2 encontrado no cache.
I0121 16:06:15.199352       1 scheduler.go:564] [GetControllerMetricInfo] Iniciando para o pod: default/test-deployment3-ff66c7fc9-47zn9
I0121 16:06:15.199356       1 scheduler.go:569] [GetControllerMetricInfo] Obtendo o nome do controlador para o pod: default/test-deployment3-ff66c7fc9-47zn9
I0121 16:06:15.199362       1 types.go:743] [ControllerName] Verificando as anotações do pod default/test-deployment3-ff66c7fc9-47zn9
I0121 16:06:15.199369       1 types.go:761] [ControllerName] Anotação 'controller' encontrada para o pod default/test-deployment3-ff66c7fc9-47zn9: test-controller3
I0121 16:06:15.199376       1 scheduler.go:572] [GetControllerMetricInfo] Métricas do controlador definidas para o pod: default/test-deployment3-ff66c7fc9-47zn9
I0121 16:06:15.199387       1 scheduler.go:564] [GetControllerMetricInfo] Iniciando para o pod: default/test-deployment3-ff66c7fc9-t7lg2
I0121 16:06:15.199391       1 scheduler.go:569] [GetControllerMetricInfo] Obtendo o nome do controlador para o pod: default/test-deployment3-ff66c7fc9-t7lg2
I0121 16:06:15.199394       1 types.go:743] [ControllerName] Verificando as anotações do pod default/test-deployment3-ff66c7fc9-t7lg2
I0121 16:06:15.199400       1 types.go:761] [ControllerName] Anotação 'controller' encontrada para o pod default/test-deployment3-ff66c7fc9-t7lg2: test-controller3
I0121 16:06:15.199404       1 scheduler.go:572] [GetControllerMetricInfo] Métricas do controlador definidas para o pod: default/test-deployment3-ff66c7fc9-t7lg2
I0121 16:06:15.199416       1 scheduler.go:97] [HigherPrecedence] Métricas para test-deployment3-ff66c7fc9-47zn9: QoS = -481.491442, Importância = 0.80
I0121 16:06:15.199425       1 scheduler.go:98] [HigherPrecedence] Métricas para test-deployment3-ff66c7fc9-t7lg2: QoS = -481.491442, Importância = 0.80
I0121 16:06:15.199430       1 scheduler.go:109] [HigherPrecedence] Decisão final: test-deployment3-ff66c7fc9-47zn9 tem precedência sobre test-deployment3-ff66c7fc9-t7lg2? false
I0121 16:06:15.207562       1 postFilter.go:142] [PREEMPT CALL] No node was chosen to allocate pod test-deployment3-ff66c7fc9-47zn9
I0121 16:06:15.236996       1 scheduler.go:247] [OnUpdatePod] Pod atualizado: default/test-deployment3-ff66c7fc9-47zn9, Anotações: map[controller:test-controller3]
I0121 16:06:15.239431       1 scheduler.go:69] Estado no Informer: map[controller:test-controller3]
I0121 16:06:15.239446       1 scheduler.go:70] Estado real no cluster: map[controller:test-controller3]
I0121 16:06:15.239507       1 types.go:743] [ControllerName] Verificando as anotações do pod default/test-deployment3-ff66c7fc9-47zn9
I0121 16:06:15.239516       1 types.go:761] [ControllerName] Anotação 'controller' encontrada para o pod default/test-deployment3-ff66c7fc9-47zn9: test-controller3
I0121 16:06:15.824429       1 types.go:743] [ControllerName] Verificando as anotações do pod default/test-deployment3-ff66c7fc9-t7lg2
I0121 16:06:15.824574       1 types.go:761] [ControllerName] Anotação 'controller' encontrada para o pod default/test-deployment3-ff66c7fc9-t7lg2: test-controller3
I0121 16:06:16.911967       1 postFilter.go:74] Comparando pod original com o atualizado...
I0121 16:06:16.912073       1 postFilter.go:81] Successfully retrieved updated pod default/test-deployment3-ff66c7fc9-47zn9 from lister
I0121 16:06:16.927762       1 postFilter.go:204] Recursos CPU do nó minikube estão sincronizados: 2000 mCPU
I0121 16:06:16.930048       1 postFilter.go:211] Recursos Memória do nó minikube estão sincronizados: 2216124416 bytes
I0121 16:06:16.935061       1 postFilter.go:145] [PREEMPT CALL] The node minikube  was chosen to allocate pod test-deployment3-ff66c7fc9-47zn9
I0121 16:06:16.935150       1 scheduler.go:83] [HigherPrecedence] Calculando precedência entre test-deployment3-ff66c7fc9-47zn9 e test-deployment2-6594f5cd7f-kbjpm
I0121 16:06:16.935163       1 scheduler.go:116] [WaitForPodsOnCache] Verificando se o pod test-deployment3-ff66c7fc9-47zn9 está no cache...
I0121 16:06:16.935174       1 scheduler.go:564] [GetControllerMetricInfo] Iniciando para o pod: default/test-deployment3-ff66c7fc9-47zn9
I0121 16:06:16.935184       1 scheduler.go:569] [GetControllerMetricInfo] Obtendo o nome do controlador para o pod: default/test-deployment3-ff66c7fc9-47zn9
I0121 16:06:16.935196       1 types.go:743] [ControllerName] Verificando as anotações do pod default/test-deployment3-ff66c7fc9-47zn9
I0121 16:06:16.935207       1 types.go:761] [ControllerName] Anotação 'controller' encontrada para o pod default/test-deployment3-ff66c7fc9-47zn9: test-controller3
I0121 16:06:16.935220       1 scheduler.go:572] [GetControllerMetricInfo] Métricas do controlador definidas para o pod: default/test-deployment3-ff66c7fc9-47zn9
I0121 16:06:16.942348       1 scheduler.go:69] Estado no Informer: map[controller:test-controller3]
I0121 16:06:16.942410       1 scheduler.go:70] Estado real no cluster: map[controller:test-controller3]
I0121 16:06:16.942425       1 scheduler.go:138] [WaitForPodsOnCache] Pod test-deployment3-ff66c7fc9-47zn9 encontrado no cache.
I0121 16:06:16.942436       1 scheduler.go:116] [WaitForPodsOnCache] Verificando se o pod test-deployment2-6594f5cd7f-kbjpm está no cache...
I0121 16:06:16.942447       1 scheduler.go:564] [GetControllerMetricInfo] Iniciando para o pod: default/test-deployment2-6594f5cd7f-kbjpm
I0121 16:06:16.942560       1 scheduler.go:569] [GetControllerMetricInfo] Obtendo o nome do controlador para o pod: default/test-deployment2-6594f5cd7f-kbjpm
I0121 16:06:16.942578       1 types.go:743] [ControllerName] Verificando as anotações do pod default/test-deployment2-6594f5cd7f-kbjpm
I0121 16:06:16.942637       1 types.go:761] [ControllerName] Anotação 'controller' encontrada para o pod default/test-deployment2-6594f5cd7f-kbjpm: test-controller2
I0121 16:06:16.942654       1 scheduler.go:572] [GetControllerMetricInfo] Métricas do controlador definidas para o pod: default/test-deployment2-6594f5cd7f-kbjpm
I0121 16:06:16.953101       1 scheduler.go:69] Estado no Informer: map[controller:test-controller2]
I0121 16:06:16.953699       1 scheduler.go:70] Estado real no cluster: map[controller:test-controller2]
I0121 16:06:16.953802       1 scheduler.go:138] [WaitForPodsOnCache] Pod test-deployment2-6594f5cd7f-kbjpm encontrado no cache.
I0121 16:06:16.953814       1 scheduler.go:564] [GetControllerMetricInfo] Iniciando para o pod: default/test-deployment3-ff66c7fc9-47zn9
I0121 16:06:16.953823       1 scheduler.go:569] [GetControllerMetricInfo] Obtendo o nome do controlador para o pod: default/test-deployment3-ff66c7fc9-47zn9
I0121 16:06:16.953833       1 types.go:743] [ControllerName] Verificando as anotações do pod default/test-deployment3-ff66c7fc9-47zn9
I0121 16:06:16.953843       1 types.go:761] [ControllerName] Anotação 'controller' encontrada para o pod default/test-deployment3-ff66c7fc9-47zn9: test-controller3
I0121 16:06:16.953853       1 scheduler.go:572] [GetControllerMetricInfo] Métricas do controlador definidas para o pod: default/test-deployment3-ff66c7fc9-47zn9
I0121 16:06:16.953870       1 scheduler.go:564] [GetControllerMetricInfo] Iniciando para o pod: default/test-deployment2-6594f5cd7f-kbjpm
I0121 16:06:16.953877       1 scheduler.go:569] [GetControllerMetricInfo] Obtendo o nome do controlador para o pod: default/test-deployment2-6594f5cd7f-kbjpm
I0121 16:06:16.953883       1 types.go:743] [ControllerName] Verificando as anotações do pod default/test-deployment2-6594f5cd7f-kbjpm
I0121 16:06:16.953892       1 types.go:761] [ControllerName] Anotação 'controller' encontrada para o pod default/test-deployment2-6594f5cd7f-kbjpm: test-controller2
I0121 16:06:16.953899       1 scheduler.go:572] [GetControllerMetricInfo] Métricas do controlador definidas para o pod: default/test-deployment2-6594f5cd7f-kbjpm
I0121 16:06:16.953948       1 scheduler.go:97] [HigherPrecedence] Métricas para test-deployment3-ff66c7fc9-47zn9: QoS = -483.133493, Importância = 0.80
I0121 16:06:16.953963       1 scheduler.go:98] [HigherPrecedence] Métricas para test-deployment2-6594f5cd7f-kbjpm: QoS = -864.536382, Importância = 0.80
I0121 16:06:16.953974       1 scheduler.go:109] [HigherPrecedence] Decisão final: test-deployment3-ff66c7fc9-47zn9 tem precedência sobre test-deployment2-6594f5cd7f-kbjpm? false
I0121 16:06:16.999711       1 scheduler.go:247] [OnUpdatePod] Pod atualizado: default/test-deployment3-ff66c7fc9-47zn9, Anotações: map[controller:test-controller3]
I0121 16:06:17.014604       1 scheduler.go:69] Estado no Informer: map[controller:test-controller3]
I0121 16:06:17.020025       1 scheduler.go:70] Estado real no cluster: map[controller:test-controller3]
I0121 16:06:17.025176       1 types.go:743] [ControllerName] Verificando as anotações do pod default/test-deployment3-ff66c7fc9-47zn9
I0121 16:06:17.025315       1 types.go:761] [ControllerName] Anotação 'controller' encontrada para o pod default/test-deployment3-ff66c7fc9-47zn9: test-controller3
I0121 16:06:22.917270       1 postFilter.go:74] Comparando pod original com o atualizado...
I0121 16:06:22.917380       1 postFilter.go:81] Successfully retrieved updated pod default/test-deployment2-6594f5cd7f-kbjpm from lister
I0121 16:06:22.944564       1 postFilter.go:204] Recursos CPU do nó minikube estão sincronizados: 2000 mCPU
I0121 16:06:22.944665       1 postFilter.go:211] Recursos Memória do nó minikube estão sincronizados: 2216124416 bytes
I0121 16:06:22.961762       1 postFilter.go:145] [PREEMPT CALL] The node minikube  was chosen to allocate pod test-deployment2-6594f5cd7f-kbjpm
W0121 16:06:22.962022       1 scheduler.go:78] [HigherPrecedence] Tentativa de comparar o pod test-deployment2-6594f5cd7f-kbjpm consigo mesmo. Retornando false.
I0121 16:06:22.962080       1 scheduler.go:83] [HigherPrecedence] Calculando precedência entre test-deployment2-6594f5cd7f-kbjpm e test-deployment3-ff66c7fc9-47zn9
I0121 16:06:22.962099       1 scheduler.go:116] [WaitForPodsOnCache] Verificando se o pod test-deployment2-6594f5cd7f-kbjpm está no cache...
I0121 16:06:22.962119       1 scheduler.go:564] [GetControllerMetricInfo] Iniciando para o pod: default/test-deployment2-6594f5cd7f-kbjpm
I0121 16:06:22.962139       1 scheduler.go:569] [GetControllerMetricInfo] Obtendo o nome do controlador para o pod: default/test-deployment2-6594f5cd7f-kbjpm
I0121 16:06:22.962159       1 types.go:743] [ControllerName] Verificando as anotações do pod default/test-deployment2-6594f5cd7f-kbjpm
I0121 16:06:22.962187       1 types.go:761] [ControllerName] Anotação 'controller' encontrada para o pod default/test-deployment2-6594f5cd7f-kbjpm: test-controller2
I0121 16:06:22.962208       1 scheduler.go:572] [GetControllerMetricInfo] Métricas do controlador definidas para o pod: default/test-deployment2-6594f5cd7f-kbjpm
I0121 16:06:22.976664       1 scheduler.go:69] Estado no Informer: map[controller:test-controller2]
I0121 16:06:22.976744       1 scheduler.go:70] Estado real no cluster: map[controller:test-controller2]
I0121 16:06:22.976760       1 scheduler.go:138] [WaitForPodsOnCache] Pod test-deployment2-6594f5cd7f-kbjpm encontrado no cache.
I0121 16:06:22.976770       1 scheduler.go:116] [WaitForPodsOnCache] Verificando se o pod test-deployment3-ff66c7fc9-47zn9 está no cache...
I0121 16:06:22.976786       1 scheduler.go:564] [GetControllerMetricInfo] Iniciando para o pod: default/test-deployment3-ff66c7fc9-47zn9
I0121 16:06:22.976796       1 scheduler.go:569] [GetControllerMetricInfo] Obtendo o nome do controlador para o pod: default/test-deployment3-ff66c7fc9-47zn9
I0121 16:06:22.976806       1 types.go:743] [ControllerName] Verificando as anotações do pod default/test-deployment3-ff66c7fc9-47zn9
I0121 16:06:22.976816       1 types.go:761] [ControllerName] Anotação 'controller' encontrada para o pod default/test-deployment3-ff66c7fc9-47zn9: test-controller3
I0121 16:06:22.976832       1 scheduler.go:572] [GetControllerMetricInfo] Métricas do controlador definidas para o pod: default/test-deployment3-ff66c7fc9-47zn9
I0121 16:06:22.981820       1 scheduler.go:69] Estado no Informer: map[controller:test-controller3]
I0121 16:06:22.981897       1 scheduler.go:70] Estado real no cluster: map[controller:test-controller3]
I0121 16:06:22.981912       1 scheduler.go:138] [WaitForPodsOnCache] Pod test-deployment3-ff66c7fc9-47zn9 encontrado no cache.
I0121 16:06:22.981945       1 scheduler.go:564] [GetControllerMetricInfo] Iniciando para o pod: default/test-deployment2-6594f5cd7f-kbjpm
I0121 16:06:22.981992       1 scheduler.go:569] [GetControllerMetricInfo] Obtendo o nome do controlador para o pod: default/test-deployment2-6594f5cd7f-kbjpm
I0121 16:06:22.982040       1 types.go:743] [ControllerName] Verificando as anotações do pod default/test-deployment2-6594f5cd7f-kbjpm
I0121 16:06:22.982087       1 types.go:761] [ControllerName] Anotação 'controller' encontrada para o pod default/test-deployment2-6594f5cd7f-kbjpm: test-controller2
I0121 16:06:22.982135       1 scheduler.go:572] [GetControllerMetricInfo] Métricas do controlador definidas para o pod: default/test-deployment2-6594f5cd7f-kbjpm
I0121 16:06:22.982189       1 scheduler.go:564] [GetControllerMetricInfo] Iniciando para o pod: default/test-deployment3-ff66c7fc9-47zn9
I0121 16:06:22.982199       1 scheduler.go:569] [GetControllerMetricInfo] Obtendo o nome do controlador para o pod: default/test-deployment3-ff66c7fc9-47zn9
I0121 16:06:22.982206       1 types.go:743] [ControllerName] Verificando as anotações do pod default/test-deployment3-ff66c7fc9-47zn9
I0121 16:06:22.982215       1 types.go:761] [ControllerName] Anotação 'controller' encontrada para o pod default/test-deployment3-ff66c7fc9-47zn9: test-controller3
I0121 16:06:22.982260       1 scheduler.go:572] [GetControllerMetricInfo] Métricas do controlador definidas para o pod: default/test-deployment3-ff66c7fc9-47zn9
I0121 16:06:22.982286       1 scheduler.go:97] [HigherPrecedence] Métricas para test-deployment2-6594f5cd7f-kbjpm: QoS = -870.563309, Importância = 0.80
I0121 16:06:22.982302       1 scheduler.go:98] [HigherPrecedence] Métricas para test-deployment3-ff66c7fc9-47zn9: QoS = -489.160420, Importância = 0.80
I0121 16:06:22.982314       1 scheduler.go:109] [HigherPrecedence] Decisão final: test-deployment2-6594f5cd7f-kbjpm tem precedência sobre test-deployment3-ff66c7fc9-47zn9? true
I0121 16:06:23.033018       1 scheduler.go:247] [OnUpdatePod] Pod atualizado: default/test-deployment3-ff66c7fc9-47zn9, Anotações: map[controller:test-controller3]
I0121 16:06:23.046997       1 scheduler.go:69] Estado no Informer: map[controller:test-controller3]
I0121 16:06:23.050227       1 scheduler.go:70] Estado real no cluster: map[controller:test-controller3]
I0121 16:06:23.051268       1 types.go:743] [ControllerName] Verificando as anotações do pod default/test-deployment3-ff66c7fc9-47zn9
I0121 16:06:23.051748       1 types.go:761] [ControllerName] Anotação 'controller' encontrada para o pod default/test-deployment3-ff66c7fc9-47zn9: test-controller3
I0121 16:11:44.680985       1 scheduler.go:53] [QueueSort] Comparando prioridade de test-deployment2-6594f5cd7f-kbjpm com test-deployment3-ff66c7fc9-47zn9
I0121 16:11:44.681431       1 scheduler.go:83] [HigherPrecedence] Calculando precedência entre test-deployment2-6594f5cd7f-kbjpm e test-deployment3-ff66c7fc9-47zn9
I0121 16:11:44.682342       1 scheduler.go:116] [WaitForPodsOnCache] Verificando se o pod test-deployment2-6594f5cd7f-kbjpm está no cache...
I0121 16:11:44.683144       1 scheduler.go:564] [GetControllerMetricInfo] Iniciando para o pod: default/test-deployment2-6594f5cd7f-kbjpm
I0121 16:11:44.683678       1 scheduler.go:569] [GetControllerMetricInfo] Obtendo o nome do controlador para o pod: default/test-deployment2-6594f5cd7f-kbjpm
I0121 16:11:44.683763       1 types.go:743] [ControllerName] Verificando as anotações do pod default/test-deployment2-6594f5cd7f-kbjpm
I0121 16:11:44.684047       1 types.go:761] [ControllerName] Anotação 'controller' encontrada para o pod default/test-deployment2-6594f5cd7f-kbjpm: test-controller2
I0121 16:11:44.684756       1 scheduler.go:572] [GetControllerMetricInfo] Métricas do controlador definidas para o pod: default/test-deployment2-6594f5cd7f-kbjpm
I0121 16:11:44.695358       1 scheduler.go:69] Estado no Informer: map[controller:test-controller2]
I0121 16:11:44.695418       1 scheduler.go:70] Estado real no cluster: map[controller:test-controller2]
I0121 16:11:44.695433       1 scheduler.go:138] [WaitForPodsOnCache] Pod test-deployment2-6594f5cd7f-kbjpm encontrado no cache.
I0121 16:11:44.695447       1 scheduler.go:116] [WaitForPodsOnCache] Verificando se o pod test-deployment3-ff66c7fc9-47zn9 está no cache...
I0121 16:11:44.695842       1 scheduler.go:564] [GetControllerMetricInfo] Iniciando para o pod: default/test-deployment3-ff66c7fc9-47zn9
I0121 16:11:44.696135       1 scheduler.go:569] [GetControllerMetricInfo] Obtendo o nome do controlador para o pod: default/test-deployment3-ff66c7fc9-47zn9
I0121 16:11:44.696151       1 types.go:743] [ControllerName] Verificando as anotações do pod default/test-deployment3-ff66c7fc9-47zn9
I0121 16:11:44.696164       1 types.go:761] [ControllerName] Anotação 'controller' encontrada para o pod default/test-deployment3-ff66c7fc9-47zn9: test-controller3
I0121 16:11:44.696177       1 scheduler.go:572] [GetControllerMetricInfo] Métricas do controlador definidas para o pod: default/test-deployment3-ff66c7fc9-47zn9
I0121 16:11:44.703174       1 scheduler.go:69] Estado no Informer: map[controller:test-controller3]
I0121 16:11:44.703875       1 scheduler.go:70] Estado real no cluster: map[controller:test-controller3]
I0121 16:11:44.704250       1 scheduler.go:138] [WaitForPodsOnCache] Pod test-deployment3-ff66c7fc9-47zn9 encontrado no cache.
I0121 16:11:44.704618       1 scheduler.go:564] [GetControllerMetricInfo] Iniciando para o pod: default/test-deployment2-6594f5cd7f-kbjpm
I0121 16:11:44.705122       1 scheduler.go:569] [GetControllerMetricInfo] Obtendo o nome do controlador para o pod: default/test-deployment2-6594f5cd7f-kbjpm
I0121 16:11:44.705805       1 types.go:743] [ControllerName] Verificando as anotações do pod default/test-deployment2-6594f5cd7f-kbjpm
I0121 16:11:44.706156       1 types.go:761] [ControllerName] Anotação 'controller' encontrada para o pod default/test-deployment2-6594f5cd7f-kbjpm: test-controller2
I0121 16:11:44.706329       1 scheduler.go:572] [GetControllerMetricInfo] Métricas do controlador definidas para o pod: default/test-deployment2-6594f5cd7f-kbjpm
I0121 16:11:44.706972       1 scheduler.go:564] [GetControllerMetricInfo] Iniciando para o pod: default/test-deployment3-ff66c7fc9-47zn9
I0121 16:11:44.707075       1 scheduler.go:569] [GetControllerMetricInfo] Obtendo o nome do controlador para o pod: default/test-deployment3-ff66c7fc9-47zn9
I0121 16:11:44.707331       1 types.go:743] [ControllerName] Verificando as anotações do pod default/test-deployment3-ff66c7fc9-47zn9
I0121 16:11:44.708186       1 types.go:761] [ControllerName] Anotação 'controller' encontrada para o pod default/test-deployment3-ff66c7fc9-47zn9: test-controller3
I0121 16:11:44.708403       1 scheduler.go:572] [GetControllerMetricInfo] Métricas do controlador definidas para o pod: default/test-deployment3-ff66c7fc9-47zn9
I0121 16:11:44.709310       1 scheduler.go:97] [HigherPrecedence] Métricas para test-deployment2-6594f5cd7f-kbjpm: QoS = -1192.282654, Importância = 0.80
I0121 16:11:44.709776       1 scheduler.go:98] [HigherPrecedence] Métricas para test-deployment3-ff66c7fc9-47zn9: QoS = -810.879765, Importância = 0.80
I0121 16:11:44.710183       1 scheduler.go:109] [HigherPrecedence] Decisão final: test-deployment2-6594f5cd7f-kbjpm tem precedência sobre test-deployment3-ff66c7fc9-47zn9? true
I0121 16:11:44.710420       1 scheduler.go:59] [QueueSort] Precedência determinada: test-deployment2-6594f5cd7f-kbjpm tem precedência sobre test-deployment3-ff66c7fc9-47zn9? true
I0121 16:11:44.711895       1 scheduler.go:145] [Reserve] resources reserved at node minikube for pod test-deployment2-6594f5cd7f-kbjpm_default at 2025-01-21 16:11:44.711880786 +0000 UTC m=+1921.366449565
I0121 16:11:44.712317       1 types.go:743] [ControllerName] Verificando as anotações do pod default/test-deployment2-6594f5cd7f-kbjpm
I0121 16:11:44.712745       1 types.go:761] [ControllerName] Anotação 'controller' encontrada para o pod default/test-deployment2-6594f5cd7f-kbjpm: test-controller2
I0121 16:11:44.713218       1 scheduler.go:147] [Reserve] Status de alocação atual para o pod test-deployment2-6594f5cd7f-kbjpm_default: 
I0121 16:11:44.713617       1 scheduler.go:149] [Reserve] Status de alocação atualizado para o pod test-deployment2-6594f5cd7f-kbjpm_default: allocating
I0121 16:11:44.714741       1 postFilter.go:74] Comparando pod original com o atualizado...
I0121 16:11:44.714846       1 postFilter.go:81] Successfully retrieved updated pod default/test-deployment3-ff66c7fc9-47zn9 from lister
I0121 16:11:44.714763       1 scheduler.go:173] [PreBind] Validando o pod test-deployment2-6594f5cd7f-kbjpm antes de vincular ao node minikube
I0121 16:11:44.723192       1 postFilter.go:204] Recursos CPU do nó minikube estão sincronizados: 2000 mCPU
I0121 16:11:44.723574       1 postFilter.go:211] Recursos Memória do nó minikube estão sincronizados: 2216124416 bytes
I0121 16:11:44.725758       1 scheduler.go:564] [GetControllerMetricInfo] Iniciando para o pod: default/test-deployment2-6594f5cd7f-kbjpm
I0121 16:11:44.725841       1 scheduler.go:569] [GetControllerMetricInfo] Obtendo o nome do controlador para o pod: default/test-deployment2-6594f5cd7f-kbjpm
I0121 16:11:44.725858       1 types.go:743] [ControllerName] Verificando as anotações do pod default/test-deployment2-6594f5cd7f-kbjpm
I0121 16:11:44.727080       1 types.go:761] [ControllerName] Anotação 'controller' encontrada para o pod default/test-deployment2-6594f5cd7f-kbjpm: test-controller2
I0121 16:11:44.727251       1 scheduler.go:572] [GetControllerMetricInfo] Métricas do controlador definidas para o pod: default/test-deployment2-6594f5cd7f-kbjpm
I0121 16:11:44.727359       1 scheduler.go:83] [HigherPrecedence] Calculando precedência entre test-deployment3-ff66c7fc9-47zn9 e test-deployment2-6594f5cd7f-kbjpm
I0121 16:11:44.728022       1 scheduler.go:116] [WaitForPodsOnCache] Verificando se o pod test-deployment3-ff66c7fc9-47zn9 está no cache...
I0121 16:11:44.728598       1 scheduler.go:564] [GetControllerMetricInfo] Iniciando para o pod: default/test-deployment3-ff66c7fc9-47zn9
I0121 16:11:44.728684       1 scheduler.go:569] [GetControllerMetricInfo] Obtendo o nome do controlador para o pod: default/test-deployment3-ff66c7fc9-47zn9
I0121 16:11:44.729318       1 types.go:743] [ControllerName] Verificando as anotações do pod default/test-deployment3-ff66c7fc9-47zn9
I0121 16:11:44.729405       1 types.go:761] [ControllerName] Anotação 'controller' encontrada para o pod default/test-deployment3-ff66c7fc9-47zn9: test-controller3
I0121 16:11:44.729423       1 scheduler.go:572] [GetControllerMetricInfo] Métricas do controlador definidas para o pod: default/test-deployment3-ff66c7fc9-47zn9
I0121 16:11:44.752925       1 scheduler.go:69] Estado no Informer: map[controller:test-controller3]
I0121 16:11:44.768655       1 scheduler.go:70] Estado real no cluster: map[controller:test-controller3]
I0121 16:11:44.754001       1 scheduler.go:181] [PostBind] Chamado para pod test-deployment2-6594f5cd7f-kbjpm
I0121 16:11:44.760621       1 scheduler.go:247] [OnUpdatePod] Pod atualizado: default/test-deployment2-6594f5cd7f-kbjpm, Anotações: map[controller:test-controller2]
I0121 16:11:44.769602       1 scheduler.go:138] [WaitForPodsOnCache] Pod test-deployment3-ff66c7fc9-47zn9 encontrado no cache.
I0121 16:11:44.771241       1 scheduler.go:116] [WaitForPodsOnCache] Verificando se o pod test-deployment2-6594f5cd7f-kbjpm está no cache...
I0121 16:11:44.771703       1 scheduler.go:564] [GetControllerMetricInfo] Iniciando para o pod: default/test-deployment2-6594f5cd7f-kbjpm
I0121 16:11:44.771911       1 scheduler.go:569] [GetControllerMetricInfo] Obtendo o nome do controlador para o pod: default/test-deployment2-6594f5cd7f-kbjpm
I0121 16:11:44.772269       1 types.go:743] [ControllerName] Verificando as anotações do pod default/test-deployment2-6594f5cd7f-kbjpm
I0121 16:11:44.770449       1 scheduler.go:199] [PostBind] Pod test-deployment2-6594f5cd7f-kbjpm - Início do binding: 2025-01-21 16:11:44.715365751 +0000 UTC m=+1921.369934899, Fim do binding: 2025-01-21 16:11:44.770368151 +0000 UTC m=+1921.424936780
I0121 16:11:44.773134       1 types.go:761] [ControllerName] Anotação 'controller' encontrada para o pod default/test-deployment2-6594f5cd7f-kbjpm: test-controller2
I0121 16:11:44.773375       1 scheduler.go:572] [GetControllerMetricInfo] Métricas do controlador definidas para o pod: default/test-deployment2-6594f5cd7f-kbjpm
I0121 16:11:44.773820       1 types.go:743] [ControllerName] Verificando as anotações do pod default/test-deployment2-6594f5cd7f-kbjpm
I0121 16:11:44.773974       1 types.go:761] [ControllerName] Anotação 'controller' encontrada para o pod default/test-deployment2-6594f5cd7f-kbjpm: test-controller2
I0121 16:11:44.774255       1 scheduler.go:206] [PostBind] Métricas atualizadas para o pod test-deployment2-6594f5cd7f-kbjpm
I0121 16:11:44.784241       1 scheduler.go:69] Estado no Informer: map[controller:test-controller2]
I0121 16:11:44.784397       1 scheduler.go:70] Estado real no cluster: map[controller:test-controller2]
I0121 16:11:44.784720       1 scheduler.go:69] Estado no Informer: map[controller:test-controller2]
I0121 16:11:44.784828       1 scheduler.go:70] Estado real no cluster: map[controller:test-controller2]
I0121 16:11:44.784856       1 scheduler.go:138] [WaitForPodsOnCache] Pod test-deployment2-6594f5cd7f-kbjpm encontrado no cache.
I0121 16:11:44.784970       1 scheduler.go:564] [GetControllerMetricInfo] Iniciando para o pod: default/test-deployment3-ff66c7fc9-47zn9
I0121 16:11:44.785137       1 types.go:743] [ControllerName] Verificando as anotações do pod default/test-deployment2-6594f5cd7f-kbjpm
I0121 16:11:44.785272       1 types.go:761] [ControllerName] Anotação 'controller' encontrada para o pod default/test-deployment2-6594f5cd7f-kbjpm: test-controller2
I0121 16:11:44.785307       1 scheduler.go:569] [GetControllerMetricInfo] Obtendo o nome do controlador para o pod: default/test-deployment3-ff66c7fc9-47zn9
I0121 16:11:44.785412       1 types.go:743] [ControllerName] Verificando as anotações do pod default/test-deployment3-ff66c7fc9-47zn9
I0121 16:11:44.785594       1 types.go:761] [ControllerName] Anotação 'controller' encontrada para o pod default/test-deployment3-ff66c7fc9-47zn9: test-controller3
I0121 16:11:44.785625       1 scheduler.go:572] [GetControllerMetricInfo] Métricas do controlador definidas para o pod: default/test-deployment3-ff66c7fc9-47zn9
I0121 16:11:44.785747       1 scheduler.go:564] [GetControllerMetricInfo] Iniciando para o pod: default/test-deployment2-6594f5cd7f-kbjpm
I0121 16:11:44.785906       1 scheduler.go:569] [GetControllerMetricInfo] Obtendo o nome do controlador para o pod: default/test-deployment2-6594f5cd7f-kbjpm
I0121 16:11:44.785931       1 types.go:743] [ControllerName] Verificando as anotações do pod default/test-deployment2-6594f5cd7f-kbjpm
I0121 16:11:44.786156       1 types.go:761] [ControllerName] Anotação 'controller' encontrada para o pod default/test-deployment2-6594f5cd7f-kbjpm: test-controller2
I0121 16:11:44.786245       1 scheduler.go:572] [GetControllerMetricInfo] Métricas do controlador definidas para o pod: default/test-deployment2-6594f5cd7f-kbjpm
I0121 16:11:44.786838       1 scheduler.go:97] [HigherPrecedence] Métricas para test-deployment3-ff66c7fc9-47zn9: QoS = -810.925614, Importância = 0.80
I0121 16:11:44.787080       1 scheduler.go:98] [HigherPrecedence] Métricas para test-deployment2-6594f5cd7f-kbjpm: QoS = -1192.393385, Importância = 0.80
I0121 16:11:44.787264       1 scheduler.go:109] [HigherPrecedence] Decisão final: test-deployment3-ff66c7fc9-47zn9 tem precedência sobre test-deployment2-6594f5cd7f-kbjpm? false
I0121 16:11:44.787875       1 postFilter.go:142] [PREEMPT CALL] No node was chosen to allocate pod test-deployment3-ff66c7fc9-47zn9
I0121 16:11:44.788427       1 scheduler.go:247] [OnUpdatePod] Pod atualizado: default/test-deployment2-6594f5cd7f-kbjpm, Anotações: map[controller:test-controller2]
I0121 16:11:44.792686       1 scheduler.go:69] Estado no Informer: map[controller:test-controller2]
I0121 16:11:44.792853       1 scheduler.go:70] Estado real no cluster: map[controller:test-controller2]
I0121 16:11:44.792975       1 types.go:743] [ControllerName] Verificando as anotações do pod default/test-deployment2-6594f5cd7f-kbjpm
I0121 16:11:44.793120       1 types.go:761] [ControllerName] Anotação 'controller' encontrada para o pod default/test-deployment2-6594f5cd7f-kbjpm: test-controller2
I0121 16:11:48.676160       1 scheduler.go:247] [OnUpdatePod] Pod atualizado: default/test-deployment2-6594f5cd7f-kbjpm, Anotações: map[controller:test-controller2]
I0121 16:11:48.705722       1 scheduler.go:69] Estado no Informer: map[controller:test-controller2]
I0121 16:11:48.705946       1 scheduler.go:70] Estado real no cluster: map[controller:test-controller2]
I0121 16:11:48.706217       1 types.go:743] [ControllerName] Verificando as anotações do pod default/test-deployment2-6594f5cd7f-kbjpm
I0121 16:11:48.706394       1 types.go:761] [ControllerName] Anotação 'controller' encontrada para o pod default/test-deployment2-6594f5cd7f-kbjpm: test-controller2
I0121 16:11:49.176304       1 postFilter.go:74] Comparando pod original com o atualizado...
I0121 16:11:49.176942       1 postFilter.go:81] Successfully retrieved updated pod default/test-deployment3-ff66c7fc9-47zn9 from lister
I0121 16:11:49.184661       1 postFilter.go:204] Recursos CPU do nó minikube estão sincronizados: 2000 mCPU
I0121 16:11:49.184950       1 postFilter.go:211] Recursos Memória do nó minikube estão sincronizados: 2216124416 bytes
I0121 16:11:49.185787       1 scheduler.go:564] [GetControllerMetricInfo] Iniciando para o pod: default/test-deployment2-6594f5cd7f-kbjpm
I0121 16:11:49.186166       1 scheduler.go:569] [GetControllerMetricInfo] Obtendo o nome do controlador para o pod: default/test-deployment2-6594f5cd7f-kbjpm
I0121 16:11:49.186596       1 types.go:743] [ControllerName] Verificando as anotações do pod default/test-deployment2-6594f5cd7f-kbjpm
I0121 16:11:49.186853       1 types.go:761] [ControllerName] Anotação 'controller' encontrada para o pod default/test-deployment2-6594f5cd7f-kbjpm: test-controller2
I0121 16:11:49.187381       1 scheduler.go:572] [GetControllerMetricInfo] Métricas do controlador definidas para o pod: default/test-deployment2-6594f5cd7f-kbjpm
I0121 16:11:49.187709       1 scheduler.go:83] [HigherPrecedence] Calculando precedência entre test-deployment3-ff66c7fc9-47zn9 e test-deployment2-6594f5cd7f-kbjpm
I0121 16:11:49.188275       1 scheduler.go:116] [WaitForPodsOnCache] Verificando se o pod test-deployment3-ff66c7fc9-47zn9 está no cache...
I0121 16:11:49.188630       1 scheduler.go:564] [GetControllerMetricInfo] Iniciando para o pod: default/test-deployment3-ff66c7fc9-47zn9
I0121 16:11:49.188927       1 scheduler.go:569] [GetControllerMetricInfo] Obtendo o nome do controlador para o pod: default/test-deployment3-ff66c7fc9-47zn9
I0121 16:11:49.189214       1 types.go:743] [ControllerName] Verificando as anotações do pod default/test-deployment3-ff66c7fc9-47zn9
I0121 16:11:49.189789       1 types.go:761] [ControllerName] Anotação 'controller' encontrada para o pod default/test-deployment3-ff66c7fc9-47zn9: test-controller3
I0121 16:11:49.190344       1 scheduler.go:572] [GetControllerMetricInfo] Métricas do controlador definidas para o pod: default/test-deployment3-ff66c7fc9-47zn9
I0121 16:11:49.197766       1 scheduler.go:69] Estado no Informer: map[controller:test-controller3]
I0121 16:11:49.197868       1 scheduler.go:70] Estado real no cluster: map[controller:test-controller3]
I0121 16:11:49.197894       1 scheduler.go:138] [WaitForPodsOnCache] Pod test-deployment3-ff66c7fc9-47zn9 encontrado no cache.
I0121 16:11:49.197911       1 scheduler.go:116] [WaitForPodsOnCache] Verificando se o pod test-deployment2-6594f5cd7f-kbjpm está no cache...
I0121 16:11:49.197928       1 scheduler.go:564] [GetControllerMetricInfo] Iniciando para o pod: default/test-deployment2-6594f5cd7f-kbjpm
I0121 16:11:49.197946       1 scheduler.go:569] [GetControllerMetricInfo] Obtendo o nome do controlador para o pod: default/test-deployment2-6594f5cd7f-kbjpm
I0121 16:11:49.197962       1 types.go:743] [ControllerName] Verificando as anotações do pod default/test-deployment2-6594f5cd7f-kbjpm
I0121 16:11:49.197975       1 types.go:761] [ControllerName] Anotação 'controller' encontrada para o pod default/test-deployment2-6594f5cd7f-kbjpm: test-controller2
I0121 16:11:49.198079       1 scheduler.go:572] [GetControllerMetricInfo] Métricas do controlador definidas para o pod: default/test-deployment2-6594f5cd7f-kbjpm
I0121 16:11:49.204707       1 scheduler.go:69] Estado no Informer: map[controller:test-controller2]
I0121 16:11:49.204794       1 scheduler.go:70] Estado real no cluster: map[controller:test-controller2]
I0121 16:11:49.204813       1 scheduler.go:138] [WaitForPodsOnCache] Pod test-deployment2-6594f5cd7f-kbjpm encontrado no cache.
I0121 16:11:49.204824       1 scheduler.go:564] [GetControllerMetricInfo] Iniciando para o pod: default/test-deployment3-ff66c7fc9-47zn9
I0121 16:11:49.204836       1 scheduler.go:569] [GetControllerMetricInfo] Obtendo o nome do controlador para o pod: default/test-deployment3-ff66c7fc9-47zn9
I0121 16:11:49.204848       1 types.go:743] [ControllerName] Verificando as anotações do pod default/test-deployment3-ff66c7fc9-47zn9
I0121 16:11:49.204861       1 types.go:761] [ControllerName] Anotação 'controller' encontrada para o pod default/test-deployment3-ff66c7fc9-47zn9: test-controller3
I0121 16:11:49.204874       1 scheduler.go:572] [GetControllerMetricInfo] Métricas do controlador definidas para o pod: default/test-deployment3-ff66c7fc9-47zn9
I0121 16:11:49.204978       1 scheduler.go:564] [GetControllerMetricInfo] Iniciando para o pod: default/test-deployment2-6594f5cd7f-kbjpm
I0121 16:11:49.205292       1 scheduler.go:569] [GetControllerMetricInfo] Obtendo o nome do controlador para o pod: default/test-deployment2-6594f5cd7f-kbjpm
I0121 16:11:49.205367       1 types.go:743] [ControllerName] Verificando as anotações do pod default/test-deployment2-6594f5cd7f-kbjpm
I0121 16:11:49.205383       1 types.go:761] [ControllerName] Anotação 'controller' encontrada para o pod default/test-deployment2-6594f5cd7f-kbjpm: test-controller2
I0121 16:11:49.205396       1 scheduler.go:572] [GetControllerMetricInfo] Métricas do controlador definidas para o pod: default/test-deployment2-6594f5cd7f-kbjpm
I0121 16:11:49.205424       1 scheduler.go:97] [HigherPrecedence] Métricas para test-deployment3-ff66c7fc9-47zn9: QoS = -815.386040, Importância = 0.80
I0121 16:11:49.205443       1 scheduler.go:98] [HigherPrecedence] Métricas para test-deployment2-6594f5cd7f-kbjpm: QoS = -1191.278278, Importância = 0.80
I0121 16:11:49.205604       1 scheduler.go:109] [HigherPrecedence] Decisão final: test-deployment3-ff66c7fc9-47zn9 tem precedência sobre test-deployment2-6594f5cd7f-kbjpm? false
I0121 16:11:49.205865       1 postFilter.go:142] [PREEMPT CALL] No node was chosen to allocate pod test-deployment3-ff66c7fc9-47zn9
I0121 16:17:14.718445       1 postFilter.go:74] Comparando pod original com o atualizado...
I0121 16:17:14.719156       1 postFilter.go:81] Successfully retrieved updated pod default/test-deployment3-ff66c7fc9-47zn9 from lister
I0121 16:17:14.727160       1 postFilter.go:204] Recursos CPU do nó minikube estão sincronizados: 2000 mCPU
I0121 16:17:14.727333       1 postFilter.go:211] Recursos Memória do nó minikube estão sincronizados: 2216124416 bytes
I0121 16:17:14.727889       1 scheduler.go:564] [GetControllerMetricInfo] Iniciando para o pod: default/test-deployment2-6594f5cd7f-kbjpm
I0121 16:17:14.727957       1 scheduler.go:569] [GetControllerMetricInfo] Obtendo o nome do controlador para o pod: default/test-deployment2-6594f5cd7f-kbjpm
I0121 16:17:14.728000       1 types.go:743] [ControllerName] Verificando as anotações do pod default/test-deployment2-6594f5cd7f-kbjpm
I0121 16:17:14.728038       1 types.go:761] [ControllerName] Anotação 'controller' encontrada para o pod default/test-deployment2-6594f5cd7f-kbjpm: test-controller2
I0121 16:17:14.728076       1 scheduler.go:572] [GetControllerMetricInfo] Métricas do controlador definidas para o pod: default/test-deployment2-6594f5cd7f-kbjpm
I0121 16:17:14.728115       1 scheduler.go:83] [HigherPrecedence] Calculando precedência entre test-deployment3-ff66c7fc9-47zn9 e test-deployment2-6594f5cd7f-kbjpm
I0121 16:17:14.728151       1 scheduler.go:116] [WaitForPodsOnCache] Verificando se o pod test-deployment3-ff66c7fc9-47zn9 está no cache...
I0121 16:17:14.728275       1 scheduler.go:564] [GetControllerMetricInfo] Iniciando para o pod: default/test-deployment3-ff66c7fc9-47zn9
I0121 16:17:14.728316       1 scheduler.go:569] [GetControllerMetricInfo] Obtendo o nome do controlador para o pod: default/test-deployment3-ff66c7fc9-47zn9
I0121 16:17:14.728351       1 types.go:743] [ControllerName] Verificando as anotações do pod default/test-deployment3-ff66c7fc9-47zn9
I0121 16:17:14.728386       1 types.go:761] [ControllerName] Anotação 'controller' encontrada para o pod default/test-deployment3-ff66c7fc9-47zn9: test-controller3
I0121 16:17:14.728435       1 scheduler.go:572] [GetControllerMetricInfo] Métricas do controlador definidas para o pod: default/test-deployment3-ff66c7fc9-47zn9
I0121 16:17:14.734116       1 scheduler.go:69] Estado no Informer: map[controller:test-controller3]
I0121 16:17:14.734407       1 scheduler.go:70] Estado real no cluster: map[controller:test-controller3]
I0121 16:17:14.734918       1 scheduler.go:138] [WaitForPodsOnCache] Pod test-deployment3-ff66c7fc9-47zn9 encontrado no cache.
I0121 16:17:14.735195       1 scheduler.go:116] [WaitForPodsOnCache] Verificando se o pod test-deployment2-6594f5cd7f-kbjpm está no cache...
I0121 16:17:14.735398       1 scheduler.go:564] [GetControllerMetricInfo] Iniciando para o pod: default/test-deployment2-6594f5cd7f-kbjpm
I0121 16:17:14.735721       1 scheduler.go:569] [GetControllerMetricInfo] Obtendo o nome do controlador para o pod: default/test-deployment2-6594f5cd7f-kbjpm
I0121 16:17:14.735876       1 types.go:743] [ControllerName] Verificando as anotações do pod default/test-deployment2-6594f5cd7f-kbjpm
I0121 16:17:14.736161       1 types.go:761] [ControllerName] Anotação 'controller' encontrada para o pod default/test-deployment2-6594f5cd7f-kbjpm: test-controller2
I0121 16:17:14.736430       1 scheduler.go:572] [GetControllerMetricInfo] Métricas do controlador definidas para o pod: default/test-deployment2-6594f5cd7f-kbjpm
I0121 16:17:14.742392       1 scheduler.go:69] Estado no Informer: map[controller:test-controller2]
I0121 16:17:14.742727       1 scheduler.go:70] Estado real no cluster: map[controller:test-controller2]
I0121 16:17:14.742895       1 scheduler.go:138] [WaitForPodsOnCache] Pod test-deployment2-6594f5cd7f-kbjpm encontrado no cache.
I0121 16:17:14.742938       1 scheduler.go:564] [GetControllerMetricInfo] Iniciando para o pod: default/test-deployment3-ff66c7fc9-47zn9
I0121 16:17:14.742978       1 scheduler.go:569] [GetControllerMetricInfo] Obtendo o nome do controlador para o pod: default/test-deployment3-ff66c7fc9-47zn9
I0121 16:17:14.743014       1 types.go:743] [ControllerName] Verificando as anotações do pod default/test-deployment3-ff66c7fc9-47zn9
I0121 16:17:14.743052       1 types.go:761] [ControllerName] Anotação 'controller' encontrada para o pod default/test-deployment3-ff66c7fc9-47zn9: test-controller3
I0121 16:17:14.743089       1 scheduler.go:572] [GetControllerMetricInfo] Métricas do controlador definidas para o pod: default/test-deployment3-ff66c7fc9-47zn9
I0121 16:17:14.743170       1 scheduler.go:564] [GetControllerMetricInfo] Iniciando para o pod: default/test-deployment2-6594f5cd7f-kbjpm
I0121 16:17:14.743266       1 scheduler.go:569] [GetControllerMetricInfo] Obtendo o nome do controlador para o pod: default/test-deployment2-6594f5cd7f-kbjpm
I0121 16:17:14.743569       1 types.go:743] [ControllerName] Verificando as anotações do pod default/test-deployment2-6594f5cd7f-kbjpm
I0121 16:17:14.743694       1 types.go:761] [ControllerName] Anotação 'controller' encontrada para o pod default/test-deployment2-6594f5cd7f-kbjpm: test-controller2
I0121 16:17:14.744000       1 scheduler.go:572] [GetControllerMetricInfo] Métricas do controlador definidas para o pod: default/test-deployment2-6594f5cd7f-kbjpm
I0121 16:17:14.744309       1 scheduler.go:97] [HigherPrecedence] Métricas para test-deployment3-ff66c7fc9-47zn9: QoS = -1140.926458, Importância = 0.80
I0121 16:17:14.744760       1 scheduler.go:98] [HigherPrecedence] Métricas para test-deployment2-6594f5cd7f-kbjpm: QoS = -1109.893174, Importância = 0.80
I0121 16:17:14.744937       1 scheduler.go:109] [HigherPrecedence] Decisão final: test-deployment3-ff66c7fc9-47zn9 tem precedência sobre test-deployment2-6594f5cd7f-kbjpm? true
I0121 16:17:14.745140       1 types.go:743] [ControllerName] Verificando as anotações do pod default/test-deployment3-ff66c7fc9-47zn9
I0121 16:17:14.745394       1 types.go:761] [ControllerName] Anotação 'controller' encontrada para o pod default/test-deployment3-ff66c7fc9-47zn9: test-controller3
I0121 16:17:14.745599       1 types.go:743] [ControllerName] Verificando as anotações do pod default/test-deployment2-6594f5cd7f-kbjpm
I0121 16:17:14.745802       1 types.go:761] [ControllerName] Anotação 'controller' encontrada para o pod default/test-deployment2-6594f5cd7f-kbjpm: test-controller2
I0121 16:17:14.746000       1 scheduler.go:564] [GetControllerMetricInfo] Iniciando para o pod: default/test-deployment2-6594f5cd7f-kbjpm
I0121 16:17:14.746207       1 scheduler.go:569] [GetControllerMetricInfo] Obtendo o nome do controlador para o pod: default/test-deployment2-6594f5cd7f-kbjpm
I0121 16:17:14.746798       1 types.go:743] [ControllerName] Verificando as anotações do pod default/test-deployment2-6594f5cd7f-kbjpm
I0121 16:17:14.746976       1 types.go:761] [ControllerName] Anotação 'controller' encontrada para o pod default/test-deployment2-6594f5cd7f-kbjpm: test-controller2
I0121 16:17:14.747176       1 scheduler.go:572] [GetControllerMetricInfo] Métricas do controlador definidas para o pod: default/test-deployment2-6594f5cd7f-kbjpm
I0121 16:17:14.747660       1 scheduler.go:564] [GetControllerMetricInfo] Iniciando para o pod: default/test-deployment2-6594f5cd7f-kbjpm
I0121 16:17:14.747866       1 scheduler.go:569] [GetControllerMetricInfo] Obtendo o nome do controlador para o pod: default/test-deployment2-6594f5cd7f-kbjpm
I0121 16:17:14.748062       1 types.go:743] [ControllerName] Verificando as anotações do pod default/test-deployment2-6594f5cd7f-kbjpm
I0121 16:17:14.748314       1 types.go:761] [ControllerName] Anotação 'controller' encontrada para o pod default/test-deployment2-6594f5cd7f-kbjpm: test-controller2
I0121 16:17:14.748569       1 scheduler.go:572] [GetControllerMetricInfo] Métricas do controlador definidas para o pod: default/test-deployment2-6594f5cd7f-kbjpm
I0121 16:17:14.748788       1 types.go:743] [ControllerName] Verificando as anotações do pod default/test-deployment2-6594f5cd7f-kbjpm
I0121 16:17:14.748983       1 types.go:761] [ControllerName] Anotação 'controller' encontrada para o pod default/test-deployment2-6594f5cd7f-kbjpm: test-controller2
I0121 16:17:14.749834       1 scheduler.go:564] [GetControllerMetricInfo] Iniciando para o pod: default/test-deployment2-6594f5cd7f-kbjpm
I0121 16:17:14.749954       1 scheduler.go:569] [GetControllerMetricInfo] Obtendo o nome do controlador para o pod: default/test-deployment2-6594f5cd7f-kbjpm
I0121 16:17:14.749994       1 types.go:743] [ControllerName] Verificando as anotações do pod default/test-deployment2-6594f5cd7f-kbjpm
I0121 16:17:14.750031       1 types.go:761] [ControllerName] Anotação 'controller' encontrada para o pod default/test-deployment2-6594f5cd7f-kbjpm: test-controller2
I0121 16:17:14.750067       1 scheduler.go:572] [GetControllerMetricInfo] Métricas do controlador definidas para o pod: default/test-deployment2-6594f5cd7f-kbjpm
I0121 16:17:14.750109       1 scheduler.go:564] [GetControllerMetricInfo] Iniciando para o pod: default/test-deployment2-6594f5cd7f-kbjpm
I0121 16:17:14.750144       1 scheduler.go:569] [GetControllerMetricInfo] Obtendo o nome do controlador para o pod: default/test-deployment2-6594f5cd7f-kbjpm
I0121 16:17:14.750181       1 types.go:743] [ControllerName] Verificando as anotações do pod default/test-deployment2-6594f5cd7f-kbjpm
I0121 16:17:14.750281       1 types.go:761] [ControllerName] Anotação 'controller' encontrada para o pod default/test-deployment2-6594f5cd7f-kbjpm: test-controller2
I0121 16:17:14.750324       1 scheduler.go:572] [GetControllerMetricInfo] Métricas do controlador definidas para o pod: default/test-deployment2-6594f5cd7f-kbjpm
I0121 16:17:14.750384       1 postFilter.go:145] [PREEMPT CALL] The node minikube  was chosen to allocate pod test-deployment3-ff66c7fc9-47zn9
I0121 16:17:14.784413       1 scheduler.go:247] [OnUpdatePod] Pod atualizado: default/test-deployment2-6594f5cd7f-kbjpm, Anotações: map[controller:test-controller2]
I0121 16:17:14.825098       1 scheduler.go:69] Estado no Informer: map[controller:test-controller2]
I0121 16:17:14.825423       1 scheduler.go:70] Estado real no cluster: map[controller:test-controller2]
I0121 16:17:14.825777       1 types.go:743] [ControllerName] Verificando as anotações do pod default/test-deployment2-6594f5cd7f-kbjpm
I0121 16:17:14.826338       1 types.go:761] [ControllerName] Anotação 'controller' encontrada para o pod default/test-deployment2-6594f5cd7f-kbjpm: test-controller2
I0121 16:17:14.827091       1 types.go:743] [ControllerName] Verificando as anotações do pod default/test-deployment2-6594f5cd7f-kbjpm
I0121 16:17:14.827136       1 types.go:761] [ControllerName] Anotação 'controller' encontrada para o pod default/test-deployment2-6594f5cd7f-kbjpm: test-controller2
I0121 16:17:14.827963       1 scheduler.go:247] [OnUpdatePod] Pod atualizado: default/test-deployment3-ff66c7fc9-47zn9, Anotações: map[controller:test-controller3]
I0121 16:17:14.841888       1 scheduler.go:69] Estado no Informer: map[controller:test-controller3]
I0121 16:17:14.841917       1 scheduler.go:70] Estado real no cluster: map[controller:test-controller3]
I0121 16:17:14.841925       1 types.go:743] [ControllerName] Verificando as anotações do pod default/test-deployment3-ff66c7fc9-47zn9
I0121 16:17:14.841931       1 types.go:761] [ControllerName] Anotação 'controller' encontrada para o pod default/test-deployment3-ff66c7fc9-47zn9: test-controller3
I0121 16:17:14.846987       1 postFilter.go:74] Comparando pod original com o atualizado...
I0121 16:17:14.847014       1 postFilter.go:81] Successfully retrieved updated pod default/test-deployment2-6594f5cd7f-spfs2 from lister
I0121 16:17:14.849104       1 scheduler.go:213] [OnAddPod] Pod adicionado: default/test-deployment2-6594f5cd7f-spfs2, Anotações: map[controller:test-controller2]
I0121 16:17:14.853285       1 postFilter.go:204] Recursos CPU do nó minikube estão sincronizados: 2000 mCPU
I0121 16:17:14.853328       1 postFilter.go:211] Recursos Memória do nó minikube estão sincronizados: 2216124416 bytes
I0121 16:17:14.853590       1 scheduler.go:564] [GetControllerMetricInfo] Iniciando para o pod: default/test-deployment2-6594f5cd7f-kbjpm
I0121 16:17:14.853598       1 scheduler.go:569] [GetControllerMetricInfo] Obtendo o nome do controlador para o pod: default/test-deployment2-6594f5cd7f-kbjpm
I0121 16:17:14.853605       1 types.go:743] [ControllerName] Verificando as anotações do pod default/test-deployment2-6594f5cd7f-kbjpm
I0121 16:17:14.853656       1 types.go:761] [ControllerName] Anotação 'controller' encontrada para o pod default/test-deployment2-6594f5cd7f-kbjpm: test-controller2
I0121 16:17:14.853666       1 scheduler.go:572] [GetControllerMetricInfo] Métricas do controlador definidas para o pod: default/test-deployment2-6594f5cd7f-kbjpm
I0121 16:17:14.853673       1 scheduler.go:83] [HigherPrecedence] Calculando precedência entre test-deployment2-6594f5cd7f-spfs2 e test-deployment2-6594f5cd7f-kbjpm
I0121 16:17:14.853679       1 scheduler.go:116] [WaitForPodsOnCache] Verificando se o pod test-deployment2-6594f5cd7f-spfs2 está no cache...
I0121 16:17:14.853683       1 scheduler.go:564] [GetControllerMetricInfo] Iniciando para o pod: default/test-deployment2-6594f5cd7f-spfs2
I0121 16:17:14.853687       1 scheduler.go:569] [GetControllerMetricInfo] Obtendo o nome do controlador para o pod: default/test-deployment2-6594f5cd7f-spfs2
I0121 16:17:14.853691       1 types.go:743] [ControllerName] Verificando as anotações do pod default/test-deployment2-6594f5cd7f-spfs2
I0121 16:17:14.853771       1 types.go:761] [ControllerName] Anotação 'controller' encontrada para o pod default/test-deployment2-6594f5cd7f-spfs2: test-controller2
I0121 16:17:14.853780       1 scheduler.go:572] [GetControllerMetricInfo] Métricas do controlador definidas para o pod: default/test-deployment2-6594f5cd7f-spfs2
W0121 16:17:14.853789       1 scheduler.go:124] [cacheMiss] Métricas não encontradas para o pod: default/test-deployment2-6594f5cd7f-spfs2
I0121 16:17:14.880639       1 scheduler.go:69] Estado no Informer: map[controller:test-controller2]
I0121 16:17:14.880667       1 scheduler.go:70] Estado real no cluster: map[controller:test-controller2]
W0121 16:17:14.880741       1 scheduler.go:134] [WaitForPodsOnCache] Pod test-deployment2-6594f5cd7f-spfs2 não encontrado no cache. Tentando novamente...
I0121 16:17:14.881246       1 scheduler.go:69] Estado no Informer: map[controller:test-controller2]
I0121 16:17:14.881258       1 scheduler.go:70] Estado real no cluster: map[controller:test-controller2]
I0121 16:17:14.890335       1 types.go:743] [ControllerName] Verificando as anotações do pod default/test-deployment2-6594f5cd7f-spfs2
I0121 16:17:14.890425       1 types.go:761] [ControllerName] Anotação 'controller' encontrada para o pod default/test-deployment2-6594f5cd7f-spfs2: test-controller2
I0121 16:17:14.890521       1 types.go:743] [ControllerName] Verificando as anotações do pod default/test-deployment2-6594f5cd7f-spfs2
I0121 16:17:14.890530       1 types.go:761] [ControllerName] Anotação 'controller' encontrada para o pod default/test-deployment2-6594f5cd7f-spfs2: test-controller2
I0121 16:17:14.981747       1 scheduler.go:564] [GetControllerMetricInfo] Iniciando para o pod: default/test-deployment2-6594f5cd7f-spfs2
I0121 16:17:14.982994       1 scheduler.go:569] [GetControllerMetricInfo] Obtendo o nome do controlador para o pod: default/test-deployment2-6594f5cd7f-spfs2
I0121 16:17:14.983151       1 types.go:743] [ControllerName] Verificando as anotações do pod default/test-deployment2-6594f5cd7f-spfs2
I0121 16:17:14.983301       1 types.go:761] [ControllerName] Anotação 'controller' encontrada para o pod default/test-deployment2-6594f5cd7f-spfs2: test-controller2
I0121 16:17:14.983410       1 scheduler.go:572] [GetControllerMetricInfo] Métricas do controlador definidas para o pod: default/test-deployment2-6594f5cd7f-spfs2
I0121 16:17:14.999300       1 scheduler.go:69] Estado no Informer: map[controller:test-controller2]
I0121 16:17:14.999449       1 scheduler.go:70] Estado real no cluster: map[controller:test-controller2]
I0121 16:17:14.999717       1 scheduler.go:138] [WaitForPodsOnCache] Pod test-deployment2-6594f5cd7f-spfs2 encontrado no cache.
I0121 16:17:14.999869       1 scheduler.go:116] [WaitForPodsOnCache] Verificando se o pod test-deployment2-6594f5cd7f-kbjpm está no cache...
I0121 16:17:14.999881       1 scheduler.go:564] [GetControllerMetricInfo] Iniciando para o pod: default/test-deployment2-6594f5cd7f-kbjpm
I0121 16:17:14.999890       1 scheduler.go:569] [GetControllerMetricInfo] Obtendo o nome do controlador para o pod: default/test-deployment2-6594f5cd7f-kbjpm
I0121 16:17:14.999898       1 types.go:743] [ControllerName] Verificando as anotações do pod default/test-deployment2-6594f5cd7f-kbjpm
I0121 16:17:15.000123       1 types.go:761] [ControllerName] Anotação 'controller' encontrada para o pod default/test-deployment2-6594f5cd7f-kbjpm: test-controller2
I0121 16:17:15.000136       1 scheduler.go:572] [GetControllerMetricInfo] Métricas do controlador definidas para o pod: default/test-deployment2-6594f5cd7f-kbjpm
I0121 16:17:15.009031       1 scheduler.go:69] Estado no Informer: map[controller:test-controller2]
I0121 16:17:15.009129       1 scheduler.go:70] Estado real no cluster: map[controller:test-controller2]
I0121 16:17:15.009140       1 scheduler.go:138] [WaitForPodsOnCache] Pod test-deployment2-6594f5cd7f-kbjpm encontrado no cache.
I0121 16:17:15.009150       1 scheduler.go:564] [GetControllerMetricInfo] Iniciando para o pod: default/test-deployment2-6594f5cd7f-spfs2
I0121 16:17:15.009156       1 scheduler.go:569] [GetControllerMetricInfo] Obtendo o nome do controlador para o pod: default/test-deployment2-6594f5cd7f-spfs2
I0121 16:17:15.009164       1 types.go:743] [ControllerName] Verificando as anotações do pod default/test-deployment2-6594f5cd7f-spfs2
I0121 16:17:15.009171       1 types.go:761] [ControllerName] Anotação 'controller' encontrada para o pod default/test-deployment2-6594f5cd7f-spfs2: test-controller2
I0121 16:17:15.009245       1 scheduler.go:572] [GetControllerMetricInfo] Métricas do controlador definidas para o pod: default/test-deployment2-6594f5cd7f-spfs2
I0121 16:17:15.009259       1 scheduler.go:564] [GetControllerMetricInfo] Iniciando para o pod: default/test-deployment2-6594f5cd7f-kbjpm
I0121 16:17:15.009264       1 scheduler.go:569] [GetControllerMetricInfo] Obtendo o nome do controlador para o pod: default/test-deployment2-6594f5cd7f-kbjpm
I0121 16:17:15.009269       1 types.go:743] [ControllerName] Verificando as anotações do pod default/test-deployment2-6594f5cd7f-kbjpm
I0121 16:17:15.009275       1 types.go:761] [ControllerName] Anotação 'controller' encontrada para o pod default/test-deployment2-6594f5cd7f-kbjpm: test-controller2
I0121 16:17:15.009280       1 scheduler.go:572] [GetControllerMetricInfo] Métricas do controlador definidas para o pod: default/test-deployment2-6594f5cd7f-kbjpm
I0121 16:17:15.009294       1 scheduler.go:97] [HigherPrecedence] Métricas para test-deployment2-6594f5cd7f-spfs2: QoS = -1110.699428, Importância = 0.80
I0121 16:17:15.009375       1 scheduler.go:98] [HigherPrecedence] Métricas para test-deployment2-6594f5cd7f-kbjpm: QoS = -1110.699428, Importância = 0.80
I0121 16:17:15.009383       1 scheduler.go:109] [HigherPrecedence] Decisão final: test-deployment2-6594f5cd7f-spfs2 tem precedência sobre test-deployment2-6594f5cd7f-kbjpm? false
I0121 16:17:15.009522       1 postFilter.go:142] [PREEMPT CALL] No node was chosen to allocate pod test-deployment2-6594f5cd7f-spfs2
I0121 16:17:15.365154       1 scheduler.go:247] [OnUpdatePod] Pod atualizado: default/test-deployment2-6594f5cd7f-spfs2, Anotações: map[controller:test-controller2]
I0121 16:17:15.534337       1 scheduler.go:69] Estado no Informer: map[controller:test-controller2]
I0121 16:17:15.534567       1 scheduler.go:70] Estado real no cluster: map[controller:test-controller2]
I0121 16:17:15.534599       1 types.go:743] [ControllerName] Verificando as anotações do pod default/test-deployment2-6594f5cd7f-spfs2
I0121 16:17:15.534615       1 types.go:761] [ControllerName] Anotação 'controller' encontrada para o pod default/test-deployment2-6594f5cd7f-spfs2: test-controller2
I0121 16:17:16.385847       1 types.go:743] [ControllerName] Verificando as anotações do pod default/test-deployment2-6594f5cd7f-kbjpm
I0121 16:17:16.385925       1 types.go:761] [ControllerName] Anotação 'controller' encontrada para o pod default/test-deployment2-6594f5cd7f-kbjpm: test-controller2
I0121 16:17:16.388871       1 postFilter.go:74] Comparando pod original com o atualizado...
I0121 16:17:16.388996       1 postFilter.go:81] Successfully retrieved updated pod default/test-deployment2-6594f5cd7f-spfs2 from lister
I0121 16:17:16.393239       1 postFilter.go:204] Recursos CPU do nó minikube estão sincronizados: 2000 mCPU
I0121 16:17:16.393302       1 postFilter.go:211] Recursos Memória do nó minikube estão sincronizados: 2216124416 bytes
I0121 16:17:16.393831       1 postFilter.go:145] [PREEMPT CALL] The node minikube  was chosen to allocate pod test-deployment2-6594f5cd7f-spfs2
I0121 16:17:16.394215       1 scheduler.go:83] [HigherPrecedence] Calculando precedência entre test-deployment2-6594f5cd7f-spfs2 e test-deployment3-ff66c7fc9-47zn9
I0121 16:17:16.394272       1 scheduler.go:116] [WaitForPodsOnCache] Verificando se o pod test-deployment2-6594f5cd7f-spfs2 está no cache...
I0121 16:17:16.394620       1 scheduler.go:564] [GetControllerMetricInfo] Iniciando para o pod: default/test-deployment2-6594f5cd7f-spfs2
I0121 16:17:16.394728       1 scheduler.go:569] [GetControllerMetricInfo] Obtendo o nome do controlador para o pod: default/test-deployment2-6594f5cd7f-spfs2
I0121 16:17:16.394739       1 types.go:743] [ControllerName] Verificando as anotações do pod default/test-deployment2-6594f5cd7f-spfs2
I0121 16:17:16.394749       1 types.go:761] [ControllerName] Anotação 'controller' encontrada para o pod default/test-deployment2-6594f5cd7f-spfs2: test-controller2
I0121 16:17:16.394777       1 scheduler.go:572] [GetControllerMetricInfo] Métricas do controlador definidas para o pod: default/test-deployment2-6594f5cd7f-spfs2
I0121 16:17:16.399184       1 scheduler.go:69] Estado no Informer: map[controller:test-controller2]
I0121 16:17:16.399263       1 scheduler.go:70] Estado real no cluster: map[controller:test-controller2]
I0121 16:17:16.399306       1 scheduler.go:138] [WaitForPodsOnCache] Pod test-deployment2-6594f5cd7f-spfs2 encontrado no cache.
I0121 16:17:16.399315       1 scheduler.go:116] [WaitForPodsOnCache] Verificando se o pod test-deployment3-ff66c7fc9-47zn9 está no cache...
I0121 16:17:16.399324       1 scheduler.go:564] [GetControllerMetricInfo] Iniciando para o pod: default/test-deployment3-ff66c7fc9-47zn9
I0121 16:17:16.399332       1 scheduler.go:569] [GetControllerMetricInfo] Obtendo o nome do controlador para o pod: default/test-deployment3-ff66c7fc9-47zn9
I0121 16:17:16.399339       1 types.go:743] [ControllerName] Verificando as anotações do pod default/test-deployment3-ff66c7fc9-47zn9
I0121 16:17:16.399694       1 types.go:761] [ControllerName] Anotação 'controller' encontrada para o pod default/test-deployment3-ff66c7fc9-47zn9: test-controller3
I0121 16:17:16.399768       1 scheduler.go:572] [GetControllerMetricInfo] Métricas do controlador definidas para o pod: default/test-deployment3-ff66c7fc9-47zn9
I0121 16:17:16.404639       1 scheduler.go:69] Estado no Informer: map[controller:test-controller3]
I0121 16:17:16.404698       1 scheduler.go:70] Estado real no cluster: map[controller:test-controller3]
I0121 16:17:16.404711       1 scheduler.go:138] [WaitForPodsOnCache] Pod test-deployment3-ff66c7fc9-47zn9 encontrado no cache.
I0121 16:17:16.404719       1 scheduler.go:564] [GetControllerMetricInfo] Iniciando para o pod: default/test-deployment2-6594f5cd7f-spfs2
I0121 16:17:16.404728       1 scheduler.go:569] [GetControllerMetricInfo] Obtendo o nome do controlador para o pod: default/test-deployment2-6594f5cd7f-spfs2
I0121 16:17:16.404736       1 types.go:743] [ControllerName] Verificando as anotações do pod default/test-deployment2-6594f5cd7f-spfs2
I0121 16:17:16.404745       1 types.go:761] [ControllerName] Anotação 'controller' encontrada para o pod default/test-deployment2-6594f5cd7f-spfs2: test-controller2
I0121 16:17:16.405072       1 scheduler.go:572] [GetControllerMetricInfo] Métricas do controlador definidas para o pod: default/test-deployment2-6594f5cd7f-spfs2
I0121 16:17:16.405132       1 scheduler.go:564] [GetControllerMetricInfo] Iniciando para o pod: default/test-deployment3-ff66c7fc9-47zn9
I0121 16:17:16.405594       1 scheduler.go:569] [GetControllerMetricInfo] Obtendo o nome do controlador para o pod: default/test-deployment3-ff66c7fc9-47zn9
I0121 16:17:16.405668       1 types.go:743] [ControllerName] Verificando as anotações do pod default/test-deployment3-ff66c7fc9-47zn9
I0121 16:17:16.405694       1 types.go:761] [ControllerName] Anotação 'controller' encontrada para o pod default/test-deployment3-ff66c7fc9-47zn9: test-controller3
I0121 16:17:16.406028       1 scheduler.go:572] [GetControllerMetricInfo] Métricas do controlador definidas para o pod: default/test-deployment3-ff66c7fc9-47zn9
I0121 16:17:16.406055       1 scheduler.go:97] [HigherPrecedence] Métricas para test-deployment2-6594f5cd7f-spfs2: QoS = -1111.856897, Importância = 0.80
I0121 16:17:16.406095       1 scheduler.go:98] [HigherPrecedence] Métricas para test-deployment3-ff66c7fc9-47zn9: QoS = -1142.592558, Importância = 0.80
I0121 16:17:16.406589       1 scheduler.go:109] [HigherPrecedence] Decisão final: test-deployment2-6594f5cd7f-spfs2 tem precedência sobre test-deployment3-ff66c7fc9-47zn9? false
I0121 16:17:16.432758       1 scheduler.go:247] [OnUpdatePod] Pod atualizado: default/test-deployment2-6594f5cd7f-spfs2, Anotações: map[controller:test-controller2]
I0121 16:17:16.436763       1 scheduler.go:69] Estado no Informer: map[controller:test-controller2]
I0121 16:17:16.436814       1 scheduler.go:70] Estado real no cluster: map[controller:test-controller2]
I0121 16:17:16.436826       1 types.go:743] [ControllerName] Verificando as anotações do pod default/test-deployment2-6594f5cd7f-spfs2
I0121 16:17:16.436835       1 types.go:761] [ControllerName] Anotação 'controller' encontrada para o pod default/test-deployment2-6594f5cd7f-spfs2: test-controller2
I0121 16:17:25.516072       1 postFilter.go:74] Comparando pod original com o atualizado...
I0121 16:17:25.516180       1 postFilter.go:81] Successfully retrieved updated pod default/test-deployment3-ff66c7fc9-47zn9 from lister
I0121 16:17:25.540423       1 postFilter.go:204] Recursos CPU do nó minikube estão sincronizados: 2000 mCPU
I0121 16:17:25.541613       1 postFilter.go:211] Recursos Memória do nó minikube estão sincronizados: 2216124416 bytes
I0121 16:17:25.543347       1 postFilter.go:145] [PREEMPT CALL] The node minikube  was chosen to allocate pod test-deployment3-ff66c7fc9-47zn9
W0121 16:17:25.544636       1 scheduler.go:78] [HigherPrecedence] Tentativa de comparar o pod test-deployment3-ff66c7fc9-47zn9 consigo mesmo. Retornando false.
I0121 16:17:25.544740       1 scheduler.go:83] [HigherPrecedence] Calculando precedência entre test-deployment3-ff66c7fc9-47zn9 e test-deployment2-6594f5cd7f-spfs2
I0121 16:17:25.544757       1 scheduler.go:116] [WaitForPodsOnCache] Verificando se o pod test-deployment3-ff66c7fc9-47zn9 está no cache...
I0121 16:17:25.544873       1 scheduler.go:564] [GetControllerMetricInfo] Iniciando para o pod: default/test-deployment3-ff66c7fc9-47zn9
I0121 16:17:25.545701       1 scheduler.go:569] [GetControllerMetricInfo] Obtendo o nome do controlador para o pod: default/test-deployment3-ff66c7fc9-47zn9
I0121 16:17:25.545867       1 types.go:743] [ControllerName] Verificando as anotações do pod default/test-deployment3-ff66c7fc9-47zn9
I0121 16:17:25.545891       1 types.go:761] [ControllerName] Anotação 'controller' encontrada para o pod default/test-deployment3-ff66c7fc9-47zn9: test-controller3
I0121 16:17:25.545907       1 scheduler.go:572] [GetControllerMetricInfo] Métricas do controlador definidas para o pod: default/test-deployment3-ff66c7fc9-47zn9
I0121 16:17:25.574001       1 scheduler.go:69] Estado no Informer: map[controller:test-controller3]
I0121 16:17:25.574081       1 scheduler.go:70] Estado real no cluster: map[controller:test-controller3]
I0121 16:17:25.574094       1 scheduler.go:138] [WaitForPodsOnCache] Pod test-deployment3-ff66c7fc9-47zn9 encontrado no cache.
I0121 16:17:25.574102       1 scheduler.go:116] [WaitForPodsOnCache] Verificando se o pod test-deployment2-6594f5cd7f-spfs2 está no cache...
I0121 16:17:25.574111       1 scheduler.go:564] [GetControllerMetricInfo] Iniciando para o pod: default/test-deployment2-6594f5cd7f-spfs2
I0121 16:17:25.574119       1 scheduler.go:569] [GetControllerMetricInfo] Obtendo o nome do controlador para o pod: default/test-deployment2-6594f5cd7f-spfs2
I0121 16:17:25.574129       1 types.go:743] [ControllerName] Verificando as anotações do pod default/test-deployment2-6594f5cd7f-spfs2
I0121 16:17:25.574137       1 types.go:761] [ControllerName] Anotação 'controller' encontrada para o pod default/test-deployment2-6594f5cd7f-spfs2: test-controller2
I0121 16:17:25.574147       1 scheduler.go:572] [GetControllerMetricInfo] Métricas do controlador definidas para o pod: default/test-deployment2-6594f5cd7f-spfs2
I0121 16:17:25.585124       1 scheduler.go:69] Estado no Informer: map[controller:test-controller2]
I0121 16:17:25.585192       1 scheduler.go:70] Estado real no cluster: map[controller:test-controller2]
I0121 16:17:25.585203       1 scheduler.go:138] [WaitForPodsOnCache] Pod test-deployment2-6594f5cd7f-spfs2 encontrado no cache.
I0121 16:17:25.585212       1 scheduler.go:564] [GetControllerMetricInfo] Iniciando para o pod: default/test-deployment3-ff66c7fc9-47zn9
I0121 16:17:25.585220       1 scheduler.go:569] [GetControllerMetricInfo] Obtendo o nome do controlador para o pod: default/test-deployment3-ff66c7fc9-47zn9
I0121 16:17:25.585228       1 types.go:743] [ControllerName] Verificando as anotações do pod default/test-deployment3-ff66c7fc9-47zn9
I0121 16:17:25.585241       1 types.go:761] [ControllerName] Anotação 'controller' encontrada para o pod default/test-deployment3-ff66c7fc9-47zn9: test-controller3
I0121 16:17:25.585249       1 scheduler.go:572] [GetControllerMetricInfo] Métricas do controlador definidas para o pod: default/test-deployment3-ff66c7fc9-47zn9
I0121 16:17:25.585262       1 scheduler.go:564] [GetControllerMetricInfo] Iniciando para o pod: default/test-deployment2-6594f5cd7f-spfs2
I0121 16:17:25.585268       1 scheduler.go:569] [GetControllerMetricInfo] Obtendo o nome do controlador para o pod: default/test-deployment2-6594f5cd7f-spfs2
I0121 16:17:25.585273       1 types.go:743] [ControllerName] Verificando as anotações do pod default/test-deployment2-6594f5cd7f-spfs2
I0121 16:17:25.585280       1 types.go:761] [ControllerName] Anotação 'controller' encontrada para o pod default/test-deployment2-6594f5cd7f-spfs2: test-controller2
I0121 16:17:25.585285       1 scheduler.go:572] [GetControllerMetricInfo] Métricas do controlador definidas para o pod: default/test-deployment2-6594f5cd7f-spfs2
I0121 16:17:25.585303       1 scheduler.go:97] [HigherPrecedence] Métricas para test-deployment3-ff66c7fc9-47zn9: QoS = -1151.743082, Importância = 0.80
I0121 16:17:25.585345       1 scheduler.go:98] [HigherPrecedence] Métricas para test-deployment2-6594f5cd7f-spfs2: QoS = -1121.007422, Importância = 0.80
I0121 16:17:25.585384       1 scheduler.go:109] [HigherPrecedence] Decisão final: test-deployment3-ff66c7fc9-47zn9 tem precedência sobre test-deployment2-6594f5cd7f-spfs2? true
I0121 16:17:25.606924       1 scheduler.go:247] [OnUpdatePod] Pod atualizado: default/test-deployment2-6594f5cd7f-spfs2, Anotações: map[controller:test-controller2]
I0121 16:17:25.617155       1 scheduler.go:69] Estado no Informer: map[controller:test-controller2]
I0121 16:17:25.617185       1 scheduler.go:70] Estado real no cluster: map[controller:test-controller2]
I0121 16:17:25.617196       1 types.go:743] [ControllerName] Verificando as anotações do pod default/test-deployment2-6594f5cd7f-spfs2
I0121 16:17:25.617203       1 types.go:761] [ControllerName] Anotação 'controller' encontrada para o pod default/test-deployment2-6594f5cd7f-spfs2: test-controller2
I0121 16:22:44.727179       1 scheduler.go:53] [QueueSort] Comparando prioridade de test-deployment3-ff66c7fc9-47zn9 com test-deployment2-6594f5cd7f-spfs2
I0121 16:22:44.727318       1 scheduler.go:83] [HigherPrecedence] Calculando precedência entre test-deployment3-ff66c7fc9-47zn9 e test-deployment2-6594f5cd7f-spfs2
I0121 16:22:44.727364       1 scheduler.go:116] [WaitForPodsOnCache] Verificando se o pod test-deployment3-ff66c7fc9-47zn9 está no cache...
I0121 16:22:44.727626       1 scheduler.go:564] [GetControllerMetricInfo] Iniciando para o pod: default/test-deployment3-ff66c7fc9-47zn9
I0121 16:22:44.727646       1 scheduler.go:569] [GetControllerMetricInfo] Obtendo o nome do controlador para o pod: default/test-deployment3-ff66c7fc9-47zn9
I0121 16:22:44.728260       1 types.go:743] [ControllerName] Verificando as anotações do pod default/test-deployment3-ff66c7fc9-47zn9
I0121 16:22:44.728631       1 types.go:761] [ControllerName] Anotação 'controller' encontrada para o pod default/test-deployment3-ff66c7fc9-47zn9: test-controller3
I0121 16:22:44.728828       1 scheduler.go:572] [GetControllerMetricInfo] Métricas do controlador definidas para o pod: default/test-deployment3-ff66c7fc9-47zn9
I0121 16:22:44.747013       1 scheduler.go:69] Estado no Informer: map[controller:test-controller3]
I0121 16:22:44.747239       1 scheduler.go:70] Estado real no cluster: map[controller:test-controller3]
I0121 16:22:44.747260       1 scheduler.go:138] [WaitForPodsOnCache] Pod test-deployment3-ff66c7fc9-47zn9 encontrado no cache.
I0121 16:22:44.747273       1 scheduler.go:116] [WaitForPodsOnCache] Verificando se o pod test-deployment2-6594f5cd7f-spfs2 está no cache...
I0121 16:22:44.748240       1 scheduler.go:564] [GetControllerMetricInfo] Iniciando para o pod: default/test-deployment2-6594f5cd7f-spfs2
I0121 16:22:44.748409       1 scheduler.go:569] [GetControllerMetricInfo] Obtendo o nome do controlador para o pod: default/test-deployment2-6594f5cd7f-spfs2
I0121 16:22:44.748427       1 types.go:743] [ControllerName] Verificando as anotações do pod default/test-deployment2-6594f5cd7f-spfs2
I0121 16:22:44.748441       1 types.go:761] [ControllerName] Anotação 'controller' encontrada para o pod default/test-deployment2-6594f5cd7f-spfs2: test-controller2
I0121 16:22:44.748643       1 scheduler.go:572] [GetControllerMetricInfo] Métricas do controlador definidas para o pod: default/test-deployment2-6594f5cd7f-spfs2
I0121 16:22:44.758668       1 scheduler.go:69] Estado no Informer: map[controller:test-controller2]
I0121 16:22:44.758758       1 scheduler.go:70] Estado real no cluster: map[controller:test-controller2]
I0121 16:22:44.758777       1 scheduler.go:138] [WaitForPodsOnCache] Pod test-deployment2-6594f5cd7f-spfs2 encontrado no cache.
I0121 16:22:44.758815       1 scheduler.go:564] [GetControllerMetricInfo] Iniciando para o pod: default/test-deployment3-ff66c7fc9-47zn9
I0121 16:22:44.758828       1 scheduler.go:569] [GetControllerMetricInfo] Obtendo o nome do controlador para o pod: default/test-deployment3-ff66c7fc9-47zn9
I0121 16:22:44.758840       1 types.go:743] [ControllerName] Verificando as anotações do pod default/test-deployment3-ff66c7fc9-47zn9
I0121 16:22:44.758853       1 types.go:761] [ControllerName] Anotação 'controller' encontrada para o pod default/test-deployment3-ff66c7fc9-47zn9: test-controller3
I0121 16:22:44.758866       1 scheduler.go:572] [GetControllerMetricInfo] Métricas do controlador definidas para o pod: default/test-deployment3-ff66c7fc9-47zn9
I0121 16:22:44.758905       1 scheduler.go:564] [GetControllerMetricInfo] Iniciando para o pod: default/test-deployment2-6594f5cd7f-spfs2
I0121 16:22:44.758915       1 scheduler.go:569] [GetControllerMetricInfo] Obtendo o nome do controlador para o pod: default/test-deployment2-6594f5cd7f-spfs2
I0121 16:22:44.758924       1 types.go:743] [ControllerName] Verificando as anotações do pod default/test-deployment2-6594f5cd7f-spfs2
I0121 16:22:44.758933       1 types.go:761] [ControllerName] Anotação 'controller' encontrada para o pod default/test-deployment2-6594f5cd7f-spfs2: test-controller2
I0121 16:22:44.758944       1 scheduler.go:572] [GetControllerMetricInfo] Métricas do controlador definidas para o pod: default/test-deployment2-6594f5cd7f-spfs2
I0121 16:22:44.759955       1 scheduler.go:97] [HigherPrecedence] Métricas para test-deployment3-ff66c7fc9-47zn9: QoS = -1470.925657, Importância = 0.80
I0121 16:22:44.760357       1 scheduler.go:98] [HigherPrecedence] Métricas para test-deployment2-6594f5cd7f-spfs2: QoS = -1440.189996, Importância = 0.80
I0121 16:22:44.760378       1 scheduler.go:109] [HigherPrecedence] Decisão final: test-deployment3-ff66c7fc9-47zn9 tem precedência sobre test-deployment2-6594f5cd7f-spfs2? true
I0121 16:22:44.760411       1 scheduler.go:59] [QueueSort] Precedência determinada: test-deployment3-ff66c7fc9-47zn9 tem precedência sobre test-deployment2-6594f5cd7f-spfs2? true
I0121 16:22:44.762177       1 scheduler.go:145] [Reserve] resources reserved at node minikube for pod test-deployment3-ff66c7fc9-47zn9_default at 2025-01-21 16:22:44.762160473 +0000 UTC m=+2581.416729265
I0121 16:22:44.762296       1 types.go:743] [ControllerName] Verificando as anotações do pod default/test-deployment3-ff66c7fc9-47zn9
I0121 16:22:44.762312       1 types.go:761] [ControllerName] Anotação 'controller' encontrada para o pod default/test-deployment3-ff66c7fc9-47zn9: test-controller3
I0121 16:22:44.762345       1 scheduler.go:147] [Reserve] Status de alocação atual para o pod test-deployment3-ff66c7fc9-47zn9_default: 
I0121 16:22:44.762359       1 scheduler.go:149] [Reserve] Status de alocação atualizado para o pod test-deployment3-ff66c7fc9-47zn9_default: allocating
I0121 16:22:44.763150       1 postFilter.go:74] Comparando pod original com o atualizado...
I0121 16:22:44.763240       1 postFilter.go:81] Successfully retrieved updated pod default/test-deployment2-6594f5cd7f-spfs2 from lister
I0121 16:22:44.764117       1 scheduler.go:173] [PreBind] Validando o pod test-deployment3-ff66c7fc9-47zn9 antes de vincular ao node minikube
I0121 16:22:44.770887       1 postFilter.go:204] Recursos CPU do nó minikube estão sincronizados: 2000 mCPU
I0121 16:22:44.771618       1 postFilter.go:211] Recursos Memória do nó minikube estão sincronizados: 2216124416 bytes
I0121 16:22:44.773321       1 scheduler.go:564] [GetControllerMetricInfo] Iniciando para o pod: default/test-deployment3-ff66c7fc9-47zn9
I0121 16:22:44.776016       1 scheduler.go:569] [GetControllerMetricInfo] Obtendo o nome do controlador para o pod: default/test-deployment3-ff66c7fc9-47zn9
I0121 16:22:44.776698       1 types.go:743] [ControllerName] Verificando as anotações do pod default/test-deployment3-ff66c7fc9-47zn9
I0121 16:22:44.777846       1 types.go:761] [ControllerName] Anotação 'controller' encontrada para o pod default/test-deployment3-ff66c7fc9-47zn9: test-controller3
I0121 16:22:44.803580       1 scheduler.go:181] [PostBind] Chamado para pod test-deployment3-ff66c7fc9-47zn9
I0121 16:22:44.803653       1 scheduler.go:199] [PostBind] Pod test-deployment3-ff66c7fc9-47zn9 - Início do binding: 2025-01-21 16:22:44.764760898 +0000 UTC m=+2581.419330005, Fim do binding: 2025-01-21 16:22:44.803645466 +0000 UTC m=+2581.458214300
I0121 16:22:44.778830       1 scheduler.go:572] [GetControllerMetricInfo] Métricas do controlador definidas para o pod: default/test-deployment3-ff66c7fc9-47zn9
I0121 16:22:44.809034       1 scheduler.go:83] [HigherPrecedence] Calculando precedência entre test-deployment2-6594f5cd7f-spfs2 e test-deployment3-ff66c7fc9-47zn9
I0121 16:22:44.809170       1 scheduler.go:116] [WaitForPodsOnCache] Verificando se o pod test-deployment2-6594f5cd7f-spfs2 está no cache...
I0121 16:22:44.809184       1 scheduler.go:564] [GetControllerMetricInfo] Iniciando para o pod: default/test-deployment2-6594f5cd7f-spfs2
I0121 16:22:44.809205       1 types.go:743] [ControllerName] Verificando as anotações do pod default/test-deployment3-ff66c7fc9-47zn9
I0121 16:22:44.809215       1 types.go:761] [ControllerName] Anotação 'controller' encontrada para o pod default/test-deployment3-ff66c7fc9-47zn9: test-controller3
I0121 16:22:44.809229       1 scheduler.go:206] [PostBind] Métricas atualizadas para o pod test-deployment3-ff66c7fc9-47zn9
I0121 16:22:44.810220       1 scheduler.go:569] [GetControllerMetricInfo] Obtendo o nome do controlador para o pod: default/test-deployment2-6594f5cd7f-spfs2
I0121 16:22:44.811010       1 types.go:743] [ControllerName] Verificando as anotações do pod default/test-deployment2-6594f5cd7f-spfs2
I0121 16:22:44.811171       1 types.go:761] [ControllerName] Anotação 'controller' encontrada para o pod default/test-deployment2-6594f5cd7f-spfs2: test-controller2
I0121 16:22:44.811848       1 scheduler.go:572] [GetControllerMetricInfo] Métricas do controlador definidas para o pod: default/test-deployment2-6594f5cd7f-spfs2
I0121 16:22:44.810979       1 scheduler.go:247] [OnUpdatePod] Pod atualizado: default/test-deployment3-ff66c7fc9-47zn9, Anotações: map[controller:test-controller3]
I0121 16:22:44.825665       1 scheduler.go:69] Estado no Informer: map[controller:test-controller3]
I0121 16:22:44.826094       1 scheduler.go:70] Estado real no cluster: map[controller:test-controller3]
I0121 16:22:44.825572       1 scheduler.go:69] Estado no Informer: map[controller:test-controller2]
I0121 16:22:44.826395       1 scheduler.go:70] Estado real no cluster: map[controller:test-controller2]
I0121 16:22:44.826634       1 scheduler.go:138] [WaitForPodsOnCache] Pod test-deployment2-6594f5cd7f-spfs2 encontrado no cache.
I0121 16:22:44.826703       1 scheduler.go:116] [WaitForPodsOnCache] Verificando se o pod test-deployment3-ff66c7fc9-47zn9 está no cache...
I0121 16:22:44.826842       1 scheduler.go:564] [GetControllerMetricInfo] Iniciando para o pod: default/test-deployment3-ff66c7fc9-47zn9
I0121 16:22:44.826961       1 types.go:743] [ControllerName] Verificando as anotações do pod default/test-deployment3-ff66c7fc9-47zn9
I0121 16:22:44.827211       1 types.go:761] [ControllerName] Anotação 'controller' encontrada para o pod default/test-deployment3-ff66c7fc9-47zn9: test-controller3
I0121 16:22:44.827512       1 scheduler.go:247] [OnUpdatePod] Pod atualizado: default/test-deployment3-ff66c7fc9-47zn9, Anotações: map[controller:test-controller3]
I0121 16:22:44.829901       1 scheduler.go:569] [GetControllerMetricInfo] Obtendo o nome do controlador para o pod: default/test-deployment3-ff66c7fc9-47zn9
I0121 16:22:44.829944       1 types.go:743] [ControllerName] Verificando as anotações do pod default/test-deployment3-ff66c7fc9-47zn9
I0121 16:22:44.831934       1 types.go:761] [ControllerName] Anotação 'controller' encontrada para o pod default/test-deployment3-ff66c7fc9-47zn9: test-controller3
I0121 16:22:44.832083       1 scheduler.go:572] [GetControllerMetricInfo] Métricas do controlador definidas para o pod: default/test-deployment3-ff66c7fc9-47zn9
I0121 16:22:44.831916       1 scheduler.go:69] Estado no Informer: map[controller:test-controller3]
I0121 16:22:44.834992       1 scheduler.go:70] Estado real no cluster: map[controller:test-controller3]
I0121 16:22:44.836871       1 scheduler.go:69] Estado no Informer: map[controller:test-controller3]
I0121 16:22:44.837068       1 scheduler.go:70] Estado real no cluster: map[controller:test-controller3]
I0121 16:22:44.837215       1 scheduler.go:138] [WaitForPodsOnCache] Pod test-deployment3-ff66c7fc9-47zn9 encontrado no cache.
I0121 16:22:44.837238       1 scheduler.go:564] [GetControllerMetricInfo] Iniciando para o pod: default/test-deployment2-6594f5cd7f-spfs2
I0121 16:22:44.837398       1 types.go:743] [ControllerName] Verificando as anotações do pod default/test-deployment3-ff66c7fc9-47zn9
I0121 16:22:44.837539       1 types.go:761] [ControllerName] Anotação 'controller' encontrada para o pod default/test-deployment3-ff66c7fc9-47zn9: test-controller3
I0121 16:22:44.837722       1 scheduler.go:569] [GetControllerMetricInfo] Obtendo o nome do controlador para o pod: default/test-deployment2-6594f5cd7f-spfs2
I0121 16:22:44.837794       1 types.go:743] [ControllerName] Verificando as anotações do pod default/test-deployment2-6594f5cd7f-spfs2
I0121 16:22:44.837925       1 types.go:761] [ControllerName] Anotação 'controller' encontrada para o pod default/test-deployment2-6594f5cd7f-spfs2: test-controller2
I0121 16:22:44.838048       1 scheduler.go:572] [GetControllerMetricInfo] Métricas do controlador definidas para o pod: default/test-deployment2-6594f5cd7f-spfs2
I0121 16:22:44.838191       1 scheduler.go:564] [GetControllerMetricInfo] Iniciando para o pod: default/test-deployment3-ff66c7fc9-47zn9
I0121 16:22:44.838266       1 scheduler.go:569] [GetControllerMetricInfo] Obtendo o nome do controlador para o pod: default/test-deployment3-ff66c7fc9-47zn9
I0121 16:22:44.838310       1 types.go:743] [ControllerName] Verificando as anotações do pod default/test-deployment3-ff66c7fc9-47zn9
I0121 16:22:44.838328       1 types.go:761] [ControllerName] Anotação 'controller' encontrada para o pod default/test-deployment3-ff66c7fc9-47zn9: test-controller3
I0121 16:22:44.838344       1 scheduler.go:572] [GetControllerMetricInfo] Métricas do controlador definidas para o pod: default/test-deployment3-ff66c7fc9-47zn9
I0121 16:22:44.838417       1 scheduler.go:97] [HigherPrecedence] Métricas para test-deployment2-6594f5cd7f-spfs2: QoS = -1440.270636, Importância = 0.80
I0121 16:22:44.838536       1 scheduler.go:98] [HigherPrecedence] Métricas para test-deployment3-ff66c7fc9-47zn9: QoS = -1471.006477, Importância = 0.80
I0121 16:22:44.838652       1 scheduler.go:109] [HigherPrecedence] Decisão final: test-deployment2-6594f5cd7f-spfs2 tem precedência sobre test-deployment3-ff66c7fc9-47zn9? false
I0121 16:22:44.838780       1 postFilter.go:142] [PREEMPT CALL] No node was chosen to allocate pod test-deployment2-6594f5cd7f-spfs2
I0121 16:22:48.273105       1 scheduler.go:247] [OnUpdatePod] Pod atualizado: default/test-deployment3-ff66c7fc9-47zn9, Anotações: map[controller:test-controller3]
I0121 16:22:48.280156       1 scheduler.go:69] Estado no Informer: map[controller:test-controller3]
I0121 16:22:48.280284       1 scheduler.go:70] Estado real no cluster: map[controller:test-controller3]
I0121 16:22:48.280368       1 types.go:743] [ControllerName] Verificando as anotações do pod default/test-deployment3-ff66c7fc9-47zn9
I0121 16:22:48.280826       1 types.go:761] [ControllerName] Anotação 'controller' encontrada para o pod default/test-deployment3-ff66c7fc9-47zn9: test-controller3
I0121 16:22:49.805599       1 postFilter.go:74] Comparando pod original com o atualizado...
I0121 16:22:49.805689       1 postFilter.go:81] Successfully retrieved updated pod default/test-deployment2-6594f5cd7f-spfs2 from lister
I0121 16:22:49.813848       1 postFilter.go:204] Recursos CPU do nó minikube estão sincronizados: 2000 mCPU
I0121 16:22:49.814264       1 postFilter.go:211] Recursos Memória do nó minikube estão sincronizados: 2216124416 bytes
I0121 16:22:49.815205       1 scheduler.go:564] [GetControllerMetricInfo] Iniciando para o pod: default/test-deployment3-ff66c7fc9-47zn9
I0121 16:22:49.815533       1 scheduler.go:569] [GetControllerMetricInfo] Obtendo o nome do controlador para o pod: default/test-deployment3-ff66c7fc9-47zn9
I0121 16:22:49.815789       1 types.go:743] [ControllerName] Verificando as anotações do pod default/test-deployment3-ff66c7fc9-47zn9
I0121 16:22:49.815952       1 types.go:761] [ControllerName] Anotação 'controller' encontrada para o pod default/test-deployment3-ff66c7fc9-47zn9: test-controller3
I0121 16:22:49.816405       1 scheduler.go:572] [GetControllerMetricInfo] Métricas do controlador definidas para o pod: default/test-deployment3-ff66c7fc9-47zn9
I0121 16:22:49.816779       1 scheduler.go:83] [HigherPrecedence] Calculando precedência entre test-deployment2-6594f5cd7f-spfs2 e test-deployment3-ff66c7fc9-47zn9
I0121 16:22:49.817089       1 scheduler.go:116] [WaitForPodsOnCache] Verificando se o pod test-deployment2-6594f5cd7f-spfs2 está no cache...
I0121 16:22:49.817396       1 scheduler.go:564] [GetControllerMetricInfo] Iniciando para o pod: default/test-deployment2-6594f5cd7f-spfs2
I0121 16:22:49.817673       1 scheduler.go:569] [GetControllerMetricInfo] Obtendo o nome do controlador para o pod: default/test-deployment2-6594f5cd7f-spfs2
I0121 16:22:49.817974       1 types.go:743] [ControllerName] Verificando as anotações do pod default/test-deployment2-6594f5cd7f-spfs2
I0121 16:22:49.818190       1 types.go:761] [ControllerName] Anotação 'controller' encontrada para o pod default/test-deployment2-6594f5cd7f-spfs2: test-controller2
I0121 16:22:49.818416       1 scheduler.go:572] [GetControllerMetricInfo] Métricas do controlador definidas para o pod: default/test-deployment2-6594f5cd7f-spfs2
I0121 16:22:49.825359       1 scheduler.go:69] Estado no Informer: map[controller:test-controller2]
I0121 16:22:49.825585       1 scheduler.go:70] Estado real no cluster: map[controller:test-controller2]
I0121 16:22:49.825607       1 scheduler.go:138] [WaitForPodsOnCache] Pod test-deployment2-6594f5cd7f-spfs2 encontrado no cache.
I0121 16:22:49.825919       1 scheduler.go:116] [WaitForPodsOnCache] Verificando se o pod test-deployment3-ff66c7fc9-47zn9 está no cache...
I0121 16:22:49.826006       1 scheduler.go:564] [GetControllerMetricInfo] Iniciando para o pod: default/test-deployment3-ff66c7fc9-47zn9
I0121 16:22:49.826023       1 scheduler.go:569] [GetControllerMetricInfo] Obtendo o nome do controlador para o pod: default/test-deployment3-ff66c7fc9-47zn9
I0121 16:22:49.826036       1 types.go:743] [ControllerName] Verificando as anotações do pod default/test-deployment3-ff66c7fc9-47zn9
I0121 16:22:49.826050       1 types.go:761] [ControllerName] Anotação 'controller' encontrada para o pod default/test-deployment3-ff66c7fc9-47zn9: test-controller3
I0121 16:22:49.826065       1 scheduler.go:572] [GetControllerMetricInfo] Métricas do controlador definidas para o pod: default/test-deployment3-ff66c7fc9-47zn9
I0121 16:22:49.832063       1 scheduler.go:69] Estado no Informer: map[controller:test-controller3]
I0121 16:22:49.832161       1 scheduler.go:70] Estado real no cluster: map[controller:test-controller3]
I0121 16:22:49.832182       1 scheduler.go:138] [WaitForPodsOnCache] Pod test-deployment3-ff66c7fc9-47zn9 encontrado no cache.
I0121 16:22:49.832196       1 scheduler.go:564] [GetControllerMetricInfo] Iniciando para o pod: default/test-deployment2-6594f5cd7f-spfs2
I0121 16:22:49.832573       1 scheduler.go:569] [GetControllerMetricInfo] Obtendo o nome do controlador para o pod: default/test-deployment2-6594f5cd7f-spfs2
I0121 16:22:49.832649       1 types.go:743] [ControllerName] Verificando as anotações do pod default/test-deployment2-6594f5cd7f-spfs2
I0121 16:22:49.832667       1 types.go:761] [ControllerName] Anotação 'controller' encontrada para o pod default/test-deployment2-6594f5cd7f-spfs2: test-controller2
I0121 16:22:49.832682       1 scheduler.go:572] [GetControllerMetricInfo] Métricas do controlador definidas para o pod: default/test-deployment2-6594f5cd7f-spfs2
I0121 16:22:49.832902       1 scheduler.go:564] [GetControllerMetricInfo] Iniciando para o pod: default/test-deployment3-ff66c7fc9-47zn9
I0121 16:22:49.832977       1 scheduler.go:569] [GetControllerMetricInfo] Obtendo o nome do controlador para o pod: default/test-deployment3-ff66c7fc9-47zn9
I0121 16:22:49.832991       1 types.go:743] [ControllerName] Verificando as anotações do pod default/test-deployment3-ff66c7fc9-47zn9
I0121 16:22:49.833004       1 types.go:761] [ControllerName] Anotação 'controller' encontrada para o pod default/test-deployment3-ff66c7fc9-47zn9: test-controller3
I0121 16:22:49.833209       1 scheduler.go:572] [GetControllerMetricInfo] Métricas do controlador definidas para o pod: default/test-deployment3-ff66c7fc9-47zn9
I0121 16:22:49.833298       1 scheduler.go:97] [HigherPrecedence] Métricas para test-deployment2-6594f5cd7f-spfs2: QoS = -1445.279334, Importância = 0.80
I0121 16:22:49.833562       1 scheduler.go:98] [HigherPrecedence] Métricas para test-deployment3-ff66c7fc9-47zn9: QoS = -1469.754302, Importância = 0.80
I0121 16:22:49.833588       1 scheduler.go:109] [HigherPrecedence] Decisão final: test-deployment2-6594f5cd7f-spfs2 tem precedência sobre test-deployment3-ff66c7fc9-47zn9? false
I0121 16:22:49.833886       1 postFilter.go:142] [PREEMPT CALL] No node was chosen to allocate pod test-deployment2-6594f5cd7f-spfs2
I0121 16:25:30.179687       1 scheduler.go:213] [OnAddPod] Pod adicionado: default/test-deployment-75477b6477-l79n8, Anotações: map[controller:test-controller]
I0121 16:25:30.180156       1 postFilter.go:74] Comparando pod original com o atualizado...
I0121 16:25:30.181498       1 postFilter.go:81] Successfully retrieved updated pod default/test-deployment-75477b6477-l79n8 from lister
I0121 16:25:30.199591       1 postFilter.go:204] Recursos CPU do nó minikube estão sincronizados: 2000 mCPU
I0121 16:25:30.205957       1 postFilter.go:211] Recursos Memória do nó minikube estão sincronizados: 2216124416 bytes
I0121 16:25:30.207115       1 scheduler.go:564] [GetControllerMetricInfo] Iniciando para o pod: default/test-deployment3-ff66c7fc9-47zn9
I0121 16:25:30.207156       1 scheduler.go:569] [GetControllerMetricInfo] Obtendo o nome do controlador para o pod: default/test-deployment3-ff66c7fc9-47zn9
I0121 16:25:30.207182       1 types.go:743] [ControllerName] Verificando as anotações do pod default/test-deployment3-ff66c7fc9-47zn9
I0121 16:25:30.207189       1 types.go:761] [ControllerName] Anotação 'controller' encontrada para o pod default/test-deployment3-ff66c7fc9-47zn9: test-controller3
I0121 16:25:30.207203       1 scheduler.go:572] [GetControllerMetricInfo] Métricas do controlador definidas para o pod: default/test-deployment3-ff66c7fc9-47zn9
I0121 16:25:30.207211       1 scheduler.go:83] [HigherPrecedence] Calculando precedência entre test-deployment-75477b6477-l79n8 e test-deployment3-ff66c7fc9-47zn9
I0121 16:25:30.207217       1 scheduler.go:116] [WaitForPodsOnCache] Verificando se o pod test-deployment-75477b6477-l79n8 está no cache...
I0121 16:25:30.207230       1 scheduler.go:564] [GetControllerMetricInfo] Iniciando para o pod: default/test-deployment-75477b6477-l79n8
I0121 16:25:30.207234       1 scheduler.go:569] [GetControllerMetricInfo] Obtendo o nome do controlador para o pod: default/test-deployment-75477b6477-l79n8
I0121 16:25:30.207238       1 types.go:743] [ControllerName] Verificando as anotações do pod default/test-deployment-75477b6477-l79n8
I0121 16:25:30.207242       1 types.go:761] [ControllerName] Anotação 'controller' encontrada para o pod default/test-deployment-75477b6477-l79n8: test-controller
I0121 16:25:30.207247       1 scheduler.go:572] [GetControllerMetricInfo] Métricas do controlador definidas para o pod: default/test-deployment-75477b6477-l79n8
W0121 16:25:30.207263       1 scheduler.go:124] [cacheMiss] Métricas não encontradas para o pod: default/test-deployment-75477b6477-l79n8
I0121 16:25:30.219658       1 scheduler.go:69] Estado no Informer: map[controller:test-controller]
I0121 16:25:30.219807       1 scheduler.go:70] Estado real no cluster: map[controller:test-controller]
I0121 16:25:30.227606       1 scheduler.go:69] Estado no Informer: map[controller:test-controller]
I0121 16:25:30.227635       1 scheduler.go:70] Estado real no cluster: map[controller:test-controller]
W0121 16:25:30.227670       1 scheduler.go:134] [WaitForPodsOnCache] Pod test-deployment-75477b6477-l79n8 não encontrado no cache. Tentando novamente...
I0121 16:25:30.227691       1 types.go:743] [ControllerName] Verificando as anotações do pod default/test-deployment-75477b6477-l79n8
I0121 16:25:30.227699       1 types.go:761] [ControllerName] Anotação 'controller' encontrada para o pod default/test-deployment-75477b6477-l79n8: test-controller
I0121 16:25:30.235753       1 types.go:743] [ControllerName] Verificando as anotações do pod default/test-deployment-75477b6477-l79n8
I0121 16:25:30.236295       1 types.go:761] [ControllerName] Anotação 'controller' encontrada para o pod default/test-deployment-75477b6477-l79n8: test-controller
I0121 16:25:30.328441       1 scheduler.go:564] [GetControllerMetricInfo] Iniciando para o pod: default/test-deployment-75477b6477-l79n8
I0121 16:25:30.328556       1 scheduler.go:569] [GetControllerMetricInfo] Obtendo o nome do controlador para o pod: default/test-deployment-75477b6477-l79n8
I0121 16:25:30.328567       1 types.go:743] [ControllerName] Verificando as anotações do pod default/test-deployment-75477b6477-l79n8
I0121 16:25:30.328578       1 types.go:761] [ControllerName] Anotação 'controller' encontrada para o pod default/test-deployment-75477b6477-l79n8: test-controller
I0121 16:25:30.328587       1 scheduler.go:572] [GetControllerMetricInfo] Métricas do controlador definidas para o pod: default/test-deployment-75477b6477-l79n8
I0121 16:25:30.335784       1 scheduler.go:69] Estado no Informer: map[controller:test-controller]
I0121 16:25:30.335914       1 scheduler.go:70] Estado real no cluster: map[controller:test-controller]
I0121 16:25:30.336231       1 scheduler.go:138] [WaitForPodsOnCache] Pod test-deployment-75477b6477-l79n8 encontrado no cache.
I0121 16:25:30.337657       1 scheduler.go:116] [WaitForPodsOnCache] Verificando se o pod test-deployment3-ff66c7fc9-47zn9 está no cache...
I0121 16:25:30.337890       1 scheduler.go:564] [GetControllerMetricInfo] Iniciando para o pod: default/test-deployment3-ff66c7fc9-47zn9
I0121 16:25:30.339166       1 scheduler.go:569] [GetControllerMetricInfo] Obtendo o nome do controlador para o pod: default/test-deployment3-ff66c7fc9-47zn9
I0121 16:25:30.339698       1 types.go:743] [ControllerName] Verificando as anotações do pod default/test-deployment3-ff66c7fc9-47zn9
I0121 16:25:30.340792       1 types.go:761] [ControllerName] Anotação 'controller' encontrada para o pod default/test-deployment3-ff66c7fc9-47zn9: test-controller3
I0121 16:25:30.340901       1 scheduler.go:572] [GetControllerMetricInfo] Métricas do controlador definidas para o pod: default/test-deployment3-ff66c7fc9-47zn9
I0121 16:25:30.350779       1 scheduler.go:69] Estado no Informer: map[controller:test-controller3]
I0121 16:25:30.350832       1 scheduler.go:70] Estado real no cluster: map[controller:test-controller3]
I0121 16:25:30.350844       1 scheduler.go:138] [WaitForPodsOnCache] Pod test-deployment3-ff66c7fc9-47zn9 encontrado no cache.
I0121 16:25:30.351027       1 scheduler.go:564] [GetControllerMetricInfo] Iniciando para o pod: default/test-deployment-75477b6477-l79n8
I0121 16:25:30.351067       1 scheduler.go:569] [GetControllerMetricInfo] Obtendo o nome do controlador para o pod: default/test-deployment-75477b6477-l79n8
I0121 16:25:30.353568       1 types.go:743] [ControllerName] Verificando as anotações do pod default/test-deployment-75477b6477-l79n8
I0121 16:25:30.353610       1 types.go:761] [ControllerName] Anotação 'controller' encontrada para o pod default/test-deployment-75477b6477-l79n8: test-controller
I0121 16:25:30.353650       1 scheduler.go:572] [GetControllerMetricInfo] Métricas do controlador definidas para o pod: default/test-deployment-75477b6477-l79n8
I0121 16:25:30.353691       1 scheduler.go:564] [GetControllerMetricInfo] Iniciando para o pod: default/test-deployment3-ff66c7fc9-47zn9
I0121 16:25:30.353725       1 scheduler.go:569] [GetControllerMetricInfo] Obtendo o nome do controlador para o pod: default/test-deployment3-ff66c7fc9-47zn9
I0121 16:25:30.353759       1 types.go:743] [ControllerName] Verificando as anotações do pod default/test-deployment3-ff66c7fc9-47zn9
I0121 16:25:30.353767       1 types.go:761] [ControllerName] Anotação 'controller' encontrada para o pod default/test-deployment3-ff66c7fc9-47zn9: test-controller3
I0121 16:25:30.353776       1 scheduler.go:572] [GetControllerMetricInfo] Métricas do controlador definidas para o pod: default/test-deployment3-ff66c7fc9-47zn9
I0121 16:25:30.353799       1 scheduler.go:97] [HigherPrecedence] Métricas para test-deployment-75477b6477-l79n8: QoS = -2.607207, Importância = 0.80
I0121 16:25:30.353875       1 scheduler.go:98] [HigherPrecedence] Métricas para test-deployment3-ff66c7fc9-47zn9: QoS = -1429.656662, Importância = 0.80
I0121 16:25:30.353887       1 scheduler.go:109] [HigherPrecedence] Decisão final: test-deployment-75477b6477-l79n8 tem precedência sobre test-deployment3-ff66c7fc9-47zn9? false
I0121 16:25:30.353950       1 postFilter.go:142] [PREEMPT CALL] No node was chosen to allocate pod test-deployment-75477b6477-l79n8
I0121 16:25:30.382187       1 scheduler.go:247] [OnUpdatePod] Pod atualizado: default/test-deployment-75477b6477-l79n8, Anotações: map[controller:test-controller]
I0121 16:25:30.389705       1 scheduler.go:69] Estado no Informer: map[controller:test-controller]
I0121 16:25:30.390033       1 scheduler.go:70] Estado real no cluster: map[controller:test-controller]
I0121 16:25:30.391361       1 types.go:743] [ControllerName] Verificando as anotações do pod default/test-deployment-75477b6477-l79n8
I0121 16:25:30.391583       1 types.go:761] [ControllerName] Anotação 'controller' encontrada para o pod default/test-deployment-75477b6477-l79n8: test-controller
I0121 16:26:21.960173       1 scheduler.go:247] [OnUpdatePod] Pod atualizado: default/test-deployment-75477b6477-l79n8, Anotações: map[controller:test-controller]
E0121 16:26:21.989297       1 scheduler.go:66] Erro ao buscar estado real do pod test-deployment-75477b6477-l79n8: pods "test-deployment-75477b6477-l79n8" not found
I0121 16:26:21.989413       1 types.go:743] [ControllerName] Verificando as anotações do pod default/test-deployment-75477b6477-l79n8
I0121 16:26:21.989431       1 types.go:761] [ControllerName] Anotação 'controller' encontrada para o pod default/test-deployment-75477b6477-l79n8: test-controller
I0121 16:26:21.989672       1 types.go:743] [ControllerName] Verificando as anotações do pod default/test-deployment-75477b6477-l79n8
I0121 16:26:21.989793       1 types.go:761] [ControllerName] Anotação 'controller' encontrada para o pod default/test-deployment-75477b6477-l79n8: test-controller
I0121 16:26:21.990606       1 scheduler.go:247] [OnUpdatePod] Pod atualizado: default/test-deployment2-6594f5cd7f-spfs2, Anotações: map[controller:test-controller2]
E0121 16:26:22.001250       1 scheduler.go:66] Erro ao buscar estado real do pod test-deployment2-6594f5cd7f-spfs2: pods "test-deployment2-6594f5cd7f-spfs2" not found
I0121 16:26:22.001659       1 types.go:743] [ControllerName] Verificando as anotações do pod default/test-deployment2-6594f5cd7f-spfs2
I0121 16:26:22.001887       1 types.go:761] [ControllerName] Anotação 'controller' encontrada para o pod default/test-deployment2-6594f5cd7f-spfs2: test-controller2
I0121 16:26:22.003657       1 types.go:743] [ControllerName] Verificando as anotações do pod default/test-deployment2-6594f5cd7f-spfs2
I0121 16:26:22.003691       1 types.go:761] [ControllerName] Anotação 'controller' encontrada para o pod default/test-deployment2-6594f5cd7f-spfs2: test-controller2
I0121 16:26:22.005358       1 types.go:743] [ControllerName] Verificando as anotações do pod default/test-deployment-75477b6477-l79n8
I0121 16:26:22.005539       1 types.go:761] [ControllerName] Anotação 'controller' encontrada para o pod default/test-deployment-75477b6477-l79n8: test-controller
I0121 16:26:22.006106       1 types.go:743] [ControllerName] Verificando as anotações do pod default/test-deployment2-6594f5cd7f-spfs2
I0121 16:26:22.006264       1 types.go:761] [ControllerName] Anotação 'controller' encontrada para o pod default/test-deployment2-6594f5cd7f-spfs2: test-controller2
I0121 16:26:22.028943       1 scheduler.go:247] [OnUpdatePod] Pod atualizado: default/test-deployment3-ff66c7fc9-47zn9, Anotações: map[controller:test-controller3]
I0121 16:26:22.064232       1 scheduler.go:69] Estado no Informer: map[controller:test-controller3]
I0121 16:26:22.067153       1 scheduler.go:70] Estado real no cluster: map[controller:test-controller3]
I0121 16:26:22.067239       1 types.go:743] [ControllerName] Verificando as anotações do pod default/test-deployment3-ff66c7fc9-47zn9
I0121 16:26:22.067248       1 types.go:761] [ControllerName] Anotação 'controller' encontrada para o pod default/test-deployment3-ff66c7fc9-47zn9: test-controller3
I0121 16:26:22.067307       1 types.go:743] [ControllerName] Verificando as anotações do pod default/test-deployment3-ff66c7fc9-47zn9
I0121 16:26:22.067335       1 types.go:761] [ControllerName] Anotação 'controller' encontrada para o pod default/test-deployment3-ff66c7fc9-47zn9: test-controller3
I0121 16:26:23.413047       1 types.go:743] [ControllerName] Verificando as anotações do pod default/test-deployment3-ff66c7fc9-47zn9
I0121 16:26:23.413595       1 types.go:761] [ControllerName] Anotação 'controller' encontrada para o pod default/test-deployment3-ff66c7fc9-47zn9: test-controller3
I0121 16:26:50.368886       1 scheduler.go:213] [OnAddPod] Pod adicionado: default/test-deployment-75477b6477-mkv9t, Anotações: map[controller:test-controller]
I0121 16:26:50.368935       1 scheduler.go:145] [Reserve] resources reserved at node minikube for pod test-deployment-75477b6477-mkv9t_default at 2025-01-21 16:26:50.368920045 +0000 UTC m=+2827.023488611
I0121 16:26:50.369428       1 types.go:743] [ControllerName] Verificando as anotações do pod default/test-deployment-75477b6477-mkv9t
I0121 16:26:50.369448       1 types.go:761] [ControllerName] Anotação 'controller' encontrada para o pod default/test-deployment-75477b6477-mkv9t: test-controller
I0121 16:26:50.390729       1 scheduler.go:147] [Reserve] Status de alocação atual para o pod test-deployment-75477b6477-mkv9t_default: 
I0121 16:26:50.394352       1 scheduler.go:149] [Reserve] Status de alocação atualizado para o pod test-deployment-75477b6477-mkv9t_default: allocating
I0121 16:26:50.397524       1 scheduler.go:173] [PreBind] Validando o pod test-deployment-75477b6477-mkv9t antes de vincular ao node minikube
I0121 16:26:50.396117       1 scheduler.go:69] Estado no Informer: map[controller:test-controller]
I0121 16:26:50.397604       1 scheduler.go:70] Estado real no cluster: map[controller:test-controller]
I0121 16:26:50.407315       1 types.go:743] [ControllerName] Verificando as anotações do pod default/test-deployment-75477b6477-mkv9t
I0121 16:26:50.407375       1 types.go:761] [ControllerName] Anotação 'controller' encontrada para o pod default/test-deployment-75477b6477-mkv9t: test-controller
I0121 16:26:50.407425       1 types.go:743] [ControllerName] Verificando as anotações do pod default/test-deployment-75477b6477-mkv9t
I0121 16:26:50.407542       1 types.go:761] [ControllerName] Anotação 'controller' encontrada para o pod default/test-deployment-75477b6477-mkv9t: test-controller
I0121 16:26:50.443157       1 scheduler.go:181] [PostBind] Chamado para pod test-deployment-75477b6477-mkv9t
I0121 16:26:50.456425       1 scheduler.go:199] [PostBind] Pod test-deployment-75477b6477-mkv9t - Início do binding: 2025-01-21 16:26:50.397536727 +0000 UTC m=+2827.052105180, Fim do binding: 2025-01-21 16:26:50.45640802 +0000 UTC m=+2827.110976730
I0121 16:26:50.459918       1 types.go:743] [ControllerName] Verificando as anotações do pod default/test-deployment-75477b6477-mkv9t
I0121 16:26:50.462583       1 types.go:761] [ControllerName] Anotação 'controller' encontrada para o pod default/test-deployment-75477b6477-mkv9t: test-controller
I0121 16:26:50.462603       1 scheduler.go:206] [PostBind] Métricas atualizadas para o pod test-deployment-75477b6477-mkv9t
I0121 16:26:50.444442       1 scheduler.go:247] [OnUpdatePod] Pod atualizado: default/test-deployment-75477b6477-mkv9t, Anotações: map[controller:test-controller]
I0121 16:26:50.511012       1 scheduler.go:69] Estado no Informer: map[controller:test-controller]
I0121 16:26:50.511357       1 scheduler.go:70] Estado real no cluster: map[controller:test-controller]
I0121 16:26:50.511835       1 types.go:743] [ControllerName] Verificando as anotações do pod default/test-deployment-75477b6477-mkv9t
I0121 16:26:50.511848       1 types.go:761] [ControllerName] Anotação 'controller' encontrada para o pod default/test-deployment-75477b6477-mkv9t: test-controller
I0121 16:26:50.512132       1 scheduler.go:247] [OnUpdatePod] Pod atualizado: default/test-deployment-75477b6477-mkv9t, Anotações: map[controller:test-controller]
I0121 16:26:50.528922       1 scheduler.go:69] Estado no Informer: map[controller:test-controller]
I0121 16:26:50.532062       1 scheduler.go:70] Estado real no cluster: map[controller:test-controller]
I0121 16:26:50.532084       1 types.go:743] [ControllerName] Verificando as anotações do pod default/test-deployment-75477b6477-mkv9t
I0121 16:26:50.532091       1 types.go:761] [ControllerName] Anotação 'controller' encontrada para o pod default/test-deployment-75477b6477-mkv9t: test-controller
I0121 16:26:54.401422       1 scheduler.go:247] [OnUpdatePod] Pod atualizado: default/test-deployment-75477b6477-mkv9t, Anotações: map[controller:test-controller]
I0121 16:26:54.416065       1 scheduler.go:69] Estado no Informer: map[controller:test-controller]
I0121 16:26:54.416150       1 scheduler.go:70] Estado real no cluster: map[controller:test-controller]
I0121 16:26:54.416169       1 types.go:743] [ControllerName] Verificando as anotações do pod default/test-deployment-75477b6477-mkv9t
I0121 16:26:54.423367       1 types.go:761] [ControllerName] Anotação 'controller' encontrada para o pod default/test-deployment-75477b6477-mkv9t: test-controller
I0121 16:26:58.903677       1 scheduler.go:247] [OnUpdatePod] Pod atualizado: default/test-deployment-75477b6477-mkv9t, Anotações: map[controller:test-controller]
I0121 16:26:58.928655       1 scheduler.go:69] Estado no Informer: map[controller:test-controller]
I0121 16:26:58.928725       1 scheduler.go:70] Estado real no cluster: map[controller:test-controller]
I0121 16:26:58.928741       1 types.go:743] [ControllerName] Verificando as anotações do pod default/test-deployment-75477b6477-mkv9t
I0121 16:26:58.928751       1 types.go:761] [ControllerName] Anotação 'controller' encontrada para o pod default/test-deployment-75477b6477-mkv9t: test-controller
I0121 16:26:58.929280       1 types.go:743] [ControllerName] Verificando as anotações do pod default/test-deployment-75477b6477-mkv9t
I0121 16:26:58.929335       1 types.go:761] [ControllerName] Anotação 'controller' encontrada para o pod default/test-deployment-75477b6477-mkv9t: test-controller
I0121 16:27:00.368415       1 types.go:743] [ControllerName] Verificando as anotações do pod default/test-deployment-75477b6477-mkv9t
I0121 16:27:00.368574       1 types.go:761] [ControllerName] Anotação 'controller' encontrada para o pod default/test-deployment-75477b6477-mkv9t: test-controller
I0121 16:27:11.313916       1 scheduler.go:145] [Reserve] resources reserved at node minikube for pod test-deployment-75477b6477-s9knd_default at 2025-01-21 16:27:11.313901223 +0000 UTC m=+2847.968469806
I0121 16:27:11.316054       1 types.go:743] [ControllerName] Verificando as anotações do pod default/test-deployment-75477b6477-s9knd
I0121 16:27:11.316423       1 types.go:761] [ControllerName] Anotação 'controller' encontrada para o pod default/test-deployment-75477b6477-s9knd: test-controller
I0121 16:27:11.319729       1 scheduler.go:147] [Reserve] Status de alocação atual para o pod test-deployment-75477b6477-s9knd_default: 
I0121 16:27:11.319945       1 scheduler.go:149] [Reserve] Status de alocação atualizado para o pod test-deployment-75477b6477-s9knd_default: allocating
I0121 16:27:11.320300       1 scheduler.go:173] [PreBind] Validando o pod test-deployment-75477b6477-s9knd antes de vincular ao node minikube
I0121 16:27:11.321932       1 scheduler.go:213] [OnAddPod] Pod adicionado: default/test-deployment-75477b6477-s9knd, Anotações: map[controller:test-controller]
I0121 16:27:11.350443       1 scheduler.go:181] [PostBind] Chamado para pod test-deployment-75477b6477-s9knd
I0121 16:27:11.351604       1 scheduler.go:199] [PostBind] Pod test-deployment-75477b6477-s9knd - Início do binding: 2025-01-21 16:27:11.320411011 +0000 UTC m=+2847.974979612, Fim do binding: 2025-01-21 16:27:11.351589388 +0000 UTC m=+2848.006158344
I0121 16:27:11.352093       1 scheduler.go:69] Estado no Informer: map[controller:test-controller]
I0121 16:27:11.352141       1 scheduler.go:70] Estado real no cluster: map[controller:test-controller]
I0121 16:27:11.352168       1 types.go:743] [ControllerName] Verificando as anotações do pod default/test-deployment-75477b6477-s9knd
I0121 16:27:11.352211       1 types.go:761] [ControllerName] Anotação 'controller' encontrada para o pod default/test-deployment-75477b6477-s9knd: test-controller
I0121 16:27:11.352252       1 scheduler.go:206] [PostBind] Métricas atualizadas para o pod test-deployment-75477b6477-s9knd
I0121 16:27:11.353549       1 types.go:743] [ControllerName] Verificando as anotações do pod default/test-deployment-75477b6477-s9knd
I0121 16:27:11.353590       1 types.go:761] [ControllerName] Anotação 'controller' encontrada para o pod default/test-deployment-75477b6477-s9knd: test-controller
I0121 16:27:11.353601       1 types.go:743] [ControllerName] Verificando as anotações do pod default/test-deployment-75477b6477-s9knd
I0121 16:27:11.353675       1 types.go:761] [ControllerName] Anotação 'controller' encontrada para o pod default/test-deployment-75477b6477-s9knd: test-controller
I0121 16:27:11.353872       1 scheduler.go:247] [OnUpdatePod] Pod atualizado: default/test-deployment-75477b6477-s9knd, Anotações: map[controller:test-controller]
I0121 16:27:11.384080       1 scheduler.go:69] Estado no Informer: map[controller:test-controller]
I0121 16:27:11.384148       1 scheduler.go:70] Estado real no cluster: map[controller:test-controller]
I0121 16:27:11.384163       1 types.go:743] [ControllerName] Verificando as anotações do pod default/test-deployment-75477b6477-s9knd
I0121 16:27:11.384171       1 types.go:761] [ControllerName] Anotação 'controller' encontrada para o pod default/test-deployment-75477b6477-s9knd: test-controller
I0121 16:27:11.464387       1 scheduler.go:247] [OnUpdatePod] Pod atualizado: default/test-deployment-75477b6477-s9knd, Anotações: map[controller:test-controller]
I0121 16:27:11.499737       1 scheduler.go:69] Estado no Informer: map[controller:test-controller]
I0121 16:27:11.499791       1 scheduler.go:70] Estado real no cluster: map[controller:test-controller]
I0121 16:27:11.499804       1 types.go:743] [ControllerName] Verificando as anotações do pod default/test-deployment-75477b6477-s9knd
I0121 16:27:11.499832       1 types.go:761] [ControllerName] Anotação 'controller' encontrada para o pod default/test-deployment-75477b6477-s9knd: test-controller
I0121 16:27:11.552512       1 postFilter.go:74] Comparando pod original com o atualizado...
I0121 16:27:11.552558       1 postFilter.go:81] Successfully retrieved updated pod default/test-deployment2-59c6b78cd5-s72hf from lister
I0121 16:27:11.560757       1 scheduler.go:213] [OnAddPod] Pod adicionado: default/test-deployment2-59c6b78cd5-s72hf, Anotações: map[controller:test-controller2]
I0121 16:27:11.588662       1 scheduler.go:69] Estado no Informer: map[controller:test-controller2]
I0121 16:27:11.588716       1 scheduler.go:70] Estado real no cluster: map[controller:test-controller2]
I0121 16:27:11.590168       1 types.go:743] [ControllerName] Verificando as anotações do pod default/test-deployment2-59c6b78cd5-s72hf
I0121 16:27:11.590202       1 types.go:761] [ControllerName] Anotação 'controller' encontrada para o pod default/test-deployment2-59c6b78cd5-s72hf: test-controller2
I0121 16:27:11.591292       1 types.go:743] [ControllerName] Verificando as anotações do pod default/test-deployment2-59c6b78cd5-s72hf
I0121 16:27:11.591389       1 types.go:761] [ControllerName] Anotação 'controller' encontrada para o pod default/test-deployment2-59c6b78cd5-s72hf: test-controller2
I0121 16:27:11.600185       1 postFilter.go:204] Recursos CPU do nó minikube estão sincronizados: 2000 mCPU
I0121 16:27:11.600210       1 postFilter.go:211] Recursos Memória do nó minikube estão sincronizados: 2216124416 bytes
I0121 16:27:11.600447       1 scheduler.go:564] [GetControllerMetricInfo] Iniciando para o pod: default/test-deployment-75477b6477-s9knd
I0121 16:27:11.603098       1 scheduler.go:569] [GetControllerMetricInfo] Obtendo o nome do controlador para o pod: default/test-deployment-75477b6477-s9knd
I0121 16:27:11.603108       1 types.go:743] [ControllerName] Verificando as anotações do pod default/test-deployment-75477b6477-s9knd
I0121 16:27:11.603184       1 types.go:761] [ControllerName] Anotação 'controller' encontrada para o pod default/test-deployment-75477b6477-s9knd: test-controller
I0121 16:27:11.603193       1 scheduler.go:572] [GetControllerMetricInfo] Métricas do controlador definidas para o pod: default/test-deployment-75477b6477-s9knd
I0121 16:27:11.603201       1 scheduler.go:83] [HigherPrecedence] Calculando precedência entre test-deployment2-59c6b78cd5-s72hf e test-deployment-75477b6477-s9knd
I0121 16:27:11.603206       1 scheduler.go:116] [WaitForPodsOnCache] Verificando se o pod test-deployment2-59c6b78cd5-s72hf está no cache...
I0121 16:27:11.603211       1 scheduler.go:564] [GetControllerMetricInfo] Iniciando para o pod: default/test-deployment2-59c6b78cd5-s72hf
I0121 16:27:11.603215       1 scheduler.go:569] [GetControllerMetricInfo] Obtendo o nome do controlador para o pod: default/test-deployment2-59c6b78cd5-s72hf
I0121 16:27:11.603219       1 types.go:743] [ControllerName] Verificando as anotações do pod default/test-deployment2-59c6b78cd5-s72hf
I0121 16:27:11.603223       1 types.go:761] [ControllerName] Anotação 'controller' encontrada para o pod default/test-deployment2-59c6b78cd5-s72hf: test-controller2
I0121 16:27:11.603228       1 scheduler.go:572] [GetControllerMetricInfo] Métricas do controlador definidas para o pod: default/test-deployment2-59c6b78cd5-s72hf
I0121 16:27:11.823892       1 scheduler.go:69] Estado no Informer: map[controller:test-controller2]
I0121 16:27:11.835598       1 scheduler.go:70] Estado real no cluster: map[controller:test-controller2]
I0121 16:27:11.835745       1 scheduler.go:138] [WaitForPodsOnCache] Pod test-deployment2-59c6b78cd5-s72hf encontrado no cache.
I0121 16:27:11.835755       1 scheduler.go:116] [WaitForPodsOnCache] Verificando se o pod test-deployment-75477b6477-s9knd está no cache...
I0121 16:27:11.835765       1 scheduler.go:564] [GetControllerMetricInfo] Iniciando para o pod: default/test-deployment-75477b6477-s9knd
I0121 16:27:11.835773       1 scheduler.go:569] [GetControllerMetricInfo] Obtendo o nome do controlador para o pod: default/test-deployment-75477b6477-s9knd
I0121 16:27:11.835782       1 types.go:743] [ControllerName] Verificando as anotações do pod default/test-deployment-75477b6477-s9knd
I0121 16:27:11.835792       1 types.go:761] [ControllerName] Anotação 'controller' encontrada para o pod default/test-deployment-75477b6477-s9knd: test-controller
I0121 16:27:11.835801       1 scheduler.go:572] [GetControllerMetricInfo] Métricas do controlador definidas para o pod: default/test-deployment-75477b6477-s9knd
I0121 16:27:11.848937       1 scheduler.go:69] Estado no Informer: map[controller:test-controller]
I0121 16:27:11.850048       1 scheduler.go:70] Estado real no cluster: map[controller:test-controller]
I0121 16:27:11.850061       1 scheduler.go:138] [WaitForPodsOnCache] Pod test-deployment-75477b6477-s9knd encontrado no cache.
I0121 16:27:11.850120       1 scheduler.go:564] [GetControllerMetricInfo] Iniciando para o pod: default/test-deployment2-59c6b78cd5-s72hf
I0121 16:27:11.850130       1 scheduler.go:569] [GetControllerMetricInfo] Obtendo o nome do controlador para o pod: default/test-deployment2-59c6b78cd5-s72hf
I0121 16:27:11.850142       1 types.go:743] [ControllerName] Verificando as anotações do pod default/test-deployment2-59c6b78cd5-s72hf
I0121 16:27:11.850150       1 types.go:761] [ControllerName] Anotação 'controller' encontrada para o pod default/test-deployment2-59c6b78cd5-s72hf: test-controller2
I0121 16:27:11.850159       1 scheduler.go:572] [GetControllerMetricInfo] Métricas do controlador definidas para o pod: default/test-deployment2-59c6b78cd5-s72hf
I0121 16:27:11.850172       1 scheduler.go:564] [GetControllerMetricInfo] Iniciando para o pod: default/test-deployment-75477b6477-s9knd
I0121 16:27:11.850178       1 scheduler.go:569] [GetControllerMetricInfo] Obtendo o nome do controlador para o pod: default/test-deployment-75477b6477-s9knd
I0121 16:27:11.850183       1 types.go:743] [ControllerName] Verificando as anotações do pod default/test-deployment-75477b6477-s9knd
I0121 16:27:11.850189       1 types.go:761] [ControllerName] Anotação 'controller' encontrada para o pod default/test-deployment-75477b6477-s9knd: test-controller
I0121 16:27:11.850196       1 scheduler.go:572] [GetControllerMetricInfo] Métricas do controlador definidas para o pod: default/test-deployment-75477b6477-s9knd
I0121 16:27:11.850213       1 scheduler.go:97] [HigherPrecedence] Métricas para test-deployment2-59c6b78cd5-s72hf: QoS = -1658.060873, Importância = 0.80
I0121 16:27:11.850226       1 scheduler.go:98] [HigherPrecedence] Métricas para test-deployment-75477b6477-s9knd: QoS = -50.302628, Importância = 0.80
I0121 16:27:11.850234       1 scheduler.go:109] [HigherPrecedence] Decisão final: test-deployment2-59c6b78cd5-s72hf tem precedência sobre test-deployment-75477b6477-s9knd? true
I0121 16:27:11.850242       1 types.go:743] [ControllerName] Verificando as anotações do pod default/test-deployment2-59c6b78cd5-s72hf
I0121 16:27:11.850248       1 types.go:761] [ControllerName] Anotação 'controller' encontrada para o pod default/test-deployment2-59c6b78cd5-s72hf: test-controller2
I0121 16:27:11.850253       1 types.go:743] [ControllerName] Verificando as anotações do pod default/test-deployment-75477b6477-s9knd
I0121 16:27:11.850258       1 types.go:761] [ControllerName] Anotação 'controller' encontrada para o pod default/test-deployment-75477b6477-s9knd: test-controller
I0121 16:27:11.850264       1 scheduler.go:564] [GetControllerMetricInfo] Iniciando para o pod: default/test-deployment-75477b6477-s9knd
I0121 16:27:11.850269       1 scheduler.go:569] [GetControllerMetricInfo] Obtendo o nome do controlador para o pod: default/test-deployment-75477b6477-s9knd
I0121 16:27:11.850328       1 types.go:743] [ControllerName] Verificando as anotações do pod default/test-deployment-75477b6477-s9knd
I0121 16:27:11.850334       1 types.go:761] [ControllerName] Anotação 'controller' encontrada para o pod default/test-deployment-75477b6477-s9knd: test-controller
I0121 16:27:11.850442       1 scheduler.go:572] [GetControllerMetricInfo] Métricas do controlador definidas para o pod: default/test-deployment-75477b6477-s9knd
I0121 16:27:11.850543       1 scheduler.go:564] [GetControllerMetricInfo] Iniciando para o pod: default/test-deployment-75477b6477-s9knd
I0121 16:27:11.850552       1 scheduler.go:569] [GetControllerMetricInfo] Obtendo o nome do controlador para o pod: default/test-deployment-75477b6477-s9knd
I0121 16:27:11.850557       1 types.go:743] [ControllerName] Verificando as anotações do pod default/test-deployment-75477b6477-s9knd
I0121 16:27:11.850568       1 types.go:761] [ControllerName] Anotação 'controller' encontrada para o pod default/test-deployment-75477b6477-s9knd: test-controller
I0121 16:27:11.850575       1 scheduler.go:572] [GetControllerMetricInfo] Métricas do controlador definidas para o pod: default/test-deployment-75477b6477-s9knd
I0121 16:27:11.850583       1 types.go:743] [ControllerName] Verificando as anotações do pod default/test-deployment-75477b6477-s9knd
I0121 16:27:11.852788       1 types.go:761] [ControllerName] Anotação 'controller' encontrada para o pod default/test-deployment-75477b6477-s9knd: test-controller
I0121 16:27:11.853088       1 postFilter.go:142] [PREEMPT CALL] No node was chosen to allocate pod test-deployment2-59c6b78cd5-s72hf
I0121 16:27:11.877595       1 scheduler.go:247] [OnUpdatePod] Pod atualizado: default/test-deployment2-59c6b78cd5-s72hf, Anotações: map[controller:test-controller2]
I0121 16:27:12.105906       1 scheduler.go:69] Estado no Informer: map[controller:test-controller2]
I0121 16:27:12.106437       1 scheduler.go:70] Estado real no cluster: map[controller:test-controller2]
I0121 16:27:12.106981       1 types.go:743] [ControllerName] Verificando as anotações do pod default/test-deployment2-59c6b78cd5-s72hf
I0121 16:27:12.107779       1 types.go:761] [ControllerName] Anotação 'controller' encontrada para o pod default/test-deployment2-59c6b78cd5-s72hf: test-controller2
I0121 16:27:14.828880       1 scheduler.go:247] [OnUpdatePod] Pod atualizado: default/test-deployment-75477b6477-s9knd, Anotações: map[controller:test-controller]
I0121 16:27:14.851146       1 scheduler.go:69] Estado no Informer: map[controller:test-controller]
I0121 16:27:14.851539       1 scheduler.go:70] Estado real no cluster: map[controller:test-controller]
I0121 16:27:14.851904       1 types.go:743] [ControllerName] Verificando as anotações do pod default/test-deployment-75477b6477-s9knd
I0121 16:27:14.852138       1 types.go:761] [ControllerName] Anotação 'controller' encontrada para o pod default/test-deployment-75477b6477-s9knd: test-controller
I0121 16:27:17.036359       1 scheduler.go:247] [OnUpdatePod] Pod atualizado: default/test-deployment-75477b6477-s9knd, Anotações: map[controller:test-controller]
I0121 16:27:17.073354       1 scheduler.go:69] Estado no Informer: map[controller:test-controller]
I0121 16:27:17.073558       1 scheduler.go:70] Estado real no cluster: map[controller:test-controller]
I0121 16:27:17.073590       1 types.go:743] [ControllerName] Verificando as anotações do pod default/test-deployment-75477b6477-s9knd
I0121 16:27:17.073597       1 types.go:761] [ControllerName] Anotação 'controller' encontrada para o pod default/test-deployment-75477b6477-s9knd: test-controller
I0121 16:27:17.074924       1 types.go:743] [ControllerName] Verificando as anotações do pod default/test-deployment-75477b6477-s9knd
I0121 16:27:17.075538       1 types.go:761] [ControllerName] Anotação 'controller' encontrada para o pod default/test-deployment-75477b6477-s9knd: test-controller
I0121 16:27:17.102961       1 scheduler.go:247] [OnUpdatePod] Pod atualizado: default/test-deployment2-59c6b78cd5-s72hf, Anotações: map[controller:test-controller2]
E0121 16:27:17.117556       1 scheduler.go:66] Erro ao buscar estado real do pod test-deployment2-59c6b78cd5-s72hf: pods "test-deployment2-59c6b78cd5-s72hf" not found
I0121 16:27:17.117607       1 types.go:743] [ControllerName] Verificando as anotações do pod default/test-deployment2-59c6b78cd5-s72hf
I0121 16:27:17.117618       1 types.go:761] [ControllerName] Anotação 'controller' encontrada para o pod default/test-deployment2-59c6b78cd5-s72hf: test-controller2
I0121 16:27:17.118271       1 types.go:743] [ControllerName] Verificando as anotações do pod default/test-deployment2-59c6b78cd5-s72hf
I0121 16:27:17.118658       1 types.go:761] [ControllerName] Anotação 'controller' encontrada para o pod default/test-deployment2-59c6b78cd5-s72hf: test-controller2
I0121 16:27:17.117984       1 types.go:743] [ControllerName] Verificando as anotações do pod default/test-deployment2-59c6b78cd5-s72hf
I0121 16:27:17.118683       1 types.go:761] [ControllerName] Anotação 'controller' encontrada para o pod default/test-deployment2-59c6b78cd5-s72hf: test-controller2
I0121 16:27:18.095920       1 types.go:743] [ControllerName] Verificando as anotações do pod default/test-deployment-75477b6477-s9knd
I0121 16:27:18.096101       1 types.go:761] [ControllerName] Anotação 'controller' encontrada para o pod default/test-deployment-75477b6477-s9knd: test-controller
I0121 16:27:23.320382       1 scheduler.go:145] [Reserve] resources reserved at node minikube for pod test-deployment-75477b6477-jx6zf_default at 2025-01-21 16:27:23.320353868 +0000 UTC m=+2859.974922781
I0121 16:27:23.329221       1 types.go:743] [ControllerName] Verificando as anotações do pod default/test-deployment-75477b6477-jx6zf
I0121 16:27:23.329623       1 types.go:761] [ControllerName] Anotação 'controller' encontrada para o pod default/test-deployment-75477b6477-jx6zf: test-controller
I0121 16:27:23.330250       1 scheduler.go:147] [Reserve] Status de alocação atual para o pod test-deployment-75477b6477-jx6zf_default: 
I0121 16:27:23.328881       1 scheduler.go:213] [OnAddPod] Pod adicionado: default/test-deployment-75477b6477-jx6zf, Anotações: map[controller:test-controller]
I0121 16:27:23.330586       1 scheduler.go:149] [Reserve] Status de alocação atualizado para o pod test-deployment-75477b6477-jx6zf_default: allocating
I0121 16:27:23.333105       1 scheduler.go:173] [PreBind] Validando o pod test-deployment-75477b6477-jx6zf antes de vincular ao node minikube
I0121 16:27:23.561408       1 scheduler.go:69] Estado no Informer: map[controller:test-controller]
I0121 16:27:23.561685       1 scheduler.go:70] Estado real no cluster: map[controller:test-controller]
I0121 16:27:23.565588       1 types.go:743] [ControllerName] Verificando as anotações do pod default/test-deployment-75477b6477-jx6zf
I0121 16:27:23.565767       1 types.go:761] [ControllerName] Anotação 'controller' encontrada para o pod default/test-deployment-75477b6477-jx6zf: test-controller
I0121 16:27:23.565927       1 types.go:743] [ControllerName] Verificando as anotações do pod default/test-deployment-75477b6477-jx6zf
I0121 16:27:23.566110       1 types.go:761] [ControllerName] Anotação 'controller' encontrada para o pod default/test-deployment-75477b6477-jx6zf: test-controller
I0121 16:27:23.566398       1 scheduler.go:247] [OnUpdatePod] Pod atualizado: default/test-deployment-75477b6477-jx6zf, Anotações: map[controller:test-controller]
I0121 16:27:23.573206       1 scheduler.go:181] [PostBind] Chamado para pod test-deployment-75477b6477-jx6zf
I0121 16:27:23.573599       1 scheduler.go:199] [PostBind] Pod test-deployment-75477b6477-jx6zf - Início do binding: 2025-01-21 16:27:23.333329376 +0000 UTC m=+2859.987898389, Fim do binding: 2025-01-21 16:27:23.573587937 +0000 UTC m=+2860.228157111
I0121 16:27:23.573896       1 types.go:743] [ControllerName] Verificando as anotações do pod default/test-deployment-75477b6477-jx6zf
I0121 16:27:23.574055       1 types.go:761] [ControllerName] Anotação 'controller' encontrada para o pod default/test-deployment-75477b6477-jx6zf: test-controller
I0121 16:27:23.574196       1 scheduler.go:206] [PostBind] Métricas atualizadas para o pod test-deployment-75477b6477-jx6zf
I0121 16:27:23.593598       1 scheduler.go:69] Estado no Informer: map[controller:test-controller]
I0121 16:27:23.593908       1 scheduler.go:70] Estado real no cluster: map[controller:test-controller]
I0121 16:27:23.594090       1 types.go:743] [ControllerName] Verificando as anotações do pod default/test-deployment-75477b6477-jx6zf
I0121 16:27:23.594272       1 types.go:761] [ControllerName] Anotação 'controller' encontrada para o pod default/test-deployment-75477b6477-jx6zf: test-controller
I0121 16:27:23.594804       1 scheduler.go:247] [OnUpdatePod] Pod atualizado: default/test-deployment-75477b6477-jx6zf, Anotações: map[controller:test-controller]
I0121 16:27:23.623421       1 scheduler.go:69] Estado no Informer: map[controller:test-controller]
I0121 16:27:23.623753       1 scheduler.go:70] Estado real no cluster: map[controller:test-controller]
I0121 16:27:23.625305       1 types.go:743] [ControllerName] Verificando as anotações do pod default/test-deployment-75477b6477-jx6zf
I0121 16:27:23.635952       1 types.go:761] [ControllerName] Anotação 'controller' encontrada para o pod default/test-deployment-75477b6477-jx6zf: test-controller
I0121 16:27:23.678786       1 scheduler.go:213] [OnAddPod] Pod adicionado: default/test-deployment2-59c6b78cd5-5ndcn, Anotações: map[controller:test-controller2]
I0121 16:27:23.680663       1 postFilter.go:74] Comparando pod original com o atualizado...
I0121 16:27:23.681024       1 postFilter.go:81] Successfully retrieved updated pod default/test-deployment2-59c6b78cd5-5ndcn from lister
I0121 16:27:23.701902       1 postFilter.go:204] Recursos CPU do nó minikube estão sincronizados: 2000 mCPU
I0121 16:27:23.703528       1 postFilter.go:211] Recursos Memória do nó minikube estão sincronizados: 2216124416 bytes
I0121 16:27:23.704279       1 scheduler.go:564] [GetControllerMetricInfo] Iniciando para o pod: default/test-deployment-75477b6477-jx6zf
I0121 16:27:23.704310       1 scheduler.go:569] [GetControllerMetricInfo] Obtendo o nome do controlador para o pod: default/test-deployment-75477b6477-jx6zf
I0121 16:27:23.704363       1 types.go:743] [ControllerName] Verificando as anotações do pod default/test-deployment-75477b6477-jx6zf
I0121 16:27:23.704413       1 types.go:761] [ControllerName] Anotação 'controller' encontrada para o pod default/test-deployment-75477b6477-jx6zf: test-controller
I0121 16:27:23.704427       1 scheduler.go:572] [GetControllerMetricInfo] Métricas do controlador definidas para o pod: default/test-deployment-75477b6477-jx6zf
I0121 16:27:23.704510       1 scheduler.go:83] [HigherPrecedence] Calculando precedência entre test-deployment2-59c6b78cd5-5ndcn e test-deployment-75477b6477-jx6zf
I0121 16:27:23.704531       1 scheduler.go:116] [WaitForPodsOnCache] Verificando se o pod test-deployment2-59c6b78cd5-5ndcn está no cache...
I0121 16:27:23.704543       1 scheduler.go:564] [GetControllerMetricInfo] Iniciando para o pod: default/test-deployment2-59c6b78cd5-5ndcn
I0121 16:27:23.704618       1 scheduler.go:569] [GetControllerMetricInfo] Obtendo o nome do controlador para o pod: default/test-deployment2-59c6b78cd5-5ndcn
I0121 16:27:23.704638       1 types.go:743] [ControllerName] Verificando as anotações do pod default/test-deployment2-59c6b78cd5-5ndcn
I0121 16:27:23.704651       1 types.go:761] [ControllerName] Anotação 'controller' encontrada para o pod default/test-deployment2-59c6b78cd5-5ndcn: test-controller2
I0121 16:27:23.704772       1 scheduler.go:572] [GetControllerMetricInfo] Métricas do controlador definidas para o pod: default/test-deployment2-59c6b78cd5-5ndcn
W0121 16:27:23.704969       1 scheduler.go:124] [cacheMiss] Métricas não encontradas para o pod: default/test-deployment2-59c6b78cd5-5ndcn
I0121 16:27:23.718151       1 scheduler.go:69] Estado no Informer: map[controller:test-controller2]
I0121 16:27:23.718234       1 scheduler.go:70] Estado real no cluster: map[controller:test-controller2]
I0121 16:27:23.745431       1 scheduler.go:69] Estado no Informer: map[controller:test-controller2]
I0121 16:27:23.746332       1 scheduler.go:70] Estado real no cluster: map[controller:test-controller2]
W0121 16:27:23.750868       1 scheduler.go:134] [WaitForPodsOnCache] Pod test-deployment2-59c6b78cd5-5ndcn não encontrado no cache. Tentando novamente...
I0121 16:27:23.750989       1 types.go:743] [ControllerName] Verificando as anotações do pod default/test-deployment2-59c6b78cd5-5ndcn
I0121 16:27:23.751093       1 types.go:761] [ControllerName] Anotação 'controller' encontrada para o pod default/test-deployment2-59c6b78cd5-5ndcn: test-controller2
I0121 16:27:23.751116       1 types.go:743] [ControllerName] Verificando as anotações do pod default/test-deployment2-59c6b78cd5-5ndcn
I0121 16:27:23.751128       1 types.go:761] [ControllerName] Anotação 'controller' encontrada para o pod default/test-deployment2-59c6b78cd5-5ndcn: test-controller2
I0121 16:27:23.851690       1 scheduler.go:564] [GetControllerMetricInfo] Iniciando para o pod: default/test-deployment2-59c6b78cd5-5ndcn
I0121 16:27:23.854601       1 scheduler.go:569] [GetControllerMetricInfo] Obtendo o nome do controlador para o pod: default/test-deployment2-59c6b78cd5-5ndcn
I0121 16:27:23.855078       1 types.go:743] [ControllerName] Verificando as anotações do pod default/test-deployment2-59c6b78cd5-5ndcn
I0121 16:27:23.855183       1 types.go:761] [ControllerName] Anotação 'controller' encontrada para o pod default/test-deployment2-59c6b78cd5-5ndcn: test-controller2
I0121 16:27:23.855211       1 scheduler.go:572] [GetControllerMetricInfo] Métricas do controlador definidas para o pod: default/test-deployment2-59c6b78cd5-5ndcn
I0121 16:27:24.110193       1 scheduler.go:69] Estado no Informer: map[controller:test-controller2]
I0121 16:27:24.120403       1 scheduler.go:70] Estado real no cluster: map[controller:test-controller2]
I0121 16:27:24.120546       1 scheduler.go:138] [WaitForPodsOnCache] Pod test-deployment2-59c6b78cd5-5ndcn encontrado no cache.
I0121 16:27:24.120565       1 scheduler.go:116] [WaitForPodsOnCache] Verificando se o pod test-deployment-75477b6477-jx6zf está no cache...
I0121 16:27:24.120578       1 scheduler.go:564] [GetControllerMetricInfo] Iniciando para o pod: default/test-deployment-75477b6477-jx6zf
I0121 16:27:24.120590       1 scheduler.go:569] [GetControllerMetricInfo] Obtendo o nome do controlador para o pod: default/test-deployment-75477b6477-jx6zf
I0121 16:27:24.120722       1 types.go:743] [ControllerName] Verificando as anotações do pod default/test-deployment-75477b6477-jx6zf
I0121 16:27:24.120743       1 types.go:761] [ControllerName] Anotação 'controller' encontrada para o pod default/test-deployment-75477b6477-jx6zf: test-controller
I0121 16:27:24.120848       1 scheduler.go:572] [GetControllerMetricInfo] Métricas do controlador definidas para o pod: default/test-deployment-75477b6477-jx6zf
I0121 16:27:24.322264       1 scheduler.go:69] Estado no Informer: map[controller:test-controller]
I0121 16:27:24.322832       1 scheduler.go:70] Estado real no cluster: map[controller:test-controller]
I0121 16:27:24.325400       1 scheduler.go:138] [WaitForPodsOnCache] Pod test-deployment-75477b6477-jx6zf encontrado no cache.
I0121 16:27:24.325579       1 scheduler.go:564] [GetControllerMetricInfo] Iniciando para o pod: default/test-deployment2-59c6b78cd5-5ndcn
I0121 16:27:24.325589       1 scheduler.go:569] [GetControllerMetricInfo] Obtendo o nome do controlador para o pod: default/test-deployment2-59c6b78cd5-5ndcn
I0121 16:27:24.325598       1 types.go:743] [ControllerName] Verificando as anotações do pod default/test-deployment2-59c6b78cd5-5ndcn
I0121 16:27:24.326110       1 types.go:761] [ControllerName] Anotação 'controller' encontrada para o pod default/test-deployment2-59c6b78cd5-5ndcn: test-controller2
I0121 16:27:24.326210       1 scheduler.go:572] [GetControllerMetricInfo] Métricas do controlador definidas para o pod: default/test-deployment2-59c6b78cd5-5ndcn
I0121 16:27:24.326228       1 scheduler.go:564] [GetControllerMetricInfo] Iniciando para o pod: default/test-deployment-75477b6477-jx6zf
I0121 16:27:24.326235       1 scheduler.go:569] [GetControllerMetricInfo] Obtendo o nome do controlador para o pod: default/test-deployment-75477b6477-jx6zf
I0121 16:27:24.326240       1 types.go:743] [ControllerName] Verificando as anotações do pod default/test-deployment-75477b6477-jx6zf
I0121 16:27:24.326246       1 types.go:761] [ControllerName] Anotação 'controller' encontrada para o pod default/test-deployment-75477b6477-jx6zf: test-controller
I0121 16:27:24.326334       1 scheduler.go:572] [GetControllerMetricInfo] Métricas do controlador definidas para o pod: default/test-deployment-75477b6477-jx6zf
I0121 16:27:24.326436       1 scheduler.go:97] [HigherPrecedence] Métricas para test-deployment2-59c6b78cd5-5ndcn: QoS = -1664.272285, Importância = 0.80
I0121 16:27:24.326534       1 scheduler.go:98] [HigherPrecedence] Métricas para test-deployment-75477b6477-jx6zf: QoS = -49.272810, Importância = 0.80
I0121 16:27:24.326546       1 scheduler.go:109] [HigherPrecedence] Decisão final: test-deployment2-59c6b78cd5-5ndcn tem precedência sobre test-deployment-75477b6477-jx6zf? true
I0121 16:27:24.326555       1 types.go:743] [ControllerName] Verificando as anotações do pod default/test-deployment2-59c6b78cd5-5ndcn
I0121 16:27:24.326565       1 types.go:761] [ControllerName] Anotação 'controller' encontrada para o pod default/test-deployment2-59c6b78cd5-5ndcn: test-controller2
I0121 16:27:24.328424       1 types.go:743] [ControllerName] Verificando as anotações do pod default/test-deployment-75477b6477-jx6zf
I0121 16:27:24.328444       1 types.go:761] [ControllerName] Anotação 'controller' encontrada para o pod default/test-deployment-75477b6477-jx6zf: test-controller
I0121 16:27:24.328540       1 scheduler.go:564] [GetControllerMetricInfo] Iniciando para o pod: default/test-deployment-75477b6477-jx6zf
I0121 16:27:24.328547       1 scheduler.go:569] [GetControllerMetricInfo] Obtendo o nome do controlador para o pod: default/test-deployment-75477b6477-jx6zf
I0121 16:27:24.328552       1 types.go:743] [ControllerName] Verificando as anotações do pod default/test-deployment-75477b6477-jx6zf
I0121 16:27:24.328557       1 types.go:761] [ControllerName] Anotação 'controller' encontrada para o pod default/test-deployment-75477b6477-jx6zf: test-controller
I0121 16:27:24.328563       1 scheduler.go:572] [GetControllerMetricInfo] Métricas do controlador definidas para o pod: default/test-deployment-75477b6477-jx6zf
I0121 16:27:24.328568       1 scheduler.go:564] [GetControllerMetricInfo] Iniciando para o pod: default/test-deployment-75477b6477-jx6zf
I0121 16:27:24.328573       1 scheduler.go:569] [GetControllerMetricInfo] Obtendo o nome do controlador para o pod: default/test-deployment-75477b6477-jx6zf
I0121 16:27:24.328721       1 types.go:743] [ControllerName] Verificando as anotações do pod default/test-deployment-75477b6477-jx6zf
I0121 16:27:24.328729       1 types.go:761] [ControllerName] Anotação 'controller' encontrada para o pod default/test-deployment-75477b6477-jx6zf: test-controller
I0121 16:27:24.328735       1 scheduler.go:572] [GetControllerMetricInfo] Métricas do controlador definidas para o pod: default/test-deployment-75477b6477-jx6zf
I0121 16:27:24.328750       1 types.go:743] [ControllerName] Verificando as anotações do pod default/test-deployment-75477b6477-jx6zf
I0121 16:27:24.328756       1 types.go:761] [ControllerName] Anotação 'controller' encontrada para o pod default/test-deployment-75477b6477-jx6zf: test-controller
I0121 16:27:24.328974       1 postFilter.go:142] [PREEMPT CALL] No node was chosen to allocate pod test-deployment2-59c6b78cd5-5ndcn
I0121 16:27:24.330567       1 scheduler.go:213] [OnAddPod] Pod adicionado: default/test-deployment3-6c95cffb97-bj44t, Anotações: map[controller:test-controller3]
I0121 16:27:25.273107       1 scheduler.go:69] Estado no Informer: map[controller:test-controller3]
I0121 16:27:25.273271       1 scheduler.go:70] Estado real no cluster: map[controller:test-controller3]
I0121 16:27:25.276788       1 types.go:743] [ControllerName] Verificando as anotações do pod default/test-deployment3-6c95cffb97-bj44t
I0121 16:27:25.282233       1 types.go:761] [ControllerName] Anotação 'controller' encontrada para o pod default/test-deployment3-6c95cffb97-bj44t: test-controller3
I0121 16:27:25.282318       1 types.go:743] [ControllerName] Verificando as anotações do pod default/test-deployment3-6c95cffb97-bj44t
I0121 16:27:25.282324       1 types.go:761] [ControllerName] Anotação 'controller' encontrada para o pod default/test-deployment3-6c95cffb97-bj44t: test-controller3
I0121 16:27:25.282406       1 scheduler.go:247] [OnUpdatePod] Pod atualizado: default/test-deployment2-59c6b78cd5-5ndcn, Anotações: map[controller:test-controller2]
I0121 16:27:25.311386       1 scheduler.go:69] Estado no Informer: map[controller:test-controller2]
I0121 16:27:25.311596       1 scheduler.go:70] Estado real no cluster: map[controller:test-controller2]
I0121 16:27:25.311670       1 types.go:743] [ControllerName] Verificando as anotações do pod default/test-deployment2-59c6b78cd5-5ndcn
I0121 16:27:25.311737       1 types.go:761] [ControllerName] Anotação 'controller' encontrada para o pod default/test-deployment2-59c6b78cd5-5ndcn: test-controller2
I0121 16:27:25.311818       1 postFilter.go:74] Comparando pod original com o atualizado...
I0121 16:27:25.311887       1 postFilter.go:81] Successfully retrieved updated pod default/test-deployment3-6c95cffb97-bj44t from lister
I0121 16:27:25.318440       1 postFilter.go:204] Recursos CPU do nó minikube estão sincronizados: 2000 mCPU
I0121 16:27:25.318585       1 postFilter.go:211] Recursos Memória do nó minikube estão sincronizados: 2216124416 bytes
I0121 16:27:25.319251       1 scheduler.go:564] [GetControllerMetricInfo] Iniciando para o pod: default/test-deployment-75477b6477-jx6zf
I0121 16:27:25.321584       1 scheduler.go:569] [GetControllerMetricInfo] Obtendo o nome do controlador para o pod: default/test-deployment-75477b6477-jx6zf
I0121 16:27:25.321646       1 types.go:743] [ControllerName] Verificando as anotações do pod default/test-deployment-75477b6477-jx6zf
I0121 16:27:25.321668       1 types.go:761] [ControllerName] Anotação 'controller' encontrada para o pod default/test-deployment-75477b6477-jx6zf: test-controller
I0121 16:27:25.321711       1 scheduler.go:572] [GetControllerMetricInfo] Métricas do controlador definidas para o pod: default/test-deployment-75477b6477-jx6zf
I0121 16:27:25.321723       1 scheduler.go:83] [HigherPrecedence] Calculando precedência entre test-deployment3-6c95cffb97-bj44t e test-deployment-75477b6477-jx6zf
I0121 16:27:25.321730       1 scheduler.go:116] [WaitForPodsOnCache] Verificando se o pod test-deployment3-6c95cffb97-bj44t está no cache...
I0121 16:27:25.321786       1 scheduler.go:564] [GetControllerMetricInfo] Iniciando para o pod: default/test-deployment3-6c95cffb97-bj44t
I0121 16:27:25.321827       1 scheduler.go:569] [GetControllerMetricInfo] Obtendo o nome do controlador para o pod: default/test-deployment3-6c95cffb97-bj44t
I0121 16:27:25.321866       1 types.go:743] [ControllerName] Verificando as anotações do pod default/test-deployment3-6c95cffb97-bj44t
I0121 16:27:25.321875       1 types.go:761] [ControllerName] Anotação 'controller' encontrada para o pod default/test-deployment3-6c95cffb97-bj44t: test-controller3
I0121 16:27:25.321917       1 scheduler.go:572] [GetControllerMetricInfo] Métricas do controlador definidas para o pod: default/test-deployment3-6c95cffb97-bj44t
I0121 16:27:25.330537       1 scheduler.go:69] Estado no Informer: map[controller:test-controller3]
I0121 16:27:25.330557       1 scheduler.go:70] Estado real no cluster: map[controller:test-controller3]
I0121 16:27:25.330562       1 scheduler.go:138] [WaitForPodsOnCache] Pod test-deployment3-6c95cffb97-bj44t encontrado no cache.
I0121 16:27:25.330567       1 scheduler.go:116] [WaitForPodsOnCache] Verificando se o pod test-deployment-75477b6477-jx6zf está no cache...
I0121 16:27:25.330572       1 scheduler.go:564] [GetControllerMetricInfo] Iniciando para o pod: default/test-deployment-75477b6477-jx6zf
I0121 16:27:25.330576       1 scheduler.go:569] [GetControllerMetricInfo] Obtendo o nome do controlador para o pod: default/test-deployment-75477b6477-jx6zf
I0121 16:27:25.330581       1 types.go:743] [ControllerName] Verificando as anotações do pod default/test-deployment-75477b6477-jx6zf
I0121 16:27:25.330647       1 types.go:761] [ControllerName] Anotação 'controller' encontrada para o pod default/test-deployment-75477b6477-jx6zf: test-controller
I0121 16:27:25.330654       1 scheduler.go:572] [GetControllerMetricInfo] Métricas do controlador definidas para o pod: default/test-deployment-75477b6477-jx6zf
I0121 16:27:25.338201       1 scheduler.go:69] Estado no Informer: map[controller:test-controller]
I0121 16:27:25.338284       1 scheduler.go:70] Estado real no cluster: map[controller:test-controller]
I0121 16:27:25.338330       1 scheduler.go:138] [WaitForPodsOnCache] Pod test-deployment-75477b6477-jx6zf encontrado no cache.
I0121 16:27:25.338342       1 scheduler.go:564] [GetControllerMetricInfo] Iniciando para o pod: default/test-deployment3-6c95cffb97-bj44t
I0121 16:27:25.338351       1 scheduler.go:569] [GetControllerMetricInfo] Obtendo o nome do controlador para o pod: default/test-deployment3-6c95cffb97-bj44t
I0121 16:27:25.338393       1 types.go:743] [ControllerName] Verificando as anotações do pod default/test-deployment3-6c95cffb97-bj44t
I0121 16:27:25.338434       1 types.go:761] [ControllerName] Anotação 'controller' encontrada para o pod default/test-deployment3-6c95cffb97-bj44t: test-controller3
I0121 16:27:25.338446       1 scheduler.go:572] [GetControllerMetricInfo] Métricas do controlador definidas para o pod: default/test-deployment3-6c95cffb97-bj44t
I0121 16:27:25.338545       1 scheduler.go:564] [GetControllerMetricInfo] Iniciando para o pod: default/test-deployment-75477b6477-jx6zf
I0121 16:27:25.338589       1 scheduler.go:569] [GetControllerMetricInfo] Obtendo o nome do controlador para o pod: default/test-deployment-75477b6477-jx6zf
I0121 16:27:25.338615       1 types.go:743] [ControllerName] Verificando as anotações do pod default/test-deployment-75477b6477-jx6zf
I0121 16:27:25.338671       1 types.go:761] [ControllerName] Anotação 'controller' encontrada para o pod default/test-deployment-75477b6477-jx6zf: test-controller
I0121 16:27:25.338713       1 scheduler.go:572] [GetControllerMetricInfo] Métricas do controlador definidas para o pod: default/test-deployment-75477b6477-jx6zf
I0121 16:27:25.338738       1 scheduler.go:97] [HigherPrecedence] Métricas para test-deployment3-6c95cffb97-bj44t: QoS = -1417.671882, Importância = 0.80
I0121 16:27:25.338798       1 scheduler.go:98] [HigherPrecedence] Métricas para test-deployment-75477b6477-jx6zf: QoS = -48.868507, Importância = 0.80
I0121 16:27:25.339145       1 scheduler.go:109] [HigherPrecedence] Decisão final: test-deployment3-6c95cffb97-bj44t tem precedência sobre test-deployment-75477b6477-jx6zf? true
I0121 16:27:25.339195       1 types.go:743] [ControllerName] Verificando as anotações do pod default/test-deployment3-6c95cffb97-bj44t
I0121 16:27:25.339207       1 types.go:761] [ControllerName] Anotação 'controller' encontrada para o pod default/test-deployment3-6c95cffb97-bj44t: test-controller3
I0121 16:27:25.339248       1 types.go:743] [ControllerName] Verificando as anotações do pod default/test-deployment-75477b6477-jx6zf
I0121 16:27:25.339258       1 types.go:761] [ControllerName] Anotação 'controller' encontrada para o pod default/test-deployment-75477b6477-jx6zf: test-controller
I0121 16:27:25.339267       1 scheduler.go:564] [GetControllerMetricInfo] Iniciando para o pod: default/test-deployment-75477b6477-jx6zf
I0121 16:27:25.339276       1 scheduler.go:569] [GetControllerMetricInfo] Obtendo o nome do controlador para o pod: default/test-deployment-75477b6477-jx6zf
I0121 16:27:25.339283       1 types.go:743] [ControllerName] Verificando as anotações do pod default/test-deployment-75477b6477-jx6zf
I0121 16:27:25.339323       1 types.go:761] [ControllerName] Anotação 'controller' encontrada para o pod default/test-deployment-75477b6477-jx6zf: test-controller
I0121 16:27:25.339364       1 scheduler.go:572] [GetControllerMetricInfo] Métricas do controlador definidas para o pod: default/test-deployment-75477b6477-jx6zf
I0121 16:27:25.339374       1 scheduler.go:564] [GetControllerMetricInfo] Iniciando para o pod: default/test-deployment-75477b6477-jx6zf
I0121 16:27:25.339382       1 scheduler.go:569] [GetControllerMetricInfo] Obtendo o nome do controlador para o pod: default/test-deployment-75477b6477-jx6zf
I0121 16:27:25.339389       1 types.go:743] [ControllerName] Verificando as anotações do pod default/test-deployment-75477b6477-jx6zf
I0121 16:27:25.339397       1 types.go:761] [ControllerName] Anotação 'controller' encontrada para o pod default/test-deployment-75477b6477-jx6zf: test-controller
I0121 16:27:25.339407       1 scheduler.go:572] [GetControllerMetricInfo] Métricas do controlador definidas para o pod: default/test-deployment-75477b6477-jx6zf
I0121 16:27:25.339451       1 types.go:743] [ControllerName] Verificando as anotações do pod default/test-deployment-75477b6477-jx6zf
I0121 16:27:25.342171       1 types.go:761] [ControllerName] Anotação 'controller' encontrada para o pod default/test-deployment-75477b6477-jx6zf: test-controller
I0121 16:27:25.342372       1 postFilter.go:142] [PREEMPT CALL] No node was chosen to allocate pod test-deployment3-6c95cffb97-bj44t
I0121 16:27:25.408445       1 scheduler.go:247] [OnUpdatePod] Pod atualizado: default/test-deployment3-6c95cffb97-bj44t, Anotações: map[controller:test-controller3]
I0121 16:27:25.421985       1 scheduler.go:69] Estado no Informer: map[controller:test-controller3]
I0121 16:27:25.422069       1 scheduler.go:70] Estado real no cluster: map[controller:test-controller3]
I0121 16:27:25.422078       1 types.go:743] [ControllerName] Verificando as anotações do pod default/test-deployment3-6c95cffb97-bj44t
I0121 16:27:25.422084       1 types.go:761] [ControllerName] Anotação 'controller' encontrada para o pod default/test-deployment3-6c95cffb97-bj44t: test-controller3
I0121 16:27:28.305907       1 scheduler.go:247] [OnUpdatePod] Pod atualizado: default/test-deployment-75477b6477-jx6zf, Anotações: map[controller:test-controller]
I0121 16:27:28.343266       1 scheduler.go:69] Estado no Informer: map[controller:test-controller]
I0121 16:27:28.343297       1 scheduler.go:70] Estado real no cluster: map[controller:test-controller]
I0121 16:27:28.343316       1 types.go:743] [ControllerName] Verificando as anotações do pod default/test-deployment-75477b6477-jx6zf
I0121 16:27:28.343331       1 types.go:761] [ControllerName] Anotação 'controller' encontrada para o pod default/test-deployment-75477b6477-jx6zf: test-controller
I0121 16:32:44.781149       1 scheduler.go:53] [QueueSort] Comparando prioridade de test-deployment3-6c95cffb97-bj44t com test-deployment2-59c6b78cd5-5ndcn
I0121 16:32:44.781636       1 scheduler.go:83] [HigherPrecedence] Calculando precedência entre test-deployment3-6c95cffb97-bj44t e test-deployment2-59c6b78cd5-5ndcn
I0121 16:32:44.781679       1 scheduler.go:116] [WaitForPodsOnCache] Verificando se o pod test-deployment3-6c95cffb97-bj44t está no cache...
I0121 16:32:44.781744       1 scheduler.go:564] [GetControllerMetricInfo] Iniciando para o pod: default/test-deployment3-6c95cffb97-bj44t
I0121 16:32:44.781759       1 scheduler.go:569] [GetControllerMetricInfo] Obtendo o nome do controlador para o pod: default/test-deployment3-6c95cffb97-bj44t
I0121 16:32:44.781922       1 types.go:743] [ControllerName] Verificando as anotações do pod default/test-deployment3-6c95cffb97-bj44t
I0121 16:32:44.782178       1 types.go:761] [ControllerName] Anotação 'controller' encontrada para o pod default/test-deployment3-6c95cffb97-bj44t: test-controller3
I0121 16:32:44.789160       1 scheduler.go:572] [GetControllerMetricInfo] Métricas do controlador definidas para o pod: default/test-deployment3-6c95cffb97-bj44t
I0121 16:32:44.819923       1 scheduler.go:69] Estado no Informer: map[controller:test-controller3]
I0121 16:32:44.820051       1 scheduler.go:70] Estado real no cluster: map[controller:test-controller3]
I0121 16:32:44.820070       1 scheduler.go:138] [WaitForPodsOnCache] Pod test-deployment3-6c95cffb97-bj44t encontrado no cache.
I0121 16:32:44.820081       1 scheduler.go:116] [WaitForPodsOnCache] Verificando se o pod test-deployment2-59c6b78cd5-5ndcn está no cache...
I0121 16:32:44.820114       1 scheduler.go:564] [GetControllerMetricInfo] Iniciando para o pod: default/test-deployment2-59c6b78cd5-5ndcn
I0121 16:32:44.825325       1 scheduler.go:569] [GetControllerMetricInfo] Obtendo o nome do controlador para o pod: default/test-deployment2-59c6b78cd5-5ndcn
I0121 16:32:44.825947       1 types.go:743] [ControllerName] Verificando as anotações do pod default/test-deployment2-59c6b78cd5-5ndcn
I0121 16:32:44.826094       1 types.go:761] [ControllerName] Anotação 'controller' encontrada para o pod default/test-deployment2-59c6b78cd5-5ndcn: test-controller2
I0121 16:32:44.826111       1 scheduler.go:572] [GetControllerMetricInfo] Métricas do controlador definidas para o pod: default/test-deployment2-59c6b78cd5-5ndcn
I0121 16:32:44.839606       1 scheduler.go:69] Estado no Informer: map[controller:test-controller2]
I0121 16:32:44.839641       1 scheduler.go:70] Estado real no cluster: map[controller:test-controller2]
I0121 16:32:44.839651       1 scheduler.go:138] [WaitForPodsOnCache] Pod test-deployment2-59c6b78cd5-5ndcn encontrado no cache.
I0121 16:32:44.839660       1 scheduler.go:564] [GetControllerMetricInfo] Iniciando para o pod: default/test-deployment3-6c95cffb97-bj44t
I0121 16:32:44.839667       1 scheduler.go:569] [GetControllerMetricInfo] Obtendo o nome do controlador para o pod: default/test-deployment3-6c95cffb97-bj44t
I0121 16:32:44.839676       1 types.go:743] [ControllerName] Verificando as anotações do pod default/test-deployment3-6c95cffb97-bj44t
I0121 16:32:44.839685       1 types.go:761] [ControllerName] Anotação 'controller' encontrada para o pod default/test-deployment3-6c95cffb97-bj44t: test-controller3
I0121 16:32:44.839694       1 scheduler.go:572] [GetControllerMetricInfo] Métricas do controlador definidas para o pod: default/test-deployment3-6c95cffb97-bj44t
I0121 16:32:44.839726       1 scheduler.go:564] [GetControllerMetricInfo] Iniciando para o pod: default/test-deployment2-59c6b78cd5-5ndcn
I0121 16:32:44.839732       1 scheduler.go:569] [GetControllerMetricInfo] Obtendo o nome do controlador para o pod: default/test-deployment2-59c6b78cd5-5ndcn
I0121 16:32:44.839738       1 types.go:743] [ControllerName] Verificando as anotações do pod default/test-deployment2-59c6b78cd5-5ndcn
I0121 16:32:44.839744       1 types.go:761] [ControllerName] Anotação 'controller' encontrada para o pod default/test-deployment2-59c6b78cd5-5ndcn: test-controller2
I0121 16:32:44.839751       1 scheduler.go:572] [GetControllerMetricInfo] Métricas do controlador definidas para o pod: default/test-deployment2-59c6b78cd5-5ndcn
I0121 16:32:44.839770       1 scheduler.go:97] [HigherPrecedence] Métricas para test-deployment3-6c95cffb97-bj44t: QoS = -1737.131787, Importância = 0.80
I0121 16:32:44.839835       1 scheduler.go:98] [HigherPrecedence] Métricas para test-deployment2-59c6b78cd5-5ndcn: QoS = -1985.349403, Importância = 0.80
I0121 16:32:44.839845       1 scheduler.go:109] [HigherPrecedence] Decisão final: test-deployment3-6c95cffb97-bj44t tem precedência sobre test-deployment2-59c6b78cd5-5ndcn? false
I0121 16:32:44.839857       1 scheduler.go:59] [QueueSort] Precedência determinada: test-deployment3-6c95cffb97-bj44t tem precedência sobre test-deployment2-59c6b78cd5-5ndcn? false
I0121 16:32:44.841835       1 postFilter.go:74] Comparando pod original com o atualizado...
I0121 16:32:44.842382       1 postFilter.go:81] Successfully retrieved updated pod default/test-deployment2-59c6b78cd5-5ndcn from lister
I0121 16:32:44.855999       1 postFilter.go:204] Recursos CPU do nó minikube estão sincronizados: 2000 mCPU
I0121 16:32:44.856021       1 postFilter.go:211] Recursos Memória do nó minikube estão sincronizados: 2216124416 bytes
I0121 16:32:44.856513       1 scheduler.go:564] [GetControllerMetricInfo] Iniciando para o pod: default/test-deployment-75477b6477-jx6zf
I0121 16:32:44.856523       1 scheduler.go:569] [GetControllerMetricInfo] Obtendo o nome do controlador para o pod: default/test-deployment-75477b6477-jx6zf
I0121 16:32:44.856530       1 types.go:743] [ControllerName] Verificando as anotações do pod default/test-deployment-75477b6477-jx6zf
I0121 16:32:44.856539       1 types.go:761] [ControllerName] Anotação 'controller' encontrada para o pod default/test-deployment-75477b6477-jx6zf: test-controller
I0121 16:32:44.856546       1 scheduler.go:572] [GetControllerMetricInfo] Métricas do controlador definidas para o pod: default/test-deployment-75477b6477-jx6zf
I0121 16:32:44.856554       1 scheduler.go:83] [HigherPrecedence] Calculando precedência entre test-deployment2-59c6b78cd5-5ndcn e test-deployment-75477b6477-jx6zf
I0121 16:32:44.856559       1 scheduler.go:116] [WaitForPodsOnCache] Verificando se o pod test-deployment2-59c6b78cd5-5ndcn está no cache...
I0121 16:32:44.856564       1 scheduler.go:564] [GetControllerMetricInfo] Iniciando para o pod: default/test-deployment2-59c6b78cd5-5ndcn
I0121 16:32:44.856569       1 scheduler.go:569] [GetControllerMetricInfo] Obtendo o nome do controlador para o pod: default/test-deployment2-59c6b78cd5-5ndcn
I0121 16:32:44.856573       1 types.go:743] [ControllerName] Verificando as anotações do pod default/test-deployment2-59c6b78cd5-5ndcn
I0121 16:32:44.856579       1 types.go:761] [ControllerName] Anotação 'controller' encontrada para o pod default/test-deployment2-59c6b78cd5-5ndcn: test-controller2
I0121 16:32:44.856584       1 scheduler.go:572] [GetControllerMetricInfo] Métricas do controlador definidas para o pod: default/test-deployment2-59c6b78cd5-5ndcn
I0121 16:32:44.864156       1 scheduler.go:69] Estado no Informer: map[controller:test-controller2]
I0121 16:32:44.864337       1 scheduler.go:70] Estado real no cluster: map[controller:test-controller2]
I0121 16:32:44.864365       1 scheduler.go:138] [WaitForPodsOnCache] Pod test-deployment2-59c6b78cd5-5ndcn encontrado no cache.
I0121 16:32:44.864437       1 scheduler.go:116] [WaitForPodsOnCache] Verificando se o pod test-deployment-75477b6477-jx6zf está no cache...
I0121 16:32:44.864544       1 scheduler.go:564] [GetControllerMetricInfo] Iniciando para o pod: default/test-deployment-75477b6477-jx6zf
I0121 16:32:44.864668       1 scheduler.go:569] [GetControllerMetricInfo] Obtendo o nome do controlador para o pod: default/test-deployment-75477b6477-jx6zf
I0121 16:32:44.864772       1 types.go:743] [ControllerName] Verificando as anotações do pod default/test-deployment-75477b6477-jx6zf
I0121 16:32:44.864800       1 types.go:761] [ControllerName] Anotação 'controller' encontrada para o pod default/test-deployment-75477b6477-jx6zf: test-controller
I0121 16:32:44.864818       1 scheduler.go:572] [GetControllerMetricInfo] Métricas do controlador definidas para o pod: default/test-deployment-75477b6477-jx6zf
I0121 16:32:44.869330       1 scheduler.go:69] Estado no Informer: map[controller:test-controller]
I0121 16:32:44.869538       1 scheduler.go:70] Estado real no cluster: map[controller:test-controller]
I0121 16:32:44.871968       1 scheduler.go:138] [WaitForPodsOnCache] Pod test-deployment-75477b6477-jx6zf encontrado no cache.
I0121 16:32:44.871981       1 scheduler.go:564] [GetControllerMetricInfo] Iniciando para o pod: default/test-deployment2-59c6b78cd5-5ndcn
I0121 16:32:44.871988       1 scheduler.go:569] [GetControllerMetricInfo] Obtendo o nome do controlador para o pod: default/test-deployment2-59c6b78cd5-5ndcn
I0121 16:32:44.872071       1 types.go:743] [ControllerName] Verificando as anotações do pod default/test-deployment2-59c6b78cd5-5ndcn
I0121 16:32:44.872080       1 types.go:761] [ControllerName] Anotação 'controller' encontrada para o pod default/test-deployment2-59c6b78cd5-5ndcn: test-controller2
I0121 16:32:44.872088       1 scheduler.go:572] [GetControllerMetricInfo] Métricas do controlador definidas para o pod: default/test-deployment2-59c6b78cd5-5ndcn
I0121 16:32:44.872104       1 scheduler.go:564] [GetControllerMetricInfo] Iniciando para o pod: default/test-deployment-75477b6477-jx6zf
I0121 16:32:44.872109       1 scheduler.go:569] [GetControllerMetricInfo] Obtendo o nome do controlador para o pod: default/test-deployment-75477b6477-jx6zf
I0121 16:32:44.872114       1 types.go:743] [ControllerName] Verificando as anotações do pod default/test-deployment-75477b6477-jx6zf
I0121 16:32:44.872161       1 types.go:761] [ControllerName] Anotação 'controller' encontrada para o pod default/test-deployment-75477b6477-jx6zf: test-controller
I0121 16:32:44.872170       1 scheduler.go:572] [GetControllerMetricInfo] Métricas do controlador definidas para o pod: default/test-deployment-75477b6477-jx6zf
I0121 16:32:44.872191       1 scheduler.go:97] [HigherPrecedence] Métricas para test-deployment2-59c6b78cd5-5ndcn: QoS = -1985.424330, Importância = 0.80
I0121 16:32:44.872202       1 scheduler.go:98] [HigherPrecedence] Métricas para test-deployment-75477b6477-jx6zf: QoS = 31.015201, Importância = 0.80
I0121 16:32:44.872210       1 scheduler.go:109] [HigherPrecedence] Decisão final: test-deployment2-59c6b78cd5-5ndcn tem precedência sobre test-deployment-75477b6477-jx6zf? true
I0121 16:32:44.872216       1 types.go:743] [ControllerName] Verificando as anotações do pod default/test-deployment2-59c6b78cd5-5ndcn
I0121 16:32:44.872222       1 types.go:761] [ControllerName] Anotação 'controller' encontrada para o pod default/test-deployment2-59c6b78cd5-5ndcn: test-controller2
I0121 16:32:44.872226       1 types.go:743] [ControllerName] Verificando as anotações do pod default/test-deployment-75477b6477-jx6zf
I0121 16:32:44.872231       1 types.go:761] [ControllerName] Anotação 'controller' encontrada para o pod default/test-deployment-75477b6477-jx6zf: test-controller
I0121 16:32:44.872235       1 scheduler.go:564] [GetControllerMetricInfo] Iniciando para o pod: default/test-deployment-75477b6477-jx6zf
I0121 16:32:44.872240       1 scheduler.go:569] [GetControllerMetricInfo] Obtendo o nome do controlador para o pod: default/test-deployment-75477b6477-jx6zf
I0121 16:32:44.872244       1 types.go:743] [ControllerName] Verificando as anotações do pod default/test-deployment-75477b6477-jx6zf
I0121 16:32:44.872249       1 types.go:761] [ControllerName] Anotação 'controller' encontrada para o pod default/test-deployment-75477b6477-jx6zf: test-controller
I0121 16:32:44.872254       1 scheduler.go:572] [GetControllerMetricInfo] Métricas do controlador definidas para o pod: default/test-deployment-75477b6477-jx6zf
I0121 16:32:44.872258       1 scheduler.go:564] [GetControllerMetricInfo] Iniciando para o pod: default/test-deployment-75477b6477-jx6zf
I0121 16:32:44.872263       1 scheduler.go:569] [GetControllerMetricInfo] Obtendo o nome do controlador para o pod: default/test-deployment-75477b6477-jx6zf
I0121 16:32:44.872267       1 types.go:743] [ControllerName] Verificando as anotações do pod default/test-deployment-75477b6477-jx6zf
I0121 16:32:44.872271       1 types.go:761] [ControllerName] Anotação 'controller' encontrada para o pod default/test-deployment-75477b6477-jx6zf: test-controller
I0121 16:32:44.872276       1 scheduler.go:572] [GetControllerMetricInfo] Métricas do controlador definidas para o pod: default/test-deployment-75477b6477-jx6zf
I0121 16:32:44.872286       1 types.go:743] [ControllerName] Verificando as anotações do pod default/test-deployment-75477b6477-jx6zf
I0121 16:32:44.872295       1 types.go:761] [ControllerName] Anotação 'controller' encontrada para o pod default/test-deployment-75477b6477-jx6zf: test-controller
I0121 16:32:44.872402       1 scheduler.go:564] [GetControllerMetricInfo] Iniciando para o pod: default/test-deployment-75477b6477-jx6zf
I0121 16:32:44.872409       1 scheduler.go:569] [GetControllerMetricInfo] Obtendo o nome do controlador para o pod: default/test-deployment-75477b6477-jx6zf
I0121 16:32:44.872413       1 types.go:743] [ControllerName] Verificando as anotações do pod default/test-deployment-75477b6477-jx6zf
I0121 16:32:44.872418       1 types.go:761] [ControllerName] Anotação 'controller' encontrada para o pod default/test-deployment-75477b6477-jx6zf: test-controller
I0121 16:32:44.872424       1 scheduler.go:572] [GetControllerMetricInfo] Métricas do controlador definidas para o pod: default/test-deployment-75477b6477-jx6zf
I0121 16:32:44.872443       1 scheduler.go:564] [GetControllerMetricInfo] Iniciando para o pod: default/test-deployment-75477b6477-jx6zf
I0121 16:32:44.872447       1 scheduler.go:569] [GetControllerMetricInfo] Obtendo o nome do controlador para o pod: default/test-deployment-75477b6477-jx6zf
I0121 16:32:44.872498       1 types.go:743] [ControllerName] Verificando as anotações do pod default/test-deployment-75477b6477-jx6zf
I0121 16:32:44.872505       1 types.go:761] [ControllerName] Anotação 'controller' encontrada para o pod default/test-deployment-75477b6477-jx6zf: test-controller
I0121 16:32:44.872511       1 scheduler.go:572] [GetControllerMetricInfo] Métricas do controlador definidas para o pod: default/test-deployment-75477b6477-jx6zf
I0121 16:32:44.872529       1 postFilter.go:145] [PREEMPT CALL] The node minikube  was chosen to allocate pod test-deployment2-59c6b78cd5-5ndcn
I0121 16:32:44.893321       1 scheduler.go:247] [OnUpdatePod] Pod atualizado: default/test-deployment-75477b6477-jx6zf, Anotações: map[controller:test-controller]
I0121 16:32:44.927668       1 scheduler.go:69] Estado no Informer: map[controller:test-controller]
I0121 16:32:44.927853       1 scheduler.go:70] Estado real no cluster: map[controller:test-controller]
I0121 16:32:44.927871       1 types.go:743] [ControllerName] Verificando as anotações do pod default/test-deployment-75477b6477-jx6zf
I0121 16:32:44.927940       1 types.go:761] [ControllerName] Anotação 'controller' encontrada para o pod default/test-deployment-75477b6477-jx6zf: test-controller
I0121 16:32:44.930223       1 types.go:743] [ControllerName] Verificando as anotações do pod default/test-deployment-75477b6477-jx6zf
I0121 16:32:44.930333       1 types.go:761] [ControllerName] Anotação 'controller' encontrada para o pod default/test-deployment-75477b6477-jx6zf: test-controller
I0121 16:32:44.962056       1 scheduler.go:247] [OnUpdatePod] Pod atualizado: default/test-deployment2-59c6b78cd5-5ndcn, Anotações: map[controller:test-controller2]
I0121 16:32:44.962339       1 postFilter.go:74] Comparando pod original com o atualizado...
I0121 16:32:44.962362       1 postFilter.go:81] Successfully retrieved updated pod default/test-deployment3-6c95cffb97-bj44t from lister
I0121 16:32:45.283214       1 scheduler.go:69] Estado no Informer: map[controller:test-controller2]
I0121 16:32:45.283298       1 scheduler.go:70] Estado real no cluster: map[controller:test-controller2]
I0121 16:32:45.283316       1 types.go:743] [ControllerName] Verificando as anotações do pod default/test-deployment2-59c6b78cd5-5ndcn
I0121 16:32:45.285297       1 types.go:761] [ControllerName] Anotação 'controller' encontrada para o pod default/test-deployment2-59c6b78cd5-5ndcn: test-controller2
I0121 16:32:45.287590       1 postFilter.go:204] Recursos CPU do nó minikube estão sincronizados: 2000 mCPU
I0121 16:32:45.288051       1 postFilter.go:211] Recursos Memória do nó minikube estão sincronizados: 2216124416 bytes
I0121 16:32:45.289969       1 scheduler.go:564] [GetControllerMetricInfo] Iniciando para o pod: default/test-deployment-75477b6477-jx6zf
I0121 16:32:45.290126       1 scheduler.go:569] [GetControllerMetricInfo] Obtendo o nome do controlador para o pod: default/test-deployment-75477b6477-jx6zf
I0121 16:32:45.290137       1 types.go:743] [ControllerName] Verificando as anotações do pod default/test-deployment-75477b6477-jx6zf
I0121 16:32:45.290146       1 types.go:761] [ControllerName] Anotação 'controller' encontrada para o pod default/test-deployment-75477b6477-jx6zf: test-controller
I0121 16:32:45.290415       1 scheduler.go:572] [GetControllerMetricInfo] Métricas do controlador definidas para o pod: default/test-deployment-75477b6477-jx6zf
I0121 16:32:45.290435       1 scheduler.go:83] [HigherPrecedence] Calculando precedência entre test-deployment3-6c95cffb97-bj44t e test-deployment-75477b6477-jx6zf
I0121 16:32:45.290559       1 scheduler.go:116] [WaitForPodsOnCache] Verificando se o pod test-deployment3-6c95cffb97-bj44t está no cache...
I0121 16:32:45.290568       1 scheduler.go:564] [GetControllerMetricInfo] Iniciando para o pod: default/test-deployment3-6c95cffb97-bj44t
I0121 16:32:45.290576       1 scheduler.go:569] [GetControllerMetricInfo] Obtendo o nome do controlador para o pod: default/test-deployment3-6c95cffb97-bj44t
I0121 16:32:45.290583       1 types.go:743] [ControllerName] Verificando as anotações do pod default/test-deployment3-6c95cffb97-bj44t
I0121 16:32:45.290922       1 types.go:761] [ControllerName] Anotação 'controller' encontrada para o pod default/test-deployment3-6c95cffb97-bj44t: test-controller3
I0121 16:32:45.291089       1 scheduler.go:572] [GetControllerMetricInfo] Métricas do controlador definidas para o pod: default/test-deployment3-6c95cffb97-bj44t
I0121 16:32:45.309709       1 scheduler.go:69] Estado no Informer: map[controller:test-controller3]
I0121 16:32:45.309817       1 scheduler.go:70] Estado real no cluster: map[controller:test-controller3]
I0121 16:32:45.309829       1 scheduler.go:138] [WaitForPodsOnCache] Pod test-deployment3-6c95cffb97-bj44t encontrado no cache.
I0121 16:32:45.309836       1 scheduler.go:116] [WaitForPodsOnCache] Verificando se o pod test-deployment-75477b6477-jx6zf está no cache...
I0121 16:32:45.309844       1 scheduler.go:564] [GetControllerMetricInfo] Iniciando para o pod: default/test-deployment-75477b6477-jx6zf
I0121 16:32:45.309850       1 scheduler.go:569] [GetControllerMetricInfo] Obtendo o nome do controlador para o pod: default/test-deployment-75477b6477-jx6zf
I0121 16:32:45.309858       1 types.go:743] [ControllerName] Verificando as anotações do pod default/test-deployment-75477b6477-jx6zf
I0121 16:32:45.309944       1 types.go:761] [ControllerName] Anotação 'controller' encontrada para o pod default/test-deployment-75477b6477-jx6zf: test-controller
I0121 16:32:45.309954       1 scheduler.go:572] [GetControllerMetricInfo] Métricas do controlador definidas para o pod: default/test-deployment-75477b6477-jx6zf
I0121 16:32:45.565856       1 scheduler.go:213] [OnAddPod] Pod adicionado: default/test-deployment-75477b6477-f58xf, Anotações: map[controller:test-controller]
I0121 16:32:45.590588       1 scheduler.go:69] Estado no Informer: map[controller:test-controller]
I0121 16:32:45.590762       1 scheduler.go:70] Estado real no cluster: map[controller:test-controller]
I0121 16:32:45.590772       1 scheduler.go:138] [WaitForPodsOnCache] Pod test-deployment-75477b6477-jx6zf encontrado no cache.
I0121 16:32:45.590779       1 scheduler.go:564] [GetControllerMetricInfo] Iniciando para o pod: default/test-deployment3-6c95cffb97-bj44t
I0121 16:32:45.590785       1 scheduler.go:569] [GetControllerMetricInfo] Obtendo o nome do controlador para o pod: default/test-deployment3-6c95cffb97-bj44t
I0121 16:32:45.590792       1 types.go:743] [ControllerName] Verificando as anotações do pod default/test-deployment3-6c95cffb97-bj44t
I0121 16:32:45.590797       1 types.go:761] [ControllerName] Anotação 'controller' encontrada para o pod default/test-deployment3-6c95cffb97-bj44t: test-controller3
I0121 16:32:45.590804       1 scheduler.go:572] [GetControllerMetricInfo] Métricas do controlador definidas para o pod: default/test-deployment3-6c95cffb97-bj44t
I0121 16:32:45.590876       1 scheduler.go:564] [GetControllerMetricInfo] Iniciando para o pod: default/test-deployment-75477b6477-jx6zf
I0121 16:32:45.590883       1 scheduler.go:569] [GetControllerMetricInfo] Obtendo o nome do controlador para o pod: default/test-deployment-75477b6477-jx6zf
I0121 16:32:45.590887       1 types.go:743] [ControllerName] Verificando as anotações do pod default/test-deployment-75477b6477-jx6zf
I0121 16:32:45.590892       1 types.go:761] [ControllerName] Anotação 'controller' encontrada para o pod default/test-deployment-75477b6477-jx6zf: test-controller
I0121 16:32:45.590897       1 scheduler.go:572] [GetControllerMetricInfo] Métricas do controlador definidas para o pod: default/test-deployment-75477b6477-jx6zf
I0121 16:32:45.590911       1 scheduler.go:97] [HigherPrecedence] Métricas para test-deployment3-6c95cffb97-bj44t: QoS = -1737.640588, Importância = 0.80
I0121 16:32:45.590921       1 scheduler.go:98] [HigherPrecedence] Métricas para test-deployment-75477b6477-jx6zf: QoS = 24.882420, Importância = 0.80
I0121 16:32:45.591395       1 scheduler.go:109] [HigherPrecedence] Decisão final: test-deployment3-6c95cffb97-bj44t tem precedência sobre test-deployment-75477b6477-jx6zf? true
I0121 16:32:45.591403       1 types.go:743] [ControllerName] Verificando as anotações do pod default/test-deployment3-6c95cffb97-bj44t
I0121 16:32:45.591408       1 types.go:761] [ControllerName] Anotação 'controller' encontrada para o pod default/test-deployment3-6c95cffb97-bj44t: test-controller3
I0121 16:32:45.591411       1 types.go:743] [ControllerName] Verificando as anotações do pod default/test-deployment-75477b6477-jx6zf
I0121 16:32:45.593948       1 types.go:761] [ControllerName] Anotação 'controller' encontrada para o pod default/test-deployment-75477b6477-jx6zf: test-controller
I0121 16:32:45.594122       1 scheduler.go:564] [GetControllerMetricInfo] Iniciando para o pod: default/test-deployment-75477b6477-jx6zf
I0121 16:32:45.594131       1 scheduler.go:569] [GetControllerMetricInfo] Obtendo o nome do controlador para o pod: default/test-deployment-75477b6477-jx6zf
I0121 16:32:45.594136       1 types.go:743] [ControllerName] Verificando as anotações do pod default/test-deployment-75477b6477-jx6zf
I0121 16:32:45.594142       1 types.go:761] [ControllerName] Anotação 'controller' encontrada para o pod default/test-deployment-75477b6477-jx6zf: test-controller
I0121 16:32:45.594147       1 scheduler.go:572] [GetControllerMetricInfo] Métricas do controlador definidas para o pod: default/test-deployment-75477b6477-jx6zf
I0121 16:32:45.594158       1 scheduler.go:564] [GetControllerMetricInfo] Iniciando para o pod: default/test-deployment-75477b6477-jx6zf
I0121 16:32:45.594163       1 scheduler.go:569] [GetControllerMetricInfo] Obtendo o nome do controlador para o pod: default/test-deployment-75477b6477-jx6zf
I0121 16:32:45.594238       1 types.go:743] [ControllerName] Verificando as anotações do pod default/test-deployment-75477b6477-jx6zf
I0121 16:32:45.594445       1 types.go:761] [ControllerName] Anotação 'controller' encontrada para o pod default/test-deployment-75477b6477-jx6zf: test-controller
I0121 16:32:45.594589       1 scheduler.go:572] [GetControllerMetricInfo] Métricas do controlador definidas para o pod: default/test-deployment-75477b6477-jx6zf
I0121 16:32:45.594598       1 types.go:743] [ControllerName] Verificando as anotações do pod default/test-deployment-75477b6477-jx6zf
I0121 16:32:45.594602       1 types.go:761] [ControllerName] Anotação 'controller' encontrada para o pod default/test-deployment-75477b6477-jx6zf: test-controller
I0121 16:32:45.594838       1 scheduler.go:564] [GetControllerMetricInfo] Iniciando para o pod: default/test-deployment-75477b6477-jx6zf
I0121 16:32:45.594845       1 scheduler.go:569] [GetControllerMetricInfo] Obtendo o nome do controlador para o pod: default/test-deployment-75477b6477-jx6zf
I0121 16:32:45.594862       1 types.go:743] [ControllerName] Verificando as anotações do pod default/test-deployment-75477b6477-jx6zf
I0121 16:32:45.594866       1 types.go:761] [ControllerName] Anotação 'controller' encontrada para o pod default/test-deployment-75477b6477-jx6zf: test-controller
I0121 16:32:45.594954       1 scheduler.go:572] [GetControllerMetricInfo] Métricas do controlador definidas para o pod: default/test-deployment-75477b6477-jx6zf
I0121 16:32:45.594965       1 scheduler.go:564] [GetControllerMetricInfo] Iniciando para o pod: default/test-deployment-75477b6477-jx6zf
I0121 16:32:45.594969       1 scheduler.go:569] [GetControllerMetricInfo] Obtendo o nome do controlador para o pod: default/test-deployment-75477b6477-jx6zf
I0121 16:32:45.594974       1 types.go:743] [ControllerName] Verificando as anotações do pod default/test-deployment-75477b6477-jx6zf
I0121 16:32:45.594978       1 types.go:761] [ControllerName] Anotação 'controller' encontrada para o pod default/test-deployment-75477b6477-jx6zf: test-controller
I0121 16:32:45.594983       1 scheduler.go:572] [GetControllerMetricInfo] Métricas do controlador definidas para o pod: default/test-deployment-75477b6477-jx6zf
I0121 16:32:45.595087       1 postFilter.go:145] [PREEMPT CALL] The node minikube  was chosen to allocate pod test-deployment3-6c95cffb97-bj44t
I0121 16:32:45.623566       1 scheduler.go:69] Estado no Informer: map[controller:test-controller]
I0121 16:32:45.623649       1 scheduler.go:70] Estado real no cluster: map[controller:test-controller]
I0121 16:32:45.641119       1 types.go:743] [ControllerName] Verificando as anotações do pod default/test-deployment-75477b6477-f58xf
I0121 16:32:45.641440       1 types.go:761] [ControllerName] Anotação 'controller' encontrada para o pod default/test-deployment-75477b6477-f58xf: test-controller
I0121 16:32:45.641629       1 types.go:743] [ControllerName] Verificando as anotações do pod default/test-deployment-75477b6477-f58xf
I0121 16:32:45.641642       1 types.go:761] [ControllerName] Anotação 'controller' encontrada para o pod default/test-deployment-75477b6477-f58xf: test-controller
I0121 16:32:45.642091       1 scheduler.go:83] [HigherPrecedence] Calculando precedência entre test-deployment3-6c95cffb97-bj44t e test-deployment2-59c6b78cd5-5ndcn
I0121 16:32:45.642100       1 scheduler.go:116] [WaitForPodsOnCache] Verificando se o pod test-deployment3-6c95cffb97-bj44t está no cache...
I0121 16:32:45.642105       1 scheduler.go:564] [GetControllerMetricInfo] Iniciando para o pod: default/test-deployment3-6c95cffb97-bj44t
I0121 16:32:45.642110       1 scheduler.go:569] [GetControllerMetricInfo] Obtendo o nome do controlador para o pod: default/test-deployment3-6c95cffb97-bj44t
I0121 16:32:45.642114       1 types.go:743] [ControllerName] Verificando as anotações do pod default/test-deployment3-6c95cffb97-bj44t
I0121 16:32:45.642283       1 types.go:761] [ControllerName] Anotação 'controller' encontrada para o pod default/test-deployment3-6c95cffb97-bj44t: test-controller3
I0121 16:32:45.642290       1 scheduler.go:572] [GetControllerMetricInfo] Métricas do controlador definidas para o pod: default/test-deployment3-6c95cffb97-bj44t
I0121 16:32:45.776085       1 scheduler.go:69] Estado no Informer: map[controller:test-controller3]
I0121 16:32:45.783128       1 scheduler.go:70] Estado real no cluster: map[controller:test-controller3]
I0121 16:32:45.783168       1 scheduler.go:138] [WaitForPodsOnCache] Pod test-deployment3-6c95cffb97-bj44t encontrado no cache.
I0121 16:32:45.783180       1 scheduler.go:116] [WaitForPodsOnCache] Verificando se o pod test-deployment2-59c6b78cd5-5ndcn está no cache...
I0121 16:32:45.783192       1 scheduler.go:564] [GetControllerMetricInfo] Iniciando para o pod: default/test-deployment2-59c6b78cd5-5ndcn
I0121 16:32:45.783204       1 scheduler.go:569] [GetControllerMetricInfo] Obtendo o nome do controlador para o pod: default/test-deployment2-59c6b78cd5-5ndcn
I0121 16:32:45.783214       1 types.go:743] [ControllerName] Verificando as anotações do pod default/test-deployment2-59c6b78cd5-5ndcn
I0121 16:32:45.783227       1 types.go:761] [ControllerName] Anotação 'controller' encontrada para o pod default/test-deployment2-59c6b78cd5-5ndcn: test-controller2
I0121 16:32:45.783283       1 scheduler.go:572] [GetControllerMetricInfo] Métricas do controlador definidas para o pod: default/test-deployment2-59c6b78cd5-5ndcn
I0121 16:32:45.854874       1 scheduler.go:69] Estado no Informer: map[controller:test-controller2]
I0121 16:32:45.855056       1 scheduler.go:70] Estado real no cluster: map[controller:test-controller2]
I0121 16:32:45.855069       1 scheduler.go:138] [WaitForPodsOnCache] Pod test-deployment2-59c6b78cd5-5ndcn encontrado no cache.
I0121 16:32:45.855078       1 scheduler.go:564] [GetControllerMetricInfo] Iniciando para o pod: default/test-deployment3-6c95cffb97-bj44t
I0121 16:32:45.855087       1 scheduler.go:569] [GetControllerMetricInfo] Obtendo o nome do controlador para o pod: default/test-deployment3-6c95cffb97-bj44t
I0121 16:32:45.855157       1 types.go:743] [ControllerName] Verificando as anotações do pod default/test-deployment3-6c95cffb97-bj44t
I0121 16:32:45.855199       1 types.go:761] [ControllerName] Anotação 'controller' encontrada para o pod default/test-deployment3-6c95cffb97-bj44t: test-controller3
I0121 16:32:45.855322       1 scheduler.go:572] [GetControllerMetricInfo] Métricas do controlador definidas para o pod: default/test-deployment3-6c95cffb97-bj44t
I0121 16:32:45.855339       1 scheduler.go:564] [GetControllerMetricInfo] Iniciando para o pod: default/test-deployment2-59c6b78cd5-5ndcn
I0121 16:32:45.858173       1 scheduler.go:569] [GetControllerMetricInfo] Obtendo o nome do controlador para o pod: default/test-deployment2-59c6b78cd5-5ndcn
I0121 16:32:45.858618       1 types.go:743] [ControllerName] Verificando as anotações do pod default/test-deployment2-59c6b78cd5-5ndcn
I0121 16:32:45.858793       1 types.go:761] [ControllerName] Anotação 'controller' encontrada para o pod default/test-deployment2-59c6b78cd5-5ndcn: test-controller2
I0121 16:32:45.858802       1 scheduler.go:572] [GetControllerMetricInfo] Métricas do controlador definidas para o pod: default/test-deployment2-59c6b78cd5-5ndcn
I0121 16:32:45.858920       1 scheduler.go:97] [HigherPrecedence] Métricas para test-deployment3-6c95cffb97-bj44t: QoS = -1737.992251, Importância = 0.80
I0121 16:32:45.858935       1 scheduler.go:98] [HigherPrecedence] Métricas para test-deployment2-59c6b78cd5-5ndcn: QoS = -1986.209866, Importância = 0.80
I0121 16:32:45.859077       1 scheduler.go:109] [HigherPrecedence] Decisão final: test-deployment3-6c95cffb97-bj44t tem precedência sobre test-deployment2-59c6b78cd5-5ndcn? false
I0121 16:32:46.193051       1 postFilter.go:74] Comparando pod original com o atualizado...
I0121 16:32:46.193091       1 postFilter.go:81] Successfully retrieved updated pod default/test-deployment-75477b6477-f58xf from lister
I0121 16:32:46.190439       1 scheduler.go:247] [OnUpdatePod] Pod atualizado: default/test-deployment3-6c95cffb97-bj44t, Anotações: map[controller:test-controller3]
I0121 16:32:46.214786       1 scheduler.go:69] Estado no Informer: map[controller:test-controller3]
I0121 16:32:46.214970       1 scheduler.go:70] Estado real no cluster: map[controller:test-controller3]
I0121 16:32:46.214986       1 types.go:743] [ControllerName] Verificando as anotações do pod default/test-deployment3-6c95cffb97-bj44t
I0121 16:32:46.215120       1 postFilter.go:204] Recursos CPU do nó minikube estão sincronizados: 2000 mCPU
I0121 16:32:46.215235       1 types.go:761] [ControllerName] Anotação 'controller' encontrada para o pod default/test-deployment3-6c95cffb97-bj44t: test-controller3
I0121 16:32:46.215135       1 postFilter.go:211] Recursos Memória do nó minikube estão sincronizados: 2216124416 bytes
I0121 16:32:46.215826       1 scheduler.go:564] [GetControllerMetricInfo] Iniciando para o pod: default/test-deployment-75477b6477-jx6zf
I0121 16:32:46.215838       1 scheduler.go:569] [GetControllerMetricInfo] Obtendo o nome do controlador para o pod: default/test-deployment-75477b6477-jx6zf
I0121 16:32:46.215845       1 types.go:743] [ControllerName] Verificando as anotações do pod default/test-deployment-75477b6477-jx6zf
I0121 16:32:46.215853       1 types.go:761] [ControllerName] Anotação 'controller' encontrada para o pod default/test-deployment-75477b6477-jx6zf: test-controller
I0121 16:32:46.215949       1 scheduler.go:572] [GetControllerMetricInfo] Métricas do controlador definidas para o pod: default/test-deployment-75477b6477-jx6zf
I0121 16:32:46.215961       1 scheduler.go:83] [HigherPrecedence] Calculando precedência entre test-deployment-75477b6477-f58xf e test-deployment-75477b6477-jx6zf
I0121 16:32:46.215968       1 scheduler.go:116] [WaitForPodsOnCache] Verificando se o pod test-deployment-75477b6477-f58xf está no cache...
I0121 16:32:46.215974       1 scheduler.go:564] [GetControllerMetricInfo] Iniciando para o pod: default/test-deployment-75477b6477-f58xf
I0121 16:32:46.215980       1 scheduler.go:569] [GetControllerMetricInfo] Obtendo o nome do controlador para o pod: default/test-deployment-75477b6477-f58xf
I0121 16:32:46.215985       1 types.go:743] [ControllerName] Verificando as anotações do pod default/test-deployment-75477b6477-f58xf
I0121 16:32:46.216081       1 types.go:761] [ControllerName] Anotação 'controller' encontrada para o pod default/test-deployment-75477b6477-f58xf: test-controller
I0121 16:32:46.216091       1 scheduler.go:572] [GetControllerMetricInfo] Métricas do controlador definidas para o pod: default/test-deployment-75477b6477-f58xf
I0121 16:32:46.225935       1 scheduler.go:69] Estado no Informer: map[controller:test-controller]
I0121 16:32:46.226004       1 scheduler.go:70] Estado real no cluster: map[controller:test-controller]
I0121 16:32:46.226016       1 scheduler.go:138] [WaitForPodsOnCache] Pod test-deployment-75477b6477-f58xf encontrado no cache.
I0121 16:32:46.226023       1 scheduler.go:116] [WaitForPodsOnCache] Verificando se o pod test-deployment-75477b6477-jx6zf está no cache...
I0121 16:32:46.226029       1 scheduler.go:564] [GetControllerMetricInfo] Iniciando para o pod: default/test-deployment-75477b6477-jx6zf
I0121 16:32:46.226036       1 scheduler.go:569] [GetControllerMetricInfo] Obtendo o nome do controlador para o pod: default/test-deployment-75477b6477-jx6zf
I0121 16:32:46.226043       1 types.go:743] [ControllerName] Verificando as anotações do pod default/test-deployment-75477b6477-jx6zf
I0121 16:32:46.226051       1 types.go:761] [ControllerName] Anotação 'controller' encontrada para o pod default/test-deployment-75477b6477-jx6zf: test-controller
I0121 16:32:46.226058       1 scheduler.go:572] [GetControllerMetricInfo] Métricas do controlador definidas para o pod: default/test-deployment-75477b6477-jx6zf
I0121 16:32:46.230130       1 scheduler.go:69] Estado no Informer: map[controller:test-controller]
I0121 16:32:46.230183       1 scheduler.go:70] Estado real no cluster: map[controller:test-controller]
I0121 16:32:46.230194       1 scheduler.go:138] [WaitForPodsOnCache] Pod test-deployment-75477b6477-jx6zf encontrado no cache.
I0121 16:32:46.230200       1 scheduler.go:564] [GetControllerMetricInfo] Iniciando para o pod: default/test-deployment-75477b6477-f58xf
I0121 16:32:46.230207       1 scheduler.go:569] [GetControllerMetricInfo] Obtendo o nome do controlador para o pod: default/test-deployment-75477b6477-f58xf
I0121 16:32:46.230214       1 types.go:743] [ControllerName] Verificando as anotações do pod default/test-deployment-75477b6477-f58xf
I0121 16:32:46.230295       1 types.go:761] [ControllerName] Anotação 'controller' encontrada para o pod default/test-deployment-75477b6477-f58xf: test-controller
I0121 16:32:46.230330       1 scheduler.go:572] [GetControllerMetricInfo] Métricas do controlador definidas para o pod: default/test-deployment-75477b6477-f58xf
I0121 16:32:46.230367       1 scheduler.go:564] [GetControllerMetricInfo] Iniciando para o pod: default/test-deployment-75477b6477-jx6zf
I0121 16:32:46.230400       1 scheduler.go:569] [GetControllerMetricInfo] Obtendo o nome do controlador para o pod: default/test-deployment-75477b6477-jx6zf
I0121 16:32:46.230445       1 types.go:743] [ControllerName] Verificando as anotações do pod default/test-deployment-75477b6477-jx6zf
I0121 16:32:46.230507       1 types.go:761] [ControllerName] Anotação 'controller' encontrada para o pod default/test-deployment-75477b6477-jx6zf: test-controller
I0121 16:32:46.230516       1 scheduler.go:572] [GetControllerMetricInfo] Métricas do controlador definidas para o pod: default/test-deployment-75477b6477-jx6zf
I0121 16:32:46.230529       1 scheduler.go:97] [HigherPrecedence] Métricas para test-deployment-75477b6477-f58xf: QoS = 30.155612, Importância = 0.80
I0121 16:32:46.230577       1 scheduler.go:98] [HigherPrecedence] Métricas para test-deployment-75477b6477-jx6zf: QoS = 13.365793, Importância = 0.80
I0121 16:32:46.230612       1 scheduler.go:109] [HigherPrecedence] Decisão final: test-deployment-75477b6477-f58xf tem precedência sobre test-deployment-75477b6477-jx6zf? false
I0121 16:32:46.230715       1 postFilter.go:142] [PREEMPT CALL] No node was chosen to allocate pod test-deployment-75477b6477-f58xf
I0121 16:32:46.249544       1 scheduler.go:247] [OnUpdatePod] Pod atualizado: default/test-deployment-75477b6477-f58xf, Anotações: map[controller:test-controller]
I0121 16:32:46.385889       1 scheduler.go:69] Estado no Informer: map[controller:test-controller]
I0121 16:32:46.386196       1 scheduler.go:70] Estado real no cluster: map[controller:test-controller]
I0121 16:32:46.386393       1 types.go:743] [ControllerName] Verificando as anotações do pod default/test-deployment-75477b6477-f58xf
I0121 16:32:46.386407       1 types.go:761] [ControllerName] Anotação 'controller' encontrada para o pod default/test-deployment-75477b6477-f58xf: test-controller
I0121 16:32:46.591616       1 types.go:743] [ControllerName] Verificando as anotações do pod default/test-deployment-75477b6477-jx6zf
I0121 16:32:46.591708       1 types.go:761] [ControllerName] Anotação 'controller' encontrada para o pod default/test-deployment-75477b6477-jx6zf: test-controller
I0121 16:32:47.386158       1 scheduler.go:53] [QueueSort] Comparando prioridade de test-deployment-75477b6477-f58xf com test-deployment2-59c6b78cd5-5ndcn
I0121 16:32:47.386996       1 scheduler.go:83] [HigherPrecedence] Calculando precedência entre test-deployment-75477b6477-f58xf e test-deployment2-59c6b78cd5-5ndcn
I0121 16:32:47.387168       1 scheduler.go:116] [WaitForPodsOnCache] Verificando se o pod test-deployment-75477b6477-f58xf está no cache...
I0121 16:32:47.387332       1 scheduler.go:564] [GetControllerMetricInfo] Iniciando para o pod: default/test-deployment-75477b6477-f58xf
I0121 16:32:47.387624       1 scheduler.go:569] [GetControllerMetricInfo] Obtendo o nome do controlador para o pod: default/test-deployment-75477b6477-f58xf
I0121 16:32:47.387800       1 types.go:743] [ControllerName] Verificando as anotações do pod default/test-deployment-75477b6477-f58xf
I0121 16:32:47.387823       1 types.go:761] [ControllerName] Anotação 'controller' encontrada para o pod default/test-deployment-75477b6477-f58xf: test-controller
I0121 16:32:47.387989       1 scheduler.go:572] [GetControllerMetricInfo] Métricas do controlador definidas para o pod: default/test-deployment-75477b6477-f58xf
I0121 16:32:47.406570       1 scheduler.go:69] Estado no Informer: map[controller:test-controller]
I0121 16:32:47.406949       1 scheduler.go:70] Estado real no cluster: map[controller:test-controller]
I0121 16:32:47.406966       1 scheduler.go:138] [WaitForPodsOnCache] Pod test-deployment-75477b6477-f58xf encontrado no cache.
I0121 16:32:47.406975       1 scheduler.go:116] [WaitForPodsOnCache] Verificando se o pod test-deployment2-59c6b78cd5-5ndcn está no cache...
I0121 16:32:47.407101       1 scheduler.go:564] [GetControllerMetricInfo] Iniciando para o pod: default/test-deployment2-59c6b78cd5-5ndcn
I0121 16:32:47.407118       1 scheduler.go:569] [GetControllerMetricInfo] Obtendo o nome do controlador para o pod: default/test-deployment2-59c6b78cd5-5ndcn
I0121 16:32:47.407131       1 types.go:743] [ControllerName] Verificando as anotações do pod default/test-deployment2-59c6b78cd5-5ndcn
I0121 16:32:47.407583       1 types.go:761] [ControllerName] Anotação 'controller' encontrada para o pod default/test-deployment2-59c6b78cd5-5ndcn: test-controller2
I0121 16:32:47.407598       1 scheduler.go:572] [GetControllerMetricInfo] Métricas do controlador definidas para o pod: default/test-deployment2-59c6b78cd5-5ndcn
I0121 16:32:47.413584       1 scheduler.go:69] Estado no Informer: map[controller:test-controller2]
